5:return {{["x"] = 0, ["y"] = 0, ["param1"] = 10, ["z"] = 0, ["name"] = "default:desert_sandstone_block"}, {["x"] = 0, ["y"] = 0, ["param1"] = 11, ["z"] = 1, ["name"] = "default:desert_sandstone_block"}, {["x"] = 0, ["y"] = 0, ["param1"] = 12, ["z"] = 2, ["name"] = "default:desert_sandstone_block"}, {["x"] = 0, ["y"] = 0, ["param1"] = 12, ["z"] = 3, ["name"] = "default:desert_sandstone_block"}, {["x"] = 0, ["y"] = 0, ["param1"] = 12, ["z"] = 4, ["name"] = "default:desert_sandstone_block"}, {["x"] = 0, ["y"] = 0, ["param1"] = 12, ["z"] = 5, ["name"] = "default:desert_sandstone_block"}, {["x"] = 0, ["y"] = 0, ["param1"] = 12, ["z"] = 6, ["name"] = "default:desert_sandstone_block"}, {["x"] = 0, ["y"] = 0, ["param1"] = 12, ["z"] = 7, ["name"] = "default:desert_sandstone_block"}, {["x"] = 0, ["y"] = 0, ["param1"] = 12, ["z"] = 8, ["name"] = "default:desert_sandstone_block"}, {["x"] = 0, ["y"] = 0, ["param1"] = 12, ["z"] = 9, ["name"] = "default:desert_sandstone_block"}, {["x"] = 0, ["y"] = 0, ["param1"] = 12, ["z"] = 10, ["name"] = "default:desert_sandstone_block"}, {["x"] = 0, ["y"] = 0, ["param1"] = 12, ["z"] = 11, ["name"] = "default:desert_sandstone_block"}, {["x"] = 0, ["y"] = 0, ["param1"] = 12, ["z"] = 12, ["name"] = "default:desert_sandstone_block"}, {["x"] = 0, ["y"] = 0, ["param1"] = 12, ["z"] = 13, ["name"] = "default:desert_sandstone_block"}, {["x"] = 0, ["y"] = 0, ["param1"] = 12, ["z"] = 14, ["name"] = "default:desert_sandstone_block"}, {["x"] = 0, ["y"] = 0, ["param1"] = 12, ["z"] = 15, ["name"] = "default:desert_sandstone_block"}, {["x"] = 0, ["y"] = 0, ["param1"] = 12, ["z"] = 16, ["name"] = "default:desert_sandstone_block"}, {["x"] = 0, ["y"] = 0, ["param1"] = 12, ["z"] = 17, ["name"] = "default:desert_sandstone_block"}, {["x"] = 0, ["y"] = 0, ["param1"] = 12, ["z"] = 18, ["name"] = "default:desert_sandstone_block"}, {["x"] = 0, ["y"] = 0, ["param1"] = 12, ["z"] = 19, ["name"] = "default:desert_sandstone_block"}, {["x"] = 0, ["y"] = 0, ["param1"] = 12, ["z"] = 20, ["name"] = "default:desert_sandstone_block"}, {["x"] = 0, ["y"] = 0, ["param1"] = 12, ["z"] = 21, ["name"] = "default:desert_sandstone_block"}, {["x"] = 0, ["y"] = 0, ["param1"] = 12, ["z"] = 22, ["name"] = "default:desert_sandstone_block"}, {["x"] = 0, ["y"] = 0, ["param1"] = 12, ["z"] = 23, ["name"] = "default:desert_sandstone_block"}, {["x"] = 0, ["y"] = 0, ["param1"] = 12, ["z"] = 24, ["name"] = "default:desert_sandstone_block"}, {["x"] = 0, ["y"] = 0, ["param1"] = 12, ["z"] = 25, ["name"] = "default:desert_sandstone_block"}, {["x"] = 0, ["y"] = 0, ["param1"] = 12, ["z"] = 26, ["name"] = "default:desert_sandstone_block"}, {["x"] = 0, ["y"] = 0, ["param1"] = 12, ["z"] = 27, ["name"] = "default:desert_sandstone_block"}, {["x"] = 0, ["y"] = 0, ["param1"] = 12, ["z"] = 28, ["name"] = "default:desert_sandstone_block"}, {["x"] = 0, ["y"] = 0, ["param1"] = 12, ["z"] = 29, ["name"] = "default:desert_sandstone_block"}, {["x"] = 0, ["y"] = 0, ["param1"] = 12, ["z"] = 30, ["name"] = "default:desert_sandstone_block"}, {["x"] = 0, ["y"] = 0, ["param1"] = 12, ["z"] = 31, ["name"] = "default:desert_sandstone_block"}, {["x"] = 0, ["y"] = 0, ["param1"] = 12, ["z"] = 32, ["name"] = "default:desert_sandstone_block"}, {["x"] = 0, ["y"] = 0, ["param1"] = 11, ["z"] = 33, ["name"] = "default:desert_sandstone_block"}, {["x"] = 0, ["y"] = 0, ["param1"] = 10, ["z"] = 34, ["name"] = "default:desert_sandstone_block"}, {["x"] = 0, ["y"] = 0, ["param1"] = 11, ["z"] = 35, ["name"] = "default:desert_sandstone_block"}, {["x"] = 0, ["y"] = 0, ["param1"] = 12, ["z"] = 36, ["name"] = "default:desert_sandstone_block"}, {["x"] = 0, ["y"] = 0, ["param1"] = 13, ["z"] = 37, ["name"] = "default:desert_sandstone_block"}, {["x"] = 0, ["y"] = 0, ["param1"] = 14, ["z"] = 38, ["name"] = "default:desert_sandstone_block"}, {["x"] = 0, ["y"] = 0, ["param1"] = 15, ["z"] = 39, ["name"] = "default:desert_sandstone_block"}, {["x"] = 0, ["y"] = 0, ["param1"] = 15, ["z"] = 40, ["name"] = "default:desert_sandstone_block"}, {["x"] = 0, ["y"] = 0, ["param1"] = 15, ["z"] = 41, ["name"] = "default:desert_sandstone_block"}, {["x"] = 0, ["y"] = 0, ["param1"] = 15, ["z"] = 42, ["name"] = "default:desert_sandstone_block"}, {["x"] = 0, ["y"] = 0, ["param1"] = 15, ["z"] = 43, ["name"] = "default:desert_sandstone_block"}, {["x"] = 0, ["y"] = 0, ["param1"] = 15, ["z"] = 44, ["name"] = "default:desert_sandstone_block"}, {["x"] = 0, ["y"] = 0, ["param1"] = 15, ["z"] = 45, ["name"] = "default:desert_sandstone_block"}, {["x"] = 0, ["y"] = 0, ["param1"] = 15, ["z"] = 46, ["name"] = "default:desert_sandstone_block"}, {["x"] = 0, ["y"] = 0, ["param1"] = 15, ["z"] = 47, ["name"] = "default:desert_sandstone_block"}, {["x"] = 0, ["y"] = 0, ["param1"] = 15, ["z"] = 48, ["name"] = "default:desert_sandstone_block"}, {["x"] = 0, ["y"] = 0, ["param1"] = 15, ["z"] = 49, ["name"] = "default:desert_sandstone_block"}, {["x"] = 1, ["y"] = 0, ["param1"] = 11, ["z"] = 0, ["name"] = "default:desert_sandstone_block"}, {["x"] = 1, ["y"] = 0, ["param1"] = 18, ["z"] = 1, ["name"] = "default:silver_sandstone_block"}, {["x"] = 1, ["y"] = 0, ["param1"] = 18, ["z"] = 2, ["name"] = "default:silver_sandstone_block"}, {["x"] = 1, ["y"] = 0, ["param1"] = 18, ["z"] = 3, ["name"] = "default:silver_sandstone_block"}, {["x"] = 1, ["y"] = 0, ["param1"] = 18, ["z"] = 4, ["name"] = "default:silver_sandstone_block"}, {["x"] = 1, ["y"] = 0, ["param1"] = 18, ["z"] = 5, ["name"] = "default:silver_sandstone_block"}, {["x"] = 1, ["y"] = 0, ["param1"] = 18, ["z"] = 6, ["name"] = "default:silver_sandstone_block"}, {["x"] = 1, ["y"] = 0, ["param1"] = 18, ["z"] = 7, ["name"] = "default:silver_sandstone_block"}, {["x"] = 1, ["y"] = 0, ["param1"] = 18, ["z"] = 8, ["name"] = "default:silver_sandstone_block"}, {["x"] = 1, ["y"] = 0, ["param1"] = 18, ["z"] = 9, ["name"] = "default:silver_sandstone_block"}, {["x"] = 1, ["y"] = 0, ["param1"] = 18, ["z"] = 10, ["name"] = "default:silver_sandstone_block"}, {["x"] = 1, ["y"] = 0, ["param1"] = 18, ["z"] = 11, ["name"] = "default:silver_sandstone_block"}, {["x"] = 1, ["y"] = 0, ["param1"] = 18, ["z"] = 12, ["name"] = "default:silver_sandstone_block"}, {["x"] = 1, ["y"] = 0, ["param1"] = 18, ["z"] = 13, ["name"] = "default:silver_sandstone_block"}, {["x"] = 1, ["y"] = 0, ["param1"] = 18, ["z"] = 14, ["name"] = "default:silver_sandstone_block"}, {["x"] = 1, ["y"] = 0, ["param1"] = 18, ["z"] = 15, ["name"] = "default:silver_sandstone_block"}, {["x"] = 1, ["y"] = 0, ["param1"] = 18, ["z"] = 16, ["name"] = "default:silver_sandstone_block"}, {["x"] = 1, ["y"] = 0, ["param1"] = 18, ["z"] = 17, ["name"] = "default:silver_sandstone_block"}, {["x"] = 1, ["y"] = 0, ["param1"] = 18, ["z"] = 18, ["name"] = "default:silver_sandstone_block"}, {["x"] = 1, ["y"] = 0, ["param1"] = 18, ["z"] = 19, ["name"] = "default:silver_sandstone_block"}, {["x"] = 1, ["y"] = 0, ["param1"] = 18, ["z"] = 20, ["name"] = "default:silver_sandstone_block"}, {["x"] = 1, ["y"] = 0, ["param1"] = 18, ["z"] = 21, ["name"] = "default:silver_sandstone_block"}, {["x"] = 1, ["y"] = 0, ["param1"] = 18, ["z"] = 22, ["name"] = "default:silver_sandstone_block"}, {["x"] = 1, ["y"] = 0, ["param1"] = 18, ["z"] = 23, ["name"] = "default:silver_sandstone_block"}, {["x"] = 1, ["y"] = 0, ["param1"] = 18, ["z"] = 24, ["name"] = "default:silver_sandstone_block"}, {["x"] = 1, ["y"] = 0, ["param1"] = 18, ["z"] = 25, ["name"] = "default:silver_sandstone_block"}, {["x"] = 1, ["y"] = 0, ["param1"] = 18, ["z"] = 26, ["name"] = "default:silver_sandstone_block"}, {["x"] = 1, ["y"] = 0, ["param1"] = 18, ["z"] = 27, ["name"] = "default:silver_sandstone_block"}, {["x"] = 1, ["y"] = 0, ["param1"] = 18, ["z"] = 28, ["name"] = "default:silver_sandstone_block"}, {["x"] = 1, ["y"] = 0, ["param1"] = 18, ["z"] = 29, ["name"] = "default:silver_sandstone_block"}, {["x"] = 1, ["y"] = 0, ["param1"] = 18, ["z"] = 30, ["name"] = "default:silver_sandstone_block"}, {["x"] = 1, ["y"] = 0, ["param1"] = 18, ["z"] = 31, ["name"] = "default:silver_sandstone_block"}, {["x"] = 1, ["y"] = 0, ["param1"] = 18, ["z"] = 32, ["name"] = "default:silver_sandstone_block"}, {["x"] = 1, ["y"] = 0, ["param1"] = 18, ["z"] = 33, ["name"] = "default:silver_sandstone_block"}, {["x"] = 1, ["y"] = 0, ["param1"] = 18, ["z"] = 34, ["name"] = "default:silver_sandstone_block"}, {["x"] = 1, ["y"] = 0, ["param1"] = 18, ["z"] = 35, ["name"] = "default:silver_sandstone_block"}, {["x"] = 1, ["y"] = 0, ["param1"] = 18, ["z"] = 36, ["name"] = "default:silver_sandstone_block"}, {["x"] = 1, ["y"] = 0, ["param1"] = 18, ["z"] = 37, ["name"] = "default:silver_sandstone_block"}, {["x"] = 1, ["y"] = 0, ["param1"] = 18, ["z"] = 38, ["name"] = "default:silver_sandstone_block"}, {["x"] = 1, ["y"] = 0, ["param1"] = 18, ["z"] = 39, ["name"] = "default:silver_sandstone_block"}, {["x"] = 1, ["y"] = 0, ["param1"] = 18, ["z"] = 40, ["name"] = "default:silver_sandstone_block"}, {["x"] = 1, ["y"] = 0, ["param1"] = 18, ["z"] = 41, ["name"] = "default:silver_sandstone_block"}, {["x"] = 1, ["y"] = 0, ["param1"] = 18, ["z"] = 42, ["name"] = "default:silver_sandstone_block"}, {["x"] = 1, ["y"] = 0, ["param1"] = 18, ["z"] = 43, ["name"] = "default:silver_sandstone_block"}, {["x"] = 1, ["y"] = 0, ["param1"] = 18, ["z"] = 44, ["name"] = "default:silver_sandstone_block"}, {["x"] = 1, ["y"] = 0, ["param1"] = 18, ["z"] = 45, ["name"] = "default:silver_sandstone_block"}, {["x"] = 1, ["y"] = 0, ["param1"] = 18, ["z"] = 46, ["name"] = "default:silver_sandstone_block"}, {["x"] = 1, ["y"] = 0, ["param1"] = 18, ["z"] = 47, ["name"] = "default:silver_sandstone_block"}, {["x"] = 1, ["y"] = 0, ["param1"] = 18, ["z"] = 48, ["name"] = "default:silver_sandstone_block"}, {["x"] = 1, ["y"] = 0, ["param1"] = 15, ["z"] = 49, ["name"] = "default:desert_sandstone_block"}, {["x"] = 2, ["y"] = 0, ["param1"] = 12, ["z"] = 0, ["name"] = "default:desert_sandstone_block"}, {["x"] = 2, ["y"] = 0, ["param1"] = 18, ["z"] = 1, ["name"] = "default:silver_sandstone_block"}, {["x"] = 2, ["y"] = 0, ["param1"] = 18, ["z"] = 2, ["name"] = "default:silver_sandstone_block"}, {["x"] = 2, ["y"] = 0, ["param1"] = 18, ["z"] = 3, ["name"] = "default:silver_sandstone_block"}, {["x"] = 2, ["y"] = 0, ["param1"] = 18, ["z"] = 4, ["name"] = "default:silver_sandstone_block"}, {["x"] = 2, ["y"] = 0, ["param1"] = 18, ["z"] = 5, ["name"] = "default:silver_sandstone_block"}, {["x"] = 2, ["y"] = 0, ["param1"] = 18, ["z"] = 6, ["name"] = "default:silver_sandstone_block"}, {["x"] = 2, ["y"] = 0, ["param1"] = 18, ["z"] = 7, ["name"] = "default:silver_sandstone_block"}, {["x"] = 2, ["y"] = 0, ["param1"] = 18, ["z"] = 8, ["name"] = "default:silver_sandstone_block"}, {["x"] = 2, ["y"] = 0, ["param1"] = 18, ["z"] = 9, ["name"] = "default:silver_sandstone_block"}, {["x"] = 2, ["y"] = 0, ["param1"] = 18, ["z"] = 10, ["name"] = "default:silver_sandstone_block"}, {["x"] = 2, ["y"] = 0, ["param1"] = 18, ["z"] = 11, ["name"] = "default:silver_sandstone_block"}, {["x"] = 2, ["y"] = 0, ["param1"] = 18, ["z"] = 12, ["name"] = "default:silver_sandstone_block"}, {["x"] = 2, ["y"] = 0, ["param1"] = 18, ["z"] = 13, ["name"] = "default:silver_sandstone_block"}, {["x"] = 2, ["y"] = 0, ["param1"] = 18, ["z"] = 14, ["name"] = "default:silver_sandstone_block"}, {["x"] = 2, ["y"] = 0, ["param1"] = 18, ["z"] = 15, ["name"] = "default:silver_sandstone_block"}, {["x"] = 2, ["y"] = 0, ["param1"] = 18, ["z"] = 16, ["name"] = "default:silver_sandstone_block"}, {["x"] = 2, ["y"] = 0, ["param1"] = 18, ["z"] = 17, ["name"] = "default:silver_sandstone_block"}, {["x"] = 2, ["y"] = 0, ["param1"] = 18, ["z"] = 18, ["name"] = "default:silver_sandstone_block"}, {["x"] = 2, ["y"] = 0, ["param1"] = 18, ["z"] = 19, ["name"] = "default:silver_sandstone_block"}, {["x"] = 2, ["y"] = 0, ["param1"] = 18, ["z"] = 20, ["name"] = "default:silver_sandstone_block"}, {["x"] = 2, ["y"] = 0, ["param1"] = 18, ["z"] = 21, ["name"] = "default:silver_sandstone_block"}, {["x"] = 2, ["y"] = 0, ["param1"] = 18, ["z"] = 22, ["name"] = "default:silver_sandstone_block"}, {["x"] = 2, ["y"] = 0, ["param1"] = 18, ["z"] = 23, ["name"] = "default:silver_sandstone_block"}, {["x"] = 2, ["y"] = 0, ["param1"] = 18, ["z"] = 24, ["name"] = "default:silver_sandstone_block"}, {["x"] = 2, ["y"] = 0, ["param1"] = 18, ["z"] = 25, ["name"] = "default:silver_sandstone_block"}, {["x"] = 2, ["y"] = 0, ["param1"] = 18, ["z"] = 26, ["name"] = "default:silver_sandstone_block"}, {["x"] = 2, ["y"] = 0, ["param1"] = 18, ["z"] = 27, ["name"] = "default:silver_sandstone_block"}, {["x"] = 2, ["y"] = 0, ["param1"] = 18, ["z"] = 28, ["name"] = "default:silver_sandstone_block"}, {["x"] = 2, ["y"] = 0, ["param1"] = 18, ["z"] = 29, ["name"] = "default:silver_sandstone_block"}, {["x"] = 2, ["y"] = 0, ["param1"] = 18, ["z"] = 30, ["name"] = "default:silver_sandstone_block"}, {["x"] = 2, ["y"] = 0, ["param1"] = 18, ["z"] = 31, ["name"] = "default:silver_sandstone_block"}, {["x"] = 2, ["y"] = 0, ["param1"] = 18, ["z"] = 32, ["name"] = "default:silver_sandstone_block"}, {["x"] = 2, ["y"] = 0, ["param1"] = 18, ["z"] = 33, ["name"] = "default:silver_sandstone_block"}, {["x"] = 2, ["y"] = 0, ["param1"] = 18, ["z"] = 34, ["name"] = "default:silver_sandstone_block"}, {["x"] = 2, ["y"] = 0, ["param1"] = 18, ["z"] = 35, ["name"] = "default:silver_sandstone_block"}, {["x"] = 2, ["y"] = 0, ["param1"] = 18, ["z"] = 36, ["name"] = "default:silver_sandstone_block"}, {["x"] = 2, ["y"] = 0, ["param1"] = 18, ["z"] = 37, ["name"] = "default:silver_sandstone_block"}, {["x"] = 2, ["y"] = 0, ["param1"] = 18, ["z"] = 38, ["name"] = "default:silver_sandstone_block"}, {["x"] = 2, ["y"] = 0, ["param1"] = 18, ["z"] = 39, ["name"] = "default:silver_sandstone_block"}, {["x"] = 2, ["y"] = 0, ["param1"] = 18, ["z"] = 40, ["name"] = "default:silver_sandstone_block"}, {["x"] = 2, ["y"] = 0, ["param1"] = 18, ["z"] = 41, ["name"] = "default:silver_sandstone_block"}, {["x"] = 2, ["y"] = 0, ["param1"] = 18, ["z"] = 42, ["name"] = "default:silver_sandstone_block"}, {["x"] = 2, ["y"] = 0, ["param1"] = 18, ["z"] = 43, ["name"] = "default:silver_sandstone_block"}, {["x"] = 2, ["y"] = 0, ["param1"] = 18, ["z"] = 44, ["name"] = "default:silver_sandstone_block"}, {["x"] = 2, ["y"] = 0, ["param1"] = 18, ["z"] = 45, ["name"] = "default:silver_sandstone_block"}, {["x"] = 2, ["y"] = 0, ["param1"] = 18, ["z"] = 46, ["name"] = "default:silver_sandstone_block"}, {["x"] = 2, ["y"] = 0, ["param1"] = 18, ["z"] = 47, ["name"] = "default:silver_sandstone_block"}, {["x"] = 2, ["y"] = 0, ["param1"] = 18, ["z"] = 48, ["name"] = "default:silver_sandstone_block"}, {["x"] = 2, ["y"] = 0, ["param1"] = 15, ["z"] = 49, ["name"] = "default:desert_sandstone_block"}, {["x"] = 2, ["param2"] = 1, ["y"] = 1, ["z"] = 18, ["name"] = "mesecons_switch:mesecon_switch_off"}, {["x"] = 2, ["param2"] = 1, ["y"] = 1, ["z"] = 19, ["name"] = "mesecons_switch:mesecon_switch_off"}, {["x"] = 2, ["param2"] = 1, ["y"] = 1, ["z"] = 20, ["name"] = "mesecons_switch:mesecon_switch_off"}, {["x"] = 2, ["param2"] = 1, ["y"] = 1, ["z"] = 21, ["name"] = "mesecons_switch:mesecon_switch_off"}, {["x"] = 2, ["param2"] = 1, ["y"] = 1, ["z"] = 22, ["name"] = "mesecons_switch:mesecon_switch_off"}, {["x"] = 2, ["param2"] = 1, ["y"] = 1, ["z"] = 23, ["name"] = "mesecons_switch:mesecon_switch_off"}, {["x"] = 2, ["param2"] = 1, ["y"] = 1, ["z"] = 24, ["name"] = "mesecons_switch:mesecon_switch_off"}, {["x"] = 2, ["param2"] = 1, ["y"] = 1, ["z"] = 25, ["name"] = "mesecons_switch:mesecon_switch_off"}, {["x"] = 2, ["y"] = 1, ["z"] = 27, ["name"] = "mesecons_lightstone:lightstone_red_off"}, {["x"] = 2, ["y"] = 1, ["z"] = 28, ["name"] = "mesecons_lightstone:lightstone_red_off"}, {["x"] = 2, ["y"] = 1, ["z"] = 29, ["name"] = "mesecons_lightstone:lightstone_red_off"}, {["x"] = 2, ["y"] = 1, ["z"] = 30, ["name"] = "mesecons_lightstone:lightstone_red_off"}, {["x"] = 2, ["y"] = 1, ["z"] = 31, ["name"] = "mesecons_lightstone:lightstone_yellow_off"}, {["x"] = 2, ["y"] = 1, ["z"] = 32, ["name"] = "mesecons_lightstone:lightstone_red_off"}, {["x"] = 2, ["y"] = 1, ["z"] = 33, ["name"] = "mesecons_lightstone:lightstone_red_off"}, {["x"] = 2, ["y"] = 1, ["z"] = 34, ["name"] = "mesecons_lightstone:lightstone_red_off"}, {["x"] = 2, ["y"] = 1, ["z"] = 35, ["name"] = "mesecons_lightstone:lightstone_red_off"}, {["x"] = 2, ["param2"] = 1, ["y"] = 1, ["z"] = 37, ["name"] = "mesecons_switch:mesecon_switch_off"}, {["x"] = 2, ["param2"] = 1, ["y"] = 1, ["z"] = 38, ["name"] = "mesecons_switch:mesecon_switch_off"}, {["x"] = 2, ["param2"] = 1, ["y"] = 1, ["z"] = 39, ["name"] = "mesecons_switch:mesecon_switch_off"}, {["x"] = 2, ["param2"] = 1, ["y"] = 1, ["z"] = 40, ["name"] = "mesecons_switch:mesecon_switch_off"}, {["x"] = 2, ["param2"] = 1, ["y"] = 1, ["z"] = 41, ["name"] = "mesecons_switch:mesecon_switch_off"}, {["x"] = 2, ["param2"] = 1, ["y"] = 1, ["z"] = 42, ["name"] = "mesecons_switch:mesecon_switch_off"}, {["x"] = 2, ["param2"] = 1, ["y"] = 1, ["z"] = 43, ["name"] = "mesecons_switch:mesecon_switch_off"}, {["x"] = 2, ["param2"] = 1, ["y"] = 1, ["z"] = 44, ["name"] = "mesecons_switch:mesecon_switch_off"}, {["x"] = 3, ["y"] = 0, ["param1"] = 12, ["z"] = 0, ["name"] = "default:desert_sandstone_block"}, {["x"] = 3, ["y"] = 0, ["param1"] = 18, ["z"] = 1, ["name"] = "default:silver_sandstone_block"}, {["x"] = 3, ["y"] = 0, ["param1"] = 18, ["z"] = 2, ["name"] = "default:silver_sandstone_block"}, {["x"] = 3, ["y"] = 0, ["param1"] = 18, ["z"] = 3, ["name"] = "default:silver_sandstone_block"}, {["x"] = 3, ["y"] = 0, ["param1"] = 18, ["z"] = 4, ["name"] = "default:silver_sandstone_block"}, {["x"] = 3, ["y"] = 0, ["param1"] = 18, ["z"] = 5, ["name"] = "default:silver_sandstone_block"}, {["x"] = 3, ["y"] = 0, ["param1"] = 18, ["z"] = 6, ["name"] = "default:silver_sandstone_block"}, {["x"] = 3, ["y"] = 0, ["param1"] = 18, ["z"] = 7, ["name"] = "default:silver_sandstone_block"}, {["x"] = 3, ["y"] = 0, ["param1"] = 18, ["z"] = 8, ["name"] = "default:silver_sandstone_block"}, {["x"] = 3, ["y"] = 0, ["param1"] = 18, ["z"] = 9, ["name"] = "default:silver_sandstone_block"}, {["x"] = 3, ["y"] = 0, ["param1"] = 18, ["z"] = 10, ["name"] = "default:silver_sandstone_block"}, {["x"] = 3, ["y"] = 0, ["param1"] = 18, ["z"] = 11, ["name"] = "default:silver_sandstone_block"}, {["x"] = 3, ["y"] = 0, ["param1"] = 18, ["z"] = 12, ["name"] = "default:silver_sandstone_block"}, {["x"] = 3, ["y"] = 0, ["param1"] = 18, ["z"] = 13, ["name"] = "default:silver_sandstone_block"}, {["x"] = 3, ["y"] = 0, ["param1"] = 18, ["z"] = 14, ["name"] = "default:silver_sandstone_block"}, {["x"] = 3, ["y"] = 0, ["param1"] = 18, ["z"] = 15, ["name"] = "default:silver_sandstone_block"}, {["x"] = 3, ["y"] = 0, ["param1"] = 18, ["z"] = 16, ["name"] = "default:silver_sandstone_block"}, {["x"] = 3, ["y"] = 0, ["param1"] = 18, ["z"] = 17, ["name"] = "default:silver_sandstone_block"}, {["x"] = 3, ["y"] = 0, ["param1"] = 18, ["z"] = 18, ["name"] = "default:silver_sandstone_block"}, {["x"] = 3, ["y"] = 0, ["param1"] = 18, ["z"] = 19, ["name"] = "default:silver_sandstone_block"}, {["x"] = 3, ["y"] = 0, ["param1"] = 18, ["z"] = 20, ["name"] = "default:silver_sandstone_block"}, {["x"] = 3, ["y"] = 0, ["param1"] = 18, ["z"] = 21, ["name"] = "default:silver_sandstone_block"}, {["x"] = 3, ["y"] = 0, ["param1"] = 18, ["z"] = 22, ["name"] = "default:silver_sandstone_block"}, {["x"] = 3, ["y"] = 0, ["param1"] = 18, ["z"] = 23, ["name"] = "default:silver_sandstone_block"}, {["x"] = 3, ["y"] = 0, ["param1"] = 18, ["z"] = 24, ["name"] = "default:silver_sandstone_block"}, {["x"] = 3, ["y"] = 0, ["param1"] = 18, ["z"] = 25, ["name"] = "default:silver_sandstone_block"}, {["x"] = 3, ["y"] = 0, ["param1"] = 18, ["z"] = 26, ["name"] = "default:silver_sandstone_block"}, {["x"] = 3, ["y"] = 0, ["param1"] = 18, ["z"] = 27, ["name"] = "default:silver_sandstone_block"}, {["x"] = 3, ["y"] = 0, ["param1"] = 18, ["z"] = 28, ["name"] = "default:silver_sandstone_block"}, {["x"] = 3, ["y"] = 0, ["param1"] = 18, ["z"] = 29, ["name"] = "default:silver_sandstone_block"}, {["x"] = 3, ["y"] = 0, ["param1"] = 18, ["z"] = 30, ["name"] = "default:silver_sandstone_block"}, {["x"] = 3, ["y"] = 0, ["param1"] = 18, ["z"] = 31, ["name"] = "default:silver_sandstone_block"}, {["x"] = 3, ["y"] = 0, ["param1"] = 18, ["z"] = 32, ["name"] = "default:silver_sandstone_block"}, {["x"] = 3, ["y"] = 0, ["param1"] = 18, ["z"] = 33, ["name"] = "default:silver_sandstone_block"}, {["x"] = 3, ["y"] = 0, ["param1"] = 18, ["z"] = 34, ["name"] = "default:silver_sandstone_block"}, {["x"] = 3, ["y"] = 0, ["param1"] = 18, ["z"] = 35, ["name"] = "default:silver_sandstone_block"}, {["x"] = 3, ["y"] = 0, ["param1"] = 18, ["z"] = 36, ["name"] = "default:silver_sandstone_block"}, {["x"] = 3, ["y"] = 0, ["param1"] = 18, ["z"] = 37, ["name"] = "default:silver_sandstone_block"}, {["x"] = 3, ["y"] = 0, ["param1"] = 18, ["z"] = 38, ["name"] = "default:silver_sandstone_block"}, {["x"] = 3, ["y"] = 0, ["param1"] = 18, ["z"] = 39, ["name"] = "default:silver_sandstone_block"}, {["x"] = 3, ["y"] = 0, ["param1"] = 18, ["z"] = 40, ["name"] = "default:silver_sandstone_block"}, {["x"] = 3, ["y"] = 0, ["param1"] = 18, ["z"] = 41, ["name"] = "default:silver_sandstone_block"}, {["x"] = 3, ["y"] = 0, ["param1"] = 18, ["z"] = 42, ["name"] = "default:silver_sandstone_block"}, {["x"] = 3, ["y"] = 0, ["param1"] = 18, ["z"] = 43, ["name"] = "default:silver_sandstone_block"}, {["x"] = 3, ["y"] = 0, ["param1"] = 18, ["z"] = 44, ["name"] = "default:silver_sandstone_block"}, {["x"] = 3, ["y"] = 0, ["param1"] = 18, ["z"] = 45, ["name"] = "default:silver_sandstone_block"}, {["x"] = 3, ["y"] = 0, ["param1"] = 18, ["z"] = 46, ["name"] = "default:silver_sandstone_block"}, {["x"] = 3, ["y"] = 0, ["param1"] = 18, ["z"] = 47, ["name"] = "default:silver_sandstone_block"}, {["x"] = 3, ["y"] = 0, ["param1"] = 18, ["z"] = 48, ["name"] = "default:silver_sandstone_block"}, {["x"] = 3, ["y"] = 0, ["param1"] = 15, ["z"] = 49, ["name"] = "default:desert_sandstone_block"}, {["x"] = 3, ["y"] = 1, ["param1"] = 31, ["z"] = 18, ["name"] = "mesecons_insulated:insulated_off"}, {["x"] = 3, ["y"] = 1, ["param1"] = 15, ["z"] = 19, ["name"] = "mesecons_insulated:insulated_off"}, {["x"] = 3, ["y"] = 1, ["param1"] = 31, ["z"] = 20, ["name"] = "mesecons_insulated:insulated_off"}, {["x"] = 3, ["y"] = 1, ["param1"] = 15, ["z"] = 21, ["name"] = "mesecons_insulated:insulated_off"}, {["x"] = 3, ["y"] = 1, ["param1"] = 31, ["z"] = 22, ["name"] = "mesecons_insulated:insulated_off"}, {["x"] = 3, ["y"] = 1, ["param1"] = 15, ["z"] = 23, ["name"] = "mesecons_insulated:insulated_off"}, {["x"] = 3, ["y"] = 1, ["param1"] = 31, ["z"] = 24, ["name"] = "mesecons_insulated:insulated_off"}, {["x"] = 3, ["y"] = 1, ["param1"] = 15, ["z"] = 25, ["name"] = "mesecons_insulated:insulated_off"}, {["x"] = 3, ["y"] = 1, ["param1"] = 15, ["z"] = 27, ["name"] = "mesecons_insulated:insulated_off"}, {["x"] = 3, ["y"] = 1, ["param1"] = 31, ["z"] = 28, ["name"] = "mesecons_insulated:insulated_off"}, {["x"] = 3, ["y"] = 1, ["param1"] = 15, ["z"] = 29, ["name"] = "mesecons_insulated:insulated_off"}, {["x"] = 3, ["y"] = 1, ["param1"] = 31, ["z"] = 30, ["name"] = "mesecons_insulated:insulated_off"}, {["x"] = 3, ["y"] = 1, ["param1"] = 15, ["z"] = 31, ["name"] = "mesecons_insulated:insulated_off"}, {["x"] = 3, ["y"] = 1, ["param1"] = 31, ["z"] = 32, ["name"] = "mesecons_insulated:insulated_off"}, {["x"] = 3, ["y"] = 1, ["param1"] = 15, ["z"] = 33, ["name"] = "mesecons_insulated:insulated_off"}, {["x"] = 3, ["y"] = 1, ["param1"] = 31, ["z"] = 34, ["name"] = "mesecons_insulated:insulated_off"}, {["x"] = 3, ["y"] = 1, ["param1"] = 15, ["z"] = 35, ["name"] = "mesecons_insulated:insulated_off"}, {["x"] = 3, ["y"] = 1, ["param1"] = 15, ["z"] = 37, ["name"] = "mesecons_insulated:insulated_off"}, {["x"] = 3, ["y"] = 1, ["param1"] = 31, ["z"] = 38, ["name"] = "mesecons_insulated:insulated_off"}, {["x"] = 3, ["y"] = 1, ["param1"] = 15, ["z"] = 39, ["name"] = "mesecons_insulated:insulated_off"}, {["x"] = 3, ["y"] = 1, ["param1"] = 31, ["z"] = 40, ["name"] = "mesecons_insulated:insulated_off"}, {["x"] = 3, ["param2"] = 2, ["y"] = 1, ["param1"] = 15, ["z"] = 41, ["name"] = "mesecons_insulated:insulated_off"}, {["x"] = 3, ["param2"] = 2, ["y"] = 1, ["param1"] = 31, ["z"] = 42, ["name"] = "mesecons_insulated:insulated_off"}, {["x"] = 3, ["y"] = 1, ["param1"] = 15, ["z"] = 43, ["name"] = "mesecons_insulated:insulated_off"}, {["x"] = 3, ["y"] = 1, ["param1"] = 31, ["z"] = 44, ["name"] = "mesecons_insulated:insulated_off"}, {["x"] = 4, ["y"] = 0, ["param1"] = 12, ["z"] = 0, ["name"] = "default:desert_sandstone_block"}, {["x"] = 4, ["y"] = 0, ["param1"] = 18, ["z"] = 1, ["name"] = "default:silver_sandstone_block"}, {["x"] = 4, ["y"] = 0, ["param1"] = 18, ["z"] = 2, ["name"] = "default:silver_sandstone_block"}, {["x"] = 4, ["y"] = 0, ["param1"] = 18, ["z"] = 3, ["name"] = "default:silver_sandstone_block"}, {["x"] = 4, ["y"] = 0, ["param1"] = 18, ["z"] = 4, ["name"] = "default:silver_sandstone_block"}, {["x"] = 4, ["y"] = 0, ["param1"] = 18, ["z"] = 5, ["name"] = "default:silver_sandstone_block"}, {["x"] = 4, ["y"] = 0, ["param1"] = 18, ["z"] = 6, ["name"] = "default:silver_sandstone_block"}, {["x"] = 4, ["y"] = 0, ["param1"] = 18, ["z"] = 7, ["name"] = "default:silver_sandstone_block"}, {["x"] = 4, ["y"] = 0, ["param1"] = 18, ["z"] = 8, ["name"] = "default:silver_sandstone_block"}, {["x"] = 4, ["y"] = 0, ["param1"] = 18, ["z"] = 9, ["name"] = "default:silver_sandstone_block"}, {["x"] = 4, ["y"] = 0, ["param1"] = 18, ["z"] = 10, ["name"] = "default:silver_sandstone_block"}, {["x"] = 4, ["y"] = 0, ["param1"] = 18, ["z"] = 11, ["name"] = "default:silver_sandstone_block"}, {["x"] = 4, ["y"] = 0, ["param1"] = 18, ["z"] = 12, ["name"] = "default:silver_sandstone_block"}, {["x"] = 4, ["y"] = 0, ["param1"] = 18, ["z"] = 13, ["name"] = "default:silver_sandstone_block"}, {["x"] = 4, ["y"] = 0, ["param1"] = 18, ["z"] = 14, ["name"] = "default:silver_sandstone_block"}, {["x"] = 4, ["y"] = 0, ["param1"] = 18, ["z"] = 15, ["name"] = "default:silver_sandstone_block"}, {["x"] = 4, ["y"] = 0, ["param1"] = 18, ["z"] = 16, ["name"] = "default:silver_sandstone_block"}, {["x"] = 4, ["y"] = 0, ["param1"] = 18, ["z"] = 17, ["name"] = "default:silver_sandstone_block"}, {["x"] = 4, ["y"] = 0, ["param1"] = 18, ["z"] = 18, ["name"] = "default:silver_sandstone_block"}, {["x"] = 4, ["y"] = 0, ["param1"] = 18, ["z"] = 19, ["name"] = "default:silver_sandstone_block"}, {["x"] = 4, ["y"] = 0, ["param1"] = 18, ["z"] = 20, ["name"] = "default:silver_sandstone_block"}, {["x"] = 4, ["y"] = 0, ["param1"] = 18, ["z"] = 21, ["name"] = "default:silver_sandstone_block"}, {["x"] = 4, ["y"] = 0, ["param1"] = 18, ["z"] = 22, ["name"] = "default:silver_sandstone_block"}, {["x"] = 4, ["y"] = 0, ["param1"] = 18, ["z"] = 23, ["name"] = "default:silver_sandstone_block"}, {["x"] = 4, ["y"] = 0, ["param1"] = 18, ["z"] = 24, ["name"] = "default:silver_sandstone_block"}, {["x"] = 4, ["y"] = 0, ["param1"] = 18, ["z"] = 25, ["name"] = "default:silver_sandstone_block"}, {["x"] = 4, ["y"] = 0, ["param1"] = 18, ["z"] = 26, ["name"] = "default:silver_sandstone_block"}, {["x"] = 4, ["y"] = 0, ["param1"] = 18, ["z"] = 27, ["name"] = "default:silver_sandstone_block"}, {["x"] = 4, ["y"] = 0, ["param1"] = 18, ["z"] = 28, ["name"] = "default:silver_sandstone_block"}, {["x"] = 4, ["y"] = 0, ["param1"] = 18, ["z"] = 29, ["name"] = "default:silver_sandstone_block"}, {["x"] = 4, ["y"] = 0, ["param1"] = 18, ["z"] = 30, ["name"] = "default:silver_sandstone_block"}, {["x"] = 4, ["y"] = 0, ["param1"] = 18, ["z"] = 31, ["name"] = "default:silver_sandstone_block"}, {["x"] = 4, ["y"] = 0, ["param1"] = 18, ["z"] = 32, ["name"] = "default:silver_sandstone_block"}, {["x"] = 4, ["y"] = 0, ["param1"] = 18, ["z"] = 33, ["name"] = "default:silver_sandstone_block"}, {["x"] = 4, ["y"] = 0, ["param1"] = 18, ["z"] = 34, ["name"] = "default:silver_sandstone_block"}, {["x"] = 4, ["y"] = 0, ["param1"] = 18, ["z"] = 35, ["name"] = "default:silver_sandstone_block"}, {["x"] = 4, ["y"] = 0, ["param1"] = 18, ["z"] = 36, ["name"] = "default:silver_sandstone_block"}, {["x"] = 4, ["y"] = 0, ["param1"] = 18, ["z"] = 37, ["name"] = "default:silver_sandstone_block"}, {["x"] = 4, ["y"] = 0, ["param1"] = 18, ["z"] = 38, ["name"] = "default:silver_sandstone_block"}, {["x"] = 4, ["y"] = 0, ["param1"] = 18, ["z"] = 39, ["name"] = "default:silver_sandstone_block"}, {["x"] = 4, ["y"] = 0, ["param1"] = 18, ["z"] = 40, ["name"] = "default:silver_sandstone_block"}, {["x"] = 4, ["y"] = 0, ["param1"] = 18, ["z"] = 41, ["name"] = "default:silver_sandstone_block"}, {["x"] = 4, ["y"] = 0, ["param1"] = 18, ["z"] = 42, ["name"] = "default:silver_sandstone_block"}, {["x"] = 4, ["y"] = 0, ["param1"] = 18, ["z"] = 43, ["name"] = "default:silver_sandstone_block"}, {["x"] = 4, ["y"] = 0, ["param1"] = 18, ["z"] = 44, ["name"] = "default:silver_sandstone_block"}, {["x"] = 4, ["y"] = 0, ["param1"] = 18, ["z"] = 45, ["name"] = "default:silver_sandstone_block"}, {["x"] = 4, ["y"] = 0, ["param1"] = 18, ["z"] = 46, ["name"] = "default:silver_sandstone_block"}, {["x"] = 4, ["y"] = 0, ["param1"] = 18, ["z"] = 47, ["name"] = "default:silver_sandstone_block"}, {["x"] = 4, ["y"] = 0, ["param1"] = 18, ["z"] = 48, ["name"] = "default:silver_sandstone_block"}, {["x"] = 4, ["y"] = 0, ["param1"] = 15, ["z"] = 49, ["name"] = "default:desert_sandstone_block"}, {["x"] = 4, ["meta"] = {["fields"] = {["infotext"] = "\"Reset\"", ["text"] = "Reset", ["formspec"] = "field[text;;${text}]"}, ["inventory"] = {}}, ["param2"] = 2, ["y"] = 1, ["param1"] = 79, ["z"] = 11, ["name"] = "default:sign_wall_steel"}, {["x"] = 4, ["y"] = 1, ["param1"] = 47, ["z"] = 18, ["name"] = "mesecons_insulated:insulated_off"}, {["x"] = 4, ["y"] = 1, ["param1"] = 31, ["z"] = 19, ["name"] = "mesecons_insulated:insulated_off"}, {["x"] = 4, ["y"] = 1, ["param1"] = 47, ["z"] = 20, ["name"] = "mesecons_insulated:insulated_off"}, {["x"] = 4, ["y"] = 1, ["param1"] = 31, ["z"] = 21, ["name"] = "mesecons_insulated:insulated_off"}, {["x"] = 4, ["y"] = 1, ["param1"] = 47, ["z"] = 22, ["name"] = "mesecons_insulated:insulated_off"}, {["x"] = 4, ["y"] = 1, ["param1"] = 31, ["z"] = 23, ["name"] = "mesecons_insulated:insulated_off"}, {["x"] = 4, ["y"] = 1, ["param1"] = 47, ["z"] = 24, ["name"] = "mesecons_insulated:insulated_off"}, {["x"] = 4, ["y"] = 1, ["param1"] = 31, ["z"] = 25, ["name"] = "mesecons_insulated:insulated_off"}, {["x"] = 4, ["y"] = 1, ["param1"] = 31, ["z"] = 27, ["name"] = "mesecons_insulated:insulated_off"}, {["x"] = 4, ["y"] = 1, ["param1"] = 47, ["z"] = 28, ["name"] = "mesecons_insulated:insulated_off"}, {["x"] = 4, ["y"] = 1, ["param1"] = 31, ["z"] = 29, ["name"] = "mesecons_insulated:insulated_off"}, {["x"] = 4, ["y"] = 1, ["param1"] = 47, ["z"] = 30, ["name"] = "mesecons_insulated:insulated_off"}, {["x"] = 4, ["y"] = 1, ["param1"] = 31, ["z"] = 31, ["name"] = "mesecons_insulated:insulated_off"}, {["x"] = 4, ["y"] = 1, ["param1"] = 47, ["z"] = 32, ["name"] = "mesecons_insulated:insulated_off"}, {["x"] = 4, ["y"] = 1, ["param1"] = 31, ["z"] = 33, ["name"] = "mesecons_insulated:insulated_off"}, {["x"] = 4, ["y"] = 1, ["param1"] = 47, ["z"] = 34, ["name"] = "mesecons_insulated:insulated_off"}, {["x"] = 4, ["y"] = 1, ["param1"] = 31, ["z"] = 35, ["name"] = "mesecons_insulated:insulated_off"}, {["x"] = 4, ["param2"] = 2, ["y"] = 1, ["param1"] = 31, ["z"] = 37, ["name"] = "mesecons_insulated:insulated_off"}, {["x"] = 4, ["param2"] = 2, ["y"] = 1, ["param1"] = 47, ["z"] = 38, ["name"] = "mesecons_insulated:insulated_off"}, {["x"] = 4, ["param2"] = 2, ["y"] = 1, ["param1"] = 31, ["z"] = 39, ["name"] = "mesecons_insulated:insulated_off"}, {["x"] = 4, ["param2"] = 2, ["y"] = 1, ["param1"] = 47, ["z"] = 40, ["name"] = "mesecons_insulated:insulated_off"}, {["x"] = 4, ["param2"] = 2, ["y"] = 1, ["param1"] = 31, ["z"] = 41, ["name"] = "mesecons_insulated:insulated_off"}, {["x"] = 4, ["param2"] = 2, ["y"] = 1, ["param1"] = 47, ["z"] = 42, ["name"] = "mesecons_insulated:insulated_off"}, {["x"] = 4, ["param2"] = 2, ["y"] = 1, ["param1"] = 31, ["z"] = 43, ["name"] = "mesecons_insulated:insulated_off"}, {["x"] = 4, ["y"] = 1, ["param1"] = 47, ["z"] = 44, ["name"] = "mesecons_insulated:insulated_off"}, {["x"] = 4, ["meta"] = {["fields"] = {["infotext"] = "Keyboard", ["channel"] = "inputa", ["lines"] = "0", ["formspec"] = "field[text;Enter text;]"}, ["inventory"] = {}}, ["param2"] = 1, ["y"] = 2, ["param1"] = 94, ["z"] = 9, ["name"] = "digiboard:keyboard"}, {["x"] = 4, ["meta"] = {["fields"] = {["infotext"] = "Keyboard", ["channel"] = "inputb", ["lines"] = "0", ["formspec"] = "field[text;Enter text;]"}, ["inventory"] = {}}, ["param2"] = 1, ["y"] = 2, ["param1"] = 94, ["z"] = 10, ["name"] = "digiboard:keyboard"}, {["x"] = 4, ["param2"] = 1, ["y"] = 2, ["param1"] = 95, ["z"] = 11, ["name"] = "mesecons_button:button_off"}, {["x"] = 4, ["meta"] = {["fields"] = {["infotext"] = "\"Input 1\"", ["text"] = "Input 1", ["formspec"] = "field[text;;${text}]"}, ["inventory"] = {}}, ["param2"] = 2, ["y"] = 2, ["param1"] = 31, ["z"] = 18, ["name"] = "default:sign_wall_steel"}, {["x"] = 4, ["meta"] = {["fields"] = {["infotext"] = "\"Input 2\"", ["text"] = "Input 2", ["formspec"] = "field[text;;${text}]"}, ["inventory"] = {}}, ["param2"] = 2, ["y"] = 2, ["param1"] = 15, ["z"] = 19, ["name"] = "default:sign_wall_steel"}, {["x"] = 4, ["meta"] = {["fields"] = {["infotext"] = "\"Input 3\"", ["text"] = "Input 3", ["formspec"] = "field[text;;${text}]"}, ["inventory"] = {}}, ["param2"] = 2, ["y"] = 2, ["param1"] = 31, ["z"] = 20, ["name"] = "default:sign_wall_steel"}, {["x"] = 4, ["meta"] = {["fields"] = {["infotext"] = "\"Input 4\"", ["text"] = "Input 4", ["formspec"] = "field[text;;${text}]"}, ["inventory"] = {}}, ["param2"] = 2, ["y"] = 2, ["param1"] = 15, ["z"] = 21, ["name"] = "default:sign_wall_steel"}, {["x"] = 4, ["meta"] = {["fields"] = {["infotext"] = "\"Input 5\"", ["text"] = "Input 5", ["formspec"] = "field[text;;${text}]"}, ["inventory"] = {}}, ["param2"] = 2, ["y"] = 2, ["param1"] = 31, ["z"] = 22, ["name"] = "default:sign_wall_steel"}, {["x"] = 4, ["meta"] = {["fields"] = {["infotext"] = "\"Input 6\"", ["text"] = "Input 6", ["formspec"] = "field[text;;${text}]"}, ["inventory"] = {}}, ["param2"] = 2, ["y"] = 2, ["param1"] = 15, ["z"] = 23, ["name"] = "default:sign_wall_steel"}, {["x"] = 4, ["meta"] = {["fields"] = {["infotext"] = "\"Input 7\"", ["text"] = "Input 7", ["formspec"] = "field[text;;${text}]"}, ["inventory"] = {}}, ["param2"] = 2, ["y"] = 2, ["param1"] = 31, ["z"] = 24, ["name"] = "default:sign_wall_steel"}, {["x"] = 4, ["meta"] = {["fields"] = {["infotext"] = "\"Input 8\"", ["text"] = "Input 8", ["formspec"] = "field[text;;${text}]"}, ["inventory"] = {}}, ["param2"] = 2, ["y"] = 2, ["param1"] = 15, ["z"] = 25, ["name"] = "default:sign_wall_steel"}, {["x"] = 4, ["meta"] = {["fields"] = {["infotext"] = "\"Output 1\"", ["text"] = "Output 1", ["formspec"] = "field[text;;${text}]"}, ["inventory"] = {}}, ["param2"] = 2, ["y"] = 2, ["param1"] = 15, ["z"] = 27, ["name"] = "default:sign_wall_steel"}, {["x"] = 4, ["meta"] = {["fields"] = {["infotext"] = "\"Output 2\"", ["text"] = "Output 2", ["formspec"] = "field[text;;${text}]"}, ["inventory"] = {}}, ["param2"] = 2, ["y"] = 2, ["param1"] = 31, ["z"] = 28, ["name"] = "default:sign_wall_steel"}, {["x"] = 4, ["meta"] = {["fields"] = {["infotext"] = "\"Output 3\"", ["text"] = "Output 3", ["formspec"] = "field[text;;${text}]"}, ["inventory"] = {}}, ["param2"] = 2, ["y"] = 2, ["param1"] = 15, ["z"] = 29, ["name"] = "default:sign_wall_steel"}, {["x"] = 4, ["meta"] = {["fields"] = {["infotext"] = "\"Output 4\"", ["text"] = "Output 4", ["formspec"] = "field[text;;${text}]"}, ["inventory"] = {}}, ["param2"] = 2, ["y"] = 2, ["param1"] = 31, ["z"] = 30, ["name"] = "default:sign_wall_steel"}, {["x"] = 4, ["meta"] = {["fields"] = {["infotext"] = "\"Carry Out Overflow (lights if 255 exceeded)\"", ["text"] = "Carry Out Overflow (lights if 255 exceeded)", ["formspec"] = "field[text;;${text}]"}, ["inventory"] = {}}, ["param2"] = 2, ["y"] = 2, ["param1"] = 15, ["z"] = 31, ["name"] = "default:sign_wall_steel"}, {["x"] = 4, ["meta"] = {["fields"] = {["infotext"] = "\"Output 5\"", ["text"] = "Output 5", ["formspec"] = "field[text;;${text}]"}, ["inventory"] = {}}, ["param2"] = 2, ["y"] = 2, ["param1"] = 31, ["z"] = 32, ["name"] = "default:sign_wall_steel"}, {["x"] = 4, ["meta"] = {["fields"] = {["infotext"] = "\"Output 6\"", ["text"] = "Output 6", ["formspec"] = "field[text;;${text}]"}, ["inventory"] = {}}, ["param2"] = 2, ["y"] = 2, ["param1"] = 15, ["z"] = 33, ["name"] = "default:sign_wall_steel"}, {["x"] = 4, ["meta"] = {["fields"] = {["infotext"] = "\"Output 7\"", ["text"] = "Output 7", ["formspec"] = "field[text;;${text}]"}, ["inventory"] = {}}, ["param2"] = 2, ["y"] = 2, ["param1"] = 31, ["z"] = 34, ["name"] = "default:sign_wall_steel"}, {["x"] = 4, ["meta"] = {["fields"] = {["infotext"] = "\"Output 8\"", ["text"] = "Output 8", ["formspec"] = "field[text;;${text}]"}, ["inventory"] = {}}, ["param2"] = 2, ["y"] = 2, ["param1"] = 15, ["z"] = 35, ["name"] = "default:sign_wall_steel"}, {["x"] = 4, ["meta"] = {["fields"] = {["infotext"] = "\"Input / Output 1\"", ["text"] = "Input / Output 1", ["formspec"] = "field[text;;${text}]"}, ["inventory"] = {}}, ["param2"] = 2, ["y"] = 2, ["param1"] = 15, ["z"] = 37, ["name"] = "default:sign_wall_steel"}, {["x"] = 4, ["meta"] = {["fields"] = {["infotext"] = "\"Input / Output 2\"", ["text"] = "Input / Output 2", ["formspec"] = "field[text;;${text}]"}, ["inventory"] = {}}, ["param2"] = 2, ["y"] = 2, ["param1"] = 31, ["z"] = 38, ["name"] = "default:sign_wall_steel"}, {["x"] = 4, ["meta"] = {["fields"] = {["infotext"] = "\"Input / Output 3\"", ["text"] = "Input / Output 3", ["formspec"] = "field[text;;${text}]"}, ["inventory"] = {}}, ["param2"] = 2, ["y"] = 2, ["param1"] = 15, ["z"] = 39, ["name"] = "default:sign_wall_steel"}, {["x"] = 4, ["meta"] = {["fields"] = {["infotext"] = "\"Input / Output 4\"", ["text"] = "Input / Output 4", ["formspec"] = "field[text;;${text}]"}, ["inventory"] = {}}, ["param2"] = 2, ["y"] = 2, ["param1"] = 31, ["z"] = 40, ["name"] = "default:sign_wall_steel"}, {["x"] = 4, ["meta"] = {["fields"] = {["infotext"] = "\"Input / Output 5\"", ["text"] = "Input / Output 5", ["formspec"] = "field[text;;${text}]"}, ["inventory"] = {}}, ["param2"] = 2, ["y"] = 2, ["param1"] = 15, ["z"] = 41, ["name"] = "default:sign_wall_steel"}, {["x"] = 4, ["meta"] = {["fields"] = {["infotext"] = "\"Input / Output 6\"", ["text"] = "Input / Output 6", ["formspec"] = "field[text;;${text}]"}, ["inventory"] = {}}, ["param2"] = 2, ["y"] = 2, ["param1"] = 31, ["z"] = 42, ["name"] = "default:sign_wall_steel"}, {["x"] = 4, ["meta"] = {["fields"] = {["infotext"] = "\"Input / Output 7\"", ["text"] = "Input / Output 7", ["formspec"] = "field[text;;${text}]"}, ["inventory"] = {}}, ["param2"] = 2, ["y"] = 2, ["param1"] = 15, ["z"] = 43, ["name"] = "default:sign_wall_steel"}, {["x"] = 4, ["meta"] = {["fields"] = {["infotext"] = "\"Input / Output 8\"", ["text"] = "Input / Output 8", ["formspec"] = "field[text;;${text}]"}, ["inventory"] = {}}, ["param2"] = 2, ["y"] = 2, ["param1"] = 31, ["z"] = 44, ["name"] = "default:sign_wall_steel"}, {["x"] = 4, ["meta"] = {["fields"] = {["infotext"] = "\"8 Bit Ripple Adder v.2                                                                             Entered numbers are converted to binary, then added using nothing but logic gates. The binary sum is then converted back to decimal notation for display. If you enter two numbers whose sum exceeds 255, the numbers displayed will not be correct.\"", ["formspec"] = "field[text;;${text}]", ["text"] = "8 Bit Ripple Adder v.2                                                                             Entered numbers are converted to binary, then added using nothing but logic gates. The binary sum is then converted back to decimal notation for display. If you enter two numbers whose sum exceeds 255, the numbers displayed will not be correct."}, ["inventory"] = {}}, ["param2"] = 2, ["y"] = 3, ["param1"] = 47, ["z"] = 5, ["name"] = "default:sign_wall_steel"}, {["x"] = 4, ["meta"] = {["fields"] = {["infotext"] = " ", ["channel"] = "displaya", ["text"] = " ", ["formspec"] = "field[channel;Channel;${channel}]"}, ["inventory"] = {}}, ["param2"] = 2, ["y"] = 3, ["param1"] = 111, ["z"] = 9, ["name"] = "digilines:lcd"}, {["x"] = 4, ["meta"] = {["fields"] = {["infotext"] = " ", ["channel"] = "displayb", ["text"] = " ", ["formspec"] = "field[channel;Channel;${channel}]"}, ["inventory"] = {}}, ["param2"] = 2, ["y"] = 3, ["param1"] = 111, ["z"] = 10, ["name"] = "digilines:lcd"}, {["x"] = 4, ["meta"] = {["fields"] = {["infotext"] = " ", ["channel"] = "displaysum", ["text"] = " ", ["formspec"] = "field[channel;Channel;${channel}]"}, ["inventory"] = {}}, ["param2"] = 2, ["y"] = 3, ["param1"] = 111, ["z"] = 11, ["name"] = "digilines:lcd"}, {["x"] = 4, ["meta"] = {["fields"] = {["infotext"] = "\"Lights if sum exceeds 255 (sum will be wrong)\"", ["text"] = "Lights if sum exceeds 255 (sum will be wrong)", ["formspec"] = "field[text;;${text}]"}, ["inventory"] = {}}, ["param2"] = 2, ["y"] = 4, ["param1"] = 63, ["z"] = 7, ["name"] = "default:sign_wall_steel"}, {["x"] = 4, ["meta"] = {["fields"] = {["infotext"] = "\"Input A\"", ["formspec"] = "field[text;;${text}]", ["text"] = "Input A"}, ["inventory"] = {}}, ["param2"] = 2, ["y"] = 4, ["param1"] = 95, ["z"] = 9, ["name"] = "default:sign_wall_steel"}, {["x"] = 4, ["meta"] = {["fields"] = {["infotext"] = "\"Input B\"", ["formspec"] = "field[text;;${text}]", ["text"] = "Input B"}, ["inventory"] = {}}, ["param2"] = 2, ["y"] = 4, ["param1"] = 95, ["z"] = 10, ["name"] = "default:sign_wall_steel"}, {["x"] = 4, ["meta"] = {["fields"] = {["infotext"] = "\"Sum\"", ["formspec"] = "field[text;;${text}]", ["text"] = "Sum"}, ["inventory"] = {}}, ["param2"] = 2, ["y"] = 4, ["param1"] = 95, ["z"] = 11, ["name"] = "default:sign_wall_steel"}, {["x"] = 5, ["y"] = 0, ["param1"] = 12, ["z"] = 0, ["name"] = "default:desert_sandstone_block"}, {["x"] = 5, ["y"] = 0, ["param1"] = 18, ["z"] = 1, ["name"] = "default:silver_sandstone_block"}, {["x"] = 5, ["y"] = 0, ["param1"] = 18, ["z"] = 2, ["name"] = "default:silver_sandstone_block"}, {["x"] = 5, ["y"] = 0, ["param1"] = 18, ["z"] = 3, ["name"] = "default:silver_sandstone_block"}, {["x"] = 5, ["y"] = 0, ["param1"] = 18, ["z"] = 4, ["name"] = "default:silver_sandstone_block"}, {["x"] = 5, ["y"] = 0, ["param1"] = 18, ["z"] = 5, ["name"] = "default:silver_sandstone_block"}, {["x"] = 5, ["y"] = 0, ["param1"] = 18, ["z"] = 6, ["name"] = "default:silver_sandstone_block"}, {["x"] = 5, ["y"] = 0, ["param1"] = 18, ["z"] = 7, ["name"] = "default:silver_sandstone_block"}, {["x"] = 5, ["y"] = 0, ["param1"] = 18, ["z"] = 8, ["name"] = "default:silver_sandstone_block"}, {["x"] = 5, ["y"] = 0, ["param1"] = 18, ["z"] = 9, ["name"] = "default:silver_sandstone_block"}, {["x"] = 5, ["y"] = 0, ["param1"] = 18, ["z"] = 10, ["name"] = "default:silver_sandstone_block"}, {["x"] = 5, ["y"] = 0, ["param1"] = 18, ["z"] = 11, ["name"] = "default:silver_sandstone_block"}, {["x"] = 5, ["y"] = 0, ["param1"] = 18, ["z"] = 12, ["name"] = "default:silver_sandstone_block"}, {["x"] = 5, ["y"] = 0, ["param1"] = 18, ["z"] = 13, ["name"] = "default:silver_sandstone_block"}, {["x"] = 5, ["y"] = 0, ["param1"] = 18, ["z"] = 14, ["name"] = "default:silver_sandstone_block"}, {["x"] = 5, ["y"] = 0, ["param1"] = 18, ["z"] = 15, ["name"] = "default:silver_sandstone_block"}, {["x"] = 5, ["y"] = 0, ["param1"] = 18, ["z"] = 16, ["name"] = "default:silver_sandstone_block"}, {["x"] = 5, ["y"] = 0, ["param1"] = 18, ["z"] = 17, ["name"] = "default:silver_sandstone_block"}, {["x"] = 5, ["y"] = 0, ["param1"] = 18, ["z"] = 18, ["name"] = "default:silver_sandstone_block"}, {["x"] = 5, ["y"] = 0, ["param1"] = 18, ["z"] = 19, ["name"] = "default:silver_sandstone_block"}, {["x"] = 5, ["y"] = 0, ["param1"] = 18, ["z"] = 20, ["name"] = "default:silver_sandstone_block"}, {["x"] = 5, ["y"] = 0, ["param1"] = 18, ["z"] = 21, ["name"] = "default:silver_sandstone_block"}, {["x"] = 5, ["y"] = 0, ["param1"] = 18, ["z"] = 22, ["name"] = "default:silver_sandstone_block"}, {["x"] = 5, ["y"] = 0, ["param1"] = 18, ["z"] = 23, ["name"] = "default:silver_sandstone_block"}, {["x"] = 5, ["y"] = 0, ["param1"] = 18, ["z"] = 24, ["name"] = "default:silver_sandstone_block"}, {["x"] = 5, ["y"] = 0, ["param1"] = 18, ["z"] = 25, ["name"] = "default:silver_sandstone_block"}, {["x"] = 5, ["y"] = 0, ["param1"] = 18, ["z"] = 26, ["name"] = "default:silver_sandstone_block"}, {["x"] = 5, ["y"] = 0, ["param1"] = 18, ["z"] = 27, ["name"] = "default:silver_sandstone_block"}, {["x"] = 5, ["y"] = 0, ["param1"] = 18, ["z"] = 28, ["name"] = "default:silver_sandstone_block"}, {["x"] = 5, ["y"] = 0, ["param1"] = 18, ["z"] = 29, ["name"] = "default:silver_sandstone_block"}, {["x"] = 5, ["y"] = 0, ["param1"] = 18, ["z"] = 30, ["name"] = "default:silver_sandstone_block"}, {["x"] = 5, ["y"] = 0, ["param1"] = 18, ["z"] = 31, ["name"] = "default:silver_sandstone_block"}, {["x"] = 5, ["y"] = 0, ["param1"] = 18, ["z"] = 32, ["name"] = "default:silver_sandstone_block"}, {["x"] = 5, ["y"] = 0, ["param1"] = 18, ["z"] = 33, ["name"] = "default:silver_sandstone_block"}, {["x"] = 5, ["y"] = 0, ["param1"] = 18, ["z"] = 34, ["name"] = "default:silver_sandstone_block"}, {["x"] = 5, ["y"] = 0, ["param1"] = 18, ["z"] = 35, ["name"] = "default:silver_sandstone_block"}, {["x"] = 5, ["y"] = 0, ["param1"] = 18, ["z"] = 36, ["name"] = "default:silver_sandstone_block"}, {["x"] = 5, ["y"] = 0, ["param1"] = 18, ["z"] = 37, ["name"] = "default:silver_sandstone_block"}, {["x"] = 5, ["y"] = 0, ["param1"] = 18, ["z"] = 38, ["name"] = "default:silver_sandstone_block"}, {["x"] = 5, ["y"] = 0, ["param1"] = 18, ["z"] = 39, ["name"] = "default:silver_sandstone_block"}, {["x"] = 5, ["y"] = 0, ["param1"] = 18, ["z"] = 40, ["name"] = "default:silver_sandstone_block"}, {["x"] = 5, ["y"] = 0, ["param1"] = 18, ["z"] = 41, ["name"] = "default:silver_sandstone_block"}, {["x"] = 5, ["y"] = 0, ["param1"] = 18, ["z"] = 42, ["name"] = "default:silver_sandstone_block"}, {["x"] = 5, ["y"] = 0, ["param1"] = 18, ["z"] = 43, ["name"] = "default:silver_sandstone_block"}, {["x"] = 5, ["y"] = 0, ["param1"] = 18, ["z"] = 44, ["name"] = "default:silver_sandstone_block"}, {["x"] = 5, ["y"] = 0, ["param1"] = 18, ["z"] = 45, ["name"] = "default:silver_sandstone_block"}, {["x"] = 5, ["y"] = 0, ["param1"] = 18, ["z"] = 46, ["name"] = "default:silver_sandstone_block"}, {["x"] = 5, ["y"] = 0, ["param1"] = 18, ["z"] = 47, ["name"] = "default:silver_sandstone_block"}, {["x"] = 5, ["y"] = 0, ["param1"] = 18, ["z"] = 48, ["name"] = "default:silver_sandstone_block"}, {["x"] = 5, ["y"] = 0, ["param1"] = 15, ["z"] = 49, ["name"] = "default:desert_sandstone_block"}, {["x"] = 5, ["y"] = 1, ["param1"] = 16, ["z"] = 4, ["name"] = "default:silver_sandstone"}, {["x"] = 5, ["y"] = 1, ["param1"] = 16, ["z"] = 5, ["name"] = "default:silver_sandstone"}, {["x"] = 5, ["y"] = 1, ["param1"] = 16, ["z"] = 6, ["name"] = "default:silver_sandstone"}, {["x"] = 5, ["y"] = 1, ["param1"] = 16, ["z"] = 7, ["name"] = "default:silver_sandstone"}, {["x"] = 5, ["y"] = 1, ["param1"] = 16, ["z"] = 8, ["name"] = "default:silver_sandstone"}, {["x"] = 5, ["y"] = 1, ["param1"] = 16, ["z"] = 9, ["name"] = "default:silver_sandstone"}, {["x"] = 5, ["y"] = 1, ["param1"] = 16, ["z"] = 10, ["name"] = "default:silver_sandstone"}, {["x"] = 5, ["y"] = 1, ["param1"] = 16, ["z"] = 11, ["name"] = "default:silver_sandstone"}, {["x"] = 5, ["y"] = 1, ["param1"] = 16, ["z"] = 12, ["name"] = "default:silver_sandstone"}, {["x"] = 5, ["y"] = 1, ["param1"] = 16, ["z"] = 17, ["name"] = "default:silver_sandstone"}, {["x"] = 5, ["y"] = 1, ["param1"] = 62, ["z"] = 18, ["name"] = "default:mese"}, {["x"] = 5, ["y"] = 1, ["param1"] = 46, ["z"] = 19, ["name"] = "mesecons_insulated:insulated_off"}, {["x"] = 5, ["y"] = 1, ["param1"] = 62, ["z"] = 20, ["name"] = "default:mese"}, {["x"] = 5, ["y"] = 1, ["param1"] = 46, ["z"] = 21, ["name"] = "mesecons_insulated:insulated_off"}, {["x"] = 5, ["y"] = 1, ["param1"] = 62, ["z"] = 22, ["name"] = "default:mese"}, {["x"] = 5, ["y"] = 1, ["param1"] = 46, ["z"] = 23, ["name"] = "mesecons_insulated:insulated_off"}, {["x"] = 5, ["y"] = 1, ["param1"] = 62, ["z"] = 24, ["name"] = "default:mese"}, {["x"] = 5, ["y"] = 1, ["param1"] = 46, ["z"] = 25, ["name"] = "mesecons_insulated:insulated_off"}, {["x"] = 5, ["y"] = 1, ["param1"] = 16, ["z"] = 26, ["name"] = "default:silver_sandstone"}, {["x"] = 5, ["y"] = 1, ["param1"] = 46, ["z"] = 27, ["name"] = "mesecons_insulated:insulated_off"}, {["x"] = 5, ["y"] = 1, ["param1"] = 62, ["z"] = 28, ["name"] = "default:mese"}, {["x"] = 5, ["y"] = 1, ["param1"] = 46, ["z"] = 29, ["name"] = "mesecons_insulated:insulated_off"}, {["x"] = 5, ["y"] = 1, ["param1"] = 62, ["z"] = 30, ["name"] = "default:mese"}, {["x"] = 5, ["y"] = 1, ["param1"] = 46, ["z"] = 31, ["name"] = "mesecons_insulated:insulated_off"}, {["x"] = 5, ["y"] = 1, ["param1"] = 62, ["z"] = 32, ["name"] = "default:mese"}, {["x"] = 5, ["y"] = 1, ["param1"] = 46, ["z"] = 33, ["name"] = "mesecons_insulated:insulated_off"}, {["x"] = 5, ["y"] = 1, ["param1"] = 62, ["z"] = 34, ["name"] = "default:mese"}, {["x"] = 5, ["y"] = 1, ["param1"] = 46, ["z"] = 35, ["name"] = "mesecons_insulated:insulated_off"}, {["x"] = 5, ["y"] = 1, ["param1"] = 16, ["z"] = 36, ["name"] = "default:silver_sandstone"}, {["x"] = 5, ["param2"] = 2, ["y"] = 1, ["param1"] = 46, ["z"] = 37, ["name"] = "mesecons_insulated:insulated_off"}, {["x"] = 5, ["y"] = 1, ["param1"] = 62, ["z"] = 38, ["name"] = "default:mese"}, {["x"] = 5, ["param2"] = 2, ["y"] = 1, ["param1"] = 46, ["z"] = 39, ["name"] = "mesecons_insulated:insulated_off"}, {["x"] = 5, ["y"] = 1, ["param1"] = 62, ["z"] = 40, ["name"] = "default:mese"}, {["x"] = 5, ["param2"] = 2, ["y"] = 1, ["param1"] = 46, ["z"] = 41, ["name"] = "mesecons_insulated:insulated_off"}, {["x"] = 5, ["y"] = 1, ["param1"] = 62, ["z"] = 42, ["name"] = "default:mese"}, {["x"] = 5, ["param2"] = 2, ["y"] = 1, ["param1"] = 46, ["z"] = 43, ["name"] = "mesecons_insulated:insulated_off"}, {["x"] = 5, ["y"] = 1, ["param1"] = 62, ["z"] = 44, ["name"] = "default:mese"}, {["x"] = 5, ["y"] = 1, ["param1"] = 16, ["z"] = 45, ["name"] = "default:silver_sandstone"}, {["x"] = 5, ["y"] = 2, ["param1"] = 16, ["z"] = 4, ["name"] = "default:silver_sandstone"}, {["x"] = 5, ["y"] = 2, ["param1"] = 16, ["z"] = 5, ["name"] = "default:silver_sandstone"}, {["x"] = 5, ["y"] = 2, ["param1"] = 16, ["z"] = 6, ["name"] = "default:silver_sandstone"}, {["x"] = 5, ["y"] = 2, ["param1"] = 16, ["z"] = 7, ["name"] = "default:silver_sandstone"}, {["x"] = 5, ["y"] = 2, ["param1"] = 16, ["z"] = 8, ["name"] = "default:silver_sandstone"}, {["x"] = 5, ["param2"] = 1, ["y"] = 2, ["param1"] = 78, ["z"] = 9, ["name"] = "digilines:wire_std_00110001"}, {["x"] = 5, ["param2"] = 1, ["y"] = 2, ["param1"] = 78, ["z"] = 10, ["name"] = "digilines:wire_std_11110011"}, {["x"] = 5, ["meta"] = {["fields"] = {["real_portstates"] = "1", ["code"] = "function toBits(num,bits)\13    -- returns a binary number based on an integer input.\13    bits = bits or math.max(1, select(2, math.frexp(num)))\13    local t = {} -- will contain the bits        \13    for b = bits, 1, -1 do\13        t[b] = math.fmod(num, 2)\13        num = math.floor((num - t[b]) / 2)\13    end\13    return t\13end\13\13function ReverseTable(t)\13  -- reverses the order of a table array\13  local reversedTable = {}\13  local itemCount = #t\13  for k, v in ipairs(t) do\13      reversedTable[itemCount + 1 - k] = v\13  end\13  return reversedTable\13end\13\13if (event.type == \"on\" and event.pin.name == \"A\") then\13  -- reset the adders and displays\13  digiline_send(\"displaya\",\" \")\13  digiline_send(\"outputa\", {})\13  digiline_send(\"displayb\",\" \")\13  digiline_send(\"outputb\", {})\13  digiline_send(\"displaysum\",\" \")\13end\13\13if event.type == \"digiline\" and event.msg then\13  x = event.msg\13  if event.channel == \"inputa\" then\13    digiline_send(\"displaya\",x .. \" (\" .. string.format(\"%08d\", table.concat(toBits(x))) .. \")\")\13    digiline_send(\"outputa\", ReverseTable(toBits(x)))\13    port.c = true -- send signal to delayer\13  end\13  if event.channel == \"inputb\" then\13    digiline_send(\"displayb\",x .. \" (\" .. string.format(\"%08d\", table.concat(toBits(x))) .. \")\")\13    digiline_send(\"outputb\", ReverseTable(toBits(x)))\13    port.c = true -- send signal to delayer\13  end\13  if event.channel == \"off\" then\13    port.c = false -- reset port to delayer\13  end\13end", ["formspec"] = "size[12,10]background[-0.2,-0.25;12.4,10.75;jeija_luac_background.png]label[0.1,8.3;]textarea[0.2,0.2;12.2,9.5;code;;function toBits(num\\,bits)\13    -- returns a binary number based on an integer input.\13    bits = bits or math.max(1\\, select(2\\, math.frexp(num)))\13    local t = {} -- will contain the bits        \13    for b = bits\\, 1\\, -1 do\13        t\\[b\\] = math.fmod(num\\, 2)\13        num = math.floor((num - t\\[b\\]) / 2)\13    end\13    return t\13end\13\13function ReverseTable(t)\13  -- reverses the order of a table array\13  local reversedTable = {}\13  local itemCount = #t\13  for k\\, v in ipairs(t) do\13      reversedTable\\[itemCount + 1 - k\\] = v\13  end\13  return reversedTable\13end\13\13if (event.type == \"on\" and event.pin.name == \"A\") then\13  -- reset the adders and displays\13  digiline_send(\"displaya\"\\,\" \")\13  digiline_send(\"outputa\"\\, {})\13  digiline_send(\"displayb\"\\,\" \")\13  digiline_send(\"outputb\"\\, {})\13  digiline_send(\"displaysum\"\\,\" \")\13end\13\13if event.type == \"digiline\" and event.msg then\13  x = event.msg\13  if event.channel == \"inputa\" then\13    digiline_send(\"displaya\"\\,x .. \" (\" .. string.format(\"%08d\"\\, table.concat(toBits(x))) .. \")\")\13    digiline_send(\"outputa\"\\, ReverseTable(toBits(x)))\13    port.c = true -- send signal to delayer\13  end\13  if event.channel == \"inputb\" then\13    digiline_send(\"displayb\"\\,x .. \" (\" .. string.format(\"%08d\"\\, table.concat(toBits(x))) .. \")\")\13    digiline_send(\"outputb\"\\, ReverseTable(toBits(x)))\13    port.c = true -- send signal to delayer\13  end\13  if event.channel == \"off\" then\13    port.c = false -- reset port to delayer\13  end\13end]image_button[4.75,8.75;2.5,1;jeija_luac_runbutton.png;program;]image_button_exit[11.72,-0.25;0.425,0.4;jeija_close_window.png;exit;]", ["lc_memory"] = "return {}", ["ignore_offevents"] = "return {[\"B\"] = true, [\"C\"] = true}", ["luac_id"] = "65376"}, ["inventory"] = {}}, ["y"] = 2, ["param1"] = 78, ["z"] = 11, ["name"] = "mesecons_luacontroller:luacontroller0000"}, {["x"] = 5, ["y"] = 2, ["param1"] = 16, ["z"] = 12, ["name"] = "default:silver_sandstone"}, {["x"] = 5, ["y"] = 2, ["param1"] = 16, ["z"] = 17, ["name"] = "default:silver_sandstone"}, {["x"] = 5, ["y"] = 2, ["param1"] = 16, ["z"] = 18, ["name"] = "default:silver_sandstone"}, {["x"] = 5, ["y"] = 2, ["param1"] = 16, ["z"] = 19, ["name"] = "default:silver_sandstone"}, {["x"] = 5, ["y"] = 2, ["param1"] = 16, ["z"] = 20, ["name"] = "default:silver_sandstone"}, {["x"] = 5, ["y"] = 2, ["param1"] = 16, ["z"] = 21, ["name"] = "default:silver_sandstone"}, {["x"] = 5, ["y"] = 2, ["param1"] = 16, ["z"] = 22, ["name"] = "default:silver_sandstone"}, {["x"] = 5, ["y"] = 2, ["param1"] = 16, ["z"] = 23, ["name"] = "default:silver_sandstone"}, {["x"] = 5, ["y"] = 2, ["param1"] = 16, ["z"] = 24, ["name"] = "default:silver_sandstone"}, {["x"] = 5, ["y"] = 2, ["param1"] = 16, ["z"] = 25, ["name"] = "default:silver_sandstone"}, {["x"] = 5, ["y"] = 2, ["param1"] = 16, ["z"] = 26, ["name"] = "default:silver_sandstone"}, {["x"] = 5, ["y"] = 2, ["param1"] = 16, ["z"] = 27, ["name"] = "default:silver_sandstone"}, {["x"] = 5, ["y"] = 2, ["param1"] = 16, ["z"] = 28, ["name"] = "default:silver_sandstone"}, {["x"] = 5, ["y"] = 2, ["param1"] = 16, ["z"] = 29, ["name"] = "default:silver_sandstone"}, {["x"] = 5, ["y"] = 2, ["param1"] = 16, ["z"] = 30, ["name"] = "default:silver_sandstone"}, {["x"] = 5, ["y"] = 2, ["param1"] = 16, ["z"] = 31, ["name"] = "default:silver_sandstone"}, {["x"] = 5, ["y"] = 2, ["param1"] = 16, ["z"] = 32, ["name"] = "default:silver_sandstone"}, {["x"] = 5, ["y"] = 2, ["param1"] = 16, ["z"] = 33, ["name"] = "default:silver_sandstone"}, {["x"] = 5, ["y"] = 2, ["param1"] = 16, ["z"] = 34, ["name"] = "default:silver_sandstone"}, {["x"] = 5, ["y"] = 2, ["param1"] = 16, ["z"] = 35, ["name"] = "default:silver_sandstone"}, {["x"] = 5, ["y"] = 2, ["param1"] = 16, ["z"] = 36, ["name"] = "default:silver_sandstone"}, {["x"] = 5, ["y"] = 2, ["param1"] = 16, ["z"] = 37, ["name"] = "default:silver_sandstone"}, {["x"] = 5, ["y"] = 2, ["param1"] = 16, ["z"] = 38, ["name"] = "default:silver_sandstone"}, {["x"] = 5, ["y"] = 2, ["param1"] = 16, ["z"] = 39, ["name"] = "default:silver_sandstone"}, {["x"] = 5, ["y"] = 2, ["param1"] = 16, ["z"] = 40, ["name"] = "default:silver_sandstone"}, {["x"] = 5, ["y"] = 2, ["param1"] = 16, ["z"] = 41, ["name"] = "default:silver_sandstone"}, {["x"] = 5, ["y"] = 2, ["param1"] = 16, ["z"] = 42, ["name"] = "default:silver_sandstone"}, {["x"] = 5, ["y"] = 2, ["param1"] = 16, ["z"] = 43, ["name"] = "default:silver_sandstone"}, {["x"] = 5, ["y"] = 2, ["param1"] = 16, ["z"] = 44, ["name"] = "default:silver_sandstone"}, {["x"] = 5, ["y"] = 2, ["param1"] = 16, ["z"] = 45, ["name"] = "default:silver_sandstone"}, {["x"] = 5, ["y"] = 3, ["param1"] = 16, ["z"] = 4, ["name"] = "default:silver_sandstone"}, {["x"] = 5, ["y"] = 3, ["param1"] = 16, ["z"] = 5, ["name"] = "default:silver_sandstone"}, {["x"] = 5, ["y"] = 3, ["param1"] = 16, ["z"] = 6, ["name"] = "default:silver_sandstone"}, {["x"] = 5, ["y"] = 3, ["z"] = 7, ["name"] = "mesecons_lightstone:lightstone_red_off"}, {["x"] = 5, ["y"] = 3, ["param1"] = 16, ["z"] = 8, ["name"] = "default:silver_sandstone"}, {["x"] = 5, ["param2"] = 1, ["y"] = 3, ["param1"] = 94, ["z"] = 11, ["name"] = "digilines:wire_std_10010000"}, {["x"] = 5, ["y"] = 3, ["param1"] = 16, ["z"] = 12, ["name"] = "default:silver_sandstone"}, {["x"] = 5, ["y"] = 3, ["param1"] = 16, ["z"] = 17, ["name"] = "default:silver_sandstone"}, {["x"] = 5, ["y"] = 3, ["z"] = 18, ["name"] = "mesecons_lightstone:lightstone_red_off"}, {["x"] = 5, ["y"] = 3, ["z"] = 19, ["name"] = "mesecons_lightstone:lightstone_red_off"}, {["x"] = 5, ["y"] = 3, ["z"] = 20, ["name"] = "mesecons_lightstone:lightstone_red_off"}, {["x"] = 5, ["y"] = 3, ["z"] = 21, ["name"] = "mesecons_lightstone:lightstone_red_off"}, {["x"] = 5, ["y"] = 3, ["z"] = 22, ["name"] = "mesecons_lightstone:lightstone_red_off"}, {["x"] = 5, ["y"] = 3, ["z"] = 23, ["name"] = "mesecons_lightstone:lightstone_red_off"}, {["x"] = 5, ["y"] = 3, ["z"] = 24, ["name"] = "mesecons_lightstone:lightstone_red_off"}, {["x"] = 5, ["y"] = 3, ["z"] = 25, ["name"] = "mesecons_lightstone:lightstone_red_off"}, {["x"] = 5, ["y"] = 3, ["param1"] = 16, ["z"] = 26, ["name"] = "default:silver_sandstone"}, {["x"] = 5, ["y"] = 3, ["z"] = 27, ["name"] = "mesecons_lightstone:lightstone_red_off"}, {["x"] = 5, ["y"] = 3, ["z"] = 28, ["name"] = "mesecons_lightstone:lightstone_red_off"}, {["x"] = 5, ["y"] = 3, ["z"] = 29, ["name"] = "mesecons_lightstone:lightstone_red_off"}, {["x"] = 5, ["y"] = 3, ["z"] = 30, ["name"] = "mesecons_lightstone:lightstone_red_off"}, {["x"] = 5, ["y"] = 3, ["z"] = 31, ["name"] = "mesecons_lightstone:lightstone_yellow_off"}, {["x"] = 5, ["y"] = 3, ["z"] = 32, ["name"] = "mesecons_lightstone:lightstone_red_off"}, {["x"] = 5, ["y"] = 3, ["z"] = 33, ["name"] = "mesecons_lightstone:lightstone_red_off"}, {["x"] = 5, ["y"] = 3, ["z"] = 34, ["name"] = "mesecons_lightstone:lightstone_red_off"}, {["x"] = 5, ["y"] = 3, ["z"] = 35, ["name"] = "mesecons_lightstone:lightstone_red_off"}, {["x"] = 5, ["y"] = 3, ["param1"] = 16, ["z"] = 36, ["name"] = "default:silver_sandstone"}, {["x"] = 5, ["y"] = 3, ["z"] = 37, ["name"] = "mesecons_lightstone:lightstone_red_off"}, {["x"] = 5, ["y"] = 3, ["z"] = 38, ["name"] = "mesecons_lightstone:lightstone_red_off"}, {["x"] = 5, ["y"] = 3, ["z"] = 39, ["name"] = "mesecons_lightstone:lightstone_red_off"}, {["x"] = 5, ["y"] = 3, ["z"] = 40, ["name"] = "mesecons_lightstone:lightstone_red_off"}, {["x"] = 5, ["y"] = 3, ["z"] = 41, ["name"] = "mesecons_lightstone:lightstone_red_off"}, {["x"] = 5, ["y"] = 3, ["z"] = 42, ["name"] = "mesecons_lightstone:lightstone_red_off"}, {["x"] = 5, ["y"] = 3, ["z"] = 43, ["name"] = "mesecons_lightstone:lightstone_red_off"}, {["x"] = 5, ["y"] = 3, ["z"] = 44, ["name"] = "mesecons_lightstone:lightstone_red_off"}, {["x"] = 5, ["y"] = 3, ["param1"] = 16, ["z"] = 45, ["name"] = "default:silver_sandstone"}, {["x"] = 5, ["y"] = 4, ["param1"] = 16, ["z"] = 4, ["name"] = "default:silver_sandstone"}, {["x"] = 5, ["y"] = 4, ["param1"] = 16, ["z"] = 5, ["name"] = "default:silver_sandstone"}, {["x"] = 5, ["y"] = 4, ["param1"] = 16, ["z"] = 6, ["name"] = "default:silver_sandstone"}, {["x"] = 5, ["y"] = 4, ["param1"] = 16, ["z"] = 7, ["name"] = "default:silver_sandstone"}, {["x"] = 5, ["y"] = 4, ["param1"] = 16, ["z"] = 8, ["name"] = "default:silver_sandstone"}, {["x"] = 5, ["y"] = 4, ["param1"] = 16, ["z"] = 9, ["name"] = "default:silver_sandstone"}, {["x"] = 5, ["y"] = 4, ["param1"] = 16, ["z"] = 10, ["name"] = "default:silver_sandstone"}, {["x"] = 5, ["y"] = 4, ["param1"] = 16, ["z"] = 11, ["name"] = "default:silver_sandstone"}, {["x"] = 5, ["y"] = 4, ["param1"] = 16, ["z"] = 12, ["name"] = "default:silver_sandstone"}, {["x"] = 5, ["y"] = 4, ["param1"] = 14, ["z"] = 17, ["name"] = "stairs:slab_silver_sandstone"}, {["x"] = 5, ["y"] = 4, ["param1"] = 14, ["z"] = 18, ["name"] = "stairs:slab_silver_sandstone"}, {["x"] = 5, ["y"] = 4, ["param1"] = 30, ["z"] = 19, ["name"] = "stairs:slab_silver_sandstone"}, {["x"] = 5, ["y"] = 4, ["param1"] = 14, ["z"] = 20, ["name"] = "stairs:slab_silver_sandstone"}, {["x"] = 5, ["y"] = 4, ["param1"] = 30, ["z"] = 21, ["name"] = "stairs:slab_silver_sandstone"}, {["x"] = 5, ["y"] = 4, ["param1"] = 14, ["z"] = 22, ["name"] = "stairs:slab_silver_sandstone"}, {["x"] = 5, ["y"] = 4, ["param1"] = 30, ["z"] = 23, ["name"] = "stairs:slab_silver_sandstone"}, {["x"] = 5, ["y"] = 4, ["param1"] = 14, ["z"] = 24, ["name"] = "stairs:slab_silver_sandstone"}, {["x"] = 5, ["y"] = 4, ["param1"] = 30, ["z"] = 25, ["name"] = "stairs:slab_silver_sandstone"}, {["x"] = 5, ["y"] = 4, ["param1"] = 14, ["z"] = 26, ["name"] = "default:silver_sandstone"}, {["x"] = 5, ["y"] = 4, ["param1"] = 30, ["z"] = 27, ["name"] = "stairs:slab_silver_sandstone"}, {["x"] = 5, ["y"] = 4, ["param1"] = 14, ["z"] = 28, ["name"] = "stairs:slab_silver_sandstone"}, {["x"] = 5, ["y"] = 4, ["param1"] = 30, ["z"] = 29, ["name"] = "stairs:slab_silver_sandstone"}, {["x"] = 5, ["y"] = 4, ["param1"] = 14, ["z"] = 30, ["name"] = "stairs:slab_silver_sandstone"}, {["x"] = 5, ["y"] = 4, ["param1"] = 30, ["z"] = 31, ["name"] = "stairs:slab_silver_sandstone"}, {["x"] = 5, ["y"] = 4, ["param1"] = 14, ["z"] = 32, ["name"] = "stairs:slab_silver_sandstone"}, {["x"] = 5, ["y"] = 4, ["param1"] = 30, ["z"] = 33, ["name"] = "stairs:slab_silver_sandstone"}, {["x"] = 5, ["y"] = 4, ["param1"] = 14, ["z"] = 34, ["name"] = "stairs:slab_silver_sandstone"}, {["x"] = 5, ["y"] = 4, ["param1"] = 30, ["z"] = 35, ["name"] = "stairs:slab_silver_sandstone"}, {["x"] = 5, ["y"] = 4, ["param1"] = 14, ["z"] = 36, ["name"] = "default:silver_sandstone"}, {["x"] = 5, ["y"] = 4, ["param1"] = 30, ["z"] = 37, ["name"] = "stairs:slab_silver_sandstone"}, {["x"] = 5, ["y"] = 4, ["param1"] = 14, ["z"] = 38, ["name"] = "stairs:slab_silver_sandstone"}, {["x"] = 5, ["y"] = 4, ["param1"] = 30, ["z"] = 39, ["name"] = "stairs:slab_silver_sandstone"}, {["x"] = 5, ["y"] = 4, ["param1"] = 14, ["z"] = 40, ["name"] = "stairs:slab_silver_sandstone"}, {["x"] = 5, ["y"] = 4, ["param1"] = 30, ["z"] = 41, ["name"] = "stairs:slab_silver_sandstone"}, {["x"] = 5, ["y"] = 4, ["param1"] = 14, ["z"] = 42, ["name"] = "stairs:slab_silver_sandstone"}, {["x"] = 5, ["y"] = 4, ["param1"] = 30, ["z"] = 43, ["name"] = "stairs:slab_silver_sandstone"}, {["x"] = 5, ["y"] = 4, ["param1"] = 14, ["z"] = 44, ["name"] = "stairs:slab_silver_sandstone"}, {["x"] = 5, ["y"] = 4, ["param1"] = 14, ["z"] = 45, ["name"] = "stairs:slab_silver_sandstone"}, {["x"] = 6, ["y"] = 0, ["param1"] = 12, ["z"] = 0, ["name"] = "default:desert_sandstone_block"}, {["x"] = 6, ["y"] = 0, ["param1"] = 18, ["z"] = 1, ["name"] = "default:silver_sandstone_block"}, {["x"] = 6, ["y"] = 0, ["param1"] = 18, ["z"] = 2, ["name"] = "default:silver_sandstone_block"}, {["x"] = 6, ["y"] = 0, ["param1"] = 18, ["z"] = 3, ["name"] = "default:silver_sandstone_block"}, {["x"] = 6, ["y"] = 0, ["param1"] = 18, ["z"] = 4, ["name"] = "default:silver_sandstone_block"}, {["x"] = 6, ["y"] = 0, ["param1"] = 18, ["z"] = 5, ["name"] = "default:silver_sandstone_block"}, {["x"] = 6, ["y"] = 0, ["param1"] = 18, ["z"] = 6, ["name"] = "default:silver_sandstone_block"}, {["x"] = 6, ["y"] = 0, ["param1"] = 18, ["z"] = 7, ["name"] = "default:silver_sandstone_block"}, {["x"] = 6, ["y"] = 0, ["param1"] = 18, ["z"] = 8, ["name"] = "default:silver_sandstone_block"}, {["x"] = 6, ["y"] = 0, ["param1"] = 18, ["z"] = 9, ["name"] = "default:silver_sandstone_block"}, {["x"] = 6, ["y"] = 0, ["param1"] = 18, ["z"] = 10, ["name"] = "default:silver_sandstone_block"}, {["x"] = 6, ["y"] = 0, ["param1"] = 18, ["z"] = 11, ["name"] = "default:silver_sandstone_block"}, {["x"] = 6, ["y"] = 0, ["param1"] = 18, ["z"] = 12, ["name"] = "default:silver_sandstone_block"}, {["x"] = 6, ["y"] = 0, ["param1"] = 18, ["z"] = 13, ["name"] = "default:silver_sandstone_block"}, {["x"] = 6, ["y"] = 0, ["param1"] = 18, ["z"] = 14, ["name"] = "default:silver_sandstone_block"}, {["x"] = 6, ["y"] = 0, ["param1"] = 18, ["z"] = 15, ["name"] = "default:silver_sandstone_block"}, {["x"] = 6, ["y"] = 0, ["param1"] = 18, ["z"] = 16, ["name"] = "default:silver_sandstone_block"}, {["x"] = 6, ["y"] = 0, ["param1"] = 18, ["z"] = 17, ["name"] = "default:silver_sandstone_block"}, {["x"] = 6, ["y"] = 0, ["param1"] = 18, ["z"] = 18, ["name"] = "default:silver_sandstone_block"}, {["x"] = 6, ["y"] = 0, ["param1"] = 18, ["z"] = 19, ["name"] = "default:silver_sandstone_block"}, {["x"] = 6, ["y"] = 0, ["param1"] = 18, ["z"] = 20, ["name"] = "default:silver_sandstone_block"}, {["x"] = 6, ["y"] = 0, ["param1"] = 18, ["z"] = 21, ["name"] = "default:silver_sandstone_block"}, {["x"] = 6, ["y"] = 0, ["param1"] = 18, ["z"] = 22, ["name"] = "default:silver_sandstone_block"}, {["x"] = 6, ["y"] = 0, ["param1"] = 18, ["z"] = 23, ["name"] = "default:silver_sandstone_block"}, {["x"] = 6, ["y"] = 0, ["param1"] = 18, ["z"] = 24, ["name"] = "default:silver_sandstone_block"}, {["x"] = 6, ["y"] = 0, ["param1"] = 18, ["z"] = 25, ["name"] = "default:silver_sandstone_block"}, {["x"] = 6, ["y"] = 0, ["param1"] = 18, ["z"] = 26, ["name"] = "default:silver_sandstone_block"}, {["x"] = 6, ["y"] = 0, ["param1"] = 18, ["z"] = 27, ["name"] = "default:silver_sandstone_block"}, {["x"] = 6, ["y"] = 0, ["param1"] = 18, ["z"] = 28, ["name"] = "default:silver_sandstone_block"}, {["x"] = 6, ["y"] = 0, ["param1"] = 18, ["z"] = 29, ["name"] = "default:silver_sandstone_block"}, {["x"] = 6, ["y"] = 0, ["param1"] = 18, ["z"] = 30, ["name"] = "default:silver_sandstone_block"}, {["x"] = 6, ["y"] = 0, ["param1"] = 18, ["z"] = 31, ["name"] = "default:silver_sandstone_block"}, {["x"] = 6, ["y"] = 0, ["param1"] = 18, ["z"] = 32, ["name"] = "default:silver_sandstone_block"}, {["x"] = 6, ["y"] = 0, ["param1"] = 18, ["z"] = 33, ["name"] = "default:silver_sandstone_block"}, {["x"] = 6, ["y"] = 0, ["param1"] = 18, ["z"] = 34, ["name"] = "default:silver_sandstone_block"}, {["x"] = 6, ["y"] = 0, ["param1"] = 18, ["z"] = 35, ["name"] = "default:silver_sandstone_block"}, {["x"] = 6, ["y"] = 0, ["param1"] = 18, ["z"] = 36, ["name"] = "default:silver_sandstone_block"}, {["x"] = 6, ["y"] = 0, ["param1"] = 18, ["z"] = 37, ["name"] = "default:silver_sandstone_block"}, {["x"] = 6, ["y"] = 0, ["param1"] = 18, ["z"] = 38, ["name"] = "default:silver_sandstone_block"}, {["x"] = 6, ["y"] = 0, ["param1"] = 18, ["z"] = 39, ["name"] = "default:silver_sandstone_block"}, {["x"] = 6, ["y"] = 0, ["param1"] = 18, ["z"] = 40, ["name"] = "default:silver_sandstone_block"}, {["x"] = 6, ["y"] = 0, ["param1"] = 18, ["z"] = 41, ["name"] = "default:silver_sandstone_block"}, {["x"] = 6, ["y"] = 0, ["param1"] = 18, ["z"] = 42, ["name"] = "default:silver_sandstone_block"}, {["x"] = 6, ["y"] = 0, ["param1"] = 18, ["z"] = 43, ["name"] = "default:silver_sandstone_block"}, {["x"] = 6, ["y"] = 0, ["param1"] = 18, ["z"] = 44, ["name"] = "default:silver_sandstone_block"}, {["x"] = 6, ["y"] = 0, ["param1"] = 18, ["z"] = 45, ["name"] = "default:silver_sandstone_block"}, {["x"] = 6, ["y"] = 0, ["param1"] = 18, ["z"] = 46, ["name"] = "default:silver_sandstone_block"}, {["x"] = 6, ["y"] = 0, ["param1"] = 18, ["z"] = 47, ["name"] = "default:silver_sandstone_block"}, {["x"] = 6, ["y"] = 0, ["param1"] = 18, ["z"] = 48, ["name"] = "default:silver_sandstone_block"}, {["x"] = 6, ["y"] = 0, ["param1"] = 15, ["z"] = 49, ["name"] = "default:desert_sandstone_block"}, {["x"] = 6, ["y"] = 1, ["param1"] = 16, ["z"] = 4, ["name"] = "default:silver_sandstone"}, {["x"] = 6, ["y"] = 1, ["param1"] = 16, ["z"] = 5, ["name"] = "default:silver_sandstone"}, {["x"] = 6, ["y"] = 1, ["param1"] = 16, ["z"] = 6, ["name"] = "default:silver_sandstone"}, {["x"] = 6, ["y"] = 1, ["param1"] = 16, ["z"] = 7, ["name"] = "default:silver_sandstone"}, {["x"] = 6, ["y"] = 1, ["param1"] = 16, ["z"] = 8, ["name"] = "default:silver_sandstone"}, {["x"] = 6, ["y"] = 1, ["param1"] = 16, ["z"] = 9, ["name"] = "default:silver_sandstone"}, {["x"] = 6, ["y"] = 1, ["param1"] = 16, ["z"] = 10, ["name"] = "default:silver_sandstone"}, {["x"] = 6, ["y"] = 1, ["param1"] = 16, ["z"] = 11, ["name"] = "default:silver_sandstone"}, {["x"] = 6, ["y"] = 1, ["param1"] = 16, ["z"] = 12, ["name"] = "default:silver_sandstone"}, {["x"] = 6, ["y"] = 1, ["param1"] = 16, ["z"] = 17, ["name"] = "default:silver_sandstone"}, {["x"] = 6, ["param2"] = 2, ["y"] = 1, ["param1"] = 45, ["z"] = 18, ["name"] = "mesecons_insulated:insulated_off"}, {["x"] = 6, ["y"] = 1, ["param1"] = 61, ["z"] = 19, ["name"] = "default:mese"}, {["x"] = 6, ["param2"] = 2, ["y"] = 1, ["param1"] = 45, ["z"] = 20, ["name"] = "mesecons_insulated:insulated_off"}, {["x"] = 6, ["y"] = 1, ["param1"] = 61, ["z"] = 21, ["name"] = "default:mese"}, {["x"] = 6, ["param2"] = 2, ["y"] = 1, ["param1"] = 45, ["z"] = 22, ["name"] = "mesecons_insulated:insulated_off"}, {["x"] = 6, ["y"] = 1, ["param1"] = 61, ["z"] = 23, ["name"] = "default:mese"}, {["x"] = 6, ["param2"] = 2, ["y"] = 1, ["param1"] = 45, ["z"] = 24, ["name"] = "mesecons_insulated:insulated_off"}, {["x"] = 6, ["y"] = 1, ["param1"] = 61, ["z"] = 25, ["name"] = "default:mese"}, {["x"] = 6, ["y"] = 1, ["param1"] = 16, ["z"] = 26, ["name"] = "default:silver_sandstone"}, {["x"] = 6, ["y"] = 1, ["param1"] = 61, ["z"] = 27, ["name"] = "default:mese"}, {["x"] = 6, ["y"] = 1, ["param1"] = 45, ["z"] = 28, ["name"] = "mesecons_insulated:insulated_off"}, {["x"] = 6, ["y"] = 1, ["param1"] = 61, ["z"] = 29, ["name"] = "default:mese"}, {["x"] = 6, ["y"] = 1, ["param1"] = 45, ["z"] = 30, ["name"] = "mesecons_insulated:insulated_off"}, {["x"] = 6, ["y"] = 1, ["param1"] = 61, ["z"] = 31, ["name"] = "default:mese"}, {["x"] = 6, ["y"] = 1, ["param1"] = 45, ["z"] = 32, ["name"] = "mesecons_insulated:insulated_off"}, {["x"] = 6, ["y"] = 1, ["param1"] = 61, ["z"] = 33, ["name"] = "default:mese"}, {["x"] = 6, ["y"] = 1, ["param1"] = 45, ["z"] = 34, ["name"] = "mesecons_insulated:insulated_off"}, {["x"] = 6, ["y"] = 1, ["param1"] = 61, ["z"] = 35, ["name"] = "default:mese"}, {["x"] = 6, ["y"] = 1, ["param1"] = 16, ["z"] = 36, ["name"] = "default:silver_sandstone"}, {["x"] = 6, ["y"] = 1, ["param1"] = 61, ["z"] = 37, ["name"] = "default:mese"}, {["x"] = 6, ["param2"] = 2, ["y"] = 1, ["param1"] = 45, ["z"] = 38, ["name"] = "mesecons_insulated:insulated_off"}, {["x"] = 6, ["y"] = 1, ["param1"] = 61, ["z"] = 39, ["name"] = "default:mese"}, {["x"] = 6, ["param2"] = 2, ["y"] = 1, ["param1"] = 45, ["z"] = 40, ["name"] = "mesecons_insulated:insulated_off"}, {["x"] = 6, ["y"] = 1, ["param1"] = 61, ["z"] = 41, ["name"] = "default:mese"}, {["x"] = 6, ["y"] = 1, ["param1"] = 45, ["z"] = 42, ["name"] = "mesecons_insulated:insulated_off"}, {["x"] = 6, ["y"] = 1, ["param1"] = 61, ["z"] = 43, ["name"] = "default:mese"}, {["x"] = 6, ["y"] = 1, ["param1"] = 45, ["z"] = 44, ["name"] = "mesecons_insulated:insulated_off"}, {["x"] = 6, ["y"] = 1, ["param1"] = 16, ["z"] = 45, ["name"] = "default:silver_sandstone"}, {["x"] = 6, ["y"] = 2, ["param1"] = 16, ["z"] = 4, ["name"] = "default:silver_sandstone"}, {["x"] = 6, ["y"] = 2, ["param1"] = 31, ["z"] = 7, ["name"] = "mesecons:wire_10100010_off"}, {["x"] = 6, ["param2"] = 1, ["y"] = 2, ["param1"] = 63, ["z"] = 10, ["name"] = "digilines:wire_std_01010000"}, {["x"] = 6, ["y"] = 2, ["param1"] = 63, ["z"] = 11, ["name"] = "mesecons_delayer:delayer_off_2"}, {["x"] = 6, ["y"] = 2, ["param1"] = 16, ["z"] = 12, ["name"] = "default:silver_sandstone"}, {["x"] = 6, ["y"] = 2, ["param1"] = 16, ["z"] = 17, ["name"] = "default:silver_sandstone"}, {["x"] = 6, ["y"] = 2, ["param1"] = 16, ["z"] = 18, ["name"] = "default:silver_sandstone"}, {["x"] = 6, ["y"] = 2, ["param1"] = 60, ["z"] = 19, ["name"] = "default:mese"}, {["x"] = 6, ["y"] = 2, ["param1"] = 16, ["z"] = 20, ["name"] = "default:silver_sandstone"}, {["x"] = 6, ["y"] = 2, ["param1"] = 60, ["z"] = 21, ["name"] = "default:mese"}, {["x"] = 6, ["y"] = 2, ["param1"] = 16, ["z"] = 22, ["name"] = "default:silver_sandstone"}, {["x"] = 6, ["y"] = 2, ["param1"] = 60, ["z"] = 23, ["name"] = "default:mese"}, {["x"] = 6, ["y"] = 2, ["param1"] = 16, ["z"] = 24, ["name"] = "default:silver_sandstone"}, {["x"] = 6, ["y"] = 2, ["param1"] = 60, ["z"] = 25, ["name"] = "default:mese"}, {["x"] = 6, ["y"] = 2, ["param1"] = 16, ["z"] = 26, ["name"] = "default:silver_sandstone"}, {["x"] = 6, ["y"] = 2, ["param1"] = 60, ["z"] = 27, ["name"] = "default:mese"}, {["x"] = 6, ["y"] = 2, ["param1"] = 16, ["z"] = 28, ["name"] = "default:silver_sandstone"}, {["x"] = 6, ["y"] = 2, ["param1"] = 60, ["z"] = 29, ["name"] = "default:mese"}, {["x"] = 6, ["y"] = 2, ["param1"] = 16, ["z"] = 30, ["name"] = "default:silver_sandstone"}, {["x"] = 6, ["y"] = 2, ["param1"] = 60, ["z"] = 31, ["name"] = "default:mese"}, {["x"] = 6, ["y"] = 2, ["param1"] = 16, ["z"] = 32, ["name"] = "default:silver_sandstone"}, {["x"] = 6, ["y"] = 2, ["param1"] = 60, ["z"] = 33, ["name"] = "default:mese"}, {["x"] = 6, ["y"] = 2, ["param1"] = 16, ["z"] = 34, ["name"] = "default:silver_sandstone"}, {["x"] = 6, ["y"] = 2, ["param1"] = 60, ["z"] = 35, ["name"] = "default:mese"}, {["x"] = 6, ["y"] = 2, ["param1"] = 16, ["z"] = 36, ["name"] = "default:silver_sandstone"}, {["x"] = 6, ["y"] = 2, ["param1"] = 60, ["z"] = 37, ["name"] = "default:mese"}, {["x"] = 6, ["y"] = 2, ["param1"] = 16, ["z"] = 38, ["name"] = "default:silver_sandstone"}, {["x"] = 6, ["y"] = 2, ["param1"] = 60, ["z"] = 39, ["name"] = "default:mese"}, {["x"] = 6, ["y"] = 2, ["param1"] = 16, ["z"] = 40, ["name"] = "default:silver_sandstone"}, {["x"] = 6, ["y"] = 2, ["param1"] = 60, ["z"] = 41, ["name"] = "default:mese"}, {["x"] = 6, ["y"] = 2, ["param1"] = 16, ["z"] = 42, ["name"] = "default:silver_sandstone"}, {["x"] = 6, ["y"] = 2, ["param1"] = 60, ["z"] = 43, ["name"] = "default:mese"}, {["x"] = 6, ["y"] = 2, ["param1"] = 16, ["z"] = 44, ["name"] = "default:silver_sandstone"}, {["x"] = 6, ["y"] = 2, ["param1"] = 16, ["z"] = 45, ["name"] = "default:silver_sandstone"}, {["x"] = 6, ["y"] = 3, ["param1"] = 16, ["z"] = 17, ["name"] = "default:silver_sandstone"}, {["x"] = 6, ["y"] = 3, ["param1"] = 45, ["z"] = 18, ["name"] = "mesecons_insulated:insulated_off"}, {["x"] = 6, ["y"] = 3, ["param1"] = 61, ["z"] = 19, ["name"] = "default:mese"}, {["x"] = 6, ["y"] = 3, ["param1"] = 45, ["z"] = 20, ["name"] = "mesecons_insulated:insulated_off"}, {["x"] = 6, ["y"] = 3, ["param1"] = 61, ["z"] = 21, ["name"] = "default:mese"}, {["x"] = 6, ["y"] = 3, ["param1"] = 45, ["z"] = 22, ["name"] = "mesecons_insulated:insulated_off"}, {["x"] = 6, ["y"] = 3, ["param1"] = 61, ["z"] = 23, ["name"] = "default:mese"}, {["x"] = 6, ["y"] = 3, ["param1"] = 45, ["z"] = 24, ["name"] = "mesecons_insulated:insulated_off"}, {["x"] = 6, ["y"] = 3, ["param1"] = 61, ["z"] = 25, ["name"] = "default:mese"}, {["x"] = 6, ["y"] = 3, ["param1"] = 16, ["z"] = 26, ["name"] = "default:silver_sandstone"}, {["x"] = 6, ["y"] = 3, ["param1"] = 61, ["z"] = 27, ["name"] = "default:mese"}, {["x"] = 6, ["param2"] = 2, ["y"] = 3, ["param1"] = 45, ["z"] = 28, ["name"] = "mesecons_insulated:insulated_off"}, {["x"] = 6, ["y"] = 3, ["param1"] = 61, ["z"] = 29, ["name"] = "default:mese"}, {["x"] = 6, ["param2"] = 2, ["y"] = 3, ["param1"] = 45, ["z"] = 30, ["name"] = "mesecons_insulated:insulated_off"}, {["x"] = 6, ["y"] = 3, ["param1"] = 61, ["z"] = 31, ["name"] = "default:mese"}, {["x"] = 6, ["param2"] = 2, ["y"] = 3, ["param1"] = 45, ["z"] = 32, ["name"] = "mesecons_insulated:insulated_off"}, {["x"] = 6, ["y"] = 3, ["param1"] = 61, ["z"] = 33, ["name"] = "default:mese"}, {["x"] = 6, ["y"] = 3, ["param1"] = 45, ["z"] = 34, ["name"] = "mesecons_insulated:insulated_off"}, {["x"] = 6, ["y"] = 3, ["param1"] = 61, ["z"] = 35, ["name"] = "default:mese"}, {["x"] = 6, ["y"] = 3, ["param1"] = 16, ["z"] = 36, ["name"] = "default:silver_sandstone"}, {["x"] = 6, ["y"] = 3, ["param1"] = 61, ["z"] = 37, ["name"] = "default:mese"}, {["x"] = 6, ["y"] = 3, ["param1"] = 45, ["z"] = 38, ["name"] = "mesecons_insulated:insulated_off"}, {["x"] = 6, ["y"] = 3, ["param1"] = 61, ["z"] = 39, ["name"] = "default:mese"}, {["x"] = 6, ["y"] = 3, ["param1"] = 45, ["z"] = 40, ["name"] = "mesecons_insulated:insulated_off"}, {["x"] = 6, ["y"] = 3, ["param1"] = 61, ["z"] = 41, ["name"] = "default:mese"}, {["x"] = 6, ["y"] = 3, ["param1"] = 45, ["z"] = 42, ["name"] = "mesecons_insulated:insulated_off"}, {["x"] = 6, ["y"] = 3, ["param1"] = 61, ["z"] = 43, ["name"] = "default:mese"}, {["x"] = 6, ["y"] = 3, ["param1"] = 45, ["z"] = 44, ["name"] = "mesecons_insulated:insulated_off"}, {["x"] = 6, ["y"] = 3, ["param1"] = 16, ["z"] = 45, ["name"] = "default:silver_sandstone"}, {["x"] = 6, ["y"] = 4, ["param1"] = 14, ["z"] = 17, ["name"] = "stairs:slab_silver_sandstone"}, {["x"] = 6, ["y"] = 4, ["param1"] = 30, ["z"] = 18, ["name"] = "stairs:slab_silver_sandstone"}, {["x"] = 6, ["y"] = 4, ["param1"] = 46, ["z"] = 19, ["name"] = "stairs:slab_silver_sandstone"}, {["x"] = 6, ["y"] = 4, ["param1"] = 30, ["z"] = 20, ["name"] = "stairs:slab_silver_sandstone"}, {["x"] = 6, ["y"] = 4, ["param1"] = 46, ["z"] = 21, ["name"] = "stairs:slab_silver_sandstone"}, {["x"] = 6, ["y"] = 4, ["param1"] = 30, ["z"] = 22, ["name"] = "stairs:slab_silver_sandstone"}, {["x"] = 6, ["y"] = 4, ["param1"] = 46, ["z"] = 23, ["name"] = "stairs:slab_silver_sandstone"}, {["x"] = 6, ["y"] = 4, ["param1"] = 30, ["z"] = 24, ["name"] = "stairs:slab_silver_sandstone"}, {["x"] = 6, ["y"] = 4, ["param1"] = 46, ["z"] = 25, ["name"] = "stairs:slab_silver_sandstone"}, {["x"] = 6, ["y"] = 4, ["param1"] = 30, ["z"] = 26, ["name"] = "default:silver_sandstone"}, {["x"] = 6, ["y"] = 4, ["param1"] = 46, ["z"] = 27, ["name"] = "stairs:slab_silver_sandstone"}, {["x"] = 6, ["y"] = 4, ["param1"] = 30, ["z"] = 28, ["name"] = "stairs:slab_silver_sandstone"}, {["x"] = 6, ["y"] = 4, ["param1"] = 46, ["z"] = 29, ["name"] = "stairs:slab_silver_sandstone"}, {["x"] = 6, ["y"] = 4, ["param1"] = 30, ["z"] = 30, ["name"] = "stairs:slab_silver_sandstone"}, {["x"] = 6, ["y"] = 4, ["param1"] = 46, ["z"] = 31, ["name"] = "stairs:slab_silver_sandstone"}, {["x"] = 6, ["y"] = 4, ["param1"] = 30, ["z"] = 32, ["name"] = "stairs:slab_silver_sandstone"}, {["x"] = 6, ["y"] = 4, ["param1"] = 46, ["z"] = 33, ["name"] = "stairs:slab_silver_sandstone"}, {["x"] = 6, ["y"] = 4, ["param1"] = 30, ["z"] = 34, ["name"] = "stairs:slab_silver_sandstone"}, {["x"] = 6, ["y"] = 4, ["param1"] = 46, ["z"] = 35, ["name"] = "stairs:slab_silver_sandstone"}, {["x"] = 6, ["y"] = 4, ["param1"] = 30, ["z"] = 36, ["name"] = "default:silver_sandstone"}, {["x"] = 6, ["y"] = 4, ["param1"] = 46, ["z"] = 37, ["name"] = "stairs:slab_silver_sandstone"}, {["x"] = 6, ["y"] = 4, ["param1"] = 30, ["z"] = 38, ["name"] = "stairs:slab_silver_sandstone"}, {["x"] = 6, ["y"] = 4, ["param1"] = 46, ["z"] = 39, ["name"] = "stairs:slab_silver_sandstone"}, {["x"] = 6, ["y"] = 4, ["param1"] = 30, ["z"] = 40, ["name"] = "stairs:slab_silver_sandstone"}, {["x"] = 6, ["y"] = 4, ["param1"] = 46, ["z"] = 41, ["name"] = "stairs:slab_silver_sandstone"}, {["x"] = 6, ["y"] = 4, ["param1"] = 30, ["z"] = 42, ["name"] = "stairs:slab_silver_sandstone"}, {["x"] = 6, ["y"] = 4, ["param1"] = 46, ["z"] = 43, ["name"] = "stairs:slab_silver_sandstone"}, {["x"] = 6, ["y"] = 4, ["param1"] = 30, ["z"] = 44, ["name"] = "stairs:slab_silver_sandstone"}, {["x"] = 6, ["y"] = 4, ["param1"] = 14, ["z"] = 45, ["name"] = "stairs:slab_silver_sandstone"}, {["x"] = 7, ["y"] = 0, ["param1"] = 12, ["z"] = 0, ["name"] = "default:desert_sandstone_block"}, {["x"] = 7, ["y"] = 0, ["param1"] = 18, ["z"] = 1, ["name"] = "default:silver_sandstone_block"}, {["x"] = 7, ["y"] = 0, ["param1"] = 18, ["z"] = 2, ["name"] = "default:silver_sandstone_block"}, {["x"] = 7, ["y"] = 0, ["param1"] = 18, ["z"] = 3, ["name"] = "default:silver_sandstone_block"}, {["x"] = 7, ["y"] = 0, ["param1"] = 18, ["z"] = 4, ["name"] = "default:silver_sandstone_block"}, {["x"] = 7, ["y"] = 0, ["param1"] = 18, ["z"] = 5, ["name"] = "default:silver_sandstone_block"}, {["x"] = 7, ["y"] = 0, ["param1"] = 18, ["z"] = 6, ["name"] = "default:silver_sandstone_block"}, {["x"] = 7, ["y"] = 0, ["param1"] = 18, ["z"] = 7, ["name"] = "default:silver_sandstone_block"}, {["x"] = 7, ["y"] = 0, ["param1"] = 18, ["z"] = 8, ["name"] = "default:silver_sandstone_block"}, {["x"] = 7, ["y"] = 0, ["param1"] = 18, ["z"] = 9, ["name"] = "default:silver_sandstone_block"}, {["x"] = 7, ["y"] = 0, ["param1"] = 18, ["z"] = 10, ["name"] = "default:silver_sandstone_block"}, {["x"] = 7, ["y"] = 0, ["param1"] = 18, ["z"] = 11, ["name"] = "default:silver_sandstone_block"}, {["x"] = 7, ["y"] = 0, ["param1"] = 18, ["z"] = 12, ["name"] = "default:silver_sandstone_block"}, {["x"] = 7, ["y"] = 0, ["param1"] = 18, ["z"] = 13, ["name"] = "default:silver_sandstone_block"}, {["x"] = 7, ["y"] = 0, ["param1"] = 18, ["z"] = 14, ["name"] = "default:silver_sandstone_block"}, {["x"] = 7, ["y"] = 0, ["param1"] = 18, ["z"] = 15, ["name"] = "default:silver_sandstone_block"}, {["x"] = 7, ["y"] = 0, ["param1"] = 18, ["z"] = 16, ["name"] = "default:silver_sandstone_block"}, {["x"] = 7, ["y"] = 0, ["param1"] = 18, ["z"] = 17, ["name"] = "default:silver_sandstone_block"}, {["x"] = 7, ["y"] = 0, ["param1"] = 18, ["z"] = 18, ["name"] = "default:silver_sandstone_block"}, {["x"] = 7, ["y"] = 0, ["param1"] = 18, ["z"] = 19, ["name"] = "default:silver_sandstone_block"}, {["x"] = 7, ["y"] = 0, ["param1"] = 18, ["z"] = 20, ["name"] = "default:silver_sandstone_block"}, {["x"] = 7, ["y"] = 0, ["param1"] = 18, ["z"] = 21, ["name"] = "default:silver_sandstone_block"}, {["x"] = 7, ["y"] = 0, ["param1"] = 18, ["z"] = 22, ["name"] = "default:silver_sandstone_block"}, {["x"] = 7, ["y"] = 0, ["param1"] = 18, ["z"] = 23, ["name"] = "default:silver_sandstone_block"}, {["x"] = 7, ["y"] = 0, ["param1"] = 18, ["z"] = 24, ["name"] = "default:silver_sandstone_block"}, {["x"] = 7, ["y"] = 0, ["param1"] = 18, ["z"] = 25, ["name"] = "default:silver_sandstone_block"}, {["x"] = 7, ["y"] = 0, ["param1"] = 18, ["z"] = 26, ["name"] = "default:silver_sandstone_block"}, {["x"] = 7, ["y"] = 0, ["param1"] = 18, ["z"] = 27, ["name"] = "default:silver_sandstone_block"}, {["x"] = 7, ["y"] = 0, ["param1"] = 18, ["z"] = 28, ["name"] = "default:silver_sandstone_block"}, {["x"] = 7, ["y"] = 0, ["param1"] = 18, ["z"] = 29, ["name"] = "default:silver_sandstone_block"}, {["x"] = 7, ["y"] = 0, ["param1"] = 18, ["z"] = 30, ["name"] = "default:silver_sandstone_block"}, {["x"] = 7, ["y"] = 0, ["param1"] = 18, ["z"] = 31, ["name"] = "default:silver_sandstone_block"}, {["x"] = 7, ["y"] = 0, ["param1"] = 18, ["z"] = 32, ["name"] = "default:silver_sandstone_block"}, {["x"] = 7, ["y"] = 0, ["param1"] = 18, ["z"] = 33, ["name"] = "default:silver_sandstone_block"}, {["x"] = 7, ["y"] = 0, ["param1"] = 18, ["z"] = 34, ["name"] = "default:silver_sandstone_block"}, {["x"] = 7, ["y"] = 0, ["param1"] = 18, ["z"] = 35, ["name"] = "default:silver_sandstone_block"}, {["x"] = 7, ["y"] = 0, ["param1"] = 18, ["z"] = 36, ["name"] = "default:silver_sandstone_block"}, {["x"] = 7, ["y"] = 0, ["param1"] = 18, ["z"] = 37, ["name"] = "default:silver_sandstone_block"}, {["x"] = 7, ["y"] = 0, ["param1"] = 18, ["z"] = 38, ["name"] = "default:silver_sandstone_block"}, {["x"] = 7, ["y"] = 0, ["param1"] = 18, ["z"] = 39, ["name"] = "default:silver_sandstone_block"}, {["x"] = 7, ["y"] = 0, ["param1"] = 18, ["z"] = 40, ["name"] = "default:silver_sandstone_block"}, {["x"] = 7, ["y"] = 0, ["param1"] = 18, ["z"] = 41, ["name"] = "default:silver_sandstone_block"}, {["x"] = 7, ["y"] = 0, ["param1"] = 18, ["z"] = 42, ["name"] = "default:silver_sandstone_block"}, {["x"] = 7, ["y"] = 0, ["param1"] = 18, ["z"] = 43, ["name"] = "default:silver_sandstone_block"}, {["x"] = 7, ["y"] = 0, ["param1"] = 18, ["z"] = 44, ["name"] = "default:silver_sandstone_block"}, {["x"] = 7, ["y"] = 0, ["param1"] = 18, ["z"] = 45, ["name"] = "default:silver_sandstone_block"}, {["x"] = 7, ["y"] = 0, ["param1"] = 18, ["z"] = 46, ["name"] = "default:silver_sandstone_block"}, {["x"] = 7, ["y"] = 0, ["param1"] = 18, ["z"] = 47, ["name"] = "default:silver_sandstone_block"}, {["x"] = 7, ["y"] = 0, ["param1"] = 18, ["z"] = 48, ["name"] = "default:silver_sandstone_block"}, {["x"] = 7, ["y"] = 0, ["param1"] = 15, ["z"] = 49, ["name"] = "default:desert_sandstone_block"}, {["x"] = 7, ["y"] = 1, ["param1"] = 16, ["z"] = 4, ["name"] = "default:silver_sandstone"}, {["x"] = 7, ["y"] = 1, ["param1"] = 16, ["z"] = 5, ["name"] = "default:silver_sandstone"}, {["x"] = 7, ["y"] = 1, ["param1"] = 16, ["z"] = 6, ["name"] = "default:silver_sandstone"}, {["x"] = 7, ["y"] = 1, ["param1"] = 16, ["z"] = 7, ["name"] = "default:silver_sandstone"}, {["x"] = 7, ["param2"] = 2, ["y"] = 1, ["param1"] = 16, ["z"] = 8, ["name"] = "default:silver_sandstone"}, {["x"] = 7, ["y"] = 1, ["param1"] = 16, ["z"] = 9, ["name"] = "default:silver_sandstone"}, {["x"] = 7, ["y"] = 1, ["param1"] = 16, ["z"] = 10, ["name"] = "default:silver_sandstone"}, {["x"] = 7, ["y"] = 1, ["param1"] = 16, ["z"] = 11, ["name"] = "default:silver_sandstone"}, {["x"] = 7, ["y"] = 1, ["param1"] = 16, ["z"] = 12, ["name"] = "default:silver_sandstone"}, {["x"] = 7, ["y"] = 1, ["param1"] = 16, ["z"] = 17, ["name"] = "default:silver_sandstone"}, {["x"] = 7, ["y"] = 1, ["param1"] = 28, ["z"] = 18, ["name"] = "mesecons_extrawires:vertical_bottom_off"}, {["x"] = 7, ["param2"] = 2, ["y"] = 1, ["param1"] = 44, ["z"] = 19, ["name"] = "mesecons_insulated:insulated_off"}, {["x"] = 7, ["y"] = 1, ["param1"] = 28, ["z"] = 20, ["name"] = "mesecons_extrawires:vertical_bottom_off"}, {["x"] = 7, ["param2"] = 2, ["y"] = 1, ["param1"] = 44, ["z"] = 21, ["name"] = "mesecons_insulated:insulated_off"}, {["x"] = 7, ["y"] = 1, ["param1"] = 28, ["z"] = 22, ["name"] = "mesecons_extrawires:vertical_bottom_off"}, {["x"] = 7, ["param2"] = 2, ["y"] = 1, ["param1"] = 44, ["z"] = 23, ["name"] = "mesecons_insulated:insulated_off"}, {["x"] = 7, ["y"] = 1, ["param1"] = 28, ["z"] = 24, ["name"] = "mesecons_extrawires:vertical_bottom_off"}, {["x"] = 7, ["y"] = 1, ["param1"] = 44, ["z"] = 25, ["name"] = "mesecons_insulated:insulated_off"}, {["x"] = 7, ["y"] = 1, ["param1"] = 44, ["z"] = 27, ["name"] = "mesecons_insulated:insulated_off"}, {["x"] = 7, ["y"] = 1, ["param1"] = 28, ["z"] = 28, ["name"] = "mesecons_extrawires:vertical_bottom_off"}, {["x"] = 7, ["y"] = 1, ["param1"] = 44, ["z"] = 29, ["name"] = "mesecons_insulated:insulated_off"}, {["x"] = 7, ["y"] = 1, ["param1"] = 28, ["z"] = 30, ["name"] = "mesecons_extrawires:vertical_bottom_off"}, {["x"] = 7, ["y"] = 1, ["param1"] = 28, ["z"] = 32, ["name"] = "mesecons_extrawires:vertical_bottom_off"}, {["x"] = 7, ["param2"] = 2, ["y"] = 1, ["param1"] = 44, ["z"] = 33, ["name"] = "mesecons_insulated:insulated_off"}, {["x"] = 7, ["y"] = 1, ["param1"] = 28, ["z"] = 34, ["name"] = "mesecons_extrawires:vertical_bottom_off"}, {["x"] = 7, ["param2"] = 2, ["y"] = 1, ["param1"] = 44, ["z"] = 35, ["name"] = "mesecons_insulated:insulated_off"}, {["x"] = 7, ["y"] = 1, ["param1"] = 16, ["z"] = 36, ["name"] = "default:silver_sandstone"}, {["x"] = 7, ["param2"] = 2, ["y"] = 1, ["param1"] = 44, ["z"] = 37, ["name"] = "mesecons_insulated:insulated_off"}, {["x"] = 7, ["y"] = 1, ["param1"] = 28, ["z"] = 38, ["name"] = "mesecons_extrawires:vertical_bottom_off"}, {["x"] = 7, ["param2"] = 2, ["y"] = 1, ["param1"] = 44, ["z"] = 39, ["name"] = "mesecons_insulated:insulated_off"}, {["x"] = 7, ["y"] = 1, ["param1"] = 28, ["z"] = 40, ["name"] = "mesecons_extrawires:vertical_bottom_off"}, {["x"] = 7, ["param2"] = 2, ["y"] = 1, ["param1"] = 44, ["z"] = 41, ["name"] = "mesecons_insulated:insulated_off"}, {["x"] = 7, ["y"] = 1, ["param1"] = 28, ["z"] = 42, ["name"] = "mesecons_extrawires:vertical_bottom_off"}, {["x"] = 7, ["y"] = 1, ["param1"] = 44, ["z"] = 43, ["name"] = "mesecons_insulated:insulated_off"}, {["x"] = 7, ["y"] = 1, ["param1"] = 44, ["z"] = 44, ["name"] = "mesecons_extrawires:vertical_bottom_off"}, {["x"] = 7, ["y"] = 1, ["param1"] = 16, ["z"] = 45, ["name"] = "default:silver_sandstone"}, {["x"] = 7, ["y"] = 2, ["param1"] = 16, ["z"] = 4, ["name"] = "default:silver_sandstone"}, {["x"] = 7, ["param2"] = 1, ["y"] = 2, ["param1"] = 15, ["z"] = 5, ["name"] = "digilines:wire_std_01100000"}, {["x"] = 7, ["param2"] = 1, ["y"] = 2, ["param1"] = 15, ["z"] = 6, ["name"] = "digilines:wire_std_10100000"}, {["x"] = 7, ["meta"] = {["fields"] = {["real_portstates"] = "1", ["code"] = "if event.type == \"program\" then\13  mem.adder = 8\13end\13\13function ReverseTable(t)\13    local reversedTable = {}\13    local itemCount = #t\13    for k, v in ipairs(t) do\13        reversedTable[itemCount + 1 - k] = v\13    end\13    return reversedTable\13end\
\
if (event.type == \"on\" or event.type == \"off\") then\13  port.d = pin.c\13  port.a = pin.b\13end\13\13-- insert this adder's result to the sum table/array then pass on to the next adder\13if (event.type == \"digiline\" and event.channel == \"sum\" .. mem.adder and event.msg) then\13  sum_table = event.msg\13  if (pin.d) then\13    table.insert(sum_table, 1)\13  else\13    table.insert(sum_table, 0)\13  end\13  rtable = table.concat(ReverseTable(sum_table)) -- reverse order of sum array and flatten\
  digiline_send(\"displaysum\",  tostring(tonumber(rtable,2)) .. \" (\" .. rtable .. \")\") -- send result to the sum display LCD\13end", ["formspec"] = "size[12,10]background[-0.2,-0.25;12.4,10.75;jeija_luac_background.png]label[0.1,8.3;]textarea[0.2,0.2;12.2,9.5;code;;if event.type == \"program\" then\13  mem.adder = 8\13end\13\13function ReverseTable(t)\13    local reversedTable = {}\13    local itemCount = #t\13    for k\\, v in ipairs(t) do\13        reversedTable\\[itemCount + 1 - k\\] = v\13    end\13    return reversedTable\13end\
\
if (event.type == \"on\" or event.type == \"off\") then\13  port.d = pin.c\13  port.a = pin.b\13end\13\13-- insert this adder's result to the sum table/array then pass on to the next adder\13if (event.type == \"digiline\" and event.channel == \"sum\" .. mem.adder and event.msg) then\13  sum_table = event.msg\13  if (pin.d) then\13    table.insert(sum_table\\, 1)\13  else\13    table.insert(sum_table\\, 0)\13  end\13  rtable = table.concat(ReverseTable(sum_table)) -- reverse order of sum array and flatten\
  digiline_send(\"displaysum\"\\,  tostring(tonumber(rtable\\,2)) .. \" (\" .. rtable .. \")\") -- send result to the sum display LCD\13end]image_button[4.75,8.75;2.5,1;jeija_luac_runbutton.png;program;]image_button_exit[11.72,-0.25;0.425,0.4;jeija_close_window.png;exit;]", ["lc_memory"] = "return {[\"adder\"] = 8}", ["ignore_offevents"] = "return {[\"D\"] = true}", ["luac_id"] = "64725"}, ["inventory"] = {}}, ["y"] = 2, ["param1"] = 15, ["z"] = 7, ["name"] = "mesecons_luacontroller:luacontroller0000"}, {["x"] = 7, ["param2"] = 3, ["y"] = 2, ["param1"] = 31, ["z"] = 8, ["name"] = "mesecons_extrawires:corner_off"}, {["x"] = 7, ["meta"] = {["fields"] = {["infotext"] = "\"Adder 8\"", ["text"] = "Adder 8", ["formspec"] = "field[text;;${text}]"}, ["inventory"] = {}}, ["param2"] = 1, ["y"] = 2, ["param1"] = 47, ["z"] = 9, ["name"] = "default:sign_wall_steel"}, {["x"] = 7, ["param2"] = 1, ["y"] = 2, ["param1"] = 47, ["z"] = 10, ["name"] = "digilines:wire_std_01110000"}, {["x"] = 7, ["meta"] = {["fields"] = {["real_portstates"] = "1", ["code"] = "if (event.type == \"on\" and event.pin.name == \"A\") then\
  -- begin cascade to collect the binary sum array\
  digiline_send(\"off\", 1)\
  digiline_send(\"sum1\",{})\13end", ["formspec"] = "size[12,10]background[-0.2,-0.25;12.4,10.75;jeija_luac_background.png]label[0.1,8.3;]textarea[0.2,0.2;12.2,9.5;code;;if (event.type == \"on\" and event.pin.name == \"A\") then\
  -- begin cascade to collect the binary sum array\
  digiline_send(\"off\"\\, 1)\
