5:return {{["x"] = 0, ["y"] = 0, ["param1"] = 15, ["z"] = 0, ["name"] = "default:desert_sandstone_block"}, {["x"] = 0, ["y"] = 0, ["param1"] = 15, ["z"] = 1, ["name"] = "default:desert_sandstone_block"}, {["x"] = 0, ["y"] = 0, ["param1"] = 15, ["z"] = 2, ["name"] = "default:desert_sandstone_block"}, {["x"] = 0, ["y"] = 0, ["param1"] = 15, ["z"] = 3, ["name"] = "default:desert_sandstone_block"}, {["x"] = 0, ["y"] = 0, ["param1"] = 15, ["z"] = 4, ["name"] = "default:desert_sandstone_block"}, {["x"] = 0, ["y"] = 0, ["param1"] = 15, ["z"] = 5, ["name"] = "default:desert_sandstone_block"}, {["x"] = 0, ["y"] = 0, ["param1"] = 15, ["z"] = 6, ["name"] = "default:desert_sandstone_block"}, {["x"] = 0, ["y"] = 0, ["param1"] = 15, ["z"] = 7, ["name"] = "default:desert_sandstone_block"}, {["x"] = 0, ["y"] = 0, ["param1"] = 15, ["z"] = 8, ["name"] = "default:desert_sandstone_block"}, {["x"] = 0, ["y"] = 0, ["param1"] = 15, ["z"] = 9, ["name"] = "default:desert_sandstone_block"}, {["x"] = 0, ["y"] = 0, ["param1"] = 15, ["z"] = 10, ["name"] = "default:desert_sandstone_block"}, {["x"] = 0, ["y"] = 0, ["param1"] = 15, ["z"] = 11, ["name"] = "default:desert_sandstone_block"}, {["x"] = 0, ["y"] = 0, ["param1"] = 15, ["z"] = 12, ["name"] = "default:desert_sandstone_block"}, {["x"] = 0, ["y"] = 0, ["param1"] = 15, ["z"] = 13, ["name"] = "default:desert_sandstone_block"}, {["x"] = 0, ["y"] = 0, ["param1"] = 15, ["z"] = 14, ["name"] = "default:desert_sandstone_block"}, {["x"] = 0, ["y"] = 0, ["param1"] = 15, ["z"] = 15, ["name"] = "default:desert_sandstone_block"}, {["x"] = 0, ["y"] = 0, ["param1"] = 15, ["z"] = 16, ["name"] = "default:desert_sandstone_block"}, {["x"] = 0, ["y"] = 0, ["param1"] = 15, ["z"] = 17, ["name"] = "default:desert_sandstone_block"}, {["x"] = 0, ["y"] = 0, ["param1"] = 15, ["z"] = 18, ["name"] = "default:desert_sandstone_block"}, {["x"] = 0, ["y"] = 0, ["param1"] = 15, ["z"] = 19, ["name"] = "default:desert_sandstone_block"}, {["x"] = 0, ["y"] = 0, ["param1"] = 15, ["z"] = 20, ["name"] = "default:desert_sandstone_block"}, {["x"] = 0, ["y"] = 0, ["param1"] = 15, ["z"] = 21, ["name"] = "default:desert_sandstone_block"}, {["x"] = 0, ["y"] = 0, ["param1"] = 15, ["z"] = 22, ["name"] = "default:desert_sandstone_block"}, {["x"] = 0, ["y"] = 0, ["param1"] = 15, ["z"] = 23, ["name"] = "default:desert_sandstone_block"}, {["x"] = 0, ["y"] = 0, ["param1"] = 15, ["z"] = 24, ["name"] = "default:desert_sandstone_block"}, {["x"] = 0, ["y"] = 0, ["param1"] = 15, ["z"] = 25, ["name"] = "default:desert_sandstone_block"}, {["x"] = 0, ["y"] = 0, ["param1"] = 15, ["z"] = 26, ["name"] = "default:desert_sandstone_block"}, {["x"] = 0, ["y"] = 0, ["param1"] = 15, ["z"] = 27, ["name"] = "default:desert_sandstone_block"}, {["x"] = 1, ["y"] = 0, ["param1"] = 15, ["z"] = 0, ["name"] = "default:desert_sandstone_block"}, {["x"] = 1, ["y"] = 0, ["param1"] = 15, ["z"] = 1, ["name"] = "default:silver_sandstone_block"}, {["x"] = 1, ["y"] = 0, ["param1"] = 15, ["z"] = 2, ["name"] = "default:silver_sandstone_block"}, {["x"] = 1, ["y"] = 0, ["param1"] = 15, ["z"] = 3, ["name"] = "default:silver_sandstone_block"}, {["x"] = 1, ["y"] = 0, ["param1"] = 15, ["z"] = 4, ["name"] = "default:silver_sandstone_block"}, {["x"] = 1, ["y"] = 0, ["param1"] = 15, ["z"] = 5, ["name"] = "default:silver_sandstone_block"}, {["x"] = 1, ["y"] = 0, ["param1"] = 15, ["z"] = 6, ["name"] = "default:silver_sandstone_block"}, {["x"] = 1, ["y"] = 0, ["param1"] = 15, ["z"] = 7, ["name"] = "default:silver_sandstone_block"}, {["x"] = 1, ["y"] = 0, ["param1"] = 15, ["z"] = 8, ["name"] = "default:silver_sandstone_block"}, {["x"] = 1, ["y"] = 0, ["param1"] = 15, ["z"] = 9, ["name"] = "default:silver_sandstone_block"}, {["x"] = 1, ["y"] = 0, ["param1"] = 15, ["z"] = 10, ["name"] = "default:silver_sandstone_block"}, {["x"] = 1, ["y"] = 0, ["param1"] = 15, ["z"] = 11, ["name"] = "default:silver_sandstone_block"}, {["x"] = 1, ["y"] = 0, ["param1"] = 15, ["z"] = 12, ["name"] = "default:silver_sandstone_block"}, {["x"] = 1, ["y"] = 0, ["param1"] = 15, ["z"] = 13, ["name"] = "default:silver_sandstone_block"}, {["x"] = 1, ["y"] = 0, ["param1"] = 15, ["z"] = 14, ["name"] = "default:silver_sandstone_block"}, {["x"] = 1, ["y"] = 0, ["param1"] = 15, ["z"] = 15, ["name"] = "default:silver_sandstone_block"}, {["x"] = 1, ["y"] = 0, ["param1"] = 15, ["z"] = 16, ["name"] = "default:silver_sandstone_block"}, {["x"] = 1, ["y"] = 0, ["param1"] = 15, ["z"] = 17, ["name"] = "default:silver_sandstone_block"}, {["x"] = 1, ["y"] = 0, ["param1"] = 15, ["z"] = 18, ["name"] = "default:silver_sandstone_block"}, {["x"] = 1, ["y"] = 0, ["param1"] = 15, ["z"] = 19, ["name"] = "default:silver_sandstone_block"}, {["x"] = 1, ["y"] = 0, ["param1"] = 15, ["z"] = 20, ["name"] = "default:silver_sandstone_block"}, {["x"] = 1, ["y"] = 0, ["param1"] = 15, ["z"] = 21, ["name"] = "default:silver_sandstone_block"}, {["x"] = 1, ["y"] = 0, ["param1"] = 15, ["z"] = 22, ["name"] = "default:silver_sandstone_block"}, {["x"] = 1, ["y"] = 0, ["param1"] = 15, ["z"] = 23, ["name"] = "default:silver_sandstone_block"}, {["x"] = 1, ["y"] = 0, ["param1"] = 15, ["z"] = 24, ["name"] = "default:silver_sandstone_block"}, {["x"] = 1, ["y"] = 0, ["param1"] = 15, ["z"] = 25, ["name"] = "default:silver_sandstone_block"}, {["x"] = 1, ["y"] = 0, ["param1"] = 15, ["z"] = 26, ["name"] = "default:silver_sandstone_block"}, {["x"] = 1, ["y"] = 0, ["param1"] = 15, ["z"] = 27, ["name"] = "default:desert_sandstone_block"}, {["x"] = 2, ["y"] = 0, ["param1"] = 15, ["z"] = 0, ["name"] = "default:desert_sandstone_block"}, {["x"] = 2, ["y"] = 0, ["param1"] = 15, ["z"] = 1, ["name"] = "default:silver_sandstone_block"}, {["x"] = 2, ["y"] = 0, ["param1"] = 15, ["z"] = 2, ["name"] = "default:silver_sandstone_block"}, {["x"] = 2, ["y"] = 0, ["param1"] = 15, ["z"] = 3, ["name"] = "default:silver_sandstone_block"}, {["x"] = 2, ["y"] = 0, ["param1"] = 15, ["z"] = 4, ["name"] = "default:silver_sandstone_block"}, {["x"] = 2, ["y"] = 0, ["param1"] = 15, ["z"] = 5, ["name"] = "default:silver_sandstone_block"}, {["x"] = 2, ["y"] = 0, ["param1"] = 15, ["z"] = 6, ["name"] = "default:silver_sandstone_block"}, {["x"] = 2, ["y"] = 0, ["param1"] = 15, ["z"] = 7, ["name"] = "default:silver_sandstone_block"}, {["x"] = 2, ["y"] = 0, ["param1"] = 15, ["z"] = 8, ["name"] = "default:silver_sandstone_block"}, {["x"] = 2, ["y"] = 0, ["param1"] = 15, ["z"] = 9, ["name"] = "default:silver_sandstone_block"}, {["x"] = 2, ["y"] = 0, ["param1"] = 15, ["z"] = 10, ["name"] = "default:silver_sandstone_block"}, {["x"] = 2, ["y"] = 0, ["param1"] = 15, ["z"] = 11, ["name"] = "default:silver_sandstone_block"}, {["x"] = 2, ["y"] = 0, ["param1"] = 15, ["z"] = 12, ["name"] = "default:silver_sandstone_block"}, {["x"] = 2, ["y"] = 0, ["param1"] = 15, ["z"] = 13, ["name"] = "default:silver_sandstone_block"}, {["x"] = 2, ["y"] = 0, ["param1"] = 15, ["z"] = 14, ["name"] = "default:silver_sandstone_block"}, {["x"] = 2, ["y"] = 0, ["param1"] = 15, ["z"] = 15, ["name"] = "default:silver_sandstone_block"}, {["x"] = 2, ["y"] = 0, ["param1"] = 15, ["z"] = 16, ["name"] = "default:silver_sandstone_block"}, {["x"] = 2, ["y"] = 0, ["param1"] = 15, ["z"] = 17, ["name"] = "default:silver_sandstone_block"}, {["x"] = 2, ["y"] = 0, ["param1"] = 15, ["z"] = 18, ["name"] = "default:silver_sandstone_block"}, {["x"] = 2, ["y"] = 0, ["param1"] = 15, ["z"] = 19, ["name"] = "default:silver_sandstone_block"}, {["x"] = 2, ["y"] = 0, ["param1"] = 15, ["z"] = 20, ["name"] = "default:silver_sandstone_block"}, {["x"] = 2, ["y"] = 0, ["param1"] = 15, ["z"] = 21, ["name"] = "default:silver_sandstone_block"}, {["x"] = 2, ["y"] = 0, ["param1"] = 15, ["z"] = 22, ["name"] = "default:silver_sandstone_block"}, {["x"] = 2, ["y"] = 0, ["param1"] = 15, ["z"] = 23, ["name"] = "default:silver_sandstone_block"}, {["x"] = 2, ["y"] = 0, ["param1"] = 15, ["z"] = 24, ["name"] = "default:silver_sandstone_block"}, {["x"] = 2, ["y"] = 0, ["param1"] = 15, ["z"] = 25, ["name"] = "default:silver_sandstone_block"}, {["x"] = 2, ["y"] = 0, ["param1"] = 15, ["z"] = 26, ["name"] = "default:silver_sandstone_block"}, {["x"] = 2, ["y"] = 0, ["param1"] = 15, ["z"] = 27, ["name"] = "default:desert_sandstone_block"}, {["x"] = 3, ["y"] = 0, ["param1"] = 15, ["z"] = 0, ["name"] = "default:desert_sandstone_block"}, {["x"] = 3, ["y"] = 0, ["param1"] = 15, ["z"] = 1, ["name"] = "default:silver_sandstone_block"}, {["x"] = 3, ["y"] = 0, ["param1"] = 15, ["z"] = 2, ["name"] = "default:silver_sandstone_block"}, {["x"] = 3, ["y"] = 0, ["param1"] = 15, ["z"] = 3, ["name"] = "default:silver_sandstone_block"}, {["x"] = 3, ["y"] = 0, ["param1"] = 15, ["z"] = 4, ["name"] = "default:silver_sandstone_block"}, {["x"] = 3, ["y"] = 0, ["param1"] = 15, ["z"] = 5, ["name"] = "default:silver_sandstone_block"}, {["x"] = 3, ["y"] = 0, ["param1"] = 15, ["z"] = 6, ["name"] = "default:silver_sandstone_block"}, {["x"] = 3, ["y"] = 0, ["param1"] = 15, ["z"] = 7, ["name"] = "default:silver_sandstone_block"}, {["x"] = 3, ["y"] = 0, ["param1"] = 15, ["z"] = 8, ["name"] = "default:silver_sandstone_block"}, {["x"] = 3, ["y"] = 0, ["param1"] = 15, ["z"] = 9, ["name"] = "default:silver_sandstone_block"}, {["x"] = 3, ["y"] = 0, ["param1"] = 15, ["z"] = 10, ["name"] = "default:silver_sandstone_block"}, {["x"] = 3, ["y"] = 0, ["param1"] = 15, ["z"] = 11, ["name"] = "default:silver_sandstone_block"}, {["x"] = 3, ["y"] = 0, ["param1"] = 15, ["z"] = 12, ["name"] = "default:silver_sandstone_block"}, {["x"] = 3, ["y"] = 0, ["param1"] = 15, ["z"] = 13, ["name"] = "default:silver_sandstone_block"}, {["x"] = 3, ["y"] = 0, ["param1"] = 15, ["z"] = 14, ["name"] = "default:silver_sandstone_block"}, {["x"] = 3, ["y"] = 0, ["param1"] = 15, ["z"] = 15, ["name"] = "default:silver_sandstone_block"}, {["x"] = 3, ["y"] = 0, ["param1"] = 15, ["z"] = 16, ["name"] = "default:silver_sandstone_block"}, {["x"] = 3, ["y"] = 0, ["param1"] = 15, ["z"] = 17, ["name"] = "default:silver_sandstone_block"}, {["x"] = 3, ["y"] = 0, ["param1"] = 15, ["z"] = 18, ["name"] = "default:silver_sandstone_block"}, {["x"] = 3, ["y"] = 0, ["param1"] = 15, ["z"] = 19, ["name"] = "default:silver_sandstone_block"}, {["x"] = 3, ["y"] = 0, ["param1"] = 15, ["z"] = 20, ["name"] = "default:silver_sandstone_block"}, {["x"] = 3, ["y"] = 0, ["param1"] = 15, ["z"] = 21, ["name"] = "default:silver_sandstone_block"}, {["x"] = 3, ["y"] = 0, ["param1"] = 15, ["z"] = 22, ["name"] = "default:silver_sandstone_block"}, {["x"] = 3, ["y"] = 0, ["param1"] = 15, ["z"] = 23, ["name"] = "default:silver_sandstone_block"}, {["x"] = 3, ["y"] = 0, ["param1"] = 15, ["z"] = 24, ["name"] = "default:silver_sandstone_block"}, {["x"] = 3, ["y"] = 0, ["param1"] = 15, ["z"] = 25, ["name"] = "default:silver_sandstone_block"}, {["x"] = 3, ["y"] = 0, ["param1"] = 15, ["z"] = 26, ["name"] = "default:silver_sandstone_block"}, {["x"] = 3, ["y"] = 0, ["param1"] = 15, ["z"] = 27, ["name"] = "default:desert_sandstone_block"}, {["x"] = 3, ["y"] = 1, ["param1"] = 16, ["z"] = 4, ["name"] = "default:silver_sandstone"}, {["x"] = 3, ["y"] = 1, ["param1"] = 16, ["z"] = 5, ["name"] = "default:silver_sandstone"}, {["x"] = 3, ["y"] = 1, ["param1"] = 16, ["z"] = 6, ["name"] = "default:silver_sandstone"}, {["x"] = 3, ["y"] = 1, ["param1"] = 16, ["z"] = 7, ["name"] = "default:silver_sandstone"}, {["x"] = 3, ["y"] = 1, ["param1"] = 16, ["z"] = 8, ["name"] = "default:silver_sandstone"}, {["x"] = 3, ["y"] = 1, ["param1"] = 16, ["z"] = 9, ["name"] = "default:silver_sandstone"}, {["x"] = 3, ["y"] = 1, ["param1"] = 16, ["z"] = 10, ["name"] = "default:silver_sandstone"}, {["x"] = 3, ["y"] = 1, ["param1"] = 16, ["z"] = 11, ["name"] = "default:silver_sandstone"}, {["x"] = 3, ["y"] = 1, ["param1"] = 16, ["z"] = 12, ["name"] = "default:silver_sandstone"}, {["x"] = 3, ["y"] = 1, ["param1"] = 16, ["z"] = 16, ["name"] = "default:silver_sandstone"}, {["x"] = 3, ["y"] = 1, ["param1"] = 16, ["z"] = 17, ["name"] = "default:silver_sandstone"}, {["x"] = 3, ["y"] = 1, ["param1"] = 16, ["z"] = 18, ["name"] = "default:silver_sandstone"}, {["x"] = 3, ["y"] = 1, ["param1"] = 16, ["z"] = 19, ["name"] = "default:silver_sandstone"}, {["x"] = 3, ["y"] = 1, ["param1"] = 16, ["z"] = 20, ["name"] = "default:silver_sandstone"}, {["x"] = 3, ["y"] = 1, ["param1"] = 16, ["z"] = 21, ["name"] = "default:silver_sandstone"}, {["x"] = 3, ["y"] = 1, ["param1"] = 16, ["z"] = 22, ["name"] = "default:silver_sandstone"}, {["x"] = 3, ["y"] = 1, ["param1"] = 16, ["z"] = 23, ["name"] = "default:silver_sandstone"}, {["x"] = 3, ["y"] = 1, ["param1"] = 16, ["z"] = 24, ["name"] = "default:silver_sandstone"}, {["x"] = 3, ["y"] = 2, ["param1"] = 16, ["z"] = 4, ["name"] = "default:silver_sandstone"}, {["x"] = 3, ["y"] = 2, ["param1"] = 16, ["z"] = 5, ["name"] = "default:silver_sandstone"}, {["x"] = 3, ["y"] = 2, ["param1"] = 16, ["z"] = 6, ["name"] = "default:silver_sandstone"}, {["x"] = 3, ["y"] = 2, ["param1"] = 16, ["z"] = 7, ["name"] = "default:silver_sandstone"}, {["x"] = 3, ["y"] = 2, ["param1"] = 16, ["z"] = 8, ["name"] = "default:silver_sandstone"}, {["x"] = 3, ["y"] = 2, ["param1"] = 16, ["z"] = 9, ["name"] = "default:silver_sandstone"}, {["x"] = 3, ["y"] = 2, ["param1"] = 16, ["z"] = 10, ["name"] = "default:silver_sandstone"}, {["x"] = 3, ["y"] = 2, ["param1"] = 16, ["z"] = 11, ["name"] = "default:silver_sandstone"}, {["x"] = 3, ["y"] = 2, ["param1"] = 16, ["z"] = 12, ["name"] = "default:silver_sandstone"}, {["x"] = 3, ["y"] = 2, ["param1"] = 16, ["z"] = 16, ["name"] = "default:silver_sandstone"}, {["x"] = 3, ["y"] = 2, ["param1"] = 16, ["z"] = 17, ["name"] = "default:silver_sandstone"}, {["x"] = 3, ["y"] = 2, ["param1"] = 16, ["z"] = 18, ["name"] = "default:silver_sandstone"}, {["x"] = 3, ["y"] = 2, ["param1"] = 16, ["z"] = 19, ["name"] = "default:silver_sandstone"}, {["x"] = 3, ["y"] = 2, ["param1"] = 16, ["z"] = 20, ["name"] = "default:silver_sandstone"}, {["x"] = 3, ["y"] = 2, ["param1"] = 16, ["z"] = 21, ["name"] = "default:silver_sandstone"}, {["x"] = 3, ["y"] = 2, ["param1"] = 16, ["z"] = 22, ["name"] = "default:silver_sandstone"}, {["x"] = 3, ["y"] = 2, ["param1"] = 16, ["z"] = 23, ["name"] = "default:silver_sandstone"}, {["x"] = 3, ["y"] = 2, ["param1"] = 16, ["z"] = 24, ["name"] = "default:silver_sandstone"}, {["x"] = 3, ["y"] = 3, ["param1"] = 16, ["z"] = 4, ["name"] = "default:silver_sandstone"}, {["x"] = 3, ["y"] = 3, ["param1"] = 16, ["z"] = 5, ["name"] = "default:silver_sandstone"}, {["x"] = 3, ["y"] = 3, ["param1"] = 16, ["z"] = 6, ["name"] = "default:silver_sandstone"}, {["x"] = 3, ["y"] = 3, ["param1"] = 16, ["z"] = 7, ["name"] = "default:silver_sandstone"}, {["x"] = 3, ["y"] = 3, ["param1"] = 16, ["z"] = 8, ["name"] = "default:silver_sandstone"}, {["x"] = 3, ["y"] = 3, ["param1"] = 16, ["z"] = 9, ["name"] = "default:silver_sandstone"}, {["x"] = 3, ["y"] = 3, ["param1"] = 16, ["z"] = 10, ["name"] = "default:silver_sandstone"}, {["x"] = 3, ["y"] = 3, ["param1"] = 16, ["z"] = 11, ["name"] = "default:silver_sandstone"}, {["x"] = 3, ["y"] = 3, ["param1"] = 16, ["z"] = 12, ["name"] = "default:silver_sandstone"}, {["x"] = 3, ["y"] = 3, ["param1"] = 16, ["z"] = 16, ["name"] = "default:silver_sandstone"}, {["x"] = 3, ["y"] = 3, ["param1"] = 16, ["z"] = 17, ["name"] = "default:silver_sandstone"}, {["x"] = 3, ["y"] = 3, ["param1"] = 16, ["z"] = 18, ["name"] = "default:silver_sandstone"}, {["x"] = 3, ["y"] = 3, ["param1"] = 16, ["z"] = 19, ["name"] = "default:silver_sandstone"}, {["x"] = 3, ["y"] = 3, ["param1"] = 16, ["z"] = 20, ["name"] = "default:silver_sandstone"}, {["x"] = 3, ["y"] = 3, ["param1"] = 16, ["z"] = 21, ["name"] = "default:silver_sandstone"}, {["x"] = 3, ["y"] = 3, ["param1"] = 16, ["z"] = 22, ["name"] = "default:silver_sandstone"}, {["x"] = 3, ["y"] = 3, ["param1"] = 16, ["z"] = 23, ["name"] = "default:silver_sandstone"}, {["x"] = 3, ["y"] = 3, ["param1"] = 16, ["z"] = 24, ["name"] = "default:silver_sandstone"}, {["x"] = 3, ["param2"] = 2, ["y"] = 4, ["param1"] = 14, ["z"] = 4, ["name"] = "stairs:slab_silver_sandstone"}, {["x"] = 3, ["param2"] = 1, ["y"] = 4, ["param1"] = 14, ["z"] = 5, ["name"] = "stairs:slab_silver_sandstone"}, {["x"] = 3, ["y"] = 4, ["param1"] = 14, ["z"] = 6, ["name"] = "stairs:slab_silver_sandstone"}, {["x"] = 3, ["y"] = 4, ["param1"] = 14, ["z"] = 7, ["name"] = "stairs:slab_silver_sandstone"}, {["x"] = 3, ["y"] = 4, ["param1"] = 14, ["z"] = 8, ["name"] = "stairs:slab_silver_sandstone"}, {["x"] = 3, ["y"] = 4, ["param1"] = 14, ["z"] = 9, ["name"] = "stairs:slab_silver_sandstone"}, {["x"] = 3, ["y"] = 4, ["param1"] = 14, ["z"] = 10, ["name"] = "stairs:slab_silver_sandstone"}, {["x"] = 3, ["y"] = 4, ["param1"] = 14, ["z"] = 11, ["name"] = "stairs:slab_silver_sandstone"}, {["x"] = 3, ["y"] = 4, ["param1"] = 14, ["z"] = 12, ["name"] = "stairs:slab_silver_sandstone"}, {["x"] = 3, ["param2"] = 2, ["y"] = 4, ["param1"] = 62, ["z"] = 16, ["name"] = "stairs:slab_silver_sandstone"}, {["x"] = 3, ["param2"] = 1, ["y"] = 4, ["param1"] = 78, ["z"] = 17, ["name"] = "stairs:slab_silver_sandstone"}, {["x"] = 3, ["y"] = 4, ["param1"] = 94, ["z"] = 18, ["name"] = "stairs:slab_silver_sandstone"}, {["x"] = 3, ["y"] = 4, ["param1"] = 110, ["z"] = 19, ["name"] = "stairs:slab_silver_sandstone"}, {["x"] = 3, ["y"] = 4, ["param1"] = 94, ["z"] = 20, ["name"] = "stairs:slab_silver_sandstone"}, {["x"] = 3, ["y"] = 4, ["param1"] = 110, ["z"] = 21, ["name"] = "stairs:slab_silver_sandstone"}, {["x"] = 3, ["y"] = 4, ["param1"] = 94, ["z"] = 22, ["name"] = "stairs:slab_silver_sandstone"}, {["x"] = 3, ["y"] = 4, ["param1"] = 78, ["z"] = 23, ["name"] = "stairs:slab_silver_sandstone"}, {["x"] = 3, ["y"] = 4, ["param1"] = 62, ["z"] = 24, ["name"] = "stairs:slab_silver_sandstone"}, {["x"] = 4, ["y"] = 0, ["param1"] = 15, ["z"] = 0, ["name"] = "default:desert_sandstone_block"}, {["x"] = 4, ["y"] = 0, ["param1"] = 15, ["z"] = 1, ["name"] = "default:silver_sandstone_block"}, {["x"] = 4, ["y"] = 0, ["param1"] = 15, ["z"] = 2, ["name"] = "default:silver_sandstone_block"}, {["x"] = 4, ["y"] = 0, ["param1"] = 15, ["z"] = 3, ["name"] = "default:silver_sandstone_block"}, {["x"] = 4, ["y"] = 0, ["param1"] = 15, ["z"] = 4, ["name"] = "default:silver_sandstone_block"}, {["x"] = 4, ["y"] = 0, ["param1"] = 15, ["z"] = 5, ["name"] = "default:silver_sandstone_block"}, {["x"] = 4, ["y"] = 0, ["param1"] = 15, ["z"] = 6, ["name"] = "default:silver_sandstone_block"}, {["x"] = 4, ["y"] = 0, ["param1"] = 15, ["z"] = 7, ["name"] = "default:silver_sandstone_block"}, {["x"] = 4, ["y"] = 0, ["param1"] = 15, ["z"] = 8, ["name"] = "default:silver_sandstone_block"}, {["x"] = 4, ["y"] = 0, ["param1"] = 15, ["z"] = 9, ["name"] = "default:silver_sandstone_block"}, {["x"] = 4, ["y"] = 0, ["param1"] = 15, ["z"] = 10, ["name"] = "default:silver_sandstone_block"}, {["x"] = 4, ["y"] = 0, ["param1"] = 15, ["z"] = 11, ["name"] = "default:silver_sandstone_block"}, {["x"] = 4, ["y"] = 0, ["param1"] = 15, ["z"] = 12, ["name"] = "default:silver_sandstone_block"}, {["x"] = 4, ["y"] = 0, ["param1"] = 15, ["z"] = 13, ["name"] = "default:silver_sandstone_block"}, {["x"] = 4, ["y"] = 0, ["param1"] = 15, ["z"] = 14, ["name"] = "default:silver_sandstone_block"}, {["x"] = 4, ["y"] = 0, ["param1"] = 15, ["z"] = 15, ["name"] = "default:silver_sandstone_block"}, {["x"] = 4, ["y"] = 0, ["param1"] = 15, ["z"] = 16, ["name"] = "default:silver_sandstone_block"}, {["x"] = 4, ["y"] = 0, ["param1"] = 15, ["z"] = 17, ["name"] = "default:silver_sandstone_block"}, {["x"] = 4, ["y"] = 0, ["param1"] = 15, ["z"] = 18, ["name"] = "default:silver_sandstone_block"}, {["x"] = 4, ["y"] = 0, ["param1"] = 15, ["z"] = 19, ["name"] = "default:silver_sandstone_block"}, {["x"] = 4, ["y"] = 0, ["param1"] = 15, ["z"] = 20, ["name"] = "default:silver_sandstone_block"}, {["x"] = 4, ["y"] = 0, ["param1"] = 15, ["z"] = 21, ["name"] = "default:silver_sandstone_block"}, {["x"] = 4, ["y"] = 0, ["param1"] = 15, ["z"] = 22, ["name"] = "default:silver_sandstone_block"}, {["x"] = 4, ["y"] = 0, ["param1"] = 15, ["z"] = 23, ["name"] = "default:silver_sandstone_block"}, {["x"] = 4, ["y"] = 0, ["param1"] = 15, ["z"] = 24, ["name"] = "default:silver_sandstone_block"}, {["x"] = 4, ["y"] = 0, ["param1"] = 15, ["z"] = 25, ["name"] = "default:silver_sandstone_block"}, {["x"] = 4, ["y"] = 0, ["param1"] = 15, ["z"] = 26, ["name"] = "default:silver_sandstone_block"}, {["x"] = 4, ["y"] = 0, ["param1"] = 15, ["z"] = 27, ["name"] = "default:desert_sandstone_block"}, {["x"] = 4, ["y"] = 1, ["param1"] = 16, ["z"] = 4, ["name"] = "default:silver_sandstone"}, {["x"] = 4, ["y"] = 1, ["param1"] = 16, ["z"] = 12, ["name"] = "default:silver_sandstone"}, {["x"] = 4, ["y"] = 1, ["param1"] = 16, ["z"] = 16, ["name"] = "default:silver_sandstone"}, {["x"] = 4, ["y"] = 1, ["param1"] = 16, ["z"] = 24, ["name"] = "default:silver_sandstone"}, {["x"] = 4, ["y"] = 2, ["param1"] = 16, ["z"] = 4, ["name"] = "default:silver_sandstone"}, {["x"] = 4, ["y"] = 2, ["param1"] = 16, ["z"] = 5, ["name"] = "default:silver_sandstone"}, {["x"] = 4, ["y"] = 2, ["param1"] = 16, ["z"] = 6, ["name"] = "default:silver_sandstone"}, {["x"] = 4, ["y"] = 2, ["param1"] = 16, ["z"] = 7, ["name"] = "default:silver_sandstone"}, {["x"] = 4, ["y"] = 2, ["param1"] = 16, ["z"] = 8, ["name"] = "default:silver_sandstone"}, {["x"] = 4, ["y"] = 2, ["param1"] = 16, ["z"] = 9, ["name"] = "default:silver_sandstone"}, {["x"] = 4, ["y"] = 2, ["param1"] = 16, ["z"] = 10, ["name"] = "default:silver_sandstone"}, {["x"] = 4, ["y"] = 2, ["param1"] = 16, ["z"] = 11, ["name"] = "default:silver_sandstone"}, {["x"] = 4, ["y"] = 2, ["param1"] = 16, ["z"] = 12, ["name"] = "default:silver_sandstone"}, {["x"] = 4, ["y"] = 2, ["param1"] = 16, ["z"] = 16, ["name"] = "default:silver_sandstone"}, {["x"] = 4, ["y"] = 2, ["param1"] = 16, ["z"] = 17, ["name"] = "default:silver_sandstone"}, {["x"] = 4, ["y"] = 2, ["param1"] = 16, ["z"] = 18, ["name"] = "default:silver_sandstone"}, {["x"] = 4, ["y"] = 2, ["param1"] = 16, ["z"] = 19, ["name"] = "default:silver_sandstone"}, {["x"] = 4, ["y"] = 2, ["param1"] = 16, ["z"] = 20, ["name"] = "default:silver_sandstone"}, {["x"] = 4, ["y"] = 2, ["param1"] = 16, ["z"] = 21, ["name"] = "default:silver_sandstone"}, {["x"] = 4, ["y"] = 2, ["param1"] = 16, ["z"] = 22, ["name"] = "default:silver_sandstone"}, {["x"] = 4, ["y"] = 2, ["param1"] = 16, ["z"] = 23, ["name"] = "default:silver_sandstone"}, {["x"] = 4, ["y"] = 2, ["param1"] = 16, ["z"] = 24, ["name"] = "default:silver_sandstone"}, {["x"] = 4, ["y"] = 3, ["param1"] = 16, ["z"] = 4, ["name"] = "default:silver_sandstone"}, {["x"] = 4, ["param2"] = 2, ["y"] = 3, ["param1"] = 13, ["z"] = 5, ["name"] = "mesecons_extrawires:corner_off"}, {["x"] = 4, ["param2"] = 3, ["y"] = 3, ["param1"] = 13, ["z"] = 6, ["name"] = "mesecons_insulated:insulated_off"}, {["x"] = 4, ["param2"] = 3, ["y"] = 3, ["param1"] = 13, ["z"] = 7, ["name"] = "mesecons_extrawires:corner_off"}, {["x"] = 4, ["param2"] = 2, ["y"] = 3, ["param1"] = 13, ["z"] = 9, ["name"] = "mesecons_extrawires:corner_off"}, {["x"] = 4, ["param2"] = 3, ["y"] = 3, ["param1"] = 13, ["z"] = 10, ["name"] = "mesecons_insulated:insulated_off"}, {["x"] = 4, ["param2"] = 3, ["y"] = 3, ["param1"] = 13, ["z"] = 11, ["name"] = "mesecons_extrawires:corner_off"}, {["x"] = 4, ["y"] = 3, ["param1"] = 16, ["z"] = 12, ["name"] = "default:silver_sandstone"}, {["x"] = 4, ["y"] = 3, ["param1"] = 16, ["z"] = 16, ["name"] = "default:silver_sandstone"}, {["x"] = 4, ["param2"] = 2, ["y"] = 3, ["param1"] = 109, ["z"] = 21, ["name"] = "mesecons_extrawires:corner_on"}, {["x"] = 4, ["param2"] = 3, ["y"] = 3, ["param1"] = 93, ["z"] = 22, ["name"] = "mesecons_insulated:insulated_on"}, {["x"] = 4, ["param2"] = 3, ["y"] = 3, ["param1"] = 77, ["z"] = 23, ["name"] = "mesecons_extrawires:corner_on"}, {["x"] = 4, ["y"] = 3, ["param1"] = 16, ["z"] = 24, ["name"] = "default:silver_sandstone"}, {["x"] = 4, ["param2"] = 1, ["y"] = 4, ["param1"] = 14, ["z"] = 4, ["name"] = "stairs:slab_silver_sandstone"}, {["x"] = 4, ["y"] = 4, ["param1"] = 14, ["z"] = 5, ["name"] = "stairs:slab_silver_sandstone"}, {["x"] = 4, ["y"] = 4, ["param1"] = 14, ["z"] = 6, ["name"] = "stairs:slab_silver_sandstone"}, {["x"] = 4, ["y"] = 4, ["param1"] = 14, ["z"] = 7, ["name"] = "stairs:slab_silver_sandstone"}, {["x"] = 4, ["param2"] = 1, ["y"] = 4, ["param1"] = 14, ["z"] = 8, ["name"] = "stairs:slab_silver_sandstone"}, {["x"] = 4, ["y"] = 4, ["param1"] = 14, ["z"] = 9, ["name"] = "stairs:slab_silver_sandstone"}, {["x"] = 4, ["y"] = 4, ["param1"] = 14, ["z"] = 10, ["name"] = "stairs:slab_silver_sandstone"}, {["x"] = 4, ["y"] = 4, ["param1"] = 14, ["z"] = 11, ["name"] = "stairs:slab_silver_sandstone"}, {["x"] = 4, ["y"] = 4, ["param1"] = 14, ["z"] = 12, ["name"] = "stairs:slab_silver_sandstone"}, {["x"] = 4, ["param2"] = 1, ["y"] = 4, ["param1"] = 78, ["z"] = 16, ["name"] = "stairs:slab_silver_sandstone"}, {["x"] = 4, ["y"] = 4, ["param1"] = 94, ["z"] = 17, ["name"] = "stairs:slab_silver_sandstone"}, {["x"] = 4, ["y"] = 4, ["param1"] = 110, ["z"] = 18, ["name"] = "stairs:slab_silver_sandstone"}, {["x"] = 4, ["y"] = 4, ["param1"] = 126, ["z"] = 19, ["name"] = "stairs:slab_silver_sandstone"}, {["x"] = 4, ["param2"] = 1, ["y"] = 4, ["param1"] = 110, ["z"] = 20, ["name"] = "stairs:slab_silver_sandstone"}, {["x"] = 4, ["y"] = 4, ["param1"] = 126, ["z"] = 21, ["name"] = "stairs:slab_silver_sandstone"}, {["x"] = 4, ["y"] = 4, ["param1"] = 110, ["z"] = 22, ["name"] = "stairs:slab_silver_sandstone"}, {["x"] = 4, ["y"] = 4, ["param1"] = 94, ["z"] = 23, ["name"] = "stairs:slab_silver_sandstone"}, {["x"] = 4, ["y"] = 4, ["param1"] = 78, ["z"] = 24, ["name"] = "stairs:slab_silver_sandstone"}, {["x"] = 5, ["y"] = 0, ["param1"] = 15, ["z"] = 0, ["name"] = "default:desert_sandstone_block"}, {["x"] = 5, ["y"] = 0, ["param1"] = 15, ["z"] = 1, ["name"] = "default:silver_sandstone_block"}, {["x"] = 5, ["y"] = 0, ["param1"] = 15, ["z"] = 2, ["name"] = "default:silver_sandstone_block"}, {["x"] = 5, ["y"] = 0, ["param1"] = 15, ["z"] = 3, ["name"] = "default:silver_sandstone_block"}, {["x"] = 5, ["y"] = 0, ["param1"] = 15, ["z"] = 4, ["name"] = "default:silver_sandstone_block"}, {["x"] = 5, ["y"] = 0, ["param1"] = 15, ["z"] = 5, ["name"] = "default:silver_sandstone_block"}, {["x"] = 5, ["y"] = 0, ["param1"] = 15, ["z"] = 6, ["name"] = "default:silver_sandstone_block"}, {["x"] = 5, ["y"] = 0, ["param1"] = 15, ["z"] = 7, ["name"] = "default:silver_sandstone_block"}, {["x"] = 5, ["y"] = 0, ["param1"] = 15, ["z"] = 8, ["name"] = "default:silver_sandstone_block"}, {["x"] = 5, ["y"] = 0, ["param1"] = 15, ["z"] = 9, ["name"] = "default:silver_sandstone_block"}, {["x"] = 5, ["y"] = 0, ["param1"] = 15, ["z"] = 10, ["name"] = "default:silver_sandstone_block"}, {["x"] = 5, ["y"] = 0, ["param1"] = 15, ["z"] = 11, ["name"] = "default:silver_sandstone_block"}, {["x"] = 5, ["y"] = 0, ["param1"] = 15, ["z"] = 12, ["name"] = "default:silver_sandstone_block"}, {["x"] = 5, ["y"] = 0, ["param1"] = 15, ["z"] = 13, ["name"] = "default:silver_sandstone_block"}, {["x"] = 5, ["y"] = 0, ["param1"] = 15, ["z"] = 14, ["name"] = "default:silver_sandstone_block"}, {["x"] = 5, ["y"] = 0, ["param1"] = 15, ["z"] = 15, ["name"] = "default:silver_sandstone_block"}, {["x"] = 5, ["y"] = 0, ["param1"] = 15, ["z"] = 16, ["name"] = "default:silver_sandstone_block"}, {["x"] = 5, ["y"] = 0, ["param1"] = 15, ["z"] = 17, ["name"] = "default:silver_sandstone_block"}, {["x"] = 5, ["y"] = 0, ["param1"] = 15, ["z"] = 18, ["name"] = "default:silver_sandstone_block"}, {["x"] = 5, ["y"] = 0, ["param1"] = 15, ["z"] = 19, ["name"] = "default:silver_sandstone_block"}, {["x"] = 5, ["y"] = 0, ["param1"] = 15, ["z"] = 20, ["name"] = "default:silver_sandstone_block"}, {["x"] = 5, ["y"] = 0, ["param1"] = 15, ["z"] = 21, ["name"] = "default:silver_sandstone_block"}, {["x"] = 5, ["y"] = 0, ["param1"] = 15, ["z"] = 22, ["name"] = "default:silver_sandstone_block"}, {["x"] = 5, ["y"] = 0, ["param1"] = 15, ["z"] = 23, ["name"] = "default:silver_sandstone_block"}, {["x"] = 5, ["y"] = 0, ["param1"] = 15, ["z"] = 24, ["name"] = "default:silver_sandstone_block"}, {["x"] = 5, ["y"] = 0, ["param1"] = 15, ["z"] = 25, ["name"] = "default:silver_sandstone_block"}, {["x"] = 5, ["y"] = 0, ["param1"] = 15, ["z"] = 26, ["name"] = "default:silver_sandstone_block"}, {["x"] = 5, ["y"] = 0, ["param1"] = 15, ["z"] = 27, ["name"] = "default:desert_sandstone_block"}, {["x"] = 5, ["y"] = 1, ["z"] = 2, ["name"] = "mesecons_switch:mesecon_switch_off"}, {["x"] = 5, ["param2"] = 3, ["y"] = 1, ["param1"] = 47, ["z"] = 3, ["name"] = "mesecons_insulated:insulated_off"}, {["x"] = 5, ["y"] = 1, ["param1"] = 62, ["z"] = 4, ["name"] = "default:mese"}, {["x"] = 5, ["param2"] = 3, ["y"] = 1, ["param1"] = 45, ["z"] = 5, ["name"] = "mesecons_insulated:insulated_off"}, {["x"] = 5, ["y"] = 1, ["param1"] = 28, ["z"] = 6, ["name"] = "mesecons_extrawires:vertical_bottom_off"}, {["x"] = 5, ["param2"] = 3, ["y"] = 1, ["param1"] = 11, ["z"] = 7, ["name"] = "mesecons_insulated:insulated_off"}, {["x"] = 5, ["param2"] = 3, ["y"] = 1, ["param1"] = 10, ["z"] = 8, ["name"] = "mesecons_insulated:insulated_off"}, {["x"] = 5, ["param2"] = 3, ["y"] = 1, ["param1"] = 11, ["z"] = 9, ["name"] = "mesecons_insulated:insulated_off"}, {["x"] = 5, ["y"] = 1, ["param1"] = 28, ["z"] = 10, ["name"] = "mesecons_extrawires:vertical_bottom_off"}, {["x"] = 5, ["param2"] = 3, ["y"] = 1, ["param1"] = 45, ["z"] = 11, ["name"] = "mesecons_insulated:insulated_off"}, {["x"] = 5, ["y"] = 1, ["param1"] = 62, ["z"] = 12, ["name"] = "default:mese"}, {["x"] = 5, ["y"] = 1, ["param1"] = 62, ["z"] = 16, ["name"] = "default:mese"}, {["x"] = 5, ["param2"] = 3, ["y"] = 1, ["param1"] = 45, ["z"] = 17, ["name"] = "mesecons_insulated:insulated_off"}, {["x"] = 5, ["param2"] = 3, ["y"] = 1, ["param1"] = 28, ["z"] = 18, ["name"] = "mesecons_insulated:insulated_off"}, {["x"] = 5, ["param2"] = 3, ["y"] = 1, ["param1"] = 27, ["z"] = 19, ["name"] = "mesecons_insulated:insulated_off"}, {["x"] = 5, ["param2"] = 3, ["y"] = 1, ["param1"] = 42, ["z"] = 20, ["name"] = "mesecons_insulated:insulated_off"}, {["x"] = 5, ["param2"] = 3, ["y"] = 1, ["param1"] = 59, ["z"] = 21, ["name"] = "mesecons_insulated:insulated_off"}, {["x"] = 5, ["y"] = 1, ["param1"] = 76, ["z"] = 22, ["name"] = "mesecons_extrawires:vertical_bottom_off"}, {["x"] = 5, ["param2"] = 3, ["y"] = 1, ["param1"] = 61, ["z"] = 23, ["name"] = "mesecons_insulated:insulated_off"}, {["x"] = 5, ["y"] = 1, ["param1"] = 62, ["z"] = 24, ["name"] = "default:mese"}, {["x"] = 5, ["meta"] = {["fields"] = {["infotext"] = "\"Input / Output 4\"", ["text"] = "Input / Output 4", ["formspec"] = "field[text;;${text}]"}, ["inventory"] = {}}, ["param2"] = 4, ["y"] = 2, ["param1"] = 31, ["z"] = 3, ["name"] = "default:sign_wall_steel"}, {["x"] = 5, ["y"] = 2, ["param1"] = 16, ["z"] = 4, ["name"] = "default:silver_sandstone"}, {["x"] = 5, ["y"] = 2, ["param1"] = 16, ["z"] = 5, ["name"] = "default:silver_sandstone"}, {["x"] = 5, ["y"] = 2, ["param1"] = 12, ["z"] = 6, ["name"] = "mesecons_extrawires:vertical_off"}, {["x"] = 5, ["y"] = 2, ["param1"] = 16, ["z"] = 7, ["name"] = "default:silver_sandstone"}, {["x"] = 5, ["y"] = 2, ["param1"] = 16, ["z"] = 8, ["name"] = "default:silver_sandstone"}, {["x"] = 5, ["y"] = 2, ["param1"] = 16, ["z"] = 9, ["name"] = "default:silver_sandstone"}, {["x"] = 5, ["y"] = 2, ["param1"] = 12, ["z"] = 10, ["name"] = "mesecons_extrawires:vertical_off"}, {["x"] = 5, ["y"] = 2, ["param1"] = 16, ["z"] = 11, ["name"] = "default:silver_sandstone"}, {["x"] = 5, ["y"] = 2, ["param1"] = 16, ["z"] = 12, ["name"] = "default:silver_sandstone"}, {["x"] = 5, ["meta"] = {["fields"] = {["infotext"] = "\"Input / Output 4\"", ["text"] = "Input / Output 4", ["formspec"] = "field[text;;${text}]"}, ["inventory"] = {}}, ["param2"] = 5, ["y"] = 2, ["param1"] = 31, ["z"] = 13, ["name"] = "default:sign_wall_steel"}, {["x"] = 5, ["meta"] = {["fields"] = {["infotext"] = "\"Input / Output 4\"", ["text"] = "Input / Output 4", ["formspec"] = "field[text;;${text}]"}, ["inventory"] = {}}, ["param2"] = 4, ["y"] = 2, ["param1"] = 47, ["z"] = 15, ["name"] = "default:sign_wall_steel"}, {["x"] = 5, ["y"] = 2, ["param1"] = 16, ["z"] = 16, ["name"] = "default:silver_sandstone"}, {["x"] = 5, ["y"] = 2, ["param1"] = 16, ["z"] = 17, ["name"] = "default:silver_sandstone"}, {["x"] = 5, ["y"] = 2, ["param1"] = 16, ["z"] = 18, ["name"] = "default:silver_sandstone"}, {["x"] = 5, ["y"] = 2, ["param1"] = 16, ["z"] = 19, ["name"] = "default:silver_sandstone"}, {["x"] = 5, ["y"] = 2, ["param1"] = 16, ["z"] = 20, ["name"] = "default:silver_sandstone"}, {["x"] = 5, ["y"] = 2, ["param1"] = 16, ["z"] = 21, ["name"] = "default:silver_sandstone"}, {["x"] = 5, ["y"] = 2, ["param1"] = 92, ["z"] = 22, ["name"] = "mesecons_extrawires:vertical_off"}, {["x"] = 5, ["y"] = 2, ["param1"] = 16, ["z"] = 23, ["name"] = "default:silver_sandstone"}, {["x"] = 5, ["y"] = 2, ["param1"] = 16, ["z"] = 24, ["name"] = "default:silver_sandstone"}, {["x"] = 5, ["meta"] = {["fields"] = {["infotext"] = "\"Input / Output 4\"", ["formspec"] = "field[text;;${text}]", ["text"] = "Input / Output 4"}, ["inventory"] = {}}, ["param2"] = 5, ["y"] = 2, ["param1"] = 47, ["z"] = 25, ["name"] = "default:sign_wall_steel"}, {["x"] = 5, ["y"] = 3, ["param1"] = 16, ["z"] = 4, ["name"] = "default:silver_sandstone"}, {["x"] = 5, ["param2"] = 2, ["y"] = 3, ["param1"] = 13, ["z"] = 5, ["name"] = "mesecons_insulated:insulated_off"}, {["x"] = 5, ["y"] = 3, ["param1"] = 13, ["z"] = 6, ["name"] = "mesecons_extrawires:vertical_top_off"}, {["x"] = 5, ["meta"] = {["fields"] = {["infotext"] = "FPGA (functional)", ["portstates"] = "0000", ["valid"] = "1", ["instr"] = "A&DC//////////////"}, ["inventory"] = {}}, ["y"] = 3, ["param1"] = 13, ["z"] = 7, ["name"] = "mesecons_fpga:fpga0000"}, {["x"] = 5, ["y"] = 3, ["param1"] = 12, ["z"] = 8, ["name"] = "mesecons_extrawires:vertical_bottom_off"}, {["x"] = 5, ["meta"] = {["fields"] = {["infotext"] = "FPGA (functional)", ["portstates"] = "0000", ["valid"] = "1", ["instr"] = "A&DB//////////////"}, ["inventory"] = {}}, ["y"] = 3, ["param1"] = 13, ["z"] = 9, ["name"] = "mesecons_fpga:fpga0000"}, {["x"] = 5, ["y"] = 3, ["param1"] = 13, ["z"] = 10, ["name"] = "mesecons_extrawires:vertical_top_off"}, {["x"] = 5, ["y"] = 3, ["param1"] = 13, ["z"] = 11, ["name"] = "mesecons_insulated:insulated_off"}, {["x"] = 5, ["y"] = 3, ["param1"] = 16, ["z"] = 12, ["name"] = "default:silver_sandstone"}, {["x"] = 5, ["y"] = 3, ["param1"] = 16, ["z"] = 16, ["name"] = "default:silver_sandstone"}, {["x"] = 5, ["y"] = 3, ["param1"] = 18, ["z"] = 20, ["name"] = "default:silver_sandstone_block"}, {["x"] = 5, ["meta"] = {["fields"] = {["infotext"] = "FPGA (functional)", ["portstates"] = "1000", ["valid"] = "1", ["instr"] = "A&DB//////////////"}, ["inventory"] = {}}, ["y"] = 3, ["param1"] = 125, ["z"] = 21, ["name"] = "mesecons_fpga:fpga0000"}, {["x"] = 5, ["y"] = 3, ["param1"] = 109, ["z"] = 22, ["name"] = "mesecons_extrawires:vertical_top_off"}, {["x"] = 5, ["y"] = 3, ["param1"] = 93, ["z"] = 23, ["name"] = "mesecons_insulated:insulated_on"}, {["x"] = 5, ["y"] = 3, ["param1"] = 16, ["z"] = 24, ["name"] = "default:silver_sandstone"}, {["x"] = 5, ["y"] = 4, ["param1"] = 14, ["z"] = 4, ["name"] = "stairs:slab_silver_sandstone"}, {["x"] = 5, ["y"] = 4, ["param1"] = 14, ["z"] = 5, ["name"] = "stairs:slab_silver_sandstone"}, {["x"] = 5, ["y"] = 4, ["param1"] = 14, ["z"] = 6, ["name"] = "stairs:slab_silver_sandstone"}, {["x"] = 5, ["y"] = 4, ["param1"] = 14, ["z"] = 7, ["name"] = "stairs:slab_silver_sandstone"}, {["x"] = 5, ["y"] = 4, ["z"] = 8, ["name"] = "mesecons_lightstone:lightstone_green_off"}, {["x"] = 5, ["y"] = 4, ["param1"] = 14, ["z"] = 9, ["name"] = "stairs:slab_silver_sandstone"}, {["x"] = 5, ["y"] = 4, ["param1"] = 14, ["z"] = 10, ["name"] = "stairs:slab_silver_sandstone"}, {["x"] = 5, ["y"] = 4, ["param1"] = 14, ["z"] = 11, ["name"] = "stairs:slab_silver_sandstone"}, {["x"] = 5, ["y"] = 4, ["param1"] = 30, ["z"] = 12, ["name"] = "stairs:slab_silver_sandstone"}, {["x"] = 5, ["y"] = 4, ["param1"] = 94, ["z"] = 16, ["name"] = "stairs:slab_silver_sandstone"}, {["x"] = 5, ["y"] = 4, ["param1"] = 110, ["z"] = 17, ["name"] = "stairs:slab_silver_sandstone"}, {["x"] = 5, ["y"] = 4, ["param1"] = 126, ["z"] = 18, ["name"] = "stairs:slab_silver_sandstone"}, {["x"] = 5, ["y"] = 4, ["param1"] = 142, ["z"] = 19, ["name"] = "stairs:slab_silver_sandstone"}, {["x"] = 5, ["y"] = 4, ["param1"] = 18, ["z"] = 20, ["name"] = "default:silver_sandstone_block"}, {["x"] = 5, ["y"] = 4, ["param1"] = 142, ["z"] = 21, ["name"] = "stairs:slab_silver_sandstone"}, {["x"] = 5, ["y"] = 4, ["param1"] = 126, ["z"] = 22, ["name"] = "stairs:slab_silver_sandstone"}, {["x"] = 5, ["y"] = 4, ["param1"] = 110, ["z"] = 23, ["name"] = "stairs:slab_silver_sandstone"}, {["x"] = 5, ["y"] = 4, ["param1"] = 94, ["z"] = 24, ["name"] = "stairs:slab_silver_sandstone"}, {["x"] = 6, ["y"] = 0, ["param1"] = 15, ["z"] = 0, ["name"] = "default:desert_sandstone_block"}, {["x"] = 6, ["y"] = 0, ["param1"] = 15, ["z"] = 1, ["name"] = "default:silver_sandstone_block"}, {["x"] = 6, ["y"] = 0, ["param1"] = 15, ["z"] = 2, ["name"] = "default:silver_sandstone_block"}, {["x"] = 6, ["y"] = 0, ["param1"] = 15, ["z"] = 3, ["name"] = "default:silver_sandstone_block"}, {["x"] = 6, ["y"] = 0, ["param1"] = 15, ["z"] = 4, ["name"] = "default:silver_sandstone_block"}, {["x"] = 6, ["y"] = 0, ["param1"] = 15, ["z"] = 5, ["name"] = "default:silver_sandstone_block"}, {["x"] = 6, ["y"] = 0, ["param1"] = 15, ["z"] = 6, ["name"] = "default:silver_sandstone_block"}, {["x"] = 6, ["y"] = 0, ["param1"] = 15, ["z"] = 7, ["name"] = "default:silver_sandstone_block"}, {["x"] = 6, ["y"] = 0, ["param1"] = 15, ["z"] = 8, ["name"] = "default:silver_sandstone_block"}, {["x"] = 6, ["y"] = 0, ["param1"] = 15, ["z"] = 9, ["name"] = "default:silver_sandstone_block"}, {["x"] = 6, ["y"] = 0, ["param1"] = 15, ["z"] = 10, ["name"] = "default:silver_sandstone_block"}, {["x"] = 6, ["y"] = 0, ["param1"] = 15, ["z"] = 11, ["name"] = "default:silver_sandstone_block"}, {["x"] = 6, ["y"] = 0, ["param1"] = 15, ["z"] = 12, ["name"] = "default:silver_sandstone_block"}, {["x"] = 6, ["y"] = 0, ["param1"] = 15, ["z"] = 13, ["name"] = "default:silver_sandstone_block"}, {["x"] = 6, ["y"] = 0, ["param1"] = 15, ["z"] = 14, ["name"] = "default:silver_sandstone_block"}, {["x"] = 6, ["y"] = 0, ["param1"] = 15, ["z"] = 15, ["name"] = "default:silver_sandstone_block"}, {["x"] = 6, ["y"] = 0, ["param1"] = 15, ["z"] = 16, ["name"] = "default:silver_sandstone_block"}, {["x"] = 6, ["y"] = 0, ["param1"] = 15, ["z"] = 17, ["name"] = "default:silver_sandstone_block"}, {["x"] = 6, ["y"] = 0, ["param1"] = 15, ["z"] = 18, ["name"] = "default:silver_sandstone_block"}, {["x"] = 6, ["y"] = 0, ["param1"] = 15, ["z"] = 19, ["name"] = "default:silver_sandstone_block"}, {["x"] = 6, ["y"] = 0, ["param1"] = 15, ["z"] = 20, ["name"] = "default:silver_sandstone_block"}, {["x"] = 6, ["y"] = 0, ["param1"] = 15, ["z"] = 21, ["name"] = "default:silver_sandstone_block"}, {["x"] = 6, ["y"] = 0, ["param1"] = 15, ["z"] = 22, ["name"] = "default:silver_sandstone_block"}, {["x"] = 6, ["y"] = 0, ["param1"] = 15, ["z"] = 23, ["name"] = "default:silver_sandstone_block"}, {["x"] = 6, ["y"] = 0, ["param1"] = 15, ["z"] = 24, ["name"] = "default:silver_sandstone_block"}, {["x"] = 6, ["y"] = 0, ["param1"] = 15, ["z"] = 25, ["name"] = "default:silver_sandstone_block"}, {["x"] = 6, ["y"] = 0, ["param1"] = 15, ["z"] = 26, ["name"] = "default:silver_sandstone_block"}, {["x"] = 6, ["y"] = 0, ["param1"] = 15, ["z"] = 27, ["name"] = "default:desert_sandstone_block"}, {["x"] = 6, ["y"] = 1, ["param1"] = 16, ["z"] = 4, ["name"] = "default:silver_sandstone"}, {["x"] = 6, ["y"] = 1, ["param1"] = 11, ["z"] = 9, ["name"] = "mesecons_extrawires:vertical_bottom_off"}, {["x"] = 6, ["y"] = 1, ["param1"] = 16, ["z"] = 12, ["name"] = "default:silver_sandstone"}, {["x"] = 6, ["y"] = 1, ["param1"] = 16, ["z"] = 16, ["name"] = "default:silver_sandstone"}, {["x"] = 6, ["y"] = 1, ["param1"] = 16, ["z"] = 24, ["name"] = "default:silver_sandstone"}, {["x"] = 6, ["y"] = 2, ["param1"] = 16, ["z"] = 4, ["name"] = "default:silver_sandstone"}, {["x"] = 6, ["y"] = 2, ["param1"] = 16, ["z"] = 5, ["name"] = "default:silver_sandstone"}, {["x"] = 6, ["y"] = 2, ["param1"] = 16, ["z"] = 6, ["name"] = "default:silver_sandstone"}, {["x"] = 6, ["y"] = 2, ["param1"] = 16, ["z"] = 7, ["name"] = "default:silver_sandstone"}, {["x"] = 6, ["y"] = 2, ["param1"] = 16, ["z"] = 8, ["name"] = "default:silver_sandstone"}, {["x"] = 6, ["y"] = 2, ["param1"] = 12, ["z"] = 9, ["name"] = "mesecons_extrawires:vertical_off"}, {["x"] = 6, ["y"] = 2, ["param1"] = 16, ["z"] = 10, ["name"] = "default:silver_sandstone"}, {["x"] = 6, ["y"] = 2, ["param1"] = 16, ["z"] = 11, ["name"] = "default:silver_sandstone"}, {["x"] = 6, ["y"] = 2, ["param1"] = 16, ["z"] = 12, ["name"] = "default:silver_sandstone"}, {["x"] = 6, ["y"] = 2, ["param1"] = 16, ["z"] = 16, ["name"] = "default:silver_sandstone"}, {["x"] = 6, ["y"] = 2, ["param1"] = 16, ["z"] = 17, ["name"] = "default:silver_sandstone"}, {["x"] = 6, ["y"] = 2, ["param1"] = 16, ["z"] = 18, ["name"] = "default:silver_sandstone"}, {["x"] = 6, ["y"] = 2, ["param1"] = 16, ["z"] = 19, ["name"] = "default:silver_sandstone"}, {["x"] = 6, ["y"] = 2, ["param1"] = 16, ["z"] = 20, ["name"] = "default:silver_sandstone"}, {["x"] = 6, ["y"] = 2, ["param1"] = 16, ["z"] = 21, ["name"] = "default:silver_sandstone"}, {["x"] = 6, ["y"] = 2, ["param1"] = 16, ["z"] = 22, ["name"] = "default:silver_sandstone"}, {["x"] = 6, ["y"] = 2, ["param1"] = 16, ["z"] = 23, ["name"] = "default:silver_sandstone"}, {["x"] = 6, ["y"] = 2, ["param1"] = 16, ["z"] = 24, ["name"] = "default:silver_sandstone"}, {["x"] = 6, ["y"] = 3, ["param1"] = 16, ["z"] = 4, ["name"] = "default:silver_sandstone"}, {["x"] = 6, ["param2"] = 2, ["y"] = 3, ["param1"] = 13, ["z"] = 5, ["name"] = "mesecons_insulated:insulated_off"}, {["x"] = 6, ["param2"] = 1, ["y"] = 3, ["param1"] = 13, ["z"] = 7, ["name"] = "mesecons_extrawires:corner_off"}, {["x"] = 6, ["meta"] = {["fields"] = {["real_portstates"] = "1", ["code"] = "-- JK Flipflop (Master Slave)\13-- by So.Po.Coder for Minetest Mesecons Lua Controller\13-- A:output, B:enable in, C:toggle, D:input\13\13if (event.type == \"program\") then\13  mem.latch = false\13end\
\13if (event.type == \"on\" and event.pin.name == \"B\") then\
  port.a = pin.d\
end\
if (event.type == \"off\" and event.pin.name == \"B\") then\
  if (pin.c) then\
\
    if (pin.a) then\
      mem.latch = false\
    else\
      mem.latch = true\
    end\
\13  else\
\
    if (pin.a) then\
      mem.latch = true\
    else\
      mem.latch = false\
    end\
\
  end\13end\
\
if (event.type == \"on\" and event.pin.name == \"C\") then\
  if (not pin.b) then\
    mem.latch = not mem.latch\13  end\13end\13if (event.type == \"off\" and event.pin.name == \"C\") then\
  if (not pin.b) then\
    port.a = mem.latch\13  end\13end", ["formspec"] = "size[12,10]background[-0.2,-0.25;12.4,10.75;jeija_luac_background.png]label[0.1,8.3;]textarea[0.2,0.2;12.2,9.5;code;;-- JK Flipflop (Master Slave)\13-- by So.Po.Coder for Minetest Mesecons Lua Controller\13-- A:output\\, B:enable in\\, C:toggle\\, D:input\13\13if (event.type == \"program\") then\13  mem.latch = false\13end\
\13if (event.type == \"on\" and event.pin.name == \"B\") then\
  port.a = pin.d\
end\
if (event.type == \"off\" and event.pin.name == \"B\") then\
  if (pin.c) then\
\
    if (pin.a) then\
      mem.latch = false\
    else\
      mem.latch = true\
    end\
\13  else\
\
    if (pin.a) then\
      mem.latch = true\
    else\
      mem.latch = false\
    end\
\
  end\13end\
\
if (event.type == \"on\" and event.pin.name == \"C\") then\
  if (not pin.b) then\
    mem.latch = not mem.latch\13  end\13end\13if (event.type == \"off\" and event.pin.name == \"C\") then\
  if (not pin.b) then\
    port.a = mem.latch\13  end\13end]image_button[4.75,8.75;2.5,1;jeija_luac_runbutton.png;program;]image_button_exit[11.72,-0.25;0.425,0.4;jeija_close_window.png;exit;]", ["ignore_offevents"] = "return {}", ["lc_memory"] = "return {[\"and4\"] = false, [\"and2\"] = false, [\"and3\"] = false, [\"and1\"] = false, [\"c\"] = false, [\"sr2\"] = false, [\"b\"] = false, [\"and5\"] = false, [\"and6\"] = false, [\"d\"] = false, [\"sr1\"] = false, [\"a\"] = false, [\"latch\"] = false}", ["luac_id"] = "53458"}, ["inventory"] = {}}, ["y"] = 3, ["param1"] = 13, ["z"] = 8, ["name"] = "mesecons_luacontroller:luacontroller0000"}, {["x"] = 6, ["y"] = 3, ["param1"] = 13, ["z"] = 9, ["name"] = "mesecons_extrawires:vertical_top_off"}, {["x"] = 6, ["y"] = 3, ["param1"] = 13, ["z"] = 11, ["name"] = "mesecons_insulated:insulated_off"}, {["x"] = 6, ["y"] = 3, ["param1"] = 16, ["z"] = 12, ["name"] = "default:silver_sandstone"}, {["x"] = 6, ["y"] = 3, ["param1"] = 16, ["z"] = 16, ["name"] = "default:silver_sandstone"}, {["x"] = 6, ["param2"] = 2, ["y"] = 3, ["param1"] = 109, ["z"] = 17, ["name"] = "mesecons_extrawires:corner_off"}, {["x"] = 6, ["param2"] = 3, ["y"] = 3, ["param1"] = 125, ["z"] = 18, ["name"] = "mesecons_insulated:insulated_off"}, {["x"] = 6, ["param2"] = 3, ["y"] = 3, ["param1"] = 141, ["z"] = 19, ["name"] = "mesecons_insulated:insulated_off"}, {["x"] = 6, ["meta"] = {["fields"] = {["real_portstates"] = "5", ["code"] = "-- JK Flipflop (Master Slave)\13-- by So.Po.Coder for Minetest Mesecons Lua Controller\13-- A:output, C:toggle, D:reset\13\13if (event.type == \"program\") then\13  mem.latch = false\13end\
\13if (event.type == \"on\" and event.pin.name == \"D\") then\
  port.a = false\
end\
if (event.type == \"off\" and event.pin.name == \"D\") then\
  if (pin.c) then\
\
    if (pin.a) then\
      mem.latch = false\
    else\
      mem.latch = true\
    end\
\13  else\
\
    if (pin.a) then\
      mem.latch = true\
    else\
      mem.latch = false\
    end\
\
  end\13end\
\
if (event.type == \"on\" and event.pin.name == \"C\") then\
  if (not pin.d) then\
    mem.latch = not mem.latch\13  end\13end\13if (event.type == \"off\" and event.pin.name == \"C\") then\
  if (not pin.d) then\
    port.a = mem.latch\13  end\13end", ["formspec"] = "size[12,10]background[-0.2,-0.25;12.4,10.75;jeija_luac_background.png]label[0.1,8.3;]textarea[0.2,0.2;12.2,9.5;code;;-- JK Flipflop (Master Slave)\13-- by So.Po.Coder for Minetest Mesecons Lua Controller\13-- A:output\\, C:toggle\\, D:reset\13\13if (event.type == \"program\") then\13  mem.latch = false\13end\
\13if (event.type == \"on\" and event.pin.name == \"D\") then\
  port.a = false\
end\
if (event.type == \"off\" and event.pin.name == \"D\") then\
  if (pin.c) then\
\
    if (pin.a) then\
      mem.latch = false\
    else\
      mem.latch = true\
    end\
\13  else\
\
    if (pin.a) then\
      mem.latch = true\
    else\
      mem.latch = false\
    end\
\
  end\13end\
\
if (event.type == \"on\" and event.pin.name == \"C\") then\
  if (not pin.d) then\
    mem.latch = not mem.latch\13  end\13end\13if (event.type == \"off\" and event.pin.name == \"C\") then\
  if (not pin.d) then\
    port.a = mem.latch\13  end\13end]image_button[4.75,8.75;2.5,1;jeija_luac_runbutton.png;program;]image_button_exit[11.72,-0.25;0.425,0.4;jeija_close_window.png;exit;]", ["ignore_offevents"] = "return {[\"A\"] = true}", ["lc_memory"] = "return {[\"and4\"] = false, [\"and2\"] = false, [\"and3\"] = false, [\"and1\"] = false, [\"c\"] = false, [\"sr2\"] = false, [\"b\"] = false, [\"latch\"] = true, [\"and6\"] = false, [\"d\"] = false, [\"sr1\"] = false, [\"a\"] = false, [\"and5\"] = false}", ["luac_id"] = "3250"}, ["inventory"] = {}}, ["y"] = 3, ["param1"] = 157, ["z"] = 20, ["name"] = "mesecons_luacontroller:luacontroller0000"}, {["x"] = 6, ["y"] = 3, ["param1"] = 109, ["z"] = 23, ["name"] = "mesecons_insulated:insulated_on"}, {["x"] = 6, ["y"] = 3, ["param1"] = 16, ["z"] = 24, ["name"] = "default:silver_sandstone"}, {["x"] = 6, ["y"] = 4, ["param1"] = 14, ["z"] = 4, ["name"] = "stairs:slab_silver_sandstone"}, {["x"] = 6, ["y"] = 4, ["param1"] = 14, ["z"] = 5, ["name"] = "stairs:slab_silver_sandstone"}, {["x"] = 6, ["y"] = 4, ["param1"] = 14, ["z"] = 6, ["name"] = "stairs:slab_silver_sandstone"}, {["x"] = 6, ["y"] = 4, ["param1"] = 14, ["z"] = 7, ["name"] = "stairs:slab_silver_sandstone"}, {["x"] = 6, ["y"] = 4, ["param1"] = 14, ["z"] = 8, ["name"] = "stairs:slab_silver_sandstone"}, {["x"] = 6, ["y"] = 4, ["param1"] = 14, ["z"] = 9, ["name"] = "stairs:slab_silver_sandstone"}, {["x"] = 6, ["y"] = 4, ["param1"] = 14, ["z"] = 10, ["name"] = "stairs:slab_silver_sandstone"}, {["x"] = 6, ["y"] = 4, ["param1"] = 30, ["z"] = 11, ["name"] = "stairs:slab_silver_sandstone"}, {["x"] = 6, ["y"] = 4, ["param1"] = 46, ["z"] = 12, ["name"] = "stairs:slab_silver_sandstone"}, {["x"] = 6, ["y"] = 4, ["param1"] = 110, ["z"] = 16, ["name"] = "stairs:slab_silver_sandstone"}, {["x"] = 6, ["y"] = 4, ["param1"] = 126, ["z"] = 17, ["name"] = "stairs:slab_silver_sandstone"}, {["x"] = 6, ["y"] = 4, ["param1"] = 142, ["z"] = 18, ["name"] = "stairs:slab_silver_sandstone"}, {["x"] = 6, ["y"] = 4, ["param1"] = 158, ["z"] = 19, ["name"] = "stairs:slab_silver_sandstone"}, {["x"] = 6, ["y"] = 4, ["param1"] = 174, ["z"] = 20, ["name"] = "stairs:slab_silver_sandstone"}, {["x"] = 6, ["y"] = 4, ["param1"] = 158, ["z"] = 21, ["name"] = "stairs:slab_silver_sandstone"}, {["x"] = 6, ["y"] = 4, ["param1"] = 142, ["z"] = 22, ["name"] = "stairs:slab_silver_sandstone"}, {["x"] = 6, ["y"] = 4, ["param1"] = 126, ["z"] = 23, ["name"] = "stairs:slab_silver_sandstone"}, {["x"] = 6, ["y"] = 4, ["param1"] = 110, ["z"] = 24, ["name"] = "stairs:slab_silver_sandstone"}, {["x"] = 7, ["y"] = 0, ["param1"] = 15, ["z"] = 0, ["name"] = "default:desert_sandstone_block"}, {["x"] = 7, ["y"] = 0, ["param1"] = 15, ["z"] = 1, ["name"] = "default:silver_sandstone_block"}, {["x"] = 7, ["y"] = 0, ["param1"] = 15, ["z"] = 2, ["name"] = "default:silver_sandstone_block"}, {["x"] = 7, ["y"] = 0, ["param1"] = 15, ["z"] = 3, ["name"] = "default:silver_sandstone_block"}, {["x"] = 7, ["y"] = 0, ["param1"] = 15, ["z"] = 4, ["name"] = "default:silver_sandstone_block"}, {["x"] = 7, ["y"] = 0, ["param1"] = 15, ["z"] = 5, ["name"] = "default:silver_sandstone_block"}, {["x"] = 7, ["y"] = 0, ["param1"] = 15, ["z"] = 6, ["name"] = "default:silver_sandstone_block"}, {["x"] = 7, ["y"] = 0, ["param1"] = 15, ["z"] = 7, ["name"] = "default:silver_sandstone_block"}, {["x"] = 7, ["y"] = 0, ["param1"] = 15, ["z"] = 8, ["name"] = "default:silver_sandstone_block"}, {["x"] = 7, ["y"] = 0, ["param1"] = 15, ["z"] = 9, ["name"] = "default:silver_sandstone_block"}, {["x"] = 7, ["y"] = 0, ["param1"] = 15, ["z"] = 10, ["name"] = "default:silver_sandstone_block"}, {["x"] = 7, ["y"] = 0, ["param1"] = 15, ["z"] = 11, ["name"] = "default:silver_sandstone_block"}, {["x"] = 7, ["y"] = 0, ["param1"] = 15, ["z"] = 12, ["name"] = "default:silver_sandstone_block"}, {["x"] = 7, ["y"] = 0, ["param1"] = 15, ["z"] = 13, ["name"] = "default:silver_sandstone_block"}, {["x"] = 7, ["y"] = 0, ["param1"] = 15, ["z"] = 14, ["name"] = "default:silver_sandstone_block"}, {["x"] = 7, ["y"] = 0, ["param1"] = 15, ["z"] = 15, ["name"] = "default:silver_sandstone_block"}, {["x"] = 7, ["y"] = 0, ["param1"] = 15, ["z"] = 16, ["name"] = "default:silver_sandstone_block"}, {["x"] = 7, ["y"] = 0, ["param1"] = 15, ["z"] = 17, ["name"] = "default:silver_sandstone_block"}, {["x"] = 7, ["y"] = 0, ["param1"] = 15, ["z"] = 18, ["name"] = "default:silver_sandstone_block"}, {["x"] = 7, ["y"] = 0, ["param1"] = 15, ["z"] = 19, ["name"] = "default:silver_sandstone_block"}, {["x"] = 7, ["y"] = 0, ["param1"] = 15, ["z"] = 20, ["name"] = "default:silver_sandstone_block"}, {["x"] = 7, ["y"] = 0, ["param1"] = 15, ["z"] = 21, ["name"] = "default:silver_sandstone_block"}, {["x"] = 7, ["y"] = 0, ["param1"] = 15, ["z"] = 22, ["name"] = "default:silver_sandstone_block"}, {["x"] = 7, ["y"] = 0, ["param1"] = 15, ["z"] = 23, ["name"] = "default:silver_sandstone_block"}, {["x"] = 7, ["y"] = 0, ["param1"] = 15, ["z"] = 24, ["name"] = "default:silver_sandstone_block"}, {["x"] = 7, ["y"] = 0, ["param1"] = 15, ["z"] = 25, ["name"] = "default:silver_sandstone_block"}, {["x"] = 7, ["y"] = 0, ["param1"] = 15, ["z"] = 26, ["name"] = "default:silver_sandstone_block"}, {["x"] = 7, ["y"] = 0, ["param1"] = 15, ["z"] = 27, ["name"] = "default:desert_sandstone_block"}, {["x"] = 7, ["y"] = 1, ["param1"] = 16, ["z"] = 4, ["name"] = "default:silver_sandstone"}, {["x"] = 7, ["y"] = 1, ["param1"] = 10, ["z"] = 9, ["name"] = "mesecons_insulated:insulated_off"}, {["x"] = 7, ["y"] = 1, ["param1"] = 16, ["z"] = 12, ["name"] = "default:silver_sandstone"}, {["x"] = 7, ["y"] = 1, ["param1"] = 16, ["z"] = 16, ["name"] = "default:silver_sandstone"}, {["x"] = 7, ["y"] = 1, ["param1"] = 16, ["z"] = 24, ["name"] = "default:silver_sandstone"}, {["x"] = 7, ["y"] = 2, ["param1"] = 16, ["z"] = 4, ["name"] = "default:silver_sandstone"}, {["x"] = 7, ["y"] = 2, ["param1"] = 16, ["z"] = 5, ["name"] = "default:silver_sandstone"}, {["x"] = 7, ["y"] = 2, ["param1"] = 16, ["z"] = 6, ["name"] = "default:silver_sandstone"}, {["x"] = 7, ["y"] = 2, ["param1"] = 16, ["z"] = 7, ["name"] = "default:silver_sandstone"}, {["x"] = 7, ["y"] = 2, ["param1"] = 16, ["z"] = 8, ["name"] = "default:silver_sandstone"}, {["x"] = 7, ["y"] = 2, ["param1"] = 16, ["z"] = 9, ["name"] = "default:silver_sandstone"}, {["x"] = 7, ["y"] = 2, ["param1"] = 16, ["z"] = 10, ["name"] = "default:silver_sandstone"}, {["x"] = 7, ["y"] = 2, ["param1"] = 16, ["z"] = 11, ["name"] = "default:silver_sandstone"}, {["x"] = 7, ["param2"] = 3, ["y"] = 2, ["param1"] = 16, ["z"] = 12, ["name"] = "default:silver_sandstone"}, {["x"] = 7, ["y"] = 2, ["param1"] = 16, ["z"] = 16, ["name"] = "default:silver_sandstone"}, {["x"] = 7, ["y"] = 2, ["param1"] = 16, ["z"] = 17, ["name"] = "default:silver_sandstone"}, {["x"] = 7, ["y"] = 2, ["param1"] = 16, ["z"] = 18, ["name"] = "default:silver_sandstone"}, {["x"] = 7, ["y"] = 2, ["param1"] = 16, ["z"] = 19, ["name"] = "default:silver_sandstone"}, {["x"] = 7, ["y"] = 2, ["param1"] = 16, ["z"] = 20, ["name"] = "default:silver_sandstone"}, {["x"] = 7, ["y"] = 2, ["param1"] = 16, ["z"] = 21, ["name"] = "default:silver_sandstone"}, {["x"] = 7, ["y"] = 2, ["param1"] = 16, ["z"] = 22, ["name"] = "default:silver_sandstone"}, {["x"] = 7, ["y"] = 2, ["param1"] = 16, ["z"] = 23, ["name"] = "default:silver_sandstone"}, {["x"] = 7, ["param2"] = 3, ["y"] = 2, ["param1"] = 16, ["z"] = 24, ["name"] = "default:silver_sandstone"}, {["x"] = 7, ["y"] = 3, ["param1"] = 16, ["z"] = 4, ["name"] = "default:silver_sandstone"}, {["x"] = 7, ["param2"] = 2, ["y"] = 3, ["param1"] = 13, ["z"] = 5, ["name"] = "mesecons_extrawires:tjunction_off"}, {["x"] = 7, ["param2"] = 3, ["y"] = 3, ["param1"] = 13, ["z"] = 6, ["name"] = "mesecons_insulated:insulated_off"}, {["x"] = 7, ["param2"] = 3, ["y"] = 3, ["param1"] = 13, ["z"] = 7, ["name"] = "mesecons_extrawires:corner_off"}, {["x"] = 7, ["y"] = 3, ["param1"] = 13, ["z"] = 8, ["name"] = "mesecons_insulated:insulated_off"}, {["x"] = 7, ["param2"] = 2, ["y"] = 3, ["param1"] = 13, ["z"] = 9, ["name"] = "mesecons_extrawires:corner_off"}, {["x"] = 7, ["param2"] = 3, ["y"] = 3, ["param1"] = 13, ["z"] = 10, ["name"] = "mesecons_insulated:insulated_off"}, {["x"] = 7, ["y"] = 3, ["param1"] = 29, ["z"] = 11, ["name"] = "mesecons_extrawires:tjunction_off"}, {["x"] = 7, ["y"] = 3, ["param1"] = 16, ["z"] = 12, ["name"] = "default:silver_sandstone"}, {["x"] = 7, ["y"] = 3, ["param1"] = 16, ["z"] = 16, ["name"] = "default:silver_sandstone"}, {["x"] = 7, ["param2"] = 2, ["y"] = 3, ["param1"] = 125, ["z"] = 17, ["name"] = "mesecons_insulated:insulated_off"}, {["x"] = 7, ["y"] = 3, ["param1"] = 173, ["z"] = 20, ["name"] = "mesecons_insulated:insulated_on"}, {["x"] = 7, ["param2"] = 2, ["y"] = 3, ["param1"] = 157, ["z"] = 21, ["name"] = "mesecons_extrawires:corner_on"}, {["x"] = 7, ["param2"] = 3, ["y"] = 3, ["param1"] = 141, ["z"] = 22, ["name"] = "mesecons_insulated:insulated_on"}, {["x"] = 7, ["y"] = 3, ["param1"] = 125, ["z"] = 23, ["name"] = "mesecons_extrawires:tjunction_on"}, {["x"] = 7, ["y"] = 3, ["param1"] = 16, ["z"] = 24, ["name"] = "default:silver_sandstone"}, {["x"] = 7, ["y"] = 4, ["param1"] = 14, ["z"] = 4, ["name"] = "stairs:slab_silver_sandstone"}, {["x"] = 7, ["y"] = 4, ["param1"] = 14, ["z"] = 5, ["name"] = "stairs:slab_silver_sandstone"}, {["x"] = 7, ["y"] = 4, ["param1"] = 14, ["z"] = 6, ["name"] = "stairs:slab_silver_sandstone"}, {["x"] = 7, ["y"] = 4, ["param1"] = 14, ["z"] = 7, ["name"] = "stairs:slab_silver_sandstone"}, {["x"] = 7, ["y"] = 4, ["param1"] = 14, ["z"] = 8, ["name"] = "stairs:slab_silver_sandstone"}, {["x"] = 7, ["y"] = 4, ["param1"] = 14, ["z"] = 9, ["name"] = "stairs:slab_silver_sandstone"}, {["x"] = 7, ["y"] = 4, ["param1"] = 30, ["z"] = 10, ["name"] = "stairs:slab_silver_sandstone"}, {["x"] = 7, ["y"] = 4, ["param1"] = 46, ["z"] = 11, ["name"] = "stairs:slab_silver_sandstone"}, {["x"] = 7, ["y"] = 4, ["param1"] = 62, ["z"] = 12, ["name"] = "stairs:slab_silver_sandstone"}, {["x"] = 7, ["y"] = 4, ["param1"] = 126, ["z"] = 16, ["name"] = "stairs:slab_silver_sandstone"}, {["x"] = 7, ["y"] = 4, ["param1"] = 142, ["z"] = 17, ["name"] = "stairs:slab_silver_sandstone"}, {["x"] = 7, ["y"] = 4, ["param1"] = 158, ["z"] = 18, ["name"] = "stairs:slab_silver_sandstone"}, {["x"] = 7, ["y"] = 4, ["param1"] = 174, ["z"] = 19, ["name"] = "stairs:slab_silver_sandstone"}, {["x"] = 7, ["y"] = 4, ["param1"] = 190, ["z"] = 20, ["name"] = "stairs:slab_silver_sandstone"}, {["x"] = 7, ["y"] = 4, ["param1"] = 174, ["z"] = 21, ["name"] = "stairs:slab_silver_sandstone"}, {["x"] = 7, ["y"] = 4, ["param1"] = 158, ["z"] = 22, ["name"] = "stairs:slab_silver_sandstone"}, {["x"] = 7, ["y"] = 4, ["param1"] = 142, ["z"] = 23, ["name"] = "stairs:slab_silver_sandstone"}, {["x"] = 7, ["y"] = 4, ["param1"] = 126, ["z"] = 24, ["name"] = "stairs:slab_silver_sandstone"}, {["x"] = 8, ["y"] = 0, ["param1"] = 15, ["z"] = 0, ["name"] = "default:desert_sandstone_block"}, {["x"] = 8, ["y"] = 0, ["param1"] = 15, ["z"] = 1, ["name"] = "default:silver_sandstone_block"}, {["x"] = 8, ["y"] = 0, ["param1"] = 15, ["z"] = 2, ["name"] = "default:silver_sandstone_block"}, {["x"] = 8, ["y"] = 0, ["param1"] = 15, ["z"] = 3, ["name"] = "default:silver_sandstone_block"}, {["x"] = 8, ["y"] = 0, ["param1"] = 15, ["z"] = 4, ["name"] = "default:silver_sandstone_block"}, {["x"] = 8, ["y"] = 0, ["param1"] = 15, ["z"] = 5, ["name"] = "default:silver_sandstone_block"}, {["x"] = 8, ["y"] = 0, ["param1"] = 15, ["z"] = 6, ["name"] = "default:silver_sandstone_block"}, {["x"] = 8, ["y"] = 0, ["param1"] = 15, ["z"] = 7, ["name"] = "default:silver_sandstone_block"}, {["x"] = 8, ["y"] = 0, ["param1"] = 15, ["z"] = 8, ["name"] = "default:silver_sandstone_block"}, {["x"] = 8, ["y"] = 0, ["param1"] = 15, ["z"] = 9, ["name"] = "default:silver_sandstone_block"}, {["x"] = 8, ["y"] = 0, ["param1"] = 15, ["z"] = 10, ["name"] = "default:silver_sandstone_block"}, {["x"] = 8, ["y"] = 0, ["param1"] = 15, ["z"] = 11, ["name"] = "default:silver_sandstone_block"}, {["x"] = 8, ["y"] = 0, ["param1"] = 15, ["z"] = 12, ["name"] = "default:silver_sandstone_block"}, {["x"] = 8, ["y"] = 0, ["param1"] = 15, ["z"] = 13, ["name"] = "default:silver_sandstone_block"}, {["x"] = 8, ["y"] = 0, ["param1"] = 15, ["z"] = 14, ["name"] = "default:silver_sandstone_block"}, {["x"] = 8, ["y"] = 0, ["param1"] = 15, ["z"] = 15, ["name"] = "default:silver_sandstone_block"}, {["x"] = 8, ["y"] = 0, ["param1"] = 15, ["z"] = 16, ["name"] = "default:silver_sandstone_block"}, {["x"] = 8, ["y"] = 0, ["param1"] = 15, ["z"] = 17, ["name"] = "default:silver_sandstone_block"}, {["x"] = 8, ["y"] = 0, ["param1"] = 15, ["z"] = 18, ["name"] = "default:silver_sandstone_block"}, {["x"] = 8, ["y"] = 0, ["param1"] = 15, ["z"] = 19, ["name"] = "default:silver_sandstone_block"}, {["x"] = 8, ["y"] = 0, ["param1"] = 15, ["z"] = 20, ["name"] = "default:silver_sandstone_block"}, {["x"] = 8, ["y"] = 0, ["param1"] = 15, ["z"] = 21, ["name"] = "default:silver_sandstone_block"}, {["x"] = 8, ["y"] = 0, ["param1"] = 15, ["z"] = 22, ["name"] = "default:silver_sandstone_block"}, {["x"] = 8, ["y"] = 0, ["param1"] = 15, ["z"] = 23, ["name"] = "default:silver_sandstone_block"}, {["x"] = 8, ["y"] = 0, ["param1"] = 15, ["z"] = 24, ["name"] = "default:silver_sandstone_block"}, {["x"] = 8, ["y"] = 0, ["param1"] = 15, ["z"] = 25, ["name"] = "default:silver_sandstone_block"}, {["x"] = 8, ["y"] = 0, ["param1"] = 15, ["z"] = 26, ["name"] = "default:silver_sandstone_block"}, {["x"] = 8, ["y"] = 0, ["param1"] = 15, ["z"] = 27, ["name"] = "default:desert_sandstone_block"}, {["x"] = 8, ["y"] = 1, ["z"] = 2, ["name"] = "mesecons_switch:mesecon_switch_off"}, {["x"] = 8, ["param2"] = 3, ["y"] = 1, ["param1"] = 47, ["z"] = 3, ["name"] = "mesecons_insulated:insulated_off"}, {["x"] = 8, ["y"] = 1, ["param1"] = 62, ["z"] = 4, ["name"] = "default:mese"}, {["x"] = 8, ["param2"] = 3, ["y"] = 1, ["param1"] = 45, ["z"] = 5, ["name"] = "mesecons_insulated:insulated_off"}, {["x"] = 8, ["y"] = 1, ["param1"] = 28, ["z"] = 6, ["name"] = "mesecons_extrawires:vertical_bottom_off"}, {["x"] = 8, ["param2"] = 3, ["y"] = 1, ["param1"] = 11, ["z"] = 7, ["name"] = "mesecons_insulated:insulated_off"}, {["x"] = 8, ["param2"] = 3, ["y"] = 1, ["param1"] = 10, ["z"] = 8, ["name"] = "mesecons_insulated:insulated_off"}, {["x"] = 8, ["y"] = 1, ["param1"] = 11, ["z"] = 9, ["name"] = "mesecons_extrawires:crossover_off"}, {["x"] = 8, ["y"] = 1, ["param1"] = 28, ["z"] = 10, ["name"] = "mesecons_extrawires:vertical_bottom_off"}, {["x"] = 8, ["param2"] = 3, ["y"] = 1, ["param1"] = 45, ["z"] = 11, ["name"] = "mesecons_insulated:insulated_off"}, {["x"] = 8, ["y"] = 1, ["param1"] = 62, ["z"] = 12, ["name"] = "default:mese"}, {["x"] = 8, ["y"] = 1, ["param1"] = 94, ["z"] = 16, ["name"] = "mesecons_extrawires:mese_powered"}, {["x"] = 8, ["param2"] = 3, ["y"] = 1, ["param1"] = 77, ["z"] = 17, ["name"] = "mesecons_insulated:insulated_on"}, {["x"] = 8, ["param2"] = 3, ["y"] = 1, ["param1"] = 60, ["z"] = 18, ["name"] = "mesecons_insulated:insulated_on"}, {["x"] = 8, ["param2"] = 3, ["y"] = 1, ["param1"] = 75, ["z"] = 19, ["name"] = "mesecons_insulated:insulated_on"}, {["x"] = 8, ["param2"] = 3, ["y"] = 1, ["param1"] = 90, ["z"] = 20, ["name"] = "mesecons_insulated:insulated_on"}, {["x"] = 8, ["param2"] = 3, ["y"] = 1, ["param1"] = 107, ["z"] = 21, ["name"] = "mesecons_insulated:insulated_on"}, {["x"] = 8, ["y"] = 1, ["param1"] = 124, ["z"] = 22, ["name"] = "mesecons_extrawires:vertical_bottom_on"}, {["x"] = 8, ["param2"] = 3, ["y"] = 1, ["param1"] = 109, ["z"] = 23, ["name"] = "mesecons_insulated:insulated_on"}, {["x"] = 8, ["y"] = 1, ["param1"] = 94, ["z"] = 24, ["name"] = "mesecons_extrawires:mese_powered"}, {["x"] = 8, ["meta"] = {["fields"] = {["infotext"] = "\"Input / Output 3\"", ["text"] = "Input / Output 3", ["formspec"] = "field[text;;${text}]"}, ["inventory"] = {}}, ["param2"] = 4, ["y"] = 2, ["param1"] = 31, ["z"] = 3, ["name"] = "default:sign_wall_steel"}, {["x"] = 8, ["y"] = 2, ["param1"] = 16, ["z"] = 4, ["name"] = "default:silver_sandstone"}, {["x"] = 8, ["y"] = 2, ["param1"] = 16, ["z"] = 5, ["name"] = "default:silver_sandstone"}, {["x"] = 8, ["y"] = 2, ["param1"] = 12, ["z"] = 6, ["name"] = "mesecons_extrawires:vertical_off"}, {["x"] = 8, ["y"] = 2, ["param1"] = 16, ["z"] = 7, ["name"] = "default:silver_sandstone"}, {["x"] = 8, ["y"] = 2, ["param1"] = 16, ["z"] = 8, ["name"] = "default:silver_sandstone"}, {["x"] = 8, ["y"] = 2, ["param1"] = 16, ["z"] = 9, ["name"] = "default:silver_sandstone"}, {["x"] = 8, ["y"] = 2, ["param1"] = 12, ["z"] = 10, ["name"] = "mesecons_extrawires:vertical_off"}, {["x"] = 8, ["y"] = 2, ["param1"] = 16, ["z"] = 11, ["name"] = "default:silver_sandstone"}, {["x"] = 8, ["y"] = 2, ["param1"] = 16, ["z"] = 12, ["name"] = "default:silver_sandstone"}, {["x"] = 8, ["meta"] = {["fields"] = {["infotext"] = "\"Input / Output 3\"", ["text"] = "Input / Output 3", ["formspec"] = "field[text;;${text}]"}, ["inventory"] = {}}, ["param2"] = 5, ["y"] = 2, ["param1"] = 63, ["z"] = 13, ["name"] = "default:sign_wall_steel"}, {["x"] = 8, ["meta"] = {["fields"] = {["infotext"] = "\"Input / Output 3\"", ["text"] = "Input / Output 3", ["formspec"] = "field[text;;${text}]"}, ["inventory"] = {}}, ["param2"] = 4, ["y"] = 2, ["param1"] = 95, ["z"] = 15, ["name"] = "default:sign_wall_steel"}, {["x"] = 8, ["y"] = 2, ["param1"] = 16, ["z"] = 16, ["name"] = "default:silver_sandstone"}, {["x"] = 8, ["y"] = 2, ["param1"] = 16, ["z"] = 17, ["name"] = "default:silver_sandstone"}, {["x"] = 8, ["y"] = 2, ["param1"] = 16, ["z"] = 18, ["name"] = "default:silver_sandstone"}, {["x"] = 8, ["y"] = 2, ["param1"] = 16, ["z"] = 19, ["name"] = "default:silver_sandstone"}, {["x"] = 8, ["y"] = 2, ["param1"] = 16, ["z"] = 20, ["name"] = "default:silver_sandstone"}, {["x"] = 8, ["y"] = 2, ["param1"] = 16, ["z"] = 21, ["name"] = "default:silver_sandstone"}, {["x"] = 8, ["y"] = 2, ["param1"] = 140, ["z"] = 22, ["name"] = "mesecons_extrawires:vertical_on"}, {["x"] = 8, ["y"] = 2, ["param1"] = 16, ["z"] = 23, ["name"] = "default:silver_sandstone"}, {["x"] = 8, ["y"] = 2, ["param1"] = 16, ["z"] = 24, ["name"] = "default:silver_sandstone"}, {["x"] = 8, ["meta"] = {["fields"] = {["infotext"] = "\"Input / Output 3\"", ["formspec"] = "field[text;;${text}]", ["text"] = "Input / Output 3"}, ["inventory"] = {}}, ["param2"] = 5, ["y"] = 2, ["param1"] = 95, ["z"] = 25, ["name"] = "default:sign_wall_steel"}, {["x"] = 8, ["y"] = 3, ["param1"] = 16, ["z"] = 4, ["name"] = "default:silver_sandstone"}, {["x"] = 8, ["param2"] = 2, ["y"] = 3, ["param1"] = 13, ["z"] = 5, ["name"] = "mesecons_insulated:insulated_off"}, {["x"] = 8, ["y"] = 3, ["param1"] = 13, ["z"] = 6, ["name"] = "mesecons_extrawires:vertical_top_off"}, {["x"] = 8, ["meta"] = {["fields"] = {["infotext"] = "FPGA (functional)", ["portstates"] = "0000", ["valid"] = "1", ["instr"] = "A&DC//////////////"}, ["inventory"] = {}}, ["y"] = 3, ["param1"] = 13, ["z"] = 7, ["name"] = "mesecons_fpga:fpga0000"}, {["x"] = 8, ["y"] = 3, ["param1"] = 12, ["z"] = 8, ["name"] = "mesecons_extrawires:vertical_bottom_off"}, {["x"] = 8, ["meta"] = {["fields"] = {["infotext"] = "FPGA (functional)", ["portstates"] = "0000", ["valid"] = "1", ["instr"] = "A&DB//////////////"}, ["inventory"] = {}}, ["y"] = 3, ["param1"] = 13, ["z"] = 9, ["name"] = "mesecons_fpga:fpga0000"}, {["x"] = 8, ["y"] = 3, ["param1"] = 29, ["z"] = 10, ["name"] = "mesecons_extrawires:vertical_top_off"}, {["x"] = 8, ["y"] = 3, ["param1"] = 45, ["z"] = 11, ["name"] = "mesecons_insulated:insulated_off"}, {["x"] = 8, ["y"] = 3, ["param1"] = 16, ["z"] = 12, ["name"] = "default:silver_sandstone"}, {["x"] = 8, ["y"] = 3, ["param1"] = 16, ["z"] = 16, ["name"] = "default:silver_sandstone"}, {["x"] = 8, ["param2"] = 2, ["y"] = 3, ["param1"] = 141, ["z"] = 17, ["name"] = "mesecons_insulated:insulated_off"}, {["x"] = 8, ["y"] = 3, ["param1"] = 188, ["z"] = 20, ["name"] = "mesecons_extrawires:vertical_bottom_on"}, {["x"] = 8, ["meta"] = {["fields"] = {["infotext"] = "FPGA (functional)", ["portstates"] = "1001", ["valid"] = "1", ["instr"] = "A&DB//////////////"}, ["inventory"] = {}}, ["y"] = 3, ["param1"] = 173, ["z"] = 21, ["name"] = "mesecons_fpga:fpga0010"}, {["x"] = 8, ["y"] = 3, ["param1"] = 157, ["z"] = 22, ["name"] = "mesecons_extrawires:vertical_top_on"}, {["x"] = 8, ["y"] = 3, ["param1"] = 141, ["z"] = 23, ["name"] = "mesecons_insulated:insulated_on"}, {["x"] = 8, ["y"] = 3, ["param1"] = 16, ["z"] = 24, ["name"] = "default:silver_sandstone"}, {["x"] = 8, ["y"] = 4, ["param1"] = 14, ["z"] = 4, ["name"] = "stairs:slab_silver_sandstone"}, {["x"] = 8, ["y"] = 4, ["param1"] = 14, ["z"] = 5, ["name"] = "stairs:slab_silver_sandstone"}, {["x"] = 8, ["y"] = 4, ["param1"] = 14, ["z"] = 6, ["name"] = "stairs:slab_silver_sandstone"}, {["x"] = 8, ["y"] = 4, ["param1"] = 14, ["z"] = 7, ["name"] = "stairs:slab_silver_sandstone"}, {["x"] = 8, ["y"] = 4, ["z"] = 8, ["name"] = "mesecons_lightstone:lightstone_green_off"}, {["x"] = 8, ["y"] = 4, ["param1"] = 30, ["z"] = 9, ["name"] = "stairs:slab_silver_sandstone"}, {["x"] = 8, ["y"] = 4, ["param1"] = 46, ["z"] = 10, ["name"] = "stairs:slab_silver_sandstone"}, {["x"] = 8, ["y"] = 4, ["param1"] = 62, ["z"] = 11, ["name"] = "stairs:slab_silver_sandstone"}, {["x"] = 8, ["y"] = 4, ["param1"] = 78, ["z"] = 12, ["name"] = "stairs:slab_silver_sandstone"}, {["x"] = 8, ["y"] = 4, ["param1"] = 142, ["z"] = 16, ["name"] = "stairs:slab_silver_sandstone"}, {["x"] = 8, ["y"] = 4, ["param1"] = 158, ["z"] = 17, ["name"] = "stairs:slab_silver_sandstone"}, {["x"] = 8, ["y"] = 4, ["param1"] = 174, ["z"] = 18, ["name"] = "stairs:slab_silver_sandstone"}, {["x"] = 8, ["y"] = 4, ["param1"] = 190, ["z"] = 19, ["name"] = "stairs:slab_silver_sandstone"}, {["x"] = 8, ["y"] = 4, ["z"] = 20, ["name"] = "mesecons_lightstone:lightstone_green_on"}, {["x"] = 8, ["y"] = 4, ["param1"] = 190, ["z"] = 21, ["name"] = "stairs:slab_silver_sandstone"}, {["x"] = 8, ["y"] = 4, ["param1"] = 174, ["z"] = 22, ["name"] = "stairs:slab_silver_sandstone"}, {["x"] = 8, ["y"] = 4, ["param1"] = 158, ["z"] = 23, ["name"] = "stairs:slab_silver_sandstone"}, {["x"] = 8, ["y"] = 4, ["param1"] = 142, ["z"] = 24, ["name"] = "stairs:slab_silver_sandstone"}, {["x"] = 9, ["y"] = 0, ["param1"] = 15, ["z"] = 0, ["name"] = "default:desert_sandstone_block"}, {["x"] = 9, ["y"] = 0, ["param1"] = 15, ["z"] = 1, ["name"] = "default:silver_sandstone_block"}, {["x"] = 9, ["y"] = 0, ["param1"] = 15, ["z"] = 2, ["name"] = "default:silver_sandstone_block"}, {["x"] = 9, ["y"] = 0, ["param1"] = 15, ["z"] = 3, ["name"] = "default:silver_sandstone_block"}, {["x"] = 9, ["y"] = 0, ["param1"] = 15, ["z"] = 4, ["name"] = "default:silver_sandstone_block"}, {["x"] = 9, ["y"] = 0, ["param1"] = 15, ["z"] = 5, ["name"] = "default:silver_sandstone_block"}, {["x"] = 9, ["y"] = 0, ["param1"] = 15, ["z"] = 6, ["name"] = "default:silver_sandstone_block"}, {["x"] = 9, ["y"] = 0, ["param1"] = 15, ["z"] = 7, ["name"] = "default:silver_sandstone_block"}, {["x"] = 9, ["y"] = 0, ["param1"] = 15, ["z"] = 8, ["name"] = "default:silver_sandstone_block"}, {["x"] = 9, ["y"] = 0, ["param1"] = 15, ["z"] = 9, ["name"] = "default:silver_sandstone_block"}, {["x"] = 9, ["y"] = 0, ["param1"] = 15, ["z"] = 10, ["name"] = "default:silver_sandstone_block"}, {["x"] = 9, ["y"] = 0, ["param1"] = 15, ["z"] = 11, ["name"] = "default:silver_sandstone_block"}, {["x"] = 9, ["y"] = 0, ["param1"] = 15, ["z"] = 12, ["name"] = "default:silver_sandstone_block"}, {["x"] = 9, ["y"] = 0, ["param1"] = 15, ["z"] = 13, ["name"] = "default:silver_sandstone_block"}, {["x"] = 9, ["y"] = 0, ["param1"] = 15, ["z"] = 14, ["name"] = "default:silver_sandstone_block"}, {["x"] = 9, ["y"] = 0, ["param1"] = 15, ["z"] = 15, ["name"] = "default:silver_sandstone_block"}, {["x"] = 9, ["y"] = 0, ["param1"] = 15, ["z"] = 16, ["name"] = "default:silver_sandstone_block"}, {["x"] = 9, ["y"] = 0, ["param1"] = 15, ["z"] = 17, ["name"] = "default:silver_sandstone_block"}, {["x"] = 9, ["y"] = 0, ["param1"] = 15, ["z"] = 18, ["name"] = "default:silver_sandstone_block"}, {["x"] = 9, ["y"] = 0, ["param1"] = 15, ["z"] = 19, ["name"] = "default:silver_sandstone_block"}, {["x"] = 9, ["y"] = 0, ["param1"] = 15, ["z"] = 20, ["name"] = "default:silver_sandstone_block"}, {["x"] = 9, ["y"] = 0, ["param1"] = 15, ["z"] = 21, ["name"] = "default:silver_sandstone_block"}, {["x"] = 9, ["y"] = 0, ["param1"] = 15, ["z"] = 22, ["name"] = "default:silver_sandstone_block"}, {["x"] = 9, ["y"] = 0, ["param1"] = 15, ["z"] = 23, ["name"] = "default:silver_sandstone_block"}, {["x"] = 9, ["y"] = 0, ["param1"] = 15, ["z"] = 24, ["name"] = "default:silver_sandstone_block"}, {["x"] = 9, ["y"] = 0, ["param1"] = 15, ["z"] = 25, ["name"] = "default:silver_sandstone_block"}, {["x"] = 9, ["y"] = 0, ["param1"] = 15, ["z"] = 26, ["name"] = "default:silver_sandstone_block"}, {["x"] = 9, ["y"] = 0, ["param1"] = 15, ["z"] = 27, ["name"] = "default:desert_sandstone_block"}, {["x"] = 9, ["y"] = 1, ["param1"] = 16, ["z"] = 4, ["name"] = "default:silver_sandstone"}, {["x"] = 9, ["y"] = 1, ["param1"] = 11, ["z"] = 9, ["name"] = "mesecons_extrawires:vertical_bottom_off"}, {["x"] = 9, ["y"] = 1, ["param1"] = 16, ["z"] = 12, ["name"] = "default:silver_sandstone"}, {["x"] = 9, ["y"] = 1, ["param1"] = 16, ["z"] = 16, ["name"] = "default:silver_sandstone"}, {["x"] = 9, ["y"] = 1, ["param1"] = 16, ["z"] = 24, ["name"] = "default:silver_sandstone"}, {["x"] = 9, ["y"] = 2, ["param1"] = 16, ["z"] = 4, ["name"] = "default:silver_sandstone"}, {["x"] = 9, ["y"] = 2, ["param1"] = 16, ["z"] = 5, ["name"] = "default:silver_sandstone"}, {["x"] = 9, ["y"] = 2, ["param1"] = 16, ["z"] = 6, ["name"] = "default:silver_sandstone"}, {["x"] = 9, ["y"] = 2, ["param1"] = 16, ["z"] = 7, ["name"] = "default:silver_sandstone"}, {["x"] = 9, ["y"] = 2, ["param1"] = 16, ["z"] = 8, ["name"] = "default:silver_sandstone"}, {["x"] = 9, ["y"] = 2, ["param1"] = 12, ["z"] = 9, ["name"] = "mesecons_extrawires:vertical_off"}, {["x"] = 9, ["y"] = 2, ["param1"] = 16, ["z"] = 10, ["name"] = "default:silver_sandstone"}, {["x"] = 9, ["y"] = 2, ["param1"] = 16, ["z"] = 11, ["name"] = "default:silver_sandstone"}, {["x"] = 9, ["y"] = 2, ["param1"] = 16, ["z"] = 12, ["name"] = "default:silver_sandstone"}, {["x"] = 9, ["y"] = 2, ["param1"] = 16, ["z"] = 16, ["name"] = "default:silver_sandstone"}, {["x"] = 9, ["y"] = 2, ["param1"] = 16, ["z"] = 17, ["name"] = "default:silver_sandstone"}, {["x"] = 9, ["y"] = 2, ["param1"] = 16, ["z"] = 18, ["name"] = "default:silver_sandstone"}, {["x"] = 9, ["y"] = 2, ["param1"] = 16, ["z"] = 19, ["name"] = "default:silver_sandstone"}, {["x"] = 9, ["y"] = 2, ["param1"] = 16, ["z"] = 20, ["name"] = "default:silver_sandstone"}, {["x"] = 9, ["y"] = 2, ["param1"] = 16, ["z"] = 21, ["name"] = "default:silver_sandstone"}, {["x"] = 9, ["y"] = 2, ["param1"] = 16, ["z"] = 22, ["name"] = "default:silver_sandstone"}, {["x"] = 9, ["y"] = 2, ["param1"] = 16, ["z"] = 23, ["name"] = "default:silver_sandstone"}, {["x"] = 9, ["y"] = 2, ["param1"] = 16, ["z"] = 24, ["name"] = "default:silver_sandstone"}, {["x"] = 9, ["y"] = 3, ["param1"] = 16, ["z"] = 4, ["name"] = "default:silver_sandstone"}, {["x"] = 9, ["param2"] = 2, ["y"] = 3, ["param1"] = 13, ["z"] = 5, ["name"] = "mesecons_insulated:insulated_off"}, {["x"] = 9, ["param2"] = 1, ["y"] = 3, ["param1"] = 13, ["z"] = 7, ["name"] = "mesecons_extrawires:corner_off"}, {["x"] = 9, ["meta"] = {["fields"] = {["real_portstates"] = "1", ["code"] = "-- JK Flipflop (Master Slave)\13-- by So.Po.Coder for Minetest Mesecons Lua Controller\13-- A:output, B:enable in, C:toggle, D:input\13\13if (event.type == \"program\") then\13  mem.latch = false\13end\
\13if (event.type == \"on\" and event.pin.name == \"B\") then\
  port.a = pin.d\
end\
if (event.type == \"off\" and event.pin.name == \"B\") then\
  if (pin.c) then\
\
    if (pin.a) then\
      mem.latch = false\
    else\
      mem.latch = true\
    end\
\13  else\
\
    if (pin.a) then\
      mem.latch = true\
    else\
      mem.latch = false\
    end\
\
  end\13end\
\
if (event.type == \"on\" and event.pin.name == \"C\") then\
  if (not pin.b) then\
    mem.latch = not mem.latch\13  end\13end\13if (event.type == \"off\" and event.pin.name == \"C\") then\
  if (not pin.b) then\
    port.a = mem.latch\13  end\13end", ["formspec"] = "size[12,10]background[-0.2,-0.25;12.4,10.75;jeija_luac_background.png]label[0.1,8.3;]textarea[0.2,0.2;12.2,9.5;code;;-- JK Flipflop (Master Slave)\13-- by So.Po.Coder for Minetest Mesecons Lua Controller\13-- A:output\\, B:enable in\\, C:toggle\\, D:input\13\13if (event.type == \"program\") then\13  mem.latch = false\13end\
\13if (event.type == \"on\" and event.pin.name == \"B\") then\
  port.a = pin.d\
end\
if (event.type == \"off\" and event.pin.name == \"B\") then\
  if (pin.c) then\
\
    if (pin.a) then\
      mem.latch = false\
    else\
      mem.latch = true\
    end\
\13  else\
\
    if (pin.a) then\
      mem.latch = true\
    else\
      mem.latch = false\
    end\
\
  end\13end\
\
if (event.type == \"on\" and event.pin.name == \"C\") then\
  if (not pin.b) then\
    mem.latch = not mem.latch\13  end\13end\13if (event.type == \"off\" and event.pin.name == \"C\") then\
  if (not pin.b) then\
    port.a = mem.latch\13  end\13end]image_button[4.75,8.75;2.5,1;jeija_luac_runbutton.png;program;]image_button_exit[11.72,-0.25;0.425,0.4;jeija_close_window.png;exit;]", ["ignore_offevents"] = "return {}", ["lc_memory"] = "return {[\"and4\"] = false, [\"and2\"] = false, [\"and3\"] = false, [\"and1\"] = false, [\"c\"] = false, [\"sr2\"] = false, [\"b\"] = false, [\"and5\"] = false, [\"and6\"] = false, [\"d\"] = false, [\"sr1\"] = false, [\"a\"] = false, [\"latch\"] = false}", ["luac_id"] = "6412"}, ["inventory"] = {}}, ["y"] = 3, ["param1"] = 13, ["z"] = 8, ["name"] = "mesecons_luacontroller:luacontroller0000"}, {["x"] = 9, ["y"] = 3, ["param1"] = 13, ["z"] = 9, ["name"] = "mesecons_extrawires:vertical_top_off"}, {["x"] = 9, ["y"] = 3, ["param1"] = 29, ["z"] = 11, ["name"] = "mesecons_insulated:insulated_off"}, {["x"] = 9, ["y"] = 3, ["param1"] = 16, ["z"] = 12, ["name"] = "default:silver_sandstone"}, {["x"] = 9, ["y"] = 3, ["param1"] = 16, ["z"] = 16, ["name"] = "default:silver_sandstone"}, {["x"] = 9, ["param2"] = 2, ["y"] = 3, ["param1"] = 125, ["z"] = 17, ["name"] = "mesecons_extrawires:tjunction_off"}, {["x"] = 9, ["param2"] = 1, ["y"] = 3, ["param1"] = 141, ["z"] = 18, ["name"] = "mesecons_insulated:insulated_off"}, {["x"] = 9, ["param2"] = 3, ["y"] = 3, ["param1"] = 157, ["z"] = 19, ["name"] = "mesecons_insulated:insulated_off"}, {["x"] = 9, ["meta"] = {["fields"] = {["real_portstates"] = "1", ["code"] = "-- JK Flipflop (Master Slave)\13-- by So.Po.Coder for Minetest Mesecons Lua Controller\13-- A:output, C:toggle, D:reset\13\13if (event.type == \"program\") then\13  mem.latch = false\13end\
\13if (event.type == \"on\" and event.pin.name == \"D\") then\
  port.a = false\
end\
if (event.type == \"off\" and event.pin.name == \"D\") then\
  if (pin.c) then\
\
    if (pin.a) then\
      mem.latch = false\
    else\
      mem.latch = true\
    end\
\13  else\
\
    if (pin.a) then\
      mem.latch = true\
    else\
      mem.latch = false\
    end\
\
  end\13end\
\
if (event.type == \"on\" and event.pin.name == \"C\") then\
  if (not pin.d) then\
    mem.latch = not mem.latch\13  end\13end\13if (event.type == \"off\" and event.pin.name == \"C\") then\
  if (not pin.d) then\
    port.a = mem.latch\13  end\13end", ["formspec"] = "size[12,10]background[-0.2,-0.25;12.4,10.75;jeija_luac_background.png]label[0.1,8.3;]textarea[0.2,0.2;12.2,9.5;code;;-- JK Flipflop (Master Slave)\13-- by So.Po.Coder for Minetest Mesecons Lua Controller\13-- A:output\\, C:toggle\\, D:reset\13\13if (event.type == \"program\") then\13  mem.latch = false\13end\
\13if (event.type == \"on\" and event.pin.name == \"D\") then\
  port.a = false\
end\
if (event.type == \"off\" and event.pin.name == \"D\") then\
  if (pin.c) then\
\
    if (pin.a) then\
      mem.latch = false\
    else\
      mem.latch = true\
    end\
\13  else\
\
    if (pin.a) then\
      mem.latch = true\
    else\
      mem.latch = false\
    end\
\
  end\13end\
\
if (event.type == \"on\" and event.pin.name == \"C\") then\
  if (not pin.d) then\
    mem.latch = not mem.latch\13  end\13end\13if (event.type == \"off\" and event.pin.name == \"C\") then\
  if (not pin.d) then\
    port.a = mem.latch\13  end\13end]image_button[4.75,8.75;2.5,1;jeija_luac_runbutton.png;program;]image_button_exit[11.72,-0.25;0.425,0.4;jeija_close_window.png;exit;]", ["ignore_offevents"] = "return {[\"A\"] = true}", ["lc_memory"] = "return {[\"and4\"] = false, [\"and2\"] = false, [\"and3\"] = false, [\"and1\"] = false, [\"c\"] = false, [\"sr2\"] = false, [\"b\"] = false, [\"and5\"] = false, [\"and6\"] = false, [\"d\"] = false, [\"sr1\"] = false, [\"a\"] = false, [\"latch\"] = true}", ["luac_id"] = "312"}, ["inventory"] = {}}, ["y"] = 3, ["param1"] = 173, ["z"] = 20, ["name"] = "mesecons_luacontroller:luacontroller0001"}, {["x"] = 9, ["y"] = 3, ["param1"] = 125, ["z"] = 23, ["name"] = "mesecons_insulated:insulated_on"}, {["x"] = 9, ["y"] = 3, ["param1"] = 16, ["z"] = 24, ["name"] = "default:silver_sandstone"}, {["x"] = 9, ["y"] = 4, ["param1"] = 14, ["z"] = 4, ["name"] = "stairs:slab_silver_sandstone"}, {["x"] = 9, ["y"] = 4, ["param1"] = 14, ["z"] = 5, ["name"] = "stairs:slab_silver_sandstone"}, {["x"] = 9, ["y"] = 4, ["param1"] = 14, ["z"] = 6, ["name"] = "stairs:slab_silver_sandstone"}, {["x"] = 9, ["y"] = 4, ["param1"] = 14, ["z"] = 7, ["name"] = "stairs:slab_silver_sandstone"}, {["x"] = 9, ["y"] = 4, ["param1"] = 14, ["z"] = 8, ["name"] = "stairs:slab_silver_sandstone"}, {["x"] = 9, ["y"] = 4, ["param1"] = 14, ["z"] = 9, ["name"] = "stairs:slab_silver_sandstone"}, {["x"] = 9, ["y"] = 4, ["param1"] = 30, ["z"] = 10, ["name"] = "stairs:slab_silver_sandstone"}, {["x"] = 9, ["y"] = 4, ["param1"] = 46, ["z"] = 11, ["name"] = "stairs:slab_silver_sandstone"}, {["x"] = 9, ["y"] = 4, ["param1"] = 62, ["z"] = 12, ["name"] = "stairs:slab_silver_sandstone"}, {["x"] = 9, ["y"] = 4, ["param1"] = 126, ["z"] = 16, ["name"] = "stairs:slab_silver_sandstone"}, {["x"] = 9, ["y"] = 4, ["param1"] = 142, ["z"] = 17, ["name"] = "stairs:slab_silver_sandstone"}, {["x"] = 9, ["y"] = 4, ["param1"] = 158, ["z"] = 18, ["name"] = "stairs:slab_silver_sandstone"}, {["x"] = 9, ["y"] = 4, ["param1"] = 174, ["z"] = 19, ["name"] = "stairs:slab_silver_sandstone"}, {["x"] = 9, ["y"] = 4, ["param1"] = 190, ["z"] = 20, ["name"] = "stairs:slab_silver_sandstone"}, {["x"] = 9, ["y"] = 4, ["param1"] = 174, ["z"] = 21, ["name"] = "stairs:slab_silver_sandstone"}, {["x"] = 9, ["y"] = 4, ["param1"] = 158, ["z"] = 22, ["name"] = "stairs:slab_silver_sandstone"}, {["x"] = 9, ["y"] = 4, ["param1"] = 142, ["z"] = 23, ["name"] = "stairs:slab_silver_sandstone"}, {["x"] = 9, ["y"] = 4, ["param1"] = 126, ["z"] = 24, ["name"] = "stairs:slab_silver_sandstone"}, {["x"] = 10, ["y"] = 0, ["param1"] = 15, ["z"] = 0, ["name"] = "default:desert_sandstone_block"}, {["x"] = 10, ["y"] = 0, ["param1"] = 15, ["z"] = 1, ["name"] = "default:silver_sandstone_block"}, {["x"] = 10, ["y"] = 0, ["param1"] = 15, ["z"] = 2, ["name"] = "default:silver_sandstone_block"}, {["x"] = 10, ["y"] = 0, ["param1"] = 15, ["z"] = 3, ["name"] = "default:silver_sandstone_block"}, {["x"] = 10, ["y"] = 0, ["param1"] = 15, ["z"] = 4, ["name"] = "default:silver_sandstone_block"}, {["x"] = 10, ["y"] = 0, ["param1"] = 15, ["z"] = 5, ["name"] = "default:silver_sandstone_block"}, {["x"] = 10, ["y"] = 0, ["param1"] = 15, ["z"] = 6, ["name"] = "default:silver_sandstone_block"}, {["x"] = 10, ["y"] = 0, ["param1"] = 15, ["z"] = 7, ["name"] = "default:silver_sandstone_block"}, {["x"] = 10, ["y"] = 0, ["param1"] = 15, ["z"] = 8, ["name"] = "default:silver_sandstone_block"}, {["x"] = 10, ["y"] = 0, ["param1"] = 15, ["z"] = 9, ["name"] = "default:silver_sandstone_block"}, {["x"] = 10, ["y"] = 0, ["param1"] = 15, ["z"] = 10, ["name"] = "default:silver_sandstone_block"}, {["x"] = 10, ["y"] = 0, ["param1"] = 15, ["z"] = 11, ["name"] = "default:silver_sandstone_block"}, {["x"] = 10, ["y"] = 0, ["param1"] = 15, ["z"] = 12, ["name"] = "default:silver_sandstone_block"}, {["x"] = 10, ["y"] = 0, ["param1"] = 15, ["z"] = 13, ["name"] = "default:silver_sandstone_block"}, {["x"] = 10, ["y"] = 0, ["param1"] = 15, ["z"] = 14, ["name"] = "default:silver_sandstone_block"}, {["x"] = 10, ["y"] = 0, ["param1"] = 15, ["z"] = 15, ["name"] = "default:silver_sandstone_block"}, {["x"] = 10, ["y"] = 0, ["param1"] = 15, ["z"] = 16, ["name"] = "default:silver_sandstone_block"}, {["x"] = 10, ["y"] = 0, ["param1"] = 15, ["z"] = 17, ["name"] = "default:silver_sandstone_block"}, {["x"] = 10, ["y"] = 0, ["param1"] = 15, ["z"] = 18, ["name"] = "default:silver_sandstone_block"}, {["x"] = 10, ["y"] = 0, ["param1"] = 15, ["z"] = 19, ["name"] = "default:silver_sandstone_block"}, {["x"] = 10, ["y"] = 0, ["param1"] = 15, ["z"] = 20, ["name"] = "default:silver_sandstone_block"}, {["x"] = 10, ["y"] = 0, ["param1"] = 15, ["z"] = 21, ["name"] = "default:silver_sandstone_block"}, {["x"] = 10, ["y"] = 0, ["param1"] = 15, ["z"] = 22, ["name"] = "default:silver_sandstone_block"}, {["x"] = 10, ["y"] = 0, ["param1"] = 15, ["z"] = 23, ["name"] = "default:silver_sandstone_block"}, {["x"] = 10, ["y"] = 0, ["param1"] = 15, ["z"] = 24, ["name"] = "default:silver_sandstone_block"}, {["x"] = 10, ["y"] = 0, ["param1"] = 15, ["z"] = 25, ["name"] = "default:silver_sandstone_block"}, {["x"] = 10, ["y"] = 0, ["param1"] = 15, ["z"] = 26, ["name"] = "default:silver_sandstone_block"}, {["x"] = 10, ["y"] = 0, ["param1"] = 15, ["z"] = 27, ["name"] = "default:desert_sandstone_block"}, {["x"] = 10, ["y"] = 1, ["param1"] = 16, ["z"] = 4, ["name"] = "default:silver_sandstone"}, {["x"] = 10, ["y"] = 1, ["param1"] = 10, ["z"] = 9, ["name"] = "mesecons_insulated:insulated_off"}, {["x"] = 10, ["y"] = 1, ["param1"] = 16, ["z"] = 12, ["name"] = "default:silver_sandstone"}, {["x"] = 10, ["y"] = 1, ["param1"] = 16, ["z"] = 16, ["name"] = "default:silver_sandstone"}, {["x"] = 10, ["y"] = 1, ["param1"] = 16, ["z"] = 24, ["name"] = "default:silver_sandstone"}, {["x"] = 10, ["y"] = 2, ["param1"] = 16, ["z"] = 4, ["name"] = "default:silver_sandstone"}, {["x"] = 10, ["y"] = 2, ["param1"] = 16, ["z"] = 5, ["name"] = "default:silver_sandstone"}, {["x"] = 10, ["y"] = 2, ["param1"] = 16, ["z"] = 6, ["name"] = "default:silver_sandstone"}, {["x"] = 10, ["y"] = 2, ["param1"] = 16, ["z"] = 7, ["name"] = "default:silver_sandstone"}, {["x"] = 10, ["y"] = 2, ["param1"] = 16, ["z"] = 8, ["name"] = "default:silver_sandstone"}, {["x"] = 10, ["y"] = 2, ["param1"] = 16, ["z"] = 9, ["name"] = "default:silver_sandstone"}, {["x"] = 10, ["y"] = 2, ["param1"] = 16, ["z"] = 10, ["name"] = "default:silver_sandstone"}, {["x"] = 10, ["y"] = 2, ["param1"] = 16, ["z"] = 11, ["name"] = "default:silver_sandstone"}, {["x"] = 10, ["y"] = 2, ["param1"] = 16, ["z"] = 12, ["name"] = "default:silver_sandstone"}, {["x"] = 10, ["y"] = 2, ["param1"] = 16, ["z"] = 16, ["name"] = "default:silver_sandstone"}, {["x"] = 10, ["y"] = 2, ["param1"] = 16, ["z"] = 17, ["name"] = "default:silver_sandstone"}, {["x"] = 10, ["y"] = 2, ["param1"] = 16, ["z"] = 18, ["name"] = "default:silver_sandstone"}, {["x"] = 10, ["y"] = 2, ["param1"] = 16, ["z"] = 19, ["name"] = "default:silver_sandstone"}, {["x"] = 10, ["y"] = 2, ["param1"] = 16, ["z"] = 20, ["name"] = "default:silver_sandstone"}, {["x"] = 10, ["y"] = 2, ["param1"] = 16, ["z"] = 21, ["name"] = "default:silver_sandstone"}, {["x"] = 10, ["y"] = 2, ["param1"] = 16, ["z"] = 22, ["name"] = "default:silver_sandstone"}, {["x"] = 10, ["y"] = 2, ["param1"] = 16, ["z"] = 23, ["name"] = "default:silver_sandstone"}, {["x"] = 10, ["y"] = 2, ["param1"] = 16, ["z"] = 24, ["name"] = "default:silver_sandstone"}, {["x"] = 10, ["y"] = 3, ["param1"] = 16, ["z"] = 4, ["name"] = "default:silver_sandstone"}, {["x"] = 10, ["param2"] = 2, ["y"] = 3, ["param1"] = 13, ["z"] = 5, ["name"] = "mesecons_extrawires:tjunction_off"}, {["x"] = 10, ["param2"] = 3, ["y"] = 3, ["param1"] = 13, ["z"] = 6, ["name"] = "mesecons_insulated:insulated_off"}, {["x"] = 10, ["param2"] = 3, ["y"] = 3, ["param1"] = 13, ["z"] = 7, ["name"] = "mesecons_extrawires:corner_off"}, {["x"] = 10, ["y"] = 3, ["param1"] = 13, ["z"] = 8, ["name"] = "mesecons_insulated:insulated_off"}, {["x"] = 10, ["param2"] = 2, ["y"] = 3, ["param1"] = 13, ["z"] = 9, ["name"] = "mesecons_extrawires:corner_off"}, {["x"] = 10, ["param2"] = 3, ["y"] = 3, ["param1"] = 13, ["z"] = 10, ["name"] = "mesecons_insulated:insulated_off"}, {["x"] = 10, ["y"] = 3, ["param1"] = 13, ["z"] = 11, ["name"] = "mesecons_extrawires:tjunction_off"}, {["x"] = 10, ["y"] = 3, ["param1"] = 16, ["z"] = 12, ["name"] = "default:silver_sandstone"}, {["x"] = 10, ["y"] = 3, ["param1"] = 16, ["z"] = 16, ["name"] = "default:silver_sandstone"}, {["x"] = 10, ["param2"] = 2, ["y"] = 3, ["param1"] = 109, ["z"] = 17, ["name"] = "mesecons_insulated:insulated_off"}, {["x"] = 10, ["y"] = 3, ["param1"] = 157, ["z"] = 20, ["name"] = "mesecons_insulated:insulated_off"}, {["x"] = 10, ["param2"] = 2, ["y"] = 3, ["param1"] = 141, ["z"] = 21, ["name"] = "mesecons_extrawires:corner_on"}, {["x"] = 10, ["param2"] = 3, ["y"] = 3, ["param1"] = 125, ["z"] = 22, ["name"] = "mesecons_insulated:insulated_on"}, {["x"] = 10, ["y"] = 3, ["param1"] = 109, ["z"] = 23, ["name"] = "mesecons_extrawires:tjunction_on"}, {["x"] = 10, ["y"] = 3, ["param1"] = 16, ["z"] = 24, ["name"] = "default:silver_sandstone"}, {["x"] = 10, ["y"] = 4, ["param1"] = 14, ["z"] = 4, ["name"] = "stairs:slab_silver_sandstone"}, {["x"] = 10, ["y"] = 4, ["param1"] = 14, ["z"] = 5, ["name"] = "stairs:slab_silver_sandstone"}, {["x"] = 10, ["y"] = 4, ["param1"] = 14, ["z"] = 6, ["name"] = "stairs:slab_silver_sandstone"}, {["x"] = 10, ["y"] = 4, ["param1"] = 14, ["z"] = 7, ["name"] = "stairs:slab_silver_sandstone"}, {["x"] = 10, ["y"] = 4, ["param1"] = 14, ["z"] = 8, ["name"] = "stairs:slab_silver_sandstone"}, {["x"] = 10, ["y"] = 4, ["param1"] = 14, ["z"] = 9, ["name"] = "stairs:slab_silver_sandstone"}, {["x"] = 10, ["y"] = 4, ["param1"] = 14, ["z"] = 10, ["name"] = "stairs:slab_silver_sandstone"}, {["x"] = 10, ["y"] = 4, ["param1"] = 30, ["z"] = 11, ["name"] = "stairs:slab_silver_sandstone"}, {["x"] = 10, ["y"] = 4, ["param1"] = 46, ["z"] = 12, ["name"] = "stairs:slab_silver_sandstone"}, {["x"] = 10, ["y"] = 4, ["param1"] = 110, ["z"] = 16, ["name"] = "stairs:slab_silver_sandstone"}, {["x"] = 10, ["y"] = 4, ["param1"] = 126, ["z"] = 17, ["name"] = "stairs:slab_silver_sandstone"}, {["x"] = 10, ["y"] = 4, ["param1"] = 142, ["z"] = 18, ["name"] = "stairs:slab_silver_sandstone"}, {["x"] = 10, ["y"] = 4, ["param1"] = 158, ["z"] = 19, ["name"] = "stairs:slab_silver_sandstone"}, {["x"] = 10, ["y"] = 4, ["param1"] = 174, ["z"] = 20, ["name"] = "stairs:slab_silver_sandstone"}, {["x"] = 10, ["y"] = 4, ["param1"] = 158, ["z"] = 21, ["name"] = "stairs:slab_silver_sandstone"}, {["x"] = 10, ["y"] = 4, ["param1"] = 142, ["z"] = 22, ["name"] = "stairs:slab_silver_sandstone"}, {["x"] = 10, ["y"] = 4, ["param1"] = 126, ["z"] = 23, ["name"] = "stairs:slab_silver_sandstone"}, {["x"] = 10, ["y"] = 4, ["param1"] = 110, ["z"] = 24, ["name"] = "stairs:slab_silver_sandstone"}, {["x"] = 11, ["y"] = 0, ["param1"] = 15, ["z"] = 0, ["name"] = "default:desert_sandstone_block"}, {["x"] = 11, ["y"] = 0, ["param1"] = 15, ["z"] = 1, ["name"] = "default:silver_sandstone_block"}, {["x"] = 11, ["y"] = 0, ["param1"] = 15, ["z"] = 2, ["name"] = "default:silver_sandstone_block"}, {["x"] = 11, ["y"] = 0, ["param1"] = 15, ["z"] = 3, ["name"] = "default:silver_sandstone_block"}, {["x"] = 11, ["y"] = 0, ["param1"] = 15, ["z"] = 4, ["name"] = "default:silver_sandstone_block"}, {["x"] = 11, ["y"] = 0, ["param1"] = 15, ["z"] = 5, ["name"] = "default:silver_sandstone_block"}, {["x"] = 11, ["y"] = 0, ["param1"] = 15, ["z"] = 6, ["name"] = "default:silver_sandstone_block"}, {["x"] = 11, ["y"] = 0, ["param1"] = 15, ["z"] = 7, ["name"] = "default:silver_sandstone_block"}, {["x"] = 11, ["y"] = 0, ["param1"] = 15, ["z"] = 8, ["name"] = "default:silver_sandstone_block"}, {["x"] = 11, ["y"] = 0, ["param1"] = 15, ["z"] = 9, ["name"] = "default:silver_sandstone_block"}, {["x"] = 11, ["y"] = 0, ["param1"] = 15, ["z"] = 10, ["name"] = "default:silver_sandstone_block"}, {["x"] = 11, ["y"] = 0, ["param1"] = 15, ["z"] = 11, ["name"] = "default:silver_sandstone_block"}, {["x"] = 11, ["y"] = 0, ["param1"] = 15, ["z"] = 12, ["name"] = "default:silver_sandstone_block"}, {["x"] = 11, ["y"] = 0, ["param1"] = 15, ["z"] = 13, ["name"] = "default:silver_sandstone_block"}, {["x"] = 11, ["y"] = 0, ["param1"] = 15, ["z"] = 14, ["name"] = "default:silver_sandstone_block"}, {["x"] = 11, ["y"] = 0, ["param1"] = 15, ["z"] = 15, ["name"] = "default:silver_sandstone_block"}, {["x"] = 11, ["y"] = 0, ["param1"] = 15, ["z"] = 16, ["name"] = "default:silver_sandstone_block"}, {["x"] = 11, ["y"] = 0, ["param1"] = 15, ["z"] = 17, ["name"] = "default:silver_sandstone_block"}, {["x"] = 11, ["y"] = 0, ["param1"] = 15, ["z"] = 18, ["name"] = "default:silver_sandstone_block"}, {["x"] = 11, ["y"] = 0, ["param1"] = 15, ["z"] = 19, ["name"] = "default:silver_sandstone_block"}, {["x"] = 11, ["y"] = 0, ["param1"] = 15, ["z"] = 20, ["name"] = "default:silver_sandstone_block"}, {["x"] = 11, ["y"] = 0, ["param1"] = 15, ["z"] = 21, ["name"] = "default:silver_sandstone_block"}, {["x"] = 11, ["y"] = 0, ["param1"] = 15, ["z"] = 22, ["name"] = "default:silver_sandstone_block"}, {["x"] = 11, ["y"] = 0, ["param1"] = 15, ["z"] = 23, ["name"] = "default:silver_sandstone_block"}, {["x"] = 11, ["y"] = 0, ["param1"] = 15, ["z"] = 24, ["name"] = "default:silver_sandstone_block"}, {["x"] = 11, ["y"] = 0, ["param1"] = 15, ["z"] = 25, ["name"] = "default:silver_sandstone_block"}, {["x"] = 11, ["y"] = 0, ["param1"] = 15, ["z"] = 26, ["name"] = "default:silver_sandstone_block"}, {["x"] = 11, ["y"] = 0, ["param1"] = 15, ["z"] = 27, ["name"] = "default:desert_sandstone_block"}, {["x"] = 11, ["y"] = 1, ["z"] = 2, ["name"] = "mesecons_switch:mesecon_switch_off"}, {["x"] = 11, ["param2"] = 3, ["y"] = 1, ["param1"] = 47, ["z"] = 3, ["name"] = "mesecons_insulated:insulated_off"}, {["x"] = 11, ["y"] = 1, ["param1"] = 62, ["z"] = 4, ["name"] = "default:mese"}, {["x"] = 11, ["param2"] = 3, ["y"] = 1, ["param1"] = 45, ["z"] = 5, ["name"] = "mesecons_insulated:insulated_off"}, {["x"] = 11, ["y"] = 1, ["param1"] = 28, ["z"] = 6, ["name"] = "mesecons_extrawires:vertical_bottom_off"}, {["x"] = 11, ["param2"] = 3, ["y"] = 1, ["param1"] = 11, ["z"] = 7, ["name"] = "mesecons_insulated:insulated_off"}, {["x"] = 11, ["param2"] = 3, ["y"] = 1, ["param1"] = 10, ["z"] = 8, ["name"] = "mesecons_insulated:insulated_off"}, {["x"] = 11, ["y"] = 1, ["param1"] = 11, ["z"] = 9, ["name"] = "mesecons_extrawires:crossover_off"}, {["x"] = 11, ["y"] = 1, ["param1"] = 28, ["z"] = 10, ["name"] = "mesecons_extrawires:vertical_bottom_off"}, {["x"] = 11, ["param2"] = 3, ["y"] = 1, ["param1"] = 45, ["z"] = 11, ["name"] = "mesecons_insulated:insulated_off"}, {["x"] = 11, ["y"] = 1, ["param1"] = 62, ["z"] = 12, ["name"] = "default:mese"}, {["x"] = 11, ["y"] = 1, ["param1"] = 62, ["z"] = 16, ["name"] = "default:mese"}, {["x"] = 11, ["param2"] = 3, ["y"] = 1, ["param1"] = 45, ["z"] = 17, ["name"] = "mesecons_insulated:insulated_off"}, {["x"] = 11, ["param2"] = 3, ["y"] = 1, ["param1"] = 28, ["z"] = 18, ["name"] = "mesecons_insulated:insulated_off"}, {["x"] = 11, ["param2"] = 3, ["y"] = 1, ["param1"] = 27, ["z"] = 19, ["name"] = "mesecons_insulated:insulated_off"}, {["x"] = 11, ["param2"] = 3, ["y"] = 1, ["param1"] = 42, ["z"] = 20, ["name"] = "mesecons_insulated:insulated_off"}, {["x"] = 11, ["param2"] = 3, ["y"] = 1, ["param1"] = 59, ["z"] = 21, ["name"] = "mesecons_insulated:insulated_off"}, {["x"] = 11, ["y"] = 1, ["param1"] = 76, ["z"] = 22, ["name"] = "mesecons_extrawires:vertical_bottom_off"}, {["x"] = 11, ["param2"] = 3, ["y"] = 1, ["param1"] = 61, ["z"] = 23, ["name"] = "mesecons_insulated:insulated_off"}, {["x"] = 11, ["y"] = 1, ["param1"] = 62, ["z"] = 24, ["name"] = "default:mese"}, {["x"] = 11, ["meta"] = {["fields"] = {["infotext"] = "\"Input / Output 2\"", ["formspec"] = "field[text;;${text}]", ["text"] = "Input / Output 2"}, ["inventory"] = {}}, ["param2"] = 4, ["y"] = 2, ["param1"] = 31, ["z"] = 3, ["name"] = "default:sign_wall_steel"}, {["x"] = 11, ["y"] = 2, ["param1"] = 16, ["z"] = 4, ["name"] = "default:silver_sandstone"}, {["x"] = 11, ["y"] = 2, ["param1"] = 16, ["z"] = 5, ["name"] = "default:silver_sandstone"}, {["x"] = 11, ["y"] = 2, ["param1"] = 12, ["z"] = 6, ["name"] = "mesecons_extrawires:vertical_off"}, {["x"] = 11, ["y"] = 2, ["param1"] = 16, ["z"] = 7, ["name"] = "default:silver_sandstone"}, {["x"] = 11, ["y"] = 2, ["param1"] = 16, ["z"] = 8, ["name"] = "default:silver_sandstone"}, {["x"] = 11, ["y"] = 2, ["param1"] = 16, ["z"] = 9, ["name"] = "default:silver_sandstone"}, {["x"] = 11, ["y"] = 2, ["param1"] = 12, ["z"] = 10, ["name"] = "mesecons_extrawires:vertical_off"}, {["x"] = 11, ["y"] = 2, ["param1"] = 16, ["z"] = 11, ["name"] = "default:silver_sandstone"}, {["x"] = 11, ["y"] = 2, ["param1"] = 16, ["z"] = 12, ["name"] = "default:silver_sandstone"}, {["x"] = 11, ["meta"] = {["fields"] = {["infotext"] = "\"Input / Output 2\"", ["text"] = "Input / Output 2", ["formspec"] = "field[text;;${text}]"}, ["inventory"] = {}}, ["param2"] = 5, ["y"] = 2, ["param1"] = 31, ["z"] = 13, ["name"] = "default:sign_wall_steel"}, {["x"] = 11, ["meta"] = {["fields"] = {["infotext"] = "\"Input / Output 2\"", ["text"] = "Input / Output 2", ["formspec"] = "field[text;;${text}]"}, ["inventory"] = {}}, ["param2"] = 4, ["y"] = 2, ["param1"] = 47, ["z"] = 15, ["name"] = "default:sign_wall_steel"}, {["x"] = 11, ["y"] = 2, ["param1"] = 16, ["z"] = 16, ["name"] = "default:silver_sandstone"}, {["x"] = 11, ["y"] = 2, ["param1"] = 16, ["z"] = 17, ["name"] = "default:silver_sandstone"}, {["x"] = 11, ["y"] = 2, ["param1"] = 16, ["z"] = 18, ["name"] = "default:silver_sandstone"}, {["x"] = 11, ["y"] = 2, ["param1"] = 16, ["z"] = 19, ["name"] = "default:silver_sandstone"}, {["x"] = 11, ["y"] = 2, ["param1"] = 16, ["z"] = 20, ["name"] = "default:silver_sandstone"}, {["x"] = 11, ["y"] = 2, ["param1"] = 16, ["z"] = 21, ["name"] = "default:silver_sandstone"}, {["x"] = 11, ["y"] = 2, ["param1"] = 92, ["z"] = 22, ["name"] = "mesecons_extrawires:vertical_off"}, {["x"] = 11, ["y"] = 2, ["param1"] = 16, ["z"] = 23, ["name"] = "default:silver_sandstone"}, {["x"] = 11, ["y"] = 2, ["param1"] = 16, ["z"] = 24, ["name"] = "default:silver_sandstone"}, {["x"] = 11, ["meta"] = {["fields"] = {["infotext"] = "\"Input / Output 2\"", ["formspec"] = "field[text;;${text}]", ["text"] = "Input / Output 2"}, ["inventory"] = {}}, ["param2"] = 5, ["y"] = 2, ["param1"] = 47, ["z"] = 25, ["name"] = "default:sign_wall_steel"}, {["x"] = 11, ["y"] = 3, ["param1"] = 16, ["z"] = 4, ["name"] = "default:silver_sandstone"}, {["x"] = 11, ["param2"] = 2, ["y"] = 3, ["param1"] = 13, ["z"] = 5, ["name"] = "mesecons_insulated:insulated_off"}, {["x"] = 11, ["y"] = 3, ["param1"] = 13, ["z"] = 6, ["name"] = "mesecons_extrawires:vertical_top_off"}, {["x"] = 11, ["meta"] = {["fields"] = {["infotext"] = "FPGA (functional)", ["portstates"] = "0000", ["valid"] = "1", ["instr"] = "A&DC//////////////"}, ["inventory"] = {}}, ["y"] = 3, ["param1"] = 13, ["z"] = 7, ["name"] = "mesecons_fpga:fpga0000"}, {["x"] = 11, ["y"] = 3, ["param1"] = 12, ["z"] = 8, ["name"] = "mesecons_extrawires:vertical_bottom_off"}, {["x"] = 11, ["meta"] = {["fields"] = {["infotext"] = "FPGA (functional)", ["portstates"] = "0000", ["valid"] = "1", ["instr"] = "A&DB//////////////"}, ["inventory"] = {}}, ["y"] = 3, ["param1"] = 13, ["z"] = 9, ["name"] = "mesecons_fpga:fpga0000"}, {["x"] = 11, ["y"] = 3, ["param1"] = 13, ["z"] = 10, ["name"] = "mesecons_extrawires:vertical_top_off"}, {["x"] = 11, ["y"] = 3, ["param1"] = 13, ["z"] = 11, ["name"] = "mesecons_insulated:insulated_off"}, {["x"] = 11, ["y"] = 3, ["param1"] = 16, ["z"] = 12, ["name"] = "default:silver_sandstone"}, {["x"] = 11, ["y"] = 3, ["param1"] = 16, ["z"] = 16, ["name"] = "default:silver_sandstone"}, {["x"] = 11, ["param2"] = 2, ["y"] = 3, ["param1"] = 93, ["z"] = 17, ["name"] = "mesecons_insulated:insulated_off"}, {["x"] = 11, ["y"] = 3, ["param1"] = 140, ["z"] = 20, ["name"] = "mesecons_extrawires:vertical_bottom_off"}, {["x"] = 11, ["meta"] = {["fields"] = {["infotext"] = "FPGA (functional)", ["portstates"] = "1000", ["valid"] = "1", ["instr"] = "A&DB//////////////"}, ["inventory"] = {}}, ["y"] = 3, ["param1"] = 125, ["z"] = 21, ["name"] = "mesecons_fpga:fpga0000"}, {["x"] = 11, ["y"] = 3, ["param1"] = 109, ["z"] = 22, ["name"] = "mesecons_extrawires:vertical_top_off"},