5:return {{["x"] = 0, ["y"] = 0, ["param1"] = 238, ["z"] = 0, ["name"] = "default:meselamp"}, {["x"] = 0, ["y"] = 0, ["param1"] = 238, ["z"] = 1, ["name"] = "default:meselamp"}, {["x"] = 0, ["y"] = 0, ["param1"] = 238, ["z"] = 2, ["name"] = "default:meselamp"}, {["x"] = 0, ["y"] = 0, ["param1"] = 238, ["z"] = 3, ["name"] = "default:meselamp"}, {["x"] = 0, ["y"] = 0, ["param1"] = 238, ["z"] = 4, ["name"] = "default:meselamp"}, {["x"] = 0, ["y"] = 0, ["param1"] = 238, ["z"] = 5, ["name"] = "default:meselamp"}, {["x"] = 0, ["y"] = 0, ["param1"] = 238, ["z"] = 6, ["name"] = "default:meselamp"}, {["x"] = 0, ["y"] = 0, ["param1"] = 238, ["z"] = 7, ["name"] = "default:meselamp"}, {["x"] = 0, ["y"] = 0, ["param1"] = 238, ["z"] = 8, ["name"] = "default:meselamp"}, {["x"] = 0, ["y"] = 0, ["param1"] = 238, ["z"] = 9, ["name"] = "default:meselamp"}, {["x"] = 0, ["y"] = 0, ["param1"] = 238, ["z"] = 10, ["name"] = "default:meselamp"}, {["x"] = 0, ["y"] = 0, ["param1"] = 238, ["z"] = 11, ["name"] = "default:meselamp"}, {["x"] = 0, ["y"] = 0, ["param1"] = 238, ["z"] = 12, ["name"] = "default:meselamp"}, {["x"] = 0, ["y"] = 0, ["param1"] = 238, ["z"] = 13, ["name"] = "default:meselamp"}, {["x"] = 0, ["y"] = 0, ["param1"] = 238, ["z"] = 14, ["name"] = "default:meselamp"}, {["x"] = 0, ["y"] = 0, ["param1"] = 238, ["z"] = 15, ["name"] = "default:meselamp"}, {["x"] = 0, ["y"] = 0, ["param1"] = 238, ["z"] = 16, ["name"] = "default:meselamp"}, {["x"] = 0, ["y"] = 0, ["param1"] = 238, ["z"] = 17, ["name"] = "default:meselamp"}, {["x"] = 0, ["y"] = 0, ["param1"] = 238, ["z"] = 18, ["name"] = "default:meselamp"}, {["x"] = 0, ["y"] = 0, ["param1"] = 238, ["z"] = 19, ["name"] = "default:meselamp"}, {["x"] = 0, ["y"] = 0, ["param1"] = 238, ["z"] = 20, ["name"] = "default:meselamp"}, {["x"] = 0, ["y"] = 0, ["param1"] = 238, ["z"] = 21, ["name"] = "default:meselamp"}, {["x"] = 0, ["y"] = 0, ["param1"] = 238, ["z"] = 22, ["name"] = "default:meselamp"}, {["x"] = 0, ["y"] = 0, ["param1"] = 238, ["z"] = 23, ["name"] = "default:meselamp"}, {["x"] = 0, ["y"] = 0, ["param1"] = 238, ["z"] = 24, ["name"] = "default:meselamp"}, {["x"] = 0, ["y"] = 0, ["param1"] = 238, ["z"] = 25, ["name"] = "default:meselamp"}, {["x"] = 0, ["y"] = 0, ["param1"] = 238, ["z"] = 26, ["name"] = "default:meselamp"}, {["x"] = 0, ["y"] = 0, ["param1"] = 238, ["z"] = 27, ["name"] = "default:meselamp"}, {["x"] = 0, ["y"] = 0, ["param1"] = 238, ["z"] = 28, ["name"] = "default:meselamp"}, {["x"] = 0, ["y"] = 0, ["param1"] = 238, ["z"] = 29, ["name"] = "default:meselamp"}, {["x"] = 0, ["y"] = 0, ["param1"] = 238, ["z"] = 30, ["name"] = "default:meselamp"}, {["x"] = 0, ["y"] = 0, ["param1"] = 238, ["z"] = 31, ["name"] = "default:meselamp"}, {["x"] = 0, ["y"] = 0, ["param1"] = 238, ["z"] = 32, ["name"] = "default:meselamp"}, {["x"] = 0, ["y"] = 0, ["param1"] = 238, ["z"] = 33, ["name"] = "default:meselamp"}, {["x"] = 0, ["y"] = 0, ["param1"] = 238, ["z"] = 34, ["name"] = "default:meselamp"}, {["x"] = 0, ["y"] = 0, ["param1"] = 238, ["z"] = 35, ["name"] = "default:meselamp"}, {["x"] = 0, ["y"] = 0, ["param1"] = 238, ["z"] = 36, ["name"] = "default:meselamp"}, {["x"] = 0, ["y"] = 0, ["param1"] = 238, ["z"] = 37, ["name"] = "default:meselamp"}, {["x"] = 0, ["y"] = 0, ["param1"] = 238, ["z"] = 38, ["name"] = "default:meselamp"}, {["x"] = 0, ["y"] = 0, ["param1"] = 238, ["z"] = 39, ["name"] = "default:meselamp"}, {["x"] = 0, ["y"] = 0, ["param1"] = 238, ["z"] = 40, ["name"] = "default:meselamp"}, {["x"] = 0, ["y"] = 0, ["param1"] = 238, ["z"] = 41, ["name"] = "default:meselamp"}, {["x"] = 0, ["y"] = 0, ["param1"] = 238, ["z"] = 42, ["name"] = "default:meselamp"}, {["x"] = 0, ["y"] = 0, ["param1"] = 238, ["z"] = 43, ["name"] = "default:meselamp"}, {["x"] = 0, ["y"] = 0, ["param1"] = 238, ["z"] = 44, ["name"] = "default:meselamp"}, {["x"] = 0, ["y"] = 0, ["param1"] = 238, ["z"] = 45, ["name"] = "default:meselamp"}, {["x"] = 0, ["y"] = 0, ["param1"] = 238, ["z"] = 46, ["name"] = "default:meselamp"}, {["x"] = 0, ["y"] = 0, ["param1"] = 238, ["z"] = 47, ["name"] = "default:meselamp"}, {["x"] = 0, ["y"] = 0, ["param1"] = 238, ["z"] = 48, ["name"] = "default:meselamp"}, {["x"] = 0, ["y"] = 0, ["param1"] = 238, ["z"] = 49, ["name"] = "default:meselamp"}, {["x"] = 0, ["y"] = 0, ["param1"] = 238, ["z"] = 50, ["name"] = "default:meselamp"}, {["x"] = 0, ["y"] = 0, ["param1"] = 238, ["z"] = 51, ["name"] = "default:meselamp"}, {["x"] = 0, ["y"] = 0, ["param1"] = 238, ["z"] = 52, ["name"] = "default:meselamp"}, {["x"] = 0, ["y"] = 0, ["param1"] = 238, ["z"] = 53, ["name"] = "default:meselamp"}, {["x"] = 0, ["y"] = 0, ["param1"] = 238, ["z"] = 54, ["name"] = "default:meselamp"}, {["x"] = 0, ["y"] = 0, ["param1"] = 238, ["z"] = 55, ["name"] = "default:meselamp"}, {["x"] = 0, ["y"] = 1, ["param1"] = 43, ["z"] = 0, ["name"] = "mesecons_lightstone:lightstone_gray_off"}, {["x"] = 0, ["y"] = 1, ["param1"] = 43, ["z"] = 1, ["name"] = "mesecons_lightstone:lightstone_gray_off"}, {["x"] = 0, ["y"] = 1, ["param1"] = 43, ["z"] = 2, ["name"] = "mesecons_lightstone:lightstone_gray_off"}, {["x"] = 0, ["y"] = 1, ["param1"] = 43, ["z"] = 3, ["name"] = "mesecons_lightstone:lightstone_gray_off"}, {["x"] = 0, ["y"] = 1, ["param1"] = 43, ["z"] = 4, ["name"] = "mesecons_lightstone:lightstone_gray_off"}, {["x"] = 0, ["y"] = 1, ["param1"] = 43, ["z"] = 5, ["name"] = "mesecons_lightstone:lightstone_gray_off"}, {["x"] = 0, ["y"] = 1, ["param1"] = 43, ["z"] = 6, ["name"] = "mesecons_lightstone:lightstone_gray_off"}, {["x"] = 0, ["y"] = 1, ["param1"] = 43, ["z"] = 7, ["name"] = "mesecons_lightstone:lightstone_gray_off"}, {["x"] = 0, ["y"] = 1, ["param1"] = 43, ["z"] = 8, ["name"] = "mesecons_lightstone:lightstone_gray_off"}, {["x"] = 0, ["y"] = 1, ["param1"] = 43, ["z"] = 9, ["name"] = "mesecons_lightstone:lightstone_gray_off"}, {["x"] = 0, ["y"] = 1, ["param1"] = 43, ["z"] = 10, ["name"] = "mesecons_lightstone:lightstone_gray_off"}, {["x"] = 0, ["y"] = 1, ["param1"] = 43, ["z"] = 11, ["name"] = "mesecons_lightstone:lightstone_gray_off"}, {["x"] = 0, ["y"] = 1, ["param1"] = 43, ["z"] = 12, ["name"] = "mesecons_lightstone:lightstone_gray_off"}, {["x"] = 0, ["y"] = 1, ["param1"] = 43, ["z"] = 13, ["name"] = "mesecons_lightstone:lightstone_gray_off"}, {["x"] = 0, ["y"] = 1, ["param1"] = 43, ["z"] = 14, ["name"] = "mesecons_lightstone:lightstone_gray_off"}, {["x"] = 0, ["y"] = 1, ["param1"] = 43, ["z"] = 15, ["name"] = "mesecons_lightstone:lightstone_gray_off"}, {["x"] = 0, ["y"] = 1, ["param1"] = 43, ["z"] = 16, ["name"] = "mesecons_lightstone:lightstone_gray_off"}, {["x"] = 0, ["y"] = 1, ["param1"] = 43, ["z"] = 17, ["name"] = "mesecons_lightstone:lightstone_gray_off"}, {["x"] = 0, ["y"] = 1, ["param1"] = 44, ["z"] = 18, ["name"] = "mesecons_lightstone:lightstone_gray_off"}, {["x"] = 0, ["y"] = 1, ["param1"] = 44, ["z"] = 19, ["name"] = "mesecons_lightstone:lightstone_gray_off"}, {["x"] = 0, ["y"] = 1, ["param1"] = 44, ["z"] = 20, ["name"] = "mesecons_lightstone:lightstone_gray_off"}, {["x"] = 0, ["y"] = 1, ["param1"] = 44, ["z"] = 21, ["name"] = "mesecons_lightstone:lightstone_gray_off"}, {["x"] = 0, ["y"] = 1, ["param1"] = 44, ["z"] = 22, ["name"] = "mesecons_lightstone:lightstone_gray_off"}, {["x"] = 0, ["y"] = 1, ["param1"] = 44, ["z"] = 23, ["name"] = "mesecons_lightstone:lightstone_gray_off"}, {["x"] = 0, ["y"] = 1, ["param1"] = 44, ["z"] = 24, ["name"] = "mesecons_lightstone:lightstone_gray_off"}, {["x"] = 0, ["y"] = 1, ["param1"] = 44, ["z"] = 25, ["name"] = "mesecons_lightstone:lightstone_gray_off"}, {["x"] = 0, ["y"] = 1, ["param1"] = 44, ["z"] = 26, ["name"] = "mesecons_lightstone:lightstone_gray_off"}, {["x"] = 0, ["y"] = 1, ["param1"] = 44, ["z"] = 27, ["name"] = "mesecons_lightstone:lightstone_gray_off"}, {["x"] = 0, ["y"] = 1, ["param1"] = 44, ["z"] = 28, ["name"] = "mesecons_lightstone:lightstone_gray_off"}, {["x"] = 0, ["y"] = 1, ["param1"] = 44, ["z"] = 29, ["name"] = "mesecons_lightstone:lightstone_gray_off"}, {["x"] = 0, ["y"] = 1, ["param1"] = 44, ["z"] = 30, ["name"] = "mesecons_lightstone:lightstone_gray_off"}, {["x"] = 0, ["y"] = 1, ["param1"] = 44, ["z"] = 31, ["name"] = "mesecons_lightstone:lightstone_gray_off"}, {["x"] = 0, ["y"] = 1, ["param1"] = 44, ["z"] = 32, ["name"] = "mesecons_lightstone:lightstone_gray_off"}, {["x"] = 0, ["y"] = 1, ["param1"] = 44, ["z"] = 33, ["name"] = "mesecons_lightstone:lightstone_gray_off"}, {["x"] = 0, ["y"] = 1, ["param1"] = 44, ["z"] = 34, ["name"] = "mesecons_lightstone:lightstone_gray_off"}, {["x"] = 0, ["y"] = 1, ["param1"] = 44, ["z"] = 35, ["name"] = "mesecons_lightstone:lightstone_gray_off"}, {["x"] = 0, ["y"] = 1, ["param1"] = 44, ["z"] = 36, ["name"] = "mesecons_lightstone:lightstone_gray_off"}, {["x"] = 0, ["y"] = 1, ["param1"] = 44, ["z"] = 37, ["name"] = "mesecons_lightstone:lightstone_gray_off"}, {["x"] = 0, ["y"] = 1, ["param1"] = 44, ["z"] = 38, ["name"] = "mesecons_lightstone:lightstone_gray_off"}, {["x"] = 0, ["y"] = 1, ["param1"] = 44, ["z"] = 39, ["name"] = "mesecons_lightstone:lightstone_gray_off"}, {["x"] = 0, ["y"] = 1, ["param1"] = 44, ["z"] = 40, ["name"] = "mesecons_lightstone:lightstone_gray_off"}, {["x"] = 0, ["y"] = 1, ["param1"] = 44, ["z"] = 41, ["name"] = "mesecons_lightstone:lightstone_gray_off"}, {["x"] = 0, ["y"] = 1, ["param1"] = 44, ["z"] = 42, ["name"] = "mesecons_lightstone:lightstone_gray_off"}, {["x"] = 0, ["y"] = 1, ["param1"] = 44, ["z"] = 43, ["name"] = "mesecons_lightstone:lightstone_gray_off"}, {["x"] = 0, ["y"] = 1, ["param1"] = 44, ["z"] = 44, ["name"] = "mesecons_lightstone:lightstone_gray_off"}, {["x"] = 0, ["y"] = 1, ["param1"] = 44, ["z"] = 45, ["name"] = "mesecons_lightstone:lightstone_gray_off"}, {["x"] = 0, ["y"] = 1, ["param1"] = 44, ["z"] = 46, ["name"] = "mesecons_lightstone:lightstone_gray_off"}, {["x"] = 0, ["y"] = 1, ["param1"] = 44, ["z"] = 47, ["name"] = "mesecons_lightstone:lightstone_gray_off"}, {["x"] = 0, ["y"] = 1, ["param1"] = 44, ["z"] = 48, ["name"] = "mesecons_lightstone:lightstone_gray_off"}, {["x"] = 0, ["y"] = 1, ["param1"] = 44, ["z"] = 49, ["name"] = "mesecons_lightstone:lightstone_gray_off"}, {["x"] = 0, ["y"] = 1, ["param1"] = 43, ["z"] = 50, ["name"] = "mesecons_lightstone:lightstone_gray_off"}, {["x"] = 0, ["y"] = 1, ["param1"] = 43, ["z"] = 51, ["name"] = "mesecons_lightstone:lightstone_gray_off"}, {["x"] = 0, ["y"] = 1, ["param1"] = 43, ["z"] = 52, ["name"] = "mesecons_lightstone:lightstone_gray_off"}, {["x"] = 0, ["y"] = 1, ["param1"] = 43, ["z"] = 53, ["name"] = "mesecons_lightstone:lightstone_gray_off"}, {["x"] = 0, ["y"] = 1, ["param1"] = 43, ["z"] = 54, ["name"] = "mesecons_lightstone:lightstone_gray_off"}, {["x"] = 0, ["y"] = 1, ["param1"] = 43, ["z"] = 55, ["name"] = "mesecons_lightstone:lightstone_gray_off"}, {["x"] = 0, ["y"] = 2, ["param1"] = 238, ["z"] = 0, ["name"] = "default:meselamp"}, {["x"] = 0, ["y"] = 2, ["param1"] = 238, ["z"] = 1, ["name"] = "default:meselamp"}, {["x"] = 0, ["y"] = 2, ["param1"] = 238, ["z"] = 2, ["name"] = "default:meselamp"}, {["x"] = 0, ["y"] = 2, ["param1"] = 238, ["z"] = 3, ["name"] = "default:meselamp"}, {["x"] = 0, ["y"] = 2, ["param1"] = 238, ["z"] = 4, ["name"] = "default:meselamp"}, {["x"] = 0, ["y"] = 2, ["param1"] = 238, ["z"] = 5, ["name"] = "default:meselamp"}, {["x"] = 0, ["y"] = 2, ["param1"] = 238, ["z"] = 6, ["name"] = "default:meselamp"}, {["x"] = 0, ["y"] = 2, ["param1"] = 238, ["z"] = 7, ["name"] = "default:meselamp"}, {["x"] = 0, ["y"] = 2, ["param1"] = 238, ["z"] = 8, ["name"] = "default:meselamp"}, {["x"] = 0, ["y"] = 2, ["param1"] = 238, ["z"] = 9, ["name"] = "default:meselamp"}, {["x"] = 0, ["y"] = 2, ["param1"] = 238, ["z"] = 10, ["name"] = "default:meselamp"}, {["x"] = 0, ["y"] = 2, ["param1"] = 238, ["z"] = 11, ["name"] = "default:meselamp"}, {["x"] = 0, ["y"] = 2, ["param1"] = 238, ["z"] = 12, ["name"] = "default:meselamp"}, {["x"] = 0, ["y"] = 2, ["param1"] = 238, ["z"] = 13, ["name"] = "default:meselamp"}, {["x"] = 0, ["y"] = 2, ["param1"] = 238, ["z"] = 14, ["name"] = "default:meselamp"}, {["x"] = 0, ["y"] = 2, ["param1"] = 238, ["z"] = 15, ["name"] = "default:meselamp"}, {["x"] = 0, ["y"] = 2, ["param1"] = 238, ["z"] = 16, ["name"] = "default:meselamp"}, {["x"] = 0, ["y"] = 2, ["param1"] = 238, ["z"] = 17, ["name"] = "default:meselamp"}, {["x"] = 0, ["y"] = 2, ["param1"] = 238, ["z"] = 18, ["name"] = "default:meselamp"}, {["x"] = 0, ["y"] = 2, ["param1"] = 238, ["z"] = 19, ["name"] = "default:meselamp"}, {["x"] = 0, ["y"] = 2, ["param1"] = 238, ["z"] = 20, ["name"] = "default:meselamp"}, {["x"] = 0, ["y"] = 2, ["param1"] = 238, ["z"] = 21, ["name"] = "default:meselamp"}, {["x"] = 0, ["y"] = 2, ["param1"] = 238, ["z"] = 22, ["name"] = "default:meselamp"}, {["x"] = 0, ["y"] = 2, ["param1"] = 238, ["z"] = 23, ["name"] = "default:meselamp"}, {["x"] = 0, ["y"] = 2, ["param1"] = 238, ["z"] = 24, ["name"] = "default:meselamp"}, {["x"] = 0, ["y"] = 2, ["param1"] = 238, ["z"] = 25, ["name"] = "default:meselamp"}, {["x"] = 0, ["y"] = 2, ["param1"] = 238, ["z"] = 26, ["name"] = "default:meselamp"}, {["x"] = 0, ["y"] = 2, ["param1"] = 238, ["z"] = 27, ["name"] = "default:meselamp"}, {["x"] = 0, ["y"] = 2, ["param1"] = 238, ["z"] = 28, ["name"] = "default:meselamp"}, {["x"] = 0, ["y"] = 2, ["param1"] = 238, ["z"] = 29, ["name"] = "default:meselamp"}, {["x"] = 0, ["y"] = 2, ["param1"] = 238, ["z"] = 30, ["name"] = "default:meselamp"}, {["x"] = 0, ["y"] = 2, ["param1"] = 238, ["z"] = 31, ["name"] = "default:meselamp"}, {["x"] = 0, ["y"] = 2, ["param1"] = 238, ["z"] = 32, ["name"] = "default:meselamp"}, {["x"] = 0, ["y"] = 2, ["param1"] = 238, ["z"] = 33, ["name"] = "default:meselamp"}, {["x"] = 0, ["y"] = 2, ["param1"] = 238, ["z"] = 34, ["name"] = "default:meselamp"}, {["x"] = 0, ["y"] = 2, ["param1"] = 238, ["z"] = 35, ["name"] = "default:meselamp"}, {["x"] = 0, ["y"] = 2, ["param1"] = 238, ["z"] = 36, ["name"] = "default:meselamp"}, {["x"] = 0, ["y"] = 2, ["param1"] = 238, ["z"] = 37, ["name"] = "default:meselamp"}, {["x"] = 0, ["y"] = 2, ["param1"] = 238, ["z"] = 38, ["name"] = "default:meselamp"}, {["x"] = 0, ["y"] = 2, ["param1"] = 238, ["z"] = 39, ["name"] = "default:meselamp"}, {["x"] = 0, ["y"] = 2, ["param1"] = 238, ["z"] = 40, ["name"] = "default:meselamp"}, {["x"] = 0, ["y"] = 2, ["param1"] = 238, ["z"] = 41, ["name"] = "default:meselamp"}, {["x"] = 0, ["y"] = 2, ["param1"] = 238, ["z"] = 42, ["name"] = "default:meselamp"}, {["x"] = 0, ["y"] = 2, ["param1"] = 238, ["z"] = 43, ["name"] = "default:meselamp"}, {["x"] = 0, ["y"] = 2, ["param1"] = 238, ["z"] = 44, ["name"] = "default:meselamp"}, {["x"] = 0, ["y"] = 2, ["param1"] = 238, ["z"] = 45, ["name"] = "default:meselamp"}, {["x"] = 0, ["y"] = 2, ["param1"] = 238, ["z"] = 46, ["name"] = "default:meselamp"}, {["x"] = 0, ["y"] = 2, ["param1"] = 238, ["z"] = 47, ["name"] = "default:meselamp"}, {["x"] = 0, ["y"] = 2, ["param1"] = 238, ["z"] = 48, ["name"] = "default:meselamp"}, {["x"] = 0, ["y"] = 2, ["param1"] = 238, ["z"] = 49, ["name"] = "default:meselamp"}, {["x"] = 0, ["y"] = 2, ["param1"] = 238, ["z"] = 50, ["name"] = "default:meselamp"}, {["x"] = 0, ["y"] = 2, ["param1"] = 238, ["z"] = 51, ["name"] = "default:meselamp"}, {["x"] = 0, ["y"] = 2, ["param1"] = 238, ["z"] = 52, ["name"] = "default:meselamp"}, {["x"] = 0, ["y"] = 2, ["param1"] = 238, ["z"] = 53, ["name"] = "default:meselamp"}, {["x"] = 0, ["y"] = 2, ["param1"] = 238, ["z"] = 54, ["name"] = "default:meselamp"}, {["x"] = 0, ["y"] = 2, ["param1"] = 238, ["z"] = 55, ["name"] = "default:meselamp"}, {["x"] = 0, ["y"] = 3, ["param1"] = 18, ["z"] = 0, ["name"] = "default:silver_sandstone_block"}, {["x"] = 0, ["y"] = 3, ["param1"] = 18, ["z"] = 1, ["name"] = "default:silver_sandstone_block"}, {["x"] = 0, ["y"] = 3, ["param1"] = 18, ["z"] = 2, ["name"] = "default:silver_sandstone_block"}, {["x"] = 0, ["y"] = 3, ["param1"] = 18, ["z"] = 3, ["name"] = "default:silver_sandstone_block"}, {["x"] = 0, ["y"] = 3, ["param1"] = 18, ["z"] = 4, ["name"] = "default:silver_sandstone_block"}, {["x"] = 0, ["y"] = 3, ["param1"] = 18, ["z"] = 5, ["name"] = "default:silver_sandstone_block"}, {["x"] = 0, ["y"] = 3, ["param1"] = 18, ["z"] = 6, ["name"] = "default:silver_sandstone_block"}, {["x"] = 0, ["y"] = 3, ["param1"] = 18, ["z"] = 7, ["name"] = "default:silver_sandstone_block"}, {["x"] = 0, ["y"] = 3, ["param1"] = 18, ["z"] = 8, ["name"] = "default:silver_sandstone_block"}, {["x"] = 0, ["y"] = 3, ["param1"] = 18, ["z"] = 9, ["name"] = "default:silver_sandstone_block"}, {["x"] = 0, ["y"] = 3, ["param1"] = 18, ["z"] = 10, ["name"] = "default:silver_sandstone_block"}, {["x"] = 0, ["y"] = 3, ["param1"] = 18, ["z"] = 11, ["name"] = "default:silver_sandstone_block"}, {["x"] = 0, ["y"] = 3, ["param1"] = 18, ["z"] = 12, ["name"] = "default:silver_sandstone_block"}, {["x"] = 0, ["y"] = 3, ["param1"] = 18, ["z"] = 13, ["name"] = "default:silver_sandstone_block"}, {["x"] = 0, ["y"] = 3, ["param1"] = 18, ["z"] = 14, ["name"] = "default:silver_sandstone_block"}, {["x"] = 0, ["y"] = 3, ["param1"] = 18, ["z"] = 15, ["name"] = "default:silver_sandstone_block"}, {["x"] = 0, ["y"] = 3, ["param1"] = 18, ["z"] = 16, ["name"] = "default:silver_sandstone_block"}, {["x"] = 0, ["y"] = 3, ["param1"] = 18, ["z"] = 17, ["name"] = "default:silver_sandstone_block"}, {["x"] = 0, ["y"] = 3, ["param1"] = 18, ["z"] = 18, ["name"] = "default:silver_sandstone_block"}, {["x"] = 0, ["y"] = 3, ["param1"] = 18, ["z"] = 19, ["name"] = "default:silver_sandstone_block"}, {["x"] = 0, ["y"] = 3, ["param1"] = 18, ["z"] = 20, ["name"] = "default:silver_sandstone_block"}, {["x"] = 0, ["y"] = 3, ["param1"] = 18, ["z"] = 21, ["name"] = "default:silver_sandstone_block"}, {["x"] = 0, ["y"] = 3, ["param1"] = 18, ["z"] = 22, ["name"] = "default:silver_sandstone_block"}, {["x"] = 0, ["y"] = 3, ["param1"] = 18, ["z"] = 23, ["name"] = "default:silver_sandstone_block"}, {["x"] = 0, ["y"] = 3, ["param1"] = 18, ["z"] = 24, ["name"] = "default:silver_sandstone_block"}, {["x"] = 0, ["y"] = 3, ["param1"] = 18, ["z"] = 25, ["name"] = "default:silver_sandstone_block"}, {["x"] = 0, ["y"] = 3, ["param1"] = 18, ["z"] = 26, ["name"] = "default:silver_sandstone_block"}, {["x"] = 0, ["y"] = 3, ["param1"] = 18, ["z"] = 27, ["name"] = "default:silver_sandstone_block"}, {["x"] = 0, ["y"] = 3, ["param1"] = 18, ["z"] = 28, ["name"] = "default:silver_sandstone_block"}, {["x"] = 0, ["y"] = 3, ["param1"] = 18, ["z"] = 29, ["name"] = "default:silver_sandstone_block"}, {["x"] = 0, ["y"] = 3, ["param1"] = 18, ["z"] = 30, ["name"] = "default:silver_sandstone_block"}, {["x"] = 0, ["y"] = 3, ["param1"] = 18, ["z"] = 31, ["name"] = "default:silver_sandstone_block"}, {["x"] = 0, ["y"] = 3, ["param1"] = 18, ["z"] = 32, ["name"] = "default:silver_sandstone_block"}, {["x"] = 0, ["y"] = 3, ["param1"] = 18, ["z"] = 33, ["name"] = "default:silver_sandstone_block"}, {["x"] = 0, ["y"] = 3, ["param1"] = 18, ["z"] = 34, ["name"] = "default:silver_sandstone_block"}, {["x"] = 0, ["y"] = 3, ["param1"] = 18, ["z"] = 35, ["name"] = "default:silver_sandstone_block"}, {["x"] = 0, ["y"] = 3, ["param1"] = 18, ["z"] = 36, ["name"] = "default:silver_sandstone_block"}, {["x"] = 0, ["y"] = 3, ["param1"] = 18, ["z"] = 37, ["name"] = "default:silver_sandstone_block"}, {["x"] = 0, ["y"] = 3, ["param1"] = 18, ["z"] = 38, ["name"] = "default:silver_sandstone_block"}, {["x"] = 0, ["y"] = 3, ["param1"] = 18, ["z"] = 39, ["name"] = "default:silver_sandstone_block"}, {["x"] = 0, ["y"] = 3, ["param1"] = 18, ["z"] = 40, ["name"] = "default:silver_sandstone_block"}, {["x"] = 0, ["y"] = 3, ["param1"] = 18, ["z"] = 41, ["name"] = "default:silver_sandstone_block"}, {["x"] = 0, ["y"] = 3, ["param1"] = 18, ["z"] = 42, ["name"] = "default:silver_sandstone_block"}, {["x"] = 0, ["y"] = 3, ["param1"] = 18, ["z"] = 43, ["name"] = "default:silver_sandstone_block"}, {["x"] = 0, ["y"] = 3, ["param1"] = 18, ["z"] = 44, ["name"] = "default:silver_sandstone_block"}, {["x"] = 0, ["y"] = 3, ["param1"] = 18, ["z"] = 45, ["name"] = "default:silver_sandstone_block"}, {["x"] = 0, ["y"] = 3, ["param1"] = 18, ["z"] = 46, ["name"] = "default:silver_sandstone_block"}, {["x"] = 0, ["y"] = 3, ["param1"] = 18, ["z"] = 47, ["name"] = "default:silver_sandstone_block"}, {["x"] = 0, ["y"] = 3, ["param1"] = 18, ["z"] = 48, ["name"] = "default:silver_sandstone_block"}, {["x"] = 0, ["y"] = 3, ["param1"] = 18, ["z"] = 49, ["name"] = "default:silver_sandstone_block"}, {["x"] = 0, ["y"] = 3, ["param1"] = 18, ["z"] = 50, ["name"] = "default:silver_sandstone_block"}, {["x"] = 0, ["y"] = 3, ["param1"] = 18, ["z"] = 51, ["name"] = "default:silver_sandstone_block"}, {["x"] = 0, ["y"] = 3, ["param1"] = 18, ["z"] = 52, ["name"] = "default:silver_sandstone_block"}, {["x"] = 0, ["y"] = 3, ["param1"] = 18, ["z"] = 53, ["name"] = "default:silver_sandstone_block"}, {["x"] = 0, ["y"] = 3, ["param1"] = 18, ["z"] = 54, ["name"] = "default:silver_sandstone_block"}, {["x"] = 0, ["y"] = 3, ["param1"] = 18, ["z"] = 55, ["name"] = "default:silver_sandstone_block"}, {["x"] = 0, ["y"] = 4, ["param1"] = 43, ["z"] = 0, ["name"] = "mesecons_lightstone:lightstone_gray_off"}, {["x"] = 0, ["y"] = 4, ["param1"] = 43, ["z"] = 1, ["name"] = "mesecons_lightstone:lightstone_gray_off"}, {["x"] = 0, ["y"] = 4, ["param1"] = 43, ["z"] = 2, ["name"] = "mesecons_lightstone:lightstone_gray_off"}, {["x"] = 0, ["y"] = 4, ["param1"] = 43, ["z"] = 3, ["name"] = "mesecons_lightstone:lightstone_gray_off"}, {["x"] = 0, ["y"] = 4, ["param1"] = 43, ["z"] = 4, ["name"] = "mesecons_lightstone:lightstone_gray_off"}, {["x"] = 0, ["y"] = 4, ["param1"] = 43, ["z"] = 5, ["name"] = "mesecons_lightstone:lightstone_gray_off"}, {["x"] = 0, ["y"] = 4, ["param1"] = 43, ["z"] = 6, ["name"] = "mesecons_lightstone:lightstone_gray_off"}, {["x"] = 0, ["y"] = 4, ["param1"] = 43, ["z"] = 7, ["name"] = "mesecons_lightstone:lightstone_gray_off"}, {["x"] = 0, ["y"] = 4, ["param1"] = 43, ["z"] = 8, ["name"] = "mesecons_lightstone:lightstone_gray_off"}, {["x"] = 0, ["y"] = 4, ["param1"] = 43, ["z"] = 9, ["name"] = "mesecons_lightstone:lightstone_gray_off"}, {["x"] = 0, ["y"] = 4, ["param1"] = 43, ["z"] = 10, ["name"] = "mesecons_lightstone:lightstone_gray_off"}, {["x"] = 0, ["y"] = 4, ["param1"] = 43, ["z"] = 11, ["name"] = "mesecons_lightstone:lightstone_gray_off"}, {["x"] = 0, ["y"] = 4, ["param1"] = 43, ["z"] = 12, ["name"] = "mesecons_lightstone:lightstone_gray_off"}, {["x"] = 0, ["y"] = 4, ["param1"] = 43, ["z"] = 13, ["name"] = "mesecons_lightstone:lightstone_gray_off"}, {["x"] = 0, ["y"] = 4, ["param1"] = 43, ["z"] = 14, ["name"] = "mesecons_lightstone:lightstone_gray_off"}, {["x"] = 0, ["y"] = 4, ["param1"] = 43, ["z"] = 15, ["name"] = "mesecons_lightstone:lightstone_gray_off"}, {["x"] = 0, ["y"] = 4, ["param1"] = 43, ["z"] = 16, ["name"] = "mesecons_lightstone:lightstone_gray_off"}, {["x"] = 0, ["y"] = 4, ["param1"] = 43, ["z"] = 17, ["name"] = "mesecons_lightstone:lightstone_gray_off"}, {["x"] = 0, ["y"] = 4, ["param1"] = 44, ["z"] = 18, ["name"] = "mesecons_lightstone:lightstone_gray_off"}, {["x"] = 0, ["y"] = 4, ["param1"] = 44, ["z"] = 19, ["name"] = "mesecons_lightstone:lightstone_gray_off"}, {["x"] = 0, ["y"] = 4, ["param1"] = 44, ["z"] = 20, ["name"] = "mesecons_lightstone:lightstone_gray_off"}, {["x"] = 0, ["y"] = 4, ["param1"] = 44, ["z"] = 21, ["name"] = "mesecons_lightstone:lightstone_gray_off"}, {["x"] = 0, ["y"] = 4, ["param1"] = 44, ["z"] = 22, ["name"] = "mesecons_lightstone:lightstone_gray_off"}, {["x"] = 0, ["y"] = 4, ["param1"] = 44, ["z"] = 23, ["name"] = "mesecons_lightstone:lightstone_gray_off"}, {["x"] = 0, ["y"] = 4, ["param1"] = 44, ["z"] = 24, ["name"] = "mesecons_lightstone:lightstone_gray_off"}, {["x"] = 0, ["y"] = 4, ["param1"] = 44, ["z"] = 25, ["name"] = "mesecons_lightstone:lightstone_gray_off"}, {["x"] = 0, ["y"] = 4, ["param1"] = 44, ["z"] = 26, ["name"] = "mesecons_lightstone:lightstone_gray_off"}, {["x"] = 0, ["y"] = 4, ["param1"] = 44, ["z"] = 27, ["name"] = "mesecons_lightstone:lightstone_gray_off"}, {["x"] = 0, ["y"] = 4, ["param1"] = 44, ["z"] = 28, ["name"] = "mesecons_lightstone:lightstone_gray_off"}, {["x"] = 0, ["y"] = 4, ["param1"] = 44, ["z"] = 29, ["name"] = "mesecons_lightstone:lightstone_gray_off"}, {["x"] = 0, ["y"] = 4, ["param1"] = 44, ["z"] = 30, ["name"] = "mesecons_lightstone:lightstone_gray_off"}, {["x"] = 0, ["y"] = 4, ["param1"] = 44, ["z"] = 31, ["name"] = "mesecons_lightstone:lightstone_gray_off"}, {["x"] = 0, ["y"] = 4, ["param1"] = 44, ["z"] = 32, ["name"] = "mesecons_lightstone:lightstone_gray_off"}, {["x"] = 0, ["y"] = 4, ["param1"] = 44, ["z"] = 33, ["name"] = "mesecons_lightstone:lightstone_gray_off"}, {["x"] = 0, ["y"] = 4, ["param1"] = 44, ["z"] = 34, ["name"] = "mesecons_lightstone:lightstone_gray_off"}, {["x"] = 0, ["y"] = 4, ["param1"] = 44, ["z"] = 35, ["name"] = "mesecons_lightstone:lightstone_gray_off"}, {["x"] = 0, ["y"] = 4, ["param1"] = 44, ["z"] = 36, ["name"] = "mesecons_lightstone:lightstone_gray_off"}, {["x"] = 0, ["y"] = 4, ["param1"] = 44, ["z"] = 37, ["name"] = "mesecons_lightstone:lightstone_gray_off"}, {["x"] = 0, ["y"] = 4, ["param1"] = 44, ["z"] = 38, ["name"] = "mesecons_lightstone:lightstone_gray_off"}, {["x"] = 0, ["y"] = 4, ["param1"] = 44, ["z"] = 39, ["name"] = "mesecons_lightstone:lightstone_gray_off"}, {["x"] = 0, ["y"] = 4, ["param1"] = 44, ["z"] = 40, ["name"] = "mesecons_lightstone:lightstone_gray_off"}, {["x"] = 0, ["y"] = 4, ["param1"] = 44, ["z"] = 41, ["name"] = "mesecons_lightstone:lightstone_gray_off"}, {["x"] = 0, ["y"] = 4, ["param1"] = 44, ["z"] = 42, ["name"] = "mesecons_lightstone:lightstone_gray_off"}, {["x"] = 0, ["y"] = 4, ["param1"] = 44, ["z"] = 43, ["name"] = "mesecons_lightstone:lightstone_gray_off"}, {["x"] = 0, ["y"] = 4, ["param1"] = 44, ["z"] = 44, ["name"] = "mesecons_lightstone:lightstone_gray_off"}, {["x"] = 0, ["y"] = 4, ["param1"] = 44, ["z"] = 45, ["name"] = "mesecons_lightstone:lightstone_gray_off"}, {["x"] = 0, ["y"] = 4, ["param1"] = 44, ["z"] = 46, ["name"] = "mesecons_lightstone:lightstone_gray_off"}, {["x"] = 0, ["y"] = 4, ["param1"] = 44, ["z"] = 47, ["name"] = "mesecons_lightstone:lightstone_gray_off"}, {["x"] = 0, ["y"] = 4, ["param1"] = 44, ["z"] = 48, ["name"] = "mesecons_lightstone:lightstone_gray_off"}, {["x"] = 0, ["y"] = 4, ["param1"] = 44, ["z"] = 49, ["name"] = "mesecons_lightstone:lightstone_gray_off"}, {["x"] = 0, ["y"] = 4, ["param1"] = 43, ["z"] = 50, ["name"] = "mesecons_lightstone:lightstone_gray_off"}, {["x"] = 0, ["y"] = 4, ["param1"] = 43, ["z"] = 51, ["name"] = "mesecons_lightstone:lightstone_gray_off"}, {["x"] = 0, ["y"] = 4, ["param1"] = 43, ["z"] = 52, ["name"] = "mesecons_lightstone:lightstone_gray_off"}, {["x"] = 0, ["y"] = 4, ["param1"] = 43, ["z"] = 53, ["name"] = "mesecons_lightstone:lightstone_gray_off"}, {["x"] = 0, ["y"] = 4, ["param1"] = 43, ["z"] = 54, ["name"] = "mesecons_lightstone:lightstone_gray_off"}, {["x"] = 0, ["y"] = 4, ["param1"] = 43, ["z"] = 55, ["name"] = "mesecons_lightstone:lightstone_gray_off"}, {["x"] = 1, ["y"] = 0, ["param1"] = 238, ["z"] = 0, ["name"] = "default:meselamp"}, {["x"] = 1, ["y"] = 0, ["param1"] = 43, ["z"] = 1, ["name"] = "mesecons_lightstone:lightstone_gray_off"}, {["x"] = 1, ["y"] = 0, ["param1"] = 43, ["z"] = 2, ["name"] = "mesecons_lightstone:lightstone_gray_off"}, {["x"] = 1, ["y"] = 0, ["param1"] = 43, ["z"] = 3, ["name"] = "mesecons_lightstone:lightstone_gray_off"}, {["x"] = 1, ["y"] = 0, ["param1"] = 43, ["z"] = 4, ["name"] = "mesecons_lightstone:lightstone_gray_off"}, {["x"] = 1, ["y"] = 0, ["param1"] = 43, ["z"] = 5, ["name"] = "mesecons_lightstone:lightstone_gray_off"}, {["x"] = 1, ["y"] = 0, ["param1"] = 43, ["z"] = 6, ["name"] = "mesecons_lightstone:lightstone_gray_off"}, {["x"] = 1, ["y"] = 0, ["param1"] = 43, ["z"] = 7, ["name"] = "mesecons_lightstone:lightstone_gray_off"}, {["x"] = 1, ["y"] = 0, ["param1"] = 43, ["z"] = 8, ["name"] = "mesecons_lightstone:lightstone_gray_off"}, {["x"] = 1, ["y"] = 0, ["param1"] = 43, ["z"] = 9, ["name"] = "mesecons_lightstone:lightstone_gray_off"}, {["x"] = 1, ["y"] = 0, ["param1"] = 43, ["z"] = 10, ["name"] = "mesecons_lightstone:lightstone_gray_off"}, {["x"] = 1, ["y"] = 0, ["param1"] = 43, ["z"] = 11, ["name"] = "mesecons_lightstone:lightstone_gray_off"}, {["x"] = 1, ["y"] = 0, ["param1"] = 43, ["z"] = 12, ["name"] = "mesecons_lightstone:lightstone_gray_off"}, {["x"] = 1, ["y"] = 0, ["param1"] = 43, ["z"] = 13, ["name"] = "mesecons_lightstone:lightstone_gray_off"}, {["x"] = 1, ["y"] = 0, ["param1"] = 43, ["z"] = 14, ["name"] = "mesecons_lightstone:lightstone_gray_off"}, {["x"] = 1, ["y"] = 0, ["param1"] = 43, ["z"] = 15, ["name"] = "mesecons_lightstone:lightstone_gray_off"}, {["x"] = 1, ["y"] = 0, ["param1"] = 43, ["z"] = 16, ["name"] = "mesecons_lightstone:lightstone_gray_off"}, {["x"] = 1, ["y"] = 0, ["param1"] = 43, ["z"] = 17, ["name"] = "mesecons_lightstone:lightstone_gray_off"}, {["x"] = 1, ["y"] = 0, ["param1"] = 44, ["z"] = 18, ["name"] = "mesecons_lightstone:lightstone_gray_off"}, {["x"] = 1, ["y"] = 0, ["param1"] = 44, ["z"] = 19, ["name"] = "mesecons_lightstone:lightstone_gray_off"}, {["x"] = 1, ["y"] = 0, ["param1"] = 44, ["z"] = 20, ["name"] = "mesecons_lightstone:lightstone_gray_off"}, {["x"] = 1, ["y"] = 0, ["param1"] = 44, ["z"] = 21, ["name"] = "mesecons_lightstone:lightstone_gray_off"}, {["x"] = 1, ["y"] = 0, ["param1"] = 44, ["z"] = 22, ["name"] = "mesecons_lightstone:lightstone_gray_off"}, {["x"] = 1, ["y"] = 0, ["param1"] = 44, ["z"] = 23, ["name"] = "mesecons_lightstone:lightstone_gray_off"}, {["x"] = 1, ["y"] = 0, ["param1"] = 44, ["z"] = 24, ["name"] = "mesecons_lightstone:lightstone_gray_off"}, {["x"] = 1, ["y"] = 0, ["param1"] = 44, ["z"] = 25, ["name"] = "mesecons_lightstone:lightstone_gray_off"}, {["x"] = 1, ["y"] = 0, ["param1"] = 44, ["z"] = 26, ["name"] = "mesecons_lightstone:lightstone_gray_off"}, {["x"] = 1, ["y"] = 0, ["param1"] = 44, ["z"] = 27, ["name"] = "mesecons_lightstone:lightstone_gray_off"}, {["x"] = 1, ["y"] = 0, ["param1"] = 44, ["z"] = 28, ["name"] = "mesecons_lightstone:lightstone_gray_off"}, {["x"] = 1, ["y"] = 0, ["param1"] = 44, ["z"] = 29, ["name"] = "mesecons_lightstone:lightstone_gray_off"}, {["x"] = 1, ["y"] = 0, ["param1"] = 44, ["z"] = 30, ["name"] = "mesecons_lightstone:lightstone_gray_off"}, {["x"] = 1, ["y"] = 0, ["param1"] = 44, ["z"] = 31, ["name"] = "mesecons_lightstone:lightstone_gray_off"}, {["x"] = 1, ["y"] = 0, ["param1"] = 44, ["z"] = 32, ["name"] = "mesecons_lightstone:lightstone_gray_off"}, {["x"] = 1, ["y"] = 0, ["param1"] = 44, ["z"] = 33, ["name"] = "mesecons_lightstone:lightstone_gray_off"}, {["x"] = 1, ["y"] = 0, ["param1"] = 44, ["z"] = 34, ["name"] = "mesecons_lightstone:lightstone_gray_off"}, {["x"] = 1, ["y"] = 0, ["param1"] = 44, ["z"] = 35, ["name"] = "mesecons_lightstone:lightstone_gray_off"}, {["x"] = 1, ["y"] = 0, ["param1"] = 44, ["z"] = 36, ["name"] = "mesecons_lightstone:lightstone_gray_off"}, {["x"] = 1, ["y"] = 0, ["param1"] = 44, ["z"] = 37, ["name"] = "mesecons_lightstone:lightstone_gray_off"}, {["x"] = 1, ["y"] = 0, ["param1"] = 44, ["z"] = 38, ["name"] = "mesecons_lightstone:lightstone_gray_off"}, {["x"] = 1, ["y"] = 0, ["param1"] = 44, ["z"] = 39, ["name"] = "mesecons_lightstone:lightstone_gray_off"}, {["x"] = 1, ["y"] = 0, ["param1"] = 44, ["z"] = 40, ["name"] = "mesecons_lightstone:lightstone_gray_off"}, {["x"] = 1, ["y"] = 0, ["param1"] = 44, ["z"] = 41, ["name"] = "mesecons_lightstone:lightstone_gray_off"}, {["x"] = 1, ["y"] = 0, ["param1"] = 44, ["z"] = 42, ["name"] = "mesecons_lightstone:lightstone_gray_off"}, {["x"] = 1, ["y"] = 0, ["param1"] = 44, ["z"] = 43, ["name"] = "mesecons_lightstone:lightstone_gray_off"}, {["x"] = 1, ["y"] = 0, ["param1"] = 44, ["z"] = 44, ["name"] = "mesecons_lightstone:lightstone_gray_off"}, {["x"] = 1, ["y"] = 0, ["param1"] = 44, ["z"] = 45, ["name"] = "mesecons_lightstone:lightstone_gray_off"}, {["x"] = 1, ["y"] = 0, ["param1"] = 44, ["z"] = 46, ["name"] = "mesecons_lightstone:lightstone_gray_off"}, {["x"] = 1, ["y"] = 0, ["param1"] = 44, ["z"] = 47, ["name"] = "mesecons_lightstone:lightstone_gray_off"}, {["x"] = 1, ["y"] = 0, ["param1"] = 44, ["z"] = 48, ["name"] = "mesecons_lightstone:lightstone_gray_off"}, {["x"] = 1, ["y"] = 0, ["param1"] = 44, ["z"] = 49, ["name"] = "mesecons_lightstone:lightstone_gray_off"}, {["x"] = 1, ["y"] = 0, ["param1"] = 43, ["z"] = 50, ["name"] = "mesecons_lightstone:lightstone_gray_off"}, {["x"] = 1, ["y"] = 0, ["param1"] = 43, ["z"] = 51, ["name"] = "mesecons_lightstone:lightstone_gray_off"}, {["x"] = 1, ["y"] = 0, ["param1"] = 43, ["z"] = 52, ["name"] = "mesecons_lightstone:lightstone_gray_off"}, {["x"] = 1, ["y"] = 0, ["param1"] = 43, ["z"] = 53, ["name"] = "mesecons_lightstone:lightstone_gray_off"}, {["x"] = 1, ["y"] = 0, ["param1"] = 43, ["z"] = 54, ["name"] = "mesecons_lightstone:lightstone_gray_off"}, {["x"] = 1, ["y"] = 0, ["param1"] = 238, ["z"] = 55, ["name"] = "default:meselamp"}, {["x"] = 1, ["y"] = 1, ["param1"] = 43, ["z"] = 0, ["name"] = "mesecons_lightstone:lightstone_gray_off"}, {["x"] = 1, ["y"] = 1, ["param1"] = 43, ["z"] = 1, ["name"] = "mesecons_lightstone:lightstone_gray_off"}, {["x"] = 1, ["y"] = 1, ["param1"] = 43, ["z"] = 2, ["name"] = "mesecons_lightstone:lightstone_gray_off"}, {["x"] = 1, ["y"] = 1, ["param1"] = 43, ["z"] = 3, ["name"] = "mesecons_lightstone:lightstone_gray_off"}, {["x"] = 1, ["y"] = 1, ["param1"] = 43, ["z"] = 4, ["name"] = "mesecons_lightstone:lightstone_gray_off"}, {["x"] = 1, ["y"] = 1, ["param1"] = 43, ["z"] = 5, ["name"] = "mesecons_lightstone:lightstone_gray_off"}, {["x"] = 1, ["y"] = 1, ["param1"] = 43, ["z"] = 6, ["name"] = "mesecons_lightstone:lightstone_gray_off"}, {["x"] = 1, ["y"] = 1, ["param1"] = 43, ["z"] = 7, ["name"] = "mesecons_lightstone:lightstone_gray_off"}, {["x"] = 1, ["y"] = 1, ["param1"] = 43, ["z"] = 8, ["name"] = "mesecons_lightstone:lightstone_gray_off"}, {["x"] = 1, ["y"] = 1, ["param1"] = 43, ["z"] = 9, ["name"] = "mesecons_lightstone:lightstone_gray_off"}, {["x"] = 1, ["y"] = 1, ["param1"] = 43, ["z"] = 10, ["name"] = "mesecons_lightstone:lightstone_gray_off"}, {["x"] = 1, ["y"] = 1, ["param1"] = 43, ["z"] = 11, ["name"] = "mesecons_lightstone:lightstone_gray_off"}, {["x"] = 1, ["y"] = 1, ["param1"] = 43, ["z"] = 12, ["name"] = "mesecons_lightstone:lightstone_gray_off"}, {["x"] = 1, ["y"] = 1, ["param1"] = 43, ["z"] = 13, ["name"] = "mesecons_lightstone:lightstone_gray_off"}, {["x"] = 1, ["y"] = 1, ["param1"] = 43, ["z"] = 14, ["name"] = "mesecons_lightstone:lightstone_gray_off"}, {["x"] = 1, ["y"] = 1, ["param1"] = 43, ["z"] = 15, ["name"] = "mesecons_lightstone:lightstone_gray_off"}, {["x"] = 1, ["y"] = 1, ["param1"] = 43, ["z"] = 16, ["name"] = "mesecons_lightstone:lightstone_gray_off"}, {["x"] = 1, ["y"] = 1, ["param1"] = 43, ["z"] = 17, ["name"] = "mesecons_lightstone:lightstone_gray_off"}, {["x"] = 1, ["y"] = 1, ["param1"] = 44, ["z"] = 18, ["name"] = "mesecons_lightstone:lightstone_gray_off"}, {["x"] = 1, ["y"] = 1, ["param1"] = 44, ["z"] = 19, ["name"] = "mesecons_lightstone:lightstone_gray_off"}, {["x"] = 1, ["y"] = 1, ["param1"] = 44, ["z"] = 20, ["name"] = "mesecons_lightstone:lightstone_gray_off"}, {["x"] = 1, ["y"] = 1, ["param1"] = 44, ["z"] = 21, ["name"] = "mesecons_lightstone:lightstone_gray_off"}, {["x"] = 1, ["y"] = 1, ["param1"] = 44, ["z"] = 22, ["name"] = "mesecons_lightstone:lightstone_gray_off"}, {["x"] = 1, ["y"] = 1, ["param1"] = 44, ["z"] = 23, ["name"] = "mesecons_lightstone:lightstone_gray_off"}, {["x"] = 1, ["y"] = 1, ["param1"] = 44, ["z"] = 24, ["name"] = "mesecons_lightstone:lightstone_gray_off"}, {["x"] = 1, ["y"] = 1, ["param1"] = 44, ["z"] = 25, ["name"] = "mesecons_lightstone:lightstone_gray_off"}, {["x"] = 1, ["y"] = 1, ["param1"] = 44, ["z"] = 26, ["name"] = "mesecons_lightstone:lightstone_gray_off"}, {["x"] = 1, ["y"] = 1, ["param1"] = 44, ["z"] = 27, ["name"] = "mesecons_lightstone:lightstone_gray_off"}, {["x"] = 1, ["y"] = 1, ["param1"] = 44, ["z"] = 28, ["name"] = "mesecons_lightstone:lightstone_gray_off"}, {["x"] = 1, ["y"] = 1, ["param1"] = 44, ["z"] = 29, ["name"] = "mesecons_lightstone:lightstone_gray_off"}, {["x"] = 1, ["y"] = 1, ["param1"] = 44, ["z"] = 30, ["name"] = "mesecons_lightstone:lightstone_gray_off"}, {["x"] = 1, ["y"] = 1, ["param1"] = 44, ["z"] = 31, ["name"] = "mesecons_lightstone:lightstone_gray_off"}, {["x"] = 1, ["y"] = 1, ["param1"] = 44, ["z"] = 32, ["name"] = "mesecons_lightstone:lightstone_gray_off"}, {["x"] = 1, ["y"] = 1, ["param1"] = 44, ["z"] = 33, ["name"] = "mesecons_lightstone:lightstone_gray_off"}, {["x"] = 1, ["y"] = 1, ["param1"] = 44, ["z"] = 34, ["name"] = "mesecons_lightstone:lightstone_gray_off"}, {["x"] = 1, ["y"] = 1, ["param1"] = 44, ["z"] = 35, ["name"] = "mesecons_lightstone:lightstone_gray_off"}, {["x"] = 1, ["y"] = 1, ["param1"] = 44, ["z"] = 36, ["name"] = "mesecons_lightstone:lightstone_gray_off"}, {["x"] = 1, ["y"] = 1, ["param1"] = 44, ["z"] = 37, ["name"] = "mesecons_lightstone:lightstone_gray_off"}, {["x"] = 1, ["y"] = 1, ["param1"] = 44, ["z"] = 38, ["name"] = "mesecons_lightstone:lightstone_gray_off"}, {["x"] = 1, ["y"] = 1, ["param1"] = 44, ["z"] = 39, ["name"] = "mesecons_lightstone:lightstone_gray_off"}, {["x"] = 1, ["y"] = 1, ["param1"] = 44, ["z"] = 40, ["name"] = "mesecons_lightstone:lightstone_gray_off"}, {["x"] = 1, ["y"] = 1, ["param1"] = 44, ["z"] = 41, ["name"] = "mesecons_lightstone:lightstone_gray_off"}, {["x"] = 1, ["y"] = 1, ["param1"] = 44, ["z"] = 42, ["name"] = "mesecons_lightstone:lightstone_gray_off"}, {["x"] = 1, ["y"] = 1, ["param1"] = 44, ["z"] = 43, ["name"] = "mesecons_lightstone:lightstone_gray_off"}, {["x"] = 1, ["y"] = 1, ["param1"] = 44, ["z"] = 44, ["name"] = "mesecons_lightstone:lightstone_gray_off"}, {["x"] = 1, ["y"] = 1, ["param1"] = 44, ["z"] = 45, ["name"] = "mesecons_lightstone:lightstone_gray_off"}, {["x"] = 1, ["y"] = 1, ["param1"] = 44, ["z"] = 46, ["name"] = "mesecons_lightstone:lightstone_gray_off"}, {["x"] = 1, ["y"] = 1, ["param1"] = 44, ["z"] = 47, ["name"] = "mesecons_lightstone:lightstone_gray_off"}, {["x"] = 1, ["y"] = 1, ["param1"] = 44, ["z"] = 48, ["name"] = "mesecons_lightstone:lightstone_gray_off"}, {["x"] = 1, ["y"] = 1, ["param1"] = 44, ["z"] = 49, ["name"] = "mesecons_lightstone:lightstone_gray_off"}, {["x"] = 1, ["y"] = 1, ["param1"] = 43, ["z"] = 50, ["name"] = "mesecons_lightstone:lightstone_gray_off"}, {["x"] = 1, ["y"] = 1, ["param1"] = 43, ["z"] = 51, ["name"] = "mesecons_lightstone:lightstone_gray_off"}, {["x"] = 1, ["y"] = 1, ["param1"] = 43, ["z"] = 52, ["name"] = "mesecons_lightstone:lightstone_gray_off"}, {["x"] = 1, ["y"] = 1, ["param1"] = 43, ["z"] = 53, ["name"] = "mesecons_lightstone:lightstone_gray_off"}, {["x"] = 1, ["y"] = 1, ["param1"] = 43, ["z"] = 54, ["name"] = "mesecons_lightstone:lightstone_gray_off"}, {["x"] = 1, ["y"] = 1, ["param1"] = 43, ["z"] = 55, ["name"] = "mesecons_lightstone:lightstone_gray_off"}, {["x"] = 1, ["y"] = 2, ["param1"] = 238, ["z"] = 0, ["name"] = "default:meselamp"}, {["x"] = 1, ["y"] = 2, ["param1"] = 238, ["z"] = 1, ["name"] = "default:meselamp"}, {["x"] = 1, ["y"] = 2, ["param1"] = 238, ["z"] = 2, ["name"] = "default:meselamp"}, {["x"] = 1, ["y"] = 2, ["param1"] = 238, ["z"] = 3, ["name"] = "default:meselamp"}, {["x"] = 1, ["y"] = 2, ["param1"] = 238, ["z"] = 4, ["name"] = "default:meselamp"}, {["x"] = 1, ["y"] = 2, ["param1"] = 238, ["z"] = 5, ["name"] = "default:meselamp"}, {["x"] = 1, ["y"] = 2, ["param1"] = 238, ["z"] = 6, ["name"] = "default:meselamp"}, {["x"] = 1, ["y"] = 2, ["param1"] = 238, ["z"] = 7, ["name"] = "default:meselamp"}, {["x"] = 1, ["y"] = 2, ["param1"] = 238, ["z"] = 8, ["name"] = "default:meselamp"}, {["x"] = 1, ["y"] = 2, ["param1"] = 238, ["z"] = 9, ["name"] = "default:meselamp"}, {["x"] = 1, ["y"] = 2, ["param1"] = 238, ["z"] = 10, ["name"] = "default:meselamp"}, {["x"] = 1, ["y"] = 2, ["param1"] = 238, ["z"] = 11, ["name"] = "default:meselamp"}, {["x"] = 1, ["y"] = 2, ["param1"] = 238, ["z"] = 12, ["name"] = "default:meselamp"}, {["x"] = 1, ["y"] = 2, ["param1"] = 238, ["z"] = 13, ["name"] = "default:meselamp"}, {["x"] = 1, ["y"] = 2, ["param1"] = 238, ["z"] = 14, ["name"] = "default:meselamp"}, {["x"] = 1, ["y"] = 2, ["param1"] = 238, ["z"] = 15, ["name"] = "default:meselamp"}, {["x"] = 1, ["y"] = 2, ["param1"] = 238, ["z"] = 16, ["name"] = "default:meselamp"}, {["x"] = 1, ["y"] = 2, ["param1"] = 238, ["z"] = 17, ["name"] = "default:meselamp"}, {["x"] = 1, ["y"] = 2, ["param1"] = 238, ["z"] = 18, ["name"] = "default:meselamp"}, {["x"] = 1, ["y"] = 2, ["param1"] = 238, ["z"] = 19, ["name"] = "default:meselamp"}, {["x"] = 1, ["y"] = 2, ["param1"] = 238, ["z"] = 20, ["name"] = "default:meselamp"}, {["x"] = 1, ["y"] = 2, ["param1"] = 238, ["z"] = 21, ["name"] = "default:meselamp"}, {["x"] = 1, ["y"] = 2, ["param1"] = 238, ["z"] = 22, ["name"] = "default:meselamp"}, {["x"] = 1, ["y"] = 2, ["param1"] = 238, ["z"] = 23, ["name"] = "default:meselamp"}, {["x"] = 1, ["y"] = 2, ["param1"] = 238, ["z"] = 24, ["name"] = "default:meselamp"}, {["x"] = 1, ["y"] = 2, ["param1"] = 238, ["z"] = 25, ["name"] = "default:meselamp"}, {["x"] = 1, ["y"] = 2, ["param1"] = 238, ["z"] = 26, ["name"] = "default:meselamp"}, {["x"] = 1, ["y"] = 2, ["param1"] = 238, ["z"] = 27, ["name"] = "default:meselamp"}, {["x"] = 1, ["y"] = 2, ["param1"] = 238, ["z"] = 28, ["name"] = "default:meselamp"}, {["x"] = 1, ["y"] = 2, ["param1"] = 238, ["z"] = 29, ["name"] = "default:meselamp"}, {["x"] = 1, ["y"] = 2, ["param1"] = 238, ["z"] = 30, ["name"] = "default:meselamp"}, {["x"] = 1, ["y"] = 2, ["param1"] = 238, ["z"] = 31, ["name"] = "default:meselamp"}, {["x"] = 1, ["y"] = 2, ["param1"] = 238, ["z"] = 32, ["name"] = "default:meselamp"}, {["x"] = 1, ["y"] = 2, ["param1"] = 238, ["z"] = 33, ["name"] = "default:meselamp"}, {["x"] = 1, ["y"] = 2, ["param1"] = 238, ["z"] = 34, ["name"] = "default:meselamp"}, {["x"] = 1, ["y"] = 2, ["param1"] = 238, ["z"] = 35, ["name"] = "default:meselamp"}, {["x"] = 1, ["y"] = 2, ["param1"] = 238, ["z"] = 36, ["name"] = "default:meselamp"}, {["x"] = 1, ["y"] = 2, ["param1"] = 238, ["z"] = 37, ["name"] = "default:meselamp"}, {["x"] = 1, ["y"] = 2, ["param1"] = 238, ["z"] = 38, ["name"] = "default:meselamp"}, {["x"] = 1, ["y"] = 2, ["param1"] = 238, ["z"] = 39, ["name"] = "default:meselamp"}, {["x"] = 1, ["y"] = 2, ["param1"] = 238, ["z"] = 40, ["name"] = "default:meselamp"}, {["x"] = 1, ["y"] = 2, ["param1"] = 238, ["z"] = 41, ["name"] = "default:meselamp"}, {["x"] = 1, ["y"] = 2, ["param1"] = 238, ["z"] = 42, ["name"] = "default:meselamp"}, {["x"] = 1, ["y"] = 2, ["param1"] = 238, ["z"] = 43, ["name"] = "default:meselamp"}, {["x"] = 1, ["y"] = 2, ["param1"] = 238, ["z"] = 44, ["name"] = "default:meselamp"}, {["x"] = 1, ["y"] = 2, ["param1"] = 238, ["z"] = 45, ["name"] = "default:meselamp"}, {["x"] = 1, ["y"] = 2, ["param1"] = 238, ["z"] = 46, ["name"] = "default:meselamp"}, {["x"] = 1, ["y"] = 2, ["param1"] = 238, ["z"] = 47, ["name"] = "default:meselamp"}, {["x"] = 1, ["y"] = 2, ["param1"] = 238, ["z"] = 48, ["name"] = "default:meselamp"}, {["x"] = 1, ["y"] = 2, ["param1"] = 238, ["z"] = 49, ["name"] = "default:meselamp"}, {["x"] = 1, ["y"] = 2, ["param1"] = 238, ["z"] = 50, ["name"] = "default:meselamp"}, {["x"] = 1, ["y"] = 2, ["param1"] = 238, ["z"] = 51, ["name"] = "default:meselamp"}, {["x"] = 1, ["y"] = 2, ["param1"] = 238, ["z"] = 52, ["name"] = "default:meselamp"}, {["x"] = 1, ["y"] = 2, ["param1"] = 238, ["z"] = 53, ["name"] = "default:meselamp"}, {["x"] = 1, ["y"] = 2, ["param1"] = 238, ["z"] = 54, ["name"] = "default:meselamp"}, {["x"] = 1, ["y"] = 2, ["param1"] = 238, ["z"] = 55, ["name"] = "default:meselamp"}, {["x"] = 1, ["y"] = 3, ["param1"] = 18, ["z"] = 0, ["name"] = "default:silver_sandstone_block"}, {["x"] = 1, ["y"] = 3, ["param1"] = 18, ["z"] = 1, ["name"] = "default:silver_sandstone_block"}, {["x"] = 1, ["y"] = 3, ["param1"] = 18, ["z"] = 2, ["name"] = "default:silver_sandstone_block"}, {["x"] = 1, ["y"] = 3, ["param1"] = 18, ["z"] = 3, ["name"] = "default:silver_sandstone_block"}, {["x"] = 1, ["y"] = 3, ["param1"] = 18, ["z"] = 4, ["name"] = "default:silver_sandstone_block"}, {["x"] = 1, ["y"] = 3, ["param1"] = 18, ["z"] = 5, ["name"] = "default:silver_sandstone_block"}, {["x"] = 1, ["y"] = 3, ["param1"] = 18, ["z"] = 6, ["name"] = "default:silver_sandstone_block"}, {["x"] = 1, ["y"] = 3, ["param1"] = 18, ["z"] = 7, ["name"] = "default:silver_sandstone_block"}, {["x"] = 1, ["y"] = 3, ["param1"] = 18, ["z"] = 8, ["name"] = "default:silver_sandstone_block"}, {["x"] = 1, ["y"] = 3, ["param1"] = 18, ["z"] = 9, ["name"] = "default:silver_sandstone_block"}, {["x"] = 1, ["y"] = 3, ["param1"] = 18, ["z"] = 10, ["name"] = "default:silver_sandstone_block"}, {["x"] = 1, ["y"] = 3, ["param1"] = 18, ["z"] = 11, ["name"] = "default:silver_sandstone_block"}, {["x"] = 1, ["y"] = 3, ["param1"] = 18, ["z"] = 12, ["name"] = "default:silver_sandstone_block"}, {["x"] = 1, ["y"] = 3, ["param1"] = 18, ["z"] = 13, ["name"] = "default:silver_sandstone_block"}, {["x"] = 1, ["y"] = 3, ["param1"] = 18, ["z"] = 14, ["name"] = "default:silver_sandstone_block"}, {["x"] = 1, ["y"] = 3, ["param1"] = 18, ["z"] = 15, ["name"] = "default:silver_sandstone_block"}, {["x"] = 1, ["y"] = 3, ["param1"] = 18, ["z"] = 16, ["name"] = "default:silver_sandstone_block"}, {["x"] = 1, ["y"] = 3, ["param1"] = 18, ["z"] = 17, ["name"] = "default:silver_sandstone_block"}, {["x"] = 1, ["y"] = 3, ["param1"] = 18, ["z"] = 18, ["name"] = "default:silver_sandstone_block"}, {["x"] = 1, ["y"] = 3, ["param1"] = 18, ["z"] = 19, ["name"] = "default:silver_sandstone_block"}, {["x"] = 1, ["y"] = 3, ["param1"] = 18, ["z"] = 20, ["name"] = "default:silver_sandstone_block"}, {["x"] = 1, ["y"] = 3, ["param1"] = 18, ["z"] = 21, ["name"] = "default:silver_sandstone_block"}, {["x"] = 1, ["y"] = 3, ["param1"] = 18, ["z"] = 22, ["name"] = "default:silver_sandstone_block"}, {["x"] = 1, ["y"] = 3, ["param1"] = 18, ["z"] = 23, ["name"] = "default:silver_sandstone_block"}, {["x"] = 1, ["y"] = 3, ["param1"] = 18, ["z"] = 24, ["name"] = "default:silver_sandstone_block"}, {["x"] = 1, ["y"] = 3, ["param1"] = 18, ["z"] = 25, ["name"] = "default:silver_sandstone_block"}, {["x"] = 1, ["y"] = 3, ["param1"] = 18, ["z"] = 26, ["name"] = "default:silver_sandstone_block"}, {["x"] = 1, ["y"] = 3, ["param1"] = 18, ["z"] = 27, ["name"] = "default:silver_sandstone_block"}, {["x"] = 1, ["y"] = 3, ["param1"] = 18, ["z"] = 28, ["name"] = "default:silver_sandstone_block"}, {["x"] = 1, ["y"] = 3, ["param1"] = 18, ["z"] = 29, ["name"] = "default:silver_sandstone_block"}, {["x"] = 1, ["y"] = 3, ["param1"] = 18, ["z"] = 30, ["name"] = "default:silver_sandstone_block"}, {["x"] = 1, ["y"] = 3, ["param1"] = 18, ["z"] = 31, ["name"] = "default:silver_sandstone_block"}, {["x"] = 1, ["y"] = 3, ["param1"] = 18, ["z"] = 32, ["name"] = "default:silver_sandstone_block"}, {["x"] = 1, ["y"] = 3, ["param1"] = 18, ["z"] = 33, ["name"] = "default:silver_sandstone_block"}, {["x"] = 1, ["y"] = 3, ["param1"] = 18, ["z"] = 34, ["name"] = "default:silver_sandstone_block"}, {["x"] = 1, ["y"] = 3, ["param1"] = 18, ["z"] = 35, ["name"] = "default:silver_sandstone_block"}, {["x"] = 1, ["y"] = 3, ["param1"] = 18, ["z"] = 36, ["name"] = "default:silver_sandstone_block"}, {["x"] = 1, ["y"] = 3, ["param1"] = 18, ["z"] = 37, ["name"] = "default:silver_sandstone_block"}, {["x"] = 1, ["y"] = 3, ["param1"] = 18, ["z"] = 38, ["name"] = "default:silver_sandstone_block"}, {["x"] = 1, ["y"] = 3, ["param1"] = 18, ["z"] = 39, ["name"] = "default:silver_sandstone_block"}, {["x"] = 1, ["y"] = 3, ["param1"] = 18, ["z"] = 40, ["name"] = "default:silver_sandstone_block"}, {["x"] = 1, ["y"] = 3, ["param1"] = 18, ["z"] = 41, ["name"] = "default:silver_sandstone_block"}, {["x"] = 1, ["y"] = 3, ["param1"] = 18, ["z"] = 42, ["name"] = "default:silver_sandstone_block"}, {["x"] = 1, ["y"] = 3, ["param1"] = 18, ["z"] = 43, ["name"] = "default:silver_sandstone_block"}, {["x"] = 1, ["y"] = 3, ["param1"] = 18, ["z"] = 44, ["name"] = "default:silver_sandstone_block"}, {["x"] = 1, ["y"] = 3, ["param1"] = 18, ["z"] = 45, ["name"] = "default:silver_sandstone_block"}, {["x"] = 1, ["y"] = 3, ["param1"] = 18, ["z"] = 46, ["name"] = "default:silver_sandstone_block"}, {["x"] = 1, ["y"] = 3, ["param1"] = 18, ["z"] = 47, ["name"] = "default:silver_sandstone_block"}, {["x"] = 1, ["y"] = 3, ["param1"] = 18, ["z"] = 48, ["name"] = "default:silver_sandstone_block"}, {["x"] = 1, ["y"] = 3, ["param1"] = 18, ["z"] = 49, ["name"] = "default:silver_sandstone_block"}, {["x"] = 1, ["y"] = 3, ["param1"] = 18, ["z"] = 50, ["name"] = "default:silver_sandstone_block"}, {["x"] = 1, ["y"] = 3, ["param1"] = 18, ["z"] = 51, ["name"] = "default:silver_sandstone_block"}, {["x"] = 1, ["y"] = 3, ["param1"] = 18, ["z"] = 52, ["name"] = "default:silver_sandstone_block"}, {["x"] = 1, ["y"] = 3, ["param1"] = 18, ["z"] = 53, ["name"] = "default:silver_sandstone_block"}, {["x"] = 1, ["y"] = 3, ["param1"] = 18, ["z"] = 54, ["name"] = "default:silver_sandstone_block"}, {["x"] = 1, ["y"] = 3, ["param1"] = 18, ["z"] = 55, ["name"] = "default:silver_sandstone_block"}, {["x"] = 1, ["y"] = 4, ["param1"] = 43, ["z"] = 0, ["name"] = "mesecons_lightstone:lightstone_gray_off"}, {["x"] = 1, ["y"] = 4, ["param1"] = 43, ["z"] = 1, ["name"] = "mesecons_lightstone:lightstone_gray_off"}, {["x"] = 1, ["y"] = 4, ["param1"] = 43, ["z"] = 2, ["name"] = "mesecons_lightstone:lightstone_gray_off"}, {["x"] = 1, ["y"] = 4, ["param1"] = 43, ["z"] = 3, ["name"] = "mesecons_lightstone:lightstone_gray_off"}, {["x"] = 1, ["y"] = 4, ["param1"] = 43, ["z"] = 4, ["name"] = "mesecons_lightstone:lightstone_gray_off"}, {["x"] = 1, ["y"] = 4, ["param1"] = 43, ["z"] = 5, ["name"] = "mesecons_lightstone:lightstone_gray_off"}, {["x"] = 1, ["y"] = 4, ["param1"] = 43, ["z"] = 6, ["name"] = "mesecons_lightstone:lightstone_gray_off"}, {["x"] = 1, ["y"] = 4, ["param1"] = 43, ["z"] = 7, ["name"] = "mesecons_lightstone:lightstone_gray_off"}, {["x"] = 1, ["y"] = 4, ["param1"] = 43, ["z"] = 8, ["name"] = "mesecons_lightstone:lightstone_gray_off"}, {["x"] = 1, ["y"] = 4, ["param1"] = 43, ["z"] = 9, ["name"] = "mesecons_lightstone:lightstone_gray_off"}, {["x"] = 1, ["y"] = 4, ["param1"] = 43, ["z"] = 10, ["name"] = "mesecons_lightstone:lightstone_gray_off"}, {["x"] = 1, ["y"] = 4, ["param1"] = 43, ["z"] = 11, ["name"] = "mesecons_lightstone:lightstone_gray_off"}, {["x"] = 1, ["y"] = 4, ["param1"] = 43, ["z"] = 12, ["name"] = "mesecons_lightstone:lightstone_gray_off"}, {["x"] = 1, ["y"] = 4, ["param1"] = 43, ["z"] = 13, ["name"] = "mesecons_lightstone:lightstone_gray_off"}, {["x"] = 1, ["y"] = 4, ["param1"] = 43, ["z"] = 14, ["name"] = "mesecons_lightstone:lightstone_gray_off"}, {["x"] = 1, ["y"] = 4, ["param1"] = 43, ["z"] = 15, ["name"] = "mesecons_lightstone:lightstone_gray_off"}, {["x"] = 1, ["y"] = 4, ["param1"] = 43, ["z"] = 16, ["name"] = "mesecons_lightstone:lightstone_gray_off"}, {["x"] = 1, ["y"] = 4, ["param1"] = 43, ["z"] = 17, ["name"] = "mesecons_lightstone:lightstone_gray_off"}, {["x"] = 1, ["y"] = 4, ["param1"] = 44, ["z"] = 18, ["name"] = "mesecons_lightstone:lightstone_gray_off"}, {["x"] = 1, ["y"] = 4, ["param1"] = 44, ["z"] = 19, ["name"] = "mesecons_lightstone:lightstone_gray_off"}, {["x"] = 1, ["y"] = 4, ["param1"] = 44, ["z"] = 20, ["name"] = "mesecons_lightstone:lightstone_gray_off"}, {["x"] = 1, ["y"] = 4, ["param1"] = 44, ["z"] = 21, ["name"] = "mesecons_lightstone:lightstone_gray_off"}, {["x"] = 1, ["y"] = 4, ["param1"] = 44, ["z"] = 22, ["name"] = "mesecons_lightstone:lightstone_gray_off"}, {["x"] = 1, ["y"] = 4, ["param1"] = 44, ["z"] = 23, ["name"] = "mesecons_lightstone:lightstone_gray_off"}, {["x"] = 1, ["y"] = 4, ["param1"] = 44, ["z"] = 24, ["name"] = "mesecons_lightstone:lightstone_gray_off"}, {["x"] = 1, ["y"] = 4, ["param1"] = 44, ["z"] = 25, ["name"] = "mesecons_lightstone:lightstone_gray_off"}, {["x"] = 1, ["y"] = 4, ["param1"] = 44, ["z"] = 26, ["name"] = "mesecons_lightstone:lightstone_gray_off"}, {["x"] = 1, ["y"] = 4, ["param1"] = 44, ["z"] = 27, ["name"] = "mesecons_lightstone:lightstone_gray_off"}, {["x"] = 1, ["y"] = 4, ["param1"] = 44, ["z"] = 28, ["name"] = "mesecons_lightstone:lightstone_gray_off"}, {["x"] = 1, ["y"] = 4, ["param1"] = 44, ["z"] = 29, ["name"] = "mesecons_lightstone:lightstone_gray_off"}, {["x"] = 1, ["y"] = 4, ["param1"] = 44, ["z"] = 30, ["name"] = "mesecons_lightstone:lightstone_gray_off"}, {["x"] = 1, ["y"] = 4, ["param1"] = 44, ["z"] = 31, ["name"] = "mesecons_lightstone:lightstone_gray_off"}, {["x"] = 1, ["y"] = 4, ["param1"] = 44, ["z"] = 32, ["name"] = "mesecons_lightstone:lightstone_gray_off"}, {["x"] = 1, ["y"] = 4, ["param1"] = 44, ["z"] = 33, ["name"] = "mesecons_lightstone:lightstone_gray_off"}, {["x"] = 1, ["y"] = 4, ["param1"] = 44, ["z"] = 34, ["name"] = "mesecons_lightstone:lightstone_gray_off"}, {["x"] = 1, ["y"] = 4, ["param1"] = 44, ["z"] = 35, ["name"] = "mesecons_lightstone:lightstone_gray_off"}, {["x"] = 1, ["y"] = 4, ["param1"] = 44, ["z"] = 36, ["name"] = "mesecons_lightstone:lightstone_gray_off"}, {["x"] = 1, ["y"] = 4, ["param1"] = 44, ["z"] = 37, ["name"] = "mesecons_lightstone:lightstone_gray_off"}, {["x"] = 1, ["y"] = 4, ["param1"] = 44, ["z"] = 38, ["name"] = "mesecons_lightstone:lightstone_gray_off"}, {["x"] = 1, ["y"] = 4, ["param1"] = 44, ["z"] = 39, ["name"] = "mesecons_lightstone:lightstone_gray_off"}, {["x"] = 1, ["y"] = 4, ["param1"] = 44, ["z"] = 40, ["name"] = "mesecons_lightstone:lightstone_gray_off"}, {["x"] = 1, ["y"] = 4, ["param1"] = 44, ["z"] = 41, ["name"] = "mesecons_lightstone:lightstone_gray_off"}, {["x"] = 1, ["y"] = 4, ["param1"] = 44, ["z"] = 42, ["name"] = "mesecons_lightstone:lightstone_gray_off"}, {["x"] = 1, ["y"] = 4, ["param1"] = 44, ["z"] = 43, ["name"] = "mesecons_lightstone:lightstone_gray_off"}, {["x"] = 1, ["y"] = 4, ["param1"] = 44, ["z"] = 44, ["name"] = "mesecons_lightstone:lightstone_gray_off"}, {["x"] = 1, ["y"] = 4, ["param1"] = 44, ["z"] = 45, ["name"] = "mesecons_lightstone:lightstone_gray_off"}, {["x"] = 1, ["y"] = 4, ["param1"] = 44, ["z"] = 46, ["name"] = "mesecons_lightstone:lightstone_gray_off"}, {["x"] = 1, ["y"] = 4, ["param1"] = 44, ["z"] = 47, ["name"] = "mesecons_lightstone:lightstone_gray_off"}, {["x"] = 1, ["y"] = 4, ["param1"] = 44, ["z"] = 48, ["name"] = "mesecons_lightstone:lightstone_gray_off"}, {["x"] = 1, ["y"] = 4, ["param1"] = 44, ["z"] = 49, ["name"] = "mesecons_lightstone:lightstone_gray_off"}, {["x"] = 1, ["y"] = 4, ["param1"] = 43, ["z"] = 50, ["name"] = "mesecons_lightstone:lightstone_gray_off"}, {["x"] = 1, ["y"] = 4, ["param1"] = 43, ["z"] = 51, ["name"] = "mesecons_lightstone:lightstone_gray_off"}, {["x"] = 1, ["y"] = 4, ["param1"] = 43, ["z"] = 52, ["name"] = "mesecons_lightstone:lightstone_gray_off"}, {["x"] = 1, ["y"] = 4, ["param1"] = 43, ["z"] = 53, ["name"] = "mesecons_lightstone:lightstone_gray_off"}, {["x"] = 1, ["y"] = 4, ["param1"] = 43, ["z"] = 54, ["name"] = "mesecons_lightstone:lightstone_gray_off"}, {["x"] = 1, ["y"] = 4, ["param1"] = 43, ["z"] = 55, ["name"] = "mesecons_lightstone:lightstone_gray_off"}, {["x"] = 2, ["y"] = 0, ["param1"] = 238, ["z"] = 0, ["name"] = "default:meselamp"}, {["x"] = 2, ["y"] = 0, ["param1"] = 43, ["z"] = 1, ["name"] = "mesecons_lightstone:lightstone_gray_off"}, {["x"] = 2, ["y"] = 0, ["param1"] = 43, ["z"] = 2, ["name"] = "mesecons_lightstone:lightstone_gray_off"}, {["x"] = 2, ["y"] = 0, ["param1"] = 43, ["z"] = 3, ["name"] = "mesecons_lightstone:lightstone_gray_off"}, {["x"] = 2, ["y"] = 0, ["param1"] = 43, ["z"] = 4, ["name"] = "mesecons_lightstone:lightstone_gray_off"}, {["x"] = 2, ["y"] = 0, ["param1"] = 43, ["z"] = 5, ["name"] = "mesecons_lightstone:lightstone_gray_off"}, {["x"] = 2, ["y"] = 0, ["param1"] = 43, ["z"] = 6, ["name"] = "mesecons_lightstone:lightstone_gray_off"}, {["x"] = 2, ["y"] = 0, ["param1"] = 43, ["z"] = 7, ["name"] = "mesecons_lightstone:lightstone_gray_off"}, {["x"] = 2, ["y"] = 0, ["param1"] = 43, ["z"] = 8, ["name"] = "mesecons_lightstone:lightstone_gray_off"}, {["x"] = 2, ["y"] = 0, ["param1"] = 43, ["z"] = 9, ["name"] = "mesecons_lightstone:lightstone_gray_off"}, {["x"] = 2, ["y"] = 0, ["param1"] = 43, ["z"] = 10, ["name"] = "mesecons_lightstone:lightstone_gray_off"}, {["x"] = 2, ["y"] = 0, ["param1"] = 43, ["z"] = 11, ["name"] = "mesecons_lightstone:lightstone_gray_off"}, {["x"] = 2, ["y"] = 0, ["param1"] = 43, ["z"] = 12, ["name"] = "mesecons_lightstone:lightstone_gray_off"}, {["x"] = 2, ["y"] = 0, ["param1"] = 43, ["z"] = 13, ["name"] = "mesecons_lightstone:lightstone_gray_off"}, {["x"] = 2, ["y"] = 0, ["param1"] = 43, ["z"] = 14, ["name"] = "mesecons_lightstone:lightstone_gray_off"}, {["x"] = 2, ["y"] = 0, ["param1"] = 43, ["z"] = 15, ["name"] = "mesecons_lightstone:lightstone_gray_off"}, {["x"] = 2, ["y"] = 0, ["param1"] = 43, ["z"] = 16, ["name"] = "mesecons_lightstone:lightstone_gray_off"}, {["x"] = 2, ["y"] = 0, ["param1"] = 43, ["z"] = 17, ["name"] = "mesecons_lightstone:lightstone_gray_off"}, {["x"] = 2, ["y"] = 0, ["param1"] = 44, ["z"] = 18, ["name"] = "mesecons_lightstone:lightstone_gray_off"}, {["x"] = 2, ["y"] = 0, ["param1"] = 44, ["z"] = 19, ["name"] = "mesecons_lightstone:lightstone_gray_off"}, {["x"] = 2, ["y"] = 0, ["param1"] = 44, ["z"] = 20, ["name"] = "mesecons_lightstone:lightstone_gray_off"}, {["x"] = 2, ["y"] = 0, ["param1"] = 44, ["z"] = 21, ["name"] = "mesecons_lightstone:lightstone_gray_off"}, {["x"] = 2, ["y"] = 0, ["param1"] = 44, ["z"] = 22, ["name"] = "mesecons_lightstone:lightstone_gray_off"}, {["x"] = 2, ["y"] = 0, ["param1"] = 44, ["z"] = 23, ["name"] = "mesecons_lightstone:lightstone_gray_off"}, {["x"] = 2, ["y"] = 0, ["param1"] = 44, ["z"] = 24, ["name"] = "mesecons_lightstone:lightstone_gray_off"}, {["x"] = 2, ["y"] = 0, ["param1"] = 44, ["z"] = 25, ["name"] = "mesecons_lightstone:lightstone_gray_off"}, {["x"] = 2, ["y"] = 0, ["param1"] = 44, ["z"] = 26, ["name"] = "mesecons_lightstone:lightstone_gray_off"}, {["x"] = 2, ["y"] = 0, ["param1"] = 44, ["z"] = 27, ["name"] = "mesecons_lightstone:lightstone_gray_off"}, {["x"] = 2, ["y"] = 0, ["param1"] = 44, ["z"] = 28, ["name"] = "mesecons_lightstone:lightstone_gray_off"}, {["x"] = 2, ["y"] = 0, ["param1"] = 44, ["z"] = 29, ["name"] = "mesecons_lightstone:lightstone_gray_off"}, {["x"] = 2, ["y"] = 0, ["param1"] = 44, ["z"] = 30, ["name"] = "mesecons_lightstone:lightstone_gray_off"}, {["x"] = 2, ["y"] = 0, ["param1"] = 44, ["z"] = 31, ["name"] = "mesecons_lightstone:lightstone_gray_off"}, {["x"] = 2, ["y"] = 0, ["param1"] = 44, ["z"] = 32, ["name"] = "mesecons_lightstone:lightstone_gray_off"}, {["x"] = 2, ["y"] = 0, ["param1"] = 44, ["z"] = 33, ["name"] = "mesecons_lightstone:lightstone_gray_off"}, {["x"] = 2, ["y"] = 0, ["param1"] = 44, ["z"] = 34, ["name"] = "mesecons_lightstone:lightstone_gray_off"}, {["x"] = 2, ["y"] = 0, ["param1"] = 44, ["z"] = 35, ["name"] = "mesecons_lightstone:lightstone_gray_off"}, {["x"] = 2, ["y"] = 0, ["param1"] = 44, ["z"] = 36, ["name"] = "mesecons_lightstone:lightstone_gray_off"}, {["x"] = 2, ["y"] = 0, ["param1"] = 44, ["z"] = 37, ["name"] = "mesecons_lightstone:lightstone_gray_off"}, {["x"] = 2, ["y"] = 0, ["param1"] = 44, ["z"] = 38, ["name"] = "mesecons_lightstone:lightstone_gray_off"}, {["x"] = 2, ["y"] = 0, ["param1"] = 44, ["z"] = 39, ["name"] = "mesecons_lightstone:lightstone_gray_off"}, {["x"] = 2, ["y"] = 0, ["param1"] = 44, ["z"] = 40, ["name"] = "mesecons_lightstone:lightstone_gray_off"}, {["x"] = 2, ["y"] = 0, ["param1"] = 44, ["z"] = 41, ["name"] = "mesecons_lightstone:lightstone_gray_off"}, {["x"] = 2, ["y"] = 0, ["param1"] = 44, ["z"] = 42, ["name"] = "mesecons_lightstone:lightstone_gray_off"}, {["x"] = 2, ["y"] = 0, ["param1"] = 44, ["z"] = 43, ["name"] = "mesecons_lightstone:lightstone_gray_off"}, {["x"] = 2, ["y"] = 0, ["param1"] = 44, ["z"] = 44, ["name"] = "mesecons_lightstone:lightstone_gray_off"}, {["x"] = 2, ["y"] = 0, ["param1"] = 44, ["z"] = 45, ["name"] = "mesecons_lightstone:lightstone_gray_off"}, {["x"] = 2, ["y"] = 0, ["param1"] = 44, ["z"] = 46, ["name"] = "mesecons_lightstone:lightstone_gray_off"}, {["x"] = 2, ["y"] = 0, ["param1"] = 44, ["z"] = 47, ["name"] = "mesecons_lightstone:lightstone_gray_off"}, {["x"] = 2, ["y"] = 0, ["param1"] = 44, ["z"] = 48, ["name"] = "mesecons_lightstone:lightstone_gray_off"}, {["x"] = 2, ["y"] = 0, ["param1"] = 44, ["z"] = 49, ["name"] = "mesecons_lightstone:lightstone_gray_off"}, {["x"] = 2, ["y"] = 0, ["param1"] = 43, ["z"] = 50, ["name"] = "mesecons_lightstone:lightstone_gray_off"}, {["x"] = 2, ["y"] = 0, ["param1"] = 43, ["z"] = 51, ["name"] = "mesecons_lightstone:lightstone_gray_off"}, {["x"] = 2, ["y"] = 0, ["param1"] = 43, ["z"] = 52, ["name"] = "mesecons_lightstone:lightstone_gray_off"}, {["x"] = 2, ["y"] = 0, ["param1"] = 43, ["z"] = 53, ["name"] = "mesecons_lightstone:lightstone_gray_off"}, {["x"] = 2, ["y"] = 0, ["param1"] = 43, ["z"] = 54, ["name"] = "mesecons_lightstone:lightstone_gray_off"}, {["x"] = 2, ["y"] = 0, ["param1"] = 238, ["z"] = 55, ["name"] = "default:meselamp"}, {["x"] = 2, ["y"] = 1, ["param1"] = 43, ["z"] = 0, ["name"] = "mesecons_lightstone:lightstone_gray_off"}, {["x"] = 2, ["y"] = 1, ["param1"] = 43, ["z"] = 1, ["name"] = "mesecons_lightstone:lightstone_gray_off"}, {["x"] = 2, ["y"] = 1, ["param1"] = 43, ["z"] = 2, ["name"] = "mesecons_lightstone:lightstone_gray_off"}, {["x"] = 2, ["y"] = 1, ["param1"] = 43, ["z"] = 3, ["name"] = "mesecons_lightstone:lightstone_gray_off"}, {["x"] = 2, ["y"] = 1, ["param1"] = 43, ["z"] = 4, ["name"] = "mesecons_lightstone:lightstone_gray_off"}, {["x"] = 2, ["y"] = 1, ["param1"] = 43, ["z"] = 5, ["name"] = "mesecons_lightstone:lightstone_gray_off"}, {["x"] = 2, ["y"] = 1, ["param1"] = 43, ["z"] = 6, ["name"] = "mesecons_lightstone:lightstone_gray_off"}, {["x"] = 2, ["y"] = 1, ["param1"] = 43, ["z"] = 7, ["name"] = "mesecons_lightstone:lightstone_gray_off"}, {["x"] = 2, ["y"] = 1, ["param1"] = 43, ["z"] = 8, ["name"] = "mesecons_lightstone:lightstone_gray_off"}, {["x"] = 2, ["y"] = 1, ["param1"] = 43, ["z"] = 9, ["name"] = "mesecons_lightstone:lightstone_gray_off"}, {["x"] = 2, ["y"] = 1, ["param1"] = 43, ["z"] = 10, ["name"] = "mesecons_lightstone:lightstone_gray_off"}, {["x"] = 2, ["y"] = 1, ["param1"] = 43, ["z"] = 11, ["name"] = "mesecons_lightstone:lightstone_gray_off"}, {["x"] = 2, ["y"] = 1, ["param1"] = 43, ["z"] = 12, ["name"] = "mesecons_lightstone:lightstone_gray_off"}, {["x"] = 2, ["y"] = 1, ["param1"] = 43, ["z"] = 13, ["name"] = "mesecons_lightstone:lightstone_gray_off"}, {["x"] = 2, ["y"] = 1, ["param1"] = 43, ["z"] = 14, ["name"] = "mesecons_lightstone:lightstone_gray_off"}, {["x"] = 2, ["y"] = 1, ["param1"] = 43, ["z"] = 15, ["name"] = "mesecons_lightstone:lightstone_gray_off"}, {["x"] = 2, ["y"] = 1, ["param1"] = 43, ["z"] = 16, ["name"] = "mesecons_lightstone:lightstone_gray_off"}, {["x"] = 2, ["y"] = 1, ["param1"] = 43, ["z"] = 17, ["name"] = "mesecons_lightstone:lightstone_gray_off"}, {["x"] = 2, ["y"] = 1, ["param1"] = 44, ["z"] = 18, ["name"] = "mesecons_lightstone:lightstone_gray_off"}, {["x"] = 2, ["y"] = 1, ["param1"] = 44, ["z"] = 19, ["name"] = "mesecons_lightstone:lightstone_gray_off"}, {["x"] = 2, ["y"] = 1, ["param1"] = 44, ["z"] = 20, ["name"] = "mesecons_lightstone:lightstone_gray_off"}, {["x"] = 2, ["y"] = 1, ["param1"] = 44, ["z"] = 21, ["name"] = "mesecons_lightstone:lightstone_gray_off"}, {["x"] = 2, ["y"] = 1, ["param1"] = 44, ["z"] = 22, ["name"] = "mesecons_lightstone:lightstone_gray_off"}, {["x"] = 2, ["y"] = 1, ["param1"] = 44, ["z"] = 23, ["name"] = "mesecons_lightstone:lightstone_gray_off"}, {["x"] = 2, ["y"] = 1, ["param1"] = 44, ["z"] = 24, ["name"] = "mesecons_lightstone:lightstone_gray_off"}, {["x"] = 2, ["y"] = 1, ["param1"] = 44, ["z"] = 25, ["name"] = "mesecons_lightstone:lightstone_gray_off"}, {["x"] = 2, ["y"] = 1, ["param1"] = 44, ["z"] = 26, ["name"] = "mesecons_lightstone:lightstone_gray_off"}, {["x"] = 2, ["y"] = 1, ["param1"] = 44, ["z"] = 27, ["name"] = "mesecons_lightstone:lightstone_gray_off"}, {["x"] = 2, ["y"] = 1, ["param1"] = 44, ["z"] = 28, ["name"] = "mesecons_lightstone:lightstone_gray_off"}, {["x"] = 2, ["y"] = 1, ["param1"] = 44, ["z"] = 29, ["name"] = "mesecons_lightstone:lightstone_gray_off"}, {["x"] = 2, ["y"] = 1, ["param1"] = 44, ["z"] = 30, ["name"] = "mesecons_lightstone:lightstone_gray_off"}, {["x"] = 2, ["y"] = 1, ["param1"] = 44, ["z"] = 31, ["name"] = "mesecons_lightstone:lightstone_gray_off"}, {["x"] = 2, ["y"] = 1, ["param1"] = 44, ["z"] = 32, ["name"] = "mesecons_lightstone:lightstone_gray_off"}, {["x"] = 2, ["y"] = 1, ["param1"] = 44, ["z"] = 33, ["name"] = "mesecons_lightstone:lightstone_gray_off"}, {["x"] = 2, ["y"] = 1, ["param1"] = 44, ["z"] = 34, ["name"] = "mesecons_lightstone:lightstone_gray_off"}, {["x"] = 2, ["y"] = 1, ["param1"] = 44, ["z"] = 35, ["name"] = "mesecons_lightstone:lightstone_gray_off"}, {["x"] = 2, ["y"] = 1, ["param1"] = 44, ["z"] = 36, ["name"] = "mesecons_lightstone:lightstone_gray_off"}, {["x"] = 2, ["y"] = 1, ["param1"] = 44, ["z"] = 37, ["name"] = "mesecons_lightstone:lightstone_gray_off"}, {["x"] = 2, ["y"] = 1, ["param1"] = 44, ["z"] = 38, ["name"] = "mesecons_lightstone:lightstone_gray_off"}, {["x"] = 2, ["y"] = 1, ["param1"] = 44, ["z"] = 39, ["name"] = "mesecons_lightstone:lightstone_gray_off"}, {["x"] = 2, ["y"] = 1, ["param1"] = 44, ["z"] = 40, ["name"] = "mesecons_lightstone:lightstone_gray_off"}, {["x"] = 2, ["y"] = 1, ["param1"] = 44, ["z"] = 41, ["name"] = "mesecons_lightstone:lightstone_gray_off"}, {["x"] = 2, ["y"] = 1, ["param1"] = 44, ["z"] = 42, ["name"] = "mesecons_lightstone:lightstone_gray_off"}, {["x"] = 2, ["y"] = 1, ["param1"] = 44, ["z"] = 43, ["name"] = "mesecons_lightstone:lightstone_gray_off"}, {["x"] = 2, ["y"] = 1, ["param1"] = 44, ["z"] = 44, ["name"] = "mesecons_lightstone:lightstone_gray_off"}, {["x"] = 2, ["y"] = 1, ["param1"] = 44, ["z"] = 45, ["name"] = "mesecons_lightstone:lightstone_gray_off"}, {["x"] = 2, ["y"] = 1, ["param1"] = 44, ["z"] = 46, ["name"] = "mesecons_lightstone:lightstone_gray_off"}, {["x"] = 2, ["y"] = 1, ["param1"] = 44, ["z"] = 47, ["name"] = "mesecons_lightstone:lightstone_gray_off"}, {["x"] = 2, ["y"] = 1, ["param1"] = 44, ["z"] = 48, ["name"] = "mesecons_lightstone:lightstone_gray_off"}, {["x"] = 2, ["y"] = 1, ["param1"] = 44, ["z"] = 49, ["name"] = "mesecons_lightstone:lightstone_gray_off"}, {["x"] = 2, ["y"] = 1, ["param1"] = 43, ["z"] = 50, ["name"] = "mesecons_lightstone:lightstone_gray_off"}, {["x"] = 2, ["y"] = 1, ["param1"] = 43, ["z"] = 51, ["name"] = "mesecons_lightstone:lightstone_gray_off"}, {["x"] = 2, ["y"] = 1, ["param1"] = 43, ["z"] = 52, ["name"] = "mesecons_lightstone:lightstone_gray_off"}, {["x"] = 2, ["y"] = 1, ["param1"] = 43, ["z"] = 53, ["name"] = "mesecons_lightstone:lightstone_gray_off"}, {["x"] = 2, ["y"] = 1, ["param1"] = 43, ["z"] = 54, ["name"] = "mesecons_lightstone:lightstone_gray_off"}, {["x"] = 2, ["y"] = 1, ["param1"] = 43, ["z"] = 55, ["name"] = "mesecons_lightstone:lightstone_gray_off"}, {["x"] = 2, ["y"] = 2, ["param1"] = 238, ["z"] = 0, ["name"] = "default:meselamp"}, {["x"] = 2, ["y"] = 2, ["param1"] = 238, ["z"] = 1, ["name"] = "default:meselamp"}, {["x"] = 2, ["y"] = 2, ["param1"] = 238, ["z"] = 2, ["name"] = "default:meselamp"}, {["x"] = 2, ["y"] = 2, ["param1"] = 238, ["z"] = 3, ["name"] = "default:meselamp"}, {["x"] = 2, ["y"] = 2, ["param1"] = 238, ["z"] = 4, ["name"] = "default:meselamp"}, {["x"] = 2, ["y"] = 2, ["param1"] = 238, ["z"] = 5, ["name"] = "default:meselamp"}, {["x"] = 2, ["y"] = 2, ["param1"] = 238, ["z"] = 6, ["name"] = "default:meselamp"}, {["x"] = 2, ["y"] = 2, ["param1"] = 238, ["z"] = 7, ["name"] = "default:meselamp"}, {["x"] = 2, ["y"] = 2, ["param1"] = 238, ["z"] = 8, ["name"] = "default:meselamp"}, {["x"] = 2, ["y"] = 2, ["param1"] = 238, ["z"] = 9, ["name"] = "default:meselamp"}, {["x"] = 2, ["y"] = 2, ["param1"] = 238, ["z"] = 10, ["name"] = "default:meselamp"}, {["x"] = 2, ["y"] = 2, ["param1"] = 238, ["z"] = 11, ["name"] = "default:meselamp"}, {["x"] = 2, ["y"] = 2, ["param1"] = 238, ["z"] = 12, ["name"] = "default:meselamp"}, {["x"] = 2, ["y"] = 2, ["param1"] = 238, ["z"] = 13, ["name"] = "default:meselamp"}, {["x"] = 2, ["y"] = 2, ["param1"] = 238, ["z"] = 14, ["name"] = "default:meselamp"}, {["x"] = 2, ["y"] = 2, ["param1"] = 238, ["z"] = 15, ["name"] = "default:meselamp"}, {["x"] = 2, ["y"] = 2, ["param1"] = 238, ["z"] = 16, ["name"] = "default:meselamp"}, {["x"] = 2, ["y"] = 2, ["param1"] = 238, ["z"] = 17, ["name"] = "default:meselamp"}, {["x"] = 2, ["y"] = 2, ["param1"] = 238, ["z"] = 18, ["name"] = "default:meselamp"}, {["x"] = 2, ["y"] = 2, ["param1"] = 238, ["z"] = 19, ["name"] = "default:meselamp"}, {["x"] = 2, ["y"] = 2, ["param1"] = 238, ["z"] = 20, ["name"] = "default:meselamp"}, {["x"] = 2, ["y"] = 2, ["param1"] = 238, ["z"] = 21, ["name"] = "default:meselamp"}, {["x"] = 2, ["y"] = 2, ["param1"] = 238, ["z"] = 22, ["name"] = "default:meselamp"}, {["x"] = 2, ["y"] = 2, ["param1"] = 238, ["z"] = 23, ["name"] = "default:meselamp"}, {["x"] = 2, ["y"] = 2, ["param1"] = 238, ["z"] = 24, ["name"] = "default:meselamp"}, {["x"] = 2, ["y"] = 2, ["param1"] = 238, ["z"] = 25, ["name"] = "default:meselamp"}, {["x"] = 2, ["y"] = 2, ["param1"] = 238, ["z"] = 26, ["name"] = "default:meselamp"}, {["x"] = 2, ["y"] = 2, ["param1"] = 238, ["z"] = 27, ["name"] = "default:meselamp"}, {["x"] = 2, ["y"] = 2, ["param1"] = 238, ["z"] = 28, ["name"] = "default:meselamp"}, {["x"] = 2, ["y"] = 2, ["param1"] = 238, ["z"] = 29, ["name"] = "default:meselamp"}, {["x"] = 2, ["y"] = 2, ["param1"] = 238, ["z"] = 30, ["name"] = "default:meselamp"}, {["x"] = 2, ["y"] = 2, ["param1"] = 238, ["z"] = 31, ["name"] = "default:meselamp"}, {["x"] = 2, ["y"] = 2, ["param1"] = 238, ["z"] = 32, ["name"] = "default:meselamp"}, {["x"] = 2, ["y"] = 2, ["param1"] = 238, ["z"] = 33, ["name"] = "default:meselamp"}, {["x"] = 2, ["y"] = 2, ["param1"] = 238, ["z"] = 34, ["name"] = "default:meselamp"}, {["x"] = 2, ["y"] = 2, ["param1"] = 238, ["z"] = 35, ["name"] = "default:meselamp"}, {["x"] = 2, ["y"] = 2, ["param1"] = 238, ["z"] = 36, ["name"] = "default:meselamp"}, {["x"] = 2, ["y"] = 2, ["param1"] = 238, ["z"] = 37, ["name"] = "default:meselamp"}, {["x"] = 2, ["y"] = 2, ["param1"] = 238, ["z"] = 38, ["name"] = "default:meselamp"}, {["x"] = 2, ["y"] = 2, ["param1"] = 238, ["z"] = 39, ["name"] = "default:meselamp"}, {["x"] = 2, ["y"] = 2, ["param1"] = 238, ["z"] = 40, ["name"] = "default:meselamp"}, {["x"] = 2, ["y"] = 2, ["param1"] = 238, ["z"] = 41, ["name"] = "default:meselamp"}, {["x"] = 2, ["y"] = 2, ["param1"] = 238, ["z"] = 42, ["name"] = "default:meselamp"}, {["x"] = 2, ["y"] = 2, ["param1"] = 238, ["z"] = 43, ["name"] = "default:meselamp"}, {["x"] = 2, ["y"] = 2, ["param1"] = 238, ["z"] = 44, ["name"] = "default:meselamp"}, {["x"] = 2, ["y"] = 2, ["param1"] = 238, ["z"] = 45, ["name"] = "default:meselamp"}, {["x"] = 2, ["y"] = 2, ["param1"] = 238, ["z"] = 46, ["name"] = "default:meselamp"}, {["x"] = 2, ["y"] = 2, ["param1"] = 238, ["z"] = 47, ["name"] = "default:meselamp"}, {["x"] = 2, ["y"] = 2, ["param1"] = 238, ["z"] = 48, ["name"] = "default:meselamp"}, {["x"] = 2, ["y"] = 2, ["param1"] = 238, ["z"] = 49, ["name"] = "default:meselamp"}, {["x"] = 2, ["y"] = 2, ["param1"] = 238, ["z"] = 50, ["name"] = "default:meselamp"}, {["x"] = 2, ["y"] = 2, ["param1"] = 238, ["z"] = 51, ["name"] = "default:meselamp"}, {["x"] = 2, ["y"] = 2, ["param1"] = 238, ["z"] = 52, ["name"] = "default:meselamp"}, {["x"] = 2, ["y"] = 2, ["param1"] = 238, ["z"] = 53, ["name"] = "default:meselamp"}, {["x"] = 2, ["y"] = 2, ["param1"] = 238, ["z"] = 54, ["name"] = "default:meselamp"}, {["x"] = 2, ["y"] = 2, ["param1"] = 238, ["z"] = 55, ["name"] = "default:meselamp"}, {["x"] = 2, ["y"] = 3, ["param1"] = 18, ["z"] = 0, ["name"] = "default:silver_sandstone_block"}, {["x"] = 2, ["y"] = 3, ["param1"] = 18, ["z"] = 1, ["name"] = "default:silver_sandstone_block"}, {["x"] = 2, ["y"] = 3, ["param1"] = 18, ["z"] = 2, ["name"] = "default:silver_sandstone_block"}, {["x"] = 2, ["y"] = 3, ["param1"] = 18, ["z"] = 3, ["name"] = "default:silver_sandstone_block"}, {["x"] = 2, ["y"] = 3, ["param1"] = 18, ["z"] = 4, ["name"] = "default:silver_sandstone_block"}, {["x"] = 2, ["y"] = 3, ["param1"] = 18, ["z"] = 5, ["name"] = "default:silver_sandstone_block"}, {["x"] = 2, ["y"] = 3, ["param1"] = 18, ["z"] = 6, ["name"] = "default:silver_sandstone_block"}, {["x"] = 2, ["y"] = 3, ["param1"] = 18, ["z"] = 7, ["name"] = "default:silver_sandstone_block"}, {["x"] = 2, ["y"] = 3, ["param1"] = 18, ["z"] = 8, ["name"] = "default:silver_sandstone_block"}, {["x"] = 2, ["y"] = 3, ["param1"] = 18, ["z"] = 9, ["name"] = "default:silver_sandstone_block"}, {["x"] = 2, ["y"] = 3, ["param1"] = 18, ["z"] = 10, ["name"] = "default:silver_sandstone_block"}, {["x"] = 2, ["y"] = 3, ["param1"] = 18, ["z"] = 11, ["name"] = "default:silver_sandstone_block"}, {["x"] = 2, ["y"] = 3, ["param1"] = 18, ["z"] = 12, ["name"] = "default:silver_sandstone_block"}, {["x"] = 2, ["y"] = 3, ["param1"] = 18, ["z"] = 13, ["name"] = "default:silver_sandstone_block"}, {["x"] = 2, ["y"] = 3, ["param1"] = 18, ["z"] = 14, ["name"] = "default:silver_sandstone_block"}, {["x"] = 2, ["y"] = 3, ["param1"] = 18, ["z"] = 15, ["name"] = "default:silver_sandstone_block"}, {["x"] = 2, ["y"] = 3, ["param1"] = 18, ["z"] = 16, ["name"] = "default:silver_sandstone_block"}, {["x"] = 2, ["y"] = 3, ["param1"] = 18, ["z"] = 17, ["name"] = "default:silver_sandstone_block"}, {["x"] = 2, ["y"] = 3, ["param1"] = 18, ["z"] = 18, ["name"] = "default:silver_sandstone_block"}, {["x"] = 2, ["y"] = 3, ["param1"] = 18, ["z"] = 19, ["name"] = "default:silver_sandstone_block"}, {["x"] = 2, ["y"] = 3, ["param1"] = 18, ["z"] = 20, ["name"] = "default:silver_sandstone_block"}, {["x"] = 2, ["y"] = 3, ["param1"] = 18, ["z"] = 21, ["name"] = "default:silver_sandstone_block"}, {["x"] = 2, ["y"] = 3, ["param1"] = 18, ["z"] = 22, ["name"] = "default:silver_sandstone_block"}, {["x"] = 2, ["y"] = 3, ["param1"] = 18, ["z"] = 23, ["name"] = "default:silver_sandstone_block"}, {["x"] = 2, ["y"] = 3, ["param1"] = 18, ["z"] = 24, ["name"] = "default:silver_sandstone_block"}, {["x"] = 2, ["y"] = 3, ["param1"] = 18, ["z"] = 25, ["name"] = "default:silver_sandstone_block"}, {["x"] = 2, ["y"] = 3, ["param1"] = 18, ["z"] = 26, ["name"] = "default:silver_sandstone_block"}, {["x"] = 2, ["y"] = 3, ["param1"] = 18, ["z"] = 27, ["name"] = "default:silver_sandstone_block"}, {["x"] = 2, ["y"] = 3, ["param1"] = 18, ["z"] = 28, ["name"] = "default:silver_sandstone_block"}, {["x"] = 2, ["y"] = 3, ["param1"] = 18, ["z"] = 29, ["name"] = "default:silver_sandstone_block"}, {["x"] = 2, ["y"] = 3, ["param1"] = 18, ["z"] = 30, ["name"] = "default:silver_sandstone_block"}, {["x"] = 2, ["y"] = 3, ["param1"] = 18, ["z"] = 31, ["name"] = "default:silver_sandstone_block"}, {["x"] = 2, ["y"] = 3, ["param1"] = 18, ["z"] = 32, ["name"] = "default:silver_sandstone_block"}, {["x"] = 2, ["y"] = 3, ["param1"] = 18, ["z"] = 33, ["name"] = "default:silver_sandstone_block"}, {["x"] = 2, ["y"] = 3, ["param1"] = 18, ["z"] = 34, ["name"] = "default:silver_sandstone_block"}, {["x"] = 2, ["y"] = 3, ["param1"] = 18, ["z"] = 35, ["name"] = "default:silver_sandstone_block"}, {["x"] = 2, ["y"] = 3, ["param1"] = 18, ["z"] = 36, ["name"] = "default:silver_sandstone_block"}, {["x"] = 2, ["y"] = 3, ["param1"] = 18, ["z"] = 37, ["name"] = "default:silver_sandstone_block"}, {["x"] = 2, ["y"] = 3, ["param1"] = 18, ["z"] = 38, ["name"] = "default:silver_sandstone_block"}, {["x"] = 2, ["y"] = 3, ["param1"] = 18, ["z"] = 39, ["name"] = "default:silver_sandstone_block"}, {["x"] = 2, ["y"] = 3, ["param1"] = 18, ["z"] = 40, ["name"] = "default:silver_sandstone_block"}, {["x"] = 2, ["y"] = 3, ["param1"] = 18, ["z"] = 41, ["name"] = "default:silver_sandstone_block"}, {["x"] = 2, ["y"] = 3, ["param1"] = 18, ["z"] = 42, ["name"] = "default:silver_sandstone_block"}, {["x"] = 2, ["y"] = 3, ["param1"] = 18, ["z"] = 43, ["name"] = "default:silver_sandstone_block"}, {["x"] = 2, ["y"] = 3, ["param1"] = 18, ["z"] = 44, ["name"] = "default:silver_sandstone_block"}, {["x"] = 2, ["y"] = 3, ["param1"] = 18, ["z"] = 45, ["name"] = "default:silver_sandstone_block"}, {["x"] = 2, ["y"] = 3, ["param1"] = 18, ["z"] = 46, ["name"] = "default:silver_sandstone_block"}, {["x"] = 2, ["y"] = 3, ["param1"] = 18, ["z"] = 47, ["name"] = "default:silver_sandstone_block"}, {["x"] = 2, ["y"] = 3, ["param1"] = 18, ["z"] = 48, ["name"] = "default:silver_sandstone_block"}, {["x"] = 2, ["y"] = 3, ["param1"] = 18, ["z"] = 49, ["name"] = "default:silver_sandstone_block"}, {["x"] = 2, ["y"] = 3, ["param1"] = 18, ["z"] = 50, ["name"] = "default:silver_sandstone_block"}, {["x"] = 2, ["y"] = 3, ["param1"] = 18, ["z"] = 51, ["name"] = "default:silver_sandstone_block"}, {["x"] = 2, ["y"] = 3, ["param1"] = 18, ["z"] = 52, ["name"] = "default:silver_sandstone_block"}, {["x"] = 2, ["y"] = 3, ["param1"] = 18, ["z"] = 53, ["name"] = "default:silver_sandstone_block"}, {["x"] = 2, ["y"] = 3, ["param1"] = 18, ["z"] = 54, ["name"] = "default:silver_sandstone_block"}, {["x"] = 2, ["y"] = 3, ["param1"] = 18, ["z"] = 55, ["name"] = "default:silver_sandstone_block"}, {["x"] = 2, ["y"] = 4, ["param1"] = 43, ["z"] = 0, ["name"] = "mesecons_lightstone:lightstone_gray_off"}, {["x"] = 2, ["y"] = 4, ["param1"] = 43, ["z"] = 1, ["name"] = "mesecons_lightstone:lightstone_gray_off"}, {["x"] = 2, ["y"] = 4, ["param1"] = 43, ["z"] = 2, ["name"] = "mesecons_lightstone:lightstone_gray_off"}, {["x"] = 2, ["y"] = 4, ["param1"] = 43, ["z"] = 3, ["name"] = "mesecons_lightstone:lightstone_gray_off"}, {["x"] = 2, ["y"] = 4, ["param1"] = 43, ["z"] = 4, ["name"] = "mesecons_lightstone:lightstone_gray_off"}, {["x"] = 2, ["y"] = 4, ["param1"] = 43, ["z"] = 5, ["name"] = "mesecons_lightstone:lightstone_gray_off"}, {["x"] = 2, ["y"] = 4, ["param1"] = 43, ["z"] = 6, ["name"] = "mesecons_lightstone:lightstone_gray_off"}, {["x"] = 2, ["y"] = 4, ["param1"] = 43, ["z"] = 7, ["name"] = "mesecons_lightstone:lightstone_gray_off"}, {["x"] = 2, ["y"] = 4, ["param1"] = 43, ["z"] = 8, ["name"] = "mesecons_lightstone:lightstone_gray_off"}, {["x"] = 2, ["y"] = 4, ["param1"] = 43, ["z"] = 9, ["name"] = "mesecons_lightstone:lightstone_gray_off"}, {["x"] = 2, ["y"] = 4, ["param1"] = 43, ["z"] = 10, ["name"] = "mesecons_lightstone:lightstone_gray_off"}, {["x"] = 2, ["y"] = 4, ["param1"] = 43, ["z"] = 11, ["name"] = "mesecons_lightstone:lightstone_gray_off"}, {["x"] = 2, ["y"] = 4, ["param1"] = 43, ["z"] = 12, ["name"] = "mesecons_lightstone:lightstone_gray_off"}, {["x"] = 2, ["y"] = 4, ["param1"] = 43, ["z"] = 13, ["name"] = "mesecons_lightstone:lightstone_gray_off"}, {["x"] = 2, ["y"] = 4, ["param1"] = 43, ["z"] = 14, ["name"] = "mesecons_lightstone:lightstone_gray_off"}, {["x"] = 2, ["y"] = 4, ["param1"] = 43, ["z"] = 15, ["name"] = "mesecons_lightstone:lightstone_gray_off"}, {["x"] = 2, ["y"] = 4, ["param1"] = 43, ["z"] = 16, ["name"] = "mesecons_lightstone:lightstone_gray_off"}, {["x"] = 2, ["y"] = 4, ["param1"] = 43, ["z"] = 17, ["name"] = "mesecons_lightstone:lightstone_gray_off"}, {["x"] = 2, ["y"] = 4, ["param1"] = 44, ["z"] = 18, ["name"] = "mesecons_lightstone:lightstone_gray_off"}, {["x"] = 2, ["y"] = 4, ["param1"] = 44, ["z"] = 19, ["name"] = "mesecons_lightstone:lightstone_gray_off"}, {["x"] = 2, ["y"] = 4, ["param1"] = 44, ["z"] = 20, ["name"] = "mesecons_lightstone:lightstone_gray_off"}, {["x"] = 2, ["y"] = 4, ["param1"] = 44, ["z"] = 21, ["name"] = "mesecons_lightstone:lightstone_gray_off"}, {["x"] = 2, ["y"] = 4, ["param1"] = 44, ["z"] = 22, ["name"] = "mesecons_lightstone:lightstone_gray_off"}, {["x"] = 2, ["y"] = 4, ["param1"] = 44, ["z"] = 23, ["name"] = "mesecons_lightstone:lightstone_gray_off"}, {["x"] = 2, ["y"] = 4, ["param1"] = 44, ["z"] = 24, ["name"] = "mesecons_lightstone:lightstone_gray_off"}, {["x"] = 2, ["y"] = 4, ["param1"] = 44, ["z"] = 25, ["name"] = "mesecons_lightstone:lightstone_gray_off"}, {["x"] = 2, ["y"] = 4, ["param1"] = 44, ["z"] = 26, ["name"] = "mesecons_lightstone:lightstone_gray_off"}, {["x"] = 2, ["y"] = 4, ["param1"] = 44, ["z"] = 27, ["name"] = "mesecons_lightstone:lightstone_gray_off"}, {["x"] = 2, ["y"] = 4, ["param1"] = 44, ["z"] = 28, ["name"] = "mesecons_lightstone:lightstone_gray_off"}, {["x"] = 2, ["y"] = 4, ["param1"] = 44, ["z"] = 29, ["name"] = "mesecons_lightstone:lightstone_gray_off"}, {["x"] = 2, ["y"] = 4, ["param1"] = 44, ["z"] = 30, ["name"] = "mesecons_lightstone:lightstone_gray_off"}, {["x"] = 2, ["y"] = 4, ["param1"] = 44, ["z"] = 31, ["name"] = "mesecons_lightstone:lightstone_gray_off"}, {["x"] = 2, ["y"] = 4, ["param1"] = 44, ["z"] = 32, ["name"] = "mesecons_lightstone:lightstone_gray_off"}, {["x"] = 2, ["y"] = 4, ["param1"] = 44, ["z"] = 33, ["name"] = "mesecons_lightstone:lightstone_gray_off"}, {["x"] = 2, ["y"] = 4, ["param1"] = 44, ["z"] = 34, ["name"] = "mesecons_lightstone:lightstone_gray_off"}, {["x"] = 2, ["y"] = 4, ["param1"] = 44, ["z"] = 35, ["name"] = "mesecons_lightstone:lightstone_gray_off"}, {["x"] = 2, ["y"] = 4, ["param1"] = 44, ["z"] = 36, ["name"] = "mesecons_lightstone:lightstone_gray_off"}, {["x"] = 2, ["y"] = 4, ["param1"] = 44, ["z"] = 37, ["name"] = "mesecons_lightstone:lightstone_gray_off"}, {["x"] = 2, ["y"] = 4, ["param1"] = 44, ["z"] = 38, ["name"] = "mesecons_lightstone:lightstone_gray_off"}, {["x"] = 2, ["y"] = 4, ["param1"] = 44, ["z"] = 39, ["name"] = "mesecons_lightstone:lightstone_gray_off"}, {["x"] = 2, ["y"] = 4, ["param1"] = 44, ["z"] = 40, ["name"] = "mesecons_lightstone:lightstone_gray_off"}, {["x"] = 2, ["y"] = 4, ["param1"] = 44, ["z"] = 41, ["name"] = "mesecons_lightstone:lightstone_gray_off"}, {["x"] = 2, ["y"] = 4, ["param1"] = 44, ["z"] = 42, ["name"] = "mesecons_lightstone:lightstone_gray_off"}, {["x"] = 2, ["y"] = 4, ["param1"] = 44, ["z"] = 43, ["name"] = "mesecons_lightstone:lightstone_gray_off"}, {["x"] = 2, ["y"] = 4, ["param1"] = 44, ["z"] = 44, ["name"] = "mesecons_lightstone:lightstone_gray_off"}, {["x"] = 2, ["y"] = 4, ["param1"] = 44, ["z"] = 45, ["name"] = "mesecons_lightstone:lightstone_gray_off"}, {["x"] = 2, ["y"] = 4, ["param1"] = 44, ["z"] = 46, ["name"] = "mesecons_lightstone:lightstone_gray_off"}, {["x"] = 2, ["y"] = 4, ["param1"] = 44, ["z"] = 47, ["name"] = "mesecons_lightstone:lightstone_gray_off"}, {["x"] = 2, ["y"] = 4, ["param1"] = 44, ["z"] = 48, ["name"] = "mesecons_lightstone:lightstone_gray_off"}, {["x"] = 2, ["y"] = 4, ["param1"] = 44, ["z"] = 49, ["name"] = "mesecons_lightstone:lightstone_gray_off"}, {["x"] = 2, ["y"] = 4, ["param1"] = 43, ["z"] = 50, ["name"] = "mesecons_lightstone:lightstone_gray_off"}, {["x"] = 2, ["y"] = 4, ["param1"] = 43, ["z"] = 51, ["name"] = "mesecons_lightstone:lightstone_gray_off"}, {["x"] = 2, ["y"] = 4, ["param1"] = 43, ["z"] = 52, ["name"] = "mesecons_lightstone:lightstone_gray_off"}, {["x"] = 2, ["y"] = 4, ["param1"] = 43, ["z"] = 53, ["name"] = "mesecons_lightstone:lightstone_gray_off"}, {["x"] = 2, ["y"] = 4, ["param1"] = 43, ["z"] = 54, ["name"] = "mesecons_lightstone:lightstone_gray_off"}, {["x"] = 2, ["y"] = 4, ["param1"] = 43, ["z"] = 55, ["name"] = "mesecons_lightstone:lightstone_gray_off"}, {["x"] = 3, ["y"] = 0, ["param1"] = 238, ["z"] = 0, ["name"] = "default:meselamp"}, {["x"] = 3, ["y"] = 0, ["param1"] = 43, ["z"] = 1, ["name"] = "mesecons_lightstone:lightstone_gray_off"}, {["x"] = 3, ["y"] = 0, ["param1"] = 43, ["z"] = 2, ["name"] = "mesecons_lightstone:lightstone_gray_off"}, {["x"] = 3, ["y"] = 0, ["param1"] = 43, ["z"] = 3, ["name"] = "mesecons_lightstone:lightstone_gray_off"}, {["x"] = 3, ["y"] = 0, ["param1"] = 43, ["z"] = 4, ["name"] = "mesecons_lightstone:lightstone_gray_off"}, {["x"] = 3, ["y"] = 0, ["param1"] = 43, ["z"] = 5, ["name"] = "mesecons_lightstone:lightstone_gray_off"}, {["x"] = 3, ["y"] = 0, ["param1"] = 43, ["z"] = 6, ["name"] = "mesecons_lightstone:lightstone_gray_off"}, {["x"] = 3, ["y"] = 0, ["param1"] = 43, ["z"] = 7, ["name"] = "mesecons_lightstone:lightstone_gray_off"}, {["x"] = 3, ["y"] = 0, ["param1"] = 43, ["z"] = 8, ["name"] = "mesecons_lightstone:lightstone_gray_off"}, {["x"] = 3, ["y"] = 0, ["param1"] = 43, ["z"] = 9, ["name"] = "mesecons_lightstone:lightstone_gray_off"}, {["x"] = 3, ["y"] = 0, ["param1"] = 43, ["z"] = 10, ["name"] = "mesecons_lightstone:lightstone_gray_off"}, {["x"] = 3, ["y"] = 0, ["param1"] = 43, ["z"] = 11, ["name"] = "mesecons_lightstone:lightstone_gray_off"}, {["x"] = 3, ["y"] = 0, ["param1"] = 43, ["z"] = 12, ["name"] = "mesecons_lightstone:lightstone_gray_off"}, {["x"] = 3, ["y"] = 0, ["param1"] = 43, ["z"] = 13, ["name"] = "mesecons_lightstone:lightstone_gray_off"}, {["x"] = 3, ["y"] = 0, ["param1"] = 43, ["z"] = 14, ["name"] = "mesecons_lightstone:lightstone_gray_off"}, {["x"] = 3, ["y"] = 0, ["param1"] = 43, ["z"] = 15, ["name"] = "mesecons_lightstone:lightstone_gray_off"}, {["x"] = 3, ["y"] = 0, ["param1"] = 43, ["z"] = 16, ["name"] = "mesecons_lightstone:lightstone_gray_off"}, {["x"] = 3, ["y"] = 0, ["param1"] = 43, ["z"] = 17, ["name"] = "mesecons_lightstone:lightstone_gray_off"}, {["x"] = 3, ["y"] = 0, ["param1"] = 44, ["z"] = 18, ["name"] = "mesecons_lightstone:lightstone_gray_off"}, {["x"] = 3, ["y"] = 0, ["param1"] = 44, ["z"] = 19, ["name"] = "mesecons_lightstone:lightstone_gray_off"}, {["x"] = 3, ["y"] = 0, ["param1"] = 44, ["z"] = 20, ["name"] = "mesecons_lightstone:lightstone_gray_off"}, {["x"] = 3, ["y"] = 0, ["param1"] = 44, ["z"] = 21, ["name"] = "mesecons_lightstone:lightstone_gray_off"}, {["x"] = 3, ["y"] = 0, ["param1"] = 44, ["z"] = 22, ["name"] = "mesecons_lightstone:lightstone_gray_off"}, {["x"] = 3, ["y"] = 0, ["param1"] = 44, ["z"] = 23, ["name"] = "mesecons_lightstone:lightstone_gray_off"}, {["x"] = 3, ["y"] = 0, ["param1"] = 44, ["z"] = 24, ["name"] = "mesecons_lightstone:lightstone_gray_off"}, {["x"] = 3, ["y"] = 0, ["param1"] = 44, ["z"] = 25, ["name"] = "mesecons_lightstone:lightstone_gray_off"}, {["x"] = 3, ["y"] = 0, ["param1"] = 44, ["z"] = 26, ["name"] = "mesecons_lightstone:lightstone_gray_off"}, {["x"] = 3, ["y"] = 0, ["param1"] = 44, ["z"] = 27, ["name"] = "mesecons_lightstone:lightstone_gray_off"}, {["x"] = 3, ["y"] = 0, ["param1"] = 44, ["z"] = 28, ["name"] = "mesecons_lightstone:lightstone_gray_off"}, {["x"] = 3, ["y"] = 0, ["param1"] = 44, ["z"] = 29, ["name"] = "mesecons_lightstone:lightstone_gray_off"}, {["x"] = 3, ["y"] = 0, ["param1"] = 44, ["z"] = 30, ["name"] = "mesecons_lightstone:lightstone_gray_off"}, {["x"] = 3, ["y"] = 0, ["param1"] = 44, ["z"] = 31, ["name"] = "mesecons_lightstone:lightstone_gray_off"}, {["x"] = 3, ["y"] = 0, ["param1"] = 44, ["z"] = 32, ["name"] = "mesecons_lightstone:lightstone_gray_off"}, {["x"] = 3, ["y"] = 0, ["param1"] = 44, ["z"] = 33, ["name"] = "mesecons_lightstone:lightstone_gray_off"}, {["x"] = 3, ["y"] = 0, ["param1"] = 44, ["z"] = 34, ["name"] = "mesecons_lightstone:lightstone_gray_off"}, {["x"] = 3, ["y"] = 0, ["param1"] = 44, ["z"] = 35, ["name"] = "mesecons_lightstone:lightstone_gray_off"}, {["x"] = 3, ["y"] = 0, ["param1"] = 44, ["z"] = 36, ["name"] = "mesecons_lightstone:lightstone_gray_off"}, {["x"] = 3, ["y"] = 0, ["param1"] = 44, ["z"] = 37, ["name"] = "mesecons_lightstone:lightstone_gray_off"}, {["x"] = 3, ["y"] = 0, ["param1"] = 44, ["z"] = 38, ["name"] = "mesecons_lightstone:lightstone_gray_off"}, {["x"] = 3, ["y"] = 0, ["param1"] = 44, ["z"] = 39, ["name"] = "mesecons_lightstone:lightstone_gray_off"}, {["x"] = 3, ["y"] = 0, ["param1"] = 44, ["z"] = 40, ["name"] = "mesecons_lightstone:lightstone_gray_off"}, {["x"] = 3, ["y"] = 0, ["param1"] = 44, ["z"] = 41, ["name"] = "mesecons_lightstone:lightstone_gray_off"}, {["x"] = 3, ["y"] = 0, ["param1"] = 44, ["z"] = 42, ["name"] = "mesecons_lightstone:lightstone_gray_off"}, {["x"] = 3, ["y"] = 0, ["param1"] = 44, ["z"] = 43, ["name"] = "mesecons_lightstone:lightstone_gray_off"}, {["x"] = 3, ["y"] = 0, ["param1"] = 44, ["z"] = 44, ["name"] = "mesecons_lightstone:lightstone_gray_off"}, {["x"] = 3, ["y"] = 0, ["param1"] = 44, ["z"] = 45, ["name"] = "mesecons_lightstone:lightstone_gray_off"}, {["x"] = 3, ["y"] = 0, ["param1"] = 44, ["z"] = 46, ["name"] = "mesecons_lightstone:lightstone_gray_off"}, {["x"] = 3, ["y"] = 0, ["param1"] = 44, ["z"] = 47, ["name"] = "mesecons_lightstone:lightstone_gray_off"}, {["x"] = 3, ["y"] = 0, ["param1"] = 44, ["z"] = 48, ["name"] = "mesecons_lightstone:lightstone_gray_off"}, {["x"] = 3, ["y"] = 0, ["param1"] = 44, ["z"] = 49, ["name"] = "mesecons_lightstone:lightstone_gray_off"}, {["x"] = 3, ["y"] = 0, ["param1"] = 43, ["z"] = 50, ["name"] = "mesecons_lightstone:lightstone_gray_off"}, {["x"] = 3, ["y"] = 0, ["param1"] = 43, ["z"] = 51, ["name"] = "mesecons_lightstone:lightstone_gray_off"}, {["x"] = 3, ["y"] = 0, ["param1"] = 43, ["z"] = 52, ["name"] = "mesecons_lightstone:lightstone_gray_off"}, {["x"] = 3, ["y"] = 0, ["param1"] = 43, ["z"] = 53, ["name"] = "mesecons_lightstone:lightstone_gray_off"}, {["x"] = 3, ["y"] = 0, ["param1"] = 43, ["z"] = 54, ["name"] = "mesecons_lightstone:lightstone_gray_off"}, {["x"] = 3, ["y"] = 0, ["param1"] = 238, ["z"] = 55, ["name"] = "default:meselamp"}, {["x"] = 3, ["y"] = 1, ["param1"] = 43, ["z"] = 0, ["name"] = "mesecons_lightstone:lightstone_gray_off"}, {["x"] = 3, ["y"] = 1, ["param1"] = 43, ["z"] = 1, ["name"] = "mesecons_lightstone:lightstone_gray_off"}, {["x"] = 3, ["y"] = 1, ["param1"] = 43, ["z"] = 2, ["name"] = "mesecons_lightstone:lightstone_gray_off"}, {["x"] = 3, ["y"] = 1, ["param1"] = 43, ["z"] = 3, ["name"] = "mesecons_lightstone:lightstone_gray_off"}, {["x"] = 3, ["y"] = 1, ["param1"] = 43, ["z"] = 4, ["name"] = "mesecons_lightstone:lightstone_gray_off"}, {["x"] = 3, ["y"] = 1, ["param1"] = 43, ["z"] = 5, ["name"] = "mesecons_lightstone:lightstone_gray_off"}, {["x"] = 3, ["y"] = 1, ["param1"] = 43, ["z"] = 6, ["name"] = "mesecons_lightstone:lightstone_gray_off"}, {["x"] = 3, ["y"] = 1, ["param1"] = 43, ["z"] = 7, ["name"] = "mesecons_lightstone:lightstone_gray_off"}, {["x"] = 3, ["y"] = 1, ["param1"] = 43, ["z"] = 8, ["name"] = "mesecons_lightstone:lightstone_gray_off"}, {["x"] = 3, ["y"] = 1, ["param1"] = 43, ["z"] = 9, ["name"] = "mesecons_lightstone:lightstone_gray_off"}, {["x"] = 3, ["y"] = 1, ["param1"] = 43, ["z"] = 10, ["name"] = "mesecons_lightstone:lightstone_gray_off"}, {["x"] = 3, ["y"] = 1, ["param1"] = 43, ["z"] = 11, ["name"] = "mesecons_lightstone:lightstone_gray_off"}, {["x"] = 3, ["y"] = 1, ["param1"] = 43, ["z"] = 12, ["name"] = "mesecons_lightstone:lightstone_gray_off"}, {["x"] = 3, ["y"] = 1, ["param1"] = 43, ["z"] = 13, ["name"] = "mesecons_lightstone:lightstone_gray_off"}, {["x"] = 3, ["y"] = 1, ["param1"] = 43, ["z"] = 14, ["name"] = "mesecons_lightstone:lightstone_gray_off"}, {["x"] = 3, ["y"] = 1, ["param1"] = 43, ["z"] = 15, ["name"] = "mesecons_lightstone:lightstone_gray_off"}, {["x"] = 3, ["y"] = 1, ["param1"] = 43, ["z"] = 16, ["name"] = "mesecons_lightstone:lightstone_gray_off"}, {["x"] = 3, ["y"] = 1, ["param1"] = 43, ["z"] = 17, ["name"] = "mesecons_lightstone:lightstone_gray_off"}, {["x"] = 3, ["y"] = 1, ["param1"] = 44, ["z"] = 18, ["name"] = "mesecons_lightstone:lightstone_gray_off"}, {["x"] = 3, ["y"] = 1, ["param1"] = 44, ["z"] = 19, ["name"] = "mesecons_lightstone:lightstone_gray_off"}, {["x"] = 3, ["y"] = 1, ["param1"] = 44, ["z"] = 20, ["name"] = "mesecons_lightstone:lightstone_gray_off"}, {["x"] = 3, ["y"] = 1, ["param1"] = 44, ["z"] = 21, ["name"] = "mesecons_lightstone:lightstone_gray_off"}, {["x"] = 3, ["y"] = 1, ["param1"] = 44, ["z"] = 22, ["name"] = "mesecons_lightstone:lightstone_gray_off"}, {["x"] = 3, ["y"] = 1, ["param1"] = 44, ["z"] = 23, ["name"] = "mesecons_lightstone:lightstone_gray_off"}, {["x"] = 3, ["y"] = 1, ["param1"] = 44, ["z"] = 24, ["name"] = "mesecons_lightstone:lightstone_gray_off"}, {["x"] = 3, ["y"] = 1, ["param1"] = 44, ["z"] = 25, ["name"] = "mesecons_lightstone:lightstone_gray_off"}, {["x"] = 3, ["y"] = 1, ["param1"] = 44, ["z"] = 26, ["name"] = "mesecons_lightstone:lightstone_gray_off"}, {["x"] = 3, ["y"] = 1, ["param1"] = 44, ["z"] = 27, ["name"] = "mesecons_lightstone:lightstone_gray_off"}, {["x"] = 3, ["y"] = 1, ["param1"] = 44, ["z"] = 28, ["name"] = "mesecons_lightstone:lightstone_gray_off"}, {["x"] = 3, ["y"] = 1, ["param1"] = 44, ["z"] = 29, ["name"] = "mesecons_lightstone:lightstone_gray_off"}, {["x"] = 3, ["y"] = 1, ["param1"] = 44, ["z"] = 30, ["name"] = "mesecons_lightstone:lightstone_gray_off"}, {["x"] = 3, ["y"] = 1, ["param1"] = 44, ["z"] = 31, ["name"] = "mesecons_lightstone:lightstone_gray_off"}, {["x"] = 3, ["y"] = 1, ["param1"] = 44, ["z"] = 32, ["name"] = "mesecons_lightstone:lightstone_gray_off"}, {["x"] = 3, ["y"] = 1, ["param1"] = 44, ["z"] = 33, ["name"] = "mesecons_lightstone:lightstone_gray_off"}, {["x"] = 3, ["y"] = 1, ["param1"] = 44, ["z"] = 34, ["name"] = "mesecons_lightstone:lightstone_gray_off"}, {["x"] = 3, ["y"] = 1, ["param1"] = 44, ["z"] = 35, ["name"] = "mesecons_lightstone:lightstone_gray_off"}, {["x"] = 3, ["y"] = 1, ["param1"] = 44, ["z"] = 36, ["name"] = "mesecons_lightstone:lightstone_gray_off"}, {["x"] = 3, ["y"] = 1, ["param1"] = 44, ["z"] = 37, ["name"] = "mesecons_lightstone:lightstone_gray_off"}, {["x"] = 3, ["y"] = 1, ["param1"] = 44, ["z"] = 38, ["name"] = "mesecons_lightstone:lightstone_gray_off"}, {["x"] = 3, ["y"] = 1, ["param1"] = 44, ["z"] = 39, ["name"] = "mesecons_lightstone:lightstone_gray_off"}, {["x"] = 3, ["y"] = 1, ["param1"] = 44, ["z"] = 40, ["name"] = "mesecons_lightstone:lightstone_gray_off"}, {["x"] = 3, ["y"] = 1, ["param1"] = 44, ["z"] = 41, ["name"] = "mesecons_lightstone:lightstone_gray_off"}, {["x"] = 3, ["y"] = 1, ["param1"] = 44, ["z"] = 42, ["name"] = "mesecons_lightstone:lightstone_gray_off"}, {["x"] = 3, ["y"] = 1, ["param1"] = 44, ["z"] = 43, ["name"] = "mesecons_lightstone:lightstone_gray_off"}, {["x"] = 3, ["y"] = 1, ["param1"] = 44, ["z"] = 44, ["name"] = "mesecons_lightstone:lightstone_gray_off"}, {["x"] = 3, ["y"] = 1, ["param1"] = 44, ["z"] = 45, ["name"] = "mesecons_lightstone:lightstone_gray_off"}, {["x"] = 3, ["y"] = 1, ["param1"] = 44, ["z"] = 46, ["name"] = "mesecons_lightstone:lightstone_gray_off"}, {["x"] = 3, ["y"] = 1, ["param1"] = 44, ["z"] = 47, ["name"] = "mesecons_lightstone:lightstone_gray_off"}, {["x"] = 3, ["y"] = 1, ["param1"] = 44, ["z"] = 48, ["name"] = "mesecons_lightstone:lightstone_gray_off"}, {["x"] = 3, ["y"] = 1, ["param1"] = 44, ["z"] = 49, ["name"] = "mesecons_lightstone:lightstone_gray_off"}, {["x"] = 3, ["y"] = 1, ["param1"] = 43, ["z"] = 50, ["name"] = "mesecons_lightstone:lightstone_gray_off"}, {["x"] = 3, ["y"] = 1, ["param1"] = 43, ["z"] = 51, ["name"] = "mesecons_lightstone:lightstone_gray_off"}, {["x"] = 3, ["y"] = 1, ["param1"] = 43, ["z"] = 52, ["name"] = "mesecons_lightstone:lightstone_gray_off"}, {["x"] = 3, ["y"] = 1, ["param1"] = 43, ["z"] = 53, ["name"] = "mesecons_lightstone:lightstone_gray_off"}, {["x"] = 3, ["y"] = 1, ["param1"] = 43, ["z"] = 54, ["name"] = "mesecons_lightstone:lightstone_gray_off"}, {["x"] = 3, ["y"] = 1, ["param1"] = 43, ["z"] = 55, ["name"] = "mesecons_lightstone:lightstone_gray_off"}, {["x"] = 3, ["y"] = 2, ["param1"] = 238, ["z"] = 0, ["name"] = "default:meselamp"}, {["x"] = 3, ["y"] = 2, ["param1"] = 238, ["z"] = 1, ["name"] = "default:meselamp"}, {["x"] = 3, ["y"] = 2, ["param1"] = 238, ["z"] = 2, ["name"] = "default:meselamp"}, {["x"] = 3, ["y"] = 2, ["param1"] = 238, ["z"] = 3, ["name"] = "default:meselamp"}, {["x"] = 3, ["y"] = 2, ["param1"] = 238, ["z"] = 4, ["name"] = "default:meselamp"}, {["x"] = 3, ["y"] = 2, ["param1"] = 238, ["z"] = 5, ["name"] = "default:meselamp"}, {["x"] = 3, ["y"] = 2, ["param1"] = 238, ["z"] = 6, ["name"] = "default:meselamp"}, {["x"] = 3, ["y"] = 2, ["param1"] = 238, ["z"] = 7, ["name"] = "default:meselamp"}, {["x"] = 3, ["y"] = 2, ["param1"] = 238, ["z"] = 8, ["name"] = "default:meselamp"}, {["x"] = 3, ["y"] = 2, ["param1"] = 238, ["z"] = 9, ["name"] = "default:meselamp"}, {["x"] = 3, ["y"] = 2, ["param1"] = 238, ["z"] = 10, ["name"] = "default:meselamp"}, {["x"] = 3, ["y"] = 2, ["param1"] = 238, ["z"] = 11, ["name"] = "default:meselamp"}, {["x"] = 3, ["y"] = 2, ["param1"] = 238, ["z"] = 12, ["name"] = "default:meselamp"}, {["x"] = 3, ["y"] = 2, ["param1"] = 238, ["z"] = 13, ["name"] = "default:meselamp"}, {["x"] = 3, ["y"] = 2, ["param1"] = 238, ["z"] = 14, ["name"] = "default:meselamp"}, {["x"] = 3, ["y"] = 2, ["param1"] = 238, ["z"] = 15, ["name"] = "default:meselamp"}, {["x"] = 3, ["y"] = 2, ["param1"] = 238, ["z"] = 16, ["name"] = "default:meselamp"}, {["x"] = 3, ["y"] = 2, ["param1"] = 238, ["z"] = 17, ["name"] = "default:meselamp"}, {["x"] = 3, ["y"] = 2, ["param1"] = 238, ["z"] = 18, ["name"] = "default:meselamp"}, {["x"] = 3, ["y"] = 2, ["param1"] = 238, ["z"] = 19, ["name"] = "default:meselamp"}, {["x"] = 3, ["y"] = 2, ["param1"] = 238, ["z"] = 20, ["name"] = "default:meselamp"}, {["x"] = 3, ["y"] = 2, ["param1"] = 238, ["z"] = 21, ["name"] = "default:meselamp"}, {["x"] = 3, ["y"] = 2, ["param1"] = 238, ["z"] = 22, ["name"] = "default:meselamp"}, {["x"] = 3, ["y"] = 2, ["param1"] = 238, ["z"] = 23, ["name"] = "default:meselamp"}, {["x"] = 3, ["y"] = 2, ["param1"] = 238, ["z"] = 24, ["name"] = "default:meselamp"}, {["x"] = 3, ["y"] = 2, ["param1"] = 238, ["z"] = 25, ["name"] = "default:meselamp"}, {["x"] = 3, ["y"] = 2, ["param1"] = 238, ["z"] = 26, ["name"] = "default:meselamp"}, {["x"] = 3, ["y"] = 2, ["param1"] = 238, ["z"] = 27, ["name"] = "default:meselamp"}, {["x"] = 3, ["y"] = 2, ["param1"] = 238, ["z"] = 28, ["name"] = "default:meselamp"}, {["x"] = 3, ["y"] = 2, ["param1"] = 238, ["z"] = 29, ["name"] = "default:meselamp"}, {["x"] = 3, ["y"] = 2, ["param1"] = 238, ["z"] = 30, ["name"] = "default:meselamp"}, {["x"] = 3, ["y"] = 2, ["param1"] = 238, ["z"] = 31, ["name"] = "default:meselamp"}, {["x"] = 3, ["y"] = 2, ["param1"] = 238, ["z"] = 32, ["name"] = "default:meselamp"}, {["x"] = 3, ["y"] = 2, ["param1"] = 238, ["z"] = 33, ["name"] = "default:meselamp"}, {["x"] = 3, ["y"] = 2, ["param1"] = 238, ["z"] = 34, ["name"] = "default:meselamp"}, {["x"] = 3, ["y"] = 2, ["param1"] = 238, ["z"] = 35, ["name"] = "default:meselamp"}, {["x"] = 3, ["y"] = 2, ["param1"] = 238, ["z"] = 36, ["name"] = "default:meselamp"}, {["x"] = 3, ["y"] = 2, ["param1"] = 238, ["z"] = 37, ["name"] = "default:meselamp"}, {["x"] = 3, ["y"] = 2, ["param1"] = 238, ["z"] = 38, ["name"] = "default:meselamp"}, {["x"] = 3, ["y"] = 2, ["param1"] = 238, ["z"] = 39, ["name"] = "default:meselamp"}, {["x"] = 3, ["y"] = 2, ["param1"] = 238, ["z"] = 40, ["name"] = "default:meselamp"}, {["x"] = 3, ["y"] = 2, ["param1"] = 238, ["z"] = 41, ["name"] = "default:meselamp"}, {["x"] = 3, ["y"] = 2, ["param1"] = 238, ["z"] = 42, ["name"] = "default:meselamp"}, {["x"] = 3, ["y"] = 2, ["param1"] = 238, ["z"] = 43, ["name"] = "default:meselamp"}, {["x"] = 3, ["y"] = 2, ["param1"] = 238, ["z"] = 44, ["name"] = "default:meselamp"}, {["x"] = 3, ["y"] = 2, ["param1"] = 238, ["z"] = 45, ["name"] = "default:meselamp"}, {["x"] = 3, ["y"] = 2, ["param1"] = 238, ["z"] = 46, ["name"] = "default:meselamp"}, {["x"] = 3, ["y"] = 2, ["param1"] = 238, ["z"] = 47, ["name"] = "default:meselamp"}, {["x"] = 3, ["y"] = 2, ["param1"] = 238, ["z"] = 48, ["name"] = "default:meselamp"}, {["x"] = 3, ["y"] = 2, ["param1"] = 238, ["z"] = 49, ["name"] = "default:meselamp"}, {["x"] = 3, ["y"] = 2, ["param1"] = 238, ["z"] = 50, ["name"] = "default:meselamp"}, {["x"] = 3, ["y"] = 2, ["param1"] = 238, ["z"] = 51, ["name"] = "default:meselamp"}, {["x"] = 3, ["y"] = 2, ["param1"] = 238, ["z"] = 52, ["name"] = "default:meselamp"}, {["x"] = 3, ["y"] = 2, ["param1"] = 238, ["z"] = 53, ["name"] = "default:meselamp"}, {["x"] = 3, ["y"] = 2, ["param1"] = 238, ["z"] = 54, ["name"] = "default:meselamp"}, {["x"] = 3, ["y"] = 2, ["param1"] = 238, ["z"] = 55, ["name"] = "default:meselamp"}, {["x"] = 3, ["y"] = 3, ["param1"] = 18, ["z"] = 0, ["name"] = "default:silver_sandstone_block"},