5:return {{["x"] = 0, ["y"] = 0, ["param1"] = 15, ["z"] = 0, ["name"] = "default:desert_sandstone_block"}, {["x"] = 0, ["y"] = 0, ["param1"] = 15, ["z"] = 1, ["name"] = "default:desert_sandstone_block"}, {["x"] = 0, ["y"] = 0, ["param1"] = 15, ["z"] = 2, ["name"] = "default:desert_sandstone_block"}, {["x"] = 0, ["y"] = 0, ["param1"] = 15, ["z"] = 3, ["name"] = "default:desert_sandstone_block"}, {["x"] = 0, ["y"] = 0, ["param1"] = 15, ["z"] = 4, ["name"] = "default:desert_sandstone_block"}, {["x"] = 0, ["y"] = 0, ["param1"] = 15, ["z"] = 5, ["name"] = "default:desert_sandstone_block"}, {["x"] = 0, ["y"] = 0, ["param1"] = 15, ["z"] = 6, ["name"] = "default:desert_sandstone_block"}, {["x"] = 0, ["y"] = 0, ["param1"] = 15, ["z"] = 7, ["name"] = "default:desert_sandstone_block"}, {["x"] = 0, ["y"] = 0, ["param1"] = 15, ["z"] = 8, ["name"] = "default:desert_sandstone_block"}, {["x"] = 0, ["y"] = 0, ["param1"] = 15, ["z"] = 9, ["name"] = "default:desert_sandstone_block"}, {["x"] = 0, ["y"] = 0, ["param1"] = 15, ["z"] = 10, ["name"] = "default:desert_sandstone_block"}, {["x"] = 0, ["y"] = 0, ["param1"] = 15, ["z"] = 11, ["name"] = "default:desert_sandstone_block"}, {["x"] = 0, ["y"] = 0, ["param1"] = 15, ["z"] = 12, ["name"] = "default:desert_sandstone_block"}, {["x"] = 0, ["y"] = 0, ["param1"] = 15, ["z"] = 13, ["name"] = "default:desert_sandstone_block"}, {["x"] = 0, ["y"] = 0, ["param1"] = 15, ["z"] = 14, ["name"] = "default:desert_sandstone_block"}, {["x"] = 0, ["y"] = 0, ["param1"] = 15, ["z"] = 15, ["name"] = "default:desert_sandstone_block"}, {["x"] = 0, ["y"] = 0, ["param1"] = 15, ["z"] = 16, ["name"] = "default:desert_sandstone_block"}, {["x"] = 0, ["y"] = 0, ["param1"] = 31, ["z"] = 17, ["name"] = "default:desert_sandstone_block"}, {["x"] = 0, ["y"] = 0, ["param1"] = 47, ["z"] = 18, ["name"] = "default:desert_sandstone_block"}, {["x"] = 0, ["y"] = 0, ["param1"] = 63, ["z"] = 19, ["name"] = "default:desert_sandstone_block"}, {["x"] = 0, ["y"] = 0, ["param1"] = 47, ["z"] = 20, ["name"] = "default:desert_sandstone_block"}, {["x"] = 0, ["y"] = 0, ["param1"] = 31, ["z"] = 21, ["name"] = "default:desert_sandstone_block"}, {["x"] = 0, ["y"] = 0, ["param1"] = 15, ["z"] = 22, ["name"] = "default:desert_sandstone_block"}, {["x"] = 1, ["y"] = 0, ["param1"] = 15, ["z"] = 0, ["name"] = "default:desert_sandstone_block"}, {["x"] = 1, ["y"] = 0, ["param1"] = 15, ["z"] = 1, ["name"] = "default:silver_sandstone_block"}, {["x"] = 1, ["y"] = 0, ["param1"] = 15, ["z"] = 2, ["name"] = "default:silver_sandstone_block"}, {["x"] = 1, ["y"] = 0, ["param1"] = 15, ["z"] = 3, ["name"] = "default:silver_sandstone_block"}, {["x"] = 1, ["y"] = 0, ["param1"] = 15, ["z"] = 4, ["name"] = "default:silver_sandstone_block"}, {["x"] = 1, ["y"] = 0, ["param1"] = 15, ["z"] = 5, ["name"] = "default:silver_sandstone_block"}, {["x"] = 1, ["y"] = 0, ["param1"] = 15, ["z"] = 6, ["name"] = "default:silver_sandstone_block"}, {["x"] = 1, ["y"] = 0, ["param1"] = 15, ["z"] = 7, ["name"] = "default:silver_sandstone_block"}, {["x"] = 1, ["y"] = 0, ["param1"] = 15, ["z"] = 8, ["name"] = "default:silver_sandstone_block"}, {["x"] = 1, ["y"] = 0, ["param1"] = 15, ["z"] = 9, ["name"] = "default:silver_sandstone_block"}, {["x"] = 1, ["y"] = 0, ["param1"] = 15, ["z"] = 10, ["name"] = "default:silver_sandstone_block"}, {["x"] = 1, ["y"] = 0, ["param1"] = 15, ["z"] = 11, ["name"] = "default:silver_sandstone_block"}, {["x"] = 1, ["y"] = 0, ["param1"] = 15, ["z"] = 12, ["name"] = "default:silver_sandstone_block"}, {["x"] = 1, ["y"] = 0, ["param1"] = 15, ["z"] = 13, ["name"] = "default:silver_sandstone_block"}, {["x"] = 1, ["y"] = 0, ["param1"] = 15, ["z"] = 14, ["name"] = "default:silver_sandstone_block"}, {["x"] = 1, ["y"] = 0, ["param1"] = 15, ["z"] = 15, ["name"] = "default:silver_sandstone_block"}, {["x"] = 1, ["y"] = 0, ["param1"] = 15, ["z"] = 16, ["name"] = "default:silver_sandstone_block"}, {["x"] = 1, ["y"] = 0, ["param1"] = 15, ["z"] = 17, ["name"] = "default:silver_sandstone_block"}, {["x"] = 1, ["y"] = 0, ["param1"] = 15, ["z"] = 18, ["name"] = "default:silver_sandstone_block"}, {["x"] = 1, ["y"] = 0, ["param1"] = 15, ["z"] = 19, ["name"] = "default:silver_sandstone_block"}, {["x"] = 1, ["y"] = 0, ["param1"] = 15, ["z"] = 20, ["name"] = "default:silver_sandstone_block"}, {["x"] = 1, ["y"] = 0, ["param1"] = 15, ["z"] = 21, ["name"] = "default:silver_sandstone_block"}, {["x"] = 1, ["y"] = 0, ["param1"] = 31, ["z"] = 22, ["name"] = "default:desert_sandstone_block"}, {["x"] = 2, ["y"] = 0, ["param1"] = 15, ["z"] = 0, ["name"] = "default:desert_sandstone_block"}, {["x"] = 2, ["y"] = 0, ["param1"] = 15, ["z"] = 1, ["name"] = "default:silver_sandstone_block"}, {["x"] = 2, ["y"] = 0, ["param1"] = 15, ["z"] = 2, ["name"] = "default:silver_sandstone_block"}, {["x"] = 2, ["y"] = 0, ["param1"] = 15, ["z"] = 3, ["name"] = "default:silver_sandstone_block"}, {["x"] = 2, ["y"] = 0, ["param1"] = 15, ["z"] = 4, ["name"] = "default:silver_sandstone_block"}, {["x"] = 2, ["y"] = 0, ["param1"] = 15, ["z"] = 5, ["name"] = "default:silver_sandstone_block"}, {["x"] = 2, ["y"] = 0, ["param1"] = 15, ["z"] = 6, ["name"] = "default:silver_sandstone_block"}, {["x"] = 2, ["y"] = 0, ["param1"] = 15, ["z"] = 7, ["name"] = "default:silver_sandstone_block"}, {["x"] = 2, ["y"] = 0, ["param1"] = 15, ["z"] = 8, ["name"] = "default:silver_sandstone_block"}, {["x"] = 2, ["y"] = 0, ["param1"] = 15, ["z"] = 9, ["name"] = "default:silver_sandstone_block"}, {["x"] = 2, ["y"] = 0, ["param1"] = 15, ["z"] = 10, ["name"] = "default:silver_sandstone_block"}, {["x"] = 2, ["y"] = 0, ["param1"] = 15, ["z"] = 11, ["name"] = "default:silver_sandstone_block"}, {["x"] = 2, ["y"] = 0, ["param1"] = 15, ["z"] = 12, ["name"] = "default:silver_sandstone_block"}, {["x"] = 2, ["y"] = 0, ["param1"] = 15, ["z"] = 13, ["name"] = "default:silver_sandstone_block"}, {["x"] = 2, ["y"] = 0, ["param1"] = 15, ["z"] = 14, ["name"] = "default:silver_sandstone_block"}, {["x"] = 2, ["y"] = 0, ["param1"] = 15, ["z"] = 15, ["name"] = "default:silver_sandstone_block"}, {["x"] = 2, ["y"] = 0, ["param1"] = 15, ["z"] = 16, ["name"] = "default:silver_sandstone_block"}, {["x"] = 2, ["y"] = 0, ["param1"] = 15, ["z"] = 17, ["name"] = "default:silver_sandstone_block"}, {["x"] = 2, ["y"] = 0, ["param1"] = 15, ["z"] = 18, ["name"] = "default:silver_sandstone_block"}, {["x"] = 2, ["y"] = 0, ["param1"] = 15, ["z"] = 19, ["name"] = "default:silver_sandstone_block"}, {["x"] = 2, ["y"] = 0, ["param1"] = 15, ["z"] = 20, ["name"] = "default:silver_sandstone_block"}, {["x"] = 2, ["y"] = 0, ["param1"] = 15, ["z"] = 21, ["name"] = "default:silver_sandstone_block"}, {["x"] = 2, ["y"] = 0, ["param1"] = 47, ["z"] = 22, ["name"] = "default:desert_sandstone_block"}, {["x"] = 2, ["y"] = 1, ["z"] = 3, ["name"] = "mesecons_lightstone:lightstone_red_off"}, {["x"] = 2, ["param2"] = 3, ["y"] = 1, ["param1"] = 15, ["z"] = 4, ["name"] = "mesecons_extrawires:corner_off"}, {["x"] = 2, ["y"] = 8, ["param1"] = 38, ["z"] = 17, ["name"] = "mesecons_lightstone:lightstone_darkgray_off"}, {["x"] = 2, ["y"] = 8, ["param1"] = 16, ["z"] = 18, ["name"] = "default:silver_sandstone"}, {["x"] = 2, ["y"] = 8, ["param1"] = 16, ["z"] = 19, ["name"] = "default:silver_sandstone"}, {["x"] = 2, ["y"] = 8, ["param1"] = 16, ["z"] = 20, ["name"] = "default:silver_sandstone"}, {["x"] = 2, ["y"] = 9, ["param1"] = 38, ["z"] = 17, ["name"] = "mesecons_lightstone:lightstone_darkgray_off"}, {["x"] = 2, ["y"] = 9, ["param1"] = 16, ["z"] = 18, ["name"] = "default:silver_sandstone"}, {["x"] = 2, ["y"] = 9, ["param1"] = 238, ["z"] = 19, ["name"] = "default:meselamp"}, {["x"] = 2, ["y"] = 9, ["param1"] = 16, ["z"] = 20, ["name"] = "default:silver_sandstone"}, {["x"] = 2, ["y"] = 10, ["param1"] = 38, ["z"] = 17, ["name"] = "mesecons_lightstone:lightstone_darkgray_off"}, {["x"] = 2, ["y"] = 10, ["param1"] = 16, ["z"] = 18, ["name"] = "default:silver_sandstone"}, {["x"] = 2, ["y"] = 10, ["param1"] = 238, ["z"] = 19, ["name"] = "default:meselamp"}, {["x"] = 2, ["y"] = 10, ["param1"] = 16, ["z"] = 20, ["name"] = "default:silver_sandstone"}, {["x"] = 2, ["y"] = 11, ["param1"] = 38, ["z"] = 17, ["name"] = "mesecons_lightstone:lightstone_darkgray_off"}, {["x"] = 2, ["y"] = 11, ["param1"] = 16, ["z"] = 18, ["name"] = "default:silver_sandstone"}, {["x"] = 2, ["y"] = 11, ["param1"] = 16, ["z"] = 19, ["name"] = "default:silver_sandstone"}, {["x"] = 2, ["y"] = 11, ["param1"] = 16, ["z"] = 20, ["name"] = "default:silver_sandstone"}, {["x"] = 2, ["y"] = 12, ["param1"] = 38, ["z"] = 17, ["name"] = "mesecons_lightstone:lightstone_darkgray_off"}, {["x"] = 2, ["y"] = 12, ["param1"] = 16, ["z"] = 18, ["name"] = "default:silver_sandstone"}, {["x"] = 2, ["y"] = 12, ["param1"] = 238, ["z"] = 19, ["name"] = "default:meselamp"}, {["x"] = 2, ["y"] = 12, ["param1"] = 16, ["z"] = 20, ["name"] = "default:silver_sandstone"}, {["x"] = 2, ["y"] = 13, ["param1"] = 38, ["z"] = 17, ["name"] = "mesecons_lightstone:lightstone_darkgray_off"}, {["x"] = 2, ["y"] = 13, ["param1"] = 16, ["z"] = 18, ["name"] = "default:silver_sandstone"}, {["x"] = 2, ["y"] = 13, ["param1"] = 238, ["z"] = 19, ["name"] = "default:meselamp"}, {["x"] = 2, ["y"] = 13, ["param1"] = 16, ["z"] = 20, ["name"] = "default:silver_sandstone"}, {["x"] = 2, ["y"] = 14, ["param1"] = 38, ["z"] = 17, ["name"] = "mesecons_lightstone:lightstone_darkgray_off"}, {["x"] = 2, ["y"] = 14, ["param1"] = 16, ["z"] = 18, ["name"] = "default:silver_sandstone"}, {["x"] = 2, ["y"] = 14, ["param1"] = 16, ["z"] = 19, ["name"] = "default:silver_sandstone"}, {["x"] = 2, ["y"] = 14, ["param1"] = 16, ["z"] = 20, ["name"] = "default:silver_sandstone"}, {["x"] = 3, ["y"] = 0, ["param1"] = 15, ["z"] = 0, ["name"] = "default:desert_sandstone_block"}, {["x"] = 3, ["y"] = 0, ["param1"] = 15, ["z"] = 1, ["name"] = "default:silver_sandstone_block"}, {["x"] = 3, ["y"] = 0, ["param1"] = 15, ["z"] = 2, ["name"] = "default:silver_sandstone_block"}, {["x"] = 3, ["y"] = 0, ["param1"] = 15, ["z"] = 3, ["name"] = "default:silver_sandstone_block"}, {["x"] = 3, ["y"] = 0, ["param1"] = 15, ["z"] = 4, ["name"] = "default:silver_sandstone_block"}, {["x"] = 3, ["y"] = 0, ["param1"] = 15, ["z"] = 5, ["name"] = "default:silver_sandstone_block"}, {["x"] = 3, ["y"] = 0, ["param1"] = 15, ["z"] = 6, ["name"] = "default:silver_sandstone_block"}, {["x"] = 3, ["y"] = 0, ["param1"] = 15, ["z"] = 7, ["name"] = "default:silver_sandstone_block"}, {["x"] = 3, ["y"] = 0, ["param1"] = 15, ["z"] = 8, ["name"] = "default:silver_sandstone_block"}, {["x"] = 3, ["y"] = 0, ["param1"] = 15, ["z"] = 9, ["name"] = "default:silver_sandstone_block"}, {["x"] = 3, ["y"] = 0, ["param1"] = 15, ["z"] = 10, ["name"] = "default:silver_sandstone_block"}, {["x"] = 3, ["y"] = 0, ["param1"] = 15, ["z"] = 11, ["name"] = "default:silver_sandstone_block"}, {["x"] = 3, ["y"] = 0, ["param1"] = 15, ["z"] = 12, ["name"] = "default:silver_sandstone_block"}, {["x"] = 3, ["y"] = 0, ["param1"] = 15, ["z"] = 13, ["name"] = "default:silver_sandstone_block"}, {["x"] = 3, ["y"] = 0, ["param1"] = 15, ["z"] = 14, ["name"] = "default:silver_sandstone_block"}, {["x"] = 3, ["y"] = 0, ["param1"] = 15, ["z"] = 15, ["name"] = "default:silver_sandstone_block"}, {["x"] = 3, ["y"] = 0, ["param1"] = 15, ["z"] = 16, ["name"] = "default:silver_sandstone_block"}, {["x"] = 3, ["y"] = 0, ["param1"] = 15, ["z"] = 17, ["name"] = "default:silver_sandstone_block"}, {["x"] = 3, ["y"] = 0, ["param1"] = 15, ["z"] = 18, ["name"] = "default:silver_sandstone_block"}, {["x"] = 3, ["y"] = 0, ["param1"] = 15, ["z"] = 19, ["name"] = "default:silver_sandstone_block"}, {["x"] = 3, ["y"] = 0, ["param1"] = 15, ["z"] = 20, ["name"] = "default:silver_sandstone_block"}, {["x"] = 3, ["y"] = 0, ["param1"] = 15, ["z"] = 21, ["name"] = "default:silver_sandstone_block"}, {["x"] = 3, ["y"] = 0, ["param1"] = 63, ["z"] = 22, ["name"] = "default:desert_sandstone_block"}, {["x"] = 3, ["param2"] = 2, ["y"] = 1, ["param1"] = 15, ["z"] = 4, ["name"] = "mesecons_extrawires:tjunction_off"}, {["x"] = 3, ["param2"] = 3, ["y"] = 1, ["param1"] = 15, ["z"] = 5, ["name"] = "mesecons_extrawires:tjunction_off"}, {["x"] = 3, ["param2"] = 3, ["y"] = 1, ["param1"] = 14, ["z"] = 6, ["name"] = "mesecons_gates:not_on"}, {["x"] = 3, ["param2"] = 3, ["y"] = 1, ["param1"] = 15, ["z"] = 7, ["name"] = "mesecons_extrawires:corner_on"}, {["x"] = 3, ["y"] = 8, ["param1"] = 38, ["z"] = 17, ["name"] = "mesecons_lightstone:lightstone_darkgray_off"}, {["x"] = 3, ["y"] = 8, ["param1"] = 16, ["z"] = 18, ["name"] = "default:silver_sandstone"}, {["x"] = 3, ["y"] = 8, ["param1"] = 239, ["z"] = 19, ["name"] = "default:meselamp"}, {["x"] = 3, ["y"] = 8, ["param1"] = 16, ["z"] = 20, ["name"] = "default:silver_sandstone"}, {["x"] = 3, ["y"] = 9, ["param1"] = 38, ["z"] = 17, ["name"] = "mesecons_lightstone:lightstone_darkgray_off"}, {["x"] = 3, ["y"] = 9, ["param1"] = 16, ["z"] = 20, ["name"] = "default:silver_sandstone"}, {["x"] = 3, ["y"] = 10, ["param1"] = 38, ["z"] = 17, ["name"] = "mesecons_lightstone:lightstone_darkgray_off"}, {["x"] = 3, ["y"] = 10, ["param1"] = 16, ["z"] = 20, ["name"] = "default:silver_sandstone"}, {["x"] = 3, ["y"] = 11, ["z"] = 17, ["name"] = "mesecons_lightstone:lightstone_darkgray_on"}, {["x"] = 3, ["param2"] = 3, ["y"] = 11, ["param1"] = 190, ["z"] = 18, ["name"] = "mesecons_extrawires:corner_on"}, {["x"] = 3, ["y"] = 11, ["param1"] = 16, ["z"] = 20, ["name"] = "default:silver_sandstone"}, {["x"] = 3, ["y"] = 12, ["param1"] = 38, ["z"] = 17, ["name"] = "mesecons_lightstone:lightstone_darkgray_off"}, {["x"] = 3, ["y"] = 12, ["param1"] = 16, ["z"] = 20, ["name"] = "default:silver_sandstone"}, {["x"] = 3, ["y"] = 13, ["param1"] = 38, ["z"] = 17, ["name"] = "mesecons_lightstone:lightstone_darkgray_off"}, {["x"] = 3, ["y"] = 13, ["param1"] = 16, ["z"] = 20, ["name"] = "default:silver_sandstone"}, {["x"] = 3, ["y"] = 14, ["param1"] = 38, ["z"] = 17, ["name"] = "mesecons_lightstone:lightstone_darkgray_off"}, {["x"] = 3, ["y"] = 14, ["param1"] = 16, ["z"] = 18, ["name"] = "default:silver_sandstone"}, {["x"] = 3, ["y"] = 14, ["param1"] = 239, ["z"] = 19, ["name"] = "default:meselamp"}, {["x"] = 3, ["y"] = 14, ["param1"] = 16, ["z"] = 20, ["name"] = "default:silver_sandstone"}, {["x"] = 4, ["y"] = 0, ["param1"] = 15, ["z"] = 0, ["name"] = "default:desert_sandstone_block"}, {["x"] = 4, ["y"] = 0, ["param1"] = 15, ["z"] = 1, ["name"] = "default:silver_sandstone_block"}, {["x"] = 4, ["y"] = 0, ["param1"] = 15, ["z"] = 2, ["name"] = "default:silver_sandstone_block"}, {["x"] = 4, ["y"] = 0, ["z"] = 3, ["name"] = "default:silver_sandstone_block"}, {["x"] = 4, ["y"] = 0, ["z"] = 4, ["name"] = "default:silver_sandstone_block"}, {["x"] = 4, ["y"] = 0, ["param1"] = 15, ["z"] = 5, ["name"] = "default:silver_sandstone_block"}, {["x"] = 4, ["y"] = 0, ["param1"] = 15, ["z"] = 6, ["name"] = "default:silver_sandstone_block"}, {["x"] = 4, ["y"] = 0, ["param1"] = 15, ["z"] = 7, ["name"] = "default:silver_sandstone_block"}, {["x"] = 4, ["y"] = 0, ["param1"] = 15, ["z"] = 8, ["name"] = "default:silver_sandstone_block"}, {["x"] = 4, ["y"] = 0, ["param1"] = 15, ["z"] = 9, ["name"] = "default:silver_sandstone_block"}, {["x"] = 4, ["y"] = 0, ["param1"] = 15, ["z"] = 10, ["name"] = "default:silver_sandstone_block"}, {["x"] = 4, ["y"] = 0, ["param1"] = 15, ["z"] = 11, ["name"] = "default:silver_sandstone_block"}, {["x"] = 4, ["y"] = 0, ["param1"] = 15, ["z"] = 12, ["name"] = "default:silver_sandstone_block"}, {["x"] = 4, ["y"] = 0, ["param1"] = 15, ["z"] = 13, ["name"] = "default:silver_sandstone_block"}, {["x"] = 4, ["y"] = 0, ["param1"] = 15, ["z"] = 14, ["name"] = "default:silver_sandstone_block"}, {["x"] = 4, ["y"] = 0, ["param1"] = 15, ["z"] = 15, ["name"] = "default:silver_sandstone_block"}, {["x"] = 4, ["y"] = 0, ["param1"] = 15, ["z"] = 16, ["name"] = "default:silver_sandstone_block"}, {["x"] = 4, ["y"] = 0, ["param1"] = 15, ["z"] = 17, ["name"] = "default:silver_sandstone_block"}, {["x"] = 4, ["y"] = 0, ["param1"] = 15, ["z"] = 18, ["name"] = "default:silver_sandstone_block"}, {["x"] = 4, ["y"] = 0, ["param1"] = 15, ["z"] = 19, ["name"] = "default:silver_sandstone_block"}, {["x"] = 4, ["y"] = 0, ["param1"] = 15, ["z"] = 20, ["name"] = "default:silver_sandstone_block"}, {["x"] = 4, ["y"] = 0, ["param1"] = 15, ["z"] = 21, ["name"] = "default:silver_sandstone_block"}, {["x"] = 4, ["y"] = 0, ["param1"] = 63, ["z"] = 22, ["name"] = "default:desert_sandstone_block"}, {["x"] = 4, ["meta"] = {["fields"] = {["infotext"] = "\"clock\"", ["text"] = "clock", ["formspec"] = "field[text;;${text}]"}, ["inventory"] = {}}, ["param2"] = 1, ["y"] = 1, ["param1"] = 15, ["z"] = 2, ["name"] = "default:sign_wall_steel"}, {["x"] = 4, ["y"] = 1, ["z"] = 3, ["name"] = "mesecons_switch:mesecon_switch_off"}, {["x"] = 4, ["meta"] = {["fields"] = {["input1"] = "0", ["input2"] = "1"}, ["inventory"] = {}}, ["param2"] = 2, ["y"] = 1, ["param1"] = 14, ["z"] = 4, ["name"] = "mesecons_gates:and_off"}, {["x"] = 4, ["y"] = 1, ["param1"] = 14, ["z"] = 5, ["name"] = "mesecons_extrawires:crossover_10"}, {["x"] = 4, ["param2"] = 1, ["y"] = 1, ["param1"] = 15, ["z"] = 6, ["name"] = "mesecons_delayer:delayer_on_2"}, {["x"] = 4, ["y"] = 1, ["param1"] = 15, ["z"] = 7, ["name"] = "mesecons_extrawires:corner_on"}, {["x"] = 4, ["y"] = 8, ["param1"] = 38, ["z"] = 17, ["name"] = "mesecons_lightstone:lightstone_darkgray_off"}, {["x"] = 4, ["y"] = 8, ["param1"] = 16, ["z"] = 18, ["name"] = "default:silver_sandstone"}, {["x"] = 4, ["y"] = 8, ["param1"] = 239, ["z"] = 19, ["name"] = "default:meselamp"}, {["x"] = 4, ["y"] = 8, ["param1"] = 16, ["z"] = 20, ["name"] = "default:silver_sandstone"}, {["x"] = 4, ["y"] = 9, ["param1"] = 38, ["z"] = 17, ["name"] = "mesecons_lightstone:lightstone_darkgray_off"}, {["x"] = 4, ["y"] = 9, ["param1"] = 223, ["z"] = 19, ["name"] = "digilines:wire_std_10001000"}, {["x"] = 4, ["y"] = 9, ["param1"] = 16, ["z"] = 20, ["name"] = "default:silver_sandstone"}, {["x"] = 4, ["y"] = 10, ["param1"] = 38, ["z"] = 17, ["name"] = "mesecons_lightstone:lightstone_darkgray_off"}, {["x"] = 4, ["y"] = 10, ["param1"] = 207, ["z"] = 19, ["name"] = "digilines:wire_std_10010001"}, {["x"] = 4, ["y"] = 10, ["param1"] = 16, ["z"] = 20, ["name"] = "default:silver_sandstone"}, {["x"] = 4, ["y"] = 11, ["z"] = 17, ["name"] = "mesecons_lightstone:lightstone_darkgray_on"}, {["x"] = 4, ["meta"] = {["fields"] = {["real_portstates"] = "1", ["code"] = "if (event.type == \"digiline\" and event.channel == \"display\") then\13  x = (event.msg.neg == \"-\")\13  port.a = x\13  port.d = x\13end", ["formspec"] = "size[12,10]background[-0.2,-0.25;12.4,10.75;jeija_luac_background.png]label[0.1,8.3;]textarea[0.2,0.2;12.2,9.5;code;;if (event.type == \"digiline\" and event.channel == \"display\") then\13  x = (event.msg.neg == \"-\")\13  port.a = x\13  port.d = x\13end]image_button[4.75,8.75;2.5,1;jeija_luac_runbutton.png;program;]image_button_exit[11.72,-0.25;0.425,0.4;jeija_close_window.png;exit;]", ["ignore_offevents"] = "return {[\"D\"] = true, [\"A\"] = true}", ["lc_memory"] = "return {}", ["luac_id"] = "45558"}, ["inventory"] = {}}, ["y"] = 11, ["param1"] = 190, ["z"] = 18, ["name"] = "mesecons_luacontroller:luacontroller1001"}, {["x"] = 4, ["y"] = 11, ["param1"] = 191, ["z"] = 19, ["name"] = "digilines:wire_std_10010000"}, {["x"] = 4, ["y"] = 11, ["param1"] = 16, ["z"] = 20, ["name"] = "default:silver_sandstone"}, {["x"] = 4, ["y"] = 12, ["param1"] = 38, ["z"] = 17, ["name"] = "mesecons_lightstone:lightstone_darkgray_off"}, {["x"] = 4, ["y"] = 12, ["param1"] = 16, ["z"] = 20, ["name"] = "default:silver_sandstone"}, {["x"] = 4, ["y"] = 13, ["param1"] = 38, ["z"] = 17, ["name"] = "mesecons_lightstone:lightstone_darkgray_off"}, {["x"] = 4, ["y"] = 13, ["param1"] = 16, ["z"] = 20, ["name"] = "default:silver_sandstone"}, {["x"] = 4, ["y"] = 14, ["param1"] = 38, ["z"] = 17, ["name"] = "mesecons_lightstone:lightstone_darkgray_off"}, {["x"] = 4, ["y"] = 14, ["param1"] = 16, ["z"] = 18, ["name"] = "default:silver_sandstone"}, {["x"] = 4, ["y"] = 14, ["param1"] = 239, ["z"] = 19, ["name"] = "default:meselamp"}, {["x"] = 4, ["y"] = 14, ["param1"] = 16, ["z"] = 20, ["name"] = "default:silver_sandstone"}, {["x"] = 5, ["y"] = 0, ["param1"] = 15, ["z"] = 0, ["name"] = "default:desert_sandstone_block"}, {["x"] = 5, ["y"] = 0, ["param1"] = 15, ["z"] = 1, ["name"] = "default:silver_sandstone_block"}, {["x"] = 5, ["y"] = 0, ["param1"] = 15, ["z"] = 2, ["name"] = "default:silver_sandstone_block"}, {["x"] = 5, ["y"] = 0, ["param1"] = 15, ["z"] = 3, ["name"] = "default:silver_sandstone_block"}, {["x"] = 5, ["y"] = 0, ["param1"] = 15, ["z"] = 4, ["name"] = "default:silver_sandstone_block"}, {["x"] = 5, ["y"] = 0, ["param1"] = 15, ["z"] = 5, ["name"] = "default:silver_sandstone_block"}, {["x"] = 5, ["y"] = 0, ["param1"] = 15, ["z"] = 6, ["name"] = "default:silver_sandstone_block"}, {["x"] = 5, ["y"] = 0, ["param1"] = 15, ["z"] = 7, ["name"] = "default:silver_sandstone_block"}, {["x"] = 5, ["y"] = 0, ["param1"] = 15, ["z"] = 8, ["name"] = "default:silver_sandstone_block"}, {["x"] = 5, ["y"] = 0, ["param1"] = 15, ["z"] = 9, ["name"] = "default:silver_sandstone_block"}, {["x"] = 5, ["y"] = 0, ["param1"] = 15, ["z"] = 10, ["name"] = "default:silver_sandstone_block"}, {["x"] = 5, ["y"] = 0, ["param1"] = 15, ["z"] = 11, ["name"] = "default:silver_sandstone_block"}, {["x"] = 5, ["y"] = 0, ["param1"] = 15, ["z"] = 12, ["name"] = "default:silver_sandstone_block"}, {["x"] = 5, ["y"] = 0, ["param1"] = 15, ["z"] = 13, ["name"] = "default:silver_sandstone_block"}, {["x"] = 5, ["y"] = 0, ["param1"] = 15, ["z"] = 14, ["name"] = "default:silver_sandstone_block"}, {["x"] = 5, ["y"] = 0, ["param1"] = 15, ["z"] = 15, ["name"] = "default:silver_sandstone_block"}, {["x"] = 5, ["y"] = 0, ["param1"] = 15, ["z"] = 16, ["name"] = "default:silver_sandstone_block"}, {["x"] = 5, ["y"] = 0, ["param1"] = 15, ["z"] = 17, ["name"] = "default:silver_sandstone_block"}, {["x"] = 5, ["y"] = 0, ["param1"] = 15, ["z"] = 18, ["name"] = "default:silver_sandstone_block"}, {["x"] = 5, ["y"] = 0, ["param1"] = 15, ["z"] = 19, ["name"] = "default:silver_sandstone_block"}, {["x"] = 5, ["y"] = 0, ["param1"] = 15, ["z"] = 20, ["name"] = "default:silver_sandstone_block"}, {["x"] = 5, ["y"] = 0, ["param1"] = 15, ["z"] = 21, ["name"] = "default:silver_sandstone_block"}, {["x"] = 5, ["y"] = 0, ["param1"] = 47, ["z"] = 22, ["name"] = "default:desert_sandstone_block"}, {["x"] = 5, ["y"] = 1, ["param1"] = 15, ["z"] = 5, ["name"] = "mesecons_insulated:insulated_off"}, {["x"] = 5, ["y"] = 8, ["param1"] = 38, ["z"] = 17, ["name"] = "mesecons_lightstone:lightstone_darkgray_off"}, {["x"] = 5, ["y"] = 8, ["param1"] = 16, ["z"] = 18, ["name"] = "default:silver_sandstone"}, {["x"] = 5, ["y"] = 8, ["param1"] = 16, ["z"] = 19, ["name"] = "default:silver_sandstone"}, {["x"] = 5, ["y"] = 8, ["param1"] = 16, ["z"] = 20, ["name"] = "default:silver_sandstone"}, {["x"] = 5, ["y"] = 9, ["param1"] = 38, ["z"] = 17, ["name"] = "mesecons_lightstone:lightstone_darkgray_off"}, {["x"] = 5, ["y"] = 9, ["param1"] = 206, ["z"] = 19, ["name"] = "digilines:wire_std_10101010"}, {["x"] = 5, ["y"] = 9, ["param1"] = 16, ["z"] = 20, ["name"] = "default:silver_sandstone"}, {["x"] = 5, ["y"] = 10, ["param1"] = 38, ["z"] = 17, ["name"] = "mesecons_lightstone:lightstone_darkgray_off"}, {["x"] = 5, ["y"] = 10, ["param1"] = 190, ["z"] = 19, ["name"] = "digilines:wire_std_10101010"}, {["x"] = 5, ["y"] = 10, ["param1"] = 16, ["z"] = 20, ["name"] = "default:silver_sandstone"}, {["x"] = 5, ["y"] = 11, ["param1"] = 38, ["z"] = 17, ["name"] = "mesecons_lightstone:lightstone_darkgray_off"}, {["x"] = 5, ["y"] = 11, ["param1"] = 16, ["z"] = 20, ["name"] = "default:silver_sandstone"}, {["x"] = 5, ["y"] = 12, ["param1"] = 38, ["z"] = 17, ["name"] = "mesecons_lightstone:lightstone_darkgray_off"}, {["x"] = 5, ["y"] = 12, ["param1"] = 16, ["z"] = 20, ["name"] = "default:silver_sandstone"}, {["x"] = 5, ["y"] = 13, ["param1"] = 38, ["z"] = 17, ["name"] = "mesecons_lightstone:lightstone_darkgray_off"}, {["x"] = 5, ["y"] = 13, ["param1"] = 16, ["z"] = 20, ["name"] = "default:silver_sandstone"}, {["x"] = 5, ["y"] = 14, ["param1"] = 38, ["z"] = 17, ["name"] = "mesecons_lightstone:lightstone_darkgray_off"}, {["x"] = 5, ["y"] = 14, ["param1"] = 16, ["z"] = 18, ["name"] = "default:silver_sandstone"}, {["x"] = 5, ["y"] = 14, ["param1"] = 16, ["z"] = 19, ["name"] = "default:silver_sandstone"}, {["x"] = 5, ["y"] = 14, ["param1"] = 16, ["z"] = 20, ["name"] = "default:silver_sandstone"}, {["x"] = 6, ["y"] = 0, ["param1"] = 15, ["z"] = 0, ["name"] = "default:desert_sandstone_block"}, {["x"] = 6, ["y"] = 0, ["param1"] = 15, ["z"] = 1, ["name"] = "default:silver_sandstone_block"}, {["x"] = 6, ["y"] = 0, ["param1"] = 15, ["z"] = 2, ["name"] = "default:silver_sandstone_block"}, {["x"] = 6, ["y"] = 0, ["param1"] = 15, ["z"] = 3, ["name"] = "default:silver_sandstone_block"}, {["x"] = 6, ["y"] = 0, ["param1"] = 15, ["z"] = 4, ["name"] = "default:silver_sandstone_block"}, {["x"] = 6, ["y"] = 0, ["param1"] = 15, ["z"] = 5, ["name"] = "default:silver_sandstone_block"}, {["x"] = 6, ["y"] = 0, ["param1"] = 15, ["z"] = 6, ["name"] = "default:silver_sandstone_block"}, {["x"] = 6, ["y"] = 0, ["param1"] = 15, ["z"] = 7, ["name"] = "default:silver_sandstone_block"}, {["x"] = 6, ["y"] = 0, ["param1"] = 15, ["z"] = 8, ["name"] = "default:silver_sandstone_block"}, {["x"] = 6, ["y"] = 0, ["param1"] = 15, ["z"] = 9, ["name"] = "default:silver_sandstone_block"}, {["x"] = 6, ["y"] = 0, ["param1"] = 15, ["z"] = 10, ["name"] = "default:silver_sandstone_block"}, {["x"] = 6, ["y"] = 0, ["param1"] = 15, ["z"] = 11, ["name"] = "default:silver_sandstone_block"}, {["x"] = 6, ["y"] = 0, ["param1"] = 15, ["z"] = 12, ["name"] = "default:silver_sandstone_block"}, {["x"] = 6, ["y"] = 0, ["param1"] = 15, ["z"] = 13, ["name"] = "default:silver_sandstone_block"}, {["x"] = 6, ["y"] = 0, ["param1"] = 15, ["z"] = 14, ["name"] = "default:silver_sandstone_block"}, {["x"] = 6, ["y"] = 0, ["param1"] = 15, ["z"] = 15, ["name"] = "default:silver_sandstone_block"}, {["x"] = 6, ["y"] = 0, ["param1"] = 15, ["z"] = 16, ["name"] = "default:silver_sandstone_block"}, {["x"] = 6, ["y"] = 0, ["param1"] = 15, ["z"] = 17, ["name"] = "default:silver_sandstone_block"}, {["x"] = 6, ["y"] = 0, ["param1"] = 15, ["z"] = 18, ["name"] = "default:silver_sandstone_block"}, {["x"] = 6, ["y"] = 0, ["param1"] = 15, ["z"] = 19, ["name"] = "default:silver_sandstone_block"}, {["x"] = 6, ["y"] = 0, ["param1"] = 15, ["z"] = 20, ["name"] = "default:silver_sandstone_block"}, {["x"] = 6, ["y"] = 0, ["param1"] = 15, ["z"] = 21, ["name"] = "default:silver_sandstone_block"}, {["x"] = 6, ["y"] = 0, ["param1"] = 63, ["z"] = 22, ["name"] = "default:desert_sandstone_block"}, {["x"] = 6, ["meta"] = {["fields"] = {["infotext"] = "\"128\"", ["text"] = "128", ["formspec"] = "field[text;;${text}]"}, ["inventory"] = {}}, ["param2"] = 1, ["y"] = 1, ["param1"] = 15, ["z"] = 2, ["name"] = "default:sign_wall_steel"}, {["x"] = 6, ["y"] = 1, ["z"] = 3, ["name"] = "mesecons_switch:mesecon_switch_on"}, {["x"] = 6, ["param2"] = 3, ["y"] = 1, ["param1"] = 15, ["z"] = 4, ["name"] = "mesecons_insulated:insulated_on"}, {["x"] = 6, ["meta"] = {["fields"] = {["real_portstates"] = "9", ["code"] = "-- Digiline Decoder\
-- Reads an 8 bit binary number (signed or unsigned) from the bus, and converts it to decimal notation\13-- by So.Po.Coder for Minetest Mesecons Lua Controller\13-- A: Clock, B: Digiline Out 1, C: Input 2, D: Input 1\13\13if (event.type == \"program\") then\
  mem.decoder = 1\13end\
\
-- create the bus array, insert the first two bits and pass to the next decoder in sequence\13if (event.type == \"on\" and event.pin.name == \"A\") then\13  bus = {}\13  table.insert(bus, pin.d and 1 or 0)\
  table.insert(bus, pin.c and 1 or 0)\13  digiline_send(\"decoder\" .. tonumber(mem.decoder + 1), bus) -- send to the next decoder\13end", ["formspec"] = "size[12,10]background[-0.2,-0.25;12.4,10.75;jeija_luac_background.png]label[0.1,8.3;]textarea[0.2,0.2;12.2,9.5;code;;-- Digiline Decoder\
-- Reads an 8 bit binary number (signed or unsigned) from the bus\\, and converts it to decimal notation\13-- by So.Po.Coder for Minetest Mesecons Lua Controller\13-- A: Clock\\, B: Digiline Out 1\\, C: Input 2\\, D: Input 1\13\13if (event.type == \"program\") then\
  mem.decoder = 1\13end\
\
-- create the bus array\\, insert the first two bits and pass to the next decoder in sequence\13if (event.type == \"on\" and event.pin.name == \"A\") then\13  bus = {}\13  table.insert(bus\\, pin.d and 1 or 0)\
  table.insert(bus\\, pin.c and 1 or 0)\13  digiline_send(\"decoder\" .. tonumber(mem.decoder + 1)\\, bus) -- send to the next decoder\13end]image_button[4.75,8.75;2.5,1;jeija_luac_runbutton.png;program;]image_button_exit[11.72,-0.25;0.425,0.4;jeija_close_window.png;exit;]", ["ignore_offevents"] = "return {}", ["lc_memory"] = "return {[\"decoder\"] = 1}", ["luac_id"] = "19440"}, ["inventory"] = {}}, ["y"] = 1, ["param1"] = 15, ["z"] = 5, ["name"] = "mesecons_luacontroller:luacontroller0000"}, {["x"] = 6, ["y"] = 1, ["param1"] = 15, ["z"] = 6, ["name"] = "digilines:wire_std_10010000"}, {["x"] = 6, ["y"] = 8, ["param1"] = 38, ["z"] = 17, ["name"] = "mesecons_lightstone:lightstone_darkgray_off"}, {["x"] = 6, ["y"] = 8, ["param1"] = 16, ["z"] = 18, ["name"] = "default:silver_sandstone"}, {["x"] = 6, ["y"] = 8, ["param1"] = 239, ["z"] = 19, ["name"] = "default:meselamp"}, {["x"] = 6, ["y"] = 8, ["param1"] = 16, ["z"] = 20, ["name"] = "default:silver_sandstone"}, {["x"] = 6, ["y"] = 9, ["z"] = 17, ["name"] = "mesecons_lightstone:lightstone_darkgray_off"}, {["x"] = 6, ["param2"] = 3, ["y"] = 9, ["param1"] = 206, ["z"] = 18, ["name"] = "mesecons_extrawires:corner_off"}, {["x"] = 6, ["y"] = 9, ["param1"] = 223, ["z"] = 19, ["name"] = "digilines:wire_std_10101010"}, {["x"] = 6, ["y"] = 9, ["param1"] = 16, ["z"] = 20, ["name"] = "default:silver_sandstone"}, {["x"] = 6, ["y"] = 10, ["z"] = 17, ["name"] = "mesecons_lightstone:lightstone_darkgray_off"}, {["x"] = 6, ["param2"] = 3, ["y"] = 10, ["param1"] = 190, ["z"] = 18, ["name"] = "mesecons_extrawires:corner_off"}, {["x"] = 6, ["y"] = 10, ["param1"] = 207, ["z"] = 19, ["name"] = "digilines:wire_std_10101000"}, {["x"] = 6, ["y"] = 10, ["param1"] = 16, ["z"] = 20, ["name"] = "default:silver_sandstone"}, {["x"] = 6, ["y"] = 11, ["z"] = 17, ["name"] = "mesecons_lightstone:lightstone_darkgray_off"}, {["x"] = 6, ["param2"] = 3, ["y"] = 11, ["param1"] = 174, ["z"] = 18, ["name"] = "mesecons_extrawires:corner_off"}, {["x"] = 6, ["y"] = 11, ["param1"] = 191, ["z"] = 19, ["name"] = "digilines:wire_std_10101000"}, {["x"] = 6, ["y"] = 11, ["param1"] = 16, ["z"] = 20, ["name"] = "default:silver_sandstone"}, {["x"] = 6, ["y"] = 12, ["param1"] = 38, ["z"] = 17, ["name"] = "mesecons_lightstone:lightstone_darkgray_off"}, {["x"] = 6, ["param2"] = 3, ["y"] = 12, ["param1"] = 190, ["z"] = 18, ["name"] = "mesecons_extrawires:corner_off"}, {["x"] = 6, ["y"] = 12, ["param1"] = 207, ["z"] = 19, ["name"] = "digilines:wire_std_10001000"}, {["x"] = 6, ["y"] = 12, ["param1"] = 16, ["z"] = 20, ["name"] = "default:silver_sandstone"}, {["x"] = 6, ["y"] = 13, ["z"] = 17, ["name"] = "mesecons_lightstone:lightstone_darkgray_off"}, {["x"] = 6, ["param2"] = 3, ["y"] = 13, ["param1"] = 206, ["z"] = 18, ["name"] = "mesecons_extrawires:corner_off"}, {["x"] = 6, ["y"] = 13, ["param1"] = 16, ["z"] = 20, ["name"] = "default:silver_sandstone"}, {["x"] = 6, ["y"] = 14, ["param1"] = 38, ["z"] = 17, ["name"] = "mesecons_lightstone:lightstone_darkgray_off"}, {["x"] = 6, ["y"] = 14, ["param1"] = 16, ["z"] = 18, ["name"] = "default:silver_sandstone"}, {["x"] = 6, ["y"] = 14, ["param1"] = 239, ["z"] = 19, ["name"] = "default:meselamp"}, {["x"] = 6, ["y"] = 14, ["param1"] = 16, ["z"] = 20, ["name"] = "default:silver_sandstone"}, {["x"] = 7, ["y"] = 0, ["param1"] = 15, ["z"] = 0, ["name"] = "default:desert_sandstone_block"}, {["x"] = 7, ["y"] = 0, ["param1"] = 15, ["z"] = 1, ["name"] = "default:silver_sandstone_block"}, {["x"] = 7, ["y"] = 0, ["param1"] = 15, ["z"] = 2, ["name"] = "default:silver_sandstone_block"}, {["x"] = 7, ["y"] = 0, ["param1"] = 15, ["z"] = 3, ["name"] = "default:silver_sandstone_block"}, {["x"] = 7, ["y"] = 0, ["param1"] = 15, ["z"] = 4, ["name"] = "default:silver_sandstone_block"}, {["x"] = 7, ["y"] = 0, ["param1"] = 15, ["z"] = 5, ["name"] = "default:silver_sandstone_block"}, {["x"] = 7, ["y"] = 0, ["param1"] = 15, ["z"] = 6, ["name"] = "default:silver_sandstone_block"}, {["x"] = 7, ["y"] = 0, ["param1"] = 15, ["z"] = 7, ["name"] = "default:silver_sandstone_block"}, {["x"] = 7, ["y"] = 0, ["param1"] = 15, ["z"] = 8, ["name"] = "default:silver_sandstone_block"}, {["x"] = 7, ["y"] = 0, ["param1"] = 15, ["z"] = 9, ["name"] = "default:silver_sandstone_block"}, {["x"] = 7, ["y"] = 0, ["param1"] = 15, ["z"] = 10, ["name"] = "default:silver_sandstone_block"}, {["x"] = 7, ["y"] = 0, ["param1"] = 15, ["z"] = 11, ["name"] = "default:silver_sandstone_block"}, {["x"] = 7, ["y"] = 0, ["param1"] = 15, ["z"] = 12, ["name"] = "default:silver_sandstone_block"}, {["x"] = 7, ["y"] = 0, ["param1"] = 15, ["z"] = 13, ["name"] = "default:silver_sandstone_block"}, {["x"] = 7, ["y"] = 0, ["param1"] = 15, ["z"] = 14, ["name"] = "default:silver_sandstone_block"}, {["x"] = 7, ["y"] = 0, ["param1"] = 15, ["z"] = 15, ["name"] = "default:silver_sandstone_block"}, {["x"] = 7, ["y"] = 0, ["param1"] = 15, ["z"] = 16, ["name"] = "default:silver_sandstone_block"}, {["x"] = 7, ["y"] = 0, ["param1"] = 15, ["z"] = 17, ["name"] = "default:silver_sandstone_block"}, {["x"] = 7, ["y"] = 0, ["param1"] = 15, ["z"] = 18, ["name"] = "default:silver_sandstone_block"}, {["x"] = 7, ["y"] = 0, ["param1"] = 15, ["z"] = 19, ["name"] = "default:silver_sandstone_block"}, {["x"] = 7, ["y"] = 0, ["param1"] = 15, ["z"] = 20, ["name"] = "default:silver_sandstone_block"}, {["x"] = 7, ["y"] = 0, ["param1"] = 15, ["z"] = 21, ["name"] = "default:silver_sandstone_block"}, {["x"] = 7, ["y"] = 0, ["param1"] = 63, ["z"] = 22, ["name"] = "default:desert_sandstone_block"}, {["x"] = 7, ["meta"] = {["fields"] = {["infotext"] = "\"64\"", ["text"] = "64", ["formspec"] = "field[text;;${text}]"}, ["inventory"] = {}}, ["param2"] = 1, ["y"] = 1, ["param1"] = 15, ["z"] = 2, ["name"] = "default:sign_wall_steel"}, {["x"] = 7, ["y"] = 1, ["z"] = 3, ["name"] = "mesecons_switch:mesecon_switch_off"}, {["x"] = 7, ["param2"] = 3, ["y"] = 1, ["param1"] = 15, ["z"] = 4, ["name"] = "mesecons_insulated:insulated_off"}, {["x"] = 7, ["y"] = 1, ["param1"] = 15, ["z"] = 5, ["name"] = "mesecons_extrawires:corner_off"}, {["x"] = 7, ["y"] = 1, ["param1"] = 15, ["z"] = 6, ["name"] = "digilines:wire_std_10100000"}, {["x"] = 7, ["y"] = 8, ["param1"] = 38, ["z"] = 17, ["name"] = "mesecons_lightstone:lightstone_darkgray_off"}, {["x"] = 7, ["y"] = 8, ["param1"] = 16, ["z"] = 18, ["name"] = "default:silver_sandstone"}, {["x"] = 7, ["y"] = 8, ["param1"] = 239, ["z"] = 19, ["name"] = "default:meselamp"}, {["x"] = 7, ["y"] = 8, ["param1"] = 16, ["z"] = 20, ["name"] = "default:silver_sandstone"}, {["x"] = 7, ["y"] = 9, ["z"] = 17, ["name"] = "mesecons_lightstone:lightstone_darkgray_on"}, {["x"] = 7, ["meta"] = {["fields"] = {["real_portstates"] = "1", ["code"] = "if (event.type == \"program\") then\13  mem.A = {[0]=true, [2]=true, [3]=true, [5]=true, [6]=true, [8]=true, [9]=true}\13  mem.D = {[0]=true, [1]=true, [2]=true, [3]=true, [5]=true, [6]=true, [8]=true, [9]=true}\13  mem.C = {[0]=true, [2]=true, [3]=true, [4]=true, [5]=true, [6]=true, [7]=true, [8]=true, [9]=true}\13end\
\
if (event.type == \"digiline\" and event.channel == \"display\") then\13  x = event.msg.hun\13  port.a = mem.A[x]\
  port.d = mem.D[x]\13  port.c = mem.C[x]\13end", ["formspec"] = "size[12,10]background[-0.2,-0.25;12.4,10.75;jeija_luac_background.png]label[0.1,8.3;]textarea[0.2,0.2;12.2,9.5;code;;if (event.type == \"program\") then\13  mem.A = {\\[0\\]=true\\, \\[2\\]=true\\, \\[3\\]=true\\, \\[5\\]=true\\, \\[6\\]=true\\, \\[8\\]=true\\, \\[9\\]=true}\13  mem.D = {\\[0\\]=true\\, \\[1\\]=true\\, \\[2\\]=true\\, \\[3\\]=true\\, \\[5\\]=true\\, \\[6\\]=true\\, \\[8\\]=true\\, \\[9\\]=true}\13  mem.C = {\\[0\\]=true\\, \\[2\\]=true\\, \\[3\\]=true\\, \\[4\\]=true\\, \\[5\\]=true\\, \\[6\\]=true\\, \\[7\\]=true\\, \\[8\\]=true\\, \\[9\\]=true}\13end\
\
if (event.type == \"digiline\" and event.channel == \"display\") then\13  x = event.msg.hun\13  port.a = mem.A\\[x\\]\
  port.d = mem.D\\[x\\]\13  port.c = mem.C\\[x\\]\13end]image_button[4.75,8.75;2.5,1;jeija_luac_runbutton.png;program;]image_button_exit[11.72,-0.25;0.425,0.4;jeija_close_window.png;exit;]", ["ignore_offevents"] = "return {[\"B\"] = true, [\"D\"] = true}", ["lc_memory"] = "return {[\"B\"] = {[0] = true, [2] = true, [3] = true, [5] = true, [6] = true, [8] = true, [9] = true}, [\"D\"] = {true, true, true, [0] = true, [5] = true, [6] = true, [8] = true, [9] = true}, [\"C\"] = {[0] = true, [2] = true, [3] = true, [4] = true, [5] = true, [6] = true, [7] = true, [8] = true, [9] = true}, [\"A\"] = {[0] = true, [2] = true, [3] = true, [5] = true, [6] = true, [8] = true, [9] = true}}", ["luac_id"] = "33448"}, ["inventory"] = {}}, ["y"] = 9, ["param1"] = 206, ["z"] = 18, ["name"] = "mesecons_luacontroller:luacontroller1000"}, {["x"] = 7, ["y"] = 9, ["param1"] = 223, ["z"] = 19, ["name"] = "digilines:wire_std_10111011"}, {["x"] = 7, ["y"] = 9, ["param1"] = 16, ["z"] = 20, ["name"] = "default:silver_sandstone"}, {["x"] = 7, ["y"] = 10, ["z"] = 17, ["name"] = "mesecons_lightstone:lightstone_darkgray_on"}, {["x"] = 7, ["meta"] = {["fields"] = {["real_portstates"] = "1", ["code"] = "if event.type == \"program\" then\13  mem.A = {[0]=true, [2]=true, [6]=true, [8]=true}\
  mem.D = {[1]=true}\13  mem.C = {[0]=true, [3]=true, [4]=true, [5]=true, [6]=true, [7]=true, [8]=true, [9]=true}\13end\
if (event.type == \"digiline\" and event.channel == \"display\") then\13  x = event.msg.hun\13  port.a = mem.A[x]\
  port.d = mem.D[x]\13  port.c = mem.C[x]\13end", ["formspec"] = "size[12,10]background[-0.2,-0.25;12.4,10.75;jeija_luac_background.png]label[0.1,8.3;]textarea[0.2,0.2;12.2,9.5;code;;if event.type == \"program\" then\13  mem.A = {\\[0\\]=true\\, \\[2\\]=true\\, \\[6\\]=true\\, \\[8\\]=true}\
  mem.D = {\\[1\\]=true}\13  mem.C = {\\[0\\]=true\\, \\[3\\]=true\\, \\[4\\]=true\\, \\[5\\]=true\\, \\[6\\]=true\\, \\[7\\]=true\\, \\[8\\]=true\\, \\[9\\]=true}\13end\
if (event.type == \"digiline\" and event.channel == \"display\") then\13  x = event.msg.hun\13  port.a = mem.A\\[x\\]\
  port.d = mem.D\\[x\\]\13  port.c = mem.C\\[x\\]\13end]image_button[4.75,8.75;2.5,1;jeija_luac_runbutton.png;program;]image_button_exit[11.72,-0.25;0.425,0.4;jeija_close_window.png;exit;]", ["ignore_offevents"] = "return {[\"B\"] = true, [\"D\"] = true}", ["lc_memory"] = "return {[\"B\"] = {[0] = true, [2] = true, [3] = true, [4] = true, [5] = true, [6] = true, [8] = true, [9] = true}, [\"accept2\"] = {true, [0] = true, [3] = true, [4] = true, [5] = true, [6] = true, [7] = true, [8] = true, [9] = true}, [\"accept1\"] = {[0] = true, [2] = true, [6] = true, [8] = true}, [\"D\"] = {true}, [\"A\"] = {[0] = true, [2] = true, [6] = true, [8] = true}, [\"C\"] = {[0] = true, [3] = true, [4] = true, [5] = true, [6] = true, [7] = true, [8] = true, [9] = true}}", ["luac_id"] = "45666"}, ["inventory"] = {}}, ["y"] = 10, ["param1"] = 190, ["z"] = 18, ["name"] = "mesecons_luacontroller:luacontroller1000"}, {["x"] = 7, ["y"] = 10, ["param1"] = 207, ["z"] = 19, ["name"] = "digilines:wire_std_10110011"}, {["x"] = 7, ["y"] = 10, ["param1"] = 16, ["z"] = 20, ["name"] = "default:silver_sandstone"}, {["x"] = 7, ["y"] = 11, ["z"] = 17, ["name"] = "mesecons_lightstone:lightstone_darkgray_on"}, {["x"] = 7, ["meta"] = {["fields"] = {["real_portstates"] = "1", ["code"] = "if event.type == \"program\" then\13  mem.A = {[0]=true, [2]=true, [3]=true, [4]=true, [5]=true, [6]=true, [8]=true, [9]=true}\13  mem.D = {[2]=true, [1]=true, [3]=true, [4]=true, [5]=true, [6]=true, [8]=true, [9]=true}\13  mem.C = {[0]=true, [2]=true, [3]=true, [4]=true, [5]=true, [6]=true, [7]=true, [8]=true, [9]=true}\13end\
if (event.type == \"digiline\" and event.channel == \"display\") then\13  x = event.msg.hun\13  port.a = mem.A[x]\13  port.d = mem.D[x]\13  port.c = mem.C[x]\13end", ["formspec"] = "size[12,10]background[-0.2,-0.25;12.4,10.75;jeija_luac_background.png]label[0.1,8.3;]textarea[0.2,0.2;12.2,9.5;code;;if event.type == \"program\" then\13  mem.A = {\\[0\\]=true\\, \\[2\\]=true\\, \\[3\\]=true\\, \\[4\\]=true\\, \\[5\\]=true\\, \\[6\\]=true\\, \\[8\\]=true\\, \\[9\\]=true}\13  mem.D = {\\[2\\]=true\\, \\[1\\]=true\\, \\[3\\]=true\\, \\[4\\]=true\\, \\[5\\]=true\\, \\[6\\]=true\\, \\[8\\]=true\\, \\[9\\]=true}\13  mem.C = {\\[0\\]=true\\, \\[2\\]=true\\, \\[3\\]=true\\, \\[4\\]=true\\, \\[5\\]=true\\, \\[6\\]=true\\, \\[7\\]=true\\, \\[8\\]=true\\, \\[9\\]=true}\13end\
if (event.type == \"digiline\" and event.channel == \"display\") then\13  x = event.msg.hun\13  port.a = mem.A\\[x\\]\13  port.d = mem.D\\[x\\]\13  port.c = mem.C\\[x\\]\13end]image_button[4.75,8.75;2.5,1;jeija_luac_runbutton.png;program;]image_button_exit[11.72,-0.25;0.425,0.4;jeija_close_window.png;exit;]", ["ignore_offevents"] = "return {[\"D\"] = true}", ["lc_memory"] = "return {[\"B\"] = {[0] = true, [2] = true, [3] = true, [4] = true, [5] = true, [6] = true, [8] = true, [9] = true}, [\"D\"] = {true, true, true, true, true, true, [8] = true, [9] = true}, [\"A\"] = {[0] = true, [2] = true, [3] = true, [4] = true, [5] = true, [6] = true, [8] = true, [9] = true}, [\"C\"] = {[0] = true, [2] = true, [3] = true, [4] = true, [5] = true, [6] = true, [7] = true, [8] = true, [9] = true}}", ["luac_id"] = "55646"}, ["inventory"] = {}}, ["y"] = 11, ["param1"] = 190, ["z"] = 18, ["name"] = "mesecons_luacontroller:luacontroller1000"}, {["x"] = 7, ["y"] = 11, ["param1"] = 191, ["z"] = 19, ["name"] = "digilines:wire_std_10110011"}, {["x"] = 7, ["y"] = 11, ["param1"] = 16, ["z"] = 20, ["name"] = "default:silver_sandstone"}, {["x"] = 7, ["y"] = 12, ["z"] = 17, ["name"] = "mesecons_lightstone:lightstone_darkgray_on"}, {["x"] = 7, ["meta"] = {["fields"] = {["real_portstates"] = "1", ["code"] = "if event.type == \"program\" then\13  mem.A = {[0]=true, [4]=true, [5]=true, [6]=true, [8]=true, [9]=true}\
  mem.D = {[1] = true}\13  mem.C = {[0]=true, [2]=true, [3]=true, [4]=true, [7]=true, [8]=true, [9]=true}\13end\
if (event.type == \"digiline\" and event.channel == \"display\") then\13  x = event.msg.hun\13  port.a = mem.A[x]\
  port.d = mem.D[x]\13  port.c = mem.C[x]\13end", ["formspec"] = "size[12,10]background[-0.2,-0.25;12.4,10.75;jeija_luac_background.png]label[0.1,8.3;]textarea[0.2,0.2;12.2,9.5;code;;if event.type == \"program\" then\13  mem.A = {\\[0\\]=true\\, \\[4\\]=true\\, \\[5\\]=true\\, \\[6\\]=true\\, \\[8\\]=true\\, \\[9\\]=true}\
  mem.D = {\\[1\\] = true}\13  mem.C = {\\[0\\]=true\\, \\[2\\]=true\\, \\[3\\]=true\\, \\[4\\]=true\\, \\[7\\]=true\\, \\[8\\]=true\\, \\[9\\]=true}\13end\
if (event.type == \"digiline\" and event.channel == \"display\") then\13  x = event.msg.hun\13  port.a = mem.A\\[x\\]\
  port.d = mem.D\\[x\\]\13  port.c = mem.C\\[x\\]\13end]image_button[4.75,8.75;2.5,1;jeija_luac_runbutton.png;program;]image_button_exit[11.72,-0.25;0.425,0.4;jeija_close_window.png;exit;]", ["ignore_offevents"] = "return {[\"D\"] = true}", ["lc_memory"] = "return {[\"accept2\"] = {true, true, true, true, [0] = true, [7] = true, [8] = true, [9] = true}, [\"accept1\"] = {[0] = true, [4] = true, [5] = true, [6] = true, [8] = true, [9] = true}, [\"D\"] = {true}, [\"A\"] = {[0] = true, [4] = true, [5] = true, [6] = true, [8] = true, [9] = true}, [\"C\"] = {[0] = true, [2] = true, [3] = true, [4] = true, [7] = true, [8] = true, [9] = true}}", ["luac_id"] = "26593"}, ["inventory"] = {}}, ["y"] = 12, ["param1"] = 190, ["z"] = 18, ["name"] = "mesecons_luacontroller:luacontroller1000"}, {["x"] = 7, ["y"] = 12, ["param1"] = 207, ["z"] = 19, ["name"] = "digilines:wire_std_00110001"}, {["x"] = 7, ["y"] = 12, ["param1"] = 16, ["z"] = 20, ["name"] = "default:silver_sandstone"}, {["x"] = 7, ["y"] = 13, ["z"] = 17, ["name"] = "mesecons_lightstone:lightstone_darkgray_on"}, {["x"] = 7, ["meta"] = {["fields"] = {["real_portstates"] = "1", ["code"] = "if event.type == \"program\" then\13  mem.A = {[0]=true, [2]=true, [3]=true, [4]=true, [5]=true, [6]=true, [7]=true, [8]=true, [9]=true}\13  mem.D = {[0]=true, [1]=true, [2]=true, [3]=true, [5]=true, [6]=true, [7]=true, [8]=true, [9]=true}\13  mem.C = {[0]=true, [2]=true, [3]=true, [4]=true, [5]=true, [6]=true, [7]=true, [8]=true, [9]=true}\13end\
if (event.type == \"digiline\" and event.channel == \"display\") then\13  x = event.msg.hun\13  port.a = mem.A[x]\13  port.d = mem.D[x]\13  port.c = mem.C[x]\13end", ["formspec"] = "size[12,10]background[-0.2,-0.25;12.4,10.75;jeija_luac_background.png]label[0.1,8.3;]textarea[0.2,0.2;12.2,9.5;code;;if event.type == \"program\" then\13  mem.A = {\\[0\\]=true\\, \\[2\\]=true\\, \\[3\\]=true\\, \\[4\\]=true\\, \\[5\\]=true\\, \\[6\\]=true\\, \\[7\\]=true\\, \\[8\\]=true\\, \\[9\\]=true}\13  mem.D = {\\[0\\]=true\\, \\[1\\]=true\\, \\[2\\]=true\\, \\[3\\]=true\\, \\[5\\]=true\\, \\[6\\]=true\\, \\[7\\]=true\\, \\[8\\]=true\\, \\[9\\]=true}\13  mem.C = {\\[0\\]=true\\, \\[2\\]=true\\, \\[3\\]=true\\, \\[4\\]=true\\, \\[5\\]=true\\, \\[6\\]=true\\, \\[7\\]=true\\, \\[8\\]=true\\, \\[9\\]=true}\13end\
if (event.type == \"digiline\" and event.channel == \"display\") then\13  x = event.msg.hun\13  port.a = mem.A\\[x\\]\13  port.d = mem.D\\[x\\]\13  port.c = mem.C\\[x\\]\13end]image_button[4.75,8.75;2.5,1;jeija_luac_runbutton.png;program;]image_button_exit[11.72,-0.25;0.425,0.4;jeija_close_window.png;exit;]", ["ignore_offevents"] = "return {[\"D\"] = true}", ["lc_memory"] = "return {[\"B\"] = {[0] = true, [2] = true, [3] = true, [4] = true, [5] = true, [6] = true, [7] = true, [8] = true, [9] = true}, [\"C\"] = {[0] = true, [2] = true, [3] = true, [4] = true, [5] = true, [6] = true, [7] = true, [8] = true, [9] = true}, [\"A\"] = {[0] = true, [2] = true, [3] = true, [4] = true, [5] = true, [6] = true, [7] = true, [8] = true, [9] = true}, [\"D\"] = {true, true, true, [0] = true, [5] = true, [6] = true, [7] = true, [8] = true, [9] = true}}", ["luac_id"] = "15901"}, ["inventory"] = {}}, ["y"] = 13, ["param1"] = 206, ["z"] = 18, ["name"] = "mesecons_luacontroller:luacontroller1000"}, {["x"] = 7, ["y"] = 13, ["param1"] = 223, ["z"] = 19, ["name"] = "digilines:wire_std_00110000"}, {["x"] = 7, ["y"] = 13, ["param1"] = 16, ["z"] = 20, ["name"] = "default:silver_sandstone"}, {["x"] = 7, ["y"] = 14, ["param1"] = 38, ["z"] = 17, ["name"] = "mesecons_lightstone:lightstone_darkgray_off"}, {["x"] = 7, ["y"] = 14, ["param1"] = 16, ["z"] = 18, ["name"] = "default:silver_sandstone"}, {["x"] = 7, ["y"] = 14, ["param1"] = 239, ["z"] = 19, ["name"] = "default:meselamp"}, {["x"] = 7, ["y"] = 14, ["param1"] = 16, ["z"] = 20, ["name"] = "default:silver_sandstone"}, {["x"] = 8, ["y"] = 0, ["param1"] = 15, ["z"] = 0, ["name"] = "default:desert_sandstone_block"}, {["x"] = 8, ["y"] = 0, ["param1"] = 15, ["z"] = 1, ["name"] = "default:silver_sandstone_block"}, {["x"] = 8, ["y"] = 0, ["param1"] = 15, ["z"] = 2, ["name"] = "default:silver_sandstone_block"}, {["x"] = 8, ["y"] = 0, ["param1"] = 15, ["z"] = 3, ["name"] = "default:silver_sandstone_block"}, {["x"] = 8, ["y"] = 0, ["param1"] = 15, ["z"] = 4, ["name"] = "default:silver_sandstone_block"}, {["x"] = 8, ["y"] = 0, ["param1"] = 15, ["z"] = 5, ["name"] = "default:silver_sandstone_block"}, {["x"] = 8, ["y"] = 0, ["param1"] = 15, ["z"] = 6, ["name"] = "default:silver_sandstone_block"}, {["x"] = 8, ["y"] = 0, ["param1"] = 15, ["z"] = 7, ["name"] = "default:silver_sandstone_block"}, {["x"] = 8, ["y"] = 0, ["param1"] = 15, ["z"] = 8, ["name"] = "default:silver_sandstone_block"}, {["x"] = 8, ["y"] = 0, ["param1"] = 15, ["z"] = 9, ["name"] = "default:silver_sandstone_block"}, {["x"] = 8, ["y"] = 0, ["param1"] = 15, ["z"] = 10, ["name"] = "default:silver_sandstone_block"}, {["x"] = 8, ["y"] = 0, ["param1"] = 15, ["z"] = 11, ["name"] = "default:silver_sandstone_block"}, {["x"] = 8, ["y"] = 0, ["param1"] = 15, ["z"] = 12, ["name"] = "default:silver_sandstone_block"}, {["x"] = 8, ["y"] = 0, ["param1"] = 15, ["z"] = 13, ["name"] = "default:silver_sandstone_block"}, {["x"] = 8, ["y"] = 0, ["param1"] = 15, ["z"] = 14, ["name"] = "default:silver_sandstone_block"}, {["x"] = 8, ["y"] = 0, ["param1"] = 15, ["z"] = 15, ["name"] = "default:silver_sandstone_block"}, {["x"] = 8, ["y"] = 0, ["param1"] = 15, ["z"] = 16, ["name"] = "default:silver_sandstone_block"}, {["x"] = 8, ["y"] = 0, ["param1"] = 15, ["z"] = 17, ["name"] = "default:silver_sandstone_block"}, {["x"] = 8, ["y"] = 0, ["param1"] = 15, ["z"] = 18, ["name"] = "default:silver_sandstone_block"}, {["x"] = 8, ["y"] = 0, ["param1"] = 15, ["z"] = 19, ["name"] = "default:silver_sandstone_block"}, {["x"] = 8, ["y"] = 0, ["param1"] = 15, ["z"] = 20, ["name"] = "default:silver_sandstone_block"}, {["x"] = 8, ["y"] = 0, ["param1"] = 15, ["z"] = 21, ["name"] = "default:silver_sandstone_block"}, {["x"] = 8, ["y"] = 0, ["param1"] = 47, ["z"] = 22, ["name"] = "default:desert_sandstone_block"}, {["x"] = 8, ["meta"] = {["fields"] = {["infotext"] = "\"32\"", ["text"] = "32", ["formspec"] = "field[text;;${text}]"}, ["inventory"] = {}}, ["param2"] = 1, ["y"] = 1, ["param1"] = 15, ["z"] = 2, ["name"] = "default:sign_wall_steel"}, {["x"] = 8, ["y"] = 1, ["z"] = 3, ["name"] = "mesecons_switch:mesecon_switch_off"}, {["x"] = 8, ["param2"] = 3, ["y"] = 1, ["param1"] = 15, ["z"] = 4, ["name"] = "mesecons_insulated:insulated_off"}, {["x"] = 8, ["meta"] = {["fields"] = {["real_portstates"] = "6", ["code"] = "-- Digiline Decoder\
-- Reads an 8 bit binary number (signed or unsigned) from the bus, and converts it to decimal notation\13-- by So.Po.Coder for Minetest Mesecons Lua Controller\13-- B: Digiline Out 1, C: Input 2, D: Input 1\13\13if (event.type == \"program\") then\13  mem.decoder = 2\13end\
\
-- insert this decoders inputs to the table/array then pass on to the next decoder in sequence\13if (event.type == \"digiline\" and event.channel == \"decoder\" .. mem.decoder) then\13  bus = event.msg\13  table.insert(bus, pin.d and 1 or 0)\
  table.insert(bus, pin.c and 1 or 0)\13  digiline_send(\"decoder\" .. tonumber(mem.decoder + 1), bus) -- send to the next decoder\13end", ["formspec"] = "size[12,10]background[-0.2,-0.25;12.4,10.75;jeija_luac_background.png]label[0.1,8.3;]textarea[0.2,0.2;12.2,9.5;code;;-- Digiline Decoder\
-- Reads an 8 bit binary number (signed or unsigned) from the bus\\, and converts it to decimal notation\13-- by So.Po.Coder for Minetest Mesecons Lua Controller\13-- B: Digiline Out 1\\, C: Input 2\\, D: Input 1\13\13if (event.type == \"program\") then\13  mem.decoder = 2\13end\
\
-- insert this decoders inputs to the table/array then pass on to the next decoder in sequence\13if (event.type == \"digiline\" and event.channel == \"decoder\" .. mem.decoder) then\13  bus = event.msg\13  table.insert(bus\\, pin.d and 1 or 0)\
  table.insert(bus\\, pin.c and 1 or 0)\13  digiline_send(\"decoder\" .. tonumber(mem.decoder + 1)\\, bus) -- send to the next decoder\13end]image_button[4.75,8.75;2.5,1;jeija_luac_runbutton.png;program;]image_button_exit[11.72,-0.25;0.425,0.4;jeija_close_window.png;exit;]", ["lc_memory"] = "return {[\"b\"] = false, [\"d\"] = false, [\"decoder\"] = 2, [\"a\"] = false, [\"c\"] = false}", ["luac_id"] = "63791"}, ["inventory"] = {}}, ["y"] = 1, ["param1"] = 15, ["z"] = 5, ["name"] = "mesecons_luacontroller:luacontroller0000"}, {["x"] = 8, ["y"] = 1, ["param1"] = 15, ["z"] = 6, ["name"] = "digilines:wire_std_10110000"}, {["x"] = 8, ["y"] = 1, ["param1"] = 18, ["z"] = 18, ["name"] = "default:silver_sandstone_block"}, {["x"] = 8, ["y"] = 1, ["param1"] = 18, ["z"] = 19, ["name"] = "default:silver_sandstone_block"}, {["x"] = 8, ["y"] = 1, ["param1"] = 18, ["z"] = 20, ["name"] = "default:silver_sandstone_block"}, {["x"] = 8, ["y"] = 2, ["param1"] = 18, ["z"] = 18, ["name"] = "default:silver_sandstone_block"}, {["x"] = 8, ["y"] = 2, ["param1"] = 18, ["z"] = 19, ["name"] = "default:silver_sandstone_block"}, {["x"] = 8, ["y"] = 2, ["param1"] = 18, ["z"] = 20, ["name"] = "default:silver_sandstone_block"}, {["x"] = 8, ["y"] = 3, ["param1"] = 18, ["z"] = 18, ["name"] = "default:silver_sandstone_block"}, {["x"] = 8, ["y"] = 3, ["param1"] = 18, ["z"] = 19, ["name"] = "default:silver_sandstone_block"}, {["x"] = 8, ["y"] = 3, ["param1"] = 18, ["z"] = 20, ["name"] = "default:silver_sandstone_block"}, {["x"] = 8, ["y"] = 4, ["param1"] = 18, ["z"] = 18, ["name"] = "default:silver_sandstone_block"}, {["x"] = 8, ["y"] = 4, ["param1"] = 18, ["z"] = 19, ["name"] = "default:silver_sandstone_block"}, {["x"] = 8, ["y"] = 4, ["param1"] = 18, ["z"] = 20, ["name"] = "default:silver_sandstone_block"}, {["x"] = 8, ["y"] = 5, ["param1"] = 18, ["z"] = 18, ["name"] = "default:silver_sandstone_block"}, {["x"] = 8, ["y"] = 5, ["param1"] = 18, ["z"] = 19, ["name"] = "default:silver_sandstone_block"}, {["x"] = 8, ["y"] = 5, ["param1"] = 18, ["z"] = 20, ["name"] = "default:silver_sandstone_block"}, {["x"] = 8, ["y"] = 6, ["param1"] = 18, ["z"] = 18, ["name"] = "default:silver_sandstone_block"}, {["x"] = 8, ["y"] = 6, ["param1"] = 18, ["z"] = 19, ["name"] = "default:silver_sandstone_block"}, {["x"] = 8, ["y"] = 6, ["param1"] = 18, ["z"] = 20, ["name"] = "default:silver_sandstone_block"}, {["x"] = 8, ["y"] = 7, ["param1"] = 18, ["z"] = 18, ["name"] = "default:silver_sandstone_block"}, {["x"] = 8, ["y"] = 7, ["param1"] = 18, ["z"] = 19, ["name"] = "default:silver_sandstone_block"}, {["x"] = 8, ["y"] = 7, ["param1"] = 18, ["z"] = 20, ["name"] = "default:silver_sandstone_block"}, {["x"] = 8, ["y"] = 8, ["param1"] = 38, ["z"] = 17, ["name"] = "mesecons_lightstone:lightstone_darkgray_off"}, {["x"] = 8, ["y"] = 8, ["param1"] = 16, ["z"] = 18, ["name"] = "default:silver_sandstone"}, {["x"] = 8, ["y"] = 8, ["param1"] = 16, ["z"] = 19, ["name"] = "default:silver_sandstone"}, {["x"] = 8, ["y"] = 8, ["param1"] = 16, ["z"] = 20, ["name"] = "default:silver_sandstone"}, {["x"] = 8, ["y"] = 9, ["z"] = 17, ["name"] = "mesecons_lightstone:lightstone_darkgray_off"}, {["x"] = 8, ["y"] = 9, ["param1"] = 189, ["z"] = 18, ["name"] = "mesecons_extrawires:corner_off"}, {["x"] = 8, ["y"] = 9, ["param1"] = 206, ["z"] = 19, ["name"] = "digilines:wire_std_10101010"}, {["x"] = 8, ["y"] = 9, ["param1"] = 16, ["z"] = 20, ["name"] = "default:silver_sandstone"}, {["x"] = 8, ["y"] = 10, ["param1"] = 38, ["z"] = 17, ["name"] = "mesecons_lightstone:lightstone_darkgray_off"}, {["x"] = 8, ["y"] = 10, ["param1"] = 173, ["z"] = 18, ["name"] = "mesecons_extrawires:corner_off"}, {["x"] = 8, ["y"] = 10, ["param1"] = 190, ["z"] = 19, ["name"] = "digilines:wire_std_10100010"}, {["x"] = 8, ["y"] = 10, ["param1"] = 16, ["z"] = 20, ["name"] = "default:silver_sandstone"}, {["x"] = 8, ["y"] = 11, ["z"] = 17, ["name"] = "mesecons_lightstone:lightstone_darkgray_off"}, {["x"] = 8, ["y"] = 11, ["param1"] = 173, ["z"] = 18, ["name"] = "mesecons_extrawires:corner_off"}, {["x"] = 8, ["y"] = 11, ["param1"] = 16, ["z"] = 20, ["name"] = "default:silver_sandstone"}, {["x"] = 8, ["y"] = 12, ["z"] = 17, ["name"] = "mesecons_lightstone:lightstone_darkgray_off"}, {["x"] = 8, ["y"] = 12, ["param1"] = 173, ["z"] = 18, ["name"] = "mesecons_extrawires:corner_off"}, {["x"] = 8, ["y"] = 12, ["param1"] = 16, ["z"] = 20, ["name"] = "default:silver_sandstone"}, {["x"] = 8, ["y"] = 13, ["z"] = 17, ["name"] = "mesecons_lightstone:lightstone_darkgray_off"}, {["x"] = 8, ["y"] = 13, ["param1"] = 189, ["z"] = 18, ["name"] = "mesecons_extrawires:corner_off"}, {["x"] = 8, ["y"] = 13, ["param1"] = 16, ["z"] = 20, ["name"] = "default:silver_sandstone"}, {["x"] = 8, ["y"] = 14, ["param1"] = 38, ["z"] = 17, ["name"] = "mesecons_lightstone:lightstone_darkgray_off"}, {["x"] = 8, ["y"] = 14, ["param1"] = 16, ["z"] = 18, ["name"] = "default:silver_sandstone"}, {["x"] = 8, ["y"] = 14, ["param1"] = 16, ["z"] = 19, ["name"] = "default:silver_sandstone"}, {["x"] = 8, ["y"] = 14, ["param1"] = 16, ["z"] = 20, ["name"] = "default:silver_sandstone"}, {["x"] = 9, ["y"] = 0, ["param1"] = 15, ["z"] = 0, ["name"] = "default:desert_sandstone_block"}, {["x"] = 9, ["y"] = 0, ["param1"] = 15, ["z"] = 1, ["name"] = "default:silver_sandstone_block"}, {["x"] = 9, ["y"] = 0, ["param1"] = 15, ["z"] = 2, ["name"] = "default:silver_sandstone_block"}, {["x"] = 9, ["y"] = 0, ["param1"] = 15, ["z"] = 3, ["name"] = "default:silver_sandstone_block"}, {["x"] = 9, ["y"] = 0, ["param1"] = 15, ["z"] = 4, ["name"] = "default:silver_sandstone_block"}, {["x"] = 9, ["y"] = 0, ["param1"] = 15, ["z"] = 5, ["name"] = "default:silver_sandstone_block"}, {["x"] = 9, ["y"] = 0, ["param1"] = 15, ["z"] = 6, ["name"] = "default:silver_sandstone_block"}, {["x"] = 9, ["y"] = 0, ["param1"] = 15, ["z"] = 7, ["name"] = "default:silver_sandstone_block"}, {["x"] = 9, ["y"] = 0, ["param1"] = 15, ["z"] = 8, ["name"] = "default:silver_sandstone_block"}, {["x"] = 9, ["y"] = 0, ["param1"] = 15, ["z"] = 9, ["name"] = "default:silver_sandstone_block"}, {["x"] = 9, ["y"] = 0, ["param1"] = 15, ["z"] = 10, ["name"] = "default:silver_sandstone_block"}, {["x"] = 9, ["y"] = 0, ["param1"] = 15, ["z"] = 11, ["name"] = "default:silver_sandstone_block"}, {["x"] = 9, ["y"] = 0, ["param1"] = 15, ["z"] = 12, ["name"] = "default:silver_sandstone_block"}, {["x"] = 9, ["y"] = 0, ["param1"] = 15, ["z"] = 13, ["name"] = "default:silver_sandstone_block"}, {["x"] = 9, ["y"] = 0, ["param1"] = 15, ["z"] = 14, ["name"] = "default:silver_sandstone_block"}, {["x"] = 9, ["y"] = 0, ["param1"] = 15, ["z"] = 15, ["name"] = "default:silver_sandstone_block"}, {["x"] = 9, ["y"] = 0, ["param1"] = 15, ["z"] = 16, ["name"] = "default:silver_sandstone_block"}, {["x"] = 9, ["y"] = 0, ["param1"] = 15, ["z"] = 17, ["name"] = "default:silver_sandstone_block"}, {["x"] = 9, ["y"] = 0, ["param1"] = 15, ["z"] = 18, ["name"] = "default:silver_sandstone_block"}, {["x"] = 9, ["y"] = 0, ["param1"] = 15, ["z"] = 19, ["name"] = "default:silver_sandstone_block"}, {["x"] = 9, ["y"] = 0, ["param1"] = 15, ["z"] = 20, ["name"] = "default:silver_sandstone_block"}, {["x"] = 9, ["y"] = 0, ["param1"] = 15, ["z"] = 21, ["name"] = "default:silver_sandstone_block"}, {["x"] = 9, ["y"] = 0, ["param1"] = 31, ["z"] = 22, ["name"] = "default:desert_sandstone_block"}, {["x"] = 9, ["meta"] = {["fields"] = {["infotext"] = "\"16\"", ["text"] = "16", ["formspec"] = "field[text;;${text}]"}, ["inventory"] = {}}, ["param2"] = 1, ["y"] = 1, ["param1"] = 15, ["z"] = 2, ["name"] = "default:sign_wall_steel"}, {["x"] = 9, ["y"] = 1, ["z"] = 3, ["name"] = "mesecons_switch:mesecon_switch_on"}, {["x"] = 9, ["param2"] = 3, ["y"] = 1, ["param1"] = 15, ["z"] = 4, ["name"] = "mesecons_insulated:insulated_on"}, {["x"] = 9, ["y"] = 1, ["param1"] = 15, ["z"] = 5, ["name"] = "mesecons_extrawires:corner_on"}, {["x"] = 9, ["y"] = 1, ["param1"] = 15, ["z"] = 6, ["name"] = "digilines:wire_std_10100000"}, {["x"] = 9, ["y"] = 1, ["param1"] = 18, ["z"] = 18, ["name"] = "default:silver_sandstone_block"}, {["x"] = 9, ["y"] = 1, ["param1"] = 79, ["z"] = 19, ["name"] = "digilines:wire_std_10101000"}, {["x"] = 9, ["y"] = 1, ["param1"] = 18, ["z"] = 20, ["name"] = "default:silver_sandstone_block"}, {["x"] = 9, ["y"] = 2, ["param1"] = 18, ["z"] = 18, ["name"] = "default:silver_sandstone_block"}, {["x"] = 9, ["y"] = 2, ["param1"] = 79, ["z"] = 19, ["name"] = "digilines:wire_std_10001000"}, {["x"] = 9, ["y"] = 2, ["param1"] = 18, ["z"] = 20, ["name"] = "default:silver_sandstone_block"}, {["x"] = 9, ["y"] = 3, ["param1"] = 18, ["z"] = 18, ["name"] = "default:silver_sandstone_block"}, {["x"] = 9, ["y"] = 3, ["param1"] = 95, ["z"] = 19, ["name"] = "digilines:wire_std_10001000"}, {["x"] = 9, ["y"] = 3, ["param1"] = 18, ["z"] = 20, ["name"] = "default:silver_sandstone_block"}, {["x"] = 9, ["y"] = 4, ["param1"] = 18, ["z"] = 18, ["name"] = "default:silver_sandstone_block"}, {["x"] = 9, ["y"] = 4, ["param1"] = 111, ["z"] = 19, ["name"] = "digilines:wire_std_10001000"}, {["x"] = 9, ["y"] = 4, ["param1"] = 18, ["z"] = 20, ["name"] = "default:silver_sandstone_block"}, {["x"] = 9, ["y"] = 5, ["param1"] = 18, ["z"] = 18, ["name"] = "default:silver_sandstone_block"}, {["x"] = 9, ["y"] = 5, ["param1"] = 127, ["z"] = 19, ["name"] = "digilines:wire_std_10001000"}, {["x"] = 9, ["y"] = 5, ["param1"] = 18, ["z"] = 20, ["name"] = "default:silver_sandstone_block"}, {["x"] = 9, ["y"] = 6, ["param1"] = 18, ["z"] = 18, ["name"] = "default:silver_sandstone_block"}, {["x"] = 9, ["y"] = 6, ["param1"] = 143, ["z"] = 19, ["name"] = "digilines:wire_std_10001000"}, {["x"] = 9, ["y"] = 6, ["param1"] = 18, ["z"] = 20, ["name"] = "default:silver_sandstone_block"}, {["x"] = 9, ["y"] = 7, ["param1"] = 18, ["z"] = 18, ["name"] = "default:silver_sandstone_block"}, {["x"] = 9, ["y"] = 7, ["param1"] = 159, ["z"] = 19, ["name"] = "digilines:wire_std_10001000"}, {["x"] = 9, ["y"] = 7, ["param1"] = 18, ["z"] = 20, ["name"] = "default:silver_sandstone_block"}, {["x"] = 9, ["y"] = 8, ["param1"] = 46, ["z"] = 17, ["name"] = "mesecons_lightstone:lightstone_darkgray_off"}, {["x"] = 9, ["y"] = 8, ["param1"] = 16, ["z"] = 18, ["name"] = "default:silver_sandstone"}, {["x"] = 9, ["y"] = 8, ["param1"] = 175, ["z"] = 19, ["name"] = "digilines:wire_std_10101010"}, {["x"] = 9, ["y"] = 8, ["param1"] = 16, ["z"] = 20, ["name"] = "default:silver_sandstone"}, {["x"] = 9, ["y"] = 9, ["param1"] = 46, ["z"] = 17, ["name"] = "mesecons_lightstone:lightstone_darkgray_off"}, {["x"] = 9, ["y"] = 9, ["param1"] = 191, ["z"] = 19, ["name"] = "digilines:wire_std_10101010"}, {["x"] = 9, ["y"] = 9, ["param1"] = 16, ["z"] = 20, ["name"] = "default:silver_sandstone"}, {["x"] = 9, ["y"] = 10, ["param1"] = 46, ["z"] = 17, ["name"] = "mesecons_lightstone:lightstone_darkgray_off"}, {["x"] = 9, ["y"] = 10, ["param1"] = 175, ["z"] = 19, ["name"] = "digilines:wire_std_10100000"}, {["x"] = 9, ["y"] = 10, ["param1"] = 16, ["z"] = 20, ["name"] = "default:silver_sandstone"}, {["x"] = 9, ["y"] = 11, ["param1"] = 46, ["z"] = 17, ["name"] = "mesecons_lightstone:lightstone_darkgray_off"}, {["x"] = 9, ["y"] = 11, ["param1"] = 16, ["z"] = 20, ["name"] = "default:silver_sandstone"}, {["x"] = 9, ["y"] = 12, ["param1"] = 46, ["z"] = 17, ["name"] = "mesecons_lightstone:lightstone_darkgray_off"}, {["x"] = 9, ["y"] = 12, ["param1"] = 16, ["z"] = 20, ["name"] = "default:silver_sandstone"}, {["x"] = 9, ["y"] = 13, ["param1"] = 46, ["z"] = 17, ["name"] = "mesecons_lightstone:lightstone_darkgray_off"}, {["x"] = 9, ["y"] = 13, ["param1"] = 16, ["z"] = 20, ["name"] = "default:silver_sandstone"}, {["x"] = 9, ["y"] = 14, ["param1"] = 46, ["z"] = 17, ["name"] = "mesecons_lightstone:lightstone_darkgray_off"}, {["x"] = 9, ["y"] = 14, ["param1"] = 16, ["z"] = 18, ["name"] = "default:silver_sandstone"}, {["x"] = 9, ["y"] = 14, ["param1"] = 239, ["z"] = 19, ["name"] = "default:meselamp"}, {["x"] = 9, ["y"] = 14, ["param1"] = 16, ["z"] = 20, ["name"] = "default:silver_sandstone"}, {["x"] = 10, ["y"] = 0, ["param1"] = 15, ["z"] = 0, ["name"] = "default:desert_sandstone_block"}, {["x"] = 10, ["y"] = 0, ["param1"] = 15, ["z"] = 1, ["name"] = "default:silver_sandstone_block"}, {["x"] = 10, ["y"] = 0, ["param1"] = 15, ["z"] = 2, ["name"] = "default:silver_sandstone_block"}, {["x"] = 10, ["y"] = 0, ["param1"] = 15, ["z"] = 3, ["name"] = "default:silver_sandstone_block"}, {["x"] = 10, ["y"] = 0, ["param1"] = 15, ["z"] = 4, ["name"] = "default:silver_sandstone_block"}, {["x"] = 10, ["y"] = 0, ["param1"] = 15, ["z"] = 5, ["name"] = "default:silver_sandstone_block"}, {["x"] = 10, ["y"] = 0, ["param1"] = 15, ["z"] = 6, ["name"] = "default:silver_sandstone_block"}, {["x"] = 10, ["y"] = 0, ["param1"] = 15, ["z"] = 7, ["name"] = "default:silver_sandstone_block"}, {["x"] = 10, ["y"] = 0, ["param1"] = 15, ["z"] = 8, ["name"] = "default:silver_sandstone_block"}, {["x"] = 10, ["y"] = 0, ["param1"] = 15, ["z"] = 9, ["name"] = "default:silver_sandstone_block"}, {["x"] = 10, ["y"] = 0, ["param1"] = 15, ["z"] = 10, ["name"] = "default:silver_sandstone_block"}, {["x"] = 10, ["y"] = 0, ["param1"] = 15, ["z"] = 11, ["name"] = "default:silver_sandstone_block"}, {["x"] = 10, ["y"] = 0, ["param1"] = 15, ["z"] = 12, ["name"] = "default:silver_sandstone_block"}, {["x"] = 10, ["y"] = 0, ["param1"] = 15, ["z"] = 13, ["name"] = "default:silver_sandstone_block"}, {["x"] = 10, ["y"] = 0, ["param1"] = 15, ["z"] = 14, ["name"] = "default:silver_sandstone_block"}, {["x"] = 10, ["y"] = 0, ["param1"] = 15, ["z"] = 15, ["name"] = "default:silver_sandstone_block"}, {["x"] = 10, ["y"] = 0, ["param1"] = 15, ["z"] = 16, ["name"] = "default:silver_sandstone_block"}, {["x"] = 10, ["y"] = 0, ["param1"] = 15, ["z"] = 17, ["name"] = "default:silver_sandstone_block"}, {["x"] = 10, ["y"] = 0, ["param1"] = 15, ["z"] = 18, ["name"] = "default:silver_sandstone_block"}, {["x"] = 10, ["y"] = 0, ["param1"] = 15, ["z"] = 19, ["name"] = "default:silver_sandstone_block"}, {["x"] = 10, ["y"] = 0, ["param1"] = 15, ["z"] = 20, ["name"] = "default:silver_sandstone_block"}, {["x"] = 10, ["y"] = 0, ["param1"] = 15, ["z"] = 21, ["name"] = "default:silver_sandstone_block"}, {["x"] = 10, ["y"] = 0, ["param1"] = 31, ["z"] = 22, ["name"] = "default:desert_sandstone_block"}, {["x"] = 10, ["meta"] = {["fields"] = {["infotext"] = "\"8\"", ["text"] = "8", ["formspec"] = "field[text;;${text}]"}, ["inventory"] = {}}, ["param2"] = 1, ["y"] = 1, ["param1"] = 15, ["z"] = 2, ["name"] = "default:sign_wall_steel"}, {["x"] = 10, ["y"] = 1, ["z"] = 3, ["name"] = "mesecons_switch:mesecon_switch_on"}, {["x"] = 10, ["param2"] = 3, ["y"] = 1, ["param1"] = 15, ["z"] = 4, ["name"] = "mesecons_insulated:insulated_on"}, {["x"] = 10, ["meta"] = {["fields"] = {["real_portstates"] = "13", ["code"] = "-- Digiline Decoder\
-- Reads an 8 bit binary number (signed or unsigned) from the bus, and converts it to decimal notation\13-- by So.Po.Coder for Minetest Mesecons Lua Controller\13-- B: Digiline Out 1, C: Input 2, D: Input 1\13\13if (event.type == \"program\") then\13  mem.decoder = 3\13end\
\
-- insert this decoders inputs to the table/array then pass on to the next decoder in sequence\13if (event.type == \"digiline\" and event.channel == \"decoder\" .. mem.decoder) then\13  bus = event.msg\13  table.insert(bus, pin.d and 1 or 0)\
  table.insert(bus, pin.c and 1 or 0)\13  digiline_send(\"decoder\" .. tonumber(mem.decoder + 1), bus) -- send to the next decoder\13end", ["formspec"] = "size[12,10]background[-0.2,-0.25;12.4,10.75;jeija_luac_background.png]label[0.1,8.3;]textarea[0.2,0.2;12.2,9.5;code;;-- Digiline Decoder\
-- Reads an 8 bit binary number (signed or unsigned) from the bus\\, and converts it to decimal notation\13-- by So.Po.Coder for Minetest Mesecons Lua Controller\13-- B: Digiline Out 1\\, C: Input 2\\, D: Input 1\13\13if (event.type == \"program\") then\13  mem.decoder = 3\13end\
\
-- insert this decoders inputs to the table/array then pass on to the next decoder in sequence\13if (event.type == \"digiline\" and event.channel == \"decoder\" .. mem.decoder) then\13  bus = event.msg\13  table.insert(bus\\, pin.d and 1 or 0)\
  table.insert(bus\\, pin.c and 1 or 0)\13  digiline_send(\"decoder\" .. tonumber(mem.decoder + 1)\\, bus) -- send to the next decoder\13end]image_button[4.75,8.75;2.5,1;jeija_luac_runbutton.png;program;]image_button_exit[11.72,-0.25;0.425,0.4;jeija_close_window.png;exit;]", ["lc_memory"] = "return {[\"b\"] = false, [\"d\"] = false, [\"decoder\"] = 3, [\"a\"] = false, [\"c\"] = false}", ["luac_id"] = "57673"}, ["inventory"] = {}}, ["y"] = 1, ["param1"] = 15, ["z"] = 5, ["name"] = "mesecons_luacontroller:luacontroller0000"}, {["x"] = 10, ["y"] = 1, ["param1"] = 15, ["z"] = 6, ["name"] = "digilines:wire_std_10110000"}, {["x"] = 10, ["y"] = 1, ["param1"] = 18, ["z"] = 18, ["name"] = "default:silver_sandstone_block"}, {["x"] = 10, ["y"] = 1, ["param1"] = 95, ["z"] = 19, ["name"] = "digilines:wire_std_10100010"}, {["x"] = 10, ["y"] = 1, ["param1"] = 18, ["z"] = 20, ["name"] = "default:silver_sandstone_block"}, {["x"] = 10, ["y"] = 2, ["param1"] = 18, ["z"] = 18, ["name"] = "default:silver_sandstone_block"}, {["x"] = 10, ["y"] = 2, ["param1"] = 79, ["z"] = 19, ["name"] = "digilines:wire_std_10100010"}, {["x"] = 10, ["y"] = 2, ["param1"] = 18, ["z"] = 20, ["name"] = "default:silver_sandstone_block"}, {["x"] = 10, ["y"] = 3, ["param1"] = 18, ["z"] = 18, ["name"] = "default:silver_sandstone_block"}, {["x"] = 10, ["y"] = 3, ["param1"] = 95, ["z"] = 19, ["name"] = "digilines:wire_std_00100010"}, {["x"] = 10, ["y"] = 3, ["param1"] = 18, ["z"] = 20, ["name"] = "default:silver_sandstone_block"}, {["x"] = 10, ["y"] = 4, ["param1"] = 18, ["z"] = 18, ["name"] = "default:silver_sandstone_block"}, {["x"] = 10, ["y"] = 4, ["param1"] = 111, ["z"] = 19, ["name"] = "digilines:wire_std_00100010"}, {["x"] = 10, ["y"] = 4, ["param1"] = 18, ["z"] = 20, ["name"] = "default:silver_sandstone_block"}, {["x"] = 10, ["y"] = 5, ["param1"] = 18, ["z"] = 18, ["name"] = "default:silver_sandstone_block"}, {["x"] = 10, ["y"] = 5, ["param1"] = 127, ["z"] = 19, ["name"] = "digilines:wire_std_00100010"}, {["x"] = 10, ["y"] = 5, ["param1"] = 18, ["z"] = 20, ["name"] = "default:silver_sandstone_block"}, {["x"] = 10, ["y"] = 6, ["param1"] = 18, ["z"] = 18, ["name"] = "default:silver_sandstone_block"}, {["x"] = 10, ["y"] = 6, ["param1"] = 143, ["z"] = 19, ["name"] = "digilines:wire_std_00100010"}, {["x"] = 10, ["y"] = 6, ["param1"] = 18, ["z"] = 20, ["name"] = "default:silver_sandstone_block"}, {["x"] = 10, ["y"] = 7, ["param1"] = 18, ["z"] = 18, ["name"] = "default:silver_sandstone_block"}, {["x"] = 10, ["y"] = 7, ["param1"] = 159, ["z"] = 19, ["name"] = "digilines:wire_std_00100010"}, {["x"] = 10, ["y"] = 7, ["param1"] = 18, ["z"] = 20, ["name"] = "default:silver_sandstone_block"}, {["x"] = 10, ["y"] = 8, ["param1"] = 46, ["z"] = 17, ["name"] = "mesecons_lightstone:lightstone_darkgray_off"}, {["x"] = 10, ["y"] = 8, ["param1"] = 16, ["z"] = 18, ["name"] = "default:silver_sandstone"}, {["x"] = 10, ["y"] = 8, ["param1"] = 175, ["z"] = 19, ["name"] = "digilines:wire_std_10101010"}, {["x"] = 10, ["y"] = 8, ["param1"] = 16, ["z"] = 20, ["name"] = "default:silver_sandstone"}, {["x"] = 10, ["y"] = 9, ["z"] = 17, ["name"] = "mesecons_lightstone:lightstone_darkgray_on"}, {["x"] = 10, ["param2"] = 3, ["y"] = 9, ["param1"] = 190, ["z"] = 18, ["name"] = "mesecons_extrawires:corner_on"}, {["x"] = 10, ["y"] = 9, ["param1"] = 191, ["z"] = 19, ["name"] = "digilines:wire_std_10101010"}, {["x"] = 10, ["y"] = 9, ["param1"] = 16, ["z"] = 20, ["name"] = "default:silver_sandstone"}, {["x"] = 10, ["y"] = 10, ["z"] = 17, ["name"] = "mesecons_lightstone:lightstone_darkgray_off"}, {["x"] = 10, ["param2"] = 3, ["y"] = 10, ["param1"] = 174, ["z"] = 18, ["name"] = "mesecons_extrawires:corner_off"}, {["x"] = 10, ["y"] = 10, ["param1"] = 175, ["z"] = 19, ["name"] = "digilines:wire_std_10101000"}, {["x"] = 10, ["y"] = 10, ["param1"] = 16, ["z"] = 20, ["name"] = "default:silver_sandstone"}, {["x"] = 10, ["y"] = 11, ["z"] = 17, ["name"] = "mesecons_lightstone:lightstone_darkgray_on"}, {["x"] = 10, ["param2"] = 3, ["y"] = 11, ["param1"] = 190, ["z"] = 18, ["name"] = "mesecons_extrawires:corner_on"}, {["x"] = 10, ["y"] = 11, ["param1"] = 16, ["z"] = 20, ["name"] = "default:silver_sandstone"}, {["x"] = 10, ["y"] = 12, ["z"] = 17, ["name"] = "mesecons_lightstone:lightstone_darkgray_on"}, {["x"] = 10, ["param2"] = 3, ["y"] = 12, ["param1"] = 190, ["z"] = 18, ["name"] = "mesecons_extrawires:corner_on"}, {["x"] = 10, ["y"] = 12, ["param1"] = 207, ["z"] = 19, ["name"] = "digilines:wire_std_10001000"}, {["x"] = 10, ["y"] = 12, ["param1"] = 16, ["z"] = 20, ["name"] = "default:silver_sandstone"}, {["x"] = 10, ["y"] = 13, ["z"] = 17, ["name"] = "mesecons_lightstone:lightstone_darkgray_on"}, {["x"] = 10, ["param2"] = 3, ["y"] = 13, ["param1"] = 206, ["z"] = 18, ["name"] = "mesecons_extrawires:corner_on"}, {["x"] = 10, ["y"] = 13, ["param1"] = 223, ["z"] = 19, ["name"] = "digilines:wire_std_10000000"}, {["x"] = 10, ["y"] = 13, ["param1"] = 16, ["z"] = 20, ["name"] = "default:silver_sandstone"}, {["x"] = 10, ["y"] = 14, ["param1"] = 46, ["z"] = 17, ["name"] = "mesecons_lightstone:lightstone_darkgray_off"}, {["x"] = 10, ["y"] = 14, ["param1"] = 16, ["z"] = 18, ["name"] = "default:silver_sandstone"}, {["x"] = 10, ["y"] = 14, ["param1"] = 239, ["z"] = 19, ["name"] = "default:meselamp"}, {["x"] = 10, ["y"] = 14, ["param1"] = 16, ["z"] = 20, ["name"] = "default:silver_sandstone"}, {["x"] = 11, ["y"] = 0, ["param1"] = 15, ["z"] = 0, ["name"] = "default:desert_sandstone_block"}, {["x"] = 11, ["y"] = 0, ["param1"] = 15, ["z"] = 1, ["name"] = "default:silver_sandstone_block"}, {["x"] = 11, ["y"] = 0, ["param1"] = 15, ["z"] = 2, ["name"] = "default:silver_sandstone_block"}, {["x"] = 11, ["y"] = 0, ["param1"] = 15, ["z"] = 3, ["name"] = "default:silver_sandstone_block"}, {["x"] = 11, ["y"] = 0, ["param1"] = 15, ["z"] = 4, ["name"] = "default:silver_sandstone_block"}, {["x"] = 11, ["y"] = 0, ["param1"] = 15, ["z"] = 5, ["name"] = "default:silver_sandstone_block"}, {["x"] = 11, ["y"] = 0, ["param1"] = 15, ["z"] = 6, ["name"] = "default:silver_sandstone_block"}, {["x"] = 11, ["y"] = 0, ["param1"] = 15, ["z"] = 7, ["name"] = "default:silver_sandstone_block"}, {["x"] = 11, ["y"] = 0, ["param1"] = 15, ["z"] = 8, ["name"] = "default:silver_sandstone_block"}, {["x"] = 11, ["y"] = 0, ["param1"] = 15, ["z"] = 9, ["name"] = "default:silver_sandstone_block"}, {["x"] = 11, ["y"] = 0, ["param1"] = 15, ["z"] = 10, ["name"] = "default:silver_sandstone_block"}, {["x"] = 11, ["y"] = 0, ["param1"] = 15, ["z"] = 11, ["name"] = "default:silver_sandstone_block"}, {["x"] = 11, ["y"] = 0, ["param1"] = 15, ["z"] = 12, ["name"] = "default:silver_sandstone_block"}, {["x"] = 11, ["y"] = 0, ["param1"] = 15, ["z"] = 13, ["name"] = "default:silver_sandstone_block"}, {["x"] = 11, ["y"] = 0, ["param1"] = 15, ["z"] = 14, ["name"] = "default:silver_sandstone_block"}, {["x"] = 11, ["y"] = 0, ["param1"] = 15, ["z"] = 15, ["name"] = "default:silver_sandstone_block"}, {["x"] = 11, ["y"] = 0, ["param1"] = 15, ["z"] = 16, ["name"] = "default:silver_sandstone_block"}, {["x"] = 11, ["y"] = 0, ["param1"] = 15, ["z"] = 17, ["name"] = "default:silver_sandstone_block"}, {["x"] = 11, ["y"] = 0, ["param1"] = 15, ["z"] = 18, ["name"] = "default:silver_sandstone_block"}, {["x"] = 11, ["y"] = 0, ["param1"] = 15, ["z"] = 19, ["name"] = "default:silver_sandstone_block"}, {["x"] = 11, ["y"] = 0, ["param1"] = 15, ["z"] = 20, ["name"] = "default:silver_sandstone_block"}, {["x"] = 11, ["y"] = 0, ["param1"] = 15, ["z"] = 21, ["name"] = "default:silver_sandstone_block"}, {["x"] = 11, ["y"] = 0, ["param1"] = 47, ["z"] = 22, ["name"] = "default:desert_sandstone_block"}, {["x"] = 11, ["meta"] = {["fields"] = {["infotext"] = "\"4\"", ["text"] = "4", ["formspec"] = "field[text;;${text}]"}, ["inventory"] = {}}, ["param2"] = 1, ["y"] = 1, ["param1"] = 15, ["z"] = 2, ["name"] = "default:sign_wall_steel"}, {["x"] = 11, ["y"] = 1, ["z"] = 3, ["name"] = "mesecons_switch:mesecon_switch_on"}, {["x"] = 11, ["param2"] = 3, ["y"] = 1, ["param1"] = 15, ["z"] = 4, ["name"] = "mesecons_insulated:insulated_on"}, {["x"] = 11, ["y"] = 1, ["param1"] = 15, ["z"] = 5, ["name"] = "mesecons_extrawires:corner_on"}, {["x"] = 11, ["y"] = 1, ["param1"] = 15, ["z"] = 6, ["name"] = "digilines:wire_std_10100000"}, {["x"] = 11, ["y"] = 1, ["param1"] = 18, ["z"] = 18, ["name"] = "default:silver_sandstone_block"}, {["x"] = 11, ["y"] = 1, ["param1"] = 110, ["z"] = 19, ["name"] = "digilines:wire_std_10100010"}, {["x"] = 11, ["y"] = 1, ["param1"] = 18, ["z"] = 20, ["name"] = "default:silver_sandstone_block"}, {["x"] = 11, ["y"] = 2, ["param1"] = 18, ["z"] = 18, ["name"] = "default:silver_sandstone_block"}, {["x"] = 11, ["y"] = 2, ["param1"] = 18, ["z"] = 19, ["name"] = "default:silver_sandstone_block"}, {["x"] = 11, ["y"] = 2, ["param1"] = 18, ["z"] = 20, ["name"] = "default:silver_sandstone_block"}, {["x"] = 11, ["y"] = 3, ["param1"] = 18, ["z"] = 18, ["name"] = "default:silver_sandstone_block"}, {["x"] = 11, ["y"] = 3, ["param1"] = 18, ["z"] = 19, ["name"] = "default:silver_sandstone_block"}, {["x"] = 11, ["y"] = 3, ["param1"] = 18, ["z"] = 20, ["name"] = "default:silver_sandstone_block"}, {["x"] = 11, ["y"] = 4, ["param1"] = 18, ["z"] = 18, ["name"] = "default:silver_sandstone_block"}, {["x"] = 11, ["y"] = 4, ["param1"] = 18, ["z"] = 19, ["name"] = "default:silver_sandstone_block"}, {["x"] = 11, ["y"] = 4, ["param1"] = 18, ["z"] = 20, ["name"] = "default:silver_sandstone_block"}, {["x"] = 11, ["y"] = 5, ["param1"] = 18, ["z"] = 18, ["name"] = "default:silver_sandstone_block"}, {["x"] = 11, ["y"] = 5, ["param1"] = 18, ["z"] = 19, ["name"] = "default:silver_sandstone_block"}, {["x"] = 11, ["y"] = 5, ["param1"] = 18, ["z"] = 20, ["name"] = "default:silver_sandstone_block"}, {["x"] = 11, ["y"] = 6, ["param1"] = 18, ["z"] = 18, ["name"] = "default:silver_sandstone_block"}, {["x"] = 11, ["y"] = 6, ["param1"] = 18, ["z"] = 19, ["name"] = "default:silver_sandstone_block"}, {["x"] = 11, ["y"] = 6, ["param1"] = 18, ["z"] = 20, ["name"] = "default:silver_sandstone_block"}, {["x"] = 11, ["y"] = 7, ["param1"] = 18, ["z"] = 18, ["name"] = "default:silver_sandstone_block"}, {["x"] = 11, ["y"] = 7, ["param1"] = 18, ["z"] = 19, ["name"] = "default:silver_sandstone_block"}, {["x"] = 11, ["y"] = 7, ["param1"] = 18, ["z"] = 20, ["name"] = "default:silver_sandstone_block"}, {["x"] = 11, ["y"] = 8, ["param1"] = 46, ["z"] = 17, ["name"] = "mesecons_lightstone:lightstone_darkgray_off"}, {["x"] = 11, ["y"] = 8, ["param1"] = 16, ["z"] = 18, ["name"] = "default:silver_sandstone"}, {["x"] = 11, ["y"] = 8, ["param1"] = 16, ["z"] = 19, ["name"] = "default:silver_sandstone"}, {["x"] = 11, ["y"] = 8, ["param1"] = 16, ["z"] = 20, ["name"] = "default:silver_sandstone"}, {["x"] = 11, ["y"] = 9, ["z"] = 17, ["name"] = "mesecons_lightstone:lightstone_darkgray_on"}, {["x"] = 11, ["meta"] = {["fields"] = {["real_portstates"] = "1", ["code"] = "if (event.type == \"program\") then\13  mem.A = {[0]=true, [2]=true, [3]=true, [5]=true, [6]=true, [8]=true, [9]=true}\13  mem.D = {[0]=true, [1]=true, [2]=true, [3]=true, [5]=true, [6]=true, [8]=true, [9]=true}\13  mem.C = {[0]=true, [2]=true, [3]=true, [4]=true, [5]=true, [6]=true, [7]=true, [8]=true, [9]=true}\13end\
\
if (event.type == \"digiline\" and event.channel == \"display\") then\13  x = event.msg.ten\13  port.a = mem.A[x]\
  port.d = mem.D[x]\13  port.c = mem.C[x]\13end", ["formspec"] = "size[12,10]background[-0.2,-0.25;12.4,10.75;jeija_luac_background.png]label[0.1,8.3;]textarea[0.2,0.2;12.2,9.5;code;;if (event.type == \"program\") then\13  mem.A = {\\[0\\]=true\\, \\[2\\]=true\\, \\[3\\]=true\\, \\[5\\]=true\\, \\[6\\]=true\\, \\[8\\]=true\\, \\[9\\]=true}\13  mem.D = {\\[0\\]=true\\, \\[1\\]=true\\, \\[2\\]=true\\, \\[3\\]=true\\, \\[5\\]=true\\, \\[6\\]=true\\, \\[8\\]=true\\, \\[9\\]=true}\13  mem.C = {\\[0\\]=true\\, \\[2\\]=true\\, \\[3\\]=true\\, \\[4\\]=true\\, \\[5\\]=true\\, \\[6\\]=true\\, \\[7\\]=true\\, \\[8\\]=true\\, \\[9\\]=true}\13end\
\
if (event.type == \"digiline\" and event.channel == \"display\") then\13  x = event.msg.ten\13  port.a = mem.A\\[x\\]\
  port.d = mem.D\\[x\\]\13  port.c = mem.C\\[x\\]\13end]image_button[4.75,8.75;2.5,1;jeija_luac_runbutton.png;program;]image_button_exit[11.72,-0.25;0.425,0.4;jeija_close_window.png;exit;]", ["ignore_offevents"] = "return {[\"B\"] = true, [\"C\"] = true, [\"A\"] = true, [\"D\"] = true}", ["lc_memory"] = "return {[\"B\"] = {[0] = true, [2] = true, [3] = true, [5] = true, [6] = true, [8] = true, [9] = true}, [\"C\"] = {[0] = true, [2] = true, [3] = true, [4] = true, [5] = true, [6] = true, [7] = true, [8] = true, [9] = true}, [\"A\"] = {[0] = true, [2] = true, [3] = true, [5] = true, [6] = true, [8] = true, [9] = true}, [\"D\"] = {true, true, true, [0] = true, [5] = true, [6] = true, [8] = true, [9] = true}}", ["luac_id"] = "3689"}, ["inventory"] = {}}, ["y"] = 9, ["param1"] = 189, ["z"] = 18, ["name"] = "mesecons_luacontroller:luacontroller1101"}, {["x"] = 11, ["y"] = 9, ["param1"] = 206, ["z"] = 19, ["name"] = "digilines:wire_std_10111011"}, {["x"] = 11, ["y"] = 9, ["param1"] = 16, ["z"] = 20, ["name"] = "default:silver_sandstone"}, {["x"] = 11, ["y"] = 10, ["z"] = 17, ["name"] = "mesecons_lightstone:lightstone_darkgray_off"}, {["x"] = 11, ["meta"] = {["fields"] = {["real_portstates"] = "1", ["code"] = "if event.type == \"program\" then\13  mem.A = {[0]=true, [2]=true, [6]=true, [8]=true}\
  mem.D = {[1]=true}\13  mem.C = {[0]=true, [3]=true, [4]=true, [5]=true, [6]=true, [7]=true, [8]=true, [9]=true}\13end\
if (event.type == \"digiline\" and event.channel == \"display\") then\13  x = event.msg.ten\13  port.a = mem.A[x]\
  port.d = mem.D[x]\13  port.c = mem.C[x]\13end", ["formspec"] = "size[12,10]background[-0.2,-0.25;12.4,10.75;jeija_luac_background.png]label[0.1,8.3;]textarea[0.2,0.2;12.2,9.5;code;;if event.type == \"program\" then\13  mem.A = {\\[0\\]=true\\, \\[2\\]=true\\, \\[6\\]=true\\, \\[8\\]=true}\
  mem.D = {\\[1\\]=true}\13  mem.C = {\\[0\\]=true\\, \\[3\\]=true\\, \\[4\\]=true\\, \\[5\\]=true\\, \\[6\\]=true\\, \\[7\\]=true\\, \\[8\\]=true\\, \\[9\\]=true}\13end\
if (event.type == \"digiline\" and event.channel == \"display\") then\13  x = event.msg.ten\13  port.a = mem.A\\[x\\]\
  port.d = mem.D\\[x\\]\13  port.c = mem.C\\[x\\]\13end]image_button[4.75,8.75;2.5,1;jeija_luac_runbutton.png;program;]image_button_exit[11.72,-0.25;0.425,0.4;jeija_close_window.png;exit;]", ["ignore_offevents"] = "return {[\"B\"] = true, [\"D\"] = true, [\"C\"] = true}", ["lc_memory"] = "return {[\"B\"] = {[0] = true, [2] = true, [3] = true, [4] = true, [5] = true, [6] = true, [8] = true, [9] = true}, [\"accept2\"] = {true, [0] = true, [3] = true, [4] = true, [5] = true, [6] = true, [7] = true, [8] = true, [9] = true}, [\"accept1\"] = {[0] = true, [2] = true, [6] = true, [8] = true}, [\"D\"] = {true}, [\"A\"] = {[0] = true, [2] = true, [6] = true, [8] = true}, [\"C\"] = {[0] = true, [3] = true, [4] = true, [5] = true, [6] = true, [7] = true, [8] = true, [9] = true}}", ["luac_id"] = "22375"}, ["inventory"] = {}}, ["y"] = 10, ["param1"] = 173, ["z"] = 18, ["name"] = "mesecons_luacontroller:luacontroller0100"}, {["x"] = 11, ["y"] = 10, ["param1"] = 190, ["z"] = 19, ["name"] = "digilines:wire_std_10110001"}, {["x"] = 11, ["y"] = 10, ["param1"] = 16, ["z"] = 20, ["name"] = "default:silver_sandstone"}, {["x"] = 11, ["y"] = 11, ["z"] = 17, ["name"] = "mesecons_lightstone:lightstone_darkgray_on"}, {["x"] = 11, ["meta"] = {["fields"] = {["real_portstates"] = "1", ["code"] = "if event.type == \"program\" then\13  mem.A = {[0]=true, [2]=true, [3]=true, [4]=true, [5]=true, [6]=true, [8]=true, [9]=true}\13  mem.D = {[2]=true, [1]=true, [3]=true, [4]=true, [5]=true, [6]=true, [8]=true, [9]=true}\13  mem.C = {[0]=true, [2]=true, [3]=true, [4]=true, [5]=true, [6]=true, [7]=true, [8]=true, [9]=true}\13end\
if (event.type == \"digiline\" and event.channel == \"display\") then\13  x = event.msg.ten\13  port.a = mem.A[x]\13  port.d = mem.D[x]\13  port.c = mem.C[x]\13end", ["formspec"] = "size[12,10]background[-0.2,-0.25;12.4,10.75;jeija_luac_background.png]label[0.1,8.3;]textarea[0.2,0.2;12.2,9.5;code;;if event.type == \"program\" then\13  mem.A = {\\[0\\]=true\\, \\[2\\]=true\\, \\[3\\]=true\\, \\[4\\]=true\\, \\[5\\]=true\\, \\[6\\]=true\\, \\[8\\]=true\\, \\[9\\]=true}\13  mem.D = {\\[2\\]=true\\, \\[1\\]=true\\, \\[3\\]=true\\, \\[4\\]=true\\, \\[5\\]=true\\, \\[6\\]=true\\, \\[8\\]=true\\, \\[9\\]=true}\13  mem.C = {\\[0\\]=true\\, \\[2\\]=true\\, \\[3\\]=true\\, \\[4\\]=true\\, \\[5\\]=true\\, \\[6\\]=true\\, \\[7\\]=true\\, \\[8\\]=true\\, \\[9\\]=true}\13end\
if (event.type == \"digiline\" and event.channel == \"display\") then\13  x = event.msg.ten\13  port.a = mem.A\\[x\\]\13  port.d = mem.D\\[x\\]\13  port.c = mem.C\\[x\\]\13end]image_button[4.75,8.75;2.5,1;jeija_luac_runbutton.png;program;]image_button_exit[11.72,-0.25;0.425,0.4;jeija_close_window.png;exit;]", ["ignore_offevents"] = "return {[\"D\"] = true, [\"A\"] = true, [\"C\"] = true}", ["lc_memory"] = "return {[\"B\"] = {[0] = true, [2] = true, [3] = true, [4] = true, [5] = true, [6] = true, [8] = true, [9] = true}, [\"D\"] = {true, true, true, true, true, true, [8] = true, [9] = true}, [\"A\"] = {[0] = true, [2] = true, [3] = true, [4] = true, [5] = true, [6] = true, [8] = true, [9] = true}, [\"C\"] = {[0] = true, [2] = true, [3] = true, [4] = true, [5] = true, [6] = true, [7] = true, [8] = true, [9] = true}}", ["luac_id"] = "22581"}, ["inventory"] = {}}, ["y"] = 11, ["param1"] = 189, ["z"] = 18, ["name"] = "mesecons_luacontroller:luacontroller1101"}, {["x"] = 11, ["y"] = 11, ["param1"] = 174, ["z"] = 19, ["name"] = "digilines:wire_std_10110011"}, {["x"] = 11, ["y"] = 11, ["param1"] = 16, ["z"] = 20, ["name"] = "default:silver_sandstone"}, {["x"] = 11, ["y"] = 12, ["z"] = 17, ["name"] = "mesecons_lightstone:lightstone_darkgray_off"}, {["x"] = 11, ["meta"] = {["fields"] = {["real_portstates"] = "1", ["code"] = "if event.type == \"program\" then\13  mem.A = {[0]=true, [4]=true, [5]=true, [6]=true, [8]=true, [9]=true}\
  mem.D = {[1] = true}\13  mem.C = {[0]=true, [2]=true, [3]=true, [4]=true, [7]=true, [8]=true, [9]=true}\13end\
if (event.type == \"digiline\" and event.channel == \"display\") then\13  x = event.msg.ten\13  port.a = mem.A[x]\
  port.d = mem.D[x]\13  port.c = mem.C[x]\13end", ["formspec"] = "size[12,10]background[-0.2,-0.25;12.4,10.75;jeija_luac_background.png]label[0.1,8.3;]textarea[0.2,0.2;12.2,9.5;code;;if event.type == \"program\" then\13  mem.A = {\\[0\\]=true\\, \\[4\\]=true\\, \\[5\\]=true\\, \\[6\\]=true\\, \\[8\\]=true\\, \\[9\\]=true}\
  mem.D = {\\[1\\] = true}\13  mem.C = {\\[0\\]=true\\, \\[2\\]=true\\, \\[3\\]=true\\, \\[4\\]=true\\, \\[7\\]=true\\, \\[8\\]=true\\, \\[9\\]=true}\13end\
if (event.type == \"digiline\" and event.channel == \"display\") then\13  x = event.msg.ten\13  port.a = mem.A\\[x\\]\
  port.d = mem.D\\[x\\]\13  port.c = mem.C\\[x\\]\13end]image_button[4.75,8.75;2.5,1;jeija_luac_runbutton.png;program;]image_button_exit[11.72,-0.25;0.425,0.4;jeija_close_window.png;exit;]", ["ignore_offevents"] = "return {[\"D\"] = true, [\"A\"] = true}", ["lc_memory"] = "return {[\"accept2\"] = {true, true, true, true, [0] = true, [7] = true, [8] = true, [9] = true}, [\"accept1\"] = {[0] = true, [4] = true, [5] = true, [6] = true, [8] = true, [9] = true}, [\"D\"] = {true}, [\"A\"] = {[0] = true, [4] = true, [5] = true, [6] = true, [8] = true, [9] = true}, [\"C\"] = {[0] = true, [2] = true, [3] = true, [4] = true, [7] = true, [8] = true, [9] = true}}", ["luac_id"] = "9186"}, ["inventory"] = {}}, ["y"] = 12, ["param1"] = 173, ["z"] = 18, ["name"] = "mesecons_luacontroller:luacontroller0001"}, {["x"] = 11, ["y"] = 12, ["param1"] = 190, ["z"] = 19, ["name"] = "digilines:wire_std_00110011"}, {["x"] = 11, ["y"] = 12, ["param1"] = 16, ["z"] = 20, ["name"] = "default:silver_sandstone"}, {["x"] = 11, ["y"] = 13, ["z"] = 17, ["name"] = "mesecons_lightstone:lightstone_darkgray_on"}, {["x"] = 11, ["meta"] = {["fields"] = {["real_portstates"] = "1", ["code"] = "if event.type == \"program\" then\13  mem.A = {[0]=true, [2]=true, [3]=true, [4]=true, [5]=true, [6]=true, [7]=true, [8]=true, [9]=true}\13  mem.D = {[0]=true, [1]=true, [2]=true, [3]=true, [5]=true, [6]=true, [7]=true, [8]=true, [9]=true}\13  mem.C = {[0]=true, [2]=true, [3]=true, [4]=true, [5]=true, [6]=true, [7]=true, [8]=true, [9]=true}\13end\
if (event.type == \"digiline\" and event.channel == \"display\") then\13  x = event.msg.ten\13  port.a = mem.A[x]\13  port.d = mem.D[x]\13  port.c = mem.C[x]\13end", ["formspec"] = "size[12,10]background[-0.2,-0.25;12.4,10.75;jeija_luac_background.png]label[0.1,8.3;]textarea[0.2,0.2;12.2,9.5;code;;if event.type == \"program\" then\13  mem.A = {\\[0\\]=true\\, \\[2\\]=true\\, \\[3\\]=true\\, \\[4\\]=true\\, \\[5\\]=true\\, \\[6\\]=true\\, \\[7\\]=true\\, \\[8\\]=true\\, \\[9\\]=true}\13  mem.D = {\\[0\\]=true\\, \\[1\\]=true\\, \\[2\\]=true\\, \\[3\\]=true\\, \\[5\\]=true\\, \\[6\\]=true\\, \\[7\\]=true\\, \\[8\\]=true\\, \\[9\\]=true}\13  mem.C = {\\[0\\]=true\\, \\[2\\]=true\\, \\[3\\]=true\\, \\[4\\]=true\\, \\[5\\]=true\\, \\[6\\]=true\\, \\[7\\]=true\\, \\[8\\]=true\\, \\[9\\]=true}\13end\
if (event.type == \"digiline\" and event.channel == \"display\") then\13  x = event.msg.ten\13  port.a = mem.A\\[x\\]\13  port.d = mem.D\\[x\\]\13  port.c = mem.C\\[x\\]\13end]image_button[4.75,8.75;2.5,1;jeija_luac_runbutton.png;program;]image_button_exit[11.72,-0.25;0.425,0.4;jeija_close_window.png;exit;]", ["ignore_offevents"] = "return {[\"D\"] = true, [\"A\"] = true, [\"C\"] = true}", ["lc_memory"] = "return {[\"B\"] = {[0] = true, [2] = true, [3] = true, [4] = true, [5] = true, [6] = true, [7] = true, [8] = true, [9] = true}, [\"C\"] = {[0] = true, [2] = true, [3] = true, [4] = true, [5] = true, [6] = true, [7] = true, [8] = true, [9] = true}, [\"A\"] = {[0] = true, [2] = true, [3] = true, [4] = true, [5] = true, [6] = true, [7] = true, [8] = true, [9] = true}, [\"D\"] = {true, true, true, [0] = true, [5] = true, [6] = true, [7] = true, [8] = true, [9] = true}}", ["luac_id"] = "60540"}, ["inventory"] = {}}, ["y"] = 13, ["param1"] = 189, ["z"] = 18, ["name"] = "mesecons_luacontroller:luacontroller1101"}, {["x"] = 11, ["y"] = 13, ["param1"] = 206, ["z"] = 19, ["name"] = "digilines:wire_std_00110000"}, {["x"] = 11, ["y"] = 13, ["param1"] = 16, ["z"] = 20, ["name"] = "default:silver_sandstone"}, {["x"] = 11, ["y"] = 14, ["param1"] = 46, ["z"] = 17, ["name"] = "mesecons_lightstone:lightstone_darkgray_off"}, {["x"] = 11, ["y"] = 14, ["param1"] = 16, ["z"] = 18, ["name"] = "default:silver_sandstone"}, {["x"] = 11, ["y"] = 14, ["param1"] = 16, ["z"] = 19, ["name"] = "default:silver_sandstone"}, {["x"] = 11, ["y"] = 14, ["param1"] = 16, ["z"] = 20, ["name"] = "default:silver_sandstone"}, {["x"] = 12, ["y"] = 0, ["param1"] = 15, ["z"] = 0, ["name"] = "default:desert_sandstone_block"}, {["x"] = 12, ["y"] = 0, ["param1"] = 15, ["z"] = 1, ["name"] = "default:silver_sandstone_block"}, {["x"] = 12, ["y"] = 0, ["param1"] = 15, ["z"] = 2, ["name"] = "default:silver_sandstone_block"}, {["x"] = 12, ["y"] = 0, ["param1"] = 15, ["z"] = 3, ["name"] = "default:silver_sandstone_block"}, {["x"] = 12, ["y"] = 0, ["param1"] = 15, ["z"] = 4, ["name"] = "default:silver_sandstone_block"}, {["x"] = 12, ["y"] = 0, ["param1"] = 15, ["z"] = 5, ["name"] = "default:silver_sandstone_block"}, {["x"] = 12, ["y"] = 0, ["param1"] = 15, ["z"] = 6, ["name"] = "default:silver_sandstone_block"}, {["x"] = 12, ["y"] = 0, ["param1"] = 15, ["z"] = 7, ["name"] = "default:silver_sandstone_block"}, {["x"] = 12, ["y"] = 0, ["param1"] = 15, ["z"] = 8, ["name"] = "default:silver_sandstone_block"}, {["x"] = 12, ["y"] = 0, ["param1"] = 15, ["z"] = 9, ["name"] = "default:silver_sandstone_block"}, {["x"] = 12, ["y"] = 0, ["param1"] = 15, ["z"] = 10, ["name"] = "default:silver_sandstone_block"}, {["x"] = 12, ["y"] = 0, ["param1"] = 15, ["z"] = 11, ["name"] = "default:silver_sandstone_block"}, {["x"] = 12, ["y"] = 0, ["param1"] = 15, ["z"] = 12, ["name"] = "default:silver_sandstone_block"}, {["x"] = 12, ["y"] = 0, ["param1"] = 15, ["z"] = 13, ["name"] = "default:silver_sandstone_block"}, {["x"] = 12, ["y"] = 0, ["param1"] = 15, ["z"] = 14, ["name"] = "default:silver_sandstone_block"}, {["x"] = 12, ["y"] = 0, ["param1"] = 15, ["z"] = 15, ["name"] = "default:silver_sandstone_block"}, {["x"] = 12, ["y"] = 0, ["param1"] = 15, ["z"] = 16, ["name"] = "default:silver_sandstone_block"}, {["x"] = 12, ["y"] = 0, ["param1"] = 15, ["z"] = 17, ["name"] = "default:silver_sandstone_block"}, {["x"] = 12, ["y"] = 0, ["param1"] = 15, ["z"] = 18, ["name"] = "default:silver_sandstone_block"}, {["x"] = 12, ["y"] = 0, ["param1"] = 15, ["z"] = 19, ["name"] = "default:silver_sandstone_block"}, {["x"] = 12, ["y"] = 0, ["param1"] = 15, ["z"] = 20, ["name"] = "default:silver_sandstone_block"}, {["x"] = 12, ["y"] = 0, ["param1"] = 15, ["z"] = 21, ["name"] = "default:silver_sandstone_block"}, {["x"] = 12, ["y"] = 0, ["param1"] = 63, ["z"] = 22, ["name"] = "default:desert_sandstone_block"}, {["x"] = 12, ["meta"] = {["fields"] = {["infotext"] = "\"2\"", ["text"] = "2", ["formspec"] = "field[text;;${text}]"}, ["inventory"] = {}}, ["param2"] = 1, ["y"] = 1, ["param1"] = 15, ["z"] = 2, ["name"] = "default:sign_wall_steel"}, {["x"] = 12, ["y"] = 1, ["z"] = 3, ["name"] = "mesecons_switch:mesecon_switch_off"}, {["x"] = 12, ["param2"] = 3, ["y"] = 1, ["param1"] = 15, ["z"] = 4, ["name"] = "mesecons_insulated:insulated_off"}, {["x"] = 12, ["meta"] = {["fields"] = {["real_portstates"] = "4", ["code"] = "-- Digiline Decoder\
-- Reads an 8 bit binary number (signed or unsigned) from the bus, and converts it to decimal notation\13-- by So.Po.Coder for Minetest Mesecons Lua Controller\13-- B: Digiline Out 1, C: Input 2, D: Input 1\13\13if (event.type == \"program\") then\13  mem.decoder = 4\13end\
\
-- insert this decoders inputs to the table/array then pass on to the next decoder in sequence\13if (event.type == \"digiline\" and event.channel == \"decoder\" .. mem.decoder) then\13  bus = event.msg\13  table.insert(bus, pin.d and 1 or 0)\
  table.insert(bus, pin.c and 1 or 0)\13  digiline_send(\"decoder\" .. tonumber(mem.decoder + 1), bus) -- send to the next decoder\13end", ["formspec"] = "size[12,10]background[-0.2,-0.25;12.4,10.75;jeija_luac_background.png]label[0.1,8.3;]textarea[0.2,0.2;12.2,9.5;code;;-- Digiline Decoder\
-- Reads an 8 bit binary number (signed or unsigned) from the bus\\, and converts it to decimal notation\13-- by So.Po.Coder for Minetest Mesecons Lua Controller\13-- B: Digiline Out 1\\, C: Input 2\\, D: Input 1\13\13if (event.type == \"program\") then\13  mem.decoder = 4\13end\
\
-- insert this decoders inputs to the table/array then pass on to the next decoder in sequence\13if (event.type == \"digiline\" and event.channel == \"decoder\" .. mem.decoder) then\13  bus = event.msg\13  table.insert(bus\\, pin.d and 1 or 0)\
