5:return {{["x"] = 1, ["y"] = 0, ["param1"] = 16, ["z"] = 1, ["name"] = "default:silver_sandstone"}, {["x"] = 1, ["y"] = 0, ["param1"] = 16, ["z"] = 2, ["name"] = "default:silver_sandstone"}, {["x"] = 1, ["y"] = 0, ["param1"] = 16, ["z"] = 3, ["name"] = "default:silver_sandstone"}, {["x"] = 1, ["y"] = 0, ["param1"] = 16, ["z"] = 4, ["name"] = "default:silver_sandstone"}, {["x"] = 1, ["y"] = 0, ["param1"] = 16, ["z"] = 5, ["name"] = "default:silver_sandstone"}, {["x"] = 1, ["y"] = 0, ["param1"] = 16, ["z"] = 6, ["name"] = "default:silver_sandstone"}, {["x"] = 1, ["y"] = 0, ["param1"] = 16, ["z"] = 7, ["name"] = "default:silver_sandstone"}, {["x"] = 1, ["y"] = 0, ["param1"] = 16, ["z"] = 8, ["name"] = "default:silver_sandstone"}, {["x"] = 1, ["y"] = 0, ["param1"] = 16, ["z"] = 9, ["name"] = "default:silver_sandstone"}, {["x"] = 1, ["y"] = 0, ["param1"] = 16, ["z"] = 10, ["name"] = "default:silver_sandstone"}, {["x"] = 1, ["y"] = 0, ["param1"] = 16, ["z"] = 11, ["name"] = "default:silver_sandstone"}, {["x"] = 1, ["y"] = 0, ["param1"] = 16, ["z"] = 12, ["name"] = "default:silver_sandstone"}, {["x"] = 1, ["y"] = 0, ["param1"] = 16, ["z"] = 13, ["name"] = "default:silver_sandstone"}, {["x"] = 1, ["y"] = 0, ["param1"] = 16, ["z"] = 14, ["name"] = "default:silver_sandstone"}, {["x"] = 1, ["y"] = 0, ["param1"] = 16, ["z"] = 15, ["name"] = "default:silver_sandstone"}, {["x"] = 1, ["y"] = 0, ["param1"] = 16, ["z"] = 16, ["name"] = "default:silver_sandstone"}, {["x"] = 1, ["y"] = 0, ["param1"] = 16, ["z"] = 17, ["name"] = "default:silver_sandstone"}, {["x"] = 1, ["y"] = 0, ["param1"] = 16, ["z"] = 18, ["name"] = "default:silver_sandstone"}, {["x"] = 1, ["y"] = 0, ["param1"] = 16, ["z"] = 19, ["name"] = "default:silver_sandstone"}, {["x"] = 1, ["y"] = 0, ["param1"] = 16, ["z"] = 20, ["name"] = "default:silver_sandstone"}, {["x"] = 1, ["y"] = 0, ["param1"] = 16, ["z"] = 21, ["name"] = "default:silver_sandstone"}, {["x"] = 1, ["y"] = 0, ["param1"] = 16, ["z"] = 22, ["name"] = "default:silver_sandstone"}, {["x"] = 1, ["y"] = 0, ["param1"] = 16, ["z"] = 23, ["name"] = "default:silver_sandstone"}, {["x"] = 1, ["y"] = 0, ["param1"] = 16, ["z"] = 24, ["name"] = "default:silver_sandstone"}, {["x"] = 1, ["y"] = 0, ["param1"] = 16, ["z"] = 25, ["name"] = "default:silver_sandstone"}, {["x"] = 1, ["y"] = 0, ["param1"] = 16, ["z"] = 26, ["name"] = "default:silver_sandstone"}, {["x"] = 1, ["y"] = 0, ["param1"] = 16, ["z"] = 27, ["name"] = "default:silver_sandstone"}, {["x"] = 1, ["y"] = 0, ["param1"] = 16, ["z"] = 28, ["name"] = "default:silver_sandstone"}, {["x"] = 1, ["y"] = 0, ["param1"] = 16, ["z"] = 29, ["name"] = "default:silver_sandstone"}, {["x"] = 1, ["y"] = 0, ["param1"] = 16, ["z"] = 30, ["name"] = "default:silver_sandstone"}, {["x"] = 1, ["y"] = 0, ["param1"] = 16, ["z"] = 31, ["name"] = "default:silver_sandstone"}, {["x"] = 1, ["y"] = 0, ["param1"] = 16, ["z"] = 32, ["name"] = "default:silver_sandstone"}, {["x"] = 1, ["y"] = 0, ["param1"] = 16, ["z"] = 33, ["name"] = "default:silver_sandstone"}, {["x"] = 1, ["y"] = 0, ["param1"] = 16, ["z"] = 34, ["name"] = "default:silver_sandstone"}, {["x"] = 1, ["y"] = 0, ["param1"] = 16, ["z"] = 35, ["name"] = "default:silver_sandstone"}, {["x"] = 1, ["y"] = 0, ["param1"] = 16, ["z"] = 36, ["name"] = "default:silver_sandstone"}, {["x"] = 1, ["y"] = 0, ["param1"] = 16, ["z"] = 37, ["name"] = "default:silver_sandstone"}, {["x"] = 1, ["y"] = 0, ["param1"] = 16, ["z"] = 38, ["name"] = "default:silver_sandstone"}, {["x"] = 1, ["y"] = 1, ["param1"] = 16, ["z"] = 1, ["name"] = "default:silver_sandstone"}, {["x"] = 1, ["y"] = 1, ["param1"] = 16, ["z"] = 2, ["name"] = "default:silver_sandstone"}, {["x"] = 1, ["y"] = 1, ["param1"] = 16, ["z"] = 3, ["name"] = "default:silver_sandstone"}, {["x"] = 1, ["y"] = 1, ["param1"] = 16, ["z"] = 4, ["name"] = "default:silver_sandstone"}, {["x"] = 1, ["y"] = 1, ["param1"] = 16, ["z"] = 5, ["name"] = "default:silver_sandstone"}, {["x"] = 1, ["y"] = 1, ["param1"] = 16, ["z"] = 6, ["name"] = "default:silver_sandstone"}, {["x"] = 1, ["y"] = 1, ["param1"] = 16, ["z"] = 7, ["name"] = "default:silver_sandstone"}, {["x"] = 1, ["y"] = 1, ["param1"] = 16, ["z"] = 8, ["name"] = "default:silver_sandstone"}, {["x"] = 1, ["y"] = 1, ["param1"] = 16, ["z"] = 9, ["name"] = "default:silver_sandstone"}, {["x"] = 1, ["y"] = 1, ["param1"] = 16, ["z"] = 10, ["name"] = "default:silver_sandstone"}, {["x"] = 1, ["y"] = 1, ["param1"] = 16, ["z"] = 11, ["name"] = "default:silver_sandstone"}, {["x"] = 1, ["y"] = 1, ["param1"] = 16, ["z"] = 12, ["name"] = "default:silver_sandstone"}, {["x"] = 1, ["y"] = 1, ["param1"] = 16, ["z"] = 13, ["name"] = "default:silver_sandstone"}, {["x"] = 1, ["y"] = 1, ["param1"] = 16, ["z"] = 14, ["name"] = "default:silver_sandstone"}, {["x"] = 1, ["y"] = 1, ["param1"] = 16, ["z"] = 15, ["name"] = "default:silver_sandstone"}, {["x"] = 1, ["y"] = 1, ["param1"] = 16, ["z"] = 16, ["name"] = "default:silver_sandstone"}, {["x"] = 1, ["y"] = 1, ["param1"] = 16, ["z"] = 17, ["name"] = "default:silver_sandstone"}, {["x"] = 1, ["y"] = 1, ["param1"] = 16, ["z"] = 18, ["name"] = "default:silver_sandstone"}, {["x"] = 1, ["y"] = 1, ["param1"] = 16, ["z"] = 19, ["name"] = "default:silver_sandstone"}, {["x"] = 1, ["y"] = 1, ["param1"] = 16, ["z"] = 20, ["name"] = "default:silver_sandstone"}, {["x"] = 1, ["y"] = 1, ["param1"] = 16, ["z"] = 21, ["name"] = "default:silver_sandstone"}, {["x"] = 1, ["y"] = 1, ["param1"] = 16, ["z"] = 22, ["name"] = "default:silver_sandstone"}, {["x"] = 1, ["y"] = 1, ["param1"] = 16, ["z"] = 23, ["name"] = "default:silver_sandstone"}, {["x"] = 1, ["y"] = 1, ["param1"] = 16, ["z"] = 24, ["name"] = "default:silver_sandstone"}, {["x"] = 1, ["y"] = 1, ["param1"] = 16, ["z"] = 25, ["name"] = "default:silver_sandstone"}, {["x"] = 1, ["y"] = 1, ["param1"] = 16, ["z"] = 26, ["name"] = "default:silver_sandstone"}, {["x"] = 1, ["y"] = 1, ["param1"] = 16, ["z"] = 27, ["name"] = "default:silver_sandstone"}, {["x"] = 1, ["y"] = 1, ["param1"] = 16, ["z"] = 28, ["name"] = "default:silver_sandstone"}, {["x"] = 1, ["y"] = 1, ["param1"] = 16, ["z"] = 29, ["name"] = "default:silver_sandstone"}, {["x"] = 1, ["y"] = 1, ["param1"] = 16, ["z"] = 30, ["name"] = "default:silver_sandstone"}, {["x"] = 1, ["y"] = 1, ["param1"] = 16, ["z"] = 31, ["name"] = "default:silver_sandstone"}, {["x"] = 1, ["y"] = 1, ["param1"] = 16, ["z"] = 32, ["name"] = "default:silver_sandstone"}, {["x"] = 1, ["y"] = 1, ["param1"] = 16, ["z"] = 33, ["name"] = "default:silver_sandstone"}, {["x"] = 1, ["y"] = 1, ["param1"] = 16, ["z"] = 34, ["name"] = "default:silver_sandstone"}, {["x"] = 1, ["y"] = 1, ["param1"] = 16, ["z"] = 35, ["name"] = "default:silver_sandstone"}, {["x"] = 1, ["y"] = 1, ["param1"] = 16, ["z"] = 36, ["name"] = "default:silver_sandstone"}, {["x"] = 1, ["y"] = 1, ["param1"] = 16, ["z"] = 37, ["name"] = "default:silver_sandstone"}, {["x"] = 1, ["y"] = 1, ["param1"] = 16, ["z"] = 38, ["name"] = "default:silver_sandstone"}, {["x"] = 1, ["y"] = 2, ["param1"] = 16, ["z"] = 1, ["name"] = "default:silver_sandstone"}, {["x"] = 1, ["y"] = 2, ["param1"] = 16, ["z"] = 2, ["name"] = "default:silver_sandstone"}, {["x"] = 1, ["y"] = 2, ["param1"] = 16, ["z"] = 3, ["name"] = "default:silver_sandstone"}, {["x"] = 1, ["y"] = 2, ["param1"] = 16, ["z"] = 4, ["name"] = "default:silver_sandstone"}, {["x"] = 1, ["y"] = 2, ["param1"] = 16, ["z"] = 5, ["name"] = "default:silver_sandstone"}, {["x"] = 1, ["y"] = 2, ["param1"] = 16, ["z"] = 6, ["name"] = "default:silver_sandstone"}, {["x"] = 1, ["y"] = 2, ["param1"] = 16, ["z"] = 7, ["name"] = "default:silver_sandstone"}, {["x"] = 1, ["y"] = 2, ["param1"] = 16, ["z"] = 8, ["name"] = "default:silver_sandstone"}, {["x"] = 1, ["y"] = 2, ["param1"] = 16, ["z"] = 9, ["name"] = "default:silver_sandstone"}, {["x"] = 1, ["y"] = 2, ["param1"] = 16, ["z"] = 10, ["name"] = "default:silver_sandstone"}, {["x"] = 1, ["y"] = 2, ["param1"] = 16, ["z"] = 11, ["name"] = "default:silver_sandstone"}, {["x"] = 1, ["y"] = 2, ["param1"] = 16, ["z"] = 12, ["name"] = "default:silver_sandstone"}, {["x"] = 1, ["y"] = 2, ["param1"] = 16, ["z"] = 13, ["name"] = "default:silver_sandstone"}, {["x"] = 1, ["y"] = 2, ["param1"] = 16, ["z"] = 14, ["name"] = "default:silver_sandstone"}, {["x"] = 1, ["y"] = 2, ["param1"] = 16, ["z"] = 15, ["name"] = "default:silver_sandstone"}, {["x"] = 1, ["y"] = 2, ["param1"] = 16, ["z"] = 16, ["name"] = "default:silver_sandstone"}, {["x"] = 1, ["y"] = 2, ["param1"] = 16, ["z"] = 17, ["name"] = "default:silver_sandstone"}, {["x"] = 1, ["y"] = 2, ["param1"] = 16, ["z"] = 18, ["name"] = "default:silver_sandstone"}, {["x"] = 1, ["y"] = 2, ["param1"] = 16, ["z"] = 19, ["name"] = "default:silver_sandstone"}, {["x"] = 1, ["y"] = 2, ["param1"] = 16, ["z"] = 20, ["name"] = "default:silver_sandstone"}, {["x"] = 1, ["y"] = 2, ["param1"] = 16, ["z"] = 21, ["name"] = "default:silver_sandstone"}, {["x"] = 1, ["y"] = 2, ["param1"] = 16, ["z"] = 22, ["name"] = "default:silver_sandstone"}, {["x"] = 1, ["y"] = 2, ["param1"] = 16, ["z"] = 23, ["name"] = "default:silver_sandstone"}, {["x"] = 1, ["y"] = 2, ["param1"] = 16, ["z"] = 24, ["name"] = "default:silver_sandstone"}, {["x"] = 1, ["y"] = 2, ["param1"] = 16, ["z"] = 25, ["name"] = "default:silver_sandstone"}, {["x"] = 1, ["y"] = 2, ["param1"] = 16, ["z"] = 26, ["name"] = "default:silver_sandstone"}, {["x"] = 1, ["y"] = 2, ["param1"] = 16, ["z"] = 27, ["name"] = "default:silver_sandstone"}, {["x"] = 1, ["y"] = 2, ["param1"] = 16, ["z"] = 28, ["name"] = "default:silver_sandstone"}, {["x"] = 1, ["y"] = 2, ["param1"] = 16, ["z"] = 29, ["name"] = "default:silver_sandstone"}, {["x"] = 1, ["y"] = 2, ["param1"] = 16, ["z"] = 30, ["name"] = "default:silver_sandstone"}, {["x"] = 1, ["y"] = 2, ["param1"] = 16, ["z"] = 31, ["name"] = "default:silver_sandstone"}, {["x"] = 1, ["y"] = 2, ["param1"] = 16, ["z"] = 32, ["name"] = "default:silver_sandstone"}, {["x"] = 1, ["y"] = 2, ["param1"] = 16, ["z"] = 33, ["name"] = "default:silver_sandstone"}, {["x"] = 1, ["y"] = 2, ["param1"] = 16, ["z"] = 34, ["name"] = "default:silver_sandstone"}, {["x"] = 1, ["y"] = 2, ["param1"] = 16, ["z"] = 35, ["name"] = "default:silver_sandstone"}, {["x"] = 1, ["y"] = 2, ["param1"] = 16, ["z"] = 36, ["name"] = "default:silver_sandstone"}, {["x"] = 1, ["y"] = 2, ["param1"] = 16, ["z"] = 37, ["name"] = "default:silver_sandstone"}, {["x"] = 1, ["y"] = 2, ["param1"] = 16, ["z"] = 38, ["name"] = "default:silver_sandstone"}, {["x"] = 1, ["y"] = 3, ["param1"] = 16, ["z"] = 1, ["name"] = "default:silver_sandstone"}, {["x"] = 1, ["y"] = 3, ["param1"] = 16, ["z"] = 2, ["name"] = "default:silver_sandstone"}, {["x"] = 1, ["y"] = 3, ["param1"] = 16, ["z"] = 3, ["name"] = "default:silver_sandstone"}, {["x"] = 1, ["y"] = 3, ["param1"] = 16, ["z"] = 4, ["name"] = "default:silver_sandstone"}, {["x"] = 1, ["y"] = 3, ["param1"] = 16, ["z"] = 5, ["name"] = "default:silver_sandstone"}, {["x"] = 1, ["y"] = 3, ["param1"] = 16, ["z"] = 6, ["name"] = "default:silver_sandstone"}, {["x"] = 1, ["y"] = 3, ["param1"] = 16, ["z"] = 7, ["name"] = "default:silver_sandstone"}, {["x"] = 1, ["y"] = 3, ["param1"] = 16, ["z"] = 8, ["name"] = "default:silver_sandstone"}, {["x"] = 1, ["y"] = 3, ["param1"] = 16, ["z"] = 9, ["name"] = "default:silver_sandstone"}, {["x"] = 1, ["y"] = 3, ["param1"] = 16, ["z"] = 10, ["name"] = "default:silver_sandstone"}, {["x"] = 1, ["y"] = 3, ["param1"] = 16, ["z"] = 11, ["name"] = "default:silver_sandstone"}, {["x"] = 1, ["y"] = 3, ["param1"] = 16, ["z"] = 12, ["name"] = "default:silver_sandstone"}, {["x"] = 1, ["y"] = 3, ["param1"] = 16, ["z"] = 13, ["name"] = "default:silver_sandstone"}, {["x"] = 1, ["y"] = 3, ["param1"] = 16, ["z"] = 14, ["name"] = "default:silver_sandstone"}, {["x"] = 1, ["y"] = 3, ["param1"] = 16, ["z"] = 15, ["name"] = "default:silver_sandstone"}, {["x"] = 1, ["y"] = 3, ["param1"] = 16, ["z"] = 16, ["name"] = "default:silver_sandstone"}, {["x"] = 1, ["y"] = 3, ["param1"] = 16, ["z"] = 17, ["name"] = "default:silver_sandstone"}, {["x"] = 1, ["y"] = 3, ["param1"] = 16, ["z"] = 18, ["name"] = "default:silver_sandstone"}, {["x"] = 1, ["y"] = 3, ["param1"] = 16, ["z"] = 19, ["name"] = "default:silver_sandstone"}, {["x"] = 1, ["y"] = 3, ["param1"] = 16, ["z"] = 20, ["name"] = "default:silver_sandstone"}, {["x"] = 1, ["y"] = 3, ["param1"] = 16, ["z"] = 21, ["name"] = "default:silver_sandstone"}, {["x"] = 1, ["y"] = 3, ["param1"] = 16, ["z"] = 22, ["name"] = "default:silver_sandstone"}, {["x"] = 1, ["y"] = 3, ["param1"] = 16, ["z"] = 23, ["name"] = "default:silver_sandstone"}, {["x"] = 1, ["y"] = 3, ["param1"] = 16, ["z"] = 24, ["name"] = "default:silver_sandstone"}, {["x"] = 1, ["y"] = 3, ["param1"] = 16, ["z"] = 25, ["name"] = "default:silver_sandstone"}, {["x"] = 1, ["y"] = 3, ["param1"] = 16, ["z"] = 26, ["name"] = "default:silver_sandstone"}, {["x"] = 1, ["y"] = 3, ["param1"] = 16, ["z"] = 27, ["name"] = "default:silver_sandstone"}, {["x"] = 1, ["y"] = 3, ["param1"] = 16, ["z"] = 28, ["name"] = "default:silver_sandstone"}, {["x"] = 1, ["y"] = 3, ["param1"] = 16, ["z"] = 29, ["name"] = "default:silver_sandstone"}, {["x"] = 1, ["y"] = 3, ["param1"] = 16, ["z"] = 30, ["name"] = "default:silver_sandstone"}, {["x"] = 1, ["y"] = 3, ["param1"] = 16, ["z"] = 31, ["name"] = "default:silver_sandstone"}, {["x"] = 1, ["y"] = 3, ["param1"] = 16, ["z"] = 32, ["name"] = "default:silver_sandstone"}, {["x"] = 1, ["y"] = 3, ["param1"] = 16, ["z"] = 33, ["name"] = "default:silver_sandstone"}, {["x"] = 1, ["y"] = 3, ["param1"] = 16, ["z"] = 34, ["name"] = "default:silver_sandstone"}, {["x"] = 1, ["y"] = 3, ["param1"] = 16, ["z"] = 35, ["name"] = "default:silver_sandstone"}, {["x"] = 1, ["y"] = 3, ["param1"] = 16, ["z"] = 36, ["name"] = "default:silver_sandstone"}, {["x"] = 1, ["y"] = 3, ["param1"] = 16, ["z"] = 37, ["name"] = "default:silver_sandstone"}, {["x"] = 1, ["y"] = 3, ["param1"] = 16, ["z"] = 38, ["name"] = "default:silver_sandstone"}, {["x"] = 1, ["y"] = 4, ["param1"] = 46, ["z"] = 1, ["name"] = "stairs:slab_silver_sandstone"}, {["x"] = 1, ["y"] = 4, ["param1"] = 62, ["z"] = 2, ["name"] = "stairs:slab_silver_sandstone"}, {["x"] = 1, ["y"] = 4, ["param1"] = 78, ["z"] = 3, ["name"] = "stairs:slab_silver_sandstone"}, {["x"] = 1, ["y"] = 4, ["param1"] = 62, ["z"] = 4, ["name"] = "stairs:slab_silver_sandstone"}, {["x"] = 1, ["y"] = 4, ["param1"] = 78, ["z"] = 5, ["name"] = "stairs:slab_silver_sandstone"}, {["x"] = 1, ["y"] = 4, ["param1"] = 62, ["z"] = 6, ["name"] = "stairs:slab_silver_sandstone"}, {["x"] = 1, ["y"] = 4, ["param1"] = 46, ["z"] = 7, ["name"] = "stairs:slab_silver_sandstone"}, {["x"] = 1, ["y"] = 4, ["param1"] = 30, ["z"] = 8, ["name"] = "stairs:slab_silver_sandstone"}, {["x"] = 1, ["y"] = 4, ["param1"] = 14, ["z"] = 9, ["name"] = "stairs:slab_silver_sandstone"}, {["x"] = 1, ["y"] = 4, ["param1"] = 30, ["z"] = 10, ["name"] = "stairs:slab_silver_sandstone"}, {["x"] = 1, ["y"] = 4, ["param1"] = 46, ["z"] = 11, ["name"] = "stairs:slab_silver_sandstone"}, {["x"] = 1, ["y"] = 4, ["param1"] = 62, ["z"] = 12, ["name"] = "stairs:slab_silver_sandstone"}, {["x"] = 1, ["y"] = 4, ["param1"] = 78, ["z"] = 13, ["name"] = "stairs:slab_silver_sandstone"}, {["x"] = 1, ["y"] = 4, ["param1"] = 62, ["z"] = 14, ["name"] = "stairs:slab_silver_sandstone"}, {["x"] = 1, ["y"] = 4, ["param1"] = 78, ["z"] = 15, ["name"] = "stairs:slab_silver_sandstone"}, {["x"] = 1, ["y"] = 4, ["param1"] = 78, ["z"] = 16, ["name"] = "stairs:slab_silver_sandstone"}, {["x"] = 1, ["y"] = 4, ["param1"] = 94, ["z"] = 17, ["name"] = "stairs:slab_silver_sandstone"}, {["x"] = 1, ["y"] = 4, ["param1"] = 110, ["z"] = 18, ["name"] = "stairs:slab_silver_sandstone"}, {["x"] = 1, ["y"] = 4, ["param1"] = 126, ["z"] = 19, ["name"] = "stairs:slab_silver_sandstone"}, {["x"] = 1, ["y"] = 4, ["param1"] = 110, ["z"] = 20, ["name"] = "stairs:slab_silver_sandstone"}, {["x"] = 1, ["y"] = 4, ["param1"] = 126, ["z"] = 21, ["name"] = "stairs:slab_silver_sandstone"}, {["x"] = 1, ["y"] = 4, ["param1"] = 110, ["z"] = 22, ["name"] = "stairs:slab_silver_sandstone"}, {["x"] = 1, ["y"] = 4, ["param1"] = 94, ["z"] = 23, ["name"] = "stairs:slab_silver_sandstone"}, {["x"] = 1, ["y"] = 4, ["param1"] = 94, ["z"] = 24, ["name"] = "stairs:slab_silver_sandstone"}, {["x"] = 1, ["y"] = 4, ["param1"] = 110, ["z"] = 25, ["name"] = "stairs:slab_silver_sandstone"}, {["x"] = 1, ["y"] = 4, ["param1"] = 126, ["z"] = 26, ["name"] = "stairs:slab_silver_sandstone"}, {["x"] = 1, ["y"] = 4, ["param1"] = 142, ["z"] = 27, ["name"] = "stairs:slab_silver_sandstone"}, {["x"] = 1, ["y"] = 4, ["param1"] = 158, ["z"] = 28, ["name"] = "stairs:slab_silver_sandstone"}, {["x"] = 1, ["y"] = 4, ["param1"] = 174, ["z"] = 29, ["name"] = "stairs:slab_silver_sandstone"}, {["x"] = 1, ["y"] = 4, ["param1"] = 190, ["z"] = 30, ["name"] = "stairs:slab_silver_sandstone"}, {["x"] = 1, ["y"] = 4, ["param1"] = 174, ["z"] = 31, ["name"] = "stairs:slab_silver_sandstone"}, {["x"] = 1, ["y"] = 4, ["param1"] = 190, ["z"] = 32, ["name"] = "stairs:slab_silver_sandstone"}, {["x"] = 1, ["y"] = 4, ["param1"] = 174, ["z"] = 33, ["name"] = "stairs:slab_silver_sandstone"}, {["x"] = 1, ["y"] = 4, ["param1"] = 158, ["z"] = 34, ["name"] = "stairs:slab_silver_sandstone"}, {["x"] = 1, ["y"] = 4, ["param1"] = 142, ["z"] = 35, ["name"] = "stairs:slab_silver_sandstone"}, {["x"] = 1, ["y"] = 4, ["param1"] = 126, ["z"] = 36, ["name"] = "stairs:slab_silver_sandstone"}, {["x"] = 1, ["y"] = 4, ["param1"] = 110, ["z"] = 37, ["name"] = "stairs:slab_silver_sandstone"}, {["x"] = 1, ["y"] = 4, ["param1"] = 94, ["z"] = 38, ["name"] = "stairs:slab_silver_sandstone"}, {["x"] = 2, ["y"] = 0, ["param1"] = 62, ["z"] = 1, ["name"] = "default:mese"}, {["x"] = 2, ["y"] = 0, ["param1"] = 45, ["z"] = 2, ["name"] = "mesecons_extrawires:vertical_bottom_off"}, {["x"] = 2, ["param2"] = 1, ["y"] = 0, ["param1"] = 44, ["z"] = 3, ["name"] = "mesecons_insulated:insulated_off"}, {["x"] = 2, ["param2"] = 3, ["y"] = 0, ["param1"] = 27, ["z"] = 4, ["name"] = "mesecons_insulated:insulated_off"}, {["x"] = 2, ["param2"] = 3, ["y"] = 0, ["param1"] = 42, ["z"] = 5, ["name"] = "mesecons_insulated:insulated_off"}, {["x"] = 2, ["param2"] = 3, ["y"] = 0, ["param1"] = 25, ["z"] = 6, ["name"] = "mesecons_insulated:insulated_off"}, {["x"] = 2, ["param2"] = 3, ["y"] = 0, ["param1"] = 42, ["z"] = 7, ["name"] = "mesecons_insulated:insulated_off"}, {["x"] = 2, ["param2"] = 3, ["y"] = 0, ["param1"] = 25, ["z"] = 8, ["name"] = "mesecons_insulated:insulated_off"}, {["x"] = 2, ["param2"] = 3, ["y"] = 0, ["param1"] = 42, ["z"] = 9, ["name"] = "mesecons_insulated:insulated_off"}, {["x"] = 2, ["param2"] = 3, ["y"] = 0, ["param1"] = 25, ["z"] = 10, ["name"] = "mesecons_insulated:insulated_off"}, {["x"] = 2, ["param2"] = 3, ["y"] = 0, ["param1"] = 42, ["z"] = 11, ["name"] = "mesecons_extrawires:corner_off"}, {["x"] = 2, ["y"] = 0, ["param1"] = 16, ["z"] = 19, ["name"] = "default:silver_sandstone"}, {["x"] = 2, ["param2"] = 2, ["y"] = 0, ["param1"] = 57, ["z"] = 20, ["name"] = "mesecons_extrawires:corner_off"}, {["x"] = 2, ["param2"] = 3, ["y"] = 0, ["param1"] = 74, ["z"] = 21, ["name"] = "mesecons_insulated:insulated_off"}, {["x"] = 2, ["param2"] = 3, ["y"] = 0, ["param1"] = 57, ["z"] = 22, ["name"] = "mesecons_insulated:insulated_off"}, {["x"] = 2, ["param2"] = 3, ["y"] = 0, ["param1"] = 42, ["z"] = 23, ["name"] = "mesecons_insulated:insulated_off"}, {["x"] = 2, ["param2"] = 3, ["y"] = 0, ["param1"] = 41, ["z"] = 24, ["name"] = "mesecons_insulated:insulated_off"}, {["x"] = 2, ["param2"] = 3, ["y"] = 0, ["param1"] = 58, ["z"] = 25, ["name"] = "mesecons_insulated:insulated_off"}, {["x"] = 2, ["param2"] = 3, ["y"] = 0, ["param1"] = 73, ["z"] = 26, ["name"] = "mesecons_insulated:insulated_off"}, {["x"] = 2, ["param2"] = 3, ["y"] = 0, ["param1"] = 90, ["z"] = 27, ["name"] = "mesecons_insulated:insulated_off"}, {["x"] = 2, ["param2"] = 3, ["y"] = 0, ["param1"] = 105, ["z"] = 28, ["name"] = "mesecons_insulated:insulated_off"}, {["x"] = 2, ["param2"] = 3, ["y"] = 0, ["param1"] = 122, ["z"] = 29, ["name"] = "mesecons_insulated:insulated_off"}, {["x"] = 2, ["param2"] = 3, ["y"] = 0, ["param1"] = 105, ["z"] = 30, ["name"] = "mesecons_insulated:insulated_off"}, {["x"] = 2, ["param2"] = 3, ["y"] = 0, ["param1"] = 122, ["z"] = 31, ["name"] = "mesecons_insulated:insulated_off"}, {["x"] = 2, ["param2"] = 3, ["y"] = 0, ["param1"] = 105, ["z"] = 32, ["name"] = "mesecons_insulated:insulated_off"}, {["x"] = 2, ["param2"] = 3, ["y"] = 0, ["param1"] = 122, ["z"] = 33, ["name"] = "mesecons_insulated:insulated_off"}, {["x"] = 2, ["param2"] = 3, ["y"] = 0, ["param1"] = 106, ["z"] = 34, ["name"] = "mesecons_insulated:insulated_off"}, {["x"] = 2, ["param2"] = 3, ["y"] = 0, ["param1"] = 91, ["z"] = 35, ["name"] = "mesecons_insulated:insulated_off"}, {["x"] = 2, ["param2"] = 3, ["y"] = 0, ["param1"] = 76, ["z"] = 36, ["name"] = "mesecons_insulated:insulated_off"}, {["x"] = 2, ["y"] = 0, ["param1"] = 61, ["z"] = 37, ["name"] = "mesecons_extrawires:vertical_bottom_off"}, {["x"] = 2, ["y"] = 0, ["param1"] = 62, ["z"] = 38, ["name"] = "default:mese"}, {["x"] = 2, ["meta"] = {["fields"] = {["infotext"] = "\"Output 8\"", ["formspec"] = "field[text;;${text}]", ["text"] = "Output 8"}, ["inventory"] = {}}, ["param2"] = 4, ["y"] = 1, ["param1"] = 31, ["z"] = 0, ["name"] = "default:sign_wall_steel"}, {["x"] = 2, ["y"] = 1, ["param1"] = 16, ["z"] = 1, ["name"] = "default:silver_sandstone"}, {["x"] = 2, ["y"] = 1, ["param1"] = 44, ["z"] = 2, ["name"] = "mesecons_extrawires:vertical_off"}, {["x"] = 2, ["y"] = 1, ["param1"] = 59, ["z"] = 3, ["name"] = "default:mese"}, {["x"] = 2, ["y"] = 1, ["param1"] = 16, ["z"] = 4, ["name"] = "default:silver_sandstone"}, {["x"] = 2, ["y"] = 1, ["param1"] = 59, ["z"] = 5, ["name"] = "default:mese"}, {["x"] = 2, ["y"] = 1, ["param1"] = 16, ["z"] = 6, ["name"] = "default:silver_sandstone"}, {["x"] = 2, ["y"] = 1, ["param1"] = 59, ["z"] = 7, ["name"] = "default:mese"}, {["x"] = 2, ["y"] = 1, ["param1"] = 16, ["z"] = 8, ["name"] = "default:silver_sandstone"}, {["x"] = 2, ["y"] = 1, ["param1"] = 59, ["z"] = 9, ["name"] = "default:mese"}, {["x"] = 2, ["y"] = 1, ["param1"] = 16, ["z"] = 10, ["name"] = "default:silver_sandstone"}, {["x"] = 2, ["y"] = 1, ["param1"] = 59, ["z"] = 11, ["name"] = "default:mese"}, {["x"] = 2, ["y"] = 1, ["param1"] = 16, ["z"] = 12, ["name"] = "default:silver_sandstone"}, {["x"] = 2, ["y"] = 1, ["param1"] = 59, ["z"] = 13, ["name"] = "default:mese"}, {["x"] = 2, ["y"] = 1, ["param1"] = 16, ["z"] = 14, ["name"] = "default:silver_sandstone"}, {["x"] = 2, ["y"] = 1, ["param1"] = 59, ["z"] = 15, ["name"] = "default:mese"}, {["x"] = 2, ["y"] = 1, ["param1"] = 16, ["z"] = 16, ["name"] = "default:silver_sandstone"}, {["x"] = 2, ["y"] = 1, ["param1"] = 59, ["z"] = 17, ["name"] = "default:mese"}, {["x"] = 2, ["y"] = 1, ["param1"] = 16, ["z"] = 18, ["name"] = "default:silver_sandstone"}, {["x"] = 2, ["y"] = 1, ["param1"] = 91, ["z"] = 19, ["name"] = "default:mese"}, {["x"] = 2, ["y"] = 1, ["param1"] = 16, ["z"] = 20, ["name"] = "default:silver_sandstone"}, {["x"] = 2, ["y"] = 1, ["param1"] = 91, ["z"] = 21, ["name"] = "default:mese"}, {["x"] = 2, ["y"] = 1, ["param1"] = 16, ["z"] = 22, ["name"] = "default:silver_sandstone"}, {["x"] = 2, ["y"] = 1, ["param1"] = 59, ["z"] = 23, ["name"] = "default:mese"}, {["x"] = 2, ["y"] = 1, ["param1"] = 16, ["z"] = 24, ["name"] = "default:silver_sandstone"}, {["x"] = 2, ["y"] = 1, ["param1"] = 75, ["z"] = 25, ["name"] = "default:mese"}, {["x"] = 2, ["y"] = 1, ["param1"] = 16, ["z"] = 26, ["name"] = "default:silver_sandstone"}, {["x"] = 2, ["y"] = 1, ["param1"] = 107, ["z"] = 27, ["name"] = "default:mese"}, {["x"] = 2, ["y"] = 1, ["param1"] = 16, ["z"] = 28, ["name"] = "default:silver_sandstone"}, {["x"] = 2, ["y"] = 1, ["param1"] = 139, ["z"] = 29, ["name"] = "default:mese"}, {["x"] = 2, ["y"] = 1, ["param1"] = 16, ["z"] = 30, ["name"] = "default:silver_sandstone"}, {["x"] = 2, ["y"] = 1, ["param1"] = 139, ["z"] = 31, ["name"] = "default:mese"}, {["x"] = 2, ["y"] = 1, ["param1"] = 16, ["z"] = 32, ["name"] = "default:silver_sandstone"}, {["x"] = 2, ["y"] = 1, ["param1"] = 139, ["z"] = 33, ["name"] = "default:mese"}, {["x"] = 2, ["y"] = 1, ["param1"] = 16, ["z"] = 34, ["name"] = "default:silver_sandstone"}, {["x"] = 2, ["y"] = 1, ["param1"] = 16, ["z"] = 35, ["name"] = "default:silver_sandstone"}, {["x"] = 2, ["y"] = 1, ["param1"] = 16, ["z"] = 36, ["name"] = "default:silver_sandstone"}, {["x"] = 2, ["y"] = 1, ["param1"] = 76, ["z"] = 37, ["name"] = "mesecons_extrawires:vertical_off"}, {["x"] = 2, ["y"] = 1, ["param1"] = 16, ["z"] = 38, ["name"] = "default:silver_sandstone"}, {["x"] = 2, ["meta"] = {["fields"] = {["infotext"] = "\"Input 8\"", ["formspec"] = "field[text;;${text}]", ["text"] = "Input 8"}, ["inventory"] = {}}, ["param2"] = 5, ["y"] = 1, ["param1"] = 31, ["z"] = 39, ["name"] = "default:sign_wall_steel"}, {["x"] = 2, ["y"] = 2, ["param1"] = 16, ["z"] = 1, ["name"] = "default:silver_sandstone"}, {["x"] = 2, ["y"] = 2, ["param1"] = 44, ["z"] = 2, ["name"] = "mesecons_extrawires:vertical_off"}, {["x"] = 2, ["param2"] = 2, ["y"] = 2, ["param1"] = 60, ["z"] = 3, ["name"] = "mesecons_extrawires:corner_off"}, {["x"] = 2, ["y"] = 2, ["param1"] = 75, ["z"] = 4, ["name"] = "default:mese"}, {["x"] = 2, ["param2"] = 2, ["y"] = 2, ["param1"] = 60, ["z"] = 5, ["name"] = "mesecons_extrawires:corner_off"}, {["x"] = 2, ["y"] = 2, ["param1"] = 59, ["z"] = 6, ["name"] = "default:mese"}, {["x"] = 2, ["param2"] = 2, ["y"] = 2, ["param1"] = 44, ["z"] = 7, ["name"] = "mesecons_extrawires:corner_off"}, {["x"] = 2, ["y"] = 2, ["param1"] = 59, ["z"] = 8, ["name"] = "default:mese"}, {["x"] = 2, ["param2"] = 2, ["y"] = 2, ["param1"] = 44, ["z"] = 9, ["name"] = "mesecons_extrawires:corner_off"}, {["x"] = 2, ["y"] = 2, ["param1"] = 59, ["z"] = 10, ["name"] = "default:mese"}, {["x"] = 2, ["param2"] = 2, ["y"] = 2, ["param1"] = 44, ["z"] = 11, ["name"] = "mesecons_extrawires:corner_off"}, {["x"] = 2, ["y"] = 2, ["param1"] = 59, ["z"] = 12, ["name"] = "default:mese"}, {["x"] = 2, ["param2"] = 2, ["y"] = 2, ["param1"] = 60, ["z"] = 13, ["name"] = "mesecons_extrawires:corner_off"}, {["x"] = 2, ["y"] = 2, ["param1"] = 75, ["z"] = 14, ["name"] = "default:mese"}, {["x"] = 2, ["param2"] = 2, ["y"] = 2, ["param1"] = 60, ["z"] = 15, ["name"] = "mesecons_extrawires:corner_off"}, {["x"] = 2, ["y"] = 2, ["param1"] = 59, ["z"] = 16, ["name"] = "default:mese"}, {["x"] = 2, ["param2"] = 2, ["y"] = 2, ["param1"] = 76, ["z"] = 17, ["name"] = "mesecons_extrawires:corner_off"}, {["x"] = 2, ["y"] = 2, ["param1"] = 91, ["z"] = 18, ["name"] = "default:mese"}, {["x"] = 2, ["param2"] = 2, ["y"] = 2, ["param1"] = 108, ["z"] = 19, ["name"] = "mesecons_extrawires:corner_off"}, {["x"] = 2, ["y"] = 2, ["param1"] = 123, ["z"] = 20, ["name"] = "default:mese"}, {["x"] = 2, ["param2"] = 2, ["y"] = 2, ["param1"] = 108, ["z"] = 21, ["name"] = "mesecons_extrawires:corner_off"}, {["x"] = 2, ["y"] = 2, ["param1"] = 91, ["z"] = 22, ["name"] = "default:mese"}, {["x"] = 2, ["param2"] = 2, ["y"] = 2, ["param1"] = 76, ["z"] = 23, ["name"] = "mesecons_extrawires:corner_off"}, {["x"] = 2, ["y"] = 2, ["param1"] = 75, ["z"] = 24, ["name"] = "default:mese"}, {["x"] = 2, ["param2"] = 2, ["y"] = 2, ["param1"] = 92, ["z"] = 25, ["name"] = "mesecons_extrawires:corner_off"}, {["x"] = 2, ["y"] = 2, ["param1"] = 107, ["z"] = 26, ["name"] = "default:mese"}, {["x"] = 2, ["param2"] = 2, ["y"] = 2, ["param1"] = 124, ["z"] = 27, ["name"] = "mesecons_extrawires:corner_off"}, {["x"] = 2, ["y"] = 2, ["param1"] = 139, ["z"] = 28, ["name"] = "default:mese"}, {["x"] = 2, ["param2"] = 2, ["y"] = 2, ["param1"] = 156, ["z"] = 29, ["name"] = "mesecons_extrawires:corner_on"}, {["x"] = 2, ["y"] = 2, ["param1"] = 171, ["z"] = 30, ["name"] = "mesecons_extrawires:mese_powered"}, {["x"] = 2, ["param2"] = 2, ["y"] = 2, ["param1"] = 156, ["z"] = 31, ["name"] = "mesecons_extrawires:corner_on"}, {["x"] = 2, ["y"] = 2, ["param1"] = 171, ["z"] = 32, ["name"] = "mesecons_extrawires:mese_powered"}, {["x"] = 2, ["param2"] = 2, ["y"] = 2, ["param1"] = 156, ["z"] = 33, ["name"] = "mesecons_extrawires:corner_off"}, {["x"] = 2, ["y"] = 2, ["param1"] = 139, ["z"] = 34, ["name"] = "default:mese"}, {["x"] = 2, ["param2"] = 2, ["y"] = 2, ["param1"] = 124, ["z"] = 35, ["name"] = "mesecons_extrawires:corner_on"}, {["x"] = 2, ["meta"] = {["fields"] = {["input2"] = "1", ["input1"] = "0"}, ["inventory"] = {}}, ["y"] = 2, ["param1"] = 108, ["z"] = 36, ["name"] = "mesecons_gates:and_off"}, {["x"] = 2, ["y"] = 2, ["param1"] = 92, ["z"] = 37, ["name"] = "mesecons_extrawires:vertical_top_off"}, {["x"] = 2, ["y"] = 2, ["param1"] = 16, ["z"] = 38, ["name"] = "default:silver_sandstone"}, {["x"] = 2, ["y"] = 3, ["param1"] = 16, ["z"] = 1, ["name"] = "default:silver_sandstone"}, {["x"] = 2, ["y"] = 3, ["param1"] = 61, ["z"] = 2, ["name"] = "mesecons_extrawires:vertical_top_off"}, {["x"] = 2, ["y"] = 3, ["param1"] = 77, ["z"] = 3, ["name"] = "mesecons_insulated:insulated_off"}, {["x"] = 2, ["y"] = 3, ["param1"] = 92, ["z"] = 4, ["name"] = "default:mese"}, {["x"] = 2, ["y"] = 3, ["param1"] = 77, ["z"] = 5, ["name"] = "mesecons_insulated:insulated_off"}, {["x"] = 2, ["y"] = 3, ["param1"] = 60, ["z"] = 6, ["name"] = "default:mese"}, {["x"] = 2, ["y"] = 3, ["param1"] = 45, ["z"] = 7, ["name"] = "mesecons_insulated:insulated_off"}, {["x"] = 2, ["y"] = 3, ["param1"] = 60, ["z"] = 8, ["name"] = "default:mese"}, {["x"] = 2, ["y"] = 3, ["param1"] = 45, ["z"] = 9, ["name"] = "mesecons_insulated:insulated_off"}, {["x"] = 2, ["y"] = 3, ["param1"] = 60, ["z"] = 10, ["name"] = "default:mese"}, {["x"] = 2, ["y"] = 3, ["param1"] = 45, ["z"] = 11, ["name"] = "mesecons_insulated:insulated_off"}, {["x"] = 2, ["y"] = 3, ["param1"] = 60, ["z"] = 12, ["name"] = "default:mese"}, {["x"] = 2, ["y"] = 3, ["param1"] = 77, ["z"] = 13, ["name"] = "mesecons_insulated:insulated_off"}, {["x"] = 2, ["y"] = 3, ["param1"] = 92, ["z"] = 14, ["name"] = "default:mese"}, {["x"] = 2, ["y"] = 3, ["param1"] = 77, ["z"] = 15, ["name"] = "mesecons_insulated:insulated_off"}, {["x"] = 2, ["y"] = 3, ["param1"] = 76, ["z"] = 16, ["name"] = "default:mese"}, {["x"] = 2, ["y"] = 3, ["param1"] = 93, ["z"] = 17, ["name"] = "mesecons_insulated:insulated_off"}, {["x"] = 2, ["y"] = 3, ["param1"] = 108, ["z"] = 18, ["name"] = "default:mese"}, {["x"] = 2, ["y"] = 3, ["param1"] = 125, ["z"] = 19, ["name"] = "mesecons_insulated:insulated_off"}, {["x"] = 2, ["y"] = 3, ["param1"] = 140, ["z"] = 20, ["name"] = "default:mese"}, {["x"] = 2, ["y"] = 3, ["param1"] = 125, ["z"] = 21, ["name"] = "mesecons_insulated:insulated_off"}, {["x"] = 2, ["y"] = 3, ["param1"] = 108, ["z"] = 22, ["name"] = "default:mese"}, {["x"] = 2, ["y"] = 3, ["param1"] = 93, ["z"] = 23, ["name"] = "mesecons_insulated:insulated_off"}, {["x"] = 2, ["y"] = 3, ["param1"] = 92, ["z"] = 24, ["name"] = "default:mese"}, {["x"] = 2, ["y"] = 3, ["param1"] = 109, ["z"] = 25, ["name"] = "mesecons_insulated:insulated_off"}, {["x"] = 2, ["y"] = 3, ["param1"] = 124, ["z"] = 26, ["name"] = "default:mese"}, {["x"] = 2, ["y"] = 3, ["param1"] = 141, ["z"] = 27, ["name"] = "mesecons_insulated:insulated_off"}, {["x"] = 2, ["y"] = 3, ["param1"] = 156, ["z"] = 28, ["name"] = "default:mese"}, {["x"] = 2, ["y"] = 3, ["param1"] = 173, ["z"] = 29, ["name"] = "mesecons_insulated:insulated_off"}, {["x"] = 2, ["y"] = 3, ["param1"] = 188, ["z"] = 30, ["name"] = "mesecons_extrawires:mese_powered"}, {["x"] = 2, ["y"] = 3, ["param1"] = 173, ["z"] = 31, ["name"] = "mesecons_insulated:insulated_off"}, {["x"] = 2, ["y"] = 3, ["param1"] = 188, ["z"] = 32, ["name"] = "mesecons_extrawires:mese_powered"}, {["x"] = 2, ["y"] = 3, ["param1"] = 173, ["z"] = 33, ["name"] = "mesecons_insulated:insulated_off"}, {["x"] = 2, ["y"] = 3, ["param1"] = 156, ["z"] = 34, ["name"] = "default:mese"}, {["x"] = 2, ["y"] = 3, ["param1"] = 16, ["z"] = 38, ["name"] = "default:silver_sandstone"}, {["x"] = 2, ["y"] = 4, ["param1"] = 62, ["z"] = 1, ["name"] = "stairs:slab_silver_sandstone"}, {["x"] = 2, ["y"] = 4, ["param1"] = 78, ["z"] = 2, ["name"] = "stairs:slab_silver_sandstone"}, {["x"] = 2, ["y"] = 4, ["param1"] = 94, ["z"] = 3, ["name"] = "stairs:slab_silver_sandstone"}, {["x"] = 2, ["y"] = 4, ["param1"] = 38, ["z"] = 4, ["name"] = "mesecons_lightstone:lightstone_red_off"}, {["x"] = 2, ["y"] = 4, ["param1"] = 94, ["z"] = 5, ["name"] = "stairs:slab_silver_sandstone"}, {["x"] = 2, ["y"] = 4, ["param1"] = 38, ["z"] = 6, ["name"] = "mesecons_lightstone:lightstone_red_off"}, {["x"] = 2, ["y"] = 4, ["param1"] = 62, ["z"] = 7, ["name"] = "stairs:slab_silver_sandstone"}, {["x"] = 2, ["y"] = 4, ["param1"] = 38, ["z"] = 8, ["name"] = "mesecons_lightstone:lightstone_red_off"}, {["x"] = 2, ["y"] = 4, ["param1"] = 30, ["z"] = 9, ["name"] = "stairs:slab_silver_sandstone"}, {["x"] = 2, ["y"] = 4, ["param1"] = 38, ["z"] = 10, ["name"] = "mesecons_lightstone:lightstone_red_off"}, {["x"] = 2, ["y"] = 4, ["param1"] = 62, ["z"] = 11, ["name"] = "stairs:slab_silver_sandstone"}, {["x"] = 2, ["y"] = 4, ["param1"] = 38, ["z"] = 12, ["name"] = "mesecons_lightstone:lightstone_red_off"}, {["x"] = 2, ["y"] = 4, ["param1"] = 94, ["z"] = 13, ["name"] = "stairs:slab_silver_sandstone"}, {["x"] = 2, ["y"] = 4, ["param1"] = 38, ["z"] = 14, ["name"] = "mesecons_lightstone:lightstone_red_off"}, {["x"] = 2, ["y"] = 4, ["param1"] = 94, ["z"] = 15, ["name"] = "stairs:slab_silver_sandstone"}, {["x"] = 2, ["y"] = 4, ["param1"] = 38, ["z"] = 16, ["name"] = "mesecons_lightstone:lightstone_red_off"}, {["x"] = 2, ["y"] = 4, ["param1"] = 110, ["z"] = 17, ["name"] = "stairs:slab_silver_sandstone"}, {["x"] = 2, ["y"] = 4, ["param1"] = 38, ["z"] = 18, ["name"] = "mesecons_lightstone:lightstone_red_off"}, {["x"] = 2, ["y"] = 4, ["param1"] = 142, ["z"] = 19, ["name"] = "stairs:slab_silver_sandstone"}, {["x"] = 2, ["y"] = 4, ["param1"] = 38, ["z"] = 20, ["name"] = "mesecons_lightstone:lightstone_red_off"}, {["x"] = 2, ["y"] = 4, ["param1"] = 142, ["z"] = 21, ["name"] = "stairs:slab_silver_sandstone"}, {["x"] = 2, ["y"] = 4, ["param1"] = 38, ["z"] = 22, ["name"] = "mesecons_lightstone:lightstone_red_off"}, {["x"] = 2, ["y"] = 4, ["param1"] = 110, ["z"] = 23, ["name"] = "stairs:slab_silver_sandstone"}, {["x"] = 2, ["y"] = 4, ["param1"] = 38, ["z"] = 24, ["name"] = "mesecons_lightstone:lightstone_red_off"}, {["x"] = 2, ["y"] = 4, ["param1"] = 94, ["z"] = 25, ["name"] = "stairs:slab_silver_sandstone"}, {["x"] = 2, ["y"] = 4, ["param1"] = 38, ["z"] = 26, ["name"] = "mesecons_lightstone:lightstone_red_off"}, {["x"] = 2, ["y"] = 4, ["param1"] = 126, ["z"] = 27, ["name"] = "stairs:slab_silver_sandstone"}, {["x"] = 2, ["y"] = 4, ["param1"] = 38, ["z"] = 28, ["name"] = "mesecons_lightstone:lightstone_red_off"}, {["x"] = 2, ["y"] = 4, ["param1"] = 190, ["z"] = 29, ["name"] = "stairs:slab_silver_sandstone"}, {["x"] = 2, ["y"] = 4, ["param1"] = 39, ["z"] = 30, ["name"] = "mesecons_lightstone:lightstone_red_on"}, {["x"] = 2, ["y"] = 4, ["param1"] = 190, ["z"] = 31, ["name"] = "stairs:slab_silver_sandstone"}, {["x"] = 2, ["y"] = 4, ["param1"] = 39, ["z"] = 32, ["name"] = "mesecons_lightstone:lightstone_red_on"}, {["x"] = 2, ["y"] = 4, ["param1"] = 190, ["z"] = 33, ["name"] = "stairs:slab_silver_sandstone"}, {["x"] = 2, ["y"] = 4, ["param1"] = 38, ["z"] = 34, ["name"] = "mesecons_lightstone:lightstone_red_off"}, {["x"] = 2, ["y"] = 4, ["param1"] = 126, ["z"] = 35, ["name"] = "stairs:slab_silver_sandstone"}, {["x"] = 2, ["y"] = 4, ["param1"] = 110, ["z"] = 36, ["name"] = "stairs:slab_silver_sandstone"}, {["x"] = 2, ["y"] = 4, ["param1"] = 94, ["z"] = 37, ["name"] = "stairs:slab_silver_sandstone"}, {["x"] = 2, ["y"] = 4, ["param1"] = 78, ["z"] = 38, ["name"] = "stairs:slab_silver_sandstone"}, {["x"] = 3, ["y"] = 0, ["param1"] = 16, ["z"] = 1, ["name"] = "default:silver_sandstone"}, {["x"] = 3, ["y"] = 0, ["param1"] = 16, ["z"] = 2, ["name"] = "default:silver_sandstone"}, {["x"] = 3, ["y"] = 0, ["param1"] = 16, ["z"] = 3, ["name"] = "default:silver_sandstone"}, {["x"] = 3, ["y"] = 0, ["param1"] = 42, ["z"] = 11, ["name"] = "mesecons_insulated:insulated_off"}, {["x"] = 3, ["y"] = 0, ["param1"] = 16, ["z"] = 19, ["name"] = "default:silver_sandstone"}, {["x"] = 3, ["param2"] = 2, ["y"] = 0, ["param1"] = 73, ["z"] = 20, ["name"] = "mesecons_insulated:insulated_off"}, {["x"] = 3, ["y"] = 0, ["param1"] = 16, ["z"] = 36, ["name"] = "default:silver_sandstone"}, {["x"] = 3, ["y"] = 0, ["param1"] = 16, ["z"] = 37, ["name"] = "default:silver_sandstone"}, {["x"] = 3, ["y"] = 0, ["param1"] = 16, ["z"] = 38, ["name"] = "default:silver_sandstone"}, {["x"] = 3, ["y"] = 1, ["param1"] = 16, ["z"] = 1, ["name"] = "default:silver_sandstone"}, {["x"] = 3, ["y"] = 1, ["param1"] = 16, ["z"] = 2, ["name"] = "default:silver_sandstone"}, {["x"] = 3, ["y"] = 1, ["param1"] = 59, ["z"] = 3, ["name"] = "default:mese"}, {["x"] = 3, ["y"] = 1, ["param1"] = 16, ["z"] = 4, ["name"] = "default:silver_sandstone"}, {["x"] = 3, ["y"] = 1, ["param1"] = 59, ["z"] = 5, ["name"] = "default:mese"}, {["x"] = 3, ["y"] = 1, ["param1"] = 16, ["z"] = 6, ["name"] = "default:silver_sandstone"}, {["x"] = 3, ["y"] = 1, ["param1"] = 59, ["z"] = 7, ["name"] = "default:mese"}, {["x"] = 3, ["y"] = 1, ["param1"] = 16, ["z"] = 8, ["name"] = "default:silver_sandstone"}, {["x"] = 3, ["y"] = 1, ["param1"] = 59, ["z"] = 9, ["name"] = "default:mese"}, {["x"] = 3, ["y"] = 1, ["param1"] = 16, ["z"] = 10, ["name"] = "default:silver_sandstone"}, {["x"] = 3, ["y"] = 1, ["param1"] = 59, ["z"] = 11, ["name"] = "default:mese"}, {["x"] = 3, ["y"] = 1, ["param1"] = 16, ["z"] = 12, ["name"] = "default:silver_sandstone"}, {["x"] = 3, ["y"] = 1, ["param1"] = 59, ["z"] = 13, ["name"] = "default:mese"}, {["x"] = 3, ["y"] = 1, ["param1"] = 16, ["z"] = 14, ["name"] = "default:silver_sandstone"}, {["x"] = 3, ["y"] = 1, ["param1"] = 59, ["z"] = 15, ["name"] = "default:mese"}, {["x"] = 3, ["y"] = 1, ["param1"] = 16, ["z"] = 16, ["name"] = "default:silver_sandstone"}, {["x"] = 3, ["y"] = 1, ["param1"] = 75, ["z"] = 17, ["name"] = "default:mese"}, {["x"] = 3, ["y"] = 1, ["param1"] = 16, ["z"] = 18, ["name"] = "default:silver_sandstone"}, {["x"] = 3, ["y"] = 1, ["param1"] = 107, ["z"] = 19, ["name"] = "default:mese"}, {["x"] = 3, ["y"] = 1, ["param1"] = 16, ["z"] = 20, ["name"] = "default:silver_sandstone"}, {["x"] = 3, ["y"] = 1, ["param1"] = 107, ["z"] = 21, ["name"] = "default:mese"}, {["x"] = 3, ["y"] = 1, ["param1"] = 16, ["z"] = 22, ["name"] = "default:silver_sandstone"}, {["x"] = 3, ["y"] = 1, ["param1"] = 75, ["z"] = 23, ["name"] = "default:mese"}, {["x"] = 3, ["y"] = 1, ["param1"] = 16, ["z"] = 24, ["name"] = "default:silver_sandstone"}, {["x"] = 3, ["y"] = 1, ["param1"] = 59, ["z"] = 25, ["name"] = "default:mese"}, {["x"] = 3, ["y"] = 1, ["param1"] = 16, ["z"] = 26, ["name"] = "default:silver_sandstone"}, {["x"] = 3, ["y"] = 1, ["param1"] = 91, ["z"] = 27, ["name"] = "default:mese"}, {["x"] = 3, ["y"] = 1, ["param1"] = 16, ["z"] = 28, ["name"] = "default:silver_sandstone"}, {["x"] = 3, ["y"] = 1, ["param1"] = 123, ["z"] = 29, ["name"] = "default:mese"}, {["x"] = 3, ["y"] = 1, ["param1"] = 16, ["z"] = 30, ["name"] = "default:silver_sandstone"}, {["x"] = 3, ["y"] = 1, ["param1"] = 123, ["z"] = 31, ["name"] = "default:mese"}, {["x"] = 3, ["y"] = 1, ["param1"] = 16, ["z"] = 32, ["name"] = "default:silver_sandstone"}, {["x"] = 3, ["y"] = 1, ["param1"] = 123, ["z"] = 33, ["name"] = "default:mese"}, {["x"] = 3, ["y"] = 1, ["param1"] = 16, ["z"] = 34, ["name"] = "default:silver_sandstone"}, {["x"] = 3, ["y"] = 1, ["param1"] = 16, ["z"] = 35, ["name"] = "default:silver_sandstone"}, {["x"] = 3, ["y"] = 1, ["param1"] = 16, ["z"] = 36, ["name"] = "default:silver_sandstone"}, {["x"] = 3, ["y"] = 1, ["param1"] = 16, ["z"] = 37, ["name"] = "default:silver_sandstone"}, {["x"] = 3, ["y"] = 1, ["param1"] = 16, ["z"] = 38, ["name"] = "default:silver_sandstone"}, {["x"] = 3, ["y"] = 2, ["param1"] = 16, ["z"] = 1, ["name"] = "default:silver_sandstone"}, {["x"] = 3, ["meta"] = {["fields"] = {["real_portstates"] = "1", ["code"] = "-- D Flipflop (toggle D state when enabled)\13-- Minetest Mesecons Lua Controller\13-- B:data, C:enable/clock, A:output, D:carry data out\13\13if (event.type == \"program\") then\13  mem.a, mem.b, mem.c, mem.d = false, false, false, false\13  mem.and1, mem.and2 = false, false\13end\13\13function set_value(port, value) -- sets variable value based on input\13  if (port == \"A\") then \13    mem.a = value\13  elseif (port == \"B\") then\13    mem.b = value\13  elseif (port == \"C\") then\13    mem.c = value\13  elseif (port == \"D\") then\13    mem.d = value\13  end\13end\13\13function run_code() -- the circuit logic ++++\13\13  -- get first two AND gates based on clock and data\13  if (mem.c and mem.b) then\13    mem.and1 = true\13  else\13    mem.and1 = false\13  end\13  if (mem.c and not mem.b) then\13    mem.and2 = true\13  else\13    mem.and2 = false\13  end\13\13  -- SR Latch\13  if (mem.and1) then\13    port.a = true\13  end\13  if (mem.and2) then\13    port.a = false\13  end\
\
  -- Carry Data Out\
  port.d = mem.b\13\13end\13\13if (event.type == \"on\") then\13  set_value(event.pin.name, true)\13  run_code()\13end\13if (event.type == \"off\") then\13  set_value(event.pin.name, false)\13  run_code()\13end", ["formspec"] = "size[12,10]background[-0.2,-0.25;12.4,10.75;jeija_luac_background.png]label[0.1,8.3;]textarea[0.2,0.2;12.2,9.5;code;;-- D Flipflop (toggle D state when enabled)\13-- Minetest Mesecons Lua Controller\13-- B:data\\, C:enable/clock\\, A:output\\, D:carry data out\13\13if (event.type == \"program\") then\13  mem.a\\, mem.b\\, mem.c\\, mem.d = false\\, false\\, false\\, false\13  mem.and1\\, mem.and2 = false\\, false\13end\13\13function set_value(port\\, value) -- sets variable value based on input\13  if (port == \"A\") then \13    mem.a = value\13  elseif (port == \"B\") then\13    mem.b = value\13  elseif (port == \"C\") then\13    mem.c = value\13  elseif (port == \"D\") then\13    mem.d = value\13  end\13end\13\13function run_code() -- the circuit logic ++++\13\13  -- get first two AND gates based on clock and data\13  if (mem.c and mem.b) then\13    mem.and1 = true\13  else\13    mem.and1 = false\13  end\13  if (mem.c and not mem.b) then\13    mem.and2 = true\13  else\13    mem.and2 = false\13  end\13\13  -- SR Latch\13  if (mem.and1) then\13    port.a = true\13  end\13  if (mem.and2) then\13    port.a = false\13  end\
\
  -- Carry Data Out\
  port.d = mem.b\13\13end\13\13if (event.type == \"on\") then\13  set_value(event.pin.name\\, true)\13  run_code()\13end\13if (event.type == \"off\") then\13  set_value(event.pin.name\\, false)\13  run_code()\13end]image_button[4.75,8.75;2.5,1;jeija_luac_runbutton.png;program;]image_button_exit[11.72,-0.25;0.425,0.4;jeija_close_window.png;exit;]", ["lc_memory"] = "return {[\"b\"] = false, [\"and2\"] = false, [\"d\"] = false, [\"and1\"] = false, [\"a\"] = false, [\"c\"] = false}", ["ignore_offevents"] = "return {[\"D\"] = true}", ["luac_id"] = "19270"}, ["inventory"] = {}}, ["y"] = 2, ["param1"] = 76, ["z"] = 3, ["name"] = "mesecons_luacontroller:luacontroller0000"}, {["x"] = 3, ["param2"] = 3, ["y"] = 2, ["param1"] = 92, ["z"] = 4, ["name"] = "mesecons_insulated:insulated_off"}, {["x"] = 3, ["meta"] = {["fields"] = {["real_portstates"] = "1", ["code"] = "-- D Flipflop (toggle D state when enabled)\13-- Minetest Mesecons Lua Controller\13-- B:data, C:enable/clock, A:output, D:carry data out\13\13if (event.type == \"program\") then\13  mem.a, mem.b, mem.c, mem.d = false, false, false, false\13  mem.and1, mem.and2 = false, false\13end\13\13function set_value(port, value) -- sets variable value based on input\13  if (port == \"A\") then \13    mem.a = value\13  elseif (port == \"B\") then\13    mem.b = value\13  elseif (port == \"C\") then\13    mem.c = value\13  elseif (port == \"D\") then\13    mem.d = value\13  end\13end\13\13function run_code() -- the circuit logic ++++\13\13  -- get first two AND gates based on clock and data\13  if (mem.c and mem.b) then\13    mem.and1 = true\13  else\13    mem.and1 = false\13  end\13  if (mem.c and not mem.b) then\13    mem.and2 = true\13  else\13    mem.and2 = false\13  end\13\13  -- SR Latch\13  if (mem.and1) then\13    port.a = true\13  end\13  if (mem.and2) then\13    port.a = false\13  end\
\
  -- Carry Data Out\
  port.d = mem.b\13\13end\13\13if (event.type == \"on\") then\13  set_value(event.pin.name, true)\13  run_code()\13end\13if (event.type == \"off\") then\13  set_value(event.pin.name, false)\13  run_code()\13end", ["formspec"] = "size[12,10]background[-0.2,-0.25;12.4,10.75;jeija_luac_background.png]label[0.1,8.3;]textarea[0.2,0.2;12.2,9.5;code;;-- D Flipflop (toggle D state when enabled)\13-- Minetest Mesecons Lua Controller\13-- B:data\\, C:enable/clock\\, A:output\\, D:carry data out\13\13if (event.type == \"program\") then\13  mem.a\\, mem.b\\, mem.c\\, mem.d = false\\, false\\, false\\, false\13  mem.and1\\, mem.and2 = false\\, false\13end\13\13function set_value(port\\, value) -- sets variable value based on input\13  if (port == \"A\") then \13    mem.a = value\13  elseif (port == \"B\") then\13    mem.b = value\13  elseif (port == \"C\") then\13    mem.c = value\13  elseif (port == \"D\") then\13    mem.d = value\13  end\13end\13\13function run_code() -- the circuit logic ++++\13\13  -- get first two AND gates based on clock and data\13  if (mem.c and mem.b) then\13    mem.and1 = true\13  else\13    mem.and1 = false\13  end\13  if (mem.c and not mem.b) then\13    mem.and2 = true\13  else\13    mem.and2 = false\13  end\13\13  -- SR Latch\13  if (mem.and1) then\13    port.a = true\13  end\13  if (mem.and2) then\13    port.a = false\13  end\
\
  -- Carry Data Out\
  port.d = mem.b\13\13end\13\13if (event.type == \"on\") then\13  set_value(event.pin.name\\, true)\13  run_code()\13end\13if (event.type == \"off\") then\13  set_value(event.pin.name\\, false)\13  run_code()\13end]image_button[4.75,8.75;2.5,1;jeija_luac_runbutton.png;program;]image_button_exit[11.72,-0.25;0.425,0.4;jeija_close_window.png;exit;]", ["lc_memory"] = "return {[\"b\"] = false, [\"and2\"] = false, [\"d\"] = false, [\"a\"] = false, [\"c\"] = false, [\"and1\"] = false}", ["ignore_offevents"] = "return {}", ["luac_id"] = "19270"}, ["inventory"] = {}}, ["y"] = 2, ["param1"] = 76, ["z"] = 5, ["name"] = "mesecons_luacontroller:luacontroller0000"}, {["x"] = 3, ["param2"] = 3, ["y"] = 2, ["param1"] = 60, ["z"] = 6, ["name"] = "mesecons_insulated:insulated_off"}, {["x"] = 3, ["meta"] = {["fields"] = {["real_portstates"] = "1", ["code"] = "-- D Flipflop (toggle D state when enabled)\13-- Minetest Mesecons Lua Controller\13-- B:data, C:enable/clock, A:output, D:carry data out\13\13if (event.type == \"program\") then\13  mem.a, mem.b, mem.c, mem.d = false, false, false, false\13  mem.and1, mem.and2 = false, false\13end\13\13function set_value(port, value) -- sets variable value based on input\13  if (port == \"A\") then \13    mem.a = value\13  elseif (port == \"B\") then\13    mem.b = value\13  elseif (port == \"C\") then\13    mem.c = value\13  elseif (port == \"D\") then\13    mem.d = value\13  end\13end\13\13function run_code() -- the circuit logic ++++\13\13  -- get first two AND gates based on clock and data\13  if (mem.c and mem.b) then\13    mem.and1 = true\13  else\13    mem.and1 = false\13  end\13  if (mem.c and not mem.b) then\13    mem.and2 = true\13  else\13    mem.and2 = false\13  end\13\13  -- SR Latch\13  if (mem.and1) then\13    port.a = true\13  end\13  if (mem.and2) then\13    port.a = false\13  end\
\
  -- Carry Data Out\
  port.d = mem.b\13\13end\13\13if (event.type == \"on\") then\13  set_value(event.pin.name, true)\13  run_code()\13end\13if (event.type == \"off\") then\13  set_value(event.pin.name, false)\13  run_code()\13end", ["formspec"] = "size[12,10]background[-0.2,-0.25;12.4,10.75;jeija_luac_background.png]label[0.1,8.3;]textarea[0.2,0.2;12.2,9.5;code;;-- D Flipflop (toggle D state when enabled)\13-- Minetest Mesecons Lua Controller\13-- B:data\\, C:enable/clock\\, A:output\\, D:carry data out\13\13if (event.type == \"program\") then\13  mem.a\\, mem.b\\, mem.c\\, mem.d = false\\, false\\, false\\, false\13  mem.and1\\, mem.and2 = false\\, false\13end\13\13function set_value(port\\, value) -- sets variable value based on input\13  if (port == \"A\") then \13    mem.a = value\13  elseif (port == \"B\") then\13    mem.b = value\13  elseif (port == \"C\") then\13    mem.c = value\13  elseif (port == \"D\") then\13    mem.d = value\13  end\13end\13\13function run_code() -- the circuit logic ++++\13\13  -- get first two AND gates based on clock and data\13  if (mem.c and mem.b) then\13    mem.and1 = true\13  else\13    mem.and1 = false\13  end\13  if (mem.c and not mem.b) then\13    mem.and2 = true\13  else\13    mem.and2 = false\13  end\13\13  -- SR Latch\13  if (mem.and1) then\13    port.a = true\13  end\13  if (mem.and2) then\13    port.a = false\13  end\
\
  -- Carry Data Out\
  port.d = mem.b\13\13end\13\13if (event.type == \"on\") then\13  set_value(event.pin.name\\, true)\13  run_code()\13end\13if (event.type == \"off\") then\13  set_value(event.pin.name\\, false)\13  run_code()\13end]image_button[4.75,8.75;2.5,1;jeija_luac_runbutton.png;program;]image_button_exit[11.72,-0.25;0.425,0.4;jeija_close_window.png;exit;]", ["lc_memory"] = "return {[\"b\"] = false, [\"and2\"] = false, [\"d\"] = false, [\"a\"] = false, [\"c\"] = false, [\"and1\"] = false}", ["ignore_offevents"] = "return {}", ["luac_id"] = "19270"}, ["inventory"] = {}}, ["y"] = 2, ["param1"] = 44, ["z"] = 7, ["name"] = "mesecons_luacontroller:luacontroller0000"}, {["x"] = 3, ["param2"] = 3, ["y"] = 2, ["param1"] = 44, ["z"] = 8, ["name"] = "mesecons_insulated:insulated_off"}, {["x"] = 3, ["meta"] = {["fields"] = {["real_portstates"] = "1", ["code"] = "-- D Flipflop (toggle D state when enabled)\13-- Minetest Mesecons Lua Controller\13-- B:data, C:enable/clock, A:output, D:carry data out\13\13if (event.type == \"program\") then\13  mem.a, mem.b, mem.c, mem.d = false, false, false, false\13  mem.and1, mem.and2 = false, false\13end\13\13function set_value(port, value) -- sets variable value based on input\13  if (port == \"A\") then \13    mem.a = value\13  elseif (port == \"B\") then\13    mem.b = value\13  elseif (port == \"C\") then\13    mem.c = value\13  elseif (port == \"D\") then\13    mem.d = value\13  end\13end\13\13function run_code() -- the circuit logic ++++\13\13  -- get first two AND gates based on clock and data\13  if (mem.c and mem.b) then\13    mem.and1 = true\13  else\13    mem.and1 = false\13  end\13  if (mem.c and not mem.b) then\13    mem.and2 = true\13  else\13    mem.and2 = false\13  end\13\13  -- SR Latch\13  if (mem.and1) then\13    port.a = true\13  end\13  if (mem.and2) then\13    port.a = false\13  end\
\
  -- Carry Data Out\
  port.d = mem.b\13\13end\13\13if (event.type == \"on\") then\13  set_value(event.pin.name, true)\13  run_code()\13end\13if (event.type == \"off\") then\13  set_value(event.pin.name, false)\13  run_code()\13end", ["formspec"] = "size[12,10]background[-0.2,-0.25;12.4,10.75;jeija_luac_background.png]label[0.1,8.3;]textarea[0.2,0.2;12.2,9.5;code;;-- D Flipflop (toggle D state when enabled)\13-- Minetest Mesecons Lua Controller\13-- B:data\\, C:enable/clock\\, A:output\\, D:carry data out\13\13if (event.type == \"program\") then\13  mem.a\\, mem.b\\, mem.c\\, mem.d = false\\, false\\, false\\, false\13  mem.and1\\, mem.and2 = false\\, false\13end\13\13function set_value(port\\, value) -- sets variable value based on input\13  if (port == \"A\") then \13    mem.a = value\13  elseif (port == \"B\") then\13    mem.b = value\13  elseif (port == \"C\") then\13    mem.c = value\13  elseif (port == \"D\") then\13    mem.d = value\13  end\13end\13\13function run_code() -- the circuit logic ++++\13\13  -- get first two AND gates based on clock and data\13  if (mem.c and mem.b) then\13    mem.and1 = true\13  else\13    mem.and1 = false\13  end\13  if (mem.c and not mem.b) then\13    mem.and2 = true\13  else\13    mem.and2 = false\13  end\13\13  -- SR Latch\13  if (mem.and1) then\13    port.a = true\13  end\13  if (mem.and2) then\13    port.a = false\13  end\
\
  -- Carry Data Out\
  port.d = mem.b\13\13end\13\13if (event.type == \"on\") then\13  set_value(event.pin.name\\, true)\13  run_code()\13end\13if (event.type == \"off\") then\13  set_value(event.pin.name\\, false)\13  run_code()\13end]image_button[4.75,8.75;2.5,1;jeija_luac_runbutton.png;program;]image_button_exit[11.72,-0.25;0.425,0.4;jeija_close_window.png;exit;]", ["lc_memory"] = "return {[\"b\"] = false, [\"and2\"] = false, [\"and1\"] = false, [\"c\"] = false, [\"a\"] = false, [\"d\"] = false}", ["ignore_offevents"] = "return {}", ["luac_id"] = "19270"}, ["inventory"] = {}}, ["y"] = 2, ["param1"] = 44, ["z"] = 9, ["name"] = "mesecons_luacontroller:luacontroller0000"}, {["x"] = 3, ["param2"] = 3, ["y"] = 2, ["param1"] = 44, ["z"] = 10, ["name"] = "mesecons_insulated:insulated_off"}, {["x"] = 3, ["meta"] = {["fields"] = {["real_portstates"] = "1", ["code"] = "-- D Flipflop (toggle D state when enabled)\13-- Minetest Mesecons Lua Controller\13-- B:data, C:enable/clock, A:output, D:carry data out\13\13if (event.type == \"program\") then\13  mem.a, mem.b, mem.c, mem.d = false, false, false, false\13  mem.and1, mem.and2 = false, false\13end\13\13function set_value(port, value) -- sets variable value based on input\13  if (port == \"A\") then \13    mem.a = value\13  elseif (port == \"B\") then\13    mem.b = value\13  elseif (port == \"C\") then\13    mem.c = value\13  elseif (port == \"D\") then\13    mem.d = value\13  end\13end\13\13function run_code() -- the circuit logic ++++\13\13  -- get first two AND gates based on clock and data\13  if (mem.c and mem.b) then\13    mem.and1 = true\13  else\13    mem.and1 = false\13  end\13  if (mem.c and not mem.b) then\13    mem.and2 = true\13  else\13    mem.and2 = false\13  end\13\13  -- SR Latch\13  if (mem.and1) then\13    port.a = true\13  end\13  if (mem.and2) then\13    port.a = false\13  end\
\
  -- Carry Data Out\
  port.d = mem.b\13\13end\13\13if (event.type == \"on\") then\13  set_value(event.pin.name, true)\13  run_code()\13end\13if (event.type == \"off\") then\13  set_value(event.pin.name, false)\13  run_code()\13end", ["formspec"] = "size[12,10]background[-0.2,-0.25;12.4,10.75;jeija_luac_background.png]label[0.1,8.3;]textarea[0.2,0.2;12.2,9.5;code;;-- D Flipflop (toggle D state when enabled)\13-- Minetest Mesecons Lua Controller\13-- B:data\\, C:enable/clock\\, A:output\\, D:carry data out\13\13if (event.type == \"program\") then\13  mem.a\\, mem.b\\, mem.c\\, mem.d = false\\, false\\, false\\, false\13  mem.and1\\, mem.and2 = false\\, false\13end\13\13function set_value(port\\, value) -- sets variable value based on input\13  if (port == \"A\") then \13    mem.a = value\13  elseif (port == \"B\") then\13    mem.b = value\13  elseif (port == \"C\") then\13    mem.c = value\13  elseif (port == \"D\") then\13    mem.d = value\13  end\13end\13\13function run_code() -- the circuit logic ++++\13\13  -- get first two AND gates based on clock and data\13  if (mem.c and mem.b) then\13    mem.and1 = true\13  else\13    mem.and1 = false\13  end\13  if (mem.c and not mem.b) then\13    mem.and2 = true\13  else\13    mem.and2 = false\13  end\13\13  -- SR Latch\13  if (mem.and1) then\13    port.a = true\13  end\13  if (mem.and2) then\13    port.a = false\13  end\
\
  -- Carry Data Out\
  port.d = mem.b\13\13end\13\13if (event.type == \"on\") then\13  set_value(event.pin.name\\, true)\13  run_code()\13end\13if (event.type == \"off\") then\13  set_value(event.pin.name\\, false)\13  run_code()\13end]image_button[4.75,8.75;2.5,1;jeija_luac_runbutton.png;program;]image_button_exit[11.72,-0.25;0.425,0.4;jeija_close_window.png;exit;]", ["lc_memory"] = "return {[\"b\"] = false, [\"and2\"] = false, [\"d\"] = false, [\"a\"] = false, [\"c\"] = false, [\"and1\"] = false}", ["ignore_offevents"] = "return {}", ["luac_id"] = "19270"}, ["inventory"] = {}}, ["y"] = 2, ["param1"] = 44, ["z"] = 11, ["name"] = "mesecons_luacontroller:luacontroller0000"}, {["x"] = 3, ["param2"] = 3, ["y"] = 2, ["param1"] = 60, ["z"] = 12, ["name"] = "mesecons_insulated:insulated_off"}, {["x"] = 3, ["meta"] = {["fields"] = {["real_portstates"] = "1", ["code"] = "-- D Flipflop (toggle D state when enabled)\13-- Minetest Mesecons Lua Controller\13-- B:data, C:enable/clock, A:output, D:carry data out\13\13if (event.type == \"program\") then\13  mem.a, mem.b, mem.c, mem.d = false, false, false, false\13  mem.and1, mem.and2 = false, false\13end\13\13function set_value(port, value) -- sets variable value based on input\13  if (port == \"A\") then \13    mem.a = value\13  elseif (port == \"B\") then\13    mem.b = value\13  elseif (port == \"C\") then\13    mem.c = value\13  elseif (port == \"D\") then\13    mem.d = value\13  end\13end\13\13function run_code() -- the circuit logic ++++\13\13  -- get first two AND gates based on clock and data\13  if (mem.c and mem.b) then\13    mem.and1 = true\13  else\13    mem.and1 = false\13  end\13  if (mem.c and not mem.b) then\13    mem.and2 = true\13  else\13    mem.and2 = false\13  end\13\13  -- SR Latch\13  if (mem.and1) then\13    port.a = true\13  end\13  if (mem.and2) then\13    port.a = false\13  end\
\
  -- Carry Data Out\
  port.d = mem.b\13\13end\13\13if (event.type == \"on\") then\13  set_value(event.pin.name, true)\13  run_code()\13end\13if (event.type == \"off\") then\13  set_value(event.pin.name, false)\13  run_code()\13end", ["formspec"] = "size[12,10]background[-0.2,-0.25;12.4,10.75;jeija_luac_background.png]label[0.1,8.3;]textarea[0.2,0.2;12.2,9.5;code;;-- D Flipflop (toggle D state when enabled)\13-- Minetest Mesecons Lua Controller\13-- B:data\\, C:enable/clock\\, A:output\\, D:carry data out\13\13if (event.type == \"program\") then\13  mem.a\\, mem.b\\, mem.c\\, mem.d = false\\, false\\, false\\, false\13  mem.and1\\, mem.and2 = false\\, false\13end\13\13function set_value(port\\, value) -- sets variable value based on input\13  if (port == \"A\") then \13    mem.a = value\13  elseif (port == \"B\") then\13    mem.b = value\13  elseif (port == \"C\") then\13    mem.c = value\13  elseif (port == \"D\") then\13    mem.d = value\13  end\13end\13\13function run_code() -- the circuit logic ++++\13\13  -- get first two AND gates based on clock and data\13  if (mem.c and mem.b) then\13    mem.and1 = true\13  else\13    mem.and1 = false\13  end\13  if (mem.c and not mem.b) then\13    mem.and2 = true\13  else\13    mem.and2 = false\13  end\13\13  -- SR Latch\13  if (mem.and1) then\13    port.a = true\13  end\13  if (mem.and2) then\13    port.a = false\13  end\
\
  -- Carry Data Out\
  port.d = mem.b\13\13end\13\13if (event.type == \"on\") then\13  set_value(event.pin.name\\, true)\13  run_code()\13end\13if (event.type == \"off\") then\13  set_value(event.pin.name\\, false)\13  run_code()\13end]image_button[4.75,8.75;2.5,1;jeija_luac_runbutton.png;program;]image_button_exit[11.72,-0.25;0.425,0.4;jeija_close_window.png;exit;]", ["lc_memory"] = "return {[\"b\"] = false, [\"and2\"] = false, [\"d\"] = false, [\"a\"] = false, [\"c\"] = false, [\"and1\"] = false}", ["ignore_offevents"] = "return {}", ["luac_id"] = "19270"}, ["inventory"] = {}}, ["y"] = 2, ["param1"] = 76, ["z"] = 13, ["name"] = "mesecons_luacontroller:luacontroller0000"}, {["x"] = 3, ["param2"] = 3, ["y"] = 2, ["param1"] = 92, ["z"] = 14, ["name"] = "mesecons_insulated:insulated_off"}, {["x"] = 3, ["meta"] = {["fields"] = {["real_portstates"] = "1", ["code"] = "-- D Flipflop (toggle D state when enabled)\13-- Minetest Mesecons Lua Controller\13-- B:data, C:enable/clock, A:output, D:carry data out\13\13if (event.type == \"program\") then\13  mem.a, mem.b, mem.c, mem.d = false, false, false, false\13  mem.and1, mem.and2 = false, false\13end\13\13function set_value(port, value) -- sets variable value based on input\13  if (port == \"A\") then \13    mem.a = value\13  elseif (port == \"B\") then\13    mem.b = value\13  elseif (port == \"C\") then\13    mem.c = value\13  elseif (port == \"D\") then\13    mem.d = value\13  end\13end\13\13function run_code() -- the circuit logic ++++\13\13  -- get first two AND gates based on clock and data\13  if (mem.c and mem.b) then\13    mem.and1 = true\13  else\13    mem.and1 = false\13  end\13  if (mem.c and not mem.b) then\13    mem.and2 = true\13  else\13    mem.and2 = false\13  end\13\13  -- SR Latch\13  if (mem.and1) then\13    port.a = true\13  end\13  if (mem.and2) then\13    port.a = false\13  end\
\
  -- Carry Data Out\
  port.d = mem.b\13\13end\13\13if (event.type == \"on\") then\13  set_value(event.pin.name, true)\13  run_code()\13end\13if (event.type == \"off\") then\13  set_value(event.pin.name, false)\13  run_code()\13end", ["formspec"] = "size[12,10]background[-0.2,-0.25;12.4,10.75;jeija_luac_background.png]label[0.1,8.3;]textarea[0.2,0.2;12.2,9.5;code;;-- D Flipflop (toggle D state when enabled)\13-- Minetest Mesecons Lua Controller\13-- B:data\\, C:enable/clock\\, A:output\\, D:carry data out\13\13if (event.type == \"program\") then\13  mem.a\\, mem.b\\, mem.c\\, mem.d = false\\, false\\, false\\, false\13  mem.and1\\, mem.and2 = false\\, false\13end\13\13function set_value(port\\, value) -- sets variable value based on input\13  if (port == \"A\") then \13    mem.a = value\13  elseif (port == \"B\") then\13    mem.b = value\13  elseif (port == \"C\") then\13    mem.c = value\13  elseif (port == \"D\") then\13    mem.d = value\13  end\13end\13\13function run_code() -- the circuit logic ++++\13\13  -- get first two AND gates based on clock and data\13  if (mem.c and mem.b) then\13    mem.and1 = true\13  else\13    mem.and1 = false\13  end\13  if (mem.c and not mem.b) then\13    mem.and2 = true\13  else\13    mem.and2 = false\13  end\13\13  -- SR Latch\13  if (mem.and1) then\13    port.a = true\13  end\13  if (mem.and2) then\13    port.a = false\13  end\
\
  -- Carry Data Out\
  port.d = mem.b\13\13end\13\13if (event.type == \"on\") then\13  set_value(event.pin.name\\, true)\13  run_code()\13end\13if (event.type == \"off\") then\13  set_value(event.pin.name\\, false)\13  run_code()\13end]image_button[4.75,8.75;2.5,1;jeija_luac_runbutton.png;program;]image_button_exit[11.72,-0.25;0.425,0.4;jeija_close_window.png;exit;]", ["lc_memory"] = "return {[\"b\"] = false, [\"and2\"] = false, [\"d\"] = false, [\"a\"] = false, [\"c\"] = false, [\"and1\"] = false}", ["ignore_offevents"] = "return {}", ["luac_id"] = "19270"}, ["inventory"] = {}}, ["y"] = 2, ["param1"] = 76, ["z"] = 15, ["name"] = "mesecons_luacontroller:luacontroller0000"}, {["x"] = 3, ["param2"] = 3, ["y"] = 2, ["param1"] = 76, ["z"] = 16, ["name"] = "mesecons_insulated:insulated_off"}, {["x"] = 3, ["meta"] = {["fields"] = {["real_portstates"] = "1", ["code"] = "-- D Flipflop (toggle D state when enabled)\13-- Minetest Mesecons Lua Controller\13-- B:data, C:enable/clock, A:output, D:carry data out\13\13if (event.type == \"program\") then\13  mem.a, mem.b, mem.c, mem.d = false, false, false, false\13  mem.and1, mem.and2 = false, false\13end\13\13function set_value(port, value) -- sets variable value based on input\13  if (port == \"A\") then \13    mem.a = value\13  elseif (port == \"B\") then\13    mem.b = value\13  elseif (port == \"C\") then\13    mem.c = value\13  elseif (port == \"D\") then\13    mem.d = value\13  end\13end\13\13function run_code() -- the circuit logic ++++\13\13  -- get first two AND gates based on clock and data\13  if (mem.c and mem.b) then\13    mem.and1 = true\13  else\13    mem.and1 = false\13  end\13  if (mem.c and not mem.b) then\13    mem.and2 = true\13  else\13    mem.and2 = false\13  end\13\13  -- SR Latch\13  if (mem.and1) then\13    port.a = true\13  end\13  if (mem.and2) then\13    port.a = false\13  end\
\
  -- Carry Data Out\
  port.d = mem.b\13\13end\13\13if (event.type == \"on\") then\13  set_value(event.pin.name, true)\13  run_code()\13end\13if (event.type == \"off\") then\13  set_value(event.pin.name, false)\13  run_code()\13end", ["formspec"] = "size[12,10]background[-0.2,-0.25;12.4,10.75;jeija_luac_background.png]label[0.1,8.3;]textarea[0.2,0.2;12.2,9.5;code;;-- D Flipflop (toggle D state when enabled)\13-- Minetest Mesecons Lua Controller\13-- B:data\\, C:enable/clock\\, A:output\\, D:carry data out\13\13if (event.type == \"program\") then\13  mem.a\\, mem.b\\, mem.c\\, mem.d = false\\, false\\, false\\, false\13  mem.and1\\, mem.and2 = false\\, false\13end\13\13function set_value(port\\, value) -- sets variable value based on input\13  if (port == \"A\") then \13    mem.a = value\13  elseif (port == \"B\") then\13    mem.b = value\13  elseif (port == \"C\") then\13    mem.c = value\13  elseif (port == \"D\") then\13    mem.d = value\13  end\13end\13\13function run_code() -- the circuit logic ++++\13\13  -- get first two AND gates based on clock and data\13  if (mem.c and mem.b) then\13    mem.and1 = true\13  else\13    mem.and1 = false\13  end\13  if (mem.c and not mem.b) then\13    mem.and2 = true\13  else\13    mem.and2 = false\13  end\13\13  -- SR Latch\13  if (mem.and1) then\13    port.a = true\13  end\13  if (mem.and2) then\13    port.a = false\13  end\
\
  -- Carry Data Out\
  port.d = mem.b\13\13end\13\13if (event.type == \"on\") then\13  set_value(event.pin.name\\, true)\13  run_code()\13end\13if (event.type == \"off\") then\13  set_value(event.pin.name\\, false)\13  run_code()\13end]image_button[4.75,8.75;2.5,1;jeija_luac_runbutton.png;program;]image_button_exit[11.72,-0.25;0.425,0.4;jeija_close_window.png;exit;]", ["lc_memory"] = "return {[\"b\"] = false, [\"and2\"] = false, [\"d\"] = false, [\"a\"] = false, [\"c\"] = false, [\"and1\"] = false}", ["ignore_offevents"] = "return {}", ["luac_id"] = "19270"}, ["inventory"] = {}}, ["y"] = 2, ["param1"] = 92, ["z"] = 17, ["name"] = "mesecons_luacontroller:luacontroller0000"}, {["x"] = 3, ["param2"] = 3, ["y"] = 2, ["param1"] = 108, ["z"] = 18, ["name"] = "mesecons_insulated:insulated_off"}, {["x"] = 3, ["meta"] = {["fields"] = {["real_portstates"] = "1", ["code"] = "-- D Flipflop (toggle D state when enabled)\13-- Minetest Mesecons Lua Controller\13-- B:data, C:enable/clock, A:output, D:carry data out\13\13if (event.type == \"program\") then\13  mem.a, mem.b, mem.c, mem.d = false, false, false, false\13  mem.and1, mem.and2 = false, false\13end\13\13function set_value(port, value) -- sets variable value based on input\13  if (port == \"A\") then \13    mem.a = value\13  elseif (port == \"B\") then\13    mem.b = value\13  elseif (port == \"C\") then\13    mem.c = value\13  elseif (port == \"D\") then\13    mem.d = value\13  end\13end\13\13function run_code() -- the circuit logic ++++\13\13  -- get first two AND gates based on clock and data\13  if (mem.c and mem.b) then\13    mem.and1 = true\13  else\13    mem.and1 = false\13  end\13  if (mem.c and not mem.b) then\13    mem.and2 = true\13  else\13    mem.and2 = false\13  end\13\13  -- SR Latch\13  if (mem.and1) then\13    port.a = true\13  end\13  if (mem.and2) then\13    port.a = false\13  end\
\
  -- Carry Data Out\
  port.d = mem.b\13\13end\13\13if (event.type == \"on\") then\13  set_value(event.pin.name, true)\13  run_code()\13end\13if (event.type == \"off\") then\13  set_value(event.pin.name, false)\13  run_code()\13end", ["formspec"] = "size[12,10]background[-0.2,-0.25;12.4,10.75;jeija_luac_background.png]label[0.1,8.3;]textarea[0.2,0.2;12.2,9.5;code;;-- D Flipflop (toggle D state when enabled)\13-- Minetest Mesecons Lua Controller\13-- B:data\\, C:enable/clock\\, A:output\\, D:carry data out\13\13if (event.type == \"program\") then\13  mem.a\\, mem.b\\, mem.c\\, mem.d = false\\, false\\, false\\, false\13  mem.and1\\, mem.and2 = false\\, false\13end\13\13function set_value(port\\, value) -- sets variable value based on input\13  if (port == \"A\") then \13    mem.a = value\13  elseif (port == \"B\") then\13    mem.b = value\13  elseif (port == \"C\") then\13    mem.c = value\13  elseif (port == \"D\") then\13    mem.d = value\13  end\13end\13\13function run_code() -- the circuit logic ++++\13\13  -- get first two AND gates based on clock and data\13  if (mem.c and mem.b) then\13    mem.and1 = true\13  else\13    mem.and1 = false\13  end\13  if (mem.c and not mem.b) then\13    mem.and2 = true\13  else\13    mem.and2 = false\13  end\13\13  -- SR Latch\13  if (mem.and1) then\13    port.a = true\13  end\13  if (mem.and2) then\13    port.a = false\13  end\
\
  -- Carry Data Out\
  port.d = mem.b\13\13end\13\13if (event.type == \"on\") then\13  set_value(event.pin.name\\, true)\13  run_code()\13end\13if (event.type == \"off\") then\13  set_value(event.pin.name\\, false)\13  run_code()\13end]image_button[4.75,8.75;2.5,1;jeija_luac_runbutton.png;program;]image_button_exit[11.72,-0.25;0.425,0.4;jeija_close_window.png;exit;]", ["lc_memory"] = "return {[\"b\"] = false, [\"and2\"] = false, [\"and1\"] = false, [\"c\"] = false, [\"a\"] = false, [\"d\"] = false}", ["ignore_offevents"] = "return {}", ["luac_id"] = "19270"}, ["inventory"] = {}}, ["y"] = 2, ["param1"] = 124, ["z"] = 19, ["name"] = "mesecons_luacontroller:luacontroller0000"}, {["x"] = 3, ["param2"] = 3, ["y"] = 2, ["param1"] = 140, ["z"] = 20, ["name"] = "mesecons_insulated:insulated_off"}, {["x"] = 3, ["meta"] = {["fields"] = {["real_portstates"] = "1", ["code"] = "-- D Flipflop (toggle D state when enabled)\13-- Minetest Mesecons Lua Controller\13-- B:data, C:enable/clock, A:output, D:carry data out\13\13if (event.type == \"program\") then\13  mem.a, mem.b, mem.c, mem.d = false, false, false, false\13  mem.and1, mem.and2 = false, false\13end\13\13function set_value(port, value) -- sets variable value based on input\13  if (port == \"A\") then \13    mem.a = value\13  elseif (port == \"B\") then\13    mem.b = value\13  elseif (port == \"C\") then\13    mem.c = value\13  elseif (port == \"D\") then\13    mem.d = value\13  end\13end\13\13function run_code() -- the circuit logic ++++\13\13  -- get first two AND gates based on clock and data\13  if (mem.c and mem.b) then\13    mem.and1 = true\13  else\13    mem.and1 = false\13  end\13  if (mem.c and not mem.b) then\13    mem.and2 = true\13  else\13    mem.and2 = false\13  end\13\13  -- SR Latch\13  if (mem.and1) then\13    port.a = true\13  end\13  if (mem.and2) then\13    port.a = false\13  end\
\
  -- Carry Data Out\
  port.d = mem.b\13\13end\13\13if (event.type == \"on\") then\13  set_value(event.pin.name, true)\13  run_code()\13end\13if (event.type == \"off\") then\13  set_value(event.pin.name, false)\13  run_code()\13end", ["formspec"] = "size[12,10]background[-0.2,-0.25;12.4,10.75;jeija_luac_background.png]label[0.1,8.3;]textarea[0.2,0.2;12.2,9.5;code;;-- D Flipflop (toggle D state when enabled)\13-- Minetest Mesecons Lua Controller\13-- B:data\\, C:enable/clock\\, A:output\\, D:carry data out\13\13if (event.type == \"program\") then\13  mem.a\\, mem.b\\, mem.c\\, mem.d = false\\, false\\, false\\, false\13  mem.and1\\, mem.and2 = false\\, false\13end\13\13function set_value(port\\, value) -- sets variable value based on input\13  if (port == \"A\") then \13    mem.a = value\13  elseif (port == \"B\") then\13    mem.b = value\13  elseif (port == \"C\") then\13    mem.c = value\13  elseif (port == \"D\") then\13    mem.d = value\13  end\13end\13\13function run_code() -- the circuit logic ++++\13\13  -- get first two AND gates based on clock and data\13  if (mem.c and mem.b) then\13    mem.and1 = true\13  else\13    mem.and1 = false\13  end\13  if (mem.c and not mem.b) then\13    mem.and2 = true\13  else\13    mem.and2 = false\13  end\13\13  -- SR Latch\13  if (mem.and1) then\13    port.a = true\13  end\13  if (mem.and2) then\13    port.a = false\13  end\
\
  -- Carry Data Out\
  port.d = mem.b\13\13end\13\13if (event.type == \"on\") then\13  set_value(event.pin.name\\, true)\13  run_code()\13end\13if (event.type == \"off\") then\13  set_value(event.pin.name\\, false)\13  run_code()\13end]image_button[4.75,8.75;2.5,1;jeija_luac_runbutton.png;program;]image_button_exit[11.72,-0.25;0.425,0.4;jeija_close_window.png;exit;]", ["lc_memory"] = "return {[\"b\"] = false, [\"and2\"] = false, [\"and1\"] = false, [\"c\"] = false, [\"a\"] = false, [\"d\"] = false}", ["ignore_offevents"] = "return {}", ["luac_id"] = "19270"}, ["inventory"] = {}}, ["y"] = 2, ["param1"] = 124, ["z"] = 21, ["name"] = "mesecons_luacontroller:luacontroller0000"}, {["x"] = 3, ["param2"] = 3, ["y"] = 2, ["param1"] = 108, ["z"] = 22, ["name"] = "mesecons_insulated:insulated_off"}, {["x"] = 3, ["meta"] = {["fields"] = {["real_portstates"] = "1", ["code"] = "-- D Flipflop (toggle D state when enabled)\13-- Minetest Mesecons Lua Controller\13-- B:data, C:enable/clock, A:output, D:carry data out\13\13if (event.type == \"program\") then\13  mem.a, mem.b, mem.c, mem.d = false, false, false, false\13  mem.and1, mem.and2 = false, false\13end\13\13function set_value(port, value) -- sets variable value based on input\13  if (port == \"A\") then \13    mem.a = value\13  elseif (port == \"B\") then\13    mem.b = value\13  elseif (port == \"C\") then\13    mem.c = value\13  elseif (port == \"D\") then\13    mem.d = value\13  end\13end\13\13function run_code() -- the circuit logic ++++\13\13  -- get first two AND gates based on clock and data\13  if (mem.c and mem.b) then\13    mem.and1 = true\13  else\13    mem.and1 = false\13  end\13  if (mem.c and not mem.b) then\13    mem.and2 = true\13  else\13    mem.and2 = false\13  end\13\13  -- SR Latch\13  if (mem.and1) then\13    port.a = true\13  end\13  if (mem.and2) then\13    port.a = false\13  end\
\
  -- Carry Data Out\
  port.d = mem.b\13\13end\13\13if (event.type == \"on\") then\13  set_value(event.pin.name, true)\13  run_code()\13end\13if (event.type == \"off\") then\13  set_value(event.pin.name, false)\13  run_code()\13end", ["formspec"] = "size[12,10]background[-0.2,-0.25;12.4,10.75;jeija_luac_background.png]label[0.1,8.3;]textarea[0.2,0.2;12.2,9.5;code;;-- D Flipflop (toggle D state when enabled)\13-- Minetest Mesecons Lua Controller\13-- B:data\\, C:enable/clock\\, A:output\\, D:carry data out\13\13if (event.type == \"program\") then\13  mem.a\\, mem.b\\, mem.c\\, mem.d = false\\, false\\, false\\, false\13  mem.and1\\, mem.and2 = false\\, false\13end\13\13function set_value(port\\, value) -- sets variable value based on input\13  if (port == \"A\") then \13    mem.a = value\13  elseif (port == \"B\") then\13    mem.b = value\13  elseif (port == \"C\") then\13    mem.c = value\13  elseif (port == \"D\") then\13    mem.d = value\13  end\13end\13\13function run_code() -- the circuit logic ++++\13\13  -- get first two AND gates based on clock and data\13  if (mem.c and mem.b) then\13    mem.and1 = true\13  else\13    mem.and1 = false\13  end\13  if (mem.c and not mem.b) then\13    mem.and2 = true\13  else\13    mem.and2 = false\13  end\13\13  -- SR Latch\13  if (mem.and1) then\13    port.a = true\13  end\13  if (mem.and2) then\13    port.a = false\13  end\
\
  -- Carry Data Out\
  port.d = mem.b\13\13end\13\13if (event.type == \"on\") then\13  set_value(event.pin.name\\, true)\13  run_code()\13end\13if (event.type == \"off\") then\13  set_value(event.pin.name\\, false)\13  run_code()\13end]image_button[4.75,8.75;2.5,1;jeija_luac_runbutton.png;program;]image_button_exit[11.72,-0.25;0.425,0.4;jeija_close_window.png;exit;]", ["lc_memory"] = "return {[\"b\"] = false, [\"and2\"] = false, [\"d\"] = false, [\"a\"] = false, [\"c\"] = false, [\"and1\"] = false}", ["ignore_offevents"] = "return {}", ["luac_id"] = "19270"}, ["inventory"] = {}}, ["y"] = 2, ["param1"] = 92, ["z"] = 23, ["name"] = "mesecons_luacontroller:luacontroller0000"}, {["x"] = 3, ["param2"] = 3, ["y"] = 2, ["param1"] = 92, ["z"] = 24, ["name"] = "mesecons_insulated:insulated_off"}, {["x"] = 3, ["meta"] = {["fields"] = {["real_portstates"] = "1", ["code"] = "-- D Flipflop (toggle D state when enabled)\13-- Minetest Mesecons Lua Controller\13-- B:data, C:enable/clock, A:output, D:carry data out\13\13if (event.type == \"program\") then\13  mem.a, mem.b, mem.c, mem.d = false, false, false, false\13  mem.and1, mem.and2 = false, false\13end\13\13function set_value(port, value) -- sets variable value based on input\13  if (port == \"A\") then \13    mem.a = value\13  elseif (port == \"B\") then\13    mem.b = value\13  elseif (port == \"C\") then\13    mem.c = value\13  elseif (port == \"D\") then\13    mem.d = value\13  end\13end\13\13function run_code() -- the circuit logic ++++\13\13  -- get first two AND gates based on clock and data\13  if (mem.c and mem.b) then\13    mem.and1 = true\13  else\13    mem.and1 = false\13  end\13  if (mem.c and not mem.b) then\13    mem.and2 = true\13  else\13    mem.and2 = false\13  end\13\13  -- SR Latch\13  if (mem.and1) then\13    port.a = true\13  end\13  if (mem.and2) then\13    port.a = false\13  end\
\
  -- Carry Data Out\
  port.d = mem.b\13\13end\13\13if (event.type == \"on\") then\13  set_value(event.pin.name, true)\13  run_code()\13end\13if (event.type == \"off\") then\13  set_value(event.pin.name, false)\13  run_code()\13end", ["formspec"] = "size[12,10]background[-0.2,-0.25;12.4,10.75;jeija_luac_background.png]label[0.1,8.3;]textarea[0.2,0.2;12.2,9.5;code;;-- D Flipflop (toggle D state when enabled)\13-- Minetest Mesecons Lua Controller\13-- B:data\\, C:enable/clock\\, A:output\\, D:carry data out\13\13if (event.type == \"program\") then\13  mem.a\\, mem.b\\, mem.c\\, mem.d = false\\, false\\, false\\, false\13  mem.and1\\, mem.and2 = false\\, false\13end\13\13function set_value(port\\, value) -- sets variable value based on input\13  if (port == \"A\") then \13    mem.a = value\13  elseif (port == \"B\") then\13    mem.b = value\13  elseif (port == \"C\") then\13    mem.c = value\13  elseif (port == \"D\") then\13    mem.d = value\13  end\13end\13\13function run_code() -- the circuit logic ++++\13\13  -- get first two AND gates based on clock and data\13  if (mem.c and mem.b) then\13    mem.and1 = true\13  else\13    mem.and1 = false\13  end\13  if (mem.c and not mem.b) then\13    mem.and2 = true\13  else\13    mem.and2 = false\13  end\13\13  -- SR Latch\13  if (mem.and1) then\13    port.a = true\13  end\13  if (mem.and2) then\13    port.a = false\13  end\
\
  -- Carry Data Out\
  port.d = mem.b\13\13end\13\13if (event.type == \"on\") then\13  set_value(event.pin.name\\, true)\13  run_code()\13end\13if (event.type == \"off\") then\13  set_value(event.pin.name\\, false)\13  run_code()\13end]image_button[4.75,8.75;2.5,1;jeija_luac_runbutton.png;program;]image_button_exit[11.72,-0.25;0.425,0.4;jeija_close_window.png;exit;]", ["lc_memory"] = "return {[\"b\"] = false, [\"and2\"] = false, [\"and1\"] = false, [\"c\"] = false, [\"a\"] = false, [\"d\"] = false}", ["ignore_offevents"] = "return {}", ["luac_id"] = "19270"}, ["inventory"] = {}}, ["y"] = 2, ["param1"] = 76, ["z"] = 25, ["name"] = "mesecons_luacontroller:luacontroller0000"}, {["x"] = 3, ["param2"] = 3, ["y"] = 2, ["param1"] = 92, ["z"] = 26, ["name"] = "mesecons_insulated:insulated_off"}, {["x"] = 3, ["meta"] = {["fields"] = {["real_portstates"] = "1", ["code"] = "-- D Flipflop (toggle D state when enabled)\13-- Minetest Mesecons Lua Controller\13-- B:data, C:enable/clock, A:output, D:carry data out\13\13if (event.type == \"program\") then\13  mem.a, mem.b, mem.c, mem.d = false, false, false, false\13  mem.and1, mem.and2 = false, false\13end\13\13function set_value(port, value) -- sets variable value based on input\13  if (port == \"A\") then \13    mem.a = value\13  elseif (port == \"B\") then\13    mem.b = value\13  elseif (port == \"C\") then\13    mem.c = value\13  elseif (port == \"D\") then\13    mem.d = value\13  end\13end\13\13function run_code() -- the circuit logic ++++\13\13  -- get first two AND gates based on clock and data\13  if (mem.c and mem.b) then\13    mem.and1 = true\13  else\13    mem.and1 = false\13  end\13  if (mem.c and not mem.b) then\13    mem.and2 = true\13  else\13    mem.and2 = false\13  end\13\13  -- SR Latch\13  if (mem.and1) then\13    port.a = true\13  end\13  if (mem.and2) then\13    port.a = false\13  end\
\
  -- Carry Data Out\
  port.d = mem.b\13\13end\13\13if (event.type == \"on\") then\13  set_value(event.pin.name, true)\13  run_code()\13end\13if (event.type == \"off\") then\13  set_value(event.pin.name, false)\13  run_code()\13end", ["formspec"] = "size[12,10]background[-0.2,-0.25;12.4,10.75;jeija_luac_background.png]label[0.1,8.3;]textarea[0.2,0.2;12.2,9.5;code;;-- D Flipflop (toggle D state when enabled)\13-- Minetest Mesecons Lua Controller\13-- B:data\\, C:enable/clock\\, A:output\\, D:carry data out\13\13if (event.type == \"program\") then\13  mem.a\\, mem.b\\, mem.c\\, mem.d = false\\, false\\, false\\, false\13  mem.and1\\, mem.and2 = false\\, false\13end\13\13function set_value(port\\, value) -- sets variable value based on input\13  if (port == \"A\") then \13    mem.a = value\13  elseif (port == \"B\") then\13    mem.b = value\13  elseif (port == \"C\") then\13    mem.c = value\13  elseif (port == \"D\") then\13    mem.d = value\13  end\13end\13\13function run_code() -- the circuit logic ++++\13\13  -- get first two AND gates based on clock and data\13  if (mem.c and mem.b) then\13    mem.and1 = true\13  else\13    mem.and1 = false\13  end\13  if (mem.c and not mem.b) then\13    mem.and2 = true\13  else\13    mem.and2 = false\13  end\13\13  -- SR Latch\13  if (mem.and1) then\13    port.a = true\13  end\13  if (mem.and2) then\13    port.a = false\13  end\
\
  -- Carry Data Out\
  port.d = mem.b\13\13end\13\13if (event.type == \"on\") then\13  set_value(event.pin.name\\, true)\13  run_code()\13end\13if (event.type == \"off\") then\13  set_value(event.pin.name\\, false)\13  run_code()\13end]image_button[4.75,8.75;2.5,1;jeija_luac_runbutton.png;program;]image_button_exit[11.72,-0.25;0.425,0.4;jeija_close_window.png;exit;]", ["lc_memory"] = "return {[\"b\"] = false, [\"and2\"] = false, [\"and1\"] = false, [\"c\"] = false, [\"a\"] = false, [\"d\"] = false}", ["ignore_offevents"] = "return {}", ["luac_id"] = "19270"}, ["inventory"] = {}}, ["y"] = 2, ["param1"] = 108, ["z"] = 27, ["name"] = "mesecons_luacontroller:luacontroller0000"}, {["x"] = 3, ["param2"] = 3, ["y"] = 2, ["param1"] = 124, ["z"] = 28, ["name"] = "mesecons_insulated:insulated_off"}, {["x"] = 3, ["meta"] = {["fields"] = {["real_portstates"] = "1", ["code"] = "-- D Flipflop (toggle D state when enabled)\13-- Minetest Mesecons Lua Controller\13-- B:data, C:enable/clock, A:output, D:carry data out\13\13if (event.type == \"program\") then\13  mem.a, mem.b, mem.c, mem.d = false, false, false, false\13  mem.and1, mem.and2 = false, false\13end\13\13function set_value(port, value) -- sets variable value based on input\13  if (port == \"A\") then \13    mem.a = value\13  elseif (port == \"B\") then\13    mem.b = value\13  elseif (port == \"C\") then\13    mem.c = value\13  elseif (port == \"D\") then\13    mem.d = value\13  end\13end\13\13function run_code() -- the circuit logic ++++\13\13  -- get first two AND gates based on clock and data\13  if (mem.c and mem.b) then\13    mem.and1 = true\13  else\13    mem.and1 = false\13  end\13  if (mem.c and not mem.b) then\13    mem.and2 = true\13  else\13    mem.and2 = false\13  end\13\13  -- SR Latch\13  if (mem.and1) then\13    port.a = true\13  end\13  if (mem.and2) then\13    port.a = false\13  end\
\
  -- Carry Data Out\
  port.d = mem.b\13\13end\13\13if (event.type == \"on\") then\13  set_value(event.pin.name, true)\13  run_code()\13end\13if (event.type == \"off\") then\13  set_value(event.pin.name, false)\13  run_code()\13end", ["formspec"] = "size[12,10]background[-0.2,-0.25;12.4,10.75;jeija_luac_background.png]label[0.1,8.3;]textarea[0.2,0.2;12.2,9.5;code;;-- D Flipflop (toggle D state when enabled)\13-- Minetest Mesecons Lua Controller\13-- B:data\\, C:enable/clock\\, A:output\\, D:carry data out\13\13if (event.type == \"program\") then\13  mem.a\\, mem.b\\, mem.c\\, mem.d = false\\, false\\, false\\, false\13  mem.and1\\, mem.and2 = false\\, false\13end\13\13function set_value(port\\, value) -- sets variable value based on input\13  if (port == \"A\") then \13    mem.a = value\13  elseif (port == \"B\") then\13    mem.b = value\13  elseif (port == \"C\") then\13    mem.c = value\13  elseif (port == \"D\") then\13    mem.d = value\13  end\13end\13\13function run_code() -- the circuit logic ++++\13\13  -- get first two AND gates based on clock and data\13  if (mem.c and mem.b) then\13    mem.and1 = true\13  else\13    mem.and1 = false\13  end\13  if (mem.c and not mem.b) then\13    mem.and2 = true\13  else\13    mem.and2 = false\13  end\13\13  -- SR Latch\13  if (mem.and1) then\13    port.a = true\13  end\13  if (mem.and2) then\13    port.a = false\13  end\
\
  -- Carry Data Out\
  port.d = mem.b\13\13end\13\13if (event.type == \"on\") then\13  set_value(event.pin.name\\, true)\13  run_code()\13end\13if (event.type == \"off\") then\13  set_value(event.pin.name\\, false)\13  run_code()\13end]image_button[4.75,8.75;2.5,1;jeija_luac_runbutton.png;program;]image_button_exit[11.72,-0.25;0.425,0.4;jeija_close_window.png;exit;]", ["lc_memory"] = "return {[\"b\"] = false, [\"and2\"] = false, [\"and1\"] = false, [\"c\"] = false, [\"a\"] = false, [\"d\"] = false}", ["ignore_offevents"] = "return {[\"A\"] = true}", ["luac_id"] = "19270"}, ["inventory"] = {}}, ["y"] = 2, ["param1"] = 140, ["z"] = 29, ["name"] = "mesecons_luacontroller:luacontroller0001"}, {["x"] = 3, ["param2"] = 3, ["y"] = 2, ["param1"] = 156, ["z"] = 30, ["name"] = "mesecons_insulated:insulated_off"}, {["x"] = 3, ["meta"] = {["fields"] = {["real_portstates"] = "1", ["code"] = "-- D Flipflop (toggle D state when enabled)\13-- Minetest Mesecons Lua Controller\13-- B:data, C:enable/clock, A:output, D:carry data out\13\13if (event.type == \"program\") then\13  mem.a, mem.b, mem.c, mem.d = false, false, false, false\13  mem.and1, mem.and2 = false, false\13end\13\13function set_value(port, value) -- sets variable value based on input\13  if (port == \"A\") then \13    mem.a = value\13  elseif (port == \"B\") then\13    mem.b = value\13  elseif (port == \"C\") then\13    mem.c = value\13  elseif (port == \"D\") then\13    mem.d = value\13  end\13end\13\13function run_code() -- the circuit logic ++++\13\13  -- get first two AND gates based on clock and data\13  if (mem.c and mem.b) then\13    mem.and1 = true\13  else\13    mem.and1 = false\13  end\13  if (mem.c and not mem.b) then\13    mem.and2 = true\13  else\13    mem.and2 = false\13  end\13\13  -- SR Latch\13  if (mem.and1) then\13    port.a = true\13  end\13  if (mem.and2) then\13    port.a = false\13  end\
\
  -- Carry Data Out\
  port.d = mem.b\13\13end\13\13if (event.type == \"on\") then\13  set_value(event.pin.name, true)\13  run_code()\13end\13if (event.type == \"off\") then\13  set_value(event.pin.name, false)\13  run_code()\13end", ["formspec"] = "size[12,10]background[-0.2,-0.25;12.4,10.75;jeija_luac_background.png]label[0.1,8.3;]textarea[0.2,0.2;12.2,9.5;code;;-- D Flipflop (toggle D state when enabled)\13-- Minetest Mesecons Lua Controller\13-- B:data\\, C:enable/clock\\, A:output\\, D:carry data out\13\13if (event.type == \"program\") then\13  mem.a\\, mem.b\\, mem.c\\, mem.d = false\\, false\\, false\\, false\13  mem.and1\\, mem.and2 = false\\, false\13end\13\13function set_value(port\\, value) -- sets variable value based on input\13  if (port == \"A\") then \13    mem.a = value\13  elseif (port == \"B\") then\13    mem.b = value\13  elseif (port == \"C\") then\13    mem.c = value\13  elseif (port == \"D\") then\13    mem.d = value\13  end\13end\13\13function run_code() -- the circuit logic ++++\13\13  -- get first two AND gates based on clock and data\13  if (mem.c and mem.b) then\13    mem.and1 = true\13  else\13    mem.and1 = false\13  end\13  if (mem.c and not mem.b) then\13    mem.and2 = true\13  else\13    mem.and2 = false\13  end\13\13  -- SR Latch\13  if (mem.and1) then\13    port.a = true\13  end\13  if (mem.and2) then\13    port.a = false\13  end\
\
  -- Carry Data Out\
  port.d = mem.b\13\13end\13\13if (event.type == \"on\") then\13  set_value(event.pin.name\\, true)\13  run_code()\13end\13if (event.type == \"off\") then\13  set_value(event.pin.name\\, false)\13  run_code()\13end]image_button[4.75,8.75;2.5,1;jeija_luac_runbutton.png;program;]image_button_exit[11.72,-0.25;0.425,0.4;jeija_close_window.png;exit;]", ["lc_memory"] = "return {[\"b\"] = false, [\"and2\"] = false, [\"and1\"] = false, [\"c\"] = false, [\"a\"] = false, [\"d\"] = false}", ["ignore_offevents"] = "return {[\"A\"] = true}", ["luac_id"] = "19270"}, ["inventory"] = {}}, ["y"] = 2, ["param1"] = 140, ["z"] = 31, ["name"] = "mesecons_luacontroller:luacontroller0001"}, {["x"] = 3, ["param2"] = 3, ["y"] = 2, ["param1"] = 156, ["z"] = 32, ["name"] = "mesecons_insulated:insulated_off"}, {["x"] = 3, ["meta"] = {["fields"] = {["real_portstates"] = "1", ["code"] = "-- D Flipflop (toggle D state when enabled)\13-- Minetest Mesecons Lua Controller\13-- B:data, C:enable/clock, A:output, D:carry data out\13\13if (event.type == \"program\") then\13  mem.a, mem.b, mem.c, mem.d = false, false, false, false\13  mem.and1, mem.and2 = false, false\13end\13\13function set_value(port, value) -- sets variable value based on input\13  if (port == \"A\") then \13    mem.a = value\13  elseif (port == \"B\") then\13    mem.b = value\13  elseif (port == \"C\") then\13    mem.c = value\13  elseif (port == \"D\") then\13    mem.d = value\13  end\13end\13\13function run_code() -- the circuit logic ++++\13\13  -- get first two AND gates based on clock and data\13  if (mem.c and mem.b) then\13    mem.and1 = true\13  else\13    mem.and1 = false\13  end\13  if (mem.c and not mem.b) then\13    mem.and2 = true\13  else\13    mem.and2 = false\13  end\13\13  -- SR Latch\13  if (mem.and1) then\13    port.a = true\13  end\13  if (mem.and2) then\13    port.a = false\13  end\
\
  -- Carry Data Out\
  port.d = mem.b\13\13end\13\13if (event.type == \"on\") then\13  set_value(event.pin.name, true)\13  run_code()\13end\13if (event.type == \"off\") then\13  set_value(event.pin.name, false)\13  run_code()\13end", ["formspec"] = "size[12,10]background[-0.2,-0.25;12.4,10.75;jeija_luac_background.png]label[0.1,8.3;]textarea[0.2,0.2;12.2,9.5;code;;-- D Flipflop (toggle D state when enabled)\13-- Minetest Mesecons Lua Controller\13-- B:data\\, C:enable/clock\\, A:output\\, D:carry data out\13\13if (event.type == \"program\") then\13  mem.a\\, mem.b\\, mem.c\\, mem.d = false\\, false\\, false\\, false\13  mem.and1\\, mem.and2 = false\\, false\13end\13\13function set_value(port\\, value) -- sets variable value based on input\13  if (port == \"A\") then \13    mem.a = value\13  elseif (port == \"B\") then\13    mem.b = value\13  elseif (port == \"C\") then\13    mem.c = value\13  elseif (port == \"D\") then\13    mem.d = value\13  end\13end\13\13function run_code() -- the circuit logic ++++\13\13  -- get first two AND gates based on clock and data\13  if (mem.c and mem.b) then\13    mem.and1 = true\13  else\13    mem.and1 = false\13  end\13  if (mem.c and not mem.b) then\13    mem.and2 = true\13  else\13    mem.and2 = false\13  end\13\13  -- SR Latch\13  if (mem.and1) then\13    port.a = true\13  end\13  if (mem.and2) then\13    port.a = false\13  end\
\
  -- Carry Data Out\
