5:return {{["x"] = 0, ["y"] = 0, ["param1"] = 15, ["z"] = 0, ["name"] = "default:desert_sandstone_block"}, {["x"] = 0, ["y"] = 0, ["param1"] = 14, ["z"] = 1, ["name"] = "default:desert_sandstone_block"}, {["x"] = 0, ["y"] = 0, ["param1"] = 15, ["z"] = 2, ["name"] = "default:desert_sandstone_block"}, {["x"] = 0, ["y"] = 0, ["param1"] = 15, ["z"] = 3, ["name"] = "default:desert_sandstone_block"}, {["x"] = 0, ["y"] = 0, ["param1"] = 15, ["z"] = 4, ["name"] = "default:desert_sandstone_block"}, {["x"] = 0, ["y"] = 0, ["param1"] = 15, ["z"] = 5, ["name"] = "default:desert_sandstone_block"}, {["x"] = 0, ["y"] = 0, ["param1"] = 15, ["z"] = 6, ["name"] = "default:desert_sandstone_block"}, {["x"] = 0, ["y"] = 0, ["param1"] = 15, ["z"] = 7, ["name"] = "default:desert_sandstone_block"}, {["x"] = 0, ["y"] = 0, ["param1"] = 15, ["z"] = 8, ["name"] = "default:desert_sandstone_block"}, {["x"] = 0, ["y"] = 0, ["param1"] = 15, ["z"] = 9, ["name"] = "default:desert_sandstone_block"}, {["x"] = 0, ["y"] = 0, ["param1"] = 15, ["z"] = 10, ["name"] = "default:desert_sandstone_block"}, {["x"] = 0, ["y"] = 0, ["param1"] = 15, ["z"] = 11, ["name"] = "default:desert_sandstone_block"}, {["x"] = 0, ["y"] = 0, ["param1"] = 15, ["z"] = 12, ["name"] = "default:desert_sandstone_block"}, {["x"] = 0, ["y"] = 0, ["param1"] = 15, ["z"] = 13, ["name"] = "default:desert_sandstone_block"}, {["x"] = 0, ["y"] = 0, ["param1"] = 15, ["z"] = 14, ["name"] = "default:desert_sandstone_block"}, {["x"] = 0, ["y"] = 0, ["param1"] = 15, ["z"] = 15, ["name"] = "default:desert_sandstone_block"}, {["x"] = 0, ["y"] = 0, ["param1"] = 15, ["z"] = 16, ["name"] = "default:desert_sandstone_block"}, {["x"] = 0, ["y"] = 0, ["param1"] = 15, ["z"] = 17, ["name"] = "default:desert_sandstone_block"}, {["x"] = 0, ["y"] = 0, ["param1"] = 15, ["z"] = 18, ["name"] = "default:desert_sandstone_block"}, {["x"] = 0, ["y"] = 0, ["param1"] = 15, ["z"] = 19, ["name"] = "default:desert_sandstone_block"}, {["x"] = 0, ["y"] = 0, ["param1"] = 15, ["z"] = 20, ["name"] = "default:desert_sandstone_block"}, {["x"] = 0, ["y"] = 0, ["param1"] = 15, ["z"] = 21, ["name"] = "default:desert_sandstone_block"}, {["x"] = 0, ["y"] = 0, ["param1"] = 15, ["z"] = 22, ["name"] = "default:desert_sandstone_block"}, {["x"] = 0, ["y"] = 0, ["param1"] = 15, ["z"] = 23, ["name"] = "default:desert_sandstone_block"}, {["x"] = 0, ["y"] = 0, ["param1"] = 15, ["z"] = 24, ["name"] = "default:desert_sandstone_block"}, {["x"] = 0, ["y"] = 0, ["param1"] = 15, ["z"] = 25, ["name"] = "default:desert_sandstone_block"}, {["x"] = 0, ["y"] = 0, ["param1"] = 15, ["z"] = 26, ["name"] = "default:desert_sandstone_block"}, {["x"] = 0, ["y"] = 0, ["param1"] = 15, ["z"] = 27, ["name"] = "default:desert_sandstone_block"}, {["x"] = 0, ["y"] = 0, ["param1"] = 15, ["z"] = 28, ["name"] = "default:desert_sandstone_block"}, {["x"] = 0, ["y"] = 0, ["param1"] = 15, ["z"] = 29, ["name"] = "default:desert_sandstone_block"}, {["x"] = 0, ["y"] = 0, ["param1"] = 15, ["z"] = 30, ["name"] = "default:desert_sandstone_block"}, {["x"] = 0, ["y"] = 0, ["param1"] = 15, ["z"] = 31, ["name"] = "default:desert_sandstone_block"}, {["x"] = 0, ["y"] = 0, ["param1"] = 15, ["z"] = 32, ["name"] = "default:desert_sandstone_block"}, {["x"] = 0, ["y"] = 0, ["param1"] = 15, ["z"] = 33, ["name"] = "default:desert_sandstone_block"}, {["x"] = 0, ["y"] = 0, ["param1"] = 15, ["z"] = 34, ["name"] = "default:desert_sandstone_block"}, {["x"] = 0, ["y"] = 0, ["param1"] = 15, ["z"] = 35, ["name"] = "default:desert_sandstone_block"}, {["x"] = 0, ["y"] = 0, ["param1"] = 15, ["z"] = 36, ["name"] = "default:desert_sandstone_block"}, {["x"] = 0, ["y"] = 0, ["param1"] = 15, ["z"] = 37, ["name"] = "default:desert_sandstone_block"}, {["x"] = 0, ["y"] = 0, ["param1"] = 15, ["z"] = 38, ["name"] = "default:desert_sandstone_block"}, {["x"] = 0, ["y"] = 0, ["param1"] = 15, ["z"] = 39, ["name"] = "default:desert_sandstone_block"}, {["x"] = 0, ["y"] = 0, ["param1"] = 15, ["z"] = 40, ["name"] = "default:desert_sandstone_block"}, {["x"] = 0, ["y"] = 0, ["param1"] = 15, ["z"] = 41, ["name"] = "default:desert_sandstone_block"}, {["x"] = 1, ["y"] = 0, ["param1"] = 15, ["z"] = 0, ["name"] = "default:desert_sandstone_block"}, {["x"] = 1, ["y"] = 0, ["param1"] = 18, ["z"] = 1, ["name"] = "default:silver_sandstone_block"}, {["x"] = 1, ["y"] = 0, ["param1"] = 18, ["z"] = 2, ["name"] = "default:silver_sandstone_block"}, {["x"] = 1, ["y"] = 0, ["param1"] = 18, ["z"] = 3, ["name"] = "default:silver_sandstone_block"}, {["x"] = 1, ["y"] = 0, ["param1"] = 18, ["z"] = 4, ["name"] = "default:silver_sandstone_block"}, {["x"] = 1, ["y"] = 0, ["param1"] = 18, ["z"] = 5, ["name"] = "default:silver_sandstone_block"}, {["x"] = 1, ["y"] = 0, ["param1"] = 18, ["z"] = 6, ["name"] = "default:silver_sandstone_block"}, {["x"] = 1, ["y"] = 0, ["param1"] = 18, ["z"] = 7, ["name"] = "default:silver_sandstone_block"}, {["x"] = 1, ["y"] = 0, ["param1"] = 18, ["z"] = 8, ["name"] = "default:silver_sandstone_block"}, {["x"] = 1, ["y"] = 0, ["param1"] = 18, ["z"] = 9, ["name"] = "default:silver_sandstone_block"}, {["x"] = 1, ["y"] = 0, ["param1"] = 18, ["z"] = 10, ["name"] = "default:silver_sandstone_block"}, {["x"] = 1, ["y"] = 0, ["param1"] = 18, ["z"] = 11, ["name"] = "default:silver_sandstone_block"}, {["x"] = 1, ["y"] = 0, ["param1"] = 18, ["z"] = 12, ["name"] = "default:silver_sandstone_block"}, {["x"] = 1, ["y"] = 0, ["param1"] = 18, ["z"] = 13, ["name"] = "default:silver_sandstone_block"}, {["x"] = 1, ["y"] = 0, ["param1"] = 18, ["z"] = 14, ["name"] = "default:silver_sandstone_block"}, {["x"] = 1, ["y"] = 0, ["param1"] = 18, ["z"] = 15, ["name"] = "default:silver_sandstone_block"}, {["x"] = 1, ["y"] = 0, ["param1"] = 18, ["z"] = 16, ["name"] = "default:silver_sandstone_block"}, {["x"] = 1, ["y"] = 0, ["param1"] = 18, ["z"] = 17, ["name"] = "default:silver_sandstone_block"}, {["x"] = 1, ["y"] = 0, ["param1"] = 18, ["z"] = 18, ["name"] = "default:silver_sandstone_block"}, {["x"] = 1, ["y"] = 0, ["param1"] = 18, ["z"] = 19, ["name"] = "default:silver_sandstone_block"}, {["x"] = 1, ["y"] = 0, ["param1"] = 18, ["z"] = 20, ["name"] = "default:silver_sandstone_block"}, {["x"] = 1, ["y"] = 0, ["param1"] = 18, ["z"] = 21, ["name"] = "default:silver_sandstone_block"}, {["x"] = 1, ["y"] = 0, ["param1"] = 18, ["z"] = 22, ["name"] = "default:silver_sandstone_block"}, {["x"] = 1, ["y"] = 0, ["param1"] = 18, ["z"] = 23, ["name"] = "default:silver_sandstone_block"}, {["x"] = 1, ["y"] = 0, ["param1"] = 18, ["z"] = 24, ["name"] = "default:silver_sandstone_block"}, {["x"] = 1, ["y"] = 0, ["param1"] = 18, ["z"] = 25, ["name"] = "default:silver_sandstone_block"}, {["x"] = 1, ["y"] = 0, ["param1"] = 18, ["z"] = 26, ["name"] = "default:silver_sandstone_block"}, {["x"] = 1, ["y"] = 0, ["param1"] = 18, ["z"] = 27, ["name"] = "default:silver_sandstone_block"}, {["x"] = 1, ["y"] = 0, ["param1"] = 18, ["z"] = 28, ["name"] = "default:silver_sandstone_block"}, {["x"] = 1, ["y"] = 0, ["param1"] = 18, ["z"] = 29, ["name"] = "default:silver_sandstone_block"}, {["x"] = 1, ["y"] = 0, ["param1"] = 18, ["z"] = 30, ["name"] = "default:silver_sandstone_block"}, {["x"] = 1, ["y"] = 0, ["param1"] = 18, ["z"] = 31, ["name"] = "default:silver_sandstone_block"}, {["x"] = 1, ["y"] = 0, ["param1"] = 18, ["z"] = 32, ["name"] = "default:silver_sandstone_block"}, {["x"] = 1, ["y"] = 0, ["param1"] = 18, ["z"] = 33, ["name"] = "default:silver_sandstone_block"}, {["x"] = 1, ["y"] = 0, ["param1"] = 18, ["z"] = 34, ["name"] = "default:silver_sandstone_block"}, {["x"] = 1, ["y"] = 0, ["param1"] = 18, ["z"] = 35, ["name"] = "default:silver_sandstone_block"}, {["x"] = 1, ["y"] = 0, ["param1"] = 18, ["z"] = 36, ["name"] = "default:silver_sandstone_block"}, {["x"] = 1, ["y"] = 0, ["param1"] = 18, ["z"] = 37, ["name"] = "default:silver_sandstone_block"}, {["x"] = 1, ["y"] = 0, ["param1"] = 18, ["z"] = 38, ["name"] = "default:silver_sandstone_block"}, {["x"] = 1, ["y"] = 0, ["param1"] = 18, ["z"] = 39, ["name"] = "default:silver_sandstone_block"}, {["x"] = 1, ["y"] = 0, ["param1"] = 18, ["z"] = 40, ["name"] = "default:silver_sandstone_block"}, {["x"] = 1, ["y"] = 0, ["param1"] = 15, ["z"] = 41, ["name"] = "default:desert_sandstone_block"}, {["x"] = 2, ["y"] = 0, ["param1"] = 15, ["z"] = 0, ["name"] = "default:desert_sandstone_block"}, {["x"] = 2, ["y"] = 0, ["param1"] = 18, ["z"] = 1, ["name"] = "default:silver_sandstone_block"}, {["x"] = 2, ["y"] = 0, ["param1"] = 18, ["z"] = 2, ["name"] = "default:silver_sandstone_block"}, {["x"] = 2, ["y"] = 0, ["param1"] = 18, ["z"] = 3, ["name"] = "default:silver_sandstone_block"}, {["x"] = 2, ["y"] = 0, ["param1"] = 18, ["z"] = 4, ["name"] = "default:silver_sandstone_block"}, {["x"] = 2, ["y"] = 0, ["param1"] = 18, ["z"] = 5, ["name"] = "default:silver_sandstone_block"}, {["x"] = 2, ["y"] = 0, ["param1"] = 18, ["z"] = 6, ["name"] = "default:silver_sandstone_block"}, {["x"] = 2, ["y"] = 0, ["param1"] = 18, ["z"] = 7, ["name"] = "default:silver_sandstone_block"}, {["x"] = 2, ["y"] = 0, ["param1"] = 18, ["z"] = 8, ["name"] = "default:silver_sandstone_block"}, {["x"] = 2, ["y"] = 0, ["param1"] = 18, ["z"] = 9, ["name"] = "default:silver_sandstone_block"}, {["x"] = 2, ["y"] = 0, ["param1"] = 18, ["z"] = 10, ["name"] = "default:silver_sandstone_block"}, {["x"] = 2, ["y"] = 0, ["param1"] = 18, ["z"] = 11, ["name"] = "default:silver_sandstone_block"}, {["x"] = 2, ["y"] = 0, ["param1"] = 18, ["z"] = 12, ["name"] = "default:silver_sandstone_block"}, {["x"] = 2, ["y"] = 0, ["param1"] = 18, ["z"] = 13, ["name"] = "default:silver_sandstone_block"}, {["x"] = 2, ["y"] = 0, ["param1"] = 18, ["z"] = 14, ["name"] = "default:silver_sandstone_block"}, {["x"] = 2, ["y"] = 0, ["param1"] = 18, ["z"] = 15, ["name"] = "default:silver_sandstone_block"}, {["x"] = 2, ["y"] = 0, ["param1"] = 18, ["z"] = 16, ["name"] = "default:silver_sandstone_block"}, {["x"] = 2, ["y"] = 0, ["param1"] = 18, ["z"] = 17, ["name"] = "default:silver_sandstone_block"}, {["x"] = 2, ["y"] = 0, ["param1"] = 18, ["z"] = 18, ["name"] = "default:silver_sandstone_block"}, {["x"] = 2, ["y"] = 0, ["param1"] = 18, ["z"] = 19, ["name"] = "default:silver_sandstone_block"}, {["x"] = 2, ["y"] = 0, ["param1"] = 18, ["z"] = 20, ["name"] = "default:silver_sandstone_block"}, {["x"] = 2, ["y"] = 0, ["param1"] = 18, ["z"] = 21, ["name"] = "default:silver_sandstone_block"}, {["x"] = 2, ["y"] = 0, ["param1"] = 18, ["z"] = 22, ["name"] = "default:silver_sandstone_block"}, {["x"] = 2, ["y"] = 0, ["param1"] = 18, ["z"] = 23, ["name"] = "default:silver_sandstone_block"}, {["x"] = 2, ["y"] = 0, ["param1"] = 18, ["z"] = 24, ["name"] = "default:silver_sandstone_block"}, {["x"] = 2, ["y"] = 0, ["param1"] = 18, ["z"] = 25, ["name"] = "default:silver_sandstone_block"}, {["x"] = 2, ["y"] = 0, ["param1"] = 18, ["z"] = 26, ["name"] = "default:silver_sandstone_block"}, {["x"] = 2, ["y"] = 0, ["param1"] = 18, ["z"] = 27, ["name"] = "default:silver_sandstone_block"}, {["x"] = 2, ["y"] = 0, ["param1"] = 18, ["z"] = 28, ["name"] = "default:silver_sandstone_block"}, {["x"] = 2, ["y"] = 0, ["param1"] = 18, ["z"] = 29, ["name"] = "default:silver_sandstone_block"}, {["x"] = 2, ["y"] = 0, ["param1"] = 18, ["z"] = 30, ["name"] = "default:silver_sandstone_block"}, {["x"] = 2, ["y"] = 0, ["param1"] = 18, ["z"] = 31, ["name"] = "default:silver_sandstone_block"}, {["x"] = 2, ["y"] = 0, ["param1"] = 18, ["z"] = 32, ["name"] = "default:silver_sandstone_block"}, {["x"] = 2, ["y"] = 0, ["param1"] = 18, ["z"] = 33, ["name"] = "default:silver_sandstone_block"}, {["x"] = 2, ["y"] = 0, ["param1"] = 18, ["z"] = 34, ["name"] = "default:silver_sandstone_block"}, {["x"] = 2, ["y"] = 0, ["param1"] = 18, ["z"] = 35, ["name"] = "default:silver_sandstone_block"}, {["x"] = 2, ["y"] = 0, ["param1"] = 18, ["z"] = 36, ["name"] = "default:silver_sandstone_block"}, {["x"] = 2, ["y"] = 0, ["param1"] = 18, ["z"] = 37, ["name"] = "default:silver_sandstone_block"}, {["x"] = 2, ["y"] = 0, ["param1"] = 18, ["z"] = 38, ["name"] = "default:silver_sandstone_block"}, {["x"] = 2, ["y"] = 0, ["param1"] = 18, ["z"] = 39, ["name"] = "default:silver_sandstone_block"}, {["x"] = 2, ["y"] = 0, ["param1"] = 18, ["z"] = 40, ["name"] = "default:silver_sandstone_block"}, {["x"] = 2, ["y"] = 0, ["param1"] = 15, ["z"] = 41, ["name"] = "default:desert_sandstone_block"}, {["x"] = 3, ["y"] = 0, ["param1"] = 15, ["z"] = 0, ["name"] = "default:desert_sandstone_block"}, {["x"] = 3, ["y"] = 0, ["param1"] = 18, ["z"] = 1, ["name"] = "default:silver_sandstone_block"}, {["x"] = 3, ["y"] = 0, ["param1"] = 18, ["z"] = 2, ["name"] = "default:silver_sandstone_block"}, {["x"] = 3, ["y"] = 0, ["param1"] = 18, ["z"] = 3, ["name"] = "default:silver_sandstone_block"}, {["x"] = 3, ["y"] = 0, ["param1"] = 18, ["z"] = 4, ["name"] = "default:silver_sandstone_block"}, {["x"] = 3, ["y"] = 0, ["param1"] = 18, ["z"] = 5, ["name"] = "default:silver_sandstone_block"}, {["x"] = 3, ["y"] = 0, ["param1"] = 18, ["z"] = 6, ["name"] = "default:silver_sandstone_block"}, {["x"] = 3, ["y"] = 0, ["param1"] = 18, ["z"] = 7, ["name"] = "default:silver_sandstone_block"}, {["x"] = 3, ["y"] = 0, ["param1"] = 18, ["z"] = 8, ["name"] = "default:silver_sandstone_block"}, {["x"] = 3, ["y"] = 0, ["param1"] = 18, ["z"] = 9, ["name"] = "default:silver_sandstone_block"}, {["x"] = 3, ["y"] = 0, ["param1"] = 18, ["z"] = 10, ["name"] = "default:silver_sandstone_block"}, {["x"] = 3, ["y"] = 0, ["param1"] = 18, ["z"] = 11, ["name"] = "default:silver_sandstone_block"}, {["x"] = 3, ["y"] = 0, ["param1"] = 18, ["z"] = 12, ["name"] = "default:silver_sandstone_block"}, {["x"] = 3, ["y"] = 0, ["param1"] = 18, ["z"] = 13, ["name"] = "default:silver_sandstone_block"}, {["x"] = 3, ["y"] = 0, ["param1"] = 18, ["z"] = 14, ["name"] = "default:silver_sandstone_block"}, {["x"] = 3, ["y"] = 0, ["param1"] = 18, ["z"] = 15, ["name"] = "default:silver_sandstone_block"}, {["x"] = 3, ["y"] = 0, ["param1"] = 18, ["z"] = 16, ["name"] = "default:silver_sandstone_block"}, {["x"] = 3, ["y"] = 0, ["param1"] = 18, ["z"] = 17, ["name"] = "default:silver_sandstone_block"}, {["x"] = 3, ["y"] = 0, ["param1"] = 18, ["z"] = 18, ["name"] = "default:silver_sandstone_block"}, {["x"] = 3, ["y"] = 0, ["param1"] = 18, ["z"] = 19, ["name"] = "default:silver_sandstone_block"}, {["x"] = 3, ["y"] = 0, ["param1"] = 18, ["z"] = 20, ["name"] = "default:silver_sandstone_block"}, {["x"] = 3, ["y"] = 0, ["param1"] = 18, ["z"] = 21, ["name"] = "default:silver_sandstone_block"}, {["x"] = 3, ["y"] = 0, ["param1"] = 18, ["z"] = 22, ["name"] = "default:silver_sandstone_block"}, {["x"] = 3, ["y"] = 0, ["param1"] = 18, ["z"] = 23, ["name"] = "default:silver_sandstone_block"}, {["x"] = 3, ["y"] = 0, ["param1"] = 18, ["z"] = 24, ["name"] = "default:silver_sandstone_block"}, {["x"] = 3, ["y"] = 0, ["param1"] = 18, ["z"] = 25, ["name"] = "default:silver_sandstone_block"}, {["x"] = 3, ["y"] = 0, ["param1"] = 18, ["z"] = 26, ["name"] = "default:silver_sandstone_block"}, {["x"] = 3, ["y"] = 0, ["param1"] = 18, ["z"] = 27, ["name"] = "default:silver_sandstone_block"}, {["x"] = 3, ["y"] = 0, ["param1"] = 18, ["z"] = 28, ["name"] = "default:silver_sandstone_block"}, {["x"] = 3, ["y"] = 0, ["param1"] = 18, ["z"] = 29, ["name"] = "default:silver_sandstone_block"}, {["x"] = 3, ["y"] = 0, ["param1"] = 18, ["z"] = 30, ["name"] = "default:silver_sandstone_block"}, {["x"] = 3, ["y"] = 0, ["param1"] = 18, ["z"] = 31, ["name"] = "default:silver_sandstone_block"}, {["x"] = 3, ["y"] = 0, ["param1"] = 18, ["z"] = 32, ["name"] = "default:silver_sandstone_block"}, {["x"] = 3, ["y"] = 0, ["param1"] = 18, ["z"] = 33, ["name"] = "default:silver_sandstone_block"}, {["x"] = 3, ["y"] = 0, ["param1"] = 18, ["z"] = 34, ["name"] = "default:silver_sandstone_block"}, {["x"] = 3, ["y"] = 0, ["param1"] = 18, ["z"] = 35, ["name"] = "default:silver_sandstone_block"}, {["x"] = 3, ["y"] = 0, ["param1"] = 18, ["z"] = 36, ["name"] = "default:silver_sandstone_block"}, {["x"] = 3, ["y"] = 0, ["param1"] = 18, ["z"] = 37, ["name"] = "default:silver_sandstone_block"}, {["x"] = 3, ["y"] = 0, ["param1"] = 18, ["z"] = 38, ["name"] = "default:silver_sandstone_block"}, {["x"] = 3, ["y"] = 0, ["param1"] = 18, ["z"] = 39, ["name"] = "default:silver_sandstone_block"}, {["x"] = 3, ["y"] = 0, ["param1"] = 18, ["z"] = 40, ["name"] = "default:silver_sandstone_block"}, {["x"] = 3, ["y"] = 0, ["param1"] = 15, ["z"] = 41, ["name"] = "default:desert_sandstone_block"}, {["x"] = 4, ["y"] = 0, ["param1"] = 15, ["z"] = 0, ["name"] = "default:desert_sandstone_block"}, {["x"] = 4, ["y"] = 0, ["param1"] = 18, ["z"] = 1, ["name"] = "default:silver_sandstone_block"}, {["x"] = 4, ["y"] = 0, ["param1"] = 18, ["z"] = 2, ["name"] = "default:silver_sandstone_block"}, {["x"] = 4, ["y"] = 0, ["param1"] = 18, ["z"] = 3, ["name"] = "default:silver_sandstone_block"}, {["x"] = 4, ["y"] = 0, ["param1"] = 18, ["z"] = 4, ["name"] = "default:silver_sandstone_block"}, {["x"] = 4, ["y"] = 0, ["param1"] = 18, ["z"] = 5, ["name"] = "default:silver_sandstone_block"}, {["x"] = 4, ["y"] = 0, ["param1"] = 18, ["z"] = 6, ["name"] = "default:silver_sandstone_block"}, {["x"] = 4, ["y"] = 0, ["param1"] = 18, ["z"] = 7, ["name"] = "default:silver_sandstone_block"}, {["x"] = 4, ["y"] = 0, ["param1"] = 18, ["z"] = 8, ["name"] = "default:silver_sandstone_block"}, {["x"] = 4, ["y"] = 0, ["param1"] = 18, ["z"] = 9, ["name"] = "default:silver_sandstone_block"}, {["x"] = 4, ["y"] = 0, ["param1"] = 18, ["z"] = 10, ["name"] = "default:silver_sandstone_block"}, {["x"] = 4, ["y"] = 0, ["param1"] = 18, ["z"] = 11, ["name"] = "default:silver_sandstone_block"}, {["x"] = 4, ["y"] = 0, ["param1"] = 18, ["z"] = 12, ["name"] = "default:silver_sandstone_block"}, {["x"] = 4, ["y"] = 0, ["param1"] = 18, ["z"] = 13, ["name"] = "default:silver_sandstone_block"}, {["x"] = 4, ["y"] = 0, ["param1"] = 18, ["z"] = 14, ["name"] = "default:silver_sandstone_block"}, {["x"] = 4, ["y"] = 0, ["param1"] = 18, ["z"] = 15, ["name"] = "default:silver_sandstone_block"}, {["x"] = 4, ["y"] = 0, ["param1"] = 18, ["z"] = 16, ["name"] = "default:silver_sandstone_block"}, {["x"] = 4, ["y"] = 0, ["param1"] = 18, ["z"] = 17, ["name"] = "default:silver_sandstone_block"}, {["x"] = 4, ["y"] = 0, ["param1"] = 18, ["z"] = 18, ["name"] = "default:silver_sandstone_block"}, {["x"] = 4, ["y"] = 0, ["param1"] = 18, ["z"] = 19, ["name"] = "default:silver_sandstone_block"}, {["x"] = 4, ["y"] = 0, ["param1"] = 18, ["z"] = 20, ["name"] = "default:silver_sandstone_block"}, {["x"] = 4, ["y"] = 0, ["param1"] = 18, ["z"] = 21, ["name"] = "default:silver_sandstone_block"}, {["x"] = 4, ["y"] = 0, ["param1"] = 18, ["z"] = 22, ["name"] = "default:silver_sandstone_block"}, {["x"] = 4, ["y"] = 0, ["param1"] = 18, ["z"] = 23, ["name"] = "default:silver_sandstone_block"}, {["x"] = 4, ["y"] = 0, ["param1"] = 18, ["z"] = 24, ["name"] = "default:silver_sandstone_block"}, {["x"] = 4, ["y"] = 0, ["param1"] = 18, ["z"] = 25, ["name"] = "default:silver_sandstone_block"}, {["x"] = 4, ["y"] = 0, ["param1"] = 18, ["z"] = 26, ["name"] = "default:silver_sandstone_block"}, {["x"] = 4, ["y"] = 0, ["param1"] = 18, ["z"] = 27, ["name"] = "default:silver_sandstone_block"}, {["x"] = 4, ["y"] = 0, ["param1"] = 18, ["z"] = 28, ["name"] = "default:silver_sandstone_block"}, {["x"] = 4, ["y"] = 0, ["param1"] = 18, ["z"] = 29, ["name"] = "default:silver_sandstone_block"}, {["x"] = 4, ["y"] = 0, ["param1"] = 18, ["z"] = 30, ["name"] = "default:silver_sandstone_block"}, {["x"] = 4, ["y"] = 0, ["param1"] = 18, ["z"] = 31, ["name"] = "default:silver_sandstone_block"}, {["x"] = 4, ["y"] = 0, ["param1"] = 18, ["z"] = 32, ["name"] = "default:silver_sandstone_block"}, {["x"] = 4, ["y"] = 0, ["param1"] = 18, ["z"] = 33, ["name"] = "default:silver_sandstone_block"}, {["x"] = 4, ["y"] = 0, ["param1"] = 18, ["z"] = 34, ["name"] = "default:silver_sandstone_block"}, {["x"] = 4, ["y"] = 0, ["param1"] = 18, ["z"] = 35, ["name"] = "default:silver_sandstone_block"}, {["x"] = 4, ["y"] = 0, ["param1"] = 18, ["z"] = 36, ["name"] = "default:silver_sandstone_block"}, {["x"] = 4, ["y"] = 0, ["param1"] = 18, ["z"] = 37, ["name"] = "default:silver_sandstone_block"}, {["x"] = 4, ["y"] = 0, ["param1"] = 18, ["z"] = 38, ["name"] = "default:silver_sandstone_block"}, {["x"] = 4, ["y"] = 0, ["param1"] = 18, ["z"] = 39, ["name"] = "default:silver_sandstone_block"}, {["x"] = 4, ["y"] = 0, ["param1"] = 18, ["z"] = 40, ["name"] = "default:silver_sandstone_block"}, {["x"] = 4, ["y"] = 0, ["param1"] = 15, ["z"] = 41, ["name"] = "default:desert_sandstone_block"}, {["x"] = 4, ["meta"] = {["fields"] = {["infotext"] = "\"Input/Output 8\"", ["formspec"] = "field[text;;${text}]", ["text"] = "Input/Output 8"}, ["inventory"] = {}}, ["param2"] = 2, ["y"] = 2, ["param1"] = 30, ["z"] = 9, ["name"] = "default:sign_wall_steel"}, {["x"] = 4, ["meta"] = {["fields"] = {["infotext"] = "\"Input/Output 7\"", ["formspec"] = "field[text;;${text}]", ["text"] = "Input/Output 7"}, ["inventory"] = {}}, ["param2"] = 2, ["y"] = 2, ["param1"] = 30, ["z"] = 12, ["name"] = "default:sign_wall_steel"}, {["x"] = 4, ["meta"] = {["fields"] = {["infotext"] = "\"Input/Output 6\"", ["formspec"] = "field[text;;${text}]", ["text"] = "Input/Output 6"}, ["inventory"] = {}}, ["param2"] = 2, ["y"] = 2, ["param1"] = 30, ["z"] = 15, ["name"] = "default:sign_wall_steel"}, {["x"] = 4, ["meta"] = {["fields"] = {["infotext"] = "\"Input/Output 5\"", ["formspec"] = "field[text;;${text}]", ["text"] = "Input/Output 5"}, ["inventory"] = {}}, ["param2"] = 2, ["y"] = 2, ["param1"] = 31, ["z"] = 18, ["name"] = "default:sign_wall_steel"}, {["x"] = 4, ["meta"] = {["fields"] = {["infotext"] = "\"Input/Output 4\"", ["formspec"] = "field[text;;${text}]", ["text"] = "Input/Output 4"}, ["inventory"] = {}}, ["param2"] = 2, ["y"] = 2, ["param1"] = 31, ["z"] = 21, ["name"] = "default:sign_wall_steel"}, {["x"] = 4, ["meta"] = {["fields"] = {["infotext"] = "\"Input/Output 3\"", ["formspec"] = "field[text;;${text}]", ["text"] = "Input/Output 3"}, ["inventory"] = {}}, ["param2"] = 2, ["y"] = 2, ["param1"] = 31, ["z"] = 24, ["name"] = "default:sign_wall_steel"}, {["x"] = 4, ["meta"] = {["fields"] = {["infotext"] = "\"Input/Output 2\"", ["formspec"] = "field[text;;${text}]", ["text"] = "Input/Output 2"}, ["inventory"] = {}}, ["param2"] = 2, ["y"] = 2, ["param1"] = 31, ["z"] = 27, ["name"] = "default:sign_wall_steel"}, {["x"] = 4, ["meta"] = {["fields"] = {["infotext"] = "\"Input/Output 1\"", ["formspec"] = "field[text;;${text}]", ["text"] = "Input/Output 1"}, ["inventory"] = {}}, ["param2"] = 2, ["y"] = 2, ["param1"] = 31, ["z"] = 30, ["name"] = "default:sign_wall_steel"}, {["x"] = 5, ["y"] = 0, ["param1"] = 15, ["z"] = 0, ["name"] = "default:desert_sandstone_block"}, {["x"] = 5, ["y"] = 0, ["param1"] = 18, ["z"] = 1, ["name"] = "default:silver_sandstone_block"}, {["x"] = 5, ["y"] = 0, ["param1"] = 18, ["z"] = 2, ["name"] = "default:silver_sandstone_block"}, {["x"] = 5, ["y"] = 0, ["param1"] = 18, ["z"] = 3, ["name"] = "default:silver_sandstone_block"}, {["x"] = 5, ["y"] = 0, ["param1"] = 18, ["z"] = 4, ["name"] = "default:silver_sandstone_block"}, {["x"] = 5, ["y"] = 0, ["param1"] = 18, ["z"] = 5, ["name"] = "default:silver_sandstone_block"}, {["x"] = 5, ["y"] = 0, ["param1"] = 18, ["z"] = 6, ["name"] = "default:silver_sandstone_block"}, {["x"] = 5, ["y"] = 0, ["param1"] = 18, ["z"] = 7, ["name"] = "default:silver_sandstone_block"}, {["x"] = 5, ["y"] = 0, ["param1"] = 18, ["z"] = 8, ["name"] = "default:silver_sandstone_block"}, {["x"] = 5, ["y"] = 0, ["param1"] = 18, ["z"] = 9, ["name"] = "default:silver_sandstone_block"}, {["x"] = 5, ["y"] = 0, ["param1"] = 18, ["z"] = 10, ["name"] = "default:silver_sandstone_block"}, {["x"] = 5, ["y"] = 0, ["param1"] = 18, ["z"] = 11, ["name"] = "default:silver_sandstone_block"}, {["x"] = 5, ["y"] = 0, ["param1"] = 18, ["z"] = 12, ["name"] = "default:silver_sandstone_block"}, {["x"] = 5, ["y"] = 0, ["param1"] = 18, ["z"] = 13, ["name"] = "default:silver_sandstone_block"}, {["x"] = 5, ["y"] = 0, ["param1"] = 18, ["z"] = 14, ["name"] = "default:silver_sandstone_block"}, {["x"] = 5, ["y"] = 0, ["param1"] = 18, ["z"] = 15, ["name"] = "default:silver_sandstone_block"}, {["x"] = 5, ["y"] = 0, ["param1"] = 18, ["z"] = 16, ["name"] = "default:silver_sandstone_block"}, {["x"] = 5, ["y"] = 0, ["param1"] = 18, ["z"] = 17, ["name"] = "default:silver_sandstone_block"}, {["x"] = 5, ["y"] = 0, ["param1"] = 18, ["z"] = 18, ["name"] = "default:silver_sandstone_block"}, {["x"] = 5, ["y"] = 0, ["param1"] = 18, ["z"] = 19, ["name"] = "default:silver_sandstone_block"}, {["x"] = 5, ["y"] = 0, ["param1"] = 18, ["z"] = 20, ["name"] = "default:silver_sandstone_block"}, {["x"] = 5, ["y"] = 0, ["param1"] = 18, ["z"] = 21, ["name"] = "default:silver_sandstone_block"}, {["x"] = 5, ["y"] = 0, ["param1"] = 18, ["z"] = 22, ["name"] = "default:silver_sandstone_block"}, {["x"] = 5, ["y"] = 0, ["param1"] = 18, ["z"] = 23, ["name"] = "default:silver_sandstone_block"}, {["x"] = 5, ["y"] = 0, ["param1"] = 18, ["z"] = 24, ["name"] = "default:silver_sandstone_block"}, {["x"] = 5, ["y"] = 0, ["param1"] = 18, ["z"] = 25, ["name"] = "default:silver_sandstone_block"}, {["x"] = 5, ["y"] = 0, ["param1"] = 18, ["z"] = 26, ["name"] = "default:silver_sandstone_block"}, {["x"] = 5, ["y"] = 0, ["param1"] = 18, ["z"] = 27, ["name"] = "default:silver_sandstone_block"}, {["x"] = 5, ["y"] = 0, ["param1"] = 18, ["z"] = 28, ["name"] = "default:silver_sandstone_block"}, {["x"] = 5, ["y"] = 0, ["param1"] = 18, ["z"] = 29, ["name"] = "default:silver_sandstone_block"}, {["x"] = 5, ["y"] = 0, ["param1"] = 18, ["z"] = 30, ["name"] = "default:silver_sandstone_block"}, {["x"] = 5, ["y"] = 0, ["param1"] = 18, ["z"] = 31, ["name"] = "default:silver_sandstone_block"}, {["x"] = 5, ["y"] = 0, ["param1"] = 18, ["z"] = 32, ["name"] = "default:silver_sandstone_block"}, {["x"] = 5, ["y"] = 0, ["param1"] = 18, ["z"] = 33, ["name"] = "default:silver_sandstone_block"}, {["x"] = 5, ["y"] = 0, ["param1"] = 18, ["z"] = 34, ["name"] = "default:silver_sandstone_block"}, {["x"] = 5, ["y"] = 0, ["param1"] = 18, ["z"] = 35, ["name"] = "default:silver_sandstone_block"}, {["x"] = 5, ["y"] = 0, ["param1"] = 18, ["z"] = 36, ["name"] = "default:silver_sandstone_block"}, {["x"] = 5, ["y"] = 0, ["param1"] = 18, ["z"] = 37, ["name"] = "default:silver_sandstone_block"}, {["x"] = 5, ["y"] = 0, ["param1"] = 18, ["z"] = 38, ["name"] = "default:silver_sandstone_block"}, {["x"] = 5, ["y"] = 0, ["param1"] = 18, ["z"] = 39, ["name"] = "default:silver_sandstone_block"}, {["x"] = 5, ["y"] = 0, ["param1"] = 18, ["z"] = 40, ["name"] = "default:silver_sandstone_block"}, {["x"] = 5, ["y"] = 0, ["param1"] = 15, ["z"] = 41, ["name"] = "default:desert_sandstone_block"}, {["x"] = 5, ["y"] = 1, ["param1"] = 16, ["z"] = 6, ["name"] = "default:silver_sandstone"}, {["x"] = 5, ["y"] = 1, ["param1"] = 16, ["z"] = 7, ["name"] = "default:silver_sandstone"}, {["x"] = 5, ["y"] = 1, ["param1"] = 16, ["z"] = 8, ["name"] = "default:silver_sandstone"}, {["x"] = 5, ["y"] = 1, ["param1"] = 61, ["z"] = 9, ["name"] = "default:mese"}, {["x"] = 5, ["y"] = 1, ["param1"] = 16, ["z"] = 10, ["name"] = "default:silver_sandstone"}, {["x"] = 5, ["y"] = 1, ["param1"] = 16, ["z"] = 11, ["name"] = "default:silver_sandstone"}, {["x"] = 5, ["y"] = 1, ["param1"] = 61, ["z"] = 12, ["name"] = "default:mese"}, {["x"] = 5, ["y"] = 1, ["param1"] = 16, ["z"] = 13, ["name"] = "default:silver_sandstone"}, {["x"] = 5, ["y"] = 1, ["param1"] = 16, ["z"] = 14, ["name"] = "default:silver_sandstone"}, {["x"] = 5, ["y"] = 1, ["param1"] = 61, ["z"] = 15, ["name"] = "default:mese"}, {["x"] = 5, ["y"] = 1, ["param1"] = 16, ["z"] = 16, ["name"] = "default:silver_sandstone"}, {["x"] = 5, ["y"] = 1, ["param1"] = 16, ["z"] = 17, ["name"] = "default:silver_sandstone"}, {["x"] = 5, ["y"] = 1, ["param1"] = 62, ["z"] = 18, ["name"] = "default:mese"}, {["x"] = 5, ["y"] = 1, ["param1"] = 16, ["z"] = 19, ["name"] = "default:silver_sandstone"}, {["x"] = 5, ["y"] = 1, ["param1"] = 16, ["z"] = 20, ["name"] = "default:silver_sandstone"}, {["x"] = 5, ["y"] = 1, ["param1"] = 62, ["z"] = 21, ["name"] = "default:mese"}, {["x"] = 5, ["y"] = 1, ["param1"] = 16, ["z"] = 22, ["name"] = "default:silver_sandstone"}, {["x"] = 5, ["y"] = 1, ["param1"] = 16, ["z"] = 23, ["name"] = "default:silver_sandstone"}, {["x"] = 5, ["y"] = 1, ["param1"] = 62, ["z"] = 24, ["name"] = "default:mese"}, {["x"] = 5, ["y"] = 1, ["param1"] = 16, ["z"] = 25, ["name"] = "default:silver_sandstone"}, {["x"] = 5, ["y"] = 1, ["param1"] = 16, ["z"] = 26, ["name"] = "default:silver_sandstone"}, {["x"] = 5, ["y"] = 1, ["param1"] = 62, ["z"] = 27, ["name"] = "default:mese"}, {["x"] = 5, ["y"] = 1, ["param1"] = 16, ["z"] = 28, ["name"] = "default:silver_sandstone"}, {["x"] = 5, ["y"] = 1, ["param1"] = 16, ["z"] = 29, ["name"] = "default:silver_sandstone"}, {["x"] = 5, ["y"] = 1, ["param1"] = 62, ["z"] = 30, ["name"] = "default:mese"}, {["x"] = 5, ["y"] = 1, ["param1"] = 16, ["z"] = 31, ["name"] = "default:silver_sandstone"}, {["x"] = 5, ["y"] = 1, ["param1"] = 16, ["z"] = 32, ["name"] = "default:silver_sandstone"}, {["x"] = 5, ["y"] = 1, ["param1"] = 16, ["z"] = 33, ["name"] = "default:silver_sandstone"}, {["x"] = 5, ["y"] = 1, ["param1"] = 16, ["z"] = 34, ["name"] = "default:silver_sandstone"}, {["x"] = 5, ["y"] = 2, ["param1"] = 16, ["z"] = 6, ["name"] = "default:silver_sandstone"}, {["x"] = 5, ["y"] = 2, ["param1"] = 16, ["z"] = 7, ["name"] = "default:silver_sandstone"}, {["x"] = 5, ["y"] = 2, ["param1"] = 16, ["z"] = 8, ["name"] = "default:silver_sandstone"}, {["x"] = 5, ["y"] = 2, ["param1"] = 16, ["z"] = 9, ["name"] = "default:silver_sandstone"}, {["x"] = 5, ["y"] = 2, ["param1"] = 16, ["z"] = 10, ["name"] = "default:silver_sandstone"}, {["x"] = 5, ["y"] = 2, ["param1"] = 16, ["z"] = 11, ["name"] = "default:silver_sandstone"}, {["x"] = 5, ["y"] = 2, ["param1"] = 16, ["z"] = 12, ["name"] = "default:silver_sandstone"}, {["x"] = 5, ["y"] = 2, ["param1"] = 16, ["z"] = 13, ["name"] = "default:silver_sandstone"}, {["x"] = 5, ["y"] = 2, ["param1"] = 16, ["z"] = 14, ["name"] = "default:silver_sandstone"}, {["x"] = 5, ["y"] = 2, ["param1"] = 16, ["z"] = 15, ["name"] = "default:silver_sandstone"}, {["x"] = 5, ["y"] = 2, ["param1"] = 16, ["z"] = 16, ["name"] = "default:silver_sandstone"}, {["x"] = 5, ["y"] = 2, ["param1"] = 16, ["z"] = 17, ["name"] = "default:silver_sandstone"}, {["x"] = 5, ["y"] = 2, ["param1"] = 16, ["z"] = 18, ["name"] = "default:silver_sandstone"}, {["x"] = 5, ["y"] = 2, ["param1"] = 16, ["z"] = 19, ["name"] = "default:silver_sandstone"}, {["x"] = 5, ["y"] = 2, ["param1"] = 16, ["z"] = 20, ["name"] = "default:silver_sandstone"}, {["x"] = 5, ["y"] = 2, ["param1"] = 16, ["z"] = 21, ["name"] = "default:silver_sandstone"}, {["x"] = 5, ["y"] = 2, ["param1"] = 16, ["z"] = 22, ["name"] = "default:silver_sandstone"}, {["x"] = 5, ["y"] = 2, ["param1"] = 16, ["z"] = 23, ["name"] = "default:silver_sandstone"}, {["x"] = 5, ["y"] = 2, ["param1"] = 16, ["z"] = 24, ["name"] = "default:silver_sandstone"}, {["x"] = 5, ["y"] = 2, ["param1"] = 16, ["z"] = 25, ["name"] = "default:silver_sandstone"}, {["x"] = 5, ["y"] = 2, ["param1"] = 16, ["z"] = 26, ["name"] = "default:silver_sandstone"}, {["x"] = 5, ["y"] = 2, ["param1"] = 16, ["z"] = 27, ["name"] = "default:silver_sandstone"}, {["x"] = 5, ["y"] = 2, ["param1"] = 16, ["z"] = 28, ["name"] = "default:silver_sandstone"}, {["x"] = 5, ["y"] = 2, ["param1"] = 16, ["z"] = 29, ["name"] = "default:silver_sandstone"}, {["x"] = 5, ["y"] = 2, ["param1"] = 16, ["z"] = 30, ["name"] = "default:silver_sandstone"}, {["x"] = 5, ["y"] = 2, ["param1"] = 16, ["z"] = 31, ["name"] = "default:silver_sandstone"}, {["x"] = 5, ["y"] = 2, ["param1"] = 16, ["z"] = 32, ["name"] = "default:silver_sandstone"}, {["x"] = 5, ["y"] = 2, ["param1"] = 16, ["z"] = 33, ["name"] = "default:silver_sandstone"}, {["x"] = 5, ["y"] = 2, ["param1"] = 16, ["z"] = 34, ["name"] = "default:silver_sandstone"}, {["x"] = 5, ["y"] = 3, ["param1"] = 16, ["z"] = 6, ["name"] = "default:silver_sandstone"}, {["x"] = 5, ["y"] = 3, ["param1"] = 16, ["z"] = 7, ["name"] = "default:silver_sandstone"}, {["x"] = 5, ["y"] = 3, ["param1"] = 16, ["z"] = 8, ["name"] = "default:silver_sandstone"}, {["x"] = 5, ["y"] = 3, ["param1"] = 16, ["z"] = 9, ["name"] = "default:silver_sandstone"}, {["x"] = 5, ["y"] = 3, ["param1"] = 16, ["z"] = 10, ["name"] = "default:silver_sandstone"}, {["x"] = 5, ["y"] = 3, ["param1"] = 16, ["z"] = 11, ["name"] = "default:silver_sandstone"}, {["x"] = 5, ["y"] = 3, ["param1"] = 16, ["z"] = 12, ["name"] = "default:silver_sandstone"}, {["x"] = 5, ["y"] = 3, ["param1"] = 16, ["z"] = 13, ["name"] = "default:silver_sandstone"}, {["x"] = 5, ["y"] = 3, ["param1"] = 16, ["z"] = 14, ["name"] = "default:silver_sandstone"}, {["x"] = 5, ["y"] = 3, ["param1"] = 16, ["z"] = 15, ["name"] = "default:silver_sandstone"}, {["x"] = 5, ["y"] = 3, ["param1"] = 16, ["z"] = 16, ["name"] = "default:silver_sandstone"}, {["x"] = 5, ["y"] = 3, ["param1"] = 16, ["z"] = 17, ["name"] = "default:silver_sandstone"}, {["x"] = 5, ["y"] = 3, ["param1"] = 16, ["z"] = 18, ["name"] = "default:silver_sandstone"}, {["x"] = 5, ["y"] = 3, ["param1"] = 16, ["z"] = 19, ["name"] = "default:silver_sandstone"}, {["x"] = 5, ["y"] = 3, ["param1"] = 16, ["z"] = 20, ["name"] = "default:silver_sandstone"}, {["x"] = 5, ["y"] = 3, ["param1"] = 16, ["z"] = 21, ["name"] = "default:silver_sandstone"}, {["x"] = 5, ["y"] = 3, ["param1"] = 16, ["z"] = 22, ["name"] = "default:silver_sandstone"}, {["x"] = 5, ["y"] = 3, ["param1"] = 16, ["z"] = 23, ["name"] = "default:silver_sandstone"}, {["x"] = 5, ["y"] = 3, ["param1"] = 16, ["z"] = 24, ["name"] = "default:silver_sandstone"}, {["x"] = 5, ["y"] = 3, ["param1"] = 16, ["z"] = 25, ["name"] = "default:silver_sandstone"}, {["x"] = 5, ["y"] = 3, ["param1"] = 16, ["z"] = 26, ["name"] = "default:silver_sandstone"}, {["x"] = 5, ["y"] = 3, ["param1"] = 16, ["z"] = 27, ["name"] = "default:silver_sandstone"}, {["x"] = 5, ["y"] = 3, ["param1"] = 16, ["z"] = 28, ["name"] = "default:silver_sandstone"}, {["x"] = 5, ["y"] = 3, ["param1"] = 16, ["z"] = 29, ["name"] = "default:silver_sandstone"}, {["x"] = 5, ["y"] = 3, ["param1"] = 16, ["z"] = 30, ["name"] = "default:silver_sandstone"}, {["x"] = 5, ["y"] = 3, ["param1"] = 16, ["z"] = 31, ["name"] = "default:silver_sandstone"}, {["x"] = 5, ["y"] = 3, ["param1"] = 16, ["z"] = 32, ["name"] = "default:silver_sandstone"}, {["x"] = 5, ["y"] = 3, ["param1"] = 16, ["z"] = 33, ["name"] = "default:silver_sandstone"}, {["x"] = 5, ["y"] = 3, ["param1"] = 16, ["z"] = 34, ["name"] = "default:silver_sandstone"}, {["x"] = 5, ["y"] = 4, ["param1"] = 14, ["z"] = 6, ["name"] = "stairs:slab_silver_sandstone"}, {["x"] = 5, ["y"] = 4, ["param1"] = 14, ["z"] = 7, ["name"] = "stairs:slab_silver_sandstone"}, {["x"] = 5, ["y"] = 4, ["param1"] = 14, ["z"] = 8, ["name"] = "stairs:slab_silver_sandstone"}, {["x"] = 5, ["y"] = 4, ["param1"] = 14, ["z"] = 9, ["name"] = "stairs:slab_silver_sandstone"}, {["x"] = 5, ["y"] = 4, ["param1"] = 14, ["z"] = 10, ["name"] = "stairs:slab_silver_sandstone"}, {["x"] = 5, ["y"] = 4, ["param1"] = 14, ["z"] = 11, ["name"] = "stairs:slab_silver_sandstone"}, {["x"] = 5, ["y"] = 4, ["param1"] = 14, ["z"] = 12, ["name"] = "stairs:slab_silver_sandstone"}, {["x"] = 5, ["y"] = 4, ["param1"] = 14, ["z"] = 13, ["name"] = "stairs:slab_silver_sandstone"}, {["x"] = 5, ["y"] = 4, ["param1"] = 14, ["z"] = 14, ["name"] = "stairs:slab_silver_sandstone"}, {["x"] = 5, ["y"] = 4, ["param1"] = 14, ["z"] = 15, ["name"] = "stairs:slab_silver_sandstone"}, {["x"] = 5, ["y"] = 4, ["param1"] = 14, ["z"] = 16, ["name"] = "stairs:slab_silver_sandstone"}, {["x"] = 5, ["y"] = 4, ["param1"] = 14, ["z"] = 17, ["name"] = "stairs:slab_silver_sandstone"}, {["x"] = 5, ["y"] = 4, ["param1"] = 14, ["z"] = 18, ["name"] = "stairs:slab_silver_sandstone"}, {["x"] = 5, ["y"] = 4, ["param1"] = 14, ["z"] = 19, ["name"] = "stairs:slab_silver_sandstone"}, {["x"] = 5, ["y"] = 4, ["param1"] = 14, ["z"] = 20, ["name"] = "stairs:slab_silver_sandstone"}, {["x"] = 5, ["y"] = 4, ["param1"] = 14, ["z"] = 21, ["name"] = "stairs:slab_silver_sandstone"}, {["x"] = 5, ["y"] = 4, ["param1"] = 14, ["z"] = 22, ["name"] = "stairs:slab_silver_sandstone"}, {["x"] = 5, ["y"] = 4, ["param1"] = 14, ["z"] = 23, ["name"] = "stairs:slab_silver_sandstone"}, {["x"] = 5, ["y"] = 4, ["param1"] = 14, ["z"] = 24, ["name"] = "stairs:slab_silver_sandstone"}, {["x"] = 5, ["y"] = 4, ["param1"] = 14, ["z"] = 25, ["name"] = "stairs:slab_silver_sandstone"}, {["x"] = 5, ["y"] = 4, ["param1"] = 14, ["z"] = 26, ["name"] = "stairs:slab_silver_sandstone"}, {["x"] = 5, ["y"] = 4, ["param1"] = 14, ["z"] = 27, ["name"] = "stairs:slab_silver_sandstone"}, {["x"] = 5, ["y"] = 4, ["param1"] = 14, ["z"] = 28, ["name"] = "stairs:slab_silver_sandstone"}, {["x"] = 5, ["y"] = 4, ["param1"] = 14, ["z"] = 29, ["name"] = "stairs:slab_silver_sandstone"}, {["x"] = 5, ["y"] = 4, ["param1"] = 14, ["z"] = 30, ["name"] = "stairs:slab_silver_sandstone"}, {["x"] = 5, ["y"] = 4, ["param1"] = 14, ["z"] = 31, ["name"] = "stairs:slab_silver_sandstone"}, {["x"] = 5, ["y"] = 4, ["param1"] = 14, ["z"] = 32, ["name"] = "stairs:slab_silver_sandstone"}, {["x"] = 5, ["y"] = 4, ["param1"] = 14, ["z"] = 33, ["name"] = "stairs:slab_silver_sandstone"}, {["x"] = 5, ["y"] = 4, ["param1"] = 14, ["z"] = 34, ["name"] = "stairs:slab_silver_sandstone"}, {["x"] = 6, ["y"] = 0, ["param1"] = 15, ["z"] = 0, ["name"] = "default:desert_sandstone_block"}, {["x"] = 6, ["y"] = 0, ["param1"] = 18, ["z"] = 1, ["name"] = "default:silver_sandstone_block"}, {["x"] = 6, ["y"] = 0, ["param1"] = 18, ["z"] = 2, ["name"] = "default:silver_sandstone_block"}, {["x"] = 6, ["y"] = 0, ["param1"] = 18, ["z"] = 3, ["name"] = "default:silver_sandstone_block"}, {["x"] = 6, ["y"] = 0, ["param1"] = 18, ["z"] = 4, ["name"] = "default:silver_sandstone_block"}, {["x"] = 6, ["y"] = 0, ["param1"] = 18, ["z"] = 5, ["name"] = "default:silver_sandstone_block"}, {["x"] = 6, ["y"] = 0, ["param1"] = 18, ["z"] = 6, ["name"] = "default:silver_sandstone_block"}, {["x"] = 6, ["y"] = 0, ["param1"] = 18, ["z"] = 7, ["name"] = "default:silver_sandstone_block"}, {["x"] = 6, ["y"] = 0, ["param1"] = 18, ["z"] = 8, ["name"] = "default:silver_sandstone_block"}, {["x"] = 6, ["y"] = 0, ["param1"] = 18, ["z"] = 9, ["name"] = "default:silver_sandstone_block"}, {["x"] = 6, ["y"] = 0, ["param1"] = 18, ["z"] = 10, ["name"] = "default:silver_sandstone_block"}, {["x"] = 6, ["y"] = 0, ["param1"] = 18, ["z"] = 11, ["name"] = "default:silver_sandstone_block"}, {["x"] = 6, ["y"] = 0, ["param1"] = 18, ["z"] = 12, ["name"] = "default:silver_sandstone_block"}, {["x"] = 6, ["y"] = 0, ["param1"] = 18, ["z"] = 13, ["name"] = "default:silver_sandstone_block"}, {["x"] = 6, ["y"] = 0, ["param1"] = 18, ["z"] = 14, ["name"] = "default:silver_sandstone_block"}, {["x"] = 6, ["y"] = 0, ["param1"] = 18, ["z"] = 15, ["name"] = "default:silver_sandstone_block"}, {["x"] = 6, ["y"] = 0, ["param1"] = 18, ["z"] = 16, ["name"] = "default:silver_sandstone_block"}, {["x"] = 6, ["y"] = 0, ["param1"] = 18, ["z"] = 17, ["name"] = "default:silver_sandstone_block"}, {["x"] = 6, ["y"] = 0, ["param1"] = 18, ["z"] = 18, ["name"] = "default:silver_sandstone_block"}, {["x"] = 6, ["y"] = 0, ["param1"] = 18, ["z"] = 19, ["name"] = "default:silver_sandstone_block"}, {["x"] = 6, ["y"] = 0, ["param1"] = 18, ["z"] = 20, ["name"] = "default:silver_sandstone_block"}, {["x"] = 6, ["y"] = 0, ["param1"] = 18, ["z"] = 21, ["name"] = "default:silver_sandstone_block"}, {["x"] = 6, ["y"] = 0, ["param1"] = 18, ["z"] = 22, ["name"] = "default:silver_sandstone_block"}, {["x"] = 6, ["y"] = 0, ["param1"] = 18, ["z"] = 23, ["name"] = "default:silver_sandstone_block"}, {["x"] = 6, ["y"] = 0, ["param1"] = 18, ["z"] = 24, ["name"] = "default:silver_sandstone_block"}, {["x"] = 6, ["y"] = 0, ["param1"] = 18, ["z"] = 25, ["name"] = "default:silver_sandstone_block"}, {["x"] = 6, ["y"] = 0, ["param1"] = 18, ["z"] = 26, ["name"] = "default:silver_sandstone_block"}, {["x"] = 6, ["y"] = 0, ["param1"] = 18, ["z"] = 27, ["name"] = "default:silver_sandstone_block"}, {["x"] = 6, ["y"] = 0, ["param1"] = 18, ["z"] = 28, ["name"] = "default:silver_sandstone_block"}, {["x"] = 6, ["y"] = 0, ["param1"] = 18, ["z"] = 29, ["name"] = "default:silver_sandstone_block"}, {["x"] = 6, ["y"] = 0, ["param1"] = 18, ["z"] = 30, ["name"] = "default:silver_sandstone_block"}, {["x"] = 6, ["y"] = 0, ["param1"] = 18, ["z"] = 31, ["name"] = "default:silver_sandstone_block"}, {["x"] = 6, ["y"] = 0, ["param1"] = 18, ["z"] = 32, ["name"] = "default:silver_sandstone_block"}, {["x"] = 6, ["y"] = 0, ["param1"] = 18, ["z"] = 33, ["name"] = "default:silver_sandstone_block"}, {["x"] = 6, ["y"] = 0, ["param1"] = 18, ["z"] = 34, ["name"] = "default:silver_sandstone_block"}, {["x"] = 6, ["y"] = 0, ["param1"] = 18, ["z"] = 35, ["name"] = "default:silver_sandstone_block"}, {["x"] = 6, ["y"] = 0, ["param1"] = 18, ["z"] = 36, ["name"] = "default:silver_sandstone_block"}, {["x"] = 6, ["y"] = 0, ["param1"] = 18, ["z"] = 37, ["name"] = "default:silver_sandstone_block"}, {["x"] = 6, ["y"] = 0, ["param1"] = 18, ["z"] = 38, ["name"] = "default:silver_sandstone_block"}, {["x"] = 6, ["y"] = 0, ["param1"] = 18, ["z"] = 39, ["name"] = "default:silver_sandstone_block"}, {["x"] = 6, ["y"] = 0, ["param1"] = 18, ["z"] = 40, ["name"] = "default:silver_sandstone_block"}, {["x"] = 6, ["y"] = 0, ["param1"] = 15, ["z"] = 41, ["name"] = "default:desert_sandstone_block"}, {["x"] = 6, ["y"] = 1, ["param1"] = 16, ["z"] = 6, ["name"] = "default:silver_sandstone"}, {["x"] = 6, ["y"] = 1, ["param1"] = 16, ["z"] = 7, ["name"] = "default:silver_sandstone"}, {["x"] = 6, ["y"] = 1, ["param1"] = 16, ["z"] = 8, ["name"] = "default:silver_sandstone"}, {["x"] = 6, ["y"] = 1, ["param1"] = 60, ["z"] = 9, ["name"] = "default:mese"}, {["x"] = 6, ["y"] = 1, ["param1"] = 16, ["z"] = 10, ["name"] = "default:silver_sandstone"}, {["x"] = 6, ["y"] = 1, ["param1"] = 16, ["z"] = 11, ["name"] = "default:silver_sandstone"}, {["x"] = 6, ["y"] = 1, ["param1"] = 60, ["z"] = 12, ["name"] = "default:mese"}, {["x"] = 6, ["y"] = 1, ["param1"] = 16, ["z"] = 13, ["name"] = "default:silver_sandstone"}, {["x"] = 6, ["y"] = 1, ["param1"] = 16, ["z"] = 14, ["name"] = "default:silver_sandstone"}, {["x"] = 6, ["y"] = 1, ["param1"] = 60, ["z"] = 15, ["name"] = "default:mese"}, {["x"] = 6, ["y"] = 1, ["param1"] = 16, ["z"] = 16, ["name"] = "default:silver_sandstone"}, {["x"] = 6, ["y"] = 1, ["param1"] = 16, ["z"] = 17, ["name"] = "default:silver_sandstone"}, {["x"] = 6, ["y"] = 1, ["param1"] = 61, ["z"] = 18, ["name"] = "default:mese"}, {["x"] = 6, ["y"] = 1, ["param1"] = 16, ["z"] = 19, ["name"] = "default:silver_sandstone"}, {["x"] = 6, ["y"] = 1, ["param1"] = 16, ["z"] = 20, ["name"] = "default:silver_sandstone"}, {["x"] = 6, ["y"] = 1, ["param1"] = 61, ["z"] = 21, ["name"] = "default:mese"}, {["x"] = 6, ["y"] = 1, ["param1"] = 16, ["z"] = 22, ["name"] = "default:silver_sandstone"}, {["x"] = 6, ["y"] = 1, ["param1"] = 16, ["z"] = 23, ["name"] = "default:silver_sandstone"}, {["x"] = 6, ["y"] = 1, ["param1"] = 61, ["z"] = 24, ["name"] = "default:mese"}, {["x"] = 6, ["y"] = 1, ["param1"] = 16, ["z"] = 25, ["name"] = "default:silver_sandstone"}, {["x"] = 6, ["y"] = 1, ["param1"] = 16, ["z"] = 26, ["name"] = "default:silver_sandstone"}, {["x"] = 6, ["y"] = 1, ["param1"] = 61, ["z"] = 27, ["name"] = "default:mese"}, {["x"] = 6, ["y"] = 1, ["param1"] = 16, ["z"] = 28, ["name"] = "default:silver_sandstone"}, {["x"] = 6, ["y"] = 1, ["param1"] = 16, ["z"] = 29, ["name"] = "default:silver_sandstone"}, {["x"] = 6, ["y"] = 1, ["param1"] = 61, ["z"] = 30, ["name"] = "default:mese"}, {["x"] = 6, ["y"] = 1, ["param1"] = 16, ["z"] = 31, ["name"] = "default:silver_sandstone"}, {["x"] = 6, ["y"] = 1, ["param1"] = 16, ["z"] = 32, ["name"] = "default:silver_sandstone"}, {["x"] = 6, ["y"] = 1, ["param1"] = 45, ["z"] = 33, ["name"] = "mesecons_extrawires:vertical_bottom_off"}, {["x"] = 6, ["y"] = 1, ["param1"] = 62, ["z"] = 34, ["name"] = "default:mese"}, {["x"] = 6, ["param2"] = 2, ["y"] = 1, ["param1"] = 47, ["z"] = 35, ["name"] = "mesecons_walllever:wall_lever_off"}, {["x"] = 6, ["y"] = 2, ["param1"] = 16, ["z"] = 6, ["name"] = "default:silver_sandstone"}, {["x"] = 6, ["y"] = 2, ["param1"] = 16, ["z"] = 7, ["name"] = "default:silver_sandstone"}, {["x"] = 6, ["y"] = 2, ["param1"] = 16, ["z"] = 8, ["name"] = "default:silver_sandstone"}, {["x"] = 6, ["y"] = 2, ["param1"] = 16, ["z"] = 9, ["name"] = "default:silver_sandstone"}, {["x"] = 6, ["y"] = 2, ["param1"] = 16, ["z"] = 10, ["name"] = "default:silver_sandstone"}, {["x"] = 6, ["y"] = 2, ["param1"] = 16, ["z"] = 11, ["name"] = "default:silver_sandstone"}, {["x"] = 6, ["y"] = 2, ["param1"] = 16, ["z"] = 12, ["name"] = "default:silver_sandstone"}, {["x"] = 6, ["y"] = 2, ["param1"] = 16, ["z"] = 13, ["name"] = "default:silver_sandstone"}, {["x"] = 6, ["y"] = 2, ["param1"] = 16, ["z"] = 14, ["name"] = "default:silver_sandstone"}, {["x"] = 6, ["y"] = 2, ["param1"] = 16, ["z"] = 15, ["name"] = "default:silver_sandstone"}, {["x"] = 6, ["y"] = 2, ["param1"] = 16, ["z"] = 16, ["name"] = "default:silver_sandstone"}, {["x"] = 6, ["y"] = 2, ["param1"] = 16, ["z"] = 17, ["name"] = "default:silver_sandstone"}, {["x"] = 6, ["y"] = 2, ["param1"] = 16, ["z"] = 18, ["name"] = "default:silver_sandstone"}, {["x"] = 6, ["y"] = 2, ["param1"] = 16, ["z"] = 19, ["name"] = "default:silver_sandstone"}, {["x"] = 6, ["y"] = 2, ["param1"] = 16, ["z"] = 20, ["name"] = "default:silver_sandstone"}, {["x"] = 6, ["y"] = 2, ["param1"] = 16, ["z"] = 21, ["name"] = "default:silver_sandstone"}, {["x"] = 6, ["y"] = 2, ["param1"] = 16, ["z"] = 22, ["name"] = "default:silver_sandstone"}, {["x"] = 6, ["y"] = 2, ["param1"] = 16, ["z"] = 23, ["name"] = "default:silver_sandstone"}, {["x"] = 6, ["y"] = 2, ["param1"] = 16, ["z"] = 24, ["name"] = "default:silver_sandstone"}, {["x"] = 6, ["y"] = 2, ["param1"] = 16, ["z"] = 25, ["name"] = "default:silver_sandstone"}, {["x"] = 6, ["y"] = 2, ["param1"] = 16, ["z"] = 26, ["name"] = "default:silver_sandstone"}, {["x"] = 6, ["y"] = 2, ["param1"] = 16, ["z"] = 27, ["name"] = "default:silver_sandstone"}, {["x"] = 6, ["y"] = 2, ["param1"] = 16, ["z"] = 28, ["name"] = "default:silver_sandstone"}, {["x"] = 6, ["y"] = 2, ["param1"] = 16, ["z"] = 29, ["name"] = "default:silver_sandstone"}, {["x"] = 6, ["y"] = 2, ["param1"] = 16, ["z"] = 30, ["name"] = "default:silver_sandstone"}, {["x"] = 6, ["y"] = 2, ["param1"] = 16, ["z"] = 31, ["name"] = "default:silver_sandstone"}, {["x"] = 6, ["y"] = 2, ["param1"] = 16, ["z"] = 32, ["name"] = "default:silver_sandstone"}, {["x"] = 6, ["y"] = 2, ["param1"] = 28, ["z"] = 33, ["name"] = "mesecons_extrawires:vertical_off"}, {["x"] = 6, ["y"] = 2, ["param1"] = 16, ["z"] = 34, ["name"] = "default:silver_sandstone"}, {["x"] = 6, ["meta"] = {["fields"] = {["infotext"] = "\"RO (RAM Out)\"", ["formspec"] = "field[text;;${text}]", ["text"] = "RO (RAM Out)"}, ["inventory"] = {}}, ["param2"] = 5, ["y"] = 2, ["param1"] = 31, ["z"] = 35, ["name"] = "default:sign_wall_steel"}, {["x"] = 6, ["y"] = 3, ["param1"] = 16, ["z"] = 6, ["name"] = "default:silver_sandstone"}, {["x"] = 6, ["y"] = 3, ["param1"] = 13, ["z"] = 7, ["name"] = "digilines:wire_std_11000000"}, {["x"] = 6, ["y"] = 3, ["param1"] = 13, ["z"] = 8, ["name"] = "digilines:wire_std_01010000"}, {["x"] = 6, ["y"] = 3, ["param1"] = 13, ["z"] = 9, ["name"] = "digilines:wire_std_01010000"}, {["x"] = 6, ["y"] = 3, ["param1"] = 13, ["z"] = 10, ["name"] = "digilines:wire_std_11010000"}, {["x"] = 6, ["y"] = 3, ["param1"] = 13, ["z"] = 11, ["name"] = "digilines:wire_std_01010000"}, {["x"] = 6, ["y"] = 3, ["param1"] = 13, ["z"] = 12, ["name"] = "digilines:wire_std_01010000"}, {["x"] = 6, ["y"] = 3, ["param1"] = 13, ["z"] = 13, ["name"] = "digilines:wire_std_11010000"}, {["x"] = 6, ["y"] = 3, ["param1"] = 13, ["z"] = 14, ["name"] = "digilines:wire_std_01010000"}, {["x"] = 6, ["y"] = 3, ["param1"] = 13, ["z"] = 15, ["name"] = "digilines:wire_std_01010000"}, {["x"] = 6, ["y"] = 3, ["param1"] = 13, ["z"] = 16, ["name"] = "digilines:wire_std_11010000"}, {["x"] = 6, ["y"] = 3, ["param1"] = 13, ["z"] = 17, ["name"] = "digilines:wire_std_01010000"}, {["x"] = 6, ["y"] = 3, ["param1"] = 13, ["z"] = 18, ["name"] = "digilines:wire_std_01010000"}, {["x"] = 6, ["y"] = 3, ["param1"] = 13, ["z"] = 19, ["name"] = "digilines:wire_std_11010000"}, {["x"] = 6, ["y"] = 3, ["param1"] = 13, ["z"] = 20, ["name"] = "digilines:wire_std_01010000"}, {["x"] = 6, ["y"] = 3, ["param1"] = 13, ["z"] = 21, ["name"] = "digilines:wire_std_01010000"}, {["x"] = 6, ["y"] = 3, ["param1"] = 13, ["z"] = 22, ["name"] = "digilines:wire_std_11010000"}, {["x"] = 6, ["y"] = 3, ["param1"] = 13, ["z"] = 23, ["name"] = "digilines:wire_std_01010000"}, {["x"] = 6, ["y"] = 3, ["param1"] = 13, ["z"] = 24, ["name"] = "digilines:wire_std_01010000"}, {["x"] = 6, ["y"] = 3, ["param1"] = 13, ["z"] = 25, ["name"] = "digilines:wire_std_11010000"}, {["x"] = 6, ["y"] = 3, ["param1"] = 13, ["z"] = 26, ["name"] = "digilines:wire_std_01010000"}, {["x"] = 6, ["y"] = 3, ["param1"] = 13, ["z"] = 27, ["name"] = "digilines:wire_std_01010000"}, {["x"] = 6, ["y"] = 3, ["param1"] = 13, ["z"] = 28, ["name"] = "digilines:wire_std_11010000"}, {["x"] = 6, ["y"] = 3, ["param1"] = 13, ["z"] = 29, ["name"] = "digilines:wire_std_01010000"}, {["x"] = 6, ["y"] = 3, ["param1"] = 13, ["z"] = 30, ["name"] = "digilines:wire_std_01010000"}, {["x"] = 6, ["y"] = 3, ["param1"] = 13, ["z"] = 31, ["name"] = "digilines:wire_std_10010000"}, {["x"] = 6, ["param2"] = 2, ["y"] = 3, ["param1"] = 13, ["z"] = 32, ["name"] = "mesecons_extrawires:corner_off"}, {["x"] = 6, ["y"] = 3, ["param1"] = 13, ["z"] = 33, ["name"] = "mesecons_extrawires:vertical_top_off"}, {["x"] = 6, ["y"] = 3, ["param1"] = 16, ["z"] = 34, ["name"] = "default:silver_sandstone"}, {["x"] = 6, ["y"] = 4, ["param1"] = 14, ["z"] = 6, ["name"] = "stairs:slab_silver_sandstone"}, {["x"] = 6, ["y"] = 4, ["param1"] = 14, ["z"] = 7, ["name"] = "stairs:slab_silver_sandstone"}, {["x"] = 6, ["y"] = 4, ["param1"] = 14, ["z"] = 8, ["name"] = "stairs:slab_silver_sandstone"}, {["x"] = 6, ["y"] = 4, ["param1"] = 14, ["z"] = 9, ["name"] = "stairs:slab_silver_sandstone"}, {["x"] = 6, ["y"] = 4, ["param1"] = 14, ["z"] = 10, ["name"] = "stairs:slab_silver_sandstone"}, {["x"] = 6, ["y"] = 4, ["param1"] = 14, ["z"] = 11, ["name"] = "stairs:slab_silver_sandstone"}, {["x"] = 6, ["y"] = 4, ["param1"] = 14, ["z"] = 12, ["name"] = "stairs:slab_silver_sandstone"}, {["x"] = 6, ["y"] = 4, ["param1"] = 14, ["z"] = 13, ["name"] = "stairs:slab_silver_sandstone"}, {["x"] = 6, ["y"] = 4, ["param1"] = 14, ["z"] = 14, ["name"] = "stairs:slab_silver_sandstone"}, {["x"] = 6, ["y"] = 4, ["param1"] = 14, ["z"] = 15, ["name"] = "stairs:slab_silver_sandstone"}, {["x"] = 6, ["y"] = 4, ["param1"] = 14, ["z"] = 16, ["name"] = "stairs:slab_silver_sandstone"}, {["x"] = 6, ["y"] = 4, ["param1"] = 14, ["z"] = 17, ["name"] = "stairs:slab_silver_sandstone"}, {["x"] = 6, ["y"] = 4, ["param1"] = 14, ["z"] = 18, ["name"] = "stairs:slab_silver_sandstone"}, {["x"] = 6, ["y"] = 4, ["param1"] = 14, ["z"] = 19, ["name"] = "stairs:slab_silver_sandstone"}, {["x"] = 6, ["y"] = 4, ["param1"] = 14, ["z"] = 20, ["name"] = "stairs:slab_silver_sandstone"}, {["x"] = 6, ["y"] = 4, ["param1"] = 14, ["z"] = 21, ["name"] = "stairs:slab_silver_sandstone"}, {["x"] = 6, ["y"] = 4, ["param1"] = 14, ["z"] = 22, ["name"] = "stairs:slab_silver_sandstone"}, {["x"] = 6, ["y"] = 4, ["param1"] = 14, ["z"] = 23, ["name"] = "stairs:slab_silver_sandstone"}, {["x"] = 6, ["y"] = 4, ["param1"] = 14, ["z"] = 24, ["name"] = "stairs:slab_silver_sandstone"}, {["x"] = 6, ["y"] = 4, ["param1"] = 14, ["z"] = 25, ["name"] = "stairs:slab_silver_sandstone"}, {["x"] = 6, ["y"] = 4, ["param1"] = 14, ["z"] = 26, ["name"] = "stairs:slab_silver_sandstone"}, {["x"] = 6, ["y"] = 4, ["param1"] = 14, ["z"] = 27, ["name"] = "stairs:slab_silver_sandstone"}, {["x"] = 6, ["y"] = 4, ["param1"] = 14, ["z"] = 28, ["name"] = "stairs:slab_silver_sandstone"}, {["x"] = 6, ["y"] = 4, ["param1"] = 14, ["z"] = 29, ["name"] = "stairs:slab_silver_sandstone"}, {["x"] = 6, ["y"] = 4, ["param1"] = 14, ["z"] = 30, ["name"] = "stairs:slab_silver_sandstone"}, {["x"] = 6, ["y"] = 4, ["param1"] = 14, ["z"] = 31, ["name"] = "stairs:slab_silver_sandstone"}, {["x"] = 6, ["y"] = 4, ["param1"] = 14, ["z"] = 32, ["name"] = "stairs:slab_silver_sandstone"}, {["x"] = 6, ["y"] = 4, ["param1"] = 14, ["z"] = 33, ["name"] = "stairs:slab_silver_sandstone"}, {["x"] = 6, ["y"] = 4, ["param1"] = 14, ["z"] = 34, ["name"] = "stairs:slab_silver_sandstone"}, {["x"] = 7, ["y"] = 0, ["param1"] = 15, ["z"] = 0, ["name"] = "default:desert_sandstone_block"}, {["x"] = 7, ["y"] = 0, ["param1"] = 18, ["z"] = 1, ["name"] = "default:silver_sandstone_block"}, {["x"] = 7, ["y"] = 0, ["param1"] = 18, ["z"] = 2, ["name"] = "default:silver_sandstone_block"}, {["x"] = 7, ["y"] = 0, ["param1"] = 18, ["z"] = 3, ["name"] = "default:silver_sandstone_block"}, {["x"] = 7, ["y"] = 0, ["param1"] = 18, ["z"] = 4, ["name"] = "default:silver_sandstone_block"}, {["x"] = 7, ["y"] = 0, ["param1"] = 18, ["z"] = 5, ["name"] = "default:silver_sandstone_block"}, {["x"] = 7, ["y"] = 0, ["param1"] = 18, ["z"] = 6, ["name"] = "default:silver_sandstone_block"}, {["x"] = 7, ["y"] = 0, ["param1"] = 18, ["z"] = 7, ["name"] = "default:silver_sandstone_block"}, {["x"] = 7, ["y"] = 0, ["param1"] = 18, ["z"] = 8, ["name"] = "default:silver_sandstone_block"}, {["x"] = 7, ["y"] = 0, ["param1"] = 18, ["z"] = 9, ["name"] = "default:silver_sandstone_block"}, {["x"] = 7, ["y"] = 0, ["param1"] = 18, ["z"] = 10, ["name"] = "default:silver_sandstone_block"}, {["x"] = 7, ["y"] = 0, ["param1"] = 18, ["z"] = 11, ["name"] = "default:silver_sandstone_block"}, {["x"] = 7, ["y"] = 0, ["param1"] = 18, ["z"] = 12, ["name"] = "default:silver_sandstone_block"}, {["x"] = 7, ["y"] = 0, ["param1"] = 18, ["z"] = 13, ["name"] = "default:silver_sandstone_block"}, {["x"] = 7, ["y"] = 0, ["param1"] = 18, ["z"] = 14, ["name"] = "default:silver_sandstone_block"}, {["x"] = 7, ["y"] = 0, ["param1"] = 18, ["z"] = 15, ["name"] = "default:silver_sandstone_block"}, {["x"] = 7, ["y"] = 0, ["param1"] = 18, ["z"] = 16, ["name"] = "default:silver_sandstone_block"}, {["x"] = 7, ["y"] = 0, ["param1"] = 18, ["z"] = 17, ["name"] = "default:silver_sandstone_block"}, {["x"] = 7, ["y"] = 0, ["param1"] = 18, ["z"] = 18, ["name"] = "default:silver_sandstone_block"}, {["x"] = 7, ["y"] = 0, ["param1"] = 18, ["z"] = 19, ["name"] = "default:silver_sandstone_block"}, {["x"] = 7, ["y"] = 0, ["param1"] = 18, ["z"] = 20, ["name"] = "default:silver_sandstone_block"}, {["x"] = 7, ["y"] = 0, ["param1"] = 18, ["z"] = 21, ["name"] = "default:silver_sandstone_block"}, {["x"] = 7, ["y"] = 0, ["param1"] = 18, ["z"] = 22, ["name"] = "default:silver_sandstone_block"}, {["x"] = 7, ["y"] = 0, ["param1"] = 18, ["z"] = 23, ["name"] = "default:silver_sandstone_block"}, {["x"] = 7, ["y"] = 0, ["param1"] = 18, ["z"] = 24, ["name"] = "default:silver_sandstone_block"}, {["x"] = 7, ["y"] = 0, ["param1"] = 18, ["z"] = 25, ["name"] = "default:silver_sandstone_block"}, {["x"] = 7, ["y"] = 0, ["param1"] = 18, ["z"] = 26, ["name"] = "default:silver_sandstone_block"}, {["x"] = 7, ["y"] = 0, ["param1"] = 18, ["z"] = 27, ["name"] = "default:silver_sandstone_block"}, {["x"] = 7, ["y"] = 0, ["param1"] = 18, ["z"] = 28, ["name"] = "default:silver_sandstone_block"}, {["x"] = 7, ["y"] = 0, ["param1"] = 18, ["z"] = 29, ["name"] = "default:silver_sandstone_block"}, {["x"] = 7, ["y"] = 0, ["param1"] = 18, ["z"] = 30, ["name"] = "default:silver_sandstone_block"}, {["x"] = 7, ["y"] = 0, ["param1"] = 18, ["z"] = 31, ["name"] = "default:silver_sandstone_block"}, {["x"] = 7, ["y"] = 0, ["param1"] = 18, ["z"] = 32, ["name"] = "default:silver_sandstone_block"}, {["x"] = 7, ["y"] = 0, ["param1"] = 18, ["z"] = 33, ["name"] = "default:silver_sandstone_block"}, {["x"] = 7, ["y"] = 0, ["param1"] = 18, ["z"] = 34, ["name"] = "default:silver_sandstone_block"}, {["x"] = 7, ["y"] = 0, ["param1"] = 18, ["z"] = 35, ["name"] = "default:silver_sandstone_block"}, {["x"] = 7, ["y"] = 0, ["param1"] = 18, ["z"] = 36, ["name"] = "default:silver_sandstone_block"}, {["x"] = 7, ["y"] = 0, ["param1"] = 18, ["z"] = 37, ["name"] = "default:silver_sandstone_block"}, {["x"] = 7, ["y"] = 0, ["param1"] = 18, ["z"] = 38, ["name"] = "default:silver_sandstone_block"}, {["x"] = 7, ["y"] = 0, ["param1"] = 18, ["z"] = 39, ["name"] = "default:silver_sandstone_block"}, {["x"] = 7, ["y"] = 0, ["param1"] = 18, ["z"] = 40, ["name"] = "default:silver_sandstone_block"}, {["x"] = 7, ["y"] = 0, ["param1"] = 15, ["z"] = 41, ["name"] = "default:desert_sandstone_block"}, {["x"] = 7, ["y"] = 1, ["param1"] = 16, ["z"] = 6, ["name"] = "default:silver_sandstone"}, {["x"] = 7, ["y"] = 1, ["param1"] = 16, ["z"] = 7, ["name"] = "default:silver_sandstone"}, {["x"] = 7, ["y"] = 1, ["param1"] = 16, ["z"] = 8, ["name"] = "default:silver_sandstone"}, {["x"] = 7, ["y"] = 1, ["param1"] = 59, ["z"] = 9, ["name"] = "default:mese"}, {["x"] = 7, ["y"] = 1, ["param1"] = 16, ["z"] = 10, ["name"] = "default:silver_sandstone"}, {["x"] = 7, ["y"] = 1, ["param1"] = 16, ["z"] = 11, ["name"] = "default:silver_sandstone"}, {["x"] = 7, ["y"] = 1, ["param1"] = 59, ["z"] = 12, ["name"] = "default:mese"}, {["x"] = 7, ["y"] = 1, ["param1"] = 16, ["z"] = 13, ["name"] = "default:silver_sandstone"}, {["x"] = 7, ["y"] = 1, ["param1"] = 16, ["z"] = 14, ["name"] = "default:silver_sandstone"}, {["x"] = 7, ["y"] = 1, ["param1"] = 59, ["z"] = 15, ["name"] = "default:mese"}, {["x"] = 7, ["y"] = 1, ["param1"] = 16, ["z"] = 16, ["name"] = "default:silver_sandstone"}, {["x"] = 7, ["y"] = 1, ["param1"] = 16, ["z"] = 17, ["name"] = "default:silver_sandstone"}, {["x"] = 7, ["y"] = 1, ["param1"] = 60, ["z"] = 18, ["name"] = "default:mese"}, {["x"] = 7, ["y"] = 1, ["param1"] = 16, ["z"] = 19, ["name"] = "default:silver_sandstone"}, {["x"] = 7, ["y"] = 1, ["param1"] = 16, ["z"] = 20, ["name"] = "default:silver_sandstone"}, {["x"] = 7, ["y"] = 1, ["param1"] = 60, ["z"] = 21, ["name"] = "default:mese"}, {["x"] = 7, ["y"] = 1, ["param1"] = 16, ["z"] = 22, ["name"] = "default:silver_sandstone"}, {["x"] = 7, ["y"] = 1, ["param1"] = 16, ["z"] = 23, ["name"] = "default:silver_sandstone"}, {["x"] = 7, ["y"] = 1, ["param1"] = 60, ["z"] = 24, ["name"] = "default:mese"}, {["x"] = 7, ["y"] = 1, ["param1"] = 16, ["z"] = 25, ["name"] = "default:silver_sandstone"}, {["x"] = 7, ["y"] = 1, ["param1"] = 16, ["z"] = 26, ["name"] = "default:silver_sandstone"}, {["x"] = 7, ["y"] = 1, ["param1"] = 60, ["z"] = 27, ["name"] = "default:mese"}, {["x"] = 7, ["y"] = 1, ["param1"] = 16, ["z"] = 28, ["name"] = "default:silver_sandstone"}, {["x"] = 7, ["y"] = 1, ["param1"] = 16, ["z"] = 29, ["name"] = "default:silver_sandstone"}, {["x"] = 7, ["y"] = 1, ["param1"] = 60, ["z"] = 30, ["name"] = "default:mese"}, {["x"] = 7, ["y"] = 1, ["param1"] = 16, ["z"] = 31, ["name"] = "default:silver_sandstone"}, {["x"] = 7, ["y"] = 1, ["param1"] = 16, ["z"] = 32, ["name"] = "default:silver_sandstone"}, {["x"] = 7, ["y"] = 1, ["param1"] = 16, ["z"] = 33, ["name"] = "default:silver_sandstone"}, {["x"] = 7, ["y"] = 1, ["param1"] = 16, ["z"] = 34, ["name"] = "default:silver_sandstone"}, {["x"] = 7, ["y"] = 2, ["param1"] = 16, ["z"] = 6, ["name"] = "default:silver_sandstone"}, {["x"] = 7, ["y"] = 2, ["param1"] = 16, ["z"] = 7, ["name"] = "default:silver_sandstone"}, {["x"] = 7, ["y"] = 2, ["param1"] = 16, ["z"] = 8, ["name"] = "default:silver_sandstone"}, {["x"] = 7, ["y"] = 2, ["param1"] = 16, ["z"] = 9, ["name"] = "default:silver_sandstone"}, {["x"] = 7, ["y"] = 2, ["param1"] = 16, ["z"] = 10, ["name"] = "default:silver_sandstone"}, {["x"] = 7, ["y"] = 2, ["param1"] = 16, ["z"] = 11, ["name"] = "default:silver_sandstone"}, {["x"] = 7, ["y"] = 2, ["param1"] = 16, ["z"] = 12, ["name"] = "default:silver_sandstone"}, {["x"] = 7, ["y"] = 2, ["param1"] = 16, ["z"] = 13, ["name"] = "default:silver_sandstone"}, {["x"] = 7, ["y"] = 2, ["param1"] = 16, ["z"] = 14, ["name"] = "default:silver_sandstone"}, {["x"] = 7, ["y"] = 2, ["param1"] = 16, ["z"] = 15, ["name"] = "default:silver_sandstone"}, {["x"] = 7, ["y"] = 2, ["param1"] = 16, ["z"] = 16, ["name"] = "default:silver_sandstone"}, {["x"] = 7, ["y"] = 2, ["param1"] = 16, ["z"] = 17, ["name"] = "default:silver_sandstone"}, {["x"] = 7, ["y"] = 2, ["param1"] = 16, ["z"] = 18, ["name"] = "default:silver_sandstone"}, {["x"] = 7, ["y"] = 2, ["param1"] = 16, ["z"] = 19, ["name"] = "default:silver_sandstone"}, {["x"] = 7, ["y"] = 2, ["param1"] = 16, ["z"] = 20, ["name"] = "default:silver_sandstone"}, {["x"] = 7, ["y"] = 2, ["param1"] = 16, ["z"] = 21, ["name"] = "default:silver_sandstone"}, {["x"] = 7, ["y"] = 2, ["param1"] = 16, ["z"] = 22, ["name"] = "default:silver_sandstone"}, {["x"] = 7, ["y"] = 2, ["param1"] = 16, ["z"] = 23, ["name"] = "default:silver_sandstone"}, {["x"] = 7, ["y"] = 2, ["param1"] = 16, ["z"] = 24, ["name"] = "default:silver_sandstone"}, {["x"] = 7, ["y"] = 2, ["param1"] = 16, ["z"] = 25, ["name"] = "default:silver_sandstone"}, {["x"] = 7, ["y"] = 2, ["param1"] = 16, ["z"] = 26, ["name"] = "default:silver_sandstone"}, {["x"] = 7, ["y"] = 2, ["param1"] = 16, ["z"] = 27, ["name"] = "default:silver_sandstone"}, {["x"] = 7, ["y"] = 2, ["param1"] = 16, ["z"] = 28, ["name"] = "default:silver_sandstone"}, {["x"] = 7, ["y"] = 2, ["param1"] = 16, ["z"] = 29, ["name"] = "default:silver_sandstone"}, {["x"] = 7, ["y"] = 2, ["param1"] = 16, ["z"] = 30, ["name"] = "default:silver_sandstone"}, {["x"] = 7, ["y"] = 2, ["param1"] = 16, ["z"] = 31, ["name"] = "default:silver_sandstone"}, {["x"] = 7, ["y"] = 2, ["param1"] = 16, ["z"] = 32, ["name"] = "default:silver_sandstone"}, {["x"] = 7, ["y"] = 2, ["param1"] = 16, ["z"] = 33, ["name"] = "default:silver_sandstone"}, {["x"] = 7, ["y"] = 2, ["param1"] = 16, ["z"] = 34, ["name"] = "default:silver_sandstone"}, {["x"] = 7, ["y"] = 3, ["param1"] = 16, ["z"] = 6, ["name"] = "default:silver_sandstone"}, {["x"] = 7, ["y"] = 3, ["param1"] = 13, ["z"] = 7, ["name"] = "digilines:wire_std_10100000"}, {["x"] = 7, ["param2"] = 2, ["y"] = 3, ["param1"] = 13, ["z"] = 8, ["name"] = "mesecons_extrawires:corner_off"}, {["x"] = 7, ["y"] = 3, ["param1"] = 12, ["z"] = 9, ["name"] = "mesecons_extrawires:vertical_bottom_off"}, {["x"] = 7, ["y"] = 3, ["param1"] = 13, ["z"] = 10, ["name"] = "digilines:wire_std_10100000"}, {["x"] = 7, ["param2"] = 2, ["y"] = 3, ["param1"] = 13, ["z"] = 11, ["name"] = "mesecons_extrawires:corner_off"}, {["x"] = 7, ["y"] = 3, ["param1"] = 12, ["z"] = 12, ["name"] = "mesecons_extrawires:vertical_bottom_off"}, {["x"] = 7, ["y"] = 3, ["param1"] = 13, ["z"] = 13, ["name"] = "digilines:wire_std_10100000"}, {["x"] = 7, ["param2"] = 2, ["y"] = 3, ["param1"] = 13, ["z"] = 14, ["name"] = "mesecons_extrawires:corner_off"}, {["x"] = 7, ["y"] = 3, ["param1"] = 12, ["z"] = 15, ["name"] = "mesecons_extrawires:vertical_bottom_off"}, {["x"] = 7, ["y"] = 3, ["param1"] = 13, ["z"] = 16, ["name"] = "digilines:wire_std_10100000"}, {["x"] = 7, ["param2"] = 2, ["y"] = 3, ["param1"] = 13, ["z"] = 17, ["name"] = "mesecons_extrawires:corner_off"}, {["x"] = 7, ["y"] = 3, ["param1"] = 12, ["z"] = 18, ["name"] = "mesecons_extrawires:vertical_bottom_off"}, {["x"] = 7, ["y"] = 3, ["param1"] = 13, ["z"] = 19, ["name"] = "digilines:wire_std_10100000"}, {["x"] = 7, ["param2"] = 2, ["y"] = 3, ["param1"] = 13, ["z"] = 20, ["name"] = "mesecons_extrawires:corner_off"}, {["x"] = 7, ["y"] = 3, ["param1"] = 12, ["z"] = 21, ["name"] = "mesecons_extrawires:vertical_bottom_off"}, {["x"] = 7, ["y"] = 3, ["param1"] = 13, ["z"] = 22, ["name"] = "digilines:wire_std_10100000"}, {["x"] = 7, ["param2"] = 2, ["y"] = 3, ["param1"] = 13, ["z"] = 23, ["name"] = "mesecons_extrawires:corner_off"}, {["x"] = 7, ["y"] = 3, ["param1"] = 12, ["z"] = 24, ["name"] = "mesecons_extrawires:vertical_bottom_off"}, {["x"] = 7, ["y"] = 3, ["param1"] = 13, ["z"] = 25, ["name"] = "digilines:wire_std_10100000"}, {["x"] = 7, ["param2"] = 2, ["y"] = 3, ["param1"] = 13, ["z"] = 26, ["name"] = "mesecons_extrawires:corner_off"}, {["x"] = 7, ["y"] = 3, ["param1"] = 12, ["z"] = 27, ["name"] = "mesecons_extrawires:vertical_bottom_off"}, {["x"] = 7, ["y"] = 3, ["param1"] = 13, ["z"] = 28, ["name"] = "digilines:wire_std_10100000"}, {["x"] = 7, ["param2"] = 2, ["y"] = 3, ["param1"] = 13, ["z"] = 29, ["name"] = "mesecons_extrawires:corner_off"}, {["x"] = 7, ["y"] = 3, ["param1"] = 12, ["z"] = 30, ["name"] = "mesecons_extrawires:vertical_bottom_off"}, {["x"] = 7, ["y"] = 3, ["param1"] = 13, ["z"] = 31, ["name"] = "digilines:wire_std_10100000"}, {["x"] = 7, ["param2"] = 2, ["y"] = 3, ["param1"] = 13, ["z"] = 32, ["name"] = "mesecons_insulated:insulated_off"}, {["x"] = 7, ["y"] = 3, ["param1"] = 16, ["z"] = 34, ["name"] = "default:silver_sandstone"}, {["x"] = 7, ["y"] = 4, ["param1"] = 14, ["z"] = 6, ["name"] = "stairs:slab_silver_sandstone"}, {["x"] = 7, ["y"] = 4, ["param1"] = 14, ["z"] = 7, ["name"] = "stairs:slab_silver_sandstone"}, {["x"] = 7, ["y"] = 4, ["param1"] = 14, ["z"] = 8, ["name"] = "stairs:slab_silver_sandstone"}, {["x"] = 7, ["y"] = 4, ["z"] = 9, ["name"] = "mesecons_lightstone:lightstone_red_off"}, {["x"] = 7, ["y"] = 4, ["param1"] = 14, ["z"] = 10, ["name"] = "stairs:slab_silver_sandstone"}, {["x"] = 7, ["y"] = 4, ["param1"] = 14, ["z"] = 11, ["name"] = "stairs:slab_silver_sandstone"}, {["x"] = 7, ["y"] = 4, ["z"] = 12, ["name"] = "mesecons_lightstone:lightstone_red_off"}, {["x"] = 7, ["y"] = 4, ["param1"] = 14, ["z"] = 13, ["name"] = "stairs:slab_silver_sandstone"}, {["x"] = 7, ["y"] = 4, ["param1"] = 14, ["z"] = 14, ["name"] = "stairs:slab_silver_sandstone"}, {["x"] = 7, ["y"] = 4, ["z"] = 15, ["name"] = "mesecons_lightstone:lightstone_red_off"}, {["x"] = 7, ["y"] = 4, ["param1"] = 14, ["z"] = 16, ["name"] = "stairs:slab_silver_sandstone"}, {["x"] = 7, ["y"] = 4, ["param1"] = 14, ["z"] = 17, ["name"] = "stairs:slab_silver_sandstone"}, {["x"] = 7, ["y"] = 4, ["z"] = 18, ["name"] = "mesecons_lightstone:lightstone_red_off"}, {["x"] = 7, ["y"] = 4, ["param1"] = 14, ["z"] = 19, ["name"] = "stairs:slab_silver_sandstone"}, {["x"] = 7, ["y"] = 4, ["param1"] = 14, ["z"] = 20, ["name"] = "stairs:slab_silver_sandstone"}, {["x"] = 7, ["y"] = 4, ["z"] = 21, ["name"] = "mesecons_lightstone:lightstone_red_off"}, {["x"] = 7, ["y"] = 4, ["param1"] = 14, ["z"] = 22, ["name"] = "stairs:slab_silver_sandstone"}, {["x"] = 7, ["y"] = 4, ["param1"] = 14, ["z"] = 23, ["name"] = "stairs:slab_silver_sandstone"}, {["x"] = 7, ["y"] = 4, ["z"] = 24, ["name"] = "mesecons_lightstone:lightstone_red_off"}, {["x"] = 7, ["y"] = 4, ["param1"] = 14, ["z"] = 25, ["name"] = "stairs:slab_silver_sandstone"}, {["x"] = 7, ["y"] = 4, ["param1"] = 14, ["z"] = 26, ["name"] = "stairs:slab_silver_sandstone"}, {["x"] = 7, ["y"] = 4, ["z"] = 27, ["name"] = "mesecons_lightstone:lightstone_red_off"}, {["x"] = 7, ["y"] = 4, ["param1"] = 14, ["z"] = 28, ["name"] = "stairs:slab_silver_sandstone"}, {["x"] = 7, ["y"] = 4, ["param1"] = 14, ["z"] = 29, ["name"] = "stairs:slab_silver_sandstone"}, {["x"] = 7, ["y"] = 4, ["z"] = 30, ["name"] = "mesecons_lightstone:lightstone_red_off"}, {["x"] = 7, ["y"] = 4, ["param1"] = 14, ["z"] = 31, ["name"] = "stairs:slab_silver_sandstone"}, {["x"] = 7, ["y"] = 4, ["param1"] = 14, ["z"] = 32, ["name"] = "stairs:slab_silver_sandstone"}, {["x"] = 7, ["y"] = 4, ["param1"] = 14, ["z"] = 33, ["name"] = "stairs:slab_silver_sandstone"}, {["x"] = 7, ["y"] = 4, ["param1"] = 14, ["z"] = 34, ["name"] = "stairs:slab_silver_sandstone"}, {["x"] = 8, ["y"] = 0, ["param1"] = 15, ["z"] = 0, ["name"] = "default:desert_sandstone_block"}, {["x"] = 8, ["y"] = 0, ["param1"] = 18, ["z"] = 1, ["name"] = "default:silver_sandstone_block"}, {["x"] = 8, ["y"] = 0, ["param1"] = 18, ["z"] = 2, ["name"] = "default:silver_sandstone_block"}, {["x"] = 8, ["y"] = 0, ["param1"] = 18, ["z"] = 3, ["name"] = "default:silver_sandstone_block"}, {["x"] = 8, ["y"] = 0, ["param1"] = 18, ["z"] = 4, ["name"] = "default:silver_sandstone_block"}, {["x"] = 8, ["y"] = 0, ["param1"] = 18, ["z"] = 5, ["name"] = "default:silver_sandstone_block"}, {["x"] = 8, ["y"] = 0, ["param1"] = 18, ["z"] = 6, ["name"] = "default:silver_sandstone_block"}, {["x"] = 8, ["y"] = 0, ["param1"] = 18, ["z"] = 7, ["name"] = "default:silver_sandstone_block"}, {["x"] = 8, ["y"] = 0, ["param1"] = 18, ["z"] = 8, ["name"] = "default:silver_sandstone_block"}, {["x"] = 8, ["y"] = 0, ["param1"] = 18, ["z"] = 9, ["name"] = "default:silver_sandstone_block"}, {["x"] = 8, ["y"] = 0, ["param1"] = 18, ["z"] = 10, ["name"] = "default:silver_sandstone_block"}, {["x"] = 8, ["y"] = 0, ["param1"] = 18, ["z"] = 11, ["name"] = "default:silver_sandstone_block"}, {["x"] = 8, ["y"] = 0, ["param1"] = 18, ["z"] = 12, ["name"] = "default:silver_sandstone_block"}, {["x"] = 8, ["y"] = 0, ["param1"] = 18, ["z"] = 13, ["name"] = "default:silver_sandstone_block"}, {["x"] = 8, ["y"] = 0, ["param1"] = 18, ["z"] = 14, ["name"] = "default:silver_sandstone_block"}, {["x"] = 8, ["y"] = 0, ["param1"] = 18, ["z"] = 15, ["name"] = "default:silver_sandstone_block"}, {["x"] = 8, ["y"] = 0, ["param1"] = 18, ["z"] = 16, ["name"] = "default:silver_sandstone_block"}, {["x"] = 8, ["y"] = 0, ["param1"] = 18, ["z"] = 17, ["name"] = "default:silver_sandstone_block"}, {["x"] = 8, ["y"] = 0, ["param1"] = 18, ["z"] = 18, ["name"] = "default:silver_sandstone_block"}, {["x"] = 8, ["y"] = 0, ["param1"] = 18, ["z"] = 19, ["name"] = "default:silver_sandstone_block"}, {["x"] = 8, ["y"] = 0, ["param1"] = 18, ["z"] = 20, ["name"] = "default:silver_sandstone_block"}, {["x"] = 8, ["y"] = 0, ["param1"] = 18, ["z"] = 21, ["name"] = "default:silver_sandstone_block"}, {["x"] = 8, ["y"] = 0, ["param1"] = 18, ["z"] = 22, ["name"] = "default:silver_sandstone_block"}, {["x"] = 8, ["y"] = 0, ["param1"] = 18, ["z"] = 23, ["name"] = "default:silver_sandstone_block"}, {["x"] = 8, ["y"] = 0, ["param1"] = 18, ["z"] = 24, ["name"] = "default:silver_sandstone_block"}, {["x"] = 8, ["y"] = 0, ["param1"] = 18, ["z"] = 25, ["name"] = "default:silver_sandstone_block"}, {["x"] = 8, ["y"] = 0, ["param1"] = 18, ["z"] = 26, ["name"] = "default:silver_sandstone_block"}, {["x"] = 8, ["y"] = 0, ["param1"] = 18, ["z"] = 27, ["name"] = "default:silver_sandstone_block"}, {["x"] = 8, ["y"] = 0, ["param1"] = 18, ["z"] = 28, ["name"] = "default:silver_sandstone_block"}, {["x"] = 8, ["y"] = 0, ["param1"] = 18, ["z"] = 29, ["name"] = "default:silver_sandstone_block"}, {["x"] = 8, ["y"] = 0, ["param1"] = 18, ["z"] = 30, ["name"] = "default:silver_sandstone_block"}, {["x"] = 8, ["y"] = 0, ["param1"] = 18, ["z"] = 31, ["name"] = "default:silver_sandstone_block"}, {["x"] = 8, ["y"] = 0, ["param1"] = 18, ["z"] = 32, ["name"] = "default:silver_sandstone_block"}, {["x"] = 8, ["y"] = 0, ["param1"] = 18, ["z"] = 33, ["name"] = "default:silver_sandstone_block"}, {["x"] = 8, ["y"] = 0, ["param1"] = 18, ["z"] = 34, ["name"] = "default:silver_sandstone_block"}, {["x"] = 8, ["y"] = 0, ["param1"] = 18, ["z"] = 35, ["name"] = "default:silver_sandstone_block"}, {["x"] = 8, ["y"] = 0, ["param1"] = 18, ["z"] = 36, ["name"] = "default:silver_sandstone_block"}, {["x"] = 8, ["y"] = 0, ["param1"] = 18, ["z"] = 37, ["name"] = "default:silver_sandstone_block"}, {["x"] = 8, ["y"] = 0, ["param1"] = 18, ["z"] = 38, ["name"] = "default:silver_sandstone_block"}, {["x"] = 8, ["y"] = 0, ["param1"] = 18, ["z"] = 39, ["name"] = "default:silver_sandstone_block"}, {["x"] = 8, ["y"] = 0, ["param1"] = 18, ["z"] = 40, ["name"] = "default:silver_sandstone_block"}, {["x"] = 8, ["y"] = 0, ["param1"] = 15, ["z"] = 41, ["name"] = "default:desert_sandstone_block"}, {["x"] = 8, ["y"] = 1, ["param1"] = 16, ["z"] = 6, ["name"] = "default:silver_sandstone"}, {["x"] = 8, ["y"] = 1, ["param1"] = 16, ["z"] = 7, ["name"] = "default:silver_sandstone"}, {["x"] = 8, ["y"] = 1, ["param1"] = 16, ["z"] = 8, ["name"] = "default:silver_sandstone"}, {["x"] = 8, ["y"] = 1, ["param1"] = 59, ["z"] = 9, ["name"] = "default:mese"}, {["x"] = 8, ["y"] = 1, ["param1"] = 16, ["z"] = 10, ["name"] = "default:silver_sandstone"}, {["x"] = 8, ["y"] = 1, ["param1"] = 16, ["z"] = 11, ["name"] = "default:silver_sandstone"}, {["x"] = 8, ["y"] = 1, ["param1"] = 59, ["z"] = 12, ["name"] = "default:mese"}, {["x"] = 8, ["y"] = 1, ["param1"] = 16, ["z"] = 13, ["name"] = "default:silver_sandstone"}, {["x"] = 8, ["y"] = 1, ["param1"] = 16, ["z"] = 14, ["name"] = "default:silver_sandstone"}, {["x"] = 8, ["y"] = 1, ["param1"] = 59, ["z"] = 15, ["name"] = "default:mese"}, {["x"] = 8, ["y"] = 1, ["param1"] = 16, ["z"] = 16, ["name"] = "default:silver_sandstone"}, {["x"] = 8, ["y"] = 1, ["param1"] = 16, ["z"] = 17, ["name"] = "default:silver_sandstone"}, {["x"] = 8, ["y"] = 1, ["param1"] = 59, ["z"] = 18, ["name"] = "default:mese"}, {["x"] = 8, ["y"] = 1, ["param1"] = 16, ["z"] = 19, ["name"] = "default:silver_sandstone"}, {["x"] = 8, ["y"] = 1, ["param1"] = 16, ["z"] = 20, ["name"] = "default:silver_sandstone"}, {["x"] = 8, ["y"] = 1, ["param1"] = 59, ["z"] = 21, ["name"] = "default:mese"}, {["x"] = 8, ["y"] = 1, ["param1"] = 16, ["z"] = 22, ["name"] = "default:silver_sandstone"}, {["x"] = 8, ["y"] = 1, ["param1"] = 16, ["z"] = 23, ["name"] = "default:silver_sandstone"}, {["x"] = 8, ["y"] = 1, ["param1"] = 59, ["z"] = 24, ["name"] = "default:mese"}, {["x"] = 8, ["y"] = 1, ["param1"] = 16, ["z"] = 25, ["name"] = "default:silver_sandstone"}, {["x"] = 8, ["y"] = 1, ["param1"] = 16, ["z"] = 26, ["name"] = "default:silver_sandstone"}, {["x"] = 8, ["y"] = 1, ["param1"] = 59, ["z"] = 27, ["name"] = "default:mese"}, {["x"] = 8, ["y"] = 1, ["param1"] = 16, ["z"] = 28, ["name"] = "default:silver_sandstone"}, {["x"] = 8, ["y"] = 1, ["param1"] = 16, ["z"] = 29, ["name"] = "default:silver_sandstone"}, {["x"] = 8, ["y"] = 1, ["param1"] = 59, ["z"] = 30, ["name"] = "default:mese"}, {["x"] = 8, ["y"] = 1, ["param1"] = 16, ["z"] = 31, ["name"] = "default:silver_sandstone"}, {["x"] = 8, ["y"] = 1, ["param1"] = 16, ["z"] = 32, ["name"] = "default:silver_sandstone"}, {["x"] = 8, ["y"] = 1, ["param1"] = 45, ["z"] = 33, ["name"] = "mesecons_extrawires:vertical_bottom_off"}, {["x"] = 8, ["y"] = 1, ["param1"] = 62, ["z"] = 34, ["name"] = "default:mese"}, {["x"] = 8, ["param2"] = 2, ["y"] = 1, ["param1"] = 47, ["z"] = 35, ["name"] = "mesecons_walllever:wall_lever_off"}, {["x"] = 8, ["y"] = 2, ["param1"] = 16, ["z"] = 6, ["name"] = "default:silver_sandstone"}, {["x"] = 8, ["y"] = 2, ["param1"] = 16, ["z"] = 7, ["name"] = "default:silver_sandstone"}, {["x"] = 8, ["y"] = 2, ["param1"] = 16, ["z"] = 8, ["name"] = "default:silver_sandstone"}, {["x"] = 8, ["y"] = 2, ["param1"] = 16, ["z"] = 9, ["name"] = "default:silver_sandstone"}, {["x"] = 8, ["y"] = 2, ["param1"] = 16, ["z"] = 10, ["name"] = "default:silver_sandstone"}, {["x"] = 8, ["y"] = 2, ["param1"] = 16, ["z"] = 11, ["name"] = "default:silver_sandstone"}, {["x"] = 8, ["y"] = 2, ["param1"] = 16, ["z"] = 12, ["name"] = "default:silver_sandstone"}, {["x"] = 8, ["y"] = 2, ["param1"] = 16, ["z"] = 13, ["name"] = "default:silver_sandstone"}, {["x"] = 8, ["y"] = 2, ["param1"] = 16, ["z"] = 14, ["name"] = "default:silver_sandstone"}, {["x"] = 8, ["y"] = 2, ["param1"] = 16, ["z"] = 15, ["name"] = "default:silver_sandstone"}, {["x"] = 8, ["y"] = 2, ["param1"] = 16, ["z"] = 16, ["name"] = "default:silver_sandstone"}, {["x"] = 8, ["y"] = 2, ["param1"] = 16, ["z"] = 17, ["name"] = "default:silver_sandstone"}, {["x"] = 8, ["y"] = 2, ["param1"] = 16, ["z"] = 18, ["name"] = "default:silver_sandstone"}, {["x"] = 8, ["y"] = 2, ["param1"] = 16, ["z"] = 19, ["name"] = "default:silver_sandstone"}, {["x"] = 8, ["y"] = 2, ["param1"] = 16, ["z"] = 20, ["name"] = "default:silver_sandstone"}, {["x"] = 8, ["y"] = 2, ["param1"] = 16, ["z"] = 21, ["name"] = "default:silver_sandstone"}, {["x"] = 8, ["y"] = 2, ["param1"] = 16, ["z"] = 22, ["name"] = "default:silver_sandstone"}, {["x"] = 8, ["y"] = 2, ["param1"] = 16, ["z"] = 23, ["name"] = "default:silver_sandstone"}, {["x"] = 8, ["y"] = 2, ["param1"] = 16, ["z"] = 24, ["name"] = "default:silver_sandstone"}, {["x"] = 8, ["y"] = 2, ["param1"] = 16, ["z"] = 25, ["name"] = "default:silver_sandstone"}, {["x"] = 8, ["y"] = 2, ["param1"] = 16, ["z"] = 26, ["name"] = "default:silver_sandstone"}, {["x"] = 8, ["y"] = 2, ["param1"] = 16, ["z"] = 27, ["name"] = "default:silver_sandstone"}, {["x"] = 8, ["y"] = 2, ["param1"] = 16, ["z"] = 28, ["name"] = "default:silver_sandstone"}, {["x"] = 8, ["y"] = 2, ["param1"] = 16, ["z"] = 29, ["name"] = "default:silver_sandstone"}, {["x"] = 8, ["y"] = 2, ["param1"] = 16, ["z"] = 30, ["name"] = "default:silver_sandstone"}, {["x"] = 8, ["y"] = 2, ["param1"] = 16, ["z"] = 31, ["name"] = "default:silver_sandstone"}, {["x"] = 8, ["y"] = 2, ["param1"] = 16, ["z"] = 32, ["name"] = "default:silver_sandstone"}, {["x"] = 8, ["y"] = 2, ["param1"] = 28, ["z"] = 33, ["name"] = "mesecons_extrawires:vertical_off"}, {["x"] = 8, ["y"] = 2, ["param1"] = 16, ["z"] = 34, ["name"] = "default:silver_sandstone"}, {["x"] = 8, ["meta"] = {["fields"] = {["infotext"] = "\"RI (RAM In)\"", ["formspec"] = "field[text;;${text}]", ["text"] = "RI (RAM In)"}, ["inventory"] = {}}, ["param2"] = 5, ["y"] = 2, ["param1"] = 31, ["z"] = 35, ["name"] = "default:sign_wall_steel"}, {["x"] = 8, ["y"] = 3, ["param1"] = 16, ["z"] = 6, ["name"] = "default:silver_sandstone"}, {["x"] = 8, ["y"] = 3, ["param1"] = 13, ["z"] = 7, ["name"] = "digilines:wire_std_10100000"}, {["x"] = 8, ["param2"] = 2, ["y"] = 3, ["param1"] = 13, ["z"] = 8, ["name"] = "mesecons_insulated:insulated_off"}, {["x"] = 8, ["y"] = 3, ["param1"] = 13, ["z"] = 10, ["name"] = "digilines:wire_std_10100000"}, {["x"] = 8, ["param2"] = 2, ["y"] = 3, ["param1"] = 13, ["z"] = 11, ["name"] = "mesecons_insulated:insulated_off"}, {["x"] = 8, ["y"] = 3, ["param1"] = 13, ["z"] = 13, ["name"] = "digilines:wire_std_10100000"}, {["x"] = 8, ["param2"] = 2, ["y"] = 3, ["param1"] = 13, ["z"] = 14, ["name"] = "mesecons_insulated:insulated_off"}, {["x"] = 8, ["y"] = 3, ["param1"] = 13, ["z"] = 16, ["name"] = "digilines:wire_std_10100000"}, {["x"] = 8, ["param2"] = 2, ["y"] = 3, ["param1"] = 13, ["z"] = 17, ["name"] = "mesecons_insulated:insulated_off"}, {["x"] = 8, ["y"] = 3, ["param1"] = 13, ["z"] = 19, ["name"] = "digilines:wire_std_10100000"}, {["x"] = 8, ["param2"] = 2, ["y"] = 3, ["param1"] = 13, ["z"] = 20, ["name"] = "mesecons_insulated:insulated_off"}, {["x"] = 8, ["y"] = 3, ["param1"] = 13, ["z"] = 22, ["name"] = "digilines:wire_std_10100000"}, {["x"] = 8, ["param2"] = 2, ["y"] = 3, ["param1"] = 13, ["z"] = 23, ["name"] = "mesecons_insulated:insulated_off"}, {["x"] = 8, ["y"] = 3, ["param1"] = 13, ["z"] = 25, ["name"] = "digilines:wire_std_10100000"}, {["x"] = 8, ["param2"] = 2, ["y"] = 3, ["param1"] = 13, ["z"] = 26, ["name"] = "mesecons_insulated:insulated_off"}, {["x"] = 8, ["y"] = 3, ["param1"] = 13, ["z"] = 28, ["name"] = "digilines:wire_std_10100000"}, {["x"] = 8, ["param2"] = 2, ["y"] = 3, ["param1"] = 13, ["z"] = 29, ["name"] = "mesecons_insulated:insulated_off"}, {["x"] = 8, ["y"] = 3, ["param1"] = 13, ["z"] = 31, ["name"] = "digilines:wire_std_11100000"}, {["x"] = 8, ["meta"] = {["fields"] = {["real_portstates"] = "1", ["code"] = "if (event.type == \"program\") then\
  mem.address = 0\
end\
\
function flatten(tbl)\
  return tonumber(table.concat(tbl), 2) + 1\
end\
\
function split(str)\13  if #str>0 then return str:sub(1,1),split(str:sub(2)) end\13end\
\
if (event.type == \"on\") then\
  if (event.pin.name == \"C\") then -- MI\
    -- set address leds, get data from address in RAM and update content leds\
    digiline_send(\"mi1\", {})\
  end\
  if (event.pin.name == \"B\") then -- RI\
    -- set content leds, write content to RAM at the address specified\
    digiline_send(\"ri1\", {})\
  end\
end\
\
if (event.type == \"on\" and event.pin.name == \"A\") then\
  digiline_send(\"ro\", true)\
end\
if (event.type == \"off\" and event.pin.name == \"A\") then\
  digiline_send(\"ro\", false)\
end\
\
if (event.type == \"digiline\") then\
  if (event.channel == \"mi9\") then\
    mem.address = flatten(event.msg)\
    digiline_send(\"ram\", \"GET \" .. mem.address)\
  end\
  if (event.channel == \"ri9\") then\
    digiline_send(\"ram\", \"SET \" .. mem.address .. \" \" ..  table.concat(event.msg))\
  end\
  if (event.channel == \"ram\" and event.msg ~= \"OK\") then\
    if (event.msg) then\
      digiline_send(\"ra\", { split(event.msg) })\
    else\
      digiline_send(\"ra\", { 0, 0, 0, 0, 0, 0, 0, 0 })\
    end\
  end\
end", ["formspec"] = "size[12,10]background[-0.2,-0.25;12.4,10.75;jeija_luac_background.png]label[0.1,8.3;]textarea[0.2,0.2;12.2,9.5;code;;if (event.type == \"program\") then\
  mem.address = 0\
end\
\
function flatten(tbl)\
  return tonumber(table.concat(tbl)\\, 2) + 1\
end\
\
function split(str)\13  if #str>0 then return str:sub(1\\,1)\\,split(str:sub(2)) end\13end\
\
if (event.type == \"on\") then\
  if (event.pin.name == \"C\") then -- MI\
    -- set address leds\\, get data from address in RAM and update content leds\
    digiline_send(\"mi1\"\\, {})\
  end\
  if (event.pin.name == \"B\") then -- RI\
    -- set content leds\\, write content to RAM at the address specified\
    digiline_send(\"ri1\"\\, {})\
  end\
end\
\
if (event.type == \"on\" and event.pin.name == \"A\") then\
  digiline_send(\"ro\"\\, true)\
end\
if (event.type == \"off\" and event.pin.name == \"A\") then\
  digiline_send(\"ro\"\\, false)\
end\
\
if (event.type == \"digiline\") then\
  if (event.channel == \"mi9\") then\
    mem.address = flatten(event.msg)\
    digiline_send(\"ram\"\\, \"GET \" .. mem.address)\
  end\
  if (event.channel == \"ri9\") then\
    digiline_send(\"ram\"\\, \"SET \" .. mem.address .. \" \" ..  table.concat(event.msg))\
  end\
  if (event.channel == \"ram\" and event.msg ~= \"OK\") then\
    if (event.msg) then\
      digiline_send(\"ra\"\\, { split(event.msg) })\
    else\
      digiline_send(\"ra\"\\, { 0\\, 0\\, 0\\, 0\\, 0\\, 0\\, 0\\, 0 })\
    end\
  end\
end]image_button[4.75,8.75;2.5,1;jeija_luac_runbutton.png;program;]image_button_exit[11.72,-0.25;0.425,0.4;jeija_close_window.png;exit;]", ["lc_memory"] = "return {[\"address\"] = 1}", ["luac_id"] = "28977"}, ["inventory"] = {}}, ["y"] = 3, ["param1"] = 13, ["z"] = 32, ["name"] = "mesecons_luacontroller:luacontroller0000"}, {["x"] = 8, ["y"] = 3, ["param1"] = 13, ["z"] = 33, ["name"] = "mesecons_extrawires:vertical_top_off"}, {["x"] = 8, ["y"] = 3, ["param1"] = 16, ["z"] = 34, ["name"] = "default:silver_sandstone"}, {["x"] = 8, ["y"] = 4, ["param1"] = 14, ["z"] = 6, ["name"] = "stairs:slab_silver_sandstone"}, {["x"] = 8, ["y"] = 4, ["param1"] = 14, ["z"] = 7, ["name"] = "stairs:slab_silver_sandstone"}, {["x"] = 8, ["y"] = 4, ["param1"] = 14, ["z"] = 8, ["name"] = "stairs:slab_silver_sandstone"}, {["x"] = 8, ["y"] = 4, ["param1"] = 14, ["z"] = 9, ["name"] = "stairs:slab_silver_sandstone"}, {["x"] = 8, ["y"] = 4, ["param1"] = 14, ["z"] = 10, ["name"] = "stairs:slab_silver_sandstone"}, {["x"] = 8, ["y"] = 4, ["param1"] = 14, ["z"] = 11, ["name"] = "stairs:slab_silver_sandstone"}, {["x"] = 8, ["y"] = 4, ["param1"] = 14, ["z"] = 12, ["name"] = "stairs:slab_silver_sandstone"}, {["x"] = 8, ["y"] = 4, ["param1"] = 14, ["z"] = 13, ["name"] = "stairs:slab_silver_sandstone"}, {["x"] = 8, ["y"] = 4, ["param1"] = 14, ["z"] = 14, ["name"] = "stairs:slab_silver_sandstone"}, {["x"] = 8, ["y"] = 4, ["param1"] = 14, ["z"] = 15, ["name"] = "stairs:slab_silver_sandstone"}, {["x"] = 8, ["y"] = 4, ["param1"] = 14, ["z"] = 16, ["name"] = "stairs:slab_silver_sandstone"}, {["x"] = 8, ["y"] = 4, ["param1"] = 14, ["z"] = 17, ["name"] = "stairs:slab_silver_sandstone"}, {["x"] = 8, ["y"] = 4, ["param1"] = 14, ["z"] = 18, ["name"] = "stairs:slab_silver_sandstone"}, {["x"] = 8, ["y"] = 4, ["param1"] = 14, ["z"] = 19, ["name"] = "stairs:slab_silver_sandstone"}, {["x"] = 8, ["y"] = 4, ["param1"] = 14, ["z"] = 20, ["name"] = "stairs:slab_silver_sandstone"}, {["x"] = 8, ["y"] = 4, ["param1"] = 14, ["z"] = 21, ["name"] = "stairs:slab_silver_sandstone"}, {["x"] = 8, ["y"] = 4, ["param1"] = 14, ["z"] = 22, ["name"] = "stairs:slab_silver_sandstone"}, {["x"] = 8, ["y"] = 4, ["param1"] = 14, ["z"] = 23, ["name"] = "stairs:slab_silver_sandstone"}, {["x"] = 8, ["y"] = 4, ["param1"] = 14, ["z"] = 24, ["name"] = "stairs:slab_silver_sandstone"}, {["x"] = 8, ["y"] = 4, ["param1"] = 14, ["z"] = 25, ["name"] = "stairs:slab_silver_sandstone"}, {["x"] = 8, ["y"] = 4, ["param1"] = 14, ["z"] = 26, ["name"] = "stairs:slab_silver_sandstone"}, {["x"] = 8, ["y"] = 4, ["param1"] = 14, ["z"] = 27, ["name"] = "stairs:slab_silver_sandstone"}, {["x"] = 8, ["y"] = 4, ["param1"] = 14, ["z"] = 28, ["name"] = "stairs:slab_silver_sandstone"}, {["x"] = 8, ["y"] = 4, ["param1"] = 14, ["z"] = 29, ["name"] = "stairs:slab_silver_sandstone"}, {["x"] = 8, ["y"] = 4, ["param1"] = 14, ["z"] = 30, ["name"] = "stairs:slab_silver_sandstone"}, {["x"] = 8, ["y"] = 4, ["param1"] = 14, ["z"] = 31, ["name"] = "stairs:slab_silver_sandstone"}, {["x"] = 8, ["y"] = 4, ["param1"] = 14, ["z"] = 32, ["name"] = "stairs:slab_silver_sandstone"}, {["x"] = 8, ["y"] = 4, ["param1"] = 14, ["z"] = 33, ["name"] = "stairs:slab_silver_sandstone"}, {["x"] = 8, ["y"] = 4, ["param1"] = 14, ["z"] = 34, ["name"] = "stairs:slab_silver_sandstone"}, {["x"] = 9, ["y"] = 0, ["param1"] = 31, ["z"] = 0, ["name"] = "default:desert_sandstone_block"}, {["x"] = 9, ["y"] = 0, ["param1"] = 18, ["z"] = 1, ["name"] = "default:silver_sandstone_block"}, {["x"] = 9, ["y"] = 0, ["param1"] = 18, ["z"] = 2, ["name"] = "default:silver_sandstone_block"}, {["x"] = 9, ["y"] = 0, ["param1"] = 18, ["z"] = 3, ["name"] = "default:silver_sandstone_block"}, {["x"] = 9, ["y"] = 0, ["param1"] = 18, ["z"] = 4, ["name"] = "default:silver_sandstone_block"}, {["x"] = 9, ["y"] = 0, ["param1"] = 18, ["z"] = 5, ["name"] = "default:silver_sandstone_block"}, {["x"] = 9, ["y"] = 0, ["param1"] = 18, ["z"] = 6, ["name"] = "default:silver_sandstone_block"}, {["x"] = 9, ["y"] = 0, ["param1"] = 18, ["z"] = 7, ["name"] = "default:silver_sandstone_block"}, {["x"] = 9, ["y"] = 0, ["param1"] = 18, ["z"] = 8, ["name"] = "default:silver_sandstone_block"}, {["x"] = 9, ["y"] = 0, ["param1"] = 18, ["z"] = 9, ["name"] = "default:silver_sandstone_block"}, {["x"] = 9, ["y"] = 0, ["param1"] = 18, ["z"] = 10, ["name"] = "default:silver_sandstone_block"}, {["x"] = 9, ["y"] = 0, ["param1"] = 18, ["z"] = 11, ["name"] = "default:silver_sandstone_block"}, {["x"] = 9, ["y"] = 0, ["param1"] = 18, ["z"] = 12, ["name"] = "default:silver_sandstone_block"}, {["x"] = 9, ["y"] = 0, ["param1"] = 18, ["z"] = 13, ["name"] = "default:silver_sandstone_block"}, {["x"] = 9, ["y"] = 0, ["param1"] = 18, ["z"] = 14, ["name"] = "default:silver_sandstone_block"}, {["x"] = 9, ["y"] = 0, ["param1"] = 18, ["z"] = 15, ["name"] = "default:silver_sandstone_block"}, {["x"] = 9, ["y"] = 0, ["param1"] = 18, ["z"] = 16, ["name"] = "default:silver_sandstone_block"}, {["x"] = 9, ["y"] = 0, ["param1"] = 18, ["z"] = 17, ["name"] = "default:silver_sandstone_block"}, {["x"] = 9, ["y"] = 0, ["param1"] = 18, ["z"] = 18, ["name"] = "default:silver_sandstone_block"}, {["x"] = 9, ["y"] = 0, ["param1"] = 18, ["z"] = 19, ["name"] = "default:silver_sandstone_block"}, {["x"] = 9, ["y"] = 0, ["param1"] = 18, ["z"] = 20, ["name"] = "default:silver_sandstone_block"}, {["x"] = 9, ["y"] = 0, ["param1"] = 18, ["z"] = 21, ["name"] = "default:silver_sandstone_block"}, {["x"] = 9, ["y"] = 0, ["param1"] = 18, ["z"] = 22, ["name"] = "default:silver_sandstone_block"}, {["x"] = 9, ["y"] = 0, ["param1"] = 18, ["z"] = 23, ["name"] = "default:silver_sandstone_block"}, {["x"] = 9, ["y"] = 0, ["param1"] = 18, ["z"] = 24, ["name"] = "default:silver_sandstone_block"}, {["x"] = 9, ["y"] = 0, ["param1"] = 18, ["z"] = 25, ["name"] = "default:silver_sandstone_block"}, {["x"] = 9, ["y"] = 0, ["param1"] = 18, ["z"] = 26, ["name"] = "default:silver_sandstone_block"}, {["x"] = 9, ["y"] = 0, ["param1"] = 18, ["z"] = 27, ["name"] = "default:silver_sandstone_block"}, {["x"] = 9, ["y"] = 0, ["param1"] = 18, ["z"] = 28, ["name"] = "default:silver_sandstone_block"}, {["x"] = 9, ["y"] = 0, ["param1"] = 18, ["z"] = 29, ["name"] = "default:silver_sandstone_block"}, {["x"] = 9, ["y"] = 0, ["param1"] = 18, ["z"] = 30, ["name"] = "default:silver_sandstone_block"}, {["x"] = 9, ["y"] = 0, ["param1"] = 18, ["z"] = 31, ["name"] = "default:silver_sandstone_block"}, {["x"] = 9, ["y"] = 0, ["param1"] = 18, ["z"] = 32, ["name"] = "default:silver_sandstone_block"}, {["x"] = 9, ["y"] = 0, ["param1"] = 18, ["z"] = 33, ["name"] = "default:silver_sandstone_block"}, {["x"] = 9, ["y"] = 0, ["param1"] = 18, ["z"] = 34, ["name"] = "default:silver_sandstone_block"}, {["x"] = 9, ["y"] = 0, ["param1"] = 18, ["z"] = 35, ["name"] = "default:silver_sandstone_block"}, {["x"] = 9, ["y"] = 0, ["param1"] = 18, ["z"] = 36, ["name"] = "default:silver_sandstone_block"}, {["x"] = 9, ["y"] = 0, ["param1"] = 18, ["z"] = 37, ["name"] = "default:silver_sandstone_block"}, {["x"] = 9, ["y"] = 0, ["param1"] = 18, ["z"] = 38, ["name"] = "default:silver_sandstone_block"}, {["x"] = 9, ["y"] = 0, ["param1"] = 18, ["z"] = 39, ["name"] = "default:silver_sandstone_block"}, {["x"] = 9, ["y"] = 0, ["param1"] = 18, ["z"] = 40, ["name"] = "default:silver_sandstone_block"}, {["x"] = 9, ["y"] = 0, ["param1"] = 15, ["z"] = 41, ["name"] = "default:desert_sandstone_block"}, {["x"] = 9, ["y"] = 1, ["param1"] = 16, ["z"] = 6, ["name"] = "default:silver_sandstone"}, {["x"] = 9, ["y"] = 1, ["param1"] = 16, ["z"] = 7, ["name"] = "default:silver_sandstone"}, {["x"] = 9, ["y"] = 1, ["param1"] = 16, ["z"] = 8, ["name"] = "default:silver_sandstone"}, {["x"] = 9, ["y"] = 1, ["param1"] = 60, ["z"] = 9, ["name"] = "default:mese"}, {["x"] = 9, ["y"] = 1, ["param1"] = 16, ["z"] = 10, ["name"] = "default:silver_sandstone"}, {["x"] = 9, ["y"] = 1, ["param1"] = 16, ["z"] = 11, ["name"] = "default:silver_sandstone"}, {["x"] = 9, ["y"] = 1, ["param1"] = 60, ["z"] = 12, ["name"] = "default:mese"}, {["x"] = 9, ["y"] = 1, ["param1"] = 16, ["z"] = 13, ["name"] = "default:silver_sandstone"}, {["x"] = 9, ["y"] = 1, ["param1"] = 16, ["z"] = 14, ["name"] = "default:silver_sandstone"}, {["x"] = 9, ["y"] = 1, ["param1"] = 60, ["z"] = 15, ["name"] = "default:mese"}, {["x"] = 9, ["y"] = 1, ["param1"] = 16, ["z"] = 16, ["name"] = "default:silver_sandstone"}, {["x"] = 9, ["y"] = 1, ["param1"] = 16, ["z"] = 17, ["name"] = "default:silver_sandstone"}, {["x"] = 9, ["y"] = 1, ["param1"] = 60, ["z"] = 18, ["name"] = "default:mese"}, {["x"] = 9, ["y"] = 1, ["param1"] = 16, ["z"] = 19, ["name"] = "default:silver_sandstone"}, {["x"] = 9, ["y"] = 1, ["param1"] = 16, ["z"] = 20, ["name"] = "default:silver_sandstone"}, {["x"] = 9, ["y"] = 1, ["param1"] = 60, ["z"] = 21, ["name"] = "default:mese"}, {["x"] = 9, ["y"] = 1, ["param1"] = 16, ["z"] = 22, ["name"] = "default:silver_sandstone"}, {["x"] = 9, ["y"] = 1, ["param1"] = 16, ["z"] = 23, ["name"] = "default:silver_sandstone"}, {["x"] = 9, ["y"] = 1, ["param1"] = 60, ["z"] = 24, ["name"] = "default:mese"}, {["x"] = 9, ["y"] = 1, ["param1"] = 16, ["z"] = 25, ["name"] = "default:silver_sandstone"}, {["x"] = 9, ["y"] = 1, ["param1"] = 16, ["z"] = 26, ["name"] = "default:silver_sandstone"}, {["x"] = 9, ["y"] = 1, ["param1"] = 60, ["z"] = 27, ["name"] = "default:mese"}, {["x"] = 9, ["y"] = 1, ["param1"] = 16, ["z"] = 28, ["name"] = "default:silver_sandstone"}, {["x"] = 9, ["y"] = 1, ["param1"] = 16, ["z"] = 29, ["name"] = "default:silver_sandstone"}, {["x"] = 9, ["y"] = 1, ["param1"] = 60, ["z"] = 30, ["name"] = "default:mese"}, {["x"] = 9, ["y"] = 1, ["param1"] = 16, ["z"] = 31, ["name"] = "default:silver_sandstone"}, {["x"] = 9, ["y"] = 1, ["param1"] = 16, ["z"] = 32, ["name"] = "default:silver_sandstone"}, {["x"] = 9, ["y"] = 1, ["param1"] = 16, ["z"] = 33, ["name"] = "default:silver_sandstone"}, {["x"] = 9, ["y"] = 1, ["param1"] = 16, ["z"] = 34, ["name"] = "default:silver_sandstone"}, {["x"] = 9, ["y"] = 2, ["param1"] = 16, ["z"] = 6, ["name"] = "default:silver_sandstone"}, {["x"] = 9, ["y"] = 2, ["param1"] = 16, ["z"] = 7, ["name"] = "default:silver_sandstone"}, {["x"] = 9, ["y"] = 2, ["param1"] = 16, ["z"] = 8, ["name"] = "default:silver_sandstone"}, {["x"] = 9, ["y"] = 2, ["param1"] = 16, ["z"] = 9, ["name"] = "default:silver_sandstone"}, {["x"] = 9, ["y"] = 2, ["param1"] = 16, ["z"] = 10, ["name"] = "default:silver_sandstone"}, {["x"] = 9, ["y"] = 2, ["param1"] = 16, ["z"] = 11, ["name"] = "default:silver_sandstone"}, {["x"] = 9, ["y"] = 2, ["param1"] = 16, ["z"] = 12, ["name"] = "default:silver_sandstone"}, {["x"] = 9, ["y"] = 2, ["param1"] = 16, ["z"] = 13, ["name"] = "default:silver_sandstone"}, {["x"] = 9, ["y"] = 2, ["param1"] = 16, ["z"] = 14, ["name"] = "default:silver_sandstone"}, {["x"] = 9, ["y"] = 2, ["param1"] = 16, ["z"] = 15, ["name"] = "default:silver_sandstone"}, {["x"] = 9, ["y"] = 2, ["param1"] = 16, ["z"] = 16, ["name"] = "default:silver_sandstone"}, {["x"] = 9, ["y"] = 2, ["param1"] = 16, ["z"] = 17, ["name"] = "default:silver_sandstone"}, {["x"] = 9, ["y"] = 2, ["param1"] = 16, ["z"] = 18, ["name"] = "default:silver_sandstone"}, {["x"] = 9, ["y"] = 2, ["param1"] = 16, ["z"] = 19, ["name"] = "default:silver_sandstone"}, {["x"] = 9, ["y"] = 2, ["param1"] = 16, ["z"] = 20, ["name"] = "default:silver_sandstone"}, {["x"] = 9, ["y"] = 2, ["param1"] = 16, ["z"] = 21, ["name"] = "default:silver_sandstone"}, {["x"] = 9, ["y"] = 2, ["param1"] = 16, ["z"] = 22, ["name"] = "default:silver_sandstone"}, {["x"] = 9, ["y"] = 2, ["param1"] = 16, ["z"] = 23, ["name"] = "default:silver_sandstone"}, {["x"] = 9, ["y"] = 2, ["param1"] = 16, ["z"] = 24, ["name"] = "default:silver_sandstone"}, {["x"] = 9, ["y"] = 2, ["param1"] = 16, ["z"] = 25, ["name"] = "default:silver_sandstone"}, {["x"] = 9, ["y"] = 2, ["param1"] = 16, ["z"] = 26, ["name"] = "default:silver_sandstone"}, {["x"] = 9, ["y"] = 2, ["param1"] = 16, ["z"] = 27, ["name"] = "default:silver_sandstone"}, {["x"] = 9, ["y"] = 2, ["param1"] = 16, ["z"] = 28, ["name"] = "default:silver_sandstone"}, {["x"] = 9, ["y"] = 2, ["param1"] = 16, ["z"] = 29, ["name"] = "default:silver_sandstone"}, {["x"] = 9, ["y"] = 2, ["param1"] = 16, ["z"] = 30, ["name"] = "default:silver_sandstone"}, {["x"] = 9, ["y"] = 2, ["param1"] = 16, ["z"] = 31, ["name"] = "default:silver_sandstone"}, {["x"] = 9, ["y"] = 2, ["param1"] = 16, ["z"] = 32, ["name"] = "default:silver_sandstone"}, {["x"] = 9, ["y"] = 2, ["param1"] = 16, ["z"] = 33, ["name"] = "default:silver_sandstone"}, {["x"] = 9, ["y"] = 2, ["param1"] = 16, ["z"] = 34, ["name"] = "default:silver_sandstone"}, {["x"] = 9, ["y"] = 3, ["param1"] = 16, ["z"] = 6, ["name"] = "default:silver_sandstone"}, {["x"] = 9, ["y"] = 3, ["param1"] = 13, ["z"] = 7, ["name"] = "digilines:wire_std_01100000"}, {["x"] = 9, ["meta"] = {["fields"] = {["real_portstates"] = "1", ["code"] = "if (event.type == \"program\") then\
  mem.unit = 1\
end\
\
if (event.type == \"digiline\") then\
\
  if (event.channel == \"mi\" .. mem.unit) then\
    port.b = pin.c\
    input = pin.c and 1 or 0\
    address = event.msg\
    table.insert(address, input)\
    digiline_send(\"mi\" .. mem.unit + 1, address)\
  end\
\
  if (event.channel == \"ri\" .. mem.unit) then\
    port.a = pin.c\
    input = pin.c and 1 or 0\
    address = event.msg\
    table.insert(address, input)\
    digiline_send(\"ri\" .. mem.unit + 1, address)\
  end\
\
  if (event.channel == \"ra\" and event.msg) then\
    output = event.msg[mem.unit]\
    port.a = (output == \"1\") and true or false\
  end\
\
  if (event.channel == \"ro\" and event.msg) then\
    port.c = pin.a\
  else\
    port.c = false\
  end\
\
end", ["formspec"] = "size[12,10]background[-0.2,-0.25;12.4,10.75;jeija_luac_background.png]label[0.1,8.3;]textarea[0.2,0.2;12.2,9.5;code;;if (event.type == \"program\") then\
  mem.unit = 1\
end\
\
if (event.type == \"digiline\") then\
\
  if (event.channel == \"mi\" .. mem.unit) then\
    port.b = pin.c\
    input = pin.c and 1 or 0\
    address = event.msg\
    table.insert(address\\, input)\
    digiline_send(\"mi\" .. mem.unit + 1\\, address)\
  end\
\
  if (event.channel == \"ri\" .. mem.unit) then\
    port.a = pin.c\
    input = pin.c and 1 or 0\
    address = event.msg\
    table.insert(address\\, input)\
    digiline_send(\"ri\" .. mem.unit + 1\\, address)\
  end\
\
  if (event.channel == \"ra\" and event.msg) then\
    output = event.msg\\[mem.unit\\]\
    port.a = (output == \"1\") and true or false\
  end\
\
  if (event.channel == \"ro\" and event.msg) then\
    port.c = pin.a\
  else\
    port.c = false\
  end\
\
end]image_button[4.75,8.75;2.5,1;jeija_luac_runbutton.png;program;]image_button_exit[11.72,-0.25;0.425,0.4;jeija_close_window.png;exit;]", ["ignore_offevents"] = "return {}", ["lc_memory"] = "return {[\"unit\"] = 1}", ["luac_id"] = "3544"}, ["inventory"] = {}}, ["y"] = 3, ["param1"] = 13, ["z"] = 8, ["name"] = "mesecons_luacontroller:luacontroller0000"}, {["x"] = 9, ["y"] = 3, ["param1"] = 12, ["z"] = 9, ["name"] = "mesecons_extrawires:vertical_bottom_off"}, {["x"] = 9, ["y"] = 3, ["param1"] = 13, ["z"] = 10, ["name"] = "digilines:wire_std_01100000"}, {["x"] = 9, ["meta"] = {["fields"] = {["real_portstates"] = "1", ["code"] = "if (event.type == \"program\") then\
  mem.unit = 2\
end\
\
if (event.type == \"digiline\") then\
\
  if (event.channel == \"mi\" .. mem.unit) then\
    port.b = pin.c\
    input = pin.c and 1 or 0\
    address = event.msg\
    table.insert(address, input)\
    digiline_send(\"mi\" .. mem.unit + 1, address)\
  end\
\
  if (event.channel == \"ri\" .. mem.unit) then\
    port.a = pin.c\
    input = pin.c and 1 or 0\
    address = event.msg\
    table.insert(address, input)\
    digiline_send(\"ri\" .. mem.unit + 1, address)\
  end\
\
  if (event.channel == \"ra\" and event.msg) then\
    output = event.msg[mem.unit]\
    port.a = (output == \"1\") and true or false\
  end\
\
  if (event.channel == \"ro\" and event.msg) then\
    port.c = pin.a\
  else\
    port.c = false\
  end\
\
end", ["formspec"] = "size[12,10]background[-0.2,-0.25;12.4,10.75;jeija_luac_background.png]label[0.1,8.3;]textarea[0.2,0.2;12.2,9.5;code;;if (event.type == \"program\") then\
  mem.unit = 2\
end\
\
if (event.type == \"digiline\") then\
\
  if (event.channel == \"mi\" .. mem.unit) then\
    port.b = pin.c\
    input = pin.c and 1 or 0\
    address = event.msg\
    table.insert(address\\, input)\
    digiline_send(\"mi\" .. mem.unit + 1\\, address)\
  end\
\
  if (event.channel == \"ri\" .. mem.unit) then\
    port.a = pin.c\
    input = pin.c and 1 or 0\
    address = event.msg\
    table.insert(address\\, input)\
    digiline_send(\"ri\" .. mem.unit + 1\\, address)\
  end\
\
  if (event.channel == \"ra\" and event.msg) then\
    output = event.msg\\[mem.unit\\]\
    port.a = (output == \"1\") and true or false\
  end\
\
  if (event.channel == \"ro\" and event.msg) then\
    port.c = pin.a\
  else\
    port.c = false\
  end\
\
end]image_button[4.75,8.75;2.5,1;jeija_luac_runbutton.png;program;]image_button_exit[11.72,-0.25;0.425,0.4;jeija_close_window.png;exit;]", ["ignore_offevents"] = "return {}", ["lc_memory"] = "return {[\"unit\"] = 2}", ["luac_id"] = "24092"}, ["inventory"] = {}}, ["y"] = 3, ["param1"] = 13, ["z"] = 11, ["name"] = "mesecons_luacontroller:luacontroller0000"}, {["x"] = 9, ["y"] = 3, ["param1"] = 12, ["z"] = 12, ["name"] = "mesecons_extrawires:vertical_bottom_off"}, {["x"] = 9, ["y"] = 3, ["param1"] = 13, ["z"] = 13, ["name"] = "digilines:wire_std_01100000"}, {["x"] = 9, ["meta"] = {["fields"] = {["real_portstates"] = "1", ["code"] = "if (event.type == \"program\") then\
  mem.unit = 3\
end\
\
if (event.type == \"digiline\") then\
\
  if (event.channel == \"mi\" .. mem.unit) then\
    port.b = pin.c\
    input = pin.c and 1 or 0\
    address = event.msg\
