5:return {{["x"] = 0, ["y"] = 0, ["param1"] = 15, ["z"] = 0, ["name"] = "default:desert_sandstone_block"}, {["x"] = 0, ["y"] = 0, ["param1"] = 15, ["z"] = 1, ["name"] = "default:desert_sandstone_block"}, {["x"] = 0, ["y"] = 0, ["param1"] = 15, ["z"] = 2, ["name"] = "default:desert_sandstone_block"}, {["x"] = 0, ["y"] = 0, ["param1"] = 15, ["z"] = 3, ["name"] = "default:desert_sandstone_block"}, {["x"] = 0, ["y"] = 0, ["param1"] = 15, ["z"] = 4, ["name"] = "default:desert_sandstone_block"}, {["x"] = 0, ["y"] = 0, ["param1"] = 15, ["z"] = 5, ["name"] = "default:desert_sandstone_block"}, {["x"] = 0, ["y"] = 0, ["param1"] = 15, ["z"] = 6, ["name"] = "default:desert_sandstone_block"}, {["x"] = 0, ["y"] = 0, ["param1"] = 15, ["z"] = 7, ["name"] = "default:desert_sandstone_block"}, {["x"] = 0, ["y"] = 0, ["param1"] = 15, ["z"] = 8, ["name"] = "default:desert_sandstone_block"}, {["x"] = 0, ["y"] = 0, ["param1"] = 15, ["z"] = 9, ["name"] = "default:desert_sandstone_block"}, {["x"] = 0, ["y"] = 0, ["param1"] = 15, ["z"] = 10, ["name"] = "default:desert_sandstone_block"}, {["x"] = 0, ["y"] = 0, ["param1"] = 15, ["z"] = 11, ["name"] = "default:desert_sandstone_block"}, {["x"] = 0, ["y"] = 0, ["param1"] = 15, ["z"] = 12, ["name"] = "default:desert_sandstone_block"}, {["x"] = 0, ["y"] = 0, ["param1"] = 15, ["z"] = 13, ["name"] = "default:desert_sandstone_block"}, {["x"] = 0, ["y"] = 0, ["param1"] = 15, ["z"] = 14, ["name"] = "default:desert_sandstone_block"}, {["x"] = 0, ["y"] = 0, ["param1"] = 15, ["z"] = 15, ["name"] = "default:desert_sandstone_block"}, {["x"] = 0, ["y"] = 0, ["param1"] = 15, ["z"] = 16, ["name"] = "default:desert_sandstone_block"}, {["x"] = 0, ["y"] = 0, ["param1"] = 15, ["z"] = 17, ["name"] = "default:desert_sandstone_block"}, {["x"] = 0, ["y"] = 0, ["param1"] = 15, ["z"] = 18, ["name"] = "default:desert_sandstone_block"}, {["x"] = 0, ["y"] = 0, ["param1"] = 15, ["z"] = 19, ["name"] = "default:desert_sandstone_block"}, {["x"] = 0, ["y"] = 0, ["param1"] = 15, ["z"] = 20, ["name"] = "default:desert_sandstone_block"}, {["x"] = 0, ["y"] = 0, ["param1"] = 15, ["z"] = 21, ["name"] = "default:desert_sandstone_block"}, {["x"] = 0, ["y"] = 0, ["param1"] = 15, ["z"] = 22, ["name"] = "default:desert_sandstone_block"}, {["x"] = 0, ["y"] = 0, ["param1"] = 15, ["z"] = 23, ["name"] = "default:desert_sandstone_block"}, {["x"] = 0, ["y"] = 0, ["param1"] = 15, ["z"] = 24, ["name"] = "default:desert_sandstone_block"}, {["x"] = 0, ["y"] = 0, ["param1"] = 15, ["z"] = 25, ["name"] = "default:desert_sandstone_block"}, {["x"] = 0, ["y"] = 0, ["param1"] = 15, ["z"] = 26, ["name"] = "default:desert_sandstone_block"}, {["x"] = 0, ["y"] = 0, ["param1"] = 15, ["z"] = 27, ["name"] = "default:desert_sandstone_block"}, {["x"] = 0, ["y"] = 0, ["param1"] = 15, ["z"] = 28, ["name"] = "default:desert_sandstone_block"}, {["x"] = 0, ["y"] = 0, ["param1"] = 15, ["z"] = 29, ["name"] = "default:desert_sandstone_block"}, {["x"] = 0, ["y"] = 0, ["param1"] = 15, ["z"] = 30, ["name"] = "default:desert_sandstone_block"}, {["x"] = 0, ["y"] = 0, ["param1"] = 15, ["z"] = 31, ["name"] = "default:desert_sandstone_block"}, {["x"] = 0, ["y"] = 0, ["param1"] = 15, ["z"] = 32, ["name"] = "default:desert_sandstone_block"}, {["x"] = 0, ["y"] = 0, ["param1"] = 15, ["z"] = 33, ["name"] = "default:desert_sandstone_block"}, {["x"] = 0, ["y"] = 0, ["param1"] = 15, ["z"] = 34, ["name"] = "default:desert_sandstone_block"}, {["x"] = 0, ["y"] = 0, ["param1"] = 15, ["z"] = 35, ["name"] = "default:desert_sandstone_block"}, {["x"] = 0, ["y"] = 0, ["param1"] = 15, ["z"] = 36, ["name"] = "default:desert_sandstone_block"}, {["x"] = 0, ["y"] = 0, ["param1"] = 15, ["z"] = 37, ["name"] = "default:desert_sandstone_block"}, {["x"] = 0, ["y"] = 0, ["param1"] = 15, ["z"] = 38, ["name"] = "default:desert_sandstone_block"}, {["x"] = 0, ["y"] = 0, ["param1"] = 15, ["z"] = 39, ["name"] = "default:desert_sandstone_block"}, {["x"] = 0, ["y"] = 0, ["param1"] = 15, ["z"] = 40, ["name"] = "default:desert_sandstone_block"}, {["x"] = 0, ["y"] = 0, ["param1"] = 15, ["z"] = 41, ["name"] = "default:desert_sandstone_block"}, {["x"] = 0, ["y"] = 0, ["param1"] = 15, ["z"] = 42, ["name"] = "default:desert_sandstone_block"}, {["x"] = 0, ["y"] = 0, ["param1"] = 15, ["z"] = 43, ["name"] = "default:desert_sandstone_block"}, {["x"] = 0, ["y"] = 0, ["param1"] = 15, ["z"] = 44, ["name"] = "default:desert_sandstone_block"}, {["x"] = 0, ["y"] = 0, ["param1"] = 15, ["z"] = 45, ["name"] = "default:desert_sandstone_block"}, {["x"] = 0, ["y"] = 0, ["param1"] = 15, ["z"] = 46, ["name"] = "default:desert_sandstone_block"}, {["x"] = 0, ["y"] = 0, ["param1"] = 15, ["z"] = 47, ["name"] = "default:desert_sandstone_block"}, {["x"] = 0, ["y"] = 0, ["param1"] = 15, ["z"] = 48, ["name"] = "default:desert_sandstone_block"}, {["x"] = 0, ["y"] = 0, ["param1"] = 15, ["z"] = 49, ["name"] = "default:desert_sandstone_block"}, {["x"] = 0, ["y"] = 0, ["param1"] = 15, ["z"] = 50, ["name"] = "default:desert_sandstone_block"}, {["x"] = 1, ["y"] = 0, ["param1"] = 15, ["z"] = 0, ["name"] = "default:desert_sandstone_block"}, {["x"] = 1, ["y"] = 0, ["param1"] = 15, ["z"] = 1, ["name"] = "default:silver_sandstone_block"}, {["x"] = 1, ["y"] = 0, ["param1"] = 15, ["z"] = 2, ["name"] = "default:silver_sandstone_block"}, {["x"] = 1, ["y"] = 0, ["param1"] = 15, ["z"] = 3, ["name"] = "default:silver_sandstone_block"}, {["x"] = 1, ["y"] = 0, ["param1"] = 15, ["z"] = 4, ["name"] = "default:silver_sandstone_block"}, {["x"] = 1, ["y"] = 0, ["param1"] = 15, ["z"] = 5, ["name"] = "default:silver_sandstone_block"}, {["x"] = 1, ["y"] = 0, ["param1"] = 15, ["z"] = 6, ["name"] = "default:silver_sandstone_block"}, {["x"] = 1, ["y"] = 0, ["param1"] = 15, ["z"] = 7, ["name"] = "default:silver_sandstone_block"}, {["x"] = 1, ["y"] = 0, ["param1"] = 14, ["z"] = 8, ["name"] = "default:silver_sandstone_block"}, {["x"] = 1, ["y"] = 0, ["param1"] = 18, ["z"] = 9, ["name"] = "default:silver_sandstone_block"}, {["x"] = 1, ["y"] = 0, ["param1"] = 18, ["z"] = 10, ["name"] = "default:silver_sandstone_block"}, {["x"] = 1, ["y"] = 0, ["param1"] = 18, ["z"] = 11, ["name"] = "default:silver_sandstone_block"}, {["x"] = 1, ["y"] = 0, ["param1"] = 18, ["z"] = 12, ["name"] = "default:silver_sandstone_block"}, {["x"] = 1, ["y"] = 0, ["param1"] = 18, ["z"] = 13, ["name"] = "default:silver_sandstone_block"}, {["x"] = 1, ["y"] = 0, ["param1"] = 18, ["z"] = 14, ["name"] = "default:silver_sandstone_block"}, {["x"] = 1, ["y"] = 0, ["param1"] = 18, ["z"] = 15, ["name"] = "default:silver_sandstone_block"}, {["x"] = 1, ["y"] = 0, ["param1"] = 18, ["z"] = 16, ["name"] = "default:silver_sandstone_block"}, {["x"] = 1, ["y"] = 0, ["param1"] = 18, ["z"] = 17, ["name"] = "default:silver_sandstone_block"}, {["x"] = 1, ["y"] = 0, ["param1"] = 18, ["z"] = 18, ["name"] = "default:silver_sandstone_block"}, {["x"] = 1, ["y"] = 0, ["param1"] = 18, ["z"] = 19, ["name"] = "default:silver_sandstone_block"}, {["x"] = 1, ["y"] = 0, ["param1"] = 18, ["z"] = 20, ["name"] = "default:silver_sandstone_block"}, {["x"] = 1, ["y"] = 0, ["param1"] = 18, ["z"] = 21, ["name"] = "default:silver_sandstone_block"}, {["x"] = 1, ["y"] = 0, ["param1"] = 18, ["z"] = 22, ["name"] = "default:silver_sandstone_block"}, {["x"] = 1, ["y"] = 0, ["param1"] = 18, ["z"] = 23, ["name"] = "default:silver_sandstone_block"}, {["x"] = 1, ["y"] = 0, ["param1"] = 18, ["z"] = 24, ["name"] = "default:silver_sandstone_block"}, {["x"] = 1, ["y"] = 0, ["param1"] = 18, ["z"] = 25, ["name"] = "default:silver_sandstone_block"}, {["x"] = 1, ["y"] = 0, ["param1"] = 18, ["z"] = 26, ["name"] = "default:silver_sandstone_block"}, {["x"] = 1, ["y"] = 0, ["param1"] = 18, ["z"] = 27, ["name"] = "default:silver_sandstone_block"}, {["x"] = 1, ["y"] = 0, ["param1"] = 18, ["z"] = 28, ["name"] = "default:silver_sandstone_block"}, {["x"] = 1, ["y"] = 0, ["param1"] = 18, ["z"] = 29, ["name"] = "default:silver_sandstone_block"}, {["x"] = 1, ["y"] = 0, ["param1"] = 18, ["z"] = 30, ["name"] = "default:silver_sandstone_block"}, {["x"] = 1, ["y"] = 0, ["param1"] = 18, ["z"] = 31, ["name"] = "default:silver_sandstone_block"}, {["x"] = 1, ["y"] = 0, ["param1"] = 18, ["z"] = 32, ["name"] = "default:silver_sandstone_block"}, {["x"] = 1, ["y"] = 0, ["param1"] = 18, ["z"] = 33, ["name"] = "default:silver_sandstone_block"}, {["x"] = 1, ["y"] = 0, ["param1"] = 18, ["z"] = 34, ["name"] = "default:silver_sandstone_block"}, {["x"] = 1, ["y"] = 0, ["param1"] = 18, ["z"] = 35, ["name"] = "default:silver_sandstone_block"}, {["x"] = 1, ["y"] = 0, ["param1"] = 18, ["z"] = 36, ["name"] = "default:silver_sandstone_block"}, {["x"] = 1, ["y"] = 0, ["param1"] = 18, ["z"] = 37, ["name"] = "default:silver_sandstone_block"}, {["x"] = 1, ["y"] = 0, ["param1"] = 18, ["z"] = 38, ["name"] = "default:silver_sandstone_block"}, {["x"] = 1, ["y"] = 0, ["param1"] = 18, ["z"] = 39, ["name"] = "default:silver_sandstone_block"}, {["x"] = 1, ["y"] = 0, ["param1"] = 18, ["z"] = 40, ["name"] = "default:silver_sandstone_block"}, {["x"] = 1, ["y"] = 0, ["param1"] = 18, ["z"] = 41, ["name"] = "default:silver_sandstone_block"}, {["x"] = 1, ["y"] = 0, ["param1"] = 18, ["z"] = 42, ["name"] = "default:silver_sandstone_block"}, {["x"] = 1, ["y"] = 0, ["param1"] = 18, ["z"] = 43, ["name"] = "default:silver_sandstone_block"}, {["x"] = 1, ["y"] = 0, ["param1"] = 18, ["z"] = 44, ["name"] = "default:silver_sandstone_block"}, {["x"] = 1, ["y"] = 0, ["param1"] = 18, ["z"] = 45, ["name"] = "default:silver_sandstone_block"}, {["x"] = 1, ["y"] = 0, ["param1"] = 18, ["z"] = 46, ["name"] = "default:silver_sandstone_block"}, {["x"] = 1, ["y"] = 0, ["param1"] = 18, ["z"] = 47, ["name"] = "default:silver_sandstone_block"}, {["x"] = 1, ["y"] = 0, ["param1"] = 18, ["z"] = 48, ["name"] = "default:silver_sandstone_block"}, {["x"] = 1, ["y"] = 0, ["param1"] = 18, ["z"] = 49, ["name"] = "default:silver_sandstone_block"}, {["x"] = 1, ["y"] = 0, ["param1"] = 15, ["z"] = 50, ["name"] = "default:desert_sandstone_block"}, {["x"] = 2, ["y"] = 0, ["param1"] = 15, ["z"] = 0, ["name"] = "default:desert_sandstone_block"}, {["x"] = 2, ["y"] = 0, ["param1"] = 15, ["z"] = 1, ["name"] = "default:silver_sandstone_block"}, {["x"] = 2, ["y"] = 0, ["param1"] = 15, ["z"] = 2, ["name"] = "default:silver_sandstone_block"}, {["x"] = 2, ["y"] = 0, ["param1"] = 15, ["z"] = 3, ["name"] = "default:silver_sandstone_block"}, {["x"] = 2, ["y"] = 0, ["param1"] = 15, ["z"] = 4, ["name"] = "default:silver_sandstone_block"}, {["x"] = 2, ["y"] = 0, ["z"] = 5, ["name"] = "default:silver_sandstone_block"}, {["x"] = 2, ["y"] = 0, ["param1"] = 15, ["z"] = 6, ["name"] = "default:silver_sandstone_block"}, {["x"] = 2, ["y"] = 0, ["param1"] = 15, ["z"] = 7, ["name"] = "default:silver_sandstone_block"}, {["x"] = 2, ["y"] = 0, ["param1"] = 14, ["z"] = 8, ["name"] = "default:silver_sandstone_block"}, {["x"] = 2, ["y"] = 0, ["param1"] = 18, ["z"] = 9, ["name"] = "default:silver_sandstone_block"}, {["x"] = 2, ["y"] = 0, ["param1"] = 18, ["z"] = 10, ["name"] = "default:silver_sandstone_block"}, {["x"] = 2, ["y"] = 0, ["param1"] = 18, ["z"] = 11, ["name"] = "default:silver_sandstone_block"}, {["x"] = 2, ["y"] = 0, ["param1"] = 18, ["z"] = 12, ["name"] = "default:silver_sandstone_block"}, {["x"] = 2, ["y"] = 0, ["param1"] = 18, ["z"] = 13, ["name"] = "default:silver_sandstone_block"}, {["x"] = 2, ["y"] = 0, ["param1"] = 18, ["z"] = 14, ["name"] = "default:silver_sandstone_block"}, {["x"] = 2, ["y"] = 0, ["param1"] = 18, ["z"] = 15, ["name"] = "default:silver_sandstone_block"}, {["x"] = 2, ["y"] = 0, ["param1"] = 18, ["z"] = 16, ["name"] = "default:silver_sandstone_block"}, {["x"] = 2, ["y"] = 0, ["param1"] = 18, ["z"] = 17, ["name"] = "default:silver_sandstone_block"}, {["x"] = 2, ["y"] = 0, ["param1"] = 18, ["z"] = 18, ["name"] = "default:silver_sandstone_block"}, {["x"] = 2, ["y"] = 0, ["param1"] = 18, ["z"] = 19, ["name"] = "default:silver_sandstone_block"}, {["x"] = 2, ["y"] = 0, ["param1"] = 18, ["z"] = 20, ["name"] = "default:silver_sandstone_block"}, {["x"] = 2, ["y"] = 0, ["param1"] = 18, ["z"] = 21, ["name"] = "default:silver_sandstone_block"}, {["x"] = 2, ["y"] = 0, ["param1"] = 18, ["z"] = 22, ["name"] = "default:silver_sandstone_block"}, {["x"] = 2, ["y"] = 0, ["param1"] = 18, ["z"] = 23, ["name"] = "default:silver_sandstone_block"}, {["x"] = 2, ["y"] = 0, ["param1"] = 18, ["z"] = 24, ["name"] = "default:silver_sandstone_block"}, {["x"] = 2, ["y"] = 0, ["param1"] = 18, ["z"] = 25, ["name"] = "default:silver_sandstone_block"}, {["x"] = 2, ["y"] = 0, ["param1"] = 18, ["z"] = 26, ["name"] = "default:silver_sandstone_block"}, {["x"] = 2, ["y"] = 0, ["param1"] = 18, ["z"] = 27, ["name"] = "default:silver_sandstone_block"}, {["x"] = 2, ["y"] = 0, ["param1"] = 18, ["z"] = 28, ["name"] = "default:silver_sandstone_block"}, {["x"] = 2, ["y"] = 0, ["param1"] = 18, ["z"] = 29, ["name"] = "default:silver_sandstone_block"}, {["x"] = 2, ["y"] = 0, ["param1"] = 18, ["z"] = 30, ["name"] = "default:silver_sandstone_block"}, {["x"] = 2, ["y"] = 0, ["param1"] = 18, ["z"] = 31, ["name"] = "default:silver_sandstone_block"}, {["x"] = 2, ["y"] = 0, ["param1"] = 18, ["z"] = 32, ["name"] = "default:silver_sandstone_block"}, {["x"] = 2, ["y"] = 0, ["param1"] = 18, ["z"] = 33, ["name"] = "default:silver_sandstone_block"}, {["x"] = 2, ["y"] = 0, ["param1"] = 18, ["z"] = 34, ["name"] = "default:silver_sandstone_block"}, {["x"] = 2, ["y"] = 0, ["param1"] = 18, ["z"] = 35, ["name"] = "default:silver_sandstone_block"}, {["x"] = 2, ["y"] = 0, ["param1"] = 18, ["z"] = 36, ["name"] = "default:silver_sandstone_block"}, {["x"] = 2, ["y"] = 0, ["param1"] = 18, ["z"] = 37, ["name"] = "default:silver_sandstone_block"}, {["x"] = 2, ["y"] = 0, ["param1"] = 18, ["z"] = 38, ["name"] = "default:silver_sandstone_block"}, {["x"] = 2, ["y"] = 0, ["param1"] = 18, ["z"] = 39, ["name"] = "default:silver_sandstone_block"}, {["x"] = 2, ["y"] = 0, ["param1"] = 18, ["z"] = 40, ["name"] = "default:silver_sandstone_block"}, {["x"] = 2, ["y"] = 0, ["param1"] = 18, ["z"] = 41, ["name"] = "default:silver_sandstone_block"}, {["x"] = 2, ["y"] = 0, ["param1"] = 18, ["z"] = 42, ["name"] = "default:silver_sandstone_block"}, {["x"] = 2, ["y"] = 0, ["param1"] = 18, ["z"] = 43, ["name"] = "default:silver_sandstone_block"}, {["x"] = 2, ["y"] = 0, ["param1"] = 18, ["z"] = 44, ["name"] = "default:silver_sandstone_block"}, {["x"] = 2, ["y"] = 0, ["param1"] = 18, ["z"] = 45, ["name"] = "default:silver_sandstone_block"}, {["x"] = 2, ["y"] = 0, ["param1"] = 18, ["z"] = 46, ["name"] = "default:silver_sandstone_block"}, {["x"] = 2, ["y"] = 0, ["param1"] = 18, ["z"] = 47, ["name"] = "default:silver_sandstone_block"}, {["x"] = 2, ["y"] = 0, ["param1"] = 18, ["z"] = 48, ["name"] = "default:silver_sandstone_block"}, {["x"] = 2, ["y"] = 0, ["param1"] = 18, ["z"] = 49, ["name"] = "default:silver_sandstone_block"}, {["x"] = 2, ["y"] = 0, ["param1"] = 15, ["z"] = 50, ["name"] = "default:desert_sandstone_block"}, {["x"] = 3, ["y"] = 0, ["param1"] = 15, ["z"] = 0, ["name"] = "default:desert_sandstone_block"}, {["x"] = 3, ["y"] = 0, ["param1"] = 15, ["z"] = 1, ["name"] = "default:silver_sandstone_block"}, {["x"] = 3, ["y"] = 0, ["param1"] = 15, ["z"] = 2, ["name"] = "default:silver_sandstone_block"}, {["x"] = 3, ["y"] = 0, ["param1"] = 18, ["z"] = 3, ["name"] = "default:silver_sandstone_block"}, {["x"] = 3, ["y"] = 0, ["param1"] = 18, ["z"] = 4, ["name"] = "default:silver_sandstone_block"}, {["x"] = 3, ["y"] = 0, ["param1"] = 18, ["z"] = 5, ["name"] = "default:silver_sandstone_block"}, {["x"] = 3, ["y"] = 0, ["param1"] = 18, ["z"] = 6, ["name"] = "default:silver_sandstone_block"}, {["x"] = 3, ["y"] = 0, ["param1"] = 18, ["z"] = 7, ["name"] = "default:silver_sandstone_block"}, {["x"] = 3, ["y"] = 0, ["param1"] = 18, ["z"] = 8, ["name"] = "default:silver_sandstone_block"}, {["x"] = 3, ["y"] = 0, ["param1"] = 18, ["z"] = 9, ["name"] = "default:silver_sandstone_block"}, {["x"] = 3, ["y"] = 0, ["param1"] = 18, ["z"] = 10, ["name"] = "default:silver_sandstone_block"}, {["x"] = 3, ["y"] = 0, ["param1"] = 18, ["z"] = 11, ["name"] = "default:silver_sandstone_block"}, {["x"] = 3, ["y"] = 0, ["param1"] = 18, ["z"] = 12, ["name"] = "default:silver_sandstone_block"}, {["x"] = 3, ["y"] = 0, ["param1"] = 18, ["z"] = 13, ["name"] = "default:silver_sandstone_block"}, {["x"] = 3, ["y"] = 0, ["param1"] = 18, ["z"] = 14, ["name"] = "default:silver_sandstone_block"}, {["x"] = 3, ["y"] = 0, ["param1"] = 18, ["z"] = 15, ["name"] = "default:silver_sandstone_block"}, {["x"] = 3, ["y"] = 0, ["param1"] = 18, ["z"] = 16, ["name"] = "default:silver_sandstone_block"}, {["x"] = 3, ["y"] = 0, ["param1"] = 18, ["z"] = 17, ["name"] = "default:silver_sandstone_block"}, {["x"] = 3, ["y"] = 0, ["param1"] = 18, ["z"] = 18, ["name"] = "default:silver_sandstone_block"}, {["x"] = 3, ["y"] = 0, ["param1"] = 18, ["z"] = 19, ["name"] = "default:silver_sandstone_block"}, {["x"] = 3, ["y"] = 0, ["param1"] = 18, ["z"] = 20, ["name"] = "default:silver_sandstone_block"}, {["x"] = 3, ["y"] = 0, ["param1"] = 18, ["z"] = 21, ["name"] = "default:silver_sandstone_block"}, {["x"] = 3, ["y"] = 0, ["param1"] = 18, ["z"] = 22, ["name"] = "default:silver_sandstone_block"}, {["x"] = 3, ["y"] = 0, ["param1"] = 18, ["z"] = 23, ["name"] = "default:silver_sandstone_block"}, {["x"] = 3, ["y"] = 0, ["param1"] = 18, ["z"] = 24, ["name"] = "default:silver_sandstone_block"}, {["x"] = 3, ["y"] = 0, ["param1"] = 18, ["z"] = 25, ["name"] = "default:silver_sandstone_block"}, {["x"] = 3, ["y"] = 0, ["param1"] = 18, ["z"] = 26, ["name"] = "default:silver_sandstone_block"}, {["x"] = 3, ["y"] = 0, ["param1"] = 18, ["z"] = 27, ["name"] = "default:silver_sandstone_block"}, {["x"] = 3, ["y"] = 0, ["param1"] = 18, ["z"] = 28, ["name"] = "default:silver_sandstone_block"}, {["x"] = 3, ["y"] = 0, ["param1"] = 18, ["z"] = 29, ["name"] = "default:silver_sandstone_block"}, {["x"] = 3, ["y"] = 0, ["param1"] = 18, ["z"] = 30, ["name"] = "default:silver_sandstone_block"}, {["x"] = 3, ["y"] = 0, ["param1"] = 18, ["z"] = 31, ["name"] = "default:silver_sandstone_block"}, {["x"] = 3, ["y"] = 0, ["param1"] = 18, ["z"] = 32, ["name"] = "default:silver_sandstone_block"}, {["x"] = 3, ["y"] = 0, ["param1"] = 18, ["z"] = 33, ["name"] = "default:silver_sandstone_block"}, {["x"] = 3, ["y"] = 0, ["param1"] = 18, ["z"] = 34, ["name"] = "default:silver_sandstone_block"}, {["x"] = 3, ["y"] = 0, ["param1"] = 18, ["z"] = 35, ["name"] = "default:silver_sandstone_block"}, {["x"] = 3, ["y"] = 0, ["param1"] = 18, ["z"] = 36, ["name"] = "default:silver_sandstone_block"}, {["x"] = 3, ["y"] = 0, ["param1"] = 18, ["z"] = 37, ["name"] = "default:silver_sandstone_block"}, {["x"] = 3, ["y"] = 0, ["param1"] = 18, ["z"] = 38, ["name"] = "default:silver_sandstone_block"}, {["x"] = 3, ["y"] = 0, ["param1"] = 18, ["z"] = 39, ["name"] = "default:silver_sandstone_block"}, {["x"] = 3, ["y"] = 0, ["param1"] = 18, ["z"] = 40, ["name"] = "default:silver_sandstone_block"}, {["x"] = 3, ["y"] = 0, ["param1"] = 18, ["z"] = 41, ["name"] = "default:silver_sandstone_block"}, {["x"] = 3, ["y"] = 0, ["param1"] = 18, ["z"] = 42, ["name"] = "default:silver_sandstone_block"}, {["x"] = 3, ["y"] = 0, ["param1"] = 18, ["z"] = 43, ["name"] = "default:silver_sandstone_block"}, {["x"] = 3, ["y"] = 0, ["param1"] = 18, ["z"] = 44, ["name"] = "default:silver_sandstone_block"}, {["x"] = 3, ["y"] = 0, ["param1"] = 18, ["z"] = 45, ["name"] = "default:silver_sandstone_block"}, {["x"] = 3, ["y"] = 0, ["param1"] = 18, ["z"] = 46, ["name"] = "default:silver_sandstone_block"}, {["x"] = 3, ["y"] = 0, ["param1"] = 18, ["z"] = 47, ["name"] = "default:silver_sandstone_block"}, {["x"] = 3, ["y"] = 0, ["param1"] = 18, ["z"] = 48, ["name"] = "default:silver_sandstone_block"}, {["x"] = 3, ["y"] = 0, ["param1"] = 18, ["z"] = 49, ["name"] = "default:silver_sandstone_block"}, {["x"] = 3, ["y"] = 0, ["param1"] = 15, ["z"] = 50, ["name"] = "default:desert_sandstone_block"}, {["x"] = 4, ["y"] = 0, ["param1"] = 15, ["z"] = 0, ["name"] = "default:desert_sandstone_block"}, {["x"] = 4, ["y"] = 0, ["param1"] = 15, ["z"] = 1, ["name"] = "default:silver_sandstone_block"}, {["x"] = 4, ["y"] = 0, ["param1"] = 15, ["z"] = 2, ["name"] = "default:silver_sandstone_block"}, {["x"] = 4, ["y"] = 0, ["param1"] = 18, ["z"] = 3, ["name"] = "default:silver_sandstone_block"}, {["x"] = 4, ["y"] = 0, ["param1"] = 18, ["z"] = 4, ["name"] = "default:silver_sandstone_block"}, {["x"] = 4, ["y"] = 0, ["param1"] = 18, ["z"] = 5, ["name"] = "default:silver_sandstone_block"}, {["x"] = 4, ["y"] = 0, ["param1"] = 18, ["z"] = 6, ["name"] = "default:silver_sandstone_block"}, {["x"] = 4, ["y"] = 0, ["param1"] = 18, ["z"] = 7, ["name"] = "default:silver_sandstone_block"}, {["x"] = 4, ["y"] = 0, ["param1"] = 18, ["z"] = 8, ["name"] = "default:silver_sandstone_block"}, {["x"] = 4, ["y"] = 0, ["param1"] = 18, ["z"] = 9, ["name"] = "default:silver_sandstone_block"}, {["x"] = 4, ["y"] = 0, ["param1"] = 18, ["z"] = 10, ["name"] = "default:silver_sandstone_block"}, {["x"] = 4, ["y"] = 0, ["param1"] = 18, ["z"] = 11, ["name"] = "default:silver_sandstone_block"}, {["x"] = 4, ["y"] = 0, ["param1"] = 18, ["z"] = 12, ["name"] = "default:silver_sandstone_block"}, {["x"] = 4, ["y"] = 0, ["param1"] = 18, ["z"] = 13, ["name"] = "default:silver_sandstone_block"}, {["x"] = 4, ["y"] = 0, ["param1"] = 18, ["z"] = 14, ["name"] = "default:silver_sandstone_block"}, {["x"] = 4, ["y"] = 0, ["param1"] = 18, ["z"] = 15, ["name"] = "default:silver_sandstone_block"}, {["x"] = 4, ["y"] = 0, ["param1"] = 18, ["z"] = 16, ["name"] = "default:silver_sandstone_block"}, {["x"] = 4, ["y"] = 0, ["param1"] = 18, ["z"] = 17, ["name"] = "default:silver_sandstone_block"}, {["x"] = 4, ["y"] = 0, ["param1"] = 18, ["z"] = 18, ["name"] = "default:silver_sandstone_block"}, {["x"] = 4, ["y"] = 0, ["param1"] = 18, ["z"] = 19, ["name"] = "default:silver_sandstone_block"}, {["x"] = 4, ["y"] = 0, ["param1"] = 18, ["z"] = 20, ["name"] = "default:silver_sandstone_block"}, {["x"] = 4, ["y"] = 0, ["param1"] = 18, ["z"] = 21, ["name"] = "default:silver_sandstone_block"}, {["x"] = 4, ["y"] = 0, ["param1"] = 18, ["z"] = 22, ["name"] = "default:silver_sandstone_block"}, {["x"] = 4, ["y"] = 0, ["param1"] = 18, ["z"] = 23, ["name"] = "default:silver_sandstone_block"}, {["x"] = 4, ["y"] = 0, ["param1"] = 18, ["z"] = 24, ["name"] = "default:silver_sandstone_block"}, {["x"] = 4, ["y"] = 0, ["param1"] = 18, ["z"] = 25, ["name"] = "default:silver_sandstone_block"}, {["x"] = 4, ["y"] = 0, ["param1"] = 18, ["z"] = 26, ["name"] = "default:silver_sandstone_block"}, {["x"] = 4, ["y"] = 0, ["param1"] = 18, ["z"] = 27, ["name"] = "default:silver_sandstone_block"}, {["x"] = 4, ["y"] = 0, ["param1"] = 18, ["z"] = 28, ["name"] = "default:silver_sandstone_block"}, {["x"] = 4, ["y"] = 0, ["param1"] = 18, ["z"] = 29, ["name"] = "default:silver_sandstone_block"}, {["x"] = 4, ["y"] = 0, ["param1"] = 18, ["z"] = 30, ["name"] = "default:silver_sandstone_block"}, {["x"] = 4, ["y"] = 0, ["param1"] = 18, ["z"] = 31, ["name"] = "default:silver_sandstone_block"}, {["x"] = 4, ["y"] = 0, ["param1"] = 18, ["z"] = 32, ["name"] = "default:silver_sandstone_block"}, {["x"] = 4, ["y"] = 0, ["param1"] = 18, ["z"] = 33, ["name"] = "default:silver_sandstone_block"}, {["x"] = 4, ["y"] = 0, ["param1"] = 18, ["z"] = 34, ["name"] = "default:silver_sandstone_block"}, {["x"] = 4, ["y"] = 0, ["param1"] = 18, ["z"] = 35, ["name"] = "default:silver_sandstone_block"}, {["x"] = 4, ["y"] = 0, ["param1"] = 18, ["z"] = 36, ["name"] = "default:silver_sandstone_block"}, {["x"] = 4, ["y"] = 0, ["param1"] = 18, ["z"] = 37, ["name"] = "default:silver_sandstone_block"}, {["x"] = 4, ["y"] = 0, ["param1"] = 18, ["z"] = 38, ["name"] = "default:silver_sandstone_block"}, {["x"] = 4, ["y"] = 0, ["param1"] = 18, ["z"] = 39, ["name"] = "default:silver_sandstone_block"}, {["x"] = 4, ["y"] = 0, ["param1"] = 18, ["z"] = 40, ["name"] = "default:silver_sandstone_block"}, {["x"] = 4, ["y"] = 0, ["param1"] = 18, ["z"] = 41, ["name"] = "default:silver_sandstone_block"}, {["x"] = 4, ["y"] = 0, ["param1"] = 18, ["z"] = 42, ["name"] = "default:silver_sandstone_block"}, {["x"] = 4, ["y"] = 0, ["param1"] = 18, ["z"] = 43, ["name"] = "default:silver_sandstone_block"}, {["x"] = 4, ["y"] = 0, ["param1"] = 18, ["z"] = 44, ["name"] = "default:silver_sandstone_block"}, {["x"] = 4, ["y"] = 0, ["param1"] = 18, ["z"] = 45, ["name"] = "default:silver_sandstone_block"}, {["x"] = 4, ["y"] = 0, ["param1"] = 18, ["z"] = 46, ["name"] = "default:silver_sandstone_block"}, {["x"] = 4, ["y"] = 0, ["param1"] = 18, ["z"] = 47, ["name"] = "default:silver_sandstone_block"}, {["x"] = 4, ["y"] = 0, ["param1"] = 18, ["z"] = 48, ["name"] = "default:silver_sandstone_block"}, {["x"] = 4, ["y"] = 0, ["param1"] = 18, ["z"] = 49, ["name"] = "default:silver_sandstone_block"}, {["x"] = 4, ["y"] = 0, ["param1"] = 15, ["z"] = 50, ["name"] = "default:desert_sandstone_block"}, {["x"] = 5, ["y"] = 0, ["param1"] = 15, ["z"] = 0, ["name"] = "default:desert_sandstone_block"}, {["x"] = 5, ["y"] = 0, ["param1"] = 15, ["z"] = 1, ["name"] = "default:silver_sandstone_block"}, {["x"] = 5, ["y"] = 0, ["param1"] = 15, ["z"] = 2, ["name"] = "default:silver_sandstone_block"}, {["x"] = 5, ["y"] = 0, ["param1"] = 18, ["z"] = 3, ["name"] = "default:silver_sandstone_block"}, {["x"] = 5, ["y"] = 0, ["param1"] = 18, ["z"] = 4, ["name"] = "default:silver_sandstone_block"}, {["x"] = 5, ["y"] = 0, ["z"] = 5, ["name"] = "default:silver_sandstone_block"}, {["x"] = 5, ["y"] = 0, ["param1"] = 18, ["z"] = 6, ["name"] = "default:silver_sandstone_block"}, {["x"] = 5, ["y"] = 0, ["param1"] = 18, ["z"] = 7, ["name"] = "default:silver_sandstone_block"}, {["x"] = 5, ["y"] = 0, ["param1"] = 18, ["z"] = 8, ["name"] = "default:silver_sandstone_block"}, {["x"] = 5, ["y"] = 0, ["param1"] = 18, ["z"] = 9, ["name"] = "default:silver_sandstone_block"}, {["x"] = 5, ["y"] = 0, ["param1"] = 18, ["z"] = 10, ["name"] = "default:silver_sandstone_block"}, {["x"] = 5, ["y"] = 0, ["param1"] = 18, ["z"] = 11, ["name"] = "default:silver_sandstone_block"}, {["x"] = 5, ["y"] = 0, ["param1"] = 18, ["z"] = 12, ["name"] = "default:silver_sandstone_block"}, {["x"] = 5, ["y"] = 0, ["param1"] = 18, ["z"] = 13, ["name"] = "default:silver_sandstone_block"}, {["x"] = 5, ["y"] = 0, ["param1"] = 18, ["z"] = 14, ["name"] = "default:silver_sandstone_block"}, {["x"] = 5, ["y"] = 0, ["param1"] = 18, ["z"] = 15, ["name"] = "default:silver_sandstone_block"}, {["x"] = 5, ["y"] = 0, ["param1"] = 18, ["z"] = 16, ["name"] = "default:silver_sandstone_block"}, {["x"] = 5, ["y"] = 0, ["param1"] = 18, ["z"] = 17, ["name"] = "default:silver_sandstone_block"}, {["x"] = 5, ["y"] = 0, ["param1"] = 18, ["z"] = 18, ["name"] = "default:silver_sandstone_block"}, {["x"] = 5, ["y"] = 0, ["param1"] = 18, ["z"] = 19, ["name"] = "default:silver_sandstone_block"}, {["x"] = 5, ["y"] = 0, ["param1"] = 18, ["z"] = 20, ["name"] = "default:silver_sandstone_block"}, {["x"] = 5, ["y"] = 0, ["param1"] = 18, ["z"] = 21, ["name"] = "default:silver_sandstone_block"}, {["x"] = 5, ["y"] = 0, ["param1"] = 18, ["z"] = 22, ["name"] = "default:silver_sandstone_block"}, {["x"] = 5, ["y"] = 0, ["param1"] = 18, ["z"] = 23, ["name"] = "default:silver_sandstone_block"}, {["x"] = 5, ["y"] = 0, ["param1"] = 18, ["z"] = 24, ["name"] = "default:silver_sandstone_block"}, {["x"] = 5, ["y"] = 0, ["param1"] = 18, ["z"] = 25, ["name"] = "default:silver_sandstone_block"}, {["x"] = 5, ["y"] = 0, ["param1"] = 18, ["z"] = 26, ["name"] = "default:silver_sandstone_block"}, {["x"] = 5, ["y"] = 0, ["param1"] = 18, ["z"] = 27, ["name"] = "default:silver_sandstone_block"}, {["x"] = 5, ["y"] = 0, ["param1"] = 18, ["z"] = 28, ["name"] = "default:silver_sandstone_block"}, {["x"] = 5, ["y"] = 0, ["param1"] = 18, ["z"] = 29, ["name"] = "default:silver_sandstone_block"}, {["x"] = 5, ["y"] = 0, ["param1"] = 18, ["z"] = 30, ["name"] = "default:silver_sandstone_block"}, {["x"] = 5, ["y"] = 0, ["param1"] = 18, ["z"] = 31, ["name"] = "default:silver_sandstone_block"}, {["x"] = 5, ["y"] = 0, ["param1"] = 18, ["z"] = 32, ["name"] = "default:silver_sandstone_block"}, {["x"] = 5, ["y"] = 0, ["param1"] = 18, ["z"] = 33, ["name"] = "default:silver_sandstone_block"}, {["x"] = 5, ["y"] = 0, ["param1"] = 18, ["z"] = 34, ["name"] = "default:silver_sandstone_block"}, {["x"] = 5, ["y"] = 0, ["param1"] = 18, ["z"] = 35, ["name"] = "default:silver_sandstone_block"}, {["x"] = 5, ["y"] = 0, ["param1"] = 18, ["z"] = 36, ["name"] = "default:silver_sandstone_block"}, {["x"] = 5, ["y"] = 0, ["param1"] = 18, ["z"] = 37, ["name"] = "default:silver_sandstone_block"}, {["x"] = 5, ["y"] = 0, ["param1"] = 18, ["z"] = 38, ["name"] = "default:silver_sandstone_block"}, {["x"] = 5, ["y"] = 0, ["param1"] = 18, ["z"] = 39, ["name"] = "default:silver_sandstone_block"}, {["x"] = 5, ["y"] = 0, ["param1"] = 18, ["z"] = 40, ["name"] = "default:silver_sandstone_block"}, {["x"] = 5, ["y"] = 0, ["param1"] = 18, ["z"] = 41, ["name"] = "default:silver_sandstone_block"}, {["x"] = 5, ["y"] = 0, ["param1"] = 18, ["z"] = 42, ["name"] = "default:silver_sandstone_block"}, {["x"] = 5, ["y"] = 0, ["param1"] = 18, ["z"] = 43, ["name"] = "default:silver_sandstone_block"}, {["x"] = 5, ["y"] = 0, ["param1"] = 18, ["z"] = 44, ["name"] = "default:silver_sandstone_block"}, {["x"] = 5, ["y"] = 0, ["param1"] = 18, ["z"] = 45, ["name"] = "default:silver_sandstone_block"}, {["x"] = 5, ["y"] = 0, ["param1"] = 18, ["z"] = 46, ["name"] = "default:silver_sandstone_block"}, {["x"] = 5, ["y"] = 0, ["param1"] = 18, ["z"] = 47, ["name"] = "default:silver_sandstone_block"}, {["x"] = 5, ["y"] = 0, ["param1"] = 18, ["z"] = 48, ["name"] = "default:silver_sandstone_block"}, {["x"] = 5, ["y"] = 0, ["param1"] = 18, ["z"] = 49, ["name"] = "default:silver_sandstone_block"}, {["x"] = 5, ["y"] = 0, ["param1"] = 15, ["z"] = 50, ["name"] = "default:desert_sandstone_block"}, {["x"] = 5, ["param2"] = 2, ["y"] = 1, ["param1"] = 47, ["z"] = 40, ["name"] = "mesecons_extrawires:corner_off"}, {["x"] = 5, ["param2"] = 1, ["y"] = 1, ["param1"] = 31, ["z"] = 41, ["name"] = "mesecons_insulated:insulated_off"}, {["x"] = 5, ["param2"] = 1, ["y"] = 1, ["param1"] = 15, ["z"] = 42, ["name"] = "mesecons_insulated:insulated_off"}, {["x"] = 5, ["param2"] = 1, ["y"] = 1, ["param1"] = 15, ["z"] = 43, ["name"] = "mesecons_insulated:insulated_off"}, {["x"] = 5, ["param2"] = 1, ["y"] = 1, ["param1"] = 15, ["z"] = 44, ["name"] = "mesecons_insulated:insulated_off"}, {["x"] = 5, ["param2"] = 1, ["y"] = 1, ["param1"] = 15, ["z"] = 45, ["name"] = "mesecons_insulated:insulated_off"}, {["x"] = 5, ["param2"] = 3, ["y"] = 1, ["param1"] = 15, ["z"] = 46, ["name"] = "mesecons_extrawires:corner_off"}, {["x"] = 5, ["meta"] = {["fields"] = {["infotext"] = "\"Output 5\"", ["text"] = "Output 5", ["formspec"] = "field[text;;${text}]"}, ["inventory"] = {}}, ["param2"] = 2, ["y"] = 2, ["param1"] = 31, ["z"] = 7, ["name"] = "default:sign_wall_steel"}, {["x"] = 5, ["meta"] = {["fields"] = {["infotext"] = "\"Output 6\"", ["formspec"] = "field[text;;${text}]", ["text"] = "Output 6"}, ["inventory"] = {}}, ["param2"] = 2, ["y"] = 2, ["param1"] = 31, ["z"] = 9, ["name"] = "default:sign_wall_steel"}, {["x"] = 5, ["meta"] = {["fields"] = {["infotext"] = "\"Output 7\"", ["formspec"] = "field[text;;${text}]", ["text"] = "Output 7"}, ["inventory"] = {}}, ["param2"] = 2, ["y"] = 2, ["param1"] = 31, ["z"] = 11, ["name"] = "default:sign_wall_steel"}, {["x"] = 5, ["meta"] = {["fields"] = {["infotext"] = "\"Output 8\"", ["formspec"] = "field[text;;${text}]", ["text"] = "Output 8"}, ["inventory"] = {}}, ["param2"] = 2, ["y"] = 2, ["param1"] = 31, ["z"] = 13, ["name"] = "default:sign_wall_steel"}, {["x"] = 5, ["meta"] = {["fields"] = {["infotext"] = "\"Serial Input\"", ["text"] = "Serial Input", ["formspec"] = "field[text;;${text}]"}, ["inventory"] = {}}, ["param2"] = 2, ["y"] = 2, ["param1"] = 31, ["z"] = 40, ["name"] = "default:sign_wall_steel"}, {["x"] = 5, ["meta"] = {["fields"] = {["infotext"] = "\"Instruction Register\"", ["formspec"] = "field[text;;${text}]", ["text"] = "Instruction Register"}, ["inventory"] = {}}, ["param2"] = 2, ["y"] = 3, ["param1"] = 15, ["z"] = 10, ["name"] = "default:sign_wall_steel"}, {["x"] = 5, ["meta"] = {["fields"] = {["infotext"] = "\"8 Bit Register\"", ["text"] = "8 Bit Register", ["formspec"] = "field[text;;${text}]"}, ["inventory"] = {}}, ["param2"] = 2, ["y"] = 3, ["param1"] = 15, ["z"] = 25, ["name"] = "default:sign_wall_steel"}, {["x"] = 5, ["meta"] = {["fields"] = {["infotext"] = "\"8 Bit Shift Register\"", ["formspec"] = "field[text;;${text}]", ["text"] = "8 Bit Shift Register"}, ["inventory"] = {}}, ["param2"] = 2, ["y"] = 3, ["param1"] = 15, ["z"] = 40, ["name"] = "default:sign_wall_steel"}, {["x"] = 6, ["y"] = 0, ["param1"] = 15, ["z"] = 0, ["name"] = "default:desert_sandstone_block"}, {["x"] = 6, ["y"] = 0, ["param1"] = 15, ["z"] = 1, ["name"] = "default:silver_sandstone_block"}, {["x"] = 6, ["y"] = 0, ["param1"] = 15, ["z"] = 2, ["name"] = "default:silver_sandstone_block"}, {["x"] = 6, ["y"] = 0, ["param1"] = 18, ["z"] = 3, ["name"] = "default:silver_sandstone_block"}, {["x"] = 6, ["y"] = 0, ["param1"] = 18, ["z"] = 4, ["name"] = "default:silver_sandstone_block"}, {["x"] = 6, ["y"] = 0, ["param1"] = 18, ["z"] = 5, ["name"] = "default:silver_sandstone_block"}, {["x"] = 6, ["y"] = 0, ["param1"] = 18, ["z"] = 6, ["name"] = "default:silver_sandstone_block"}, {["x"] = 6, ["y"] = 0, ["param1"] = 18, ["z"] = 7, ["name"] = "default:silver_sandstone_block"}, {["x"] = 6, ["y"] = 0, ["param1"] = 18, ["z"] = 8, ["name"] = "default:silver_sandstone_block"}, {["x"] = 6, ["y"] = 0, ["param1"] = 18, ["z"] = 9, ["name"] = "default:silver_sandstone_block"}, {["x"] = 6, ["y"] = 0, ["param1"] = 18, ["z"] = 10, ["name"] = "default:silver_sandstone_block"}, {["x"] = 6, ["y"] = 0, ["param1"] = 18, ["z"] = 11, ["name"] = "default:silver_sandstone_block"}, {["x"] = 6, ["y"] = 0, ["param1"] = 18, ["z"] = 12, ["name"] = "default:silver_sandstone_block"}, {["x"] = 6, ["y"] = 0, ["param1"] = 18, ["z"] = 13, ["name"] = "default:silver_sandstone_block"}, {["x"] = 6, ["y"] = 0, ["param1"] = 18, ["z"] = 14, ["name"] = "default:silver_sandstone_block"}, {["x"] = 6, ["y"] = 0, ["param1"] = 18, ["z"] = 15, ["name"] = "default:silver_sandstone_block"}, {["x"] = 6, ["y"] = 0, ["param1"] = 18, ["z"] = 16, ["name"] = "default:silver_sandstone_block"}, {["x"] = 6, ["y"] = 0, ["param1"] = 18, ["z"] = 17, ["name"] = "default:silver_sandstone_block"}, {["x"] = 6, ["y"] = 0, ["param1"] = 18, ["z"] = 18, ["name"] = "default:silver_sandstone_block"}, {["x"] = 6, ["y"] = 0, ["param1"] = 18, ["z"] = 19, ["name"] = "default:silver_sandstone_block"}, {["x"] = 6, ["y"] = 0, ["param1"] = 18, ["z"] = 20, ["name"] = "default:silver_sandstone_block"}, {["x"] = 6, ["y"] = 0, ["param1"] = 18, ["z"] = 21, ["name"] = "default:silver_sandstone_block"}, {["x"] = 6, ["y"] = 0, ["param1"] = 18, ["z"] = 22, ["name"] = "default:silver_sandstone_block"}, {["x"] = 6, ["y"] = 0, ["param1"] = 18, ["z"] = 23, ["name"] = "default:silver_sandstone_block"}, {["x"] = 6, ["y"] = 0, ["param1"] = 18, ["z"] = 24, ["name"] = "default:silver_sandstone_block"}, {["x"] = 6, ["y"] = 0, ["param1"] = 18, ["z"] = 25, ["name"] = "default:silver_sandstone_block"}, {["x"] = 6, ["y"] = 0, ["param1"] = 18, ["z"] = 26, ["name"] = "default:silver_sandstone_block"}, {["x"] = 6, ["y"] = 0, ["param1"] = 18, ["z"] = 27, ["name"] = "default:silver_sandstone_block"}, {["x"] = 6, ["y"] = 0, ["param1"] = 18, ["z"] = 28, ["name"] = "default:silver_sandstone_block"}, {["x"] = 6, ["y"] = 0, ["param1"] = 18, ["z"] = 29, ["name"] = "default:silver_sandstone_block"}, {["x"] = 6, ["y"] = 0, ["param1"] = 18, ["z"] = 30, ["name"] = "default:silver_sandstone_block"}, {["x"] = 6, ["y"] = 0, ["param1"] = 18, ["z"] = 31, ["name"] = "default:silver_sandstone_block"}, {["x"] = 6, ["y"] = 0, ["param1"] = 18, ["z"] = 32, ["name"] = "default:silver_sandstone_block"}, {["x"] = 6, ["y"] = 0, ["param1"] = 18, ["z"] = 33, ["name"] = "default:silver_sandstone_block"}, {["x"] = 6, ["y"] = 0, ["param1"] = 18, ["z"] = 34, ["name"] = "default:silver_sandstone_block"}, {["x"] = 6, ["y"] = 0, ["param1"] = 18, ["z"] = 35, ["name"] = "default:silver_sandstone_block"}, {["x"] = 6, ["y"] = 0, ["param1"] = 18, ["z"] = 36, ["name"] = "default:silver_sandstone_block"}, {["x"] = 6, ["y"] = 0, ["param1"] = 18, ["z"] = 37, ["name"] = "default:silver_sandstone_block"}, {["x"] = 6, ["y"] = 0, ["param1"] = 18, ["z"] = 38, ["name"] = "default:silver_sandstone_block"}, {["x"] = 6, ["y"] = 0, ["param1"] = 18, ["z"] = 39, ["name"] = "default:silver_sandstone_block"}, {["x"] = 6, ["y"] = 0, ["param1"] = 18, ["z"] = 40, ["name"] = "default:silver_sandstone_block"}, {["x"] = 6, ["y"] = 0, ["param1"] = 18, ["z"] = 41, ["name"] = "default:silver_sandstone_block"}, {["x"] = 6, ["y"] = 0, ["param1"] = 18, ["z"] = 42, ["name"] = "default:silver_sandstone_block"}, {["x"] = 6, ["y"] = 0, ["param1"] = 18, ["z"] = 43, ["name"] = "default:silver_sandstone_block"}, {["x"] = 6, ["y"] = 0, ["param1"] = 18, ["z"] = 44, ["name"] = "default:silver_sandstone_block"}, {["x"] = 6, ["y"] = 0, ["param1"] = 18, ["z"] = 45, ["name"] = "default:silver_sandstone_block"}, {["x"] = 6, ["y"] = 0, ["param1"] = 18, ["z"] = 46, ["name"] = "default:silver_sandstone_block"}, {["x"] = 6, ["y"] = 0, ["param1"] = 18, ["z"] = 47, ["name"] = "default:silver_sandstone_block"}, {["x"] = 6, ["y"] = 0, ["param1"] = 18, ["z"] = 48, ["name"] = "default:silver_sandstone_block"}, {["x"] = 6, ["y"] = 0, ["param1"] = 18, ["z"] = 49, ["name"] = "default:silver_sandstone_block"}, {["x"] = 6, ["y"] = 0, ["param1"] = 15, ["z"] = 50, ["name"] = "default:desert_sandstone_block"}, {["x"] = 6, ["y"] = 1, ["param1"] = 16, ["z"] = 6, ["name"] = "default:silver_sandstone"}, {["x"] = 6, ["y"] = 1, ["param1"] = 62, ["z"] = 7, ["name"] = "default:mese"}, {["x"] = 6, ["y"] = 1, ["param1"] = 16, ["z"] = 8, ["name"] = "default:silver_sandstone"}, {["x"] = 6, ["y"] = 1, ["param1"] = 62, ["z"] = 9, ["name"] = "default:mese"}, {["x"] = 6, ["y"] = 1, ["param1"] = 16, ["z"] = 10, ["name"] = "default:silver_sandstone"}, {["x"] = 6, ["y"] = 1, ["param1"] = 62, ["z"] = 11, ["name"] = "default:mese"}, {["x"] = 6, ["y"] = 1, ["param1"] = 16, ["z"] = 12, ["name"] = "default:silver_sandstone"}, {["x"] = 6, ["y"] = 1, ["param1"] = 62, ["z"] = 13, ["name"] = "default:mese"}, {["x"] = 6, ["y"] = 1, ["param1"] = 16, ["z"] = 14, ["name"] = "default:silver_sandstone"}, {["x"] = 6, ["y"] = 1, ["param1"] = 16, ["z"] = 21, ["name"] = "default:silver_sandstone"}, {["x"] = 6, ["y"] = 1, ["param1"] = 16, ["z"] = 22, ["name"] = "default:silver_sandstone"}, {["x"] = 6, ["y"] = 1, ["param1"] = 16, ["z"] = 23, ["name"] = "default:silver_sandstone"}, {["x"] = 6, ["y"] = 1, ["param1"] = 16, ["z"] = 24, ["name"] = "default:silver_sandstone"}, {["x"] = 6, ["y"] = 1, ["param1"] = 16, ["z"] = 25, ["name"] = "default:silver_sandstone"}, {["x"] = 6, ["y"] = 1, ["param1"] = 16, ["z"] = 26, ["name"] = "default:silver_sandstone"}, {["x"] = 6, ["y"] = 1, ["param1"] = 16, ["z"] = 27, ["name"] = "default:silver_sandstone"}, {["x"] = 6, ["y"] = 1, ["param1"] = 16, ["z"] = 28, ["name"] = "default:silver_sandstone"}, {["x"] = 6, ["y"] = 1, ["param1"] = 16, ["z"] = 29, ["name"] = "default:silver_sandstone"}, {["x"] = 6, ["y"] = 1, ["param1"] = 16, ["z"] = 36, ["name"] = "default:silver_sandstone"}, {["x"] = 6, ["y"] = 1, ["param1"] = 16, ["z"] = 37, ["name"] = "default:silver_sandstone"}, {["x"] = 6, ["y"] = 1, ["param1"] = 16, ["z"] = 38, ["name"] = "default:silver_sandstone"}, {["x"] = 6, ["y"] = 1, ["param1"] = 16, ["z"] = 39, ["name"] = "default:silver_sandstone"}, {["x"] = 6, ["y"] = 1, ["param1"] = 62, ["z"] = 40, ["name"] = "default:mese"}, {["x"] = 6, ["y"] = 1, ["param1"] = 16, ["z"] = 41, ["name"] = "default:silver_sandstone"}, {["x"] = 6, ["y"] = 1, ["param1"] = 16, ["z"] = 42, ["name"] = "default:silver_sandstone"}, {["x"] = 6, ["y"] = 1, ["param1"] = 16, ["z"] = 43, ["name"] = "default:silver_sandstone"}, {["x"] = 6, ["y"] = 1, ["param1"] = 16, ["z"] = 44, ["name"] = "default:silver_sandstone"}, {["x"] = 6, ["param2"] = 2, ["y"] = 1, ["param1"] = 15, ["z"] = 46, ["name"] = "mesecons_insulated:insulated_off"}, {["x"] = 6, ["y"] = 2, ["param1"] = 16, ["z"] = 6, ["name"] = "default:silver_sandstone"}, {["x"] = 6, ["y"] = 2, ["param1"] = 16, ["z"] = 7, ["name"] = "default:silver_sandstone"}, {["x"] = 6, ["y"] = 2, ["param1"] = 16, ["z"] = 8, ["name"] = "default:silver_sandstone"}, {["x"] = 6, ["y"] = 2, ["param1"] = 16, ["z"] = 9, ["name"] = "default:silver_sandstone"}, {["x"] = 6, ["y"] = 2, ["param1"] = 16, ["z"] = 10, ["name"] = "default:silver_sandstone"}, {["x"] = 6, ["y"] = 2, ["param1"] = 16, ["z"] = 11, ["name"] = "default:silver_sandstone"}, {["x"] = 6, ["y"] = 2, ["param1"] = 16, ["z"] = 12, ["name"] = "default:silver_sandstone"}, {["x"] = 6, ["y"] = 2, ["param1"] = 16, ["z"] = 13, ["name"] = "default:silver_sandstone"}, {["x"] = 6, ["y"] = 2, ["param1"] = 16, ["z"] = 14, ["name"] = "default:silver_sandstone"}, {["x"] = 6, ["y"] = 2, ["param1"] = 16, ["z"] = 21, ["name"] = "default:silver_sandstone"}, {["x"] = 6, ["y"] = 2, ["param1"] = 16, ["z"] = 22, ["name"] = "default:silver_sandstone"}, {["x"] = 6, ["y"] = 2, ["param1"] = 16, ["z"] = 23, ["name"] = "default:silver_sandstone"}, {["x"] = 6, ["y"] = 2, ["param1"] = 16, ["z"] = 24, ["name"] = "default:silver_sandstone"}, {["x"] = 6, ["y"] = 2, ["param1"] = 16, ["z"] = 25, ["name"] = "default:silver_sandstone"}, {["x"] = 6, ["y"] = 2, ["param1"] = 16, ["z"] = 26, ["name"] = "default:silver_sandstone"}, {["x"] = 6, ["y"] = 2, ["param1"] = 16, ["z"] = 27, ["name"] = "default:silver_sandstone"}, {["x"] = 6, ["y"] = 2, ["param1"] = 16, ["z"] = 28, ["name"] = "default:silver_sandstone"}, {["x"] = 6, ["y"] = 2, ["param1"] = 16, ["z"] = 29, ["name"] = "default:silver_sandstone"}, {["x"] = 6, ["y"] = 2, ["param1"] = 16, ["z"] = 36, ["name"] = "default:silver_sandstone"}, {["x"] = 6, ["y"] = 2, ["param1"] = 16, ["z"] = 37, ["name"] = "default:silver_sandstone"}, {["x"] = 6, ["y"] = 2, ["param1"] = 16, ["z"] = 38, ["name"] = "default:silver_sandstone"}, {["x"] = 6, ["y"] = 2, ["param1"] = 16, ["z"] = 39, ["name"] = "default:silver_sandstone"}, {["x"] = 6, ["y"] = 2, ["param1"] = 16, ["z"] = 40, ["name"] = "default:silver_sandstone"}, {["x"] = 6, ["y"] = 2, ["param1"] = 16, ["z"] = 41, ["name"] = "default:silver_sandstone"}, {["x"] = 6, ["y"] = 2, ["param1"] = 16, ["z"] = 42, ["name"] = "default:silver_sandstone"}, {["x"] = 6, ["y"] = 2, ["param1"] = 16, ["z"] = 43, ["name"] = "default:silver_sandstone"}, {["x"] = 6, ["y"] = 2, ["param1"] = 16, ["z"] = 44, ["name"] = "default:silver_sandstone"}, {["x"] = 6, ["y"] = 3, ["param1"] = 16, ["z"] = 6, ["name"] = "default:silver_sandstone"}, {["x"] = 6, ["y"] = 3, ["param1"] = 16, ["z"] = 7, ["name"] = "default:silver_sandstone"}, {["x"] = 6, ["y"] = 3, ["param1"] = 16, ["z"] = 8, ["name"] = "default:silver_sandstone"}, {["x"] = 6, ["y"] = 3, ["param1"] = 16, ["z"] = 9, ["name"] = "default:silver_sandstone"}, {["x"] = 6, ["y"] = 3, ["param1"] = 16, ["z"] = 10, ["name"] = "default:silver_sandstone"}, {["x"] = 6, ["y"] = 3, ["param1"] = 16, ["z"] = 11, ["name"] = "default:silver_sandstone"}, {["x"] = 6, ["y"] = 3, ["param1"] = 16, ["z"] = 12, ["name"] = "default:silver_sandstone"}, {["x"] = 6, ["y"] = 3, ["param1"] = 16, ["z"] = 13, ["name"] = "default:silver_sandstone"}, {["x"] = 6, ["y"] = 3, ["param1"] = 16, ["z"] = 14, ["name"] = "default:silver_sandstone"}, {["x"] = 6, ["y"] = 3, ["param1"] = 16, ["z"] = 21, ["name"] = "default:silver_sandstone"}, {["x"] = 6, ["y"] = 3, ["param1"] = 16, ["z"] = 22, ["name"] = "default:silver_sandstone"}, {["x"] = 6, ["y"] = 3, ["param1"] = 16, ["z"] = 23, ["name"] = "default:silver_sandstone"}, {["x"] = 6, ["y"] = 3, ["param1"] = 16, ["z"] = 24, ["name"] = "default:silver_sandstone"}, {["x"] = 6, ["y"] = 3, ["param1"] = 16, ["z"] = 25, ["name"] = "default:silver_sandstone"}, {["x"] = 6, ["y"] = 3, ["param1"] = 16, ["z"] = 26, ["name"] = "default:silver_sandstone"}, {["x"] = 6, ["y"] = 3, ["param1"] = 16, ["z"] = 27, ["name"] = "default:silver_sandstone"}, {["x"] = 6, ["y"] = 3, ["param1"] = 16, ["z"] = 28, ["name"] = "default:silver_sandstone"}, {["x"] = 6, ["y"] = 3, ["param1"] = 16, ["z"] = 29, ["name"] = "default:silver_sandstone"}, {["x"] = 6, ["y"] = 3, ["param1"] = 16, ["z"] = 36, ["name"] = "default:silver_sandstone"}, {["x"] = 6, ["y"] = 3, ["param1"] = 16, ["z"] = 37, ["name"] = "default:silver_sandstone"}, {["x"] = 6, ["y"] = 3, ["param1"] = 16, ["z"] = 38, ["name"] = "default:silver_sandstone"}, {["x"] = 6, ["y"] = 3, ["param1"] = 16, ["z"] = 39, ["name"] = "default:silver_sandstone"}, {["x"] = 6, ["y"] = 3, ["param1"] = 16, ["z"] = 40, ["name"] = "default:silver_sandstone"}, {["x"] = 6, ["y"] = 3, ["param1"] = 16, ["z"] = 41, ["name"] = "default:silver_sandstone"}, {["x"] = 6, ["y"] = 3, ["param1"] = 16, ["z"] = 42, ["name"] = "default:silver_sandstone"}, {["x"] = 6, ["y"] = 3, ["param1"] = 16, ["z"] = 43, ["name"] = "default:silver_sandstone"}, {["x"] = 6, ["y"] = 3, ["param1"] = 16, ["z"] = 44, ["name"] = "default:silver_sandstone"}, {["x"] = 6, ["y"] = 4, ["param1"] = 14, ["z"] = 6, ["name"] = "stairs:slab_silver_sandstone"}, {["x"] = 6, ["y"] = 4, ["param1"] = 14, ["z"] = 7, ["name"] = "stairs:slab_silver_sandstone"}, {["x"] = 6, ["y"] = 4, ["param1"] = 14, ["z"] = 8, ["name"] = "stairs:slab_silver_sandstone"}, {["x"] = 6, ["y"] = 4, ["param1"] = 14, ["z"] = 9, ["name"] = "stairs:slab_silver_sandstone"}, {["x"] = 6, ["y"] = 4, ["param1"] = 14, ["z"] = 10, ["name"] = "stairs:slab_silver_sandstone"}, {["x"] = 6, ["y"] = 4, ["param1"] = 14, ["z"] = 11, ["name"] = "stairs:slab_silver_sandstone"}, {["x"] = 6, ["y"] = 4, ["param1"] = 14, ["z"] = 12, ["name"] = "stairs:slab_silver_sandstone"}, {["x"] = 6, ["y"] = 4, ["param1"] = 14, ["z"] = 13, ["name"] = "stairs:slab_silver_sandstone"}, {["x"] = 6, ["y"] = 4, ["param1"] = 14, ["z"] = 14, ["name"] = "stairs:slab_silver_sandstone"}, {["x"] = 6, ["y"] = 4, ["param1"] = 14, ["z"] = 21, ["name"] = "stairs:slab_silver_sandstone"}, {["x"] = 6, ["y"] = 4, ["param1"] = 14, ["z"] = 22, ["name"] = "stairs:slab_silver_sandstone"}, {["x"] = 6, ["y"] = 4, ["param1"] = 14, ["z"] = 23, ["name"] = "stairs:slab_silver_sandstone"}, {["x"] = 6, ["y"] = 4, ["param1"] = 14, ["z"] = 24, ["name"] = "stairs:slab_silver_sandstone"}, {["x"] = 6, ["y"] = 4, ["param1"] = 14, ["z"] = 25, ["name"] = "stairs:slab_silver_sandstone"}, {["x"] = 6, ["y"] = 4, ["param1"] = 14, ["z"] = 26, ["name"] = "stairs:slab_silver_sandstone"}, {["x"] = 6, ["y"] = 4, ["param1"] = 14, ["z"] = 27, ["name"] = "stairs:slab_silver_sandstone"}, {["x"] = 6, ["y"] = 4, ["param1"] = 14, ["z"] = 28, ["name"] = "stairs:slab_silver_sandstone"}, {["x"] = 6, ["y"] = 4, ["param1"] = 14, ["z"] = 29, ["name"] = "stairs:slab_silver_sandstone"}, {["x"] = 6, ["y"] = 4, ["param1"] = 14, ["z"] = 36, ["name"] = "stairs:slab_silver_sandstone"}, {["x"] = 6, ["y"] = 4, ["param1"] = 14, ["z"] = 37, ["name"] = "stairs:slab_silver_sandstone"}, {["x"] = 6, ["y"] = 4, ["param1"] = 14, ["z"] = 38, ["name"] = "stairs:slab_silver_sandstone"}, {["x"] = 6, ["y"] = 4, ["param1"] = 14, ["z"] = 39, ["name"] = "stairs:slab_silver_sandstone"}, {["x"] = 6, ["y"] = 4, ["param1"] = 14, ["z"] = 40, ["name"] = "stairs:slab_silver_sandstone"}, {["x"] = 6, ["y"] = 4, ["param1"] = 14, ["z"] = 41, ["name"] = "stairs:slab_silver_sandstone"}, {["x"] = 6, ["y"] = 4, ["param1"] = 14, ["z"] = 42, ["name"] = "stairs:slab_silver_sandstone"}, {["x"] = 6, ["y"] = 4, ["param1"] = 14, ["z"] = 43, ["name"] = "stairs:slab_silver_sandstone"}, {["x"] = 6, ["y"] = 4, ["param1"] = 14, ["z"] = 44, ["name"] = "stairs:slab_silver_sandstone"}, {["x"] = 7, ["y"] = 0, ["param1"] = 15, ["z"] = 0, ["name"] = "default:desert_sandstone_block"}, {["x"] = 7, ["y"] = 0, ["param1"] = 15, ["z"] = 1, ["name"] = "default:silver_sandstone_block"}, {["x"] = 7, ["y"] = 0, ["param1"] = 15, ["z"] = 2, ["name"] = "default:silver_sandstone_block"}, {["x"] = 7, ["y"] = 0, ["param1"] = 18, ["z"] = 3, ["name"] = "default:silver_sandstone_block"}, {["x"] = 7, ["y"] = 0, ["param1"] = 18, ["z"] = 4, ["name"] = "default:silver_sandstone_block"}, {["x"] = 7, ["y"] = 0, ["param1"] = 18, ["z"] = 5, ["name"] = "default:silver_sandstone_block"}, {["x"] = 7, ["y"] = 0, ["param1"] = 18, ["z"] = 6, ["name"] = "default:silver_sandstone_block"}, {["x"] = 7, ["y"] = 0, ["param1"] = 18, ["z"] = 7, ["name"] = "default:silver_sandstone_block"}, {["x"] = 7, ["y"] = 0, ["param1"] = 18, ["z"] = 8, ["name"] = "default:silver_sandstone_block"}, {["x"] = 7, ["y"] = 0, ["param1"] = 18, ["z"] = 9, ["name"] = "default:silver_sandstone_block"}, {["x"] = 7, ["y"] = 0, ["param1"] = 18, ["z"] = 10, ["name"] = "default:silver_sandstone_block"}, {["x"] = 7, ["y"] = 0, ["param1"] = 18, ["z"] = 11, ["name"] = "default:silver_sandstone_block"}, {["x"] = 7, ["y"] = 0, ["param1"] = 18, ["z"] = 12, ["name"] = "default:silver_sandstone_block"}, {["x"] = 7, ["y"] = 0, ["param1"] = 18, ["z"] = 13, ["name"] = "default:silver_sandstone_block"}, {["x"] = 7, ["y"] = 0, ["param1"] = 18, ["z"] = 14, ["name"] = "default:silver_sandstone_block"}, {["x"] = 7, ["y"] = 0, ["param1"] = 18, ["z"] = 15, ["name"] = "default:silver_sandstone_block"}, {["x"] = 7, ["y"] = 0, ["param1"] = 18, ["z"] = 16, ["name"] = "default:silver_sandstone_block"}, {["x"] = 7, ["y"] = 0, ["param1"] = 18, ["z"] = 17, ["name"] = "default:silver_sandstone_block"}, {["x"] = 7, ["y"] = 0, ["param1"] = 18, ["z"] = 18, ["name"] = "default:silver_sandstone_block"}, {["x"] = 7, ["y"] = 0, ["param1"] = 18, ["z"] = 19, ["name"] = "default:silver_sandstone_block"}, {["x"] = 7, ["y"] = 0, ["param1"] = 18, ["z"] = 20, ["name"] = "default:silver_sandstone_block"}, {["x"] = 7, ["y"] = 0, ["param1"] = 18, ["z"] = 21, ["name"] = "default:silver_sandstone_block"}, {["x"] = 7, ["y"] = 0, ["param1"] = 18, ["z"] = 22, ["name"] = "default:silver_sandstone_block"}, {["x"] = 7, ["y"] = 0, ["param1"] = 18, ["z"] = 23, ["name"] = "default:silver_sandstone_block"}, {["x"] = 7, ["y"] = 0, ["param1"] = 18, ["z"] = 24, ["name"] = "default:silver_sandstone_block"}, {["x"] = 7, ["y"] = 0, ["param1"] = 18, ["z"] = 25, ["name"] = "default:silver_sandstone_block"}, {["x"] = 7, ["y"] = 0, ["param1"] = 18, ["z"] = 26, ["name"] = "default:silver_sandstone_block"}, {["x"] = 7, ["y"] = 0, ["param1"] = 18, ["z"] = 27, ["name"] = "default:silver_sandstone_block"}, {["x"] = 7, ["y"] = 0, ["param1"] = 18, ["z"] = 28, ["name"] = "default:silver_sandstone_block"}, {["x"] = 7, ["y"] = 0, ["param1"] = 18, ["z"] = 29, ["name"] = "default:silver_sandstone_block"}, {["x"] = 7, ["y"] = 0, ["param1"] = 18, ["z"] = 30, ["name"] = "default:silver_sandstone_block"}, {["x"] = 7, ["y"] = 0, ["param1"] = 18, ["z"] = 31, ["name"] = "default:silver_sandstone_block"}, {["x"] = 7, ["y"] = 0, ["param1"] = 18, ["z"] = 32, ["name"] = "default:silver_sandstone_block"}, {["x"] = 7, ["y"] = 0, ["param1"] = 18, ["z"] = 33, ["name"] = "default:silver_sandstone_block"}, {["x"] = 7, ["y"] = 0, ["param1"] = 18, ["z"] = 34, ["name"] = "default:silver_sandstone_block"}, {["x"] = 7, ["y"] = 0, ["param1"] = 18, ["z"] = 35, ["name"] = "default:silver_sandstone_block"}, {["x"] = 7, ["y"] = 0, ["param1"] = 18, ["z"] = 36, ["name"] = "default:silver_sandstone_block"}, {["x"] = 7, ["y"] = 0, ["param1"] = 18, ["z"] = 37, ["name"] = "default:silver_sandstone_block"}, {["x"] = 7, ["y"] = 0, ["param1"] = 18, ["z"] = 38, ["name"] = "default:silver_sandstone_block"}, {["x"] = 7, ["y"] = 0, ["param1"] = 18, ["z"] = 39, ["name"] = "default:silver_sandstone_block"}, {["x"] = 7, ["y"] = 0, ["param1"] = 18, ["z"] = 40, ["name"] = "default:silver_sandstone_block"}, {["x"] = 7, ["y"] = 0, ["param1"] = 18, ["z"] = 41, ["name"] = "default:silver_sandstone_block"}, {["x"] = 7, ["y"] = 0, ["param1"] = 18, ["z"] = 42, ["name"] = "default:silver_sandstone_block"}, {["x"] = 7, ["y"] = 0, ["param1"] = 18, ["z"] = 43, ["name"] = "default:silver_sandstone_block"}, {["x"] = 7, ["y"] = 0, ["param1"] = 18, ["z"] = 44, ["name"] = "default:silver_sandstone_block"}, {["x"] = 7, ["y"] = 0, ["param1"] = 18, ["z"] = 45, ["name"] = "default:silver_sandstone_block"}, {["x"] = 7, ["y"] = 0, ["param1"] = 18, ["z"] = 46, ["name"] = "default:silver_sandstone_block"}, {["x"] = 7, ["y"] = 0, ["param1"] = 18, ["z"] = 47, ["name"] = "default:silver_sandstone_block"}, {["x"] = 7, ["y"] = 0, ["param1"] = 18, ["z"] = 48, ["name"] = "default:silver_sandstone_block"}, {["x"] = 7, ["y"] = 0, ["param1"] = 18, ["z"] = 49, ["name"] = "default:silver_sandstone_block"}, {["x"] = 7, ["y"] = 0, ["param1"] = 15, ["z"] = 50, ["name"] = "default:desert_sandstone_block"}, {["x"] = 7, ["y"] = 1, ["z"] = 6, ["name"] = "default:silver_sandstone"}, {["x"] = 7, ["param2"] = 2, ["y"] = 1, ["param1"] = 45, ["z"] = 7, ["name"] = "mesecons_insulated:insulated_off"}, {["x"] = 7, ["y"] = 1, ["param1"] = 45, ["z"] = 9, ["name"] = "mesecons_insulated:insulated_off"}, {["x"] = 7, ["y"] = 1, ["param1"] = 45, ["z"] = 11, ["name"] = "mesecons_insulated:insulated_off"}, {["x"] = 7, ["y"] = 1, ["param1"] = 45, ["z"] = 13, ["name"] = "mesecons_insulated:insulated_off"}, {["x"] = 7, ["y"] = 1, ["param1"] = 16, ["z"] = 14, ["name"] = "default:silver_sandstone"}, {["x"] = 7, ["y"] = 1, ["param1"] = 16, ["z"] = 21, ["name"] = "default:silver_sandstone"}, {["x"] = 7, ["y"] = 1, ["param1"] = 16, ["z"] = 22, ["name"] = "default:silver_sandstone"}, {["x"] = 7, ["y"] = 1, ["param1"] = 16, ["z"] = 23, ["name"] = "default:silver_sandstone"}, {["x"] = 7, ["y"] = 1, ["param1"] = 16, ["z"] = 24, ["name"] = "default:silver_sandstone"}, {["x"] = 7, ["y"] = 1, ["param1"] = 16, ["z"] = 25, ["name"] = "default:silver_sandstone"}, {["x"] = 7, ["y"] = 1, ["param1"] = 16, ["z"] = 26, ["name"] = "default:silver_sandstone"}, {["x"] = 7, ["y"] = 1, ["param1"] = 16, ["z"] = 27, ["name"] = "default:silver_sandstone"}, {["x"] = 7, ["y"] = 1, ["param1"] = 16, ["z"] = 28, ["name"] = "default:silver_sandstone"}, {["x"] = 7, ["y"] = 1, ["param1"] = 16, ["z"] = 29, ["name"] = "default:silver_sandstone"}, {["x"] = 7, ["y"] = 1, ["param1"] = 16, ["z"] = 36, ["name"] = "default:silver_sandstone"}, {["x"] = 7, ["y"] = 1, ["param1"] = 16, ["z"] = 37, ["name"] = "default:silver_sandstone"}, {["x"] = 7, ["y"] = 1, ["param1"] = 16, ["z"] = 38, ["name"] = "default:silver_sandstone"}, {["x"] = 7, ["y"] = 1, ["param1"] = 16, ["z"] = 39, ["name"] = "default:silver_sandstone"}, {["x"] = 7, ["y"] = 1, ["param1"] = 61, ["z"] = 40, ["name"] = "default:mese"}, {["x"] = 7, ["y"] = 1, ["param1"] = 44, ["z"] = 41, ["name"] = "mesecons_extrawires:vertical_bottom_off"}, {["x"] = 7, ["y"] = 1, ["param1"] = 16, ["z"] = 42, ["name"] = "default:silver_sandstone"}, {["x"] = 7, ["y"] = 1, ["param1"] = 16, ["z"] = 43, ["name"] = "default:silver_sandstone"}, {["x"] = 7, ["y"] = 1, ["param1"] = 16, ["z"] = 44, ["name"] = "default:silver_sandstone"}, {["x"] = 7, ["param2"] = 2, ["y"] = 1, ["param1"] = 15, ["z"] = 46, ["name"] = "mesecons_insulated:insulated_off"}, {["x"] = 7, ["y"] = 2, ["z"] = 6, ["name"] = "default:silver_sandstone"}, {["x"] = 7, ["y"] = 2, ["z"] = 7, ["name"] = "default:silver_sandstone"}, {["x"] = 7, ["y"] = 2, ["z"] = 8, ["name"] = "default:silver_sandstone"}, {["x"] = 7, ["y"] = 2, ["param1"] = 16, ["z"] = 9, ["name"] = "default:silver_sandstone"}, {["x"] = 7, ["y"] = 2, ["param1"] = 16, ["z"] = 10, ["name"] = "default:silver_sandstone"}, {["x"] = 7, ["y"] = 2, ["param1"] = 16, ["z"] = 11, ["name"] = "default:silver_sandstone"}, {["x"] = 7, ["y"] = 2, ["param1"] = 16, ["z"] = 12, ["name"] = "default:silver_sandstone"}, {["x"] = 7, ["y"] = 2, ["param1"] = 16, ["z"] = 13, ["name"] = "default:silver_sandstone"}, {["x"] = 7, ["y"] = 2, ["param1"] = 16, ["z"] = 14, ["name"] = "default:silver_sandstone"}, {["x"] = 7, ["y"] = 2, ["param1"] = 16, ["z"] = 21, ["name"] = "default:silver_sandstone"}, {["x"] = 7, ["y"] = 2, ["param1"] = 16, ["z"] = 22, ["name"] = "default:silver_sandstone"}, {["x"] = 7, ["y"] = 2, ["param1"] = 16, ["z"] = 23, ["name"] = "default:silver_sandstone"}, {["x"] = 7, ["y"] = 2, ["param1"] = 16, ["z"] = 24, ["name"] = "default:silver_sandstone"}, {["x"] = 7, ["y"] = 2, ["param1"] = 16, ["z"] = 25, ["name"] = "default:silver_sandstone"}, {["x"] = 7, ["y"] = 2, ["param1"] = 16, ["z"] = 26, ["name"] = "default:silver_sandstone"}, {["x"] = 7, ["y"] = 2, ["param1"] = 16, ["z"] = 27, ["name"] = "default:silver_sandstone"}, {["x"] = 7, ["y"] = 2, ["param1"] = 16, ["z"] = 28, ["name"] = "default:silver_sandstone"}, {["x"] = 7, ["y"] = 2, ["param1"] = 16, ["z"] = 29, ["name"] = "default:silver_sandstone"}, {["x"] = 7, ["y"] = 2, ["param1"] = 16, ["z"] = 36, ["name"] = "default:silver_sandstone"}, {["x"] = 7, ["y"] = 2, ["param1"] = 16, ["z"] = 37, ["name"] = "default:silver_sandstone"}, {["x"] = 7, ["y"] = 2, ["param1"] = 16, ["z"] = 38, ["name"] = "default:silver_sandstone"}, {["x"] = 7, ["y"] = 2, ["param1"] = 16, ["z"] = 39, ["name"] = "default:silver_sandstone"}, {["x"] = 7, ["y"] = 2, ["param1"] = 16, ["z"] = 40, ["name"] = "default:silver_sandstone"}, {["x"] = 7, ["y"] = 2, ["param1"] = 28, ["z"] = 41, ["name"] = "mesecons_extrawires:vertical_off"}, {["x"] = 7, ["y"] = 2, ["param1"] = 16, ["z"] = 42, ["name"] = "default:silver_sandstone"}, {["x"] = 7, ["y"] = 2, ["param1"] = 16, ["z"] = 43, ["name"] = "default:silver_sandstone"}, {["x"] = 7, ["y"] = 2, ["param1"] = 16, ["z"] = 44, ["name"] = "default:silver_sandstone"}, {["x"] = 7, ["y"] = 3, ["z"] = 6, ["name"] = "default:silver_sandstone"}, {["x"] = 7, ["y"] = 3, ["param1"] = 16, ["z"] = 14, ["name"] = "default:silver_sandstone"}, {["x"] = 7, ["y"] = 3, ["param1"] = 16, ["z"] = 21, ["name"] = "default:silver_sandstone"}, {["x"] = 7, ["y"] = 3, ["param1"] = 16, ["z"] = 29, ["name"] = "default:silver_sandstone"}, {["x"] = 7, ["y"] = 3, ["param1"] = 16, ["z"] = 36, ["name"] = "default:silver_sandstone"}, {["x"] = 7, ["param2"] = 2, ["y"] = 3, ["param1"] = 13, ["z"] = 37, ["name"] = "mesecons_extrawires:corner_off"}, {["x"] = 7, ["param2"] = 3, ["y"] = 3, ["param1"] = 13, ["z"] = 38, ["name"] = "mesecons_extrawires:corner_off"}, {["x"] = 7, ["y"] = 3, ["param1"] = 13, ["z"] = 41, ["name"] = "mesecons_extrawires:vertical_top_off"}, {["x"] = 7, ["y"] = 3, ["param1"] = 16, ["z"] = 44, ["name"] = "default:silver_sandstone"}, {["x"] = 7, ["y"] = 4, ["param1"] = 14, ["z"] = 6, ["name"] = "stairs:slab_silver_sandstone"}, {["x"] = 7, ["y"] = 4, ["param1"] = 14, ["z"] = 7, ["name"] = "stairs:slab_silver_sandstone"}, {["x"] = 7, ["y"] = 4, ["param1"] = 14, ["z"] = 8, ["name"] = "stairs:slab_silver_sandstone"}, {["x"] = 7, ["y"] = 4, ["param1"] = 14, ["z"] = 9, ["name"] = "stairs:slab_silver_sandstone"}, {["x"] = 7, ["y"] = 4, ["param1"] = 14, ["z"] = 10, ["name"] = "stairs:slab_silver_sandstone"}, {["x"] = 7, ["y"] = 4, ["param1"] = 14, ["z"] = 11, ["name"] = "stairs:slab_silver_sandstone"}, {["x"] = 7, ["y"] = 4, ["param1"] = 14, ["z"] = 12, ["name"] = "stairs:slab_silver_sandstone"}, {["x"] = 7, ["y"] = 4, ["param1"] = 14, ["z"] = 13, ["name"] = "stairs:slab_silver_sandstone"}, {["x"] = 7, ["y"] = 4, ["param1"] = 14, ["z"] = 14, ["name"] = "stairs:slab_silver_sandstone"}, {["x"] = 7, ["y"] = 4, ["param1"] = 14, ["z"] = 21, ["name"] = "stairs:slab_silver_sandstone"}, {["x"] = 7, ["y"] = 4, ["param1"] = 14, ["z"] = 22, ["name"] = "stairs:slab_silver_sandstone"}, {["x"] = 7, ["y"] = 4, ["param1"] = 14, ["z"] = 23, ["name"] = "stairs:slab_silver_sandstone"}, {["x"] = 7, ["y"] = 4, ["param1"] = 14, ["z"] = 24, ["name"] = "stairs:slab_silver_sandstone"}, {["x"] = 7, ["y"] = 4, ["param1"] = 14, ["z"] = 25, ["name"] = "stairs:slab_silver_sandstone"}, {["x"] = 7, ["y"] = 4, ["param1"] = 14, ["z"] = 26, ["name"] = "stairs:slab_silver_sandstone"}, {["x"] = 7, ["y"] = 4, ["param1"] = 14, ["z"] = 27, ["name"] = "stairs:slab_silver_sandstone"}, {["x"] = 7, ["y"] = 4, ["param1"] = 14, ["z"] = 28, ["name"] = "stairs:slab_silver_sandstone"}, {["x"] = 7, ["y"] = 4, ["param1"] = 14, ["z"] = 29, ["name"] = "stairs:slab_silver_sandstone"}, {["x"] = 7, ["y"] = 4, ["param1"] = 14, ["z"] = 36, ["name"] = "stairs:slab_silver_sandstone"}, {["x"] = 7, ["y"] = 4, ["param1"] = 14, ["z"] = 37, ["name"] = "stairs:slab_silver_sandstone"}, {["x"] = 7, ["y"] = 4, ["param1"] = 14, ["z"] = 38, ["name"] = "stairs:slab_silver_sandstone"}, {["x"] = 7, ["y"] = 4, ["param1"] = 14, ["z"] = 39, ["name"] = "stairs:slab_silver_sandstone"}, {["x"] = 7, ["y"] = 4, ["param1"] = 14, ["z"] = 40, ["name"] = "stairs:slab_silver_sandstone"}, {["x"] = 7, ["y"] = 4, ["param1"] = 14, ["z"] = 41, ["name"] = "stairs:slab_silver_sandstone"}, {["x"] = 7, ["y"] = 4, ["param1"] = 14, ["z"] = 42, ["name"] = "stairs:slab_silver_sandstone"}, {["x"] = 7, ["y"] = 4, ["param1"] = 14, ["z"] = 43, ["name"] = "stairs:slab_silver_sandstone"}, {["x"] = 7, ["y"] = 4, ["param1"] = 14, ["z"] = 44, ["name"] = "stairs:slab_silver_sandstone"}, {["x"] = 8, ["y"] = 0, ["param1"] = 15, ["z"] = 0, ["name"] = "default:desert_sandstone_block"}, {["x"] = 8, ["y"] = 0, ["param1"] = 15, ["z"] = 1, ["name"] = "default:silver_sandstone_block"}, {["x"] = 8, ["y"] = 0, ["param1"] = 15, ["z"] = 2, ["name"] = "default:silver_sandstone_block"}, {["x"] = 8, ["y"] = 0, ["param1"] = 18, ["z"] = 3, ["name"] = "default:silver_sandstone_block"}, {["x"] = 8, ["y"] = 0, ["param1"] = 18, ["z"] = 4, ["name"] = "default:silver_sandstone_block"}, {["x"] = 8, ["y"] = 0, ["param1"] = 18, ["z"] = 5, ["name"] = "default:silver_sandstone_block"}, {["x"] = 8, ["y"] = 0, ["param1"] = 18, ["z"] = 6, ["name"] = "default:silver_sandstone_block"}, {["x"] = 8, ["y"] = 0, ["param1"] = 18, ["z"] = 7, ["name"] = "default:silver_sandstone_block"}, {["x"] = 8, ["y"] = 0, ["param1"] = 18, ["z"] = 8, ["name"] = "default:silver_sandstone_block"}, {["x"] = 8, ["y"] = 0, ["param1"] = 18, ["z"] = 9, ["name"] = "default:silver_sandstone_block"}, {["x"] = 8, ["y"] = 0, ["param1"] = 18, ["z"] = 10, ["name"] = "default:silver_sandstone_block"}, {["x"] = 8, ["y"] = 0, ["param1"] = 18, ["z"] = 11, ["name"] = "default:silver_sandstone_block"}, {["x"] = 8, ["y"] = 0, ["param1"] = 18, ["z"] = 12, ["name"] = "default:silver_sandstone_block"}, {["x"] = 8, ["y"] = 0, ["param1"] = 18, ["z"] = 13, ["name"] = "default:silver_sandstone_block"}, {["x"] = 8, ["y"] = 0, ["param1"] = 18, ["z"] = 14, ["name"] = "default:silver_sandstone_block"}, {["x"] = 8, ["y"] = 0, ["param1"] = 18, ["z"] = 15, ["name"] = "default:silver_sandstone_block"}, {["x"] = 8, ["y"] = 0, ["param1"] = 18, ["z"] = 16, ["name"] = "default:silver_sandstone_block"}, {["x"] = 8, ["y"] = 0, ["param1"] = 18, ["z"] = 17, ["name"] = "default:silver_sandstone_block"}, {["x"] = 8, ["y"] = 0, ["param1"] = 18, ["z"] = 18, ["name"] = "default:silver_sandstone_block"}, {["x"] = 8, ["y"] = 0, ["param1"] = 18, ["z"] = 19, ["name"] = "default:silver_sandstone_block"}, {["x"] = 8, ["y"] = 0, ["param1"] = 18, ["z"] = 20, ["name"] = "default:silver_sandstone_block"}, {["x"] = 8, ["y"] = 0, ["param1"] = 18, ["z"] = 21, ["name"] = "default:silver_sandstone_block"}, {["x"] = 8, ["y"] = 0, ["param1"] = 18, ["z"] = 22, ["name"] = "default:silver_sandstone_block"}, {["x"] = 8, ["y"] = 0, ["param1"] = 18, ["z"] = 23, ["name"] = "default:silver_sandstone_block"}, {["x"] = 8, ["y"] = 0, ["param1"] = 18, ["z"] = 24, ["name"] = "default:silver_sandstone_block"}, {["x"] = 8, ["y"] = 0, ["param1"] = 18, ["z"] = 25, ["name"] = "default:silver_sandstone_block"}, {["x"] = 8, ["y"] = 0, ["param1"] = 18, ["z"] = 26, ["name"] = "default:silver_sandstone_block"}, {["x"] = 8, ["y"] = 0, ["param1"] = 18, ["z"] = 27, ["name"] = "default:silver_sandstone_block"}, {["x"] = 8, ["y"] = 0, ["param1"] = 18, ["z"] = 28, ["name"] = "default:silver_sandstone_block"}, {["x"] = 8, ["y"] = 0, ["param1"] = 18, ["z"] = 29, ["name"] = "default:silver_sandstone_block"}, {["x"] = 8, ["y"] = 0, ["param1"] = 18, ["z"] = 30, ["name"] = "default:silver_sandstone_block"}, {["x"] = 8, ["y"] = 0, ["param1"] = 18, ["z"] = 31, ["name"] = "default:silver_sandstone_block"}, {["x"] = 8, ["y"] = 0, ["param1"] = 18, ["z"] = 32, ["name"] = "default:silver_sandstone_block"}, {["x"] = 8, ["y"] = 0, ["param1"] = 18, ["z"] = 33, ["name"] = "default:silver_sandstone_block"}, {["x"] = 8, ["y"] = 0, ["param1"] = 18, ["z"] = 34, ["name"] = "default:silver_sandstone_block"}, {["x"] = 8, ["y"] = 0, ["param1"] = 18, ["z"] = 35, ["name"] = "default:silver_sandstone_block"}, {["x"] = 8, ["y"] = 0, ["param1"] = 18, ["z"] = 36, ["name"] = "default:silver_sandstone_block"}, {["x"] = 8, ["y"] = 0, ["param1"] = 18, ["z"] = 37, ["name"] = "default:silver_sandstone_block"}, {["x"] = 8, ["y"] = 0, ["param1"] = 18, ["z"] = 38, ["name"] = "default:silver_sandstone_block"}, {["x"] = 8, ["y"] = 0, ["param1"] = 18, ["z"] = 39, ["name"] = "default:silver_sandstone_block"}, {["x"] = 8, ["y"] = 0, ["param1"] = 18, ["z"] = 40, ["name"] = "default:silver_sandstone_block"}, {["x"] = 8, ["y"] = 0, ["param1"] = 18, ["z"] = 41, ["name"] = "default:silver_sandstone_block"}, {["x"] = 8, ["y"] = 0, ["param1"] = 18, ["z"] = 42, ["name"] = "default:silver_sandstone_block"}, {["x"] = 8, ["y"] = 0, ["param1"] = 18, ["z"] = 43, ["name"] = "default:silver_sandstone_block"}, {["x"] = 8, ["y"] = 0, ["param1"] = 18, ["z"] = 44, ["name"] = "default:silver_sandstone_block"}, {["x"] = 8, ["y"] = 0, ["param1"] = 18, ["z"] = 45, ["name"] = "default:silver_sandstone_block"}, {["x"] = 8, ["y"] = 0, ["param1"] = 18, ["z"] = 46, ["name"] = "default:silver_sandstone_block"}, {["x"] = 8, ["y"] = 0, ["param1"] = 18, ["z"] = 47, ["name"] = "default:silver_sandstone_block"}, {["x"] = 8, ["y"] = 0, ["param1"] = 18, ["z"] = 48, ["name"] = "default:silver_sandstone_block"}, {["x"] = 8, ["y"] = 0, ["param1"] = 18, ["z"] = 49, ["name"] = "default:silver_sandstone_block"}, {["x"] = 8, ["y"] = 0, ["param1"] = 15, ["z"] = 50, ["name"] = "default:desert_sandstone_block"}, {["x"] = 8, ["y"] = 1, ["param1"] = 16, ["z"] = 6, ["name"] = "default:silver_sandstone"}, {["x"] = 8, ["param2"] = 1, ["y"] = 1, ["param1"] = 28, ["z"] = 7, ["name"] = "mesecons_extrawires:corner_off"}, {["x"] = 8, ["param2"] = 3, ["y"] = 1, ["param1"] = 11, ["z"] = 8, ["name"] = "mesecons_extrawires:corner_off"}, {["x"] = 8, ["y"] = 1, ["param1"] = 28, ["z"] = 9, ["name"] = "mesecons_insulated:insulated_off"}, {["x"] = 8, ["y"] = 1, ["param1"] = 28, ["z"] = 11, ["name"] = "mesecons_insulated:insulated_off"}, {["x"] = 8, ["y"] = 1, ["param1"] = 28, ["z"] = 13, ["name"] = "mesecons_insulated:insulated_off"}, {["x"] = 8, ["y"] = 1, ["param1"] = 16, ["z"] = 14, ["name"] = "default:silver_sandstone"}, {["x"] = 8, ["y"] = 1, ["param1"] = 16, ["z"] = 21, ["name"] = "default:silver_sandstone"}, {["x"] = 8, ["y"] = 1, ["param1"] = 16, ["z"] = 22, ["name"] = "default:silver_sandstone"}, {["x"] = 8, ["y"] = 1, ["param1"] = 16, ["z"] = 23, ["name"] = "default:silver_sandstone"}, {["x"] = 8, ["y"] = 1, ["param1"] = 16, ["z"] = 24, ["name"] = "default:silver_sandstone"}, {["x"] = 8, ["y"] = 1, ["param1"] = 16, ["z"] = 25, ["name"] = "default:silver_sandstone"}, {["x"] = 8, ["y"] = 1, ["param1"] = 16, ["z"] = 26, ["name"] = "default:silver_sandstone"}, {["x"] = 8, ["y"] = 1, ["param1"] = 16, ["z"] = 27, ["name"] = "default:silver_sandstone"}, {["x"] = 8, ["y"] = 1, ["param1"] = 16, ["z"] = 28, ["name"] = "default:silver_sandstone"}, {["x"] = 8, ["y"] = 1, ["param1"] = 16, ["z"] = 29, ["name"] = "default:silver_sandstone"}, {["x"] = 8, ["y"] = 1, ["param1"] = 16, ["z"] = 36, ["name"] = "default:silver_sandstone"}, {["x"] = 8, ["y"] = 1, ["param1"] = 16, ["z"] = 37, ["name"] = "default:silver_sandstone"}, {["x"] = 8, ["y"] = 1, ["param1"] = 16, ["z"] = 38, ["name"] = "default:silver_sandstone"}, {["x"] = 8, ["y"] = 1, ["param1"] = 16, ["z"] = 39, ["name"] = "default:silver_sandstone"}, {["x"] = 8, ["y"] = 1, ["param1"] = 16, ["z"] = 40, ["name"] = "default:silver_sandstone"}, {["x"] = 8, ["y"] = 1, ["param1"] = 16, ["z"] = 41, ["name"] = "default:silver_sandstone"}, {["x"] = 8, ["y"] = 1, ["param1"] = 16, ["z"] = 42, ["name"] = "default:silver_sandstone"}, {["x"] = 8, ["y"] = 1, ["param1"] = 16, ["z"] = 43, ["name"] = "default:silver_sandstone"}, {["x"] = 8, ["y"] = 1, ["param1"] = 16, ["z"] = 44, ["name"] = "default:silver_sandstone"}, {["x"] = 8, ["param2"] = 2, ["y"] = 1, ["param1"] = 15, ["z"] = 46, ["name"] = "mesecons_insulated:insulated_off"}, {["x"] = 8, ["y"] = 2, ["param1"] = 16, ["z"] = 6, ["name"] = "default:silver_sandstone"}, {["x"] = 8, ["y"] = 2, ["param1"] = 16, ["z"] = 7, ["name"] = "default:silver_sandstone"}, {["x"] = 8, ["param2"] = 2, ["y"] = 2, ["param1"] = 16, ["z"] = 8, ["name"] = "default:silver_sandstone"}, {["x"] = 8, ["param2"] = 1, ["y"] = 2, ["param1"] = 16, ["z"] = 9, ["name"] = "default:silver_sandstone"}, {["x"] = 8, ["y"] = 2, ["param1"] = 16, ["z"] = 10, ["name"] = "default:silver_sandstone"}, {["x"] = 8, ["y"] = 2, ["param1"] = 16, ["z"] = 11, ["name"] = "default:silver_sandstone"}, {["x"] = 8, ["param2"] = 2, ["y"] = 2, ["param1"] = 16, ["z"] = 12, ["name"] = "default:silver_sandstone"}, {["x"] = 8, ["y"] = 2, ["param1"] = 16, ["z"] = 13, ["name"] = "default:silver_sandstone"}, {["x"] = 8, ["y"] = 2, ["param1"] = 16, ["z"] = 14, ["name"] = "default:silver_sandstone"}, {["x"] = 8, ["y"] = 2, ["param1"] = 16, ["z"] = 21, ["name"] = "default:silver_sandstone"}, {["x"] = 8, ["y"] = 2, ["param1"] = 16, ["z"] = 22, ["name"] = "default:silver_sandstone"}, {["x"] = 8, ["param2"] = 2, ["y"] = 2, ["param1"] = 16, ["z"] = 23, ["name"] = "default:silver_sandstone"}, {["x"] = 8, ["param2"] = 1, ["y"] = 2, ["param1"] = 16, ["z"] = 24, ["name"] = "default:silver_sandstone"}, {["x"] = 8, ["y"] = 2, ["param1"] = 16, ["z"] = 25, ["name"] = "default:silver_sandstone"}, {["x"] = 8, ["y"] = 2, ["param1"] = 16, ["z"] = 26, ["name"] = "default:silver_sandstone"}, {["x"] = 8, ["param2"] = 2, ["y"] = 2, ["param1"] = 16, ["z"] = 27, ["name"] = "default:silver_sandstone"}, {["x"] = 8, ["y"] = 2, ["param1"] = 16, ["z"] = 28, ["name"] = "default:silver_sandstone"}, {["x"] = 8, ["y"] = 2, ["param1"] = 16, ["z"] = 29, ["name"] = "default:silver_sandstone"}, {["x"] = 8, ["y"] = 2, ["param1"] = 16, ["z"] = 36, ["name"] = "default:silver_sandstone"}, {["x"] = 8, ["y"] = 2, ["param1"] = 16, ["z"] = 37, ["name"] = "default:silver_sandstone"}, {["x"] = 8, ["param2"] = 2, ["y"] = 2, ["param1"] = 16, ["z"] = 38, ["name"] = "default:silver_sandstone"}, {["x"] = 8, ["param2"] = 1, ["y"] = 2, ["param1"] = 16, ["z"] = 39, ["name"] = "default:silver_sandstone"}, {["x"] = 8, ["y"] = 2, ["param1"] = 16, ["z"] = 40, ["name"] = "default:silver_sandstone"}, {["x"] = 8, ["y"] = 2, ["param1"] = 16, ["z"] = 41, ["name"] = "default:silver_sandstone"}, {["x"] = 8, ["param2"] = 2, ["y"] = 2, ["param1"] = 16, ["z"] = 42, ["name"] = "default:silver_sandstone"}, {["x"] = 8, ["y"] = 2, ["param1"] = 16, ["z"] = 43, ["name"] = "default:silver_sandstone"}, {["x"] = 8, ["y"] = 2, ["param1"] = 16, ["z"] = 44, ["name"] = "default:silver_sandstone"}, {["x"] = 8, ["y"] = 3, ["param1"] = 16, ["z"] = 6, ["name"] = "default:silver_sandstone"}, {["x"] = 8, ["y"] = 3, ["param1"] = 16, ["z"] = 14, ["name"] = "default:silver_sandstone"}, {["x"] = 8, ["y"] = 3, ["param1"] = 16, ["z"] = 21, ["name"] = "default:silver_sandstone"}, {["x"] = 8, ["y"] = 3, ["param1"] = 16, ["z"] = 29, ["name"] = "default:silver_sandstone"}, {["x"] = 8, ["y"] = 3, ["param1"] = 16, ["z"] = 36, ["name"] = "default:silver_sandstone"}, {["x"] = 8, ["meta"] = {["fields"] = {["infotext"] = "FPGA (functional)", ["portstates"] = "0000", ["instr"] = "B&AC//////////////", ["valid"] = "1"}, ["inventory"] = {}}, ["y"] = 3, ["param1"] = 13, ["z"] = 37, ["name"] = "mesecons_fpga:fpga0000"}, {["x"] = 8, ["y"] = 3, ["param1"] = 13, ["z"] = 38, ["name"] = "mesecons_extrawires:crossover_off"}, {["x"] = 8, ["param2"] = 3, ["y"] = 3, ["param1"] = 13, ["z"] = 39, ["name"] = "mesecons_insulated:insulated_off"}, {["x"] = 8, ["param2"] = 3, ["y"] = 3, ["param1"] = 13, ["z"] = 40, ["name"] = "mesecons_extrawires:tjunction_off"}, {["x"] = 8, ["meta"] = {["fields"] = {["real_portstates"] = "1", ["code"] = "-- Shift Register D Latch (toggle D state when enabled)\
-- by So.Po.Coder for Minetest Mesecons Luacontroller\
-- A:input, B:reset, C:clock, D:output\13\13if (event.type == \"program\") then\13  mem.and1, mem.and2 = false, false\13end\13\13if (event.type == \"on\" and event.pin.name == \"C\") then\
\
  -- get first two AND gates based on clock and data\13  if (pin.c and pin.a) then\
    mem.and1 = true\
  else\
    mem.and1 = false\
  end\
  if (pin.c and not pin.a) then\
    mem.and2 = true\
  else\
    mem.and2 = false\
  end\
\
  -- SR Latch\
  if (mem.and1) then\
    port.d = true\
  end\
  if (mem.and2) then\
    port.d = false\
  end\
\13end\
if (event.type == \"on\" or event.type == \"off\") then\
  -- reset latch to low\
  if (pin.b) then\
    port.d = false\
  end\
end", ["formspec"] = "size[12,10]background[-0.2,-0.25;12.4,10.75;jeija_luac_background.png]label[0.1,8.3;]textarea[0.2,0.2;12.2,9.5;code;;-- Shift Register D Latch (toggle D state when enabled)\
-- by So.Po.Coder for Minetest Mesecons Luacontroller\
-- A:input\\, B:reset\\, C:clock\\, D:output\13\13if (event.type == \"program\") then\13  mem.and1\\, mem.and2 = false\\, false\13end\13\13if (event.type == \"on\" and event.pin.name == \"C\") then\
\
  -- get first two AND gates based on clock and data\13  if (pin.c and pin.a) then\
    mem.and1 = true\
  else\
    mem.and1 = false\
  end\
  if (pin.c and not pin.a) then\
    mem.and2 = true\
  else\
    mem.and2 = false\
  end\
\
  -- SR Latch\
  if (mem.and1) then\
    port.d = true\
  end\
  if (mem.and2) then\
    port.d = false\
  end\
\13end\
if (event.type == \"on\" or event.type == \"off\") then\
  -- reset latch to low\
  if (pin.b) then\
    port.d = false\
  end\
end]image_button[4.75,8.75;2.5,1;jeija_luac_runbutton.png;program;]image_button_exit[11.72,-0.25;0.425,0.4;jeija_close_window.png;exit;]", ["lc_memory"] = "return {[\"b\"] = false, [\"and2\"] = true, [\"d\"] = false, [\"and1\"] = false, [\"a\"] = false, [\"c\"] = false}", ["ignore_offevents"] = "return {}", ["luac_id"] = "2726"}, ["inventory"] = {}}, ["y"] = 3, ["param1"] = 13, ["z"] = 41, ["name"] = "mesecons_luacontroller:luacontroller0000"}, {["x"] = 8, ["param2"] = 3, ["y"] = 3, ["param1"] = 13, ["z"] = 42, ["name"] = "mesecons_extrawires:corner_off"}, {["x"] = 8, ["y"] = 3, ["param1"] = 16, ["z"] = 44, ["name"] = "default:silver_sandstone"}, {["x"] = 8, ["y"] = 4, ["param1"] = 14, ["z"] = 6, ["name"] = "stairs:slab_silver_sandstone"}, {["x"] = 8, ["y"] = 4, ["param1"] = 14, ["z"] = 7, ["name"] = "stairs:slab_silver_sandstone"}, {["x"] = 8, ["y"] = 4, ["param1"] = 14, ["z"] = 8, ["name"] = "stairs:slab_silver_sandstone"}, {["x"] = 8, ["y"] = 4, ["param1"] = 14, ["z"] = 9, ["name"] = "stairs:slab_silver_sandstone"}, {["x"] = 8, ["y"] = 4, ["param1"] = 14, ["z"] = 10, ["name"] = "stairs:slab_silver_sandstone"}, {["x"] = 8, ["y"] = 4, ["param1"] = 14, ["z"] = 11, ["name"] = "stairs:slab_silver_sandstone"}, {["x"] = 8, ["y"] = 4, ["param1"] = 14, ["z"] = 12, ["name"] = "stairs:slab_silver_sandstone"}, {["x"] = 8, ["y"] = 4, ["param1"] = 14, ["z"] = 13, ["name"] = "stairs:slab_silver_sandstone"}, {["x"] = 8, ["y"] = 4, ["param1"] = 14, ["z"] = 14, ["name"] = "stairs:slab_silver_sandstone"}, {["x"] = 8, ["y"] = 4, ["param1"] = 14, ["z"] = 21, ["name"] = "stairs:slab_silver_sandstone"}, {["x"] = 8, ["y"] = 4, ["param1"] = 14, ["z"] = 22, ["name"] = "stairs:slab_silver_sandstone"}, {["x"] = 8, ["y"] = 4, ["param1"] = 14, ["z"] = 23, ["name"] = "stairs:slab_silver_sandstone"}, {["x"] = 8, ["y"] = 4, ["param1"] = 14, ["z"] = 24, ["name"] = "stairs:slab_silver_sandstone"}, {["x"] = 8, ["y"] = 4, ["param1"] = 14, ["z"] = 25, ["name"] = "stairs:slab_silver_sandstone"}, {["x"] = 8, ["y"] = 4, ["param1"] = 14, ["z"] = 26, ["name"] = "stairs:slab_silver_sandstone"}, {["x"] = 8, ["y"] = 4, ["param1"] = 14, ["z"] = 27, ["name"] = "stairs:slab_silver_sandstone"}, {["x"] = 8, ["y"] = 4, ["param1"] = 14, ["z"] = 28, ["name"] = "stairs:slab_silver_sandstone"}, {["x"] = 8, ["y"] = 4, ["param1"] = 14, ["z"] = 29, ["name"] = "stairs:slab_silver_sandstone"}, {["x"] = 8, ["y"] = 4, ["param1"] = 14, ["z"] = 36, ["name"] = "stairs:slab_silver_sandstone"}, {["x"] = 8, ["y"] = 4, ["param1"] = 14, ["z"] = 37, ["name"] = "stairs:slab_silver_sandstone"}, {["x"] = 8, ["y"] = 4, ["param1"] = 14, ["z"] = 38, ["name"] = "stairs:slab_silver_sandstone"}, {["x"] = 8, ["y"] = 4, ["param1"] = 14, ["z"] = 39, ["name"] = "stairs:slab_silver_sandstone"}, {["x"] = 8, ["y"] = 4, ["param1"] = 14, ["z"] = 40, ["name"] = "stairs:slab_silver_sandstone"}, {["x"] = 8, ["y"] = 4, ["param1"] = 14, ["z"] = 41, ["name"] = "stairs:slab_silver_sandstone"}, {["x"] = 8, ["y"] = 4, ["param1"] = 14, ["z"] = 42, ["name"] = "stairs:slab_silver_sandstone"}, {["x"] = 8, ["y"] = 4, ["param1"] = 14, ["z"] = 43, ["name"] = "stairs:slab_silver_sandstone"}, {["x"] = 8, ["y"] = 4, ["param1"] = 14, ["z"] = 44, ["name"] = "stairs:slab_silver_sandstone"}, {["x"] = 9, ["y"] = 0, ["param1"] = 15, ["z"] = 0, ["name"] = "default:desert_sandstone_block"}, {["x"] = 9, ["y"] = 0, ["param1"] = 15, ["z"] = 1, ["name"] = "default:silver_sandstone_block"}, {["x"] = 9, ["y"] = 0, ["param1"] = 15, ["z"] = 2, ["name"] = "default:silver_sandstone_block"}, {["x"] = 9, ["y"] = 0, ["param1"] = 18, ["z"] = 3, ["name"] = "default:silver_sandstone_block"}, {["x"] = 9, ["y"] = 0, ["param1"] = 18, ["z"] = 4, ["name"] = "default:silver_sandstone_block"}, {["x"] = 9, ["y"] = 0, ["param1"] = 18, ["z"] = 5, ["name"] = "default:silver_sandstone_block"}, {["x"] = 9, ["y"] = 0, ["param1"] = 18, ["z"] = 6, ["name"] = "default:silver_sandstone_block"}, {["x"] = 9, ["y"] = 0, ["param1"] = 18, ["z"] = 7, ["name"] = "default:silver_sandstone_block"}, {["x"] = 9, ["y"] = 0, ["param1"] = 18, ["z"] = 8, ["name"] = "default:silver_sandstone_block"}, {["x"] = 9, ["y"] = 0, ["param1"] = 18, ["z"] = 9, ["name"] = "default:silver_sandstone_block"}, {["x"] = 9, ["y"] = 0, ["param1"] = 18, ["z"] = 10, ["name"] = "default:silver_sandstone_block"}, {["x"] = 9, ["y"] = 0, ["param1"] = 18, ["z"] = 11, ["name"] = "default:silver_sandstone_block"}, {["x"] = 9, ["y"] = 0, ["param1"] = 18, ["z"] = 12, ["name"] = "default:silver_sandstone_block"}, {["x"] = 9, ["y"] = 0, ["param1"] = 18, ["z"] = 13, ["name"] = "default:silver_sandstone_block"}, {["x"] = 9, ["y"] = 0, ["param1"] = 18, ["z"] = 14, ["name"] = "default:silver_sandstone_block"}, {["x"] = 9, ["y"] = 0, ["param1"] = 18, ["z"] = 15, ["name"] = "default:silver_sandstone_block"}, {["x"] = 9, ["y"] = 0, ["param1"] = 18, ["z"] = 16, ["name"] = "default:silver_sandstone_block"}, {["x"] = 9, ["y"] = 0, ["param1"] = 18, ["z"] = 17, ["name"] = "default:silver_sandstone_block"}, {["x"] = 9, ["y"] = 0, ["param1"] = 18, ["z"] = 18, ["name"] = "default:silver_sandstone_block"}, {["x"] = 9, ["y"] = 0, ["param1"] = 18, ["z"] = 19, ["name"] = "default:silver_sandstone_block"}, {["x"] = 9, ["y"] = 0, ["param1"] = 18, ["z"] = 20, ["name"] = "default:silver_sandstone_block"}, {["x"] = 9, ["y"] = 0, ["param1"] = 18, ["z"] = 21, ["name"] = "default:silver_sandstone_block"}, {["x"] = 9, ["y"] = 0, ["param1"] = 18, ["z"] = 22, ["name"] = "default:silver_sandstone_block"}, {["x"] = 9, ["y"] = 0, ["param1"] = 18, ["z"] = 23, ["name"] = "default:silver_sandstone_block"}, {["x"] = 9, ["y"] = 0, ["param1"] = 18, ["z"] = 24, ["name"] = "default:silver_sandstone_block"}, {["x"] = 9, ["y"] = 0, ["param1"] = 18, ["z"] = 25, ["name"] = "default:silver_sandstone_block"}, {["x"] = 9, ["y"] = 0, ["param1"] = 18, ["z"] = 26, ["name"] = "default:silver_sandstone_block"}, {["x"] = 9, ["y"] = 0, ["param1"] = 18, ["z"] = 27, ["name"] = "default:silver_sandstone_block"}, {["x"] = 9, ["y"] = 0, ["param1"] = 18, ["z"] = 28, ["name"] = "default:silver_sandstone_block"}, {["x"] = 9, ["y"] = 0, ["param1"] = 18, ["z"] = 29, ["name"] = "default:silver_sandstone_block"}, {["x"] = 9, ["y"] = 0, ["param1"] = 18, ["z"] = 30, ["name"] = "default:silver_sandstone_block"}, {["x"] = 9, ["y"] = 0, ["param1"] = 18, ["z"] = 31, ["name"] = "default:silver_sandstone_block"}, {["x"] = 9, ["y"] = 0, ["param1"] = 18, ["z"] = 32, ["name"] = "default:silver_sandstone_block"}, {["x"] = 9, ["y"] = 0, ["param1"] = 18, ["z"] = 33, ["name"] = "default:silver_sandstone_block"}, {["x"] = 9, ["y"] = 0, ["param1"] = 18, ["z"] = 34, ["name"] = "default:silver_sandstone_block"}, {["x"] = 9, ["y"] = 0, ["param1"] = 18, ["z"] = 35, ["name"] = "default:silver_sandstone_block"}, {["x"] = 9, ["y"] = 0, ["param1"] = 18, ["z"] = 36, ["name"] = "default:silver_sandstone_block"}, {["x"] = 9, ["y"] = 0, ["param1"] = 18, ["z"] = 37, ["name"] = "default:silver_sandstone_block"}, {["x"] = 9, ["y"] = 0, ["param1"] = 18, ["z"] = 38, ["name"] = "default:silver_sandstone_block"}, {["x"] = 9, ["y"] = 0, ["param1"] = 18, ["z"] = 39, ["name"] = "default:silver_sandstone_block"}, {["x"] = 9, ["y"] = 0, ["param1"] = 18, ["z"] = 40, ["name"] = "default:silver_sandstone_block"}, {["x"] = 9, ["y"] = 0, ["param1"] = 18, ["z"] = 41, ["name"] = "default:silver_sandstone_block"}, {["x"] = 9, ["y"] = 0, ["param1"] = 18, ["z"] = 42, ["name"] = "default:silver_sandstone_block"}, {["x"] = 9, ["y"] = 0, ["param1"] = 18, ["z"] = 43, ["name"] = "default:silver_sandstone_block"}, {["x"] = 9, ["y"] = 0, ["param1"] = 18, ["z"] = 44, ["name"] = "default:silver_sandstone_block"}, {["x"] = 9, ["y"] = 0, ["param1"] = 18, ["z"] = 45, ["name"] = "default:silver_sandstone_block"}, {["x"] = 9, ["y"] = 0, ["param1"] = 18, ["z"] = 46, ["name"] = "default:silver_sandstone_block"}, {["x"] = 9, ["y"] = 0, ["param1"] = 18, ["z"] = 47, ["name"] = "default:silver_sandstone_block"}, {["x"] = 9, ["y"] = 0, ["param1"] = 18, ["z"] = 48, ["name"] = "default:silver_sandstone_block"}, {["x"] = 9, ["y"] = 0, ["param1"] = 18, ["z"] = 49, ["name"] = "default:silver_sandstone_block"}, {["x"] = 9, ["y"] = 0, ["param1"] = 15, ["z"] = 50, ["name"] = "default:desert_sandstone_block"}, {["x"] = 9, ["y"] = 1, ["param1"] = 16, ["z"] = 6, ["name"] = "default:silver_sandstone"}, {["x"] = 9, ["y"] = 1, ["param1"] = 11, ["z"] = 7, ["name"] = "mesecons_extrawires:vertical_bottom_off"}, {["x"] = 9, ["y"] = 1, ["param1"] = 10, ["z"] = 8, ["name"] = "mesecons_extrawires:crossover_off"}, {["x"] = 9, ["y"] = 1, ["param1"] = 11, ["z"] = 9, ["name"] = "mesecons_extrawires:crossover_off"}, {["x"] = 9, ["param2"] = 1, ["y"] = 1, ["param1"] = 10, ["z"] = 10, ["name"] = "mesecons_insulated:insulated_off"}, {["x"] = 9, ["y"] = 1, ["param1"] = 11, ["z"] = 11, ["name"] = "mesecons_extrawires:crossover_off"}, {["x"] = 9, ["param2"] = 1, ["y"] = 1, ["param1"] = 11, ["z"] = 12, ["name"] = "mesecons_insulated:insulated_off"}, {["x"] = 9, ["y"] = 1, ["param1"] = 28, ["z"] = 13, ["name"] = "mesecons_extrawires:corner_off"}, {["x"] = 9, ["y"] = 1, ["param1"] = 16, ["z"] = 14, ["name"] = "default:silver_sandstone"}, {["x"] = 9, ["y"] = 1, ["param1"] = 16, ["z"] = 21, ["name"] = "default:silver_sandstone"}, {["x"] = 9, ["y"] = 1, ["param1"] = 44, ["z"] = 22, ["name"] = "mesecons_extrawires:vertical_bottom_off"}, {["x"] = 9, ["y"] = 1, ["param1"] = 16, ["z"] = 23, ["name"] = "default:silver_sandstone"}, {["x"] = 9, ["y"] = 1, ["param1"] = 16, ["z"] = 24, ["name"] = "default:silver_sandstone"}, {["x"] = 9, ["y"] = 1, ["param1"] = 16, ["z"] = 25, ["name"] = "default:silver_sandstone"}, {["x"] = 9, ["y"] = 1, ["param1"] = 16, ["z"] = 26, ["name"] = "default:silver_sandstone"}, {["x"] = 9, ["y"] = 1, ["param1"] = 16, ["z"] = 27, ["name"] = "default:silver_sandstone"}, {["x"] = 9, ["y"] = 1, ["param1"] = 16, ["z"] = 28, ["name"] = "default:silver_sandstone"}, {["x"] = 9, ["y"] = 1, ["param1"] = 16, ["z"] = 29, ["name"] = "default:silver_sandstone"}, {["x"] = 9, ["y"] = 1, ["param1"] = 16, ["z"] = 36, ["name"] = "default:silver_sandstone"}, {["x"] = 9, ["y"] = 1, ["param1"] = 44, ["z"] = 37, ["name"] = "mesecons_extrawires:vertical_bottom_off"}, {["x"] = 9, ["y"] = 1, ["param1"] = 16, ["z"] = 38, ["name"] = "default:silver_sandstone"}, {["x"] = 9, ["y"] = 1, ["param1"] = 16, ["z"] = 39, ["name"] = "default:silver_sandstone"}, {["x"] = 9, ["y"] = 1, ["param1"] = 16, ["z"] = 40, ["name"] = "default:silver_sandstone"}, {["x"] = 9, ["y"] = 1, ["param1"] = 16, ["z"] = 41, ["name"] = "default:silver_sandstone"}, {["x"] = 9, ["y"] = 1, ["param1"] = 16, ["z"] = 42, ["name"] = "default:silver_sandstone"}, {["x"] = 9, ["y"] = 1, ["param1"] = 16, ["z"] = 43, ["name"] = "default:silver_sandstone"}, {["x"] = 9, ["y"] = 1, ["param1"] = 16, ["z"] = 44, ["name"] = "default:silver_sandstone"}, {["x"] = 9, ["param2"] = 2, ["y"] = 1, ["param1"] = 15, ["z"] = 46, ["name"] = "mesecons_insulated:insulated_off"}, {["x"] = 9, ["y"] = 2, ["param1"] = 16, ["z"] = 6, ["name"] = "default:silver_sandstone"}, {["x"] = 9, ["y"] = 2, ["param1"] = 12, ["z"] = 7, ["name"] = "mesecons_extrawires:vertical_off"}, {["x"] = 9, ["param2"] = 2, ["y"] = 2, ["param1"] = 16, ["z"] = 8, ["name"] = "default:silver_sandstone"}, {["x"] = 9, ["param2"] = 2, ["y"] = 2, ["param1"] = 16, ["z"] = 9, ["name"] = "default:silver_sandstone"}, {["x"] = 9, ["param2"] = 1, ["y"] = 2, ["param1"] = 16, ["z"] = 10, ["name"] = "default:silver_sandstone"}, {["x"] = 9, ["param2"] = 3, ["y"] = 2, ["param1"] = 16, ["z"] = 11, ["name"] = "default:silver_sandstone"}, {["x"] = 9, ["y"] = 2, ["param1"] = 16, ["z"] = 12, ["name"] = "default:silver_sandstone"}, {["x"] = 9, ["y"] = 2, ["param1"] = 16, ["z"] = 13, ["name"] = "default:silver_sandstone"}, {["x"] = 9, ["y"] = 2, ["param1"] = 16, ["z"] = 14, ["name"] = "default:silver_sandstone"}, {["x"] = 9, ["y"] = 2, ["param1"] = 16, ["z"] = 21, ["name"] = "default:silver_sandstone"}, {["x"] = 9, ["y"] = 2, ["param1"] = 28, ["z"] = 22, ["name"] = "mesecons_extrawires:vertical_off"}, {["x"] = 9, ["param2"] = 2, ["y"] = 2, ["param1"] = 16, ["z"] = 23, ["name"] = "default:silver_sandstone"}, {["x"] = 9, ["param2"] = 2, ["y"] = 2, ["param1"] = 16, ["z"] = 24, ["name"] = "default:silver_sandstone"}, {["x"] = 9, ["param2"] = 1, ["y"] = 2, ["param1"] = 16, ["z"] = 25, ["name"] = "default:silver_sandstone"}, {["x"] = 9, ["param2"] = 3, ["y"] = 2, ["param1"] = 16, ["z"] = 26, ["name"] = "default:silver_sandstone"}, {["x"] = 9, ["y"] = 2, ["param1"] = 16, ["z"] = 27, ["name"] = "default:silver_sandstone"}, {["x"] = 9, ["y"] = 2, ["param1"] = 16, ["z"] = 28, ["name"] = "default:silver_sandstone"}, {["x"] = 9, ["y"] = 2, ["param1"] = 16, ["z"] = 29, ["name"] = "default:silver_sandstone"}, {["x"] = 9, ["y"] = 2, ["param1"] = 16, ["z"] = 36, ["name"] = "default:silver_sandstone"}, {["x"] = 9, ["y"] = 2, ["param1"] = 28, ["z"] = 37, ["name"] = "mesecons_extrawires:vertical_off"}, {["x"] = 9, ["param2"] = 2, ["y"] = 2, ["param1"] = 16, ["z"] = 38, ["name"] = "default:silver_sandstone"}, {["x"] = 9, ["param2"] = 2, ["y"] = 2, ["param1"] = 16, ["z"] = 39, ["name"] = "default:silver_sandstone"}, {["x"] = 9, ["param2"] = 1, ["y"] = 2, ["param1"] = 16, ["z"] = 40, ["name"] = "default:silver_sandstone"}, {["x"] = 9, ["param2"] = 3, ["y"] = 2, ["param1"] = 16, ["z"] = 41, ["name"] = "default:silver_sandstone"}, {["x"] = 9, ["y"] = 2, ["param1"] = 16, ["z"] = 42, ["name"] = "default:silver_sandstone"}, {["x"] = 9, ["y"] = 2, ["param1"] = 16, ["z"] = 43, ["name"] = "default:silver_sandstone"}, {["x"] = 9, ["y"] = 2, ["param1"] = 16, ["z"] = 44, ["name"] = "default:silver_sandstone"}, {["x"] = 9, ["y"] = 3, ["param1"] = 16, ["z"] = 6, ["name"] = "default:silver_sandstone"}, {["x"] = 9, ["y"] = 3, ["param1"] = 13, ["z"] = 7, ["name"] = "mesecons_extrawires:vertical_top_off"}, {["x"] = 9, ["param2"] = 2, ["y"] = 3, ["param1"] = 13, ["z"] = 9, ["name"] = "mesecons_extrawires:corner_off"}, {["x"] = 9, ["param2"] = 1, ["y"] = 3, ["param1"] = 13, ["z"] = 10, ["name"] = "mesecons_insulated:insulated_off"}, {["x"] = 9, ["param2"] = 3, ["y"] = 3, ["param1"] = 13, ["z"] = 11, ["name"] = "mesecons_extrawires:corner_off"}, {["x"] = 9, ["y"] = 3, ["param1"] = 16, ["z"] = 14, ["name"] = "default:silver_sandstone"}, {["x"] = 9, ["y"] = 3, ["param1"] = 16, ["z"] = 21, ["name"] = "default:silver_sandstone"}, {["x"] = 9, ["y"] = 3, ["param1"] = 13, ["z"] = 22, ["name"] = "mesecons_extrawires:vertical_top_off"}, {["x"] = 9, ["param2"] = 2, ["y"] = 3, ["param1"] = 13, ["z"] = 24, ["name"] = "mesecons_extrawires:corner_off"}, {["x"] = 9, ["param2"] = 1, ["y"] = 3, ["param1"] = 13, ["z"] = 25, ["name"] = "mesecons_insulated:insulated_off"}, {["x"] = 9, ["param2"] = 3, ["y"] = 3, ["param1"] = 13, ["z"] = 26, ["name"] = "mesecons_extrawires:corner_off"}, {["x"] = 9, ["y"] = 3, ["param1"] = 16, ["z"] = 29, ["name"] = "default:silver_sandstone"}, {["x"] = 9, ["y"] = 3, ["param1"] = 16, ["z"] = 36, ["name"] = "default:silver_sandstone"}, {["x"] = 9, ["y"] = 3, ["param1"] = 13, ["z"] = 37, ["name"] = "mesecons_extrawires:vertical_top_off"}, {["x"] = 9, ["y"] = 3, ["param1"] = 13, ["z"] = 38, ["name"] = "mesecons_insulated:insulated_off"}, {["x"] = 9, ["param2"] = 2, ["y"] = 3, ["param1"] = 13, ["z"] = 39, ["name"] = "mesecons_extrawires:corner_off"}, {["x"] = 9, ["y"] = 3, ["param1"] = 13, ["z"] = 40, ["name"] = "mesecons_extrawires:crossover_off"}, {["x"] = 9, ["y"] = 3, ["param1"] = 13, ["z"] = 41, ["name"] = "mesecons_extrawires:corner_off"}, {["x"] = 9, ["y"] = 3, ["param1"] = 13, ["z"] = 42, ["name"] = "mesecons_insulated:insulated_off"}, {["x"] = 9, ["y"] = 3, ["param1"] = 16, ["z"] = 44, ["name"] = "default:silver_sandstone"}, {["x"] = 9, ["y"] = 4, ["param1"] = 14, ["z"] = 6, ["name"] = "stairs:slab_silver_sandstone"}, {["x"] = 9, ["y"] = 4, ["param1"] = 14, ["z"] = 7, ["name"] = "stairs:slab_silver_sandstone"}, {["x"] = 9, ["y"] = 4, ["param1"] = 14, ["z"] = 8, ["name"] = "stairs:slab_silver_sandstone"}, {["x"] = 9, ["y"] = 4, ["param1"] = 14, ["z"] = 9, ["name"] = "stairs:slab_silver_sandstone"}, {["x"] = 9, ["y"] = 4, ["param1"] = 14, ["z"] = 10, ["name"] = "stairs:slab_silver_sandstone"}, {["x"] = 9, ["y"] = 4, ["param1"] = 14, ["z"] = 11, ["name"] = "stairs:slab_silver_sandstone"}, {["x"] = 9, ["y"] = 4, ["param1"] = 14, ["z"] = 12, ["name"] = "stairs:slab_silver_sandstone"}, {["x"] = 9, ["y"] = 4, ["param1"] = 14, ["z"] = 13, ["name"] = "stairs:slab_silver_sandstone"}, {["x"] = 9, ["y"] = 4, ["param1"] = 14, ["z"] = 14, ["name"] = "stairs:slab_silver_sandstone"}, {["x"] = 9, ["y"] = 4, ["param1"] = 14, ["z"] = 21, ["name"] = "stairs:slab_silver_sandstone"}, {["x"] = 9, ["y"] = 4, ["param1"] = 14, ["z"] = 22, ["name"] = "stairs:slab_silver_sandstone"}, {["x"] = 9, ["y"] = 4, ["param1"] = 14, ["z"] = 23, ["name"] = "stairs:slab_silver_sandstone"}, {["x"] = 9, ["y"] = 4, ["param1"] = 14, ["z"] = 24, ["name"] = "stairs:slab_silver_sandstone"}, {["x"] = 9, ["y"] = 4, ["param1"] = 14, ["z"] = 25, ["name"] = "stairs:slab_silver_sandstone"}, {["x"] = 9, ["y"] = 4, ["param1"] = 14, ["z"] = 26, ["name"] = "stairs:slab_silver_sandstone"}, {["x"] = 9, ["y"] = 4, ["param1"] = 14, ["z"] = 27, ["name"] = "stairs:slab_silver_sandstone"}, {["x"] = 9, ["y"] = 4, ["param1"] = 14, ["z"] = 28, ["name"] = "stairs:slab_silver_sandstone"}, {["x"] = 9, ["y"] = 4, ["param1"] = 14, ["z"] = 29, ["name"] = "stairs:slab_silver_sandstone"}, {["x"] = 9, ["y"] = 4, ["param1"] = 14, ["z"] = 36, ["name"] = "stairs:slab_silver_sandstone"}, {["x"] = 9, ["y"] = 4, ["param1"] = 14, ["z"] = 37, ["name"] = "stairs:slab_silver_sandstone"}, {["x"] = 9, ["y"] = 4, ["param1"] = 14, ["z"] = 38, ["name"] = "stairs:slab_silver_sandstone"}, {["x"] = 9, ["y"] = 4, ["param1"] = 14, ["z"] = 39, ["name"] = "stairs:slab_silver_sandstone"}, {["x"] = 9, ["y"] = 4, ["param1"] = 14, ["z"] = 40, ["name"] = "stairs:slab_silver_sandstone"}, {["x"] = 9, ["y"] = 4, ["param1"] = 14, ["z"] = 41, ["name"] = "stairs:slab_silver_sandstone"}, {["x"] = 9, ["y"] = 4, ["param1"] = 14, ["z"] = 42, ["name"] = "stairs:slab_silver_sandstone"}, {["x"] = 9, ["y"] = 4, ["param1"] = 14, ["z"] = 43, ["name"] = "stairs:slab_silver_sandstone"}, {["x"] = 9, ["y"] = 4, ["param1"] = 14, ["z"] = 44, ["name"] = "stairs:slab_silver_sandstone"}, {["x"] = 10, ["y"] = 0, ["param1"] = 15, ["z"] = 0, ["name"] = "default:desert_sandstone_block"}, {["x"] = 10, ["y"] = 0, ["param1"] = 15, ["z"] = 1, ["name"] = "default:silver_sandstone_block"}, {["x"] = 10, ["y"] = 0, ["param1"] = 15, ["z"] = 2, ["name"] = "default:silver_sandstone_block"}, {["x"] = 10, ["y"] = 0, ["param1"] = 18, ["z"] = 3, ["name"] = "default:silver_sandstone_block"}, {["x"] = 10, ["y"] = 0, ["param1"] = 18, ["z"] = 4, ["name"] = "default:silver_sandstone_block"}, {["x"] = 10, ["y"] = 0, ["param1"] = 18, ["z"] = 5, ["name"] = "default:silver_sandstone_block"}, {["x"] = 10, ["y"] = 0, ["param1"] = 18, ["z"] = 6, ["name"] = "default:silver_sandstone_block"}, {["x"] = 10, ["y"] = 0, ["param1"] = 18, ["z"] = 7, ["name"] = "default:silver_sandstone_block"}, {["x"] = 10, ["y"] = 0, ["param1"] = 18, ["z"] = 8, ["name"] = "default:silver_sandstone_block"}, {["x"] = 10, ["y"] = 0, ["param1"] = 18, ["z"] = 9, ["name"] = "default:silver_sandstone_block"}, {["x"] = 10, ["y"] = 0, ["param1"] = 18, ["z"] = 10, ["name"] = "default:silver_sandstone_block"}, {["x"] = 10, ["y"] = 0, ["param1"] = 18, ["z"] = 11, ["name"] = "default:silver_sandstone_block"}, {["x"] = 10, ["y"] = 0, ["param1"] = 18, ["z"] = 12, ["name"] = "default:silver_sandstone_block"}, {["x"] = 10, ["y"] = 0, ["param1"] = 18, ["z"] = 13, ["name"] = "default:silver_sandstone_block"}, {["x"] = 10, ["y"] = 0, ["param1"] = 18, ["z"] = 14, ["name"] = "default:silver_sandstone_block"}, {["x"] = 10, ["y"] = 0, ["param1"] = 18, ["z"] = 15, ["name"] = "default:silver_sandstone_block"}, {["x"] = 10, ["y"] = 0, ["param1"] = 18, ["z"] = 16, ["name"] = "default:silver_sandstone_block"}, {["x"] = 10, ["y"] = 0, ["param1"] = 18, ["z"] = 17, ["name"] = "default:silver_sandstone_block"}, {["x"] = 10, ["y"] = 0, ["param1"] = 18, ["z"] = 18, ["name"] = "default:silver_sandstone_block"}, {["x"] = 10, ["y"] = 0, ["param1"] = 18, ["z"] = 19, ["name"] = "default:silver_sandstone_block"}, {["x"] = 10, ["y"] = 0, ["param1"] = 18, ["z"] = 20, ["name"] = "default:silver_sandstone_block"}, {["x"] = 10, ["y"] = 0, ["param1"] = 18, ["z"] = 21, ["name"] = "default:silver_sandstone_block"}, {["x"] = 10, ["y"] = 0, ["param1"] = 18, ["z"] = 22, ["name"] = "default:silver_sandstone_block"}, {["x"] = 10, ["y"] = 0, ["param1"] = 18, ["z"] = 23, ["name"] = "default:silver_sandstone_block"}, {["x"] = 10, ["y"] = 0, ["param1"] = 18, ["z"] = 24, ["name"] = "default:silver_sandstone_block"}, {["x"] = 10, ["y"] = 0, ["param1"] = 18, ["z"] = 25, ["name"] = "default:silver_sandstone_block"}, {["x"] = 10, ["y"] = 0, ["param1"] = 18, ["z"] = 26, ["name"] = "default:silver_sandstone_block"}, {["x"] = 10, ["y"] = 0, ["param1"] = 18, ["z"] = 27, ["name"] = "default:silver_sandstone_block"}, {["x"] = 10, ["y"] = 0, ["param1"] = 18, ["z"] = 28, ["name"] = "default:silver_sandstone_block"}, {["x"] = 10, ["y"] = 0, ["param1"] = 18, ["z"] = 29, ["name"] = "default:silver_sandstone_block"}, {["x"] = 10, ["y"] = 0, ["param1"] = 18, ["z"] = 30, ["name"] = "default:silver_sandstone_block"}, {["x"] = 10, ["y"] = 0, ["param1"] = 18, ["z"] = 31, ["name"] = "default:silver_sandstone_block"}, {["x"] = 10, ["y"] = 0, ["param1"] = 18, ["z"] = 32, ["name"] = "default:silver_sandstone_block"}, {["x"] = 10, ["y"] = 0, ["param1"] = 18, ["z"] = 33, ["name"] = "default:silver_sandstone_block"}, {["x"] = 10, ["y"] = 0, ["param1"] = 18, ["z"] = 34, ["name"] = "default:silver_sandstone_block"}, {["x"] = 10, ["y"] = 0, ["param1"] = 18, ["z"] = 35, ["name"] = "default:silver_sandstone_block"}, {["x"] = 10, ["y"] = 0, ["param1"] = 18, ["z"] = 36, ["name"] = "default:silver_sandstone_block"}, {["x"] = 10, ["y"] = 0, ["param1"] = 18, ["z"] = 37, ["name"] = "default:silver_sandstone_block"}, {["x"] = 10, ["y"] = 0, ["param1"] = 18, ["z"] = 38, ["name"] = "default:silver_sandstone_block"}, {["x"] = 10, ["y"] = 0, ["param1"] = 18, ["z"] = 39, ["name"] = "default:silver_sandstone_block"}, {["x"] = 10, ["y"] = 0, ["param1"] = 18, ["z"] = 40, ["name"] = "default:silver_sandstone_block"}, {["x"] = 10, ["y"] = 0, ["param1"] = 18, ["z"] = 41, ["name"] = "default:silver_sandstone_block"}, {["x"] = 10, ["y"] = 0, ["param1"] = 18, ["z"] = 42, ["name"] = "default:silver_sandstone_block"}, {["x"] = 10, ["y"] = 0, ["param1"] = 18, ["z"] = 43, ["name"] = "default:silver_sandstone_block"}, {["x"] = 10, ["y"] = 0, ["param1"] = 18, ["z"] = 44, ["name"] = "default:silver_sandstone_block"}, {["x"] = 10, ["y"] = 0, ["param1"] = 18, ["z"] = 45, ["name"] = "default:silver_sandstone_block"}, {["x"] = 10, ["y"] = 0, ["param1"] = 18, ["z"] = 46, ["name"] = "default:silver_sandstone_block"}, {["x"] = 10, ["y"] = 0, ["param1"] = 18, ["z"] = 47, ["name"] = "default:silver_sandstone_block"}, {["x"] = 10, ["y"] = 0, ["param1"] = 18, ["z"] = 48, ["name"] = "default:silver_sandstone_block"}, {["x"] = 10, ["y"] = 0, ["param1"] = 18, ["z"] = 49, ["name"] = "default:silver_sandstone_block"}, {["x"] = 10, ["y"] = 0, ["param1"] = 15, ["z"] = 50, ["name"] = "default:desert_sandstone_block"}, {["x"] = 10, ["y"] = 1, ["param1"] = 16, ["z"] = 6, ["name"] = "default:silver_sandstone"}, {["x"] = 10, ["param2"] = 2, ["y"] = 1, ["param1"] = 9, ["z"] = 8, ["name"] = "mesecons_insulated:insulated_off"}, {["x"] = 10, ["y"] = 1, ["param1"] = 10, ["z"] = 9, ["name"] = "mesecons_insulated:insulated_off"}, {["x"] = 10, ["y"] = 1, ["param1"] = 11, ["z"] = 11, ["name"] = "mesecons_insulated:insulated_off"}, {["x"] = 10, ["y"] = 1, ["param1"] = 45, ["z"] = 13, ["name"] = "mesecons_extrawires:vertical_bottom_off"}, {["x"] = 10, ["y"] = 1, ["param1"] = 62, ["z"] = 14, ["name"] = "default:mese"}, {["x"] = 10, ["param2"] = 3, ["y"] = 1, ["param1"] = 47, ["z"] = 15, ["name"] = "mesecons_insulated:insulated_off"}, {["x"] = 10, ["param2"] = 3, ["y"] = 1, ["param1"] = 31, ["z"] = 16, ["name"] = "mesecons_insulated:insulated_off"}, {["x"] = 10, ["param2"] = 3, ["y"] = 1, ["param1"] = 15, ["z"] = 17, ["name"] = "mesecons_insulated:insulated_off"}, {["x"] = 10, ["param2"] = 3, ["y"] = 1, ["param1"] = 15, ["z"] = 18, ["name"] = "mesecons_insulated:insulated_off"}, {["x"] = 10, ["param2"] = 3, ["y"] = 1, ["param1"] = 31, ["z"] = 19, ["name"] = "mesecons_insulated:insulated_off"}, {["x"] = 10, ["param2"] = 3, ["y"] = 1, ["param1"] = 47, ["z"] = 20, ["name"] = "mesecons_insulated:insulated_off"}, {["x"] = 10, ["y"] = 1, ["param1"] = 62, ["z"] = 21, ["name"] = "default:mese"}, {["x"] = 10, ["y"] = 1, ["param1"] = 61, ["z"] = 22, ["name"] = "default:mese"}, {["x"] = 10, ["y"] = 1, ["param1"] = 60, ["z"] = 23, ["name"] = "default:mese"}, {["x"] = 10, ["y"] = 1, ["param1"] = 59, ["z"] = 24, ["name"] = "default:mese"}, {["x"] = 10, ["y"] = 1, ["param1"] = 58, ["z"] = 25, ["name"] = "default:mese"}, {["x"] = 10, ["y"] = 1, ["param1"] = 59, ["z"] = 26, ["name"] = "default:mese"}, {["x"] = 10, ["y"] = 1, ["param1"] = 60, ["z"] = 27, ["name"] = "default:mese"}, {["x"] = 10, ["y"] = 1, ["param1"] = 45, ["z"] = 28, ["name"] = "mesecons_extrawires:vertical_bottom_off"}, {["x"] = 10, ["y"] = 1, ["param1"] = 62, ["z"] = 29, ["name"] = "default:mese"}, {["x"] = 10, ["param2"] = 3, ["y"] = 1, ["param1"] = 47, ["z"] = 30, ["name"] = "mesecons_insulated:insulated_off"}, {["x"] = 10, ["param2"] = 3, ["y"] = 1, ["param1"] = 31, ["z"] = 31, ["name"] = "mesecons_insulated:insulated_off"}, {["x"] = 10, ["param2"] = 3, ["y"] = 1, ["param1"] = 15, ["z"] = 32, ["name"] = "mesecons_insulated:insulated_off"}, {["x"] = 10, ["param2"] = 3, ["y"] = 1, ["param1"] = 15, ["z"] = 33, ["name"] = "mesecons_insulated:insulated_off"}, {["x"] = 10, ["param2"] = 3, ["y"] = 1, ["param1"] = 31, ["z"] = 34, ["name"] = "mesecons_insulated:insulated_off"},